File: original_data/46NTB3.csv
Specimen name:	AWA_4_06_Rz
Specimen ID:	46NTB3
Material:	42CrMoS4
Specimen type:	Round Tensile Specimen
Gauge diameter:	5.008	mm
Gauge length:	25	mm
Parallel length:	30	mm
Original cross-section:	19.69783620349046	mm²
Cross-section after fracture:	12.796753224774415	mm²
Yield stress at 0.2% plastic strain:	1076.8155586756914	MPa
Yield stress at 1% plastic strain:	1144.8573488734698	MPa
Ultimate tensile strength:	1195.2531108888	MPa
Uniform elongation:	4.9285777327232205	%
Elongation after fracture:	11.118201972550775	%
Reduction of area:	35.03472618730159	%
Slope of linear-elastic region:	210269.08347084664	MPa
Crosshead seperation speed:	0.02993019531852049	mm/s
Strain rate:	0.0009976731772840164	s-1
Test temperature:	RT	Cel
Machine type:	INSTRON 8852TT
Standard:	DIN EN ISO 6892-1
Date:	2022-09-13 00:00:00
Heat treatment batch:	Batch 4
Time	Displacement	Force	Machine Displacement	Engineering Strain	Engineering Stress	True Strain	True Stress
s	mm	kN	mm		MPa		MPa
0	0.0009724297484699194	0.1609	0	3.889718993879678e-05	8.168409887147323	3.8896433462693014e-05	8.1687276153382
0.440001	0.0009830472484699195	0.163189	-0.000137329	3.932188993879678e-05	8.284615544273988	3.932111685357777e-05	8.284941311014606
0.870001	0.0009570573484699195	0.161206	-0.000640869	3.8282293938796775e-05	8.18394458836216	3.828156119056002e-05	8.18425788853447
1.27	0.0020593297484699192	0.267443	0.00622559	8.237318993879677e-05	13.57727809476906	8.236979745395512e-05	13.578396498476414
1.69	0.0035743697484699197	0.471587	0.0185928	0.00014297478993879678	23.941056018956775	0.00014296457001769123	23.944478986412
2.11	0.00528535974846992	0.697172	0.031311	0.0002114143899387968	35.393329135129115	0.00021139204506592853	35.40081179421612
2.55	0.007234619748469919	0.976158	0.0447464	0.0002893847899387968	49.55661068128004	0.00028934292623674507	49.57095161065212
2.97	0.00916869974846992	1.2744	0.0583267	0.0003667479899387968	64.69746153002207	0.00036668075433319376	64.72118919399234
3.39	0.01127402974846992	1.58509	0.0703659	0.0004509611899387968	80.47025996282383	0.0004508595375011202	80.50654892701135
3.82001	0.01339422974846992	1.92284	0.083168	0.0005357691899387969	97.61681334619243	0.0005356257168697083	97.66911342720333
4.22001	0.01539842974846992	2.25043	0.0955429	0.0006159371899387968	114.24757403563055	0.0006157475784829927	114.31794336533937
4.64001	0.01762772974846992	2.58995	0.107681	0.0007051091899387968	131.4839850044575	0.0007048607172473475	131.57669557061394
5.06001	0.01981042974846992	2.95407	0.120522	0.0007924171899387968	149.96926411016344	0.000792103393198278	150.0881023330068
5.48001	0.022023629748469917	3.31865	0.132866	0.0008809451899387967	168.47789603468905	0.0008805573854645271	168.6263158268118
5.90001	0.02445302974846992	3.71305	0.146072	0.0009781211899387967	188.50039982269965	0.0009776431411088573	188.6847760580782
6.33001	0.02683542974846992	4.10499	0.159012	0.0010734171899387968	208.39801679702234	0.0010728414896477637	208.6217148106014
6.73001	0.029167129748469918	4.51425	0.171776	0.0011666851899387967	229.17491816690372	0.0011660051416560232	229.44229314983448
7.15001	0.03138912974846992	4.88719	0.183121	0.0012555651899387968	248.10796218997848	0.0012547776271211405	248.41947791065087
7.57001	0.03403332974846992	5.33252	0.196915	0.0013613331899387968	270.71602915730796	0.0013604074160076217	271.0845638728482
8.01001	0.036781229748469924	5.78092	0.209824	0.0014712491899387969	293.4799508067602	0.0014701679632221586	293.91173294664793
8.42001	0.03900012974846992	6.16435	0.221596	0.0015600051899387968	312.9455406329186	0.0015587896458482428	313.43373730047415
8.82001	0.04148472974846992	6.57482	0.234375	0.001659389189938797	333.7838700696953	0.0016580139248867322	334.3377474154649
9.23001	0.04378812974846992	6.99014	0.247002	0.0017515251899387968	354.8684194440274	0.0017499930584768929	355.48998041979735
9.63001	0.046162729748469924	7.38168	0.258484	0.001846509189938797	374.74572961937645	0.0018448064875594785	375.437701053009
10.04	0.048667929748469924	7.80746	0.270477	0.001946717189938797	396.3613017868692	0.0019448247916082012	397.13290514648423
10.44	0.05120472974846992	8.21916	0.282722	0.002048189189938797	417.2620746304898	0.0020460945101726338	418.11670630111945
10.88	0.053752529748469925	8.66648	0.296204	0.002150101189938797	439.9711679227131	0.0021477930303009894	440.9171504544025
11.29	0.056431929748469924	9.08492	0.308052	0.002257277189938797	461.2141103290396	0.002254733367138859	462.2551984199632
11.69	0.05893642974846992	9.49067	0.32019	0.0023574571899387968	481.8128195379273	0.00235468274730182	482.9486726335516
12.11	0.06145982974846992	9.92614	0.333061	0.0024583931899387966	503.9203239105565	0.0024553762848816643	505.15915820313
12.52	0.06377582974846992	10.3295	0.344872	0.0025510331899387968	524.3976999955767	0.002547784828050516	525.735455932993
12.93	0.06621402974846992	10.7262	0.357414	0.0026485611899387967	544.5369678776858	0.0026450599325839614	545.9792073572936
13.35	0.06889602974846992	11.1537	0.369484	0.002755841189938797	566.2398592807652	0.0027520508217783583	567.8003264083563
13.75	0.07124162974846993	11.5509	0.381866	0.002849665189938797	586.4045106615912	0.002845612591298731	588.0755671828466
14.17	0.07382562974846993	11.976	0.39389	0.002953025189938797	607.9855612708288	0.0029486735758982763	609.7809579483807
14.58	0.07614672974846992	12.3689	0.406326	0.003045869189938797	627.9319145626882	0.0030412399280797292	629.844513034634
14.98	0.07852522974846993	12.7598	0.41713	0.003141009189938797	647.7767338596796	0.003136086525968105	649.8114065337614
15.39	0.08105982974846992	13.1802	0.43045	0.003242393189938797	669.1191795809767	0.003237147968129119	671.2887270521076
15.81	0.08364982974846992	13.593	0.442581	0.0033459931899387967	690.0757961217749	0.00334040781035222	692.3847850361401
16.23	0.08615542974846992	14.0133	0.455185	0.0034462171899387966	711.4131651433288	0.003440292591212742	713.8648494221944
16.64	0.08862272974846992	14.4127	0.467506	0.003544909189938797	731.6895039185099	0.0035386408088829294	734.2832767651324
17.04	0.09099942974846992	14.7855	0.47905	0.003639977189938797	750.6154405619438	0.0036333685050867026	753.3476636440051
17.47	0.09365852974846992	15.2344	0.492485	0.0037463411899387967	773.4047457101132	0.0037393411314075456	776.3021837654611
17.87	0.09594292974846992	15.599	0.503479	0.003837717189938797	791.9143929745875	0.0038303719399874142	794.9535364534661
18.28	0.09824732974846992	15.9753	0.515953	0.003929893189938797	811.0180141090408	0.003922191331423067	814.2052282796055
18.68	0.10081292974846992	16.3896	0.528503	0.004032517189938797	832.0507811459901	0.004024408384450349	835.4060402238632
19.09	0.10327542974846993	16.7967	0.540619	0.004131017189938797	852.7180258014138	0.0041225079648805965	856.24061862417
19.49	0.10559142974846993	17.1773	0.551773	0.004223657189938797	872.0399450248336	0.004214762586285451	875.7231428085515
19.9	0.10812442974846992	17.5698	0.564316	0.004324977189938797	891.9659915177194	0.004315651355769674	895.8237240852346
20.3	0.11062242974846992	17.9361	0.575775	0.004424897189938797	910.5619426778317	0.004415136116273555	914.591085659252
20.71	0.11331942974846992	18.3222	0.588333	0.004532777189938797	930.1630803871392	0.004522535093842414	934.3793023808413
21.11	0.11634542974846993	18.6776	0.599876	0.004653817189938797	948.20567127522	0.004643021663367634	952.618447127798
21.52	0.11957942974846993	19.0429	0.612015	0.004783177189938797	966.7508554378979	0.004771774145321894	971.3749960779822
21.93	0.12346842974846992	19.3786	0.624573	0.004938737189938797	983.7933364765266	0.004926581633062032	988.6520332145972
22.33	0.12780342974846992	19.6854	0.636749	0.005112137189938797	999.3686512893098	0.005099114580004112	1004.4775609380248
22.75	0.13296342974846992	19.9434	0.648773	0.005318537189938796	1012.4665366273086	0.0053044437200290544	1017.8513775559294
23.18	0.13859842974846992	20.1949	0.661163	0.005543937189938797	1025.2344364819858	0.005528626133113939	1030.9182718028042
23.58	0.1446364297484699	20.4046	0.673126	0.005785457189938796	1035.8802758439174	0.005768785703033799	1041.8733168337144
24	0.1511884297484699	20.6003	0.685371	0.006047537189938796	1045.8153772417716	0.006029324229059369	1052.1399846294512
24.41	0.15821642974846992	20.7887	0.69799	0.006328657189938797	1055.3798795583566	0.00630871533159148	1062.0590170212404
24.82	0.1650654297484699	20.9412	0.710388	0.006602617189938796	1063.1218466670573	0.0065809153864849045	1070.1412332468606
25.23	0.1728114297484699	21.097	0.72274	0.006912457189938797	1071.031344867291	0.006888675687252575	1078.4348031877687
25.65	0.18061342974846992	21.2244	0.735092	0.007224537189938797	1077.4990603403955	0.007198565236343144	1085.283492373949
26.09	0.18892042974846993	21.3432	0.748497	0.007556817189938797	1083.5301796355673	0.007528407481795809	1091.7182191228546
26.5	0.19702842974846993	21.4663	0.760643	0.007881137189938797	1089.7795970197055	0.007850243241705579	1098.368299530614
26.9	0.20507342974846993	21.5583	0.772133	0.008202937189938798	1094.450160783643	0.008169475963021424	1103.4278667100696
27.33	0.21428742974846993	21.6498	0.785416	0.008571497189938796	1099.0953410488635	0.008534970485185254	1108.5162336761387
27.73	0.2227934297484699	21.739	0.797539	0.008911737189938797	1103.6237572199857	0.00887226201497593	1113.458962100903
28.14	0.23144742974846993	21.8149	0.809624	0.009257897189938797	1107.4769723252343	0.009215305530741742	1117.7298802752462
28.55	0.24022542974846992	21.8856	0.821976	0.009609017189938797	1111.0661990438252	0.009563144212964137	1121.7424532495972
28.95	0.2491854297484699	21.9481	0.834198	0.009967417189938797	1114.2391363834568	0.00991807012481507	1125.3452227051478
29.35	0.2581424297484699	22.0083	0.846321	0.010325697189938796	1117.2953096289898	0.010272751335383705	1128.8321626679576
29.77	0.2673124297484699	22.0693	0.858719	0.010692497189938796	1120.3920964724703	0.010635736691029997	1132.3718858156317
30.19	0.2773034297484699	22.133	0.872131	0.011092137189938796	1123.6259542090227	0.011031070593968342	1136.089367443285
30.6	0.2867894297484699	22.1769	0.884193	0.011471577189938796	1125.8546253963798	0.011406277566934044	1138.7699536362638
31.01	0.2967764297484699	22.224	0.896812	0.011871057189938796	1128.245750975526	0.01180114890350639	1141.639220809662
31.41	0.3060724297484699	22.2636	0.90873	0.012242897189938795	1130.2561240739165	0.012168559051910747	1144.0937335992521
31.82	0.3153854297484699	22.3054	0.920822	0.012615417189938796	1132.378184566662	0.012536505788289552	1146.663607781756
32.22	0.3253584297484699	22.3412	0.932678	0.013014337189938796	1134.195643074803	0.0129303783647508	1148.956447613138
32.63	0.3346394297484699	22.3801	0.944923	0.013385577189938795	1136.1704792749897	0.013296781858472715	1151.3787769262547
33.04	0.3444254297484699	22.4089	0.956818	0.013777017189938796	1137.6325688010918	0.013682976834593933	1153.3057522572985
33.44	0.3541154297484699	22.4456	0.968903	0.014164617189938795	1139.4957176069233	0.014065236361346357	1155.6362382364
33.85	0.3642194297484699	22.4772	0.9813	0.014568777189938795	1141.0999547258411	0.014463672160221017	1157.7243857176911
34.25	0.3743574297484699	22.5102	0.993408	0.014974297189938797	1142.7752656411667	0.014863289207541314	1159.8875220901887
34.66	0.3840884297484699	22.5329	1.00507	0.015363537189938796	1143.9276764829208	0.015246713087230374	1161.5024518831665
35.06	0.3940074297484699	22.5625	1.01755	0.015760297189938797	1145.4303796069703	0.015637393358251598	1163.4827027999606
35.48	0.4044694297484699	22.5843	1.02981	0.016178777189938796	1146.5371001510337	0.0160492954779492	1165.086668434376
35.9001	0.4147394297484699	22.617	1.04242	0.016589577189938795	1148.1971809671288	0.016453473361481327	1167.245286730053
36.3301	0.4253234297484699	22.6391	1.05527	0.017012937189938796	1149.3191316104226	0.01686983791957228	1168.8724258077057
36.7301	0.4349984297484699	22.6562	1.06653	0.017399937189938798	1150.1872472665457	0.017250291670668313	1170.2004331256521
37.1401	0.4452934297484699	22.6951	1.07941	0.017811737189938795	1152.1620834667324	0.017654967027835207	1172.6840916976544
37.5401	0.4549484297484699	22.7084	1.09092	0.018197937189938795	1152.8372845326062	0.018034336546056563	1173.8165450267502
37.9601	0.4656704297484699	22.7321	1.10378	0.018626817189938794	1154.0404623717943	0.018455462620272055	1175.5365630941862
38.3801	0.4762624297484699	22.76	1.11677	0.019050497189938797	1155.4568616002057	0.01887130864566138	1177.4688892952158
38.7901	0.4869184297484699	22.7726	1.12896	0.019476737189938795	1156.0965257678756	0.019289492910284405	1178.6135139664577
39.2101	0.4971214297484699	22.7852	1.14091	0.019884857189938796	1156.7361899355453	0.01968973581627326	1179.7377238788476
39.6201	0.5072844297484699	22.8188	1.15373	0.020291377189938797	1158.441961049331	0.02008825041371805	1181.9483438336354
40.0201	0.5172674297484698	22.8322	1.16574	0.020690697189938795	1159.122238814948	0.020479552238567664	1183.105286064392
40.4401	0.5276594297484699	22.8457	1.17821	0.021106377189938796	1159.8075932803085	0.020886722971603693	1184.286929811838
40.8601	0.5379824297484699	22.8603	1.19033	0.021519297189938794	1160.5487914428463	0.02129102612984131	1185.5229857893291
41.3001	0.5489564297484699	22.886	1.20371	0.021958257189938796	1161.853503276903	0.02172064671051367	1187.3657813188886
41.7101	0.5597234297484699	22.9091	1.21639	0.022388937189938795	1163.0262209176306	0.022141984150216065	1189.0651419280073
42.1101	0.5699824297484699	22.9262	1.2288	0.022799297189938797	1163.894336573754	0.022543277291462188	1190.4303094509858
42.5301	0.5803354297484699	22.9438	1.24128	0.023213417189938794	1164.787835728594	0.022948084165578288	1191.8265416971278
42.9401	0.5902024297484699	22.9537	1.25306	0.023608097189938795	1165.2904290031918	0.02333373577429836	1192.8007187056046
43.3401	0.6011914297484698	22.9717	1.26649	0.024047657189938794	1166.2042349570054	0.023763065758903044	1194.2487146127064
43.7701	0.6113284297484699	22.9897	1.27815	0.024453137189938797	1167.1180409108194	0.024158945522687367	1195.6577384820644
44.1701	0.6215344297484698	23.0086	1.29068	0.024861377189938794	1168.0775371623242	0.024557361678465946	1197.1175534008116
44.5901	0.6323944297484699	23.0282	1.30368	0.025295777189938796	1169.0725703120322	0.02498113407617966	1198.6451695695143
45.0001	0.6424934297484699	23.0353	1.31621	0.025699737189938798	1169.4330159938145	0.025375050106118676	1199.487137166093
45.4001	0.6521154297484699	23.0545	1.3271	0.026084617189938798	1170.4077423445494	0.025750216242552693	1200.9373802597474
45.8401	0.6633204297484699	23.0719	1.34108	0.026532817189938798	1171.2910880999027	0.026186926951149766	1202.368740416662
46.2501	0.6740284297484699	23.0969	1.35332	0.026961137189938797	1172.5602630357555	0.02660408913007693	1204.1738211509332
46.6501	0.6837144297484699	23.0942	1.36391	0.027348577189938793	1172.4231921426833	0.026981286396761478	1204.487298312272
47.0601	0.6942344297484699	23.0937	1.37686	0.0277693771899388	1172.397808643966	0.027390800609786402	1204.954565608858
47.4601	0.7047204297484699	23.1321	1.38979	0.0281888171899388	1174.347261345436	0.02779882447619153	1207.4507216130075
47.8701	0.7150314297484699	23.1371	1.40138	0.028601257189938795	1174.6010963326064	0.028199876591976935	1208.1961643843993
48.2701	0.7248544297484699	23.148	1.41338	0.028994177189938797	1175.1544566046382	0.02858179812835943	1209.227093144979
48.7101	0.7357074297484699	23.1709	1.42651	0.029428297189938796	1176.317020845879	0.029003596871659033	1210.934027724915
49.1201	0.7462734297484699	23.1708	1.4389	0.029850937189938795	1176.3119441461356	0.029414070593607917	1211.4259581066165
49.5201	0.7565974297484699	23.1983	1.45115	0.030263897189938795	1177.7080365755735	0.029814980289164312	1213.3500715142611
49.9401	0.7672554297484699	23.2194	1.46368	0.030690217189938796	1178.7792202214332	0.03022869159220223	1214.9562105090156
50.3601	0.7783204297484699	23.2251	1.47681	0.031132817189938797	1179.0685921068077	0.030658020394352833	1215.7763190392675
50.8001	0.7891654297484699	23.234	1.48972	0.0315666171899388	1179.520418383971	0.03107863427455769	1216.7538878988141
51.2201	0.7997144297484698	23.2381	1.50182	0.03198857718993879	1179.728563073451	0.031487598383713095	1217.4664012765018
51.6301	0.8098924297484699	23.2566	1.51431	0.032395697189938795	1180.6677525259818	0.031882021079458756	1218.9163075187391
52.0301	0.8201114297484698	23.2611	1.52703	0.032804457189938796	1180.8962040144352	0.03227787617802717	1219.634862984788
52.4401	0.8306544297484699	23.264	1.53926	0.033226177189938796	1181.0434283069942	0.03268611795221893	1220.284986524935
52.8601	0.8410154297484699	23.2816	1.55137	0.0336406171899388	1181.9369274618346	0.033087150090991946	1221.6980151812306
53.2701	0.8515254297484699	23.3059	1.56397	0.03406101718993879	1183.1705654994832	0.033493785167158334	1223.4705584695907
53.6701	0.8616654297484699	23.3073	1.57606	0.0344666171899388	1183.241639295891	0.03388594817088816	1224.0239759206981
54.0801	0.8727994297484699	23.3169	1.58807	0.0349119771899388	1183.7290024712584	0.03431637690740408	1225.055322404604
54.4901	0.8827884297484699	23.3098	1.60021	0.0353115371899388	1183.368556789476	0.0347023835411669	1225.155119591952
54.8901	0.89331342974847	23.3413	1.61356	0.035732537189938796	1184.9677172086504	0.035108941770426186	1227.3096202326853
55.3001	0.9040454297484699	23.3323	1.62575	0.0361618171899388	1184.5108142317433	0.03552332583903005	1227.344877755497
55.7001	0.9139884297484699	23.343	1.63713	0.0365595371899388	1185.0540211042883	0.035907091851804365	1228.379047660937
56.1401	0.9257964297484699	23.372	1.65096	0.037031857189938795	1186.5262640298774	0.03636264930584156	1230.4655351915435
56.5401	0.9353874297484699	23.3652	1.66217	0.03741549718993879	1186.1810484473256	0.0367325213139825	1230.562602132265
56.9501	0.94565942974847	23.3787	1.67454	0.037826377189938795	1186.8664029126858	0.03712850407670667	1231.761259143327
57.3601	0.9563174297484699	23.3841	1.68704	0.038252697189938796	1187.14054469883	0.037539201348552924	1232.5518724770934
57.7601	0.9670394297484699	23.3952	1.69894	0.038681577189938796	1187.7040583703485	0.03795219468337942	1233.6463245830046
58.1601	0.9778714297484699	23.4066	1.71143	0.0391148571899388	1188.2828021410976	0.03836925190718757	1234.762314248107
58.5701	0.9883024297484699	23.4065	1.72321	0.039532097189938796	1188.277725441354	0.03877070536682826	1235.2528359721412
58.9801	0.9993704297484699	23.4082	1.73593	0.0399748171899388	1188.364029336992	0.03919649861966837	1235.8686641648374
59.3801	1.00973242974847	23.4229	1.74855	0.0403892971899388	1189.1103041992733	0.03959496733254349	1237.1376336671963
59.7901	1.01979242974847	23.42	1.76015	0.040791697189938796	1188.9630799067145	0.03998167084953795	1237.462901832286
60.1901	1.0299724297484698	23.434	1.77225	0.04119889718993879	1189.673817870792	0.0403728349655445	1238.6870671828128
60.6001	1.04101242974847	23.4408	1.78434	0.0416404971899388	1190.0190334533438	0.04079687150701622	1239.5720176718316
61.0001	1.05135242974847	23.4513	1.7963	0.0420540971899388	1190.552086926402	0.041193858672551285	1240.6196800996893
61.4301	1.06259242974847	23.4567	1.80915	0.042503697189938794	1190.826228712546	0.04162522114969993	1241.440746143581
61.8301	1.0731224297484698	23.4424	1.82098	0.04292489718993879	1190.1002606492382	0.04202916689673951	1241.1851919833261
62.2401	1.0844024297484698	23.4672	1.83372	0.04337609718993879	1191.359282185604	0.042461702765964546	1243.0357981978225
62.6401	1.0949524297484698	23.4778	1.84606	0.043798097189938795	1191.8974123584055	0.04286607726128616	1244.1002510653154
63.0501	1.1052624297484699	23.4744	1.85782	0.044210497189938795	1191.7248045671295	0.043261094797586205	1244.411550690625
63.4601	1.1162424297484699	23.4733	1.87015	0.044649697189938796	1191.6689608699521	0.04368161121860258	1244.8766191234445
63.8601	1.1270424297484698	23.4777	1.88263	0.04508169718993879	1191.892335658662	0.044095061490073535	1245.6248650178347
64.2701	1.13805242974847	23.4923	1.89529	0.0455220971899388	1192.6335338212	0.044516375186813555	1246.9247134597888
64.6701	1.14790242974847	23.4884	1.90619	0.0459160971899388	1192.435542531207	0.04489314941396475	1247.1875287948073
65.0801	1.1596124297484698	23.4939	1.91959	0.04638449718993879	1192.7147610170948	0.045340886234460843	1248.0382354978908
65.4801	1.1700624297484699	23.4858	1.93095	0.04680249718993879	1192.3035483378785	0.04574027721737706	1248.1063318085162
65.8901	1.1808424297484699	23.5031	1.94306	0.04723369718993879	1193.1818173934882	0.046152113466675776	1249.5402060487932
66.2901	1.19146242974847	23.509	1.95541	0.047658497189938795	1193.4813426783496	0.046557671334486	1250.36086989463
66.7001	1.20288242974847	23.5115	1.96801	0.048115297189938795	1193.608260171935	0.04699359625010317	1251.0390763384735
67.1101	1.21373242974847	23.5051	1.98061	0.0485492971899388	1193.2833513883566	0.04740758712624229	1251.2164194467161
67.5101	1.2245224297484698	23.5085	1.99236	0.04898089718993879	1193.4559591796326	0.0478191187525785	1251.91250281693
67.9101	1.23518242974847	23.5102	2.00441	0.0494072971899388	1193.5422630752705	0.04822552592453172	1252.5119603757826
68.3201	1.2461224297484699	23.5162	2.01675	0.04984489718993879	1193.8468650598752	0.048642436296243985	1253.3540393093153
68.7401	1.2577424297484698	23.5319	2.03017	0.050309697189938794	1194.6439069195908	0.04908507038502269	1254.7460801265208
69.1501	1.26850242974847	23.5294	2.04142	0.0507400971899388	1194.5169894260052	0.04949477034279769	1255.126897564514
69.5501	1.27975242974847	23.5268	2.05396	0.0511900971899388	1194.3849952326768	0.04992294822242317	1255.5256792208422
69.9701	1.2908524297484698	23.5221	2.06568	0.05163409718993879	1194.1463903447363	0.050345237454004856	1255.805061122811
70.3801	1.30264242974847	23.5316	2.07858	0.0521056971899388	1194.6286768203604	0.0507935818824933	1256.8756369091793
70.8001	1.31443242974847	23.5268	2.09231	0.052577297189938796	1194.3849952326768	0.051241725388334367	1257.1825300862288
71.2101	1.32504242974847	23.522	2.10302	0.0530016971899388	1194.141313644993	0.05164484491686315	1257.4328299528006
71.6101	1.33592242974847	23.5335	2.11604	0.0534368971899388	1194.7251341154852	0.05205805421463567	1258.5675382774502
72.0301	1.34761242974847	23.5337	2.12867	0.053904497189938796	1194.735287514972	0.05250183613712924	1259.1368924635435
72.4401	1.3590524297484698	23.54	2.14075	0.05436209718993879	1195.0551195988069	0.05293593684185594	1260.0208221577711
72.8401	1.3701724297484699	23.5337	2.15266	0.054806897189938794	1194.735287514972	0.053357714336005675	1260.215021586997
73.2501	1.3814824297484698	23.5293	2.16455	0.05525929718993879	1194.511912726262	nan	nan
73.6601	1.3931824297484698	23.5254	2.17699	0.055727297189938796	1194.313921436269	nan	nan
74.0601	1.4045624297484698	23.5439	2.18929	0.05618249718993879	1195.2531108888	nan	nan
74.4701	1.4156124297484698	23.5224	2.20124	0.05662449718993879	1194.1616204439667	nan	nan
74.8701	1.42669242974847	23.5327	2.2129	0.0570676971899388	1194.6845205175377	nan	nan
75.2801	1.43871242974847	23.5188	2.22592	0.0575484971899388	1193.9788592532038	nan	nan
75.6801	1.44949242974847	23.5233	2.23753	0.0579796971899388	1194.2073107416572	nan	nan
76.1201	1.46179242974847	23.531	2.25056	0.0584716971899388	1194.5982166218998	nan	nan
76.5301	1.4735124297484699	23.5174	2.26347	0.058940497189938795	1193.907785456796	nan	nan
76.9301	1.4851024297484698	23.5135	2.27538	0.0594040971899388	1193.709794166803	nan	nan
77.3501	1.49729242974847	23.5193	2.28857	0.0598916971899388	1194.004242751921	nan	nan
77.7701	1.50885242974847	23.5025	2.30102	0.0603540971899388	1193.151357195028	nan	nan
78.2001	1.5218424297484698	23.5171	2.3144	0.06087369718993879	1193.8925553575657	nan	nan
78.6001	1.5331924297484698	23.5067	2.32591	0.061327697189938794	1193.3645785842511	nan	nan
79.0201	1.5450224297484698	23.5064	2.3383	0.061800897189938794	1193.3493484850208	nan	nan
79.4501	1.5569824297484698	23.4801	2.35112	0.06227929718993879	1192.014176452504	nan	nan
79.8501	1.56910242974847	23.507	2.36391	0.06276409718993879	1193.3798086834813	nan	nan
80.2601	1.58111242974847	23.4907	2.37641	0.0632444971899388	1192.5523066253056	nan	nan
80.6601	1.59236242974847	23.4953	2.3887	0.0636944971899388	1192.7858348135023	nan	nan
81.0701	1.6045024297484698	23.4792	2.40067	0.06418009718993879	1191.9684861548133	nan	nan
81.4701	1.6160924297484698	23.4635	2.41231	0.06464369718993879	1191.171444295098	nan	nan
81.8901	1.6285424297484699	23.4651	2.42471	0.0651416971899388	1191.2526714909925	nan	nan
82.3101	1.64110242974847	23.4682	2.43824	0.0656440971899388	1191.4100491830382	nan	nan
82.7501	1.6546324297484698	23.4548	2.45119	0.06618529718993879	1190.7297714174213	nan	nan
83.1601	1.66617242974847	23.4354	2.46305	0.0666468971899388	1189.7448916671997	nan	nan
83.5601	1.67780242974847	23.4394	2.47536	0.0671120971899388	1189.9479596569358	nan	nan
83.9701	1.6902224297484698	23.4383	2.48782	0.06760889718993879	1189.8921159597587	nan	nan
84.3701	1.70204242974847	23.412	2.4994	0.0680816971899388	1188.5569439272415	nan	nan
84.8001	1.7152124297484699	23.4087	2.51274	0.06860849718993879	1188.389412835709	nan	nan
85.2001	1.72715242974847	23.4041	2.52471	0.0690860971899388	1188.155884647512	nan	nan
85.6101	1.73972242974847	23.3881	2.53696	0.0695888971899388	1187.3436126885665	nan	nan
86.0101	1.75237242974847	23.3795	2.54936	0.0700948971899388	1186.9070165106332	nan	nan
86.4201	1.7641824297484698	23.362	2.56121	0.07056729718993879	1186.0185940555364	nan	nan
86.8201	1.7762424297484698	23.3377	2.5732	0.0710496971899388	1184.7849560178877	nan	nan
87.2401	1.78898242974847	23.3308	2.58576	0.0715592971899388	1184.4346637355923	nan	nan
87.6501	1.8013024297484699	23.3075	2.5979	0.0720520971899388	1183.2517926953776	nan	nan
88.0501	1.8136624297484698	23.2999	2.60986	0.07254649718993879	1182.8659635148786	nan	nan
88.4801	1.82707242974847	23.2954	2.62295	0.0730828971899388	1182.6375120264252	nan	nan
88.8801	1.83937242974847	23.2686	2.63444	0.0735748971899388	1181.276956495191	nan	nan
89.3001	1.8521024297484698	23.2441	2.64722	0.07408409718993879	1180.0331650580554	nan	nan
89.7201	1.86483242974847	23.2131	2.65985	0.0745932971899388	1178.4593881375984	nan	nan
90.1501	1.8784424297484699	23.2017	2.67278	0.07513769718993879	1177.8806443668493	nan	nan
90.5601	1.8910124297484698	23.1749	2.68472	0.07564049718993879	1176.5200888356155	nan	nan
90.9601	1.90296242974847	23.1499	2.69668	0.0761184971899388	1175.2509138997627	nan	nan
91.3601	1.91526242974847	23.1489	2.7087	0.0766104971899388	1175.200146902329	nan	nan
91.7801	1.92845242974847	23.1193	2.72149	0.0771380971899388	1173.6974437782792	nan	nan
92.2001	1.94194242974847	23.0959	2.73402	0.0776776971899388	1172.5094960383215	nan	nan
92.6401	1.95577242974847	23.0581	2.74719	0.0782308971899388	1170.590503535312	nan	nan
93.0501	1.9685324297484699	23.0426	2.75974	0.07874129718993879	1169.8036150750834	nan	nan
93.4601	1.98125242974847	23.007	2.77165	0.07925009718993879	1167.9963099664294	nan	nan
93.8601	1.99345242974847	22.9841	2.78341	0.0797380971899388	1166.8337457251887	nan	nan
94.2601	2.00592242974847	22.9564	2.79536	0.0802368971899388	1165.4274998962637	nan	nan
94.6701	2.0189524297484702	22.9275	2.80773	0.08075809718993882	1163.960333670418	nan	nan
95.0701	2.03166242974847	22.9017	2.81957	0.0812664971899388	1162.6505451366183	nan	nan
95.5001	2.04437242974847	22.8698	2.83202	0.08177489718993881	1161.0310779184706	nan	nan
95.9001	2.05660242974847	22.8517	2.84368	0.0822640971899388	1160.1121952649132	nan	nan
96.3201	2.07050242974847	22.813	2.85677	0.0828200971899388	1158.1475124642134	nan	nan
96.7301	2.0839624297484702	22.7929	2.86945	0.0833584971899388	1157.1270958157877	nan	nan
97.1301	2.09620242974847	22.7398	2.88094	0.0838480971899388	1154.431368252037	nan	nan
97.5701	2.10996242974847	22.7067	2.89342	0.0843984971899388	1152.750980636968	nan	nan
97.9801	2.12286242974847	22.6892	2.90593	0.0849144971899388	1151.8625581818712	nan	nan
98.3801	2.13533242974847	22.6493	2.91737	0.0854132971899388	1149.8369549842505	nan	nan
98.7901	2.14851242974847	22.6301	2.93024	0.08594049718993879	1148.8622286335155	nan	nan
99.2001	2.1609824297484703	22.5846	2.94232	0.08643929718993881	1146.5523302502638	nan	nan
99.6001	2.17409242974847	22.5703	2.95478	0.08696369718993881	1145.8263621869562	nan	nan
100	2.18670242974847	22.5338	2.96687	0.08746809718993881	1143.9733667806115	nan	nan
100.44	2.20044242974847	22.4904	2.97971	0.08801769718993879	1141.7700790919714	nan	nan
100.85	2.21373242974847	22.4409	2.9921	0.0885492971899388	1139.257112718983	nan	nan
101.25	2.2261924297484703	22.42	3.00432	0.08904769718993881	1138.1960824726104	nan	nan
101.67	2.2392624297484702	22.377	3.01672	0.08957049718993881	1136.013101582944	nan	nan
102.09	2.25285242974847	22.3547	3.0299	0.0901140971899388	1134.8809975401634	nan	nan
102.5	2.2651024297484703	22.3225	3.04127	0.09060409718993881	1133.2463002227853	nan	nan
102.92	2.27868242974847	22.2841	3.05459	0.0911472971899388	1131.2968475213156	nan	nan
103.33	2.2924124297484703	22.2459	3.06693	0.09169649718993882	1129.3575482193328	nan	nan
103.74	2.30504242974847	22.2156	3.07928	0.0922016971899388	1127.8193081970794	nan	nan
104.14	2.3175624297484703	22.1707	3.09166	0.09270249718993881	1125.5398700122885	nan	nan
104.54	2.3301724297484703	22.1517	3.10332	0.09320689718993881	1124.5752970610404	nan	nan
104.98	2.34423242974847	22.1111	3.11623	0.0937692971899388	1122.5141569652158	nan	nan
105.4	2.35738242974847	22.063	3.12869	0.0942952971899388	1120.0722643886354	nan	nan
105.81	2.37127242974847	22.0169	3.14194	0.0948508971899388	1117.7319058069231	nan	nan
106.21	2.38361242974847	21.9829	3.15363	0.0953444971899388	1116.0058278941638	nan	nan
106.64	2.39675242974847	21.9484	3.16597	0.0958700971899388	1114.254366482687	nan	nan
107.04	2.40964242974847	21.915	3.1781	0.0963856971899388	1112.5587487683879	nan	nan
107.46	2.4232424297484703	21.8637	3.19044	0.09692969718993881	1109.9544018000186	nan	nan
107.88	2.43658242974847	21.8227	3.20319	0.0974632971899388	1107.8729549052202	nan	nan
108.31	2.4506924297484702	21.7811	3.21635	0.09802769718993881	1105.7610478119614	nan	nan
108.71	2.4633724297484703	21.7607	3.22842	0.09853489718993881	1104.7254010643057	nan	nan
109.11	2.47621242974847	21.7144	3.23995	0.0990484971899388	1102.3748890831068	nan	nan
109.55	2.4899524297484703	21.6731	3.25285	0.09959809718993881	1100.2782120890784	nan	nan
109.97	2.50353242974847	21.6237	3.26541	0.1001412971899388	1097.7703224158336	nan	nan
110.39	2.51698242974847	21.586	3.27796	0.1006792971899388	1095.8564066125678	nan	nan
110.8	2.52970242974847	21.5405	3.29019	0.1011880971899388	1093.546508229316	nan	nan
111.21	2.5430924297484703	21.5081	3.30338	0.10172369718993882	1091.901657512451	nan	nan
111.61	2.55596242974847	21.4567	3.31498	0.10223849718993881	1089.2922338443382	nan	nan
112.03	2.56944242974847	21.4151	3.3277	0.1027776971899388	1087.1803267510793	nan	nan
112.44	2.58212242974847	21.3829	3.33926	0.1032848971899388	1085.5456294337012	nan	nan
112.85	2.59580242974847	21.3338	3.35213	0.1038320971899388	1083.0529698596868	nan	nan
113.25	2.60870242974847	21.2844	3.36402	0.10434809718993882	1080.545080186442	nan	nan
113.66	2.6215924297484703	21.2478	3.37578	0.1048636971899388	1078.687008080354	nan	nan
114.06	2.63418242974847	21.2098	3.3879	0.10536729718993881	1076.757862177858	nan	nan
114.48	2.64763242974847	21.1618	3.39975	0.1059052971899388	1074.3210463010207	nan	nan
114.9	2.66155242974847	21.1071	3.41272	0.1064620971899388	1071.5440915413753	nan	nan
115.32	2.67478242974847	21.0596	3.42479	0.1069912971899388	1069.1326591632553	nan	nan
115.74	2.68835242974847	21.0186	3.43724	0.10753409718993881	1067.051212268457	nan	nan
116.15	2.70190242974847	20.9686	3.45045	0.10807609718993881	1064.5128623967519	nan	nan
116.57	2.71566242974847	20.9196	3.4629	0.1086264971899388	1062.0252795224808	nan	nan
116.98	2.72823242974847	20.8756	3.47468	0.1091292971899388	1059.7915316353801	nan	nan
117.39	2.74206242974847	20.8303	3.48746	0.10968249718993879	1057.4917866516155	nan	nan
117.8	2.75508242974847	20.7668	3.49953	0.11020329718993879	1054.2680823145497	nan	nan
118.24	2.76900242974847	20.7105	3.51218	0.1107600971899388	1051.4099003590097	nan	nan
118.66	2.7826624297484703	20.6808	3.52466	0.11130649718993882	1049.902120535217	nan	nan
119.08	2.79626242974847	20.627	3.53709	0.11185049718993881	1047.170856073262	nan	nan
119.5	2.81039242974847	20.5622	3.54956	0.1124156971899388	1043.8811546395323	nan	nan
119.94	2.8245424297484703	20.4986	3.56256	0.1129816971899388	1040.652373602723	nan	nan
120.36	2.83874242974847	20.4503	3.57509	0.1135496971899388	1038.200327626656	nan	nan
120.79	2.8528224297484703	20.3787	3.58846	0.11411289718993882	1034.5654106103739	nan	nan
121.19	2.8656924297484703	20.3153	3.59937	0.11462769718993882	1031.3467829730519	nan	nan
121.59	2.87902242974847	20.2591	3.61242	0.1151608971899388	1028.4936777172552	nan	nan
122	2.8927324297484702	20.1527	3.62314	0.1157092971899388	1023.0920691902666	nan	nan
122.2	2.90215242974847	20.0157	3.62964	0.11608609718993881	1016.1369905417944	nan	nan