File: original_data/46NTC5.csv
Specimen name:	AWA_5_11_Rz
Specimen ID:	46NTC5
Material:	42CrMoS4
Specimen type:	Round Tensile Specimen
Gauge diameter:	5.034	mm
Gauge length:	25	mm
Parallel length:	30	mm
Original cross-section:	19.902897380768227	mm²
Cross-section after fracture:	10.400494592519463	mm²
Yield stress at 0.2% plastic strain:	1077.8005316843687	MPa
Yield stress at 1% plastic strain:	1131.5887691547725	MPa
Ultimate tensile strength:	1185.053590377785	MPa
Uniform elongation:	4.957434961804152	%
Elongation after fracture:	13.157702603706396	%
Reduction of area:	47.743816422581496	%
Slope of linear-elastic region:	206270.8046436583	MPa
Crosshead seperation speed:	0.029813099575939004	mm/s
Strain rate:	0.0009937699858646335	s-1
Test temperature:	RT	Cel
Machine type:	INSTRON 8852TT
Standard:	DIN EN ISO 6892-1
Date:	2022-09-13 00:00:00
Heat treatment batch:	Batch 5
Time	Displacement	Force	Machine Displacement	Engineering Strain	Engineering Stress	True Strain	True Stress
s	mm	kN	mm		MPa		MPa
0	0.0012150061568678729	0.20313	0	4.860024627471492e-05	10.206051717690132	4.859906532102654e-05	10.206547734317104
0.440001	0.001174359956867873	0.203653	-0.000122071	4.697439827471492e-05	10.232329298787715	4.697329501222723e-05	10.232809956299475
0.860001	0.0015522911568678728	0.237561	0.00196838	6.209164627471491e-05	11.936000847271135	6.2089718668321e-05	11.93674197321368
1.27	0.0033224861568678732	0.423346	0.0152054	0.00013289944627471493	21.270571409822512	0.00013289061592576147	21.273398256984827
1.68	0.005111696156867873	0.569686	0.0266571	0.00020446784627471492	28.623269723054307	0.0002044469455735885	28.629122261367918
2.11	0.0074682061568678735	0.760297	0.0395279	0.0002987282462747149	38.20031754445259	0.0002986836358762238	38.21172905831978
2.52	0.009804316156867872	0.994413	0.0527115	0.0003921726462747149	49.96322801527789	0.00039209576668192895	49.982822226625075
2.92	0.011516306156867872	1.23775	0.064064	0.00046065224627471485	62.189437865263436	0.00046054617860096555	62.21808556951063
3.36	0.013778106156867873	1.54467	0.0773621	0.0005511242462747149	77.61030821033042	0.0005509724330834357	77.65308113294599
3.77001	0.015619706156867872	1.8313	0.0888138	0.0006247882462747149	92.01172899426938	0.0006245931473577569	92.0692168410644
4.17001	0.017875606156867875	2.16477	0.101753	0.000715024246274715	108.76657597058075	0.0007147687382274512	108.844346709584
4.59001	0.020070906156867872	2.49869	0.11409	0.0008028362462747149	125.54403272030305	0.0008025141456399887	125.6448240202744
5.01001	0.022529606156867873	2.86255	0.127129	0.0009011842462747149	143.82579306096534	0.0009007784235475863	143.95540659987984
5.44001	0.024851106156867874	3.25453	0.140289	0.000994044246274715	163.52041302010568	0.0009935505114621066	163.6829595458168
5.84001	0.027302506156867874	3.62865	0.151878	0.001092100246274715	182.317676194537	0.0010915043386218852	182.51678537360928
6.25001	0.029624906156867872	3.99819	0.163811	0.0011849962462747148	200.88482211958603	0.0011842946923939337	201.1228698797313
6.66001	0.031958906156867875	4.40713	0.176193	0.001278356246274715	221.43157931661358	0.001277539844622651	221.71464775915547
7.06001	0.03451320615686787	4.80834	0.188507	0.0013805282462747148	241.58995085038237	0.0013795761932785834	241.92347260154742
7.46001	0.03691400615686787	5.19057	0.200706	0.0014765602462747148	260.7946923856194	0.0014754712030877447	261.1797714608354
7.88001	0.03946260615686787	5.62249	0.213234	0.0015785042462747147	282.49605534483135	0.001577259717937107	282.94197656774907
8.29001	0.04191550615686787	6.03054	0.224907	0.0016766202462747148	302.99809543444616	0.001675216287600985	303.50610817583424
8.71001	0.04443020615686787	6.45599	0.237633	0.001777208246274715	324.37438009594996	0.0017756308802948603	324.95086091913674
9.12001	0.04709640615686787	6.88029	0.250122	0.001883856246274715	345.69288422540365	0.0018820840145005139	346.34411992464436
9.52001	0.04952850615686787	7.3122	0.26226	0.0019811402462747148	367.39374474520645	0.001979180376028547	368.1216032791507
9.95001	0.052142606156867874	7.74665	0.274765	0.002085704246274715	389.22222487492866	0.002083532184834109	390.0340273220948
10.35	0.05445850615686787	8.14845	0.286049	0.002178340246274715	409.41024033383627	0.002175971103069952	410.30207513759245
10.77	0.05736310615686787	8.60061	0.298897	0.0022945242462747146	432.1285406571305	0.002291895845368155	433.1200700711755
11.18	0.05975670615686787	9.02304	0.311012	0.002390268246274715	453.35308861707654	0.002387416099157044	454.4367241091485
11.58	0.06260690615686787	9.45312	0.3237	0.0025042762462747148	474.9620027250084	0.0025011457718086367	476.15143878631574
11.99	0.06473620615686787	9.87083	0.335739	0.002589448246274715	495.9493992838443	0.0025861014015737182	497.2336345860608
12.39	0.06732100615686787	10.291	0.347649	0.0026928402462747148	517.0603959373266	0.002689221047804996	518.4527569812614
12.81	0.06987750615686787	10.7148	0.360069	0.002795100246274715	538.3537780963237	0.00279120121734272	539.8585308740637
13.25	0.07240300615686787	11.1465	0.372917	0.002896120246274715	560.0440873885348	0.0028919345695689134	561.6660424088271
13.66	0.07521210615686787	11.6011	0.386032	0.0030084842462747147	582.8849829276571	0.0030039678136882016	584.6385832161851
14.07	0.07760490615686787	11.9981	0.397141	0.0031041962462747146	602.8318274701816	0.0030993881766651684	604.7031357661494
14.48	0.08015180615686787	12.4345	0.409523	0.003206072246274715	624.7582832846845	0.003200943755268775	626.7613034773537
14.9	0.08279440615686787	12.8795	0.422485	0.003311776246274715	647.1168369910405	0.003306304393029431	649.2599431603518
15.31	0.08514510615686786	13.2538	0.433777	0.0034058042462747147	665.9231440748362	0.0034000176299921227	668.1911479466189
15.73	0.08781970615686788	13.6847	0.44619	0.0035127882462747152	687.5732582143166	0.003506632816578573	689.9885574742246
16.14	0.09021760615686787	14.106	0.459389	0.003608704246274715	708.7410305210309	0.0036022084959102005	711.2986672873812
16.54	0.09278800615686787	14.523	0.471252	0.003711520246274715	729.6927538818185	0.003704649550242692	732.4010233114108
16.96	0.09532920615686787	14.9297	0.483727	0.0038131682462747146	750.1269646512006	0.0038059165490193832	752.987324973483
17.37	0.09771070615686787	15.3247	0.494797	0.003908428246274715	769.9733213118986	0.0039008101839116223	772.982706789792
17.79	0.10029930615686787	15.737	0.507317	0.004011972246274715	790.6888981503944	0.0040039457465230735	793.8611200652114
18.21	0.10294300615686787	16.169	0.519638	0.004117720246274715	812.3942806248793	0.004109265637457461	815.7394930021662
18.63	0.10556700615686787	16.6209	0.533493	0.0042226802462747145	835.0995175235362	0.00421378975106874	838.6258757598564
19.06	0.10808500615686788	17.0133	0.545303	0.004323400246274715	854.81523993786	0.004314081201747886	858.5109483567267
19.46	0.11067200615686787	17.4389	0.557785	0.004426880246274714	876.199061190501	0.004417110434496836	880.0778895062897
19.88	0.11319900615686787	17.8496	0.570435	0.004527960246274715	896.8342477235356	0.004517739874290892	900.8950775447254
20.3	0.11575700615686788	18.2484	0.582787	0.004630280246274715	916.8715313597038	0.004619593474496591	921.1169034997304
20.71	0.11824900615686787	18.6446	0.594749	0.004729960246274715	936.7781807494977	0.004718809133364481	941.2091043040203
21.12	0.12094100615686787	19.029	0.606766	0.004837640246274715	956.0919516365161	0.004825976466353536	960.7171805408922
21.52	0.12356600615686787	19.4032	0.618523	0.004942640246274715	974.8932343262204	0.004930465500418315	979.711780862022
21.92	0.12671000615686787	19.7598	0.630722	0.005068400246274715	992.8102236558533	0.005055599141607925	997.8421832379346
22.33	0.13020900615686787	20.0916	0.642273	0.005208360246274715	1009.4811632508396	0.005194843650599711	1014.7389048108784
22.75	0.13480000615686788	20.3896	0.653992	0.005392000246274715	1024.4538576429613	0.005377515457607244	1029.977713095669
23.17	0.14070800615686788	20.6365	0.667267	0.005628320246274715	1036.8590866544205	0.005612540433416632	1042.6948616443715
23.59	0.14745300615686788	20.8157	0.679459	0.005898120246274715	1045.8628008660587	0.0058807944281806445	1052.0314254266723
24.03	0.15528300615686788	20.9882	0.693108	0.006211320246274715	1054.5298806735786	0.006192109505011646	1061.0799034717081
24.44	0.16310000615686787	21.1424	0.706078	0.0065240002462747144	1062.2774963623879	0.006502811065551487	1069.2077950102682
24.84	0.17065400615686788	21.2318	0.717972	0.006826160246274715	1066.7693046800243	0.006802967499536704	1074.0512428995771
25.25	0.17874800615686787	21.3634	0.730293	0.007149920246274715	1073.381407304196	0.007124480754758564	1081.0559987602553
25.65	0.18635700615686787	21.47	0.741776	0.007454280246274715	1078.737411405539	0.007426634400860435	1086.7786223822968
26.07	0.19477900615686788	21.5515	0.754478	0.007791160246274715	1082.8322925899615	0.007760965888597954	1091.268812501371
26.48	0.20397300615686786	21.6413	0.767273	0.008158920246274714	1087.3441984839635	0.008125816196785674	1096.2157530796435
26.9	0.21243700615686786	21.7383	0.779465	0.008497480246274714	1092.2178607525398	0.008461579892671697	1101.4989604489128
27.31	0.22097300615686788	21.8187	0.791481	0.008838920246274716	1096.2574736019578	0.008800085660154907	1105.947205980508
27.71	0.22917400615686787	21.8738	0.80291	0.009166960246274714	1099.025914746273	0.009125198689864675	1109.1006416163777
28.13	0.23867800615686788	21.9382	0.815788	0.009547120246274715	1102.2616245410802	0.0095018344979442	1112.785048813428
28.55	0.24797000615686787	21.9968	0.828392	0.009918800246274714	1105.2059194785916	0.00986993182548522	1116.1682362249
28.99	0.2581170061568679	22.0518	0.841888	0.010324680246274715	1107.9693362288153	0.010271744784546882	1119.408765348055
29.4	0.2678790061568679	22.1225	0.85479	0.010715160246274716	1111.5215828513758	0.010658159734945561	1123.4317147288211
29.8	0.27707100615686786	22.1566	0.866417	0.011082840246274714	1113.2349012365146	0.011021875599699468	1125.5727058034963
30.22	0.2868880061568679	22.1987	0.879333	0.011475520246274715	1115.3501711489585	0.011410175895605999	1128.1493946196642
30.65	0.2968960061568679	22.242	0.891693	0.011875840246274716	1117.5257337904984	0.011805875834865205	1130.7972908760953
31.05	0.30632700615686786	22.2773	0.902924	0.012253080246274715	1119.2993449047328	0.012178618895397236	1133.0142095974534
31.46	0.3160960061568679	22.3092	0.916092	0.012643840246274716	1120.9021266198627	0.012564574349125291	1135.0746340405537
31.86	0.32603100615686786	22.3326	0.928154	0.013041240246274715	1122.0778348372305	0.012956935441108633	1136.7111214563627
32.27	0.33547100615686787	22.3806	0.939789	0.013418840246274715	1124.4895440010623	0.013329605012056581	1139.578889550619
32.67	0.3450100061568679	22.41	0.951675	0.013800400246274715	1125.9667158639093	0.013706041854095574	1141.5055072068149
33.09	0.3550290061568679	22.428	0.964584	0.014201160246274715	1126.871106800346	0.014101268379581441	1142.873983964915
33.52	0.3656190061568679	22.454	0.977074	0.014624760246274715	1128.1774492640882	0.014518849801305923	1144.6767739748293
33.92	0.3759030061568679	22.5061	0.989952	0.015036120246274716	1130.7951585856638	0.014924198310099768	1147.797930564063
34.33	0.3856550061568679	22.5118	1.001	0.015426200246274715	1131.0815490488687	0.015308426080161726	1148.5298395193631
34.73	0.39604000615686785	22.5396	1.0135	0.015841600246274713	1132.4783306062545	0.015717431732385632	1150.4185996072872
35.15	0.40562500615686786	22.5676	1.0257	0.016225000246274716	1133.885160951823	0.016094781573632522	1152.2824479675137
35.58	0.4163300061568679	22.5929	1.03919	0.016653200246274716	1135.1563326569262	0.016516056204084112	1154.0603183754888
35.9801	0.4262620061568679	22.6025	1.05141	0.017050480246274716	1135.6386744896924	0.016906752261591714	1155.0018592759845
36.3901	0.4362310061568679	22.6146	1.06362	0.017449240246274714	1136.2466261747416	0.017298750354380447	1156.0732665338837
36.7901	0.44679300615686784	22.6647	1.07628	0.017871720246274713	1138.763847614491	0.017713898642310107	1159.1155165256287
37.2001	0.4562440061568679	22.6681	1.08791	0.018249760246274716	1138.9346770135955	0.01808523208971568	1159.719961805262
37.6001	0.46601500615686786	22.7021	1.09981	0.018640600246274716	1140.6429710046432	0.01846899354529256	1161.9052406508638
38.0201	0.4768550061568679	22.7185	1.11294	0.019074200246274715	1141.4669716356188	0.018894568318012936	1163.2395412271055
38.4501	0.48707200615686785	22.7298	1.12582	0.019482880246274713	1142.0347281679376	0.019295518587579382	1164.2848540139205
38.8501	0.4970840061568679	22.7477	1.13727	0.019883360246274715	1142.934094710283	0.019688268057680553	1165.6594650531574
39.2701	0.5077790061568679	22.757	1.15091	0.020311160246274714	1143.4013633607756	0.02010763984009918	1166.6251716778052
39.6801	0.5174730061568679	22.7866	1.16241	0.020698920246274715	1144.888584011805	0.020487608570652106	1168.5865415031358
40.0901	0.5277150061568678	22.8076	1.17513	0.021108600246274714	1145.9437067709816	0.0208889000747593	1170.1329743819447
40.4901	0.5375520061568678	22.8309	1.18721	0.021502080246274712	1147.114390594258	0.021274171735800564	1171.7797362724723
40.8901	0.5474050061568678	22.8455	1.20011	0.021896200246274714	1147.8479521315903	0.021659921306650103	1172.9814607437402
41.3301	0.5579990061568678	22.8608	1.21251	0.022319960246274712	1148.6166844275617	0.022074515432515665	1174.2537631621929
41.7401	0.5683040061568678	22.8766	1.22498	0.022732160246274714	1149.4105386939893	0.022477634748108218	1175.539123248338
42.1401	0.5782870061568679	22.8986	1.23764	0.023131480246274715	1150.515905394079	0.02286800290087024	1177.1290413327272
42.5601	0.5885100061568679	22.9084	1.24937	0.023540400246274715	1151.008296015028	0.023267597979435298	1178.1034919900044
43.0001	0.5993780061568679	22.9309	1.26244	0.023975120246274715	1152.1387846855741	0.023692229687650765	1179.7614505888077
43.4101	0.6098310061568679	22.9589	1.27568	0.024393240246274716	1153.5456150311427	0.024100476577098528	1181.684330353634
43.8101	0.6195110061568678	22.9638	1.28689	0.024780440246274713	1153.791810341617	0.0244783850075007	1182.3832793544286
44.2301	0.6297120061568678	22.9893	1.29977	0.025188480246274715	1155.0730308349025	0.024876478853031497	1184.1675650550922
44.6401	0.6393600061568678	22.9935	1.31147	0.025574400246274713	1155.284055386738	0.025252846114431203	1184.8297522173377
45.0401	0.6493060061568678	23.019	1.32397	0.025972240246274713	1156.5652758800234	0.025640690092369224	1186.6038670856783
45.4801	0.6603750061568678	23.0492	1.33741	0.026415000246274713	1158.0826428956009	0.026072148637942886	1188.6733961928946
45.9001	0.6706100061568678	23.0605	1.34933	0.026824400246274714	1158.6503994279196	0.02647093311999349	1189.7305014876802
46.3101	0.6808240061568679	23.058	1.36172	0.027232960246274716	1158.5247895756368	0.026868740905935593	1190.0748491144739
46.7201	0.6909710061568679	23.0778	1.37417	0.027638840246274717	1159.5196196057173	0.027263782587057576	1191.5673971344208
47.1201	0.7007810061568679	23.0901	1.38601	0.028031240246274715	1160.137620078949	0.02764555591585187	1192.6577164261237
47.5301	0.7110290061568678	23.0998	1.39783	0.028441160246274712	1160.6249863058067	0.02804421918537184	1193.6345075271604
47.9301	0.7207740061568678	23.115	1.40951	0.02883096024627471	1161.3886942076867	0.02842316760039371	1194.8726454808614
48.3501	0.7313450061568678	23.139	1.42296	0.029253800246274712	1162.5945487896026	0.028834073909080868	1196.6048574873016
48.7601	0.7410510061568679	23.1449	1.43438	0.029642040246274717	1162.8909880409904	0.029211208096217477	1197.3614495105314
49.1701	0.7514060061568679	23.1623	1.44658	0.030056240246274717	1163.7652326128791	0.029613402931748845	1198.7436400345537
49.5701	0.7613460061568679	23.1894	1.45834	0.030453840246274715	1165.1268434116257	0.02999932679467858	1200.6094301675296
49.9701	0.7712770061568679	23.186	1.4711	0.030851080246274715	1164.956014012521	0.030384752551895284	1200.8961654842017
50.4101	0.7822900061568678	23.1993	1.48347	0.03129160024627471	1165.624258426666	0.03081199748588375	1202.0985067587137
50.8201	0.7922830061568679	23.2262	1.49545	0.03169132024627472	1166.97582043723	0.03119951402907142	1203.9588248823654
51.2201	0.8021170061568679	23.2382	1.50795	0.03208468024627471	1167.578747728188	0.031580718195288585	1205.0401385113928
51.6301	0.8126100061568678	23.2505	1.52029	0.03250440024627471	1168.19674820142	0.031987307583702905	1206.1682828713554
52.0301	0.8220350061568679	23.2483	1.53193	0.032881400246274714	1168.086211531411	0.0323523725551936	1206.49452177493
52.4501	0.8324570061568679	23.2623	1.54414	0.033298280246274715	1168.7896267041951	0.03275589990530038	1207.7083112431303
52.8601	0.8424860061568679	23.264	1.55651	0.03369944024627471	1168.8750414037474	0.03314405708714883	1208.2654760168948
53.2801	0.8528630061568678	23.2854	1.56926	0.03411452024627471	1169.950261739289	0.03354552454360823	1209.8625536305285
53.6901	0.8635740061568679	23.3002	1.5818	0.03454296024627471	1170.693872064804	0.03395974488715587	1211.133103948096
54.0901	0.8736510061568679	23.3133	1.59351	0.034946040246274714	1171.3520676907665	0.034349290330500666	1212.286184190845
54.5101	0.8841660061568679	23.3277	1.60664	0.035366640246274714	1172.075580439916	0.034755605772365625	1213.527955834778
54.9201	0.8942200061568679	23.3447	1.61821	0.03576880024627472	1172.9297274354396	0.035143953146653015	1214.8840165589954
55.3301	0.9043920061568679	23.3378	1.63009	0.03617568024627472	1172.5830442431388	0.035536704988279	1215.002033513882
55.7401	0.9143260061568679	23.3445	1.64198	0.03657304024627472	1172.919678647257	0.03592011856942303	1215.8169172600706
56.1401	0.9245900061568678	23.3648	1.65444	0.036983600246274714	1173.939630647794	0.03631611450929522	1217.3561446609315
56.5401	0.9347480061568678	23.3794	1.66597	0.037389920246274716	1174.6731921851263	0.036707866526164354	1218.594129156365
56.9601	0.9456820061568678	23.3864	1.67814	0.037827280246274714	1175.0248997715182	0.03712937421834393	1219.4728959515262
57.3801	0.9564890061568678	23.3957	1.69117	0.038259560246274714	1175.4921684220108	0.03754581152512313	1220.4659818587768
57.7901	0.9677090061568678	23.4073	1.70358	0.03870836024627471	1176.0749981366032	0.03797797997852782	1221.5989328411117
58.2101	0.9784790061568679	23.4101	1.71564	0.039139160246274715	1176.2156811711602	0.03839263986278206	1222.2517752006995
58.6201	0.9891310061568679	23.4243	1.72745	0.03956524024627472	1176.929145132127	0.03880258752620759	1223.4946295121222
59.0201	0.9994840061568678	23.4218	1.73919	0.039979360246274714	1176.803535279844	0.03920086703930502	1223.8513877558867
59.4301	1.010315006156868	23.449	1.75191	0.040412600246274716	1178.170170472682	0.03961736548237755	1225.78309059408
59.8301	1.020915006156868	23.4553	1.76416	0.04083660024627472	1178.4867073004352	0.040024813091981866	1226.6120978620118
60.2501	1.031455006156868	23.4517	1.77655	0.04125820024627472	1178.3058291131474	0.040429789854483034	1226.9206069620504
60.6901	1.042775006156868	23.4584	1.78959	0.041711000246274714	1178.642463517266	0.04086455385101759	1227.8048196033044
61.1101	1.0538350061568678	23.4628	1.80175	0.04215340024627471	1178.8635368572839	0.04128914962274043	1228.556643362168
61.5301	1.065145006156868	23.4817	1.81446	0.042605800246274715	1179.8131473405424	0.04172315658814391	1230.0800306240624
61.9401	1.0758850061568679	23.4863	1.82673	0.04303540024627472	1180.0442694687429	0.042135116234869444	1230.827946913653
62.3401	1.086265006156868	23.4818	1.83852	0.043450600246274715	1179.8181717346338	0.042533105970130006	1231.081979477966
62.7701	1.097785006156868	23.4889	1.85128	0.04391140024627472	1180.1749037151174	0.042974620194665004	1231.9980362727608
63.1701	1.1083550061568679	23.4911	1.86373	0.04433420024627471	1180.285440385126	0.0433795534129392	1232.612451446923
63.5801	1.119205006156868	23.5149	1.87632	0.04476820024627472	1181.4812461788595	0.04379504286538655	1234.374035195013
63.9901	1.1298950061568678	23.513	1.88844	0.04519580024627471	1181.3857826911244	0.04420423652218208	1234.7794585394213
64.4001	1.140425006156868	23.5076	1.90063	0.045617000246274714	1181.1144654101931	0.0446071420387341	1234.9933642696885
64.8301	1.152045006156868	23.5074	1.91354	0.046081800246274715	1181.1044166220106	0.04505156549735125	1235.5318344187788
65.2301	1.1632450061568678	23.5294	1.92645	0.04652980024627471	1182.2097833221	0.045479738605766554	1237.217768389269
65.6401	1.1739550061568678	23.5335	1.9382	0.04695820024627471	1182.415783479844	0.04588900773544784	1237.9399006148465
66.0401	1.1848450061568678	23.5369	1.9501	0.047393800246274716	1182.5866128789487	0.0463049836613465	1238.6338865836524
66.4501	1.196005006156868	23.536	1.96314	0.047840200246274715	1182.541393332127	0.04673109359145398	1239.1144103886447
66.8601	1.2064950061568678	23.5317	1.97442	0.048259800246274714	1182.3253443862004	0.04713145617482888	1239.3841293323862
67.2601	1.2175150061568678	23.5341	1.98688	0.04870060024627471	1182.445929844392	0.04755187422982806	1240.031756386578
67.6701	1.2284250061568678	23.5379	1.9987	0.04913700024627471	1182.636856819862	0.04796792169336152	1240.7480843446733
68.0701	1.2393550061568679	23.5599	2.01141	0.049574200246274715	1183.7422235199515	0.04838455834753445	1242.4252975487
68.4801	1.249805006156868	23.5454	2.02296	0.049992200246274716	1183.0136863767107	0.04878273580496054	1242.1551434801388
68.8801	1.2610450061568679	23.5697	2.03524	0.05044180024627472	1184.2346141409005	0.049210837813175215	1243.96953999212
69.3001	1.272575006156868	23.5644	2.04794	0.05090300024627472	1183.9683212540606	0.04964979481565981	1244.2358610024376
69.7201	1.2837850061568679	23.5576	2.0603	0.051351400246274714	1183.6266624558514	0.05007638448691453	1244.4075489417842
70.1301	1.2952750061568679	23.5713	2.07257	0.05181100024627471	1184.3150044463614	0.05051344061458993	1245.6755494333986
70.5301	1.3064150061568678	23.5714	2.08512	0.05225660024627471	1184.320028840453	0.05093700115661595	1246.2085671512252
70.9701	1.3181450061568678	23.5769	2.0977	0.05272580024627471	1184.5963705154752	0.05138280061570956	1247.0551621197362
71.3901	1.329725006156868	23.5722	2.11009	0.053189000246274716	1184.3602239931831	0.05182270445926614	1247.3551602388345
71.8201	1.341245006156868	23.5664	2.12287	0.05364980024627472	1184.068809135887	0.05226013707844891	1247.5938642238716
72.2201	1.352295006156868	23.5652	2.13464	0.05409180024627472	1184.0085164067914	0.05267954333429717	1248.0536685661557
72.6401	1.3642150061568679	23.5723	2.14778	0.05456860024627472	1184.3652483872747	0.05313177358248177	1248.9944021720996
73.0601	1.375985006156868	23.5617	2.16012	0.05503940024627472	1183.832662613595	0.05357811243567731	1248.9901023557975
73.4701	1.3874550061568678	23.586	2.1726	0.05549820024627471	1185.053590377785	nan	nan
73.8801	1.398295006156868	23.5656	2.18403	0.05593180024627472	1184.0286139831564	nan	nan
74.2801	1.410285006156868	23.5821	2.1971	0.056411400246274716	1184.8576390082237	nan	nan
74.6801	1.421785006156868	23.5802	2.20961	0.05687140024627472	1184.7621755204887	nan	nan
75.0901	1.4330150061568678	23.5753	2.22189	0.057320600246274715	1184.515980210014	nan	nan
75.5101	1.4446750061568678	23.5681	2.23424	0.057787000246274714	1184.1542238354396	nan	nan
75.9201	1.456485006156868	23.5745	2.24644	0.05825940024627472	1184.4757850572837	nan	nan
76.3301	1.4674850061568678	23.5656	2.258	0.058699400246274715	1184.0286139831564	nan	nan
76.7301	1.4789650061568678	23.5704	2.27028	0.05915860024627471	1184.2697848995397	nan	nan
77.1401	1.4908950061568678	23.5604	2.28281	0.05963580024627471	1183.7673454904082	nan	nan
77.5401	1.5027250061568678	23.5703	2.29501	0.06010900024627471	1184.2647605054483	nan	nan
77.9501	1.5141850061568678	23.5579	2.30724	0.06056740024627471	1183.6417356381253	nan	nan
78.3501	1.5256550061568679	23.5642	2.31908	0.06102620024627472	1183.958272465878	nan	nan
78.7701	1.537795006156868	23.562	2.33186	0.061511800246274714	1183.847735795869	nan	nan
79.1801	1.549665006156868	23.5506	2.34404	0.06198660024627472	1183.274954869459	nan	nan
79.5801	1.5610050061568679	23.554	2.35582	0.06244020024627472	1183.4457842685638	nan	nan
80.0101	1.573245006156868	23.5532	2.36868	0.06292980024627472	1183.4055891158334	nan	nan
80.4101	1.5848950061568678	23.5387	2.38047	0.06339580024627471	1182.6770519725924	nan	nan
80.8301	1.597285006156868	23.5356	2.39389	0.06389140024627472	1182.5212957557617	nan	nan
81.2401	1.6099350061568678	23.5363	2.40586	0.06439740024627472	1182.5564665144009	nan	nan
81.6401	1.621475006156868	23.5199	2.41763	0.06485900024627472	1181.7324658834252	nan	nan
82.0501	1.633105006156868	23.5185	2.43062	0.06532420024627472	1181.6621243661466	nan	nan
82.4501	1.6449150061568678	23.5158	2.44194	0.0657966002462747	1181.5264657256812	nan	nan
82.8601	1.6571250061568679	23.4961	2.45387	0.06628500024627472	1180.5366600896918	nan	nan
83.2601	1.669005006156868	23.4987	2.46574	0.06676020024627471	1180.667294336066	nan	nan
83.6901	1.6815250061568678	23.4862	2.47871	0.06726100024627471	1180.0392450746517	nan	nan
84.0901	1.693535006156868	23.4637	2.4902	0.06774140024627472	1178.9087564041056	nan	nan
84.5101	1.7064250061568678	23.464	2.50286	0.06825700024627471	1178.9238295863795	nan	nan
84.9301	1.7191050061568678	23.4486	2.51573	0.0687642002462747	1178.1500728963167	nan	nan
85.3401	1.7317450061568678	23.4321	2.52862	0.06926980024627472	1177.3210478712497	nan	nan
85.7501	1.7440850061568678	23.4285	2.54037	0.06976340024627471	1177.1401696839623	nan	nan
86.1501	1.756035006156868	23.419	2.5527	0.07024140024627472	1176.6628522452872	nan	nan
86.5701	1.7686650061568678	23.3973	2.56534	0.07074660024627472	1175.572558727472	nan	nan
86.9801	1.781215006156868	23.3884	2.57766	0.07124860024627472	1175.1253876533447	nan	nan
87.3801	1.7933650061568678	23.362	2.59029	0.0717346002462747	1173.7989476132373	nan	nan
87.8001	1.8066850061568678	23.3454	2.60299	0.0722674002462747	1172.9648981940788	nan	nan
88.2101	1.8191250061568678	23.3325	2.61481	0.0727650002462747	1172.316751356299	nan	nan
88.6201	1.8319150061568679	23.3163	2.62733	0.07327660024627472	1171.5027995135058	nan	nan
89.0301	1.8444550061568679	23.2874	2.63927	0.07377820024627471	1170.0507496211155	nan	nan
89.4301	1.856805006156868	23.2677	2.65201	0.07427220024627472	1169.0609439851262	nan	nan
89.8301	1.8690650061568679	23.2361	2.6638	0.07476260024627472	1167.4732354522705	nan	nan
90.2501	1.882395006156868	23.2229	2.67679	0.07529580024627472	1166.8100154322167	nan	nan
90.6701	1.895445006156868	23.1854	2.68896	0.07581780024627471	1164.9258676479733	nan	nan
91.1101	1.9089450061568678	23.161	2.70212	0.07635780024627471	1163.699915489692	nan	nan
91.5301	1.9219050061568679	23.1402	2.71475	0.07687620024627471	1162.6548415186985	nan	nan
91.9401	1.9351850061568678	23.1239	2.72726	0.07740740024627471	1161.8358652818138	nan	nan
92.3501	1.9481550061568678	23.088	2.73978	0.07792620024627471	1160.0321078030315	nan	nan
92.7501	1.960825006156868	23.063	2.75143	0.07843300024627471	1158.7760092802025	nan	nan
93.1601	1.9736250061568679	23.0367	2.76427	0.07894500024627471	1157.4545936341865	nan	nan
93.5601	1.986445006156868	23.0074	2.77657	0.07945780024627472	1155.982446165431	nan	nan
93.9801	1.9997250061568679	22.9548	2.78884	0.07998900024627471	1153.3396148733984	nan	nan
94.3901	2.011915006156868	22.9327	2.80095	0.08047660024627472	1152.2292237792178	nan	nan
94.7901	2.024475006156868	22.9185	2.81312	0.08097900024627473	1151.515759818251	nan	nan
95.2201	2.0384550061568683	22.8816	2.82613	0.08153820024627473	1149.661758398555	nan	nan
95.6201	2.051305006156868	22.8545	2.8385	0.08205220024627473	1148.3001475998087	nan	nan
96.0401	2.064465006156868	22.817	2.8506	0.08257860024627472	1146.415999815565	nan	nan
96.4601	2.077715006156868	22.7884	2.86329	0.08310860024627471	1144.9790231054487	nan	nan
96.8701	2.090535006156868	22.752	2.87558	0.08362140024627472	1143.1501436562098	nan	nan
97.2701	2.103345006156868	22.733	2.88798	0.08413380024627472	1142.1955087788597	nan	nan
97.7001	2.117075006156868	22.6727	2.90051	0.08468300024627473	1139.1657991417962	nan	nan
98.1001	2.129415006156868	22.6566	2.91217	0.08517660024627473	1138.3568716930945	nan	nan
98.5201	2.142795006156868	22.6128	2.92554	0.08571180024627471	1136.1561870810979	nan	nan
98.9401	2.156115006156868	22.5697	2.93778	0.08624460024627473	1133.990673227741	nan	nan
99.3501	2.168735006156868	22.5333	2.94981	0.08674940024627473	1132.1617937785018	nan	nan
99.7501	2.181615006156868	22.5102	2.96213	0.08726460024627473	1131.0011587434078	nan	nan
100.18	2.195825006156868	22.4513	2.97543	0.08783300024627472	1128.0417906236225	nan	nan
100.58	2.2083350061568683	22.4376	2.98767	0.08833340024627473	1127.3534486331123	nan	nan
101	2.222315006156868	22.3974	3.00042	0.08889260024627471	1125.3336422084035	nan	nan
101.42	2.235135006156868	22.3582	3.01243	0.08940540024627472	1123.3640797246076	nan	nan
101.84	2.248765006156868	22.3137	3.0257	0.08995060024627471	1121.128224353972	nan	nan
102.27	2.261515006156868	22.2823	3.03768	0.09046060024627472	1119.5505646092986	nan	nan
102.67	2.274165006156868	22.2499	3.04952	0.09096660024627472	1117.9226609237123	nan	nan
103.09	2.288175006156868	22.2127	3.06257	0.09152700024627473	1116.0535863217428	nan	nan
103.51	2.301435006156868	22.1653	3.07495	0.09205740024627472	1113.6720235224589	nan	nan
103.93	2.314565006156868	22.1419	3.08734	0.09258260024627471	1112.496315305091	nan	nan
104.36	2.3285850061568683	22.0929	3.10053	0.09314340024627472	1110.0343622003463	nan	nan
104.76	2.3413950061568682	22.0571	3.11269	0.09365580024627473	1108.235629115655	nan	nan
105.17	2.354605006156868	22.0314	3.12514	0.09418420024627473	1106.944359834187	nan	nan
105.57	2.366625006156868	21.9707	3.13625	0.09466500024627472	1103.894552620758	nan	nan
105.99	2.379665006156868	21.9325	3.14899	0.09518660024627472	1101.9752340778755	nan	nan
106.41	2.393445006156868	21.9031	3.16245	0.09573780024627472	1100.4980622150283	nan	nan
106.84	2.407535006156868	21.8744	3.1757	0.09630140024627472	1099.0560611108208	nan	nan
107.24	2.420665006156868	21.8216	3.18762	0.09682660024627472	1096.403181030606	nan	nan
107.65	2.433415006156868	21.7875	3.19988	0.09733660024627472	1094.6898626454672	nan	nan
108.05	2.446115006156868	21.7362	3.21119	0.09784460024627473	1092.1123484766222	nan	nan
108.47	2.459245006156868	21.6927	3.22356	0.09836980024627472	1089.9267370468995	nan	nan
108.91	2.473325006156868	21.6646	3.2365	0.09893300024627472	1088.5148823072398	nan	nan
109.32	2.486845006156868	21.6339	3.25024	0.09947380024627472	1086.972393321206	nan	nan
109.73	2.499505006156868	21.5752	3.26162	0.09998020024627471	1084.0230739896033	nan	nan
110.13	2.511985006156868	21.5428	3.27376	0.10047940024627472	1082.395170304017	nan	nan
110.53	2.525015006156868	21.5028	3.28565	0.10100060024627472	1080.3854126674905	nan	nan
110.95	2.538675006156868	21.4595	3.29922	0.10154700024627472	1078.2098500259508	nan	nan
111.39	2.552585006156868	21.3999	3.31213	0.10210340024627472	1075.2153111475263	nan	nan
111.81	2.566005006156868	21.3788	3.32439	0.10264020024627472	1074.1551639942588	nan	nan
112.23	2.579775006156868	21.3234	3.33774	0.10319100024627473	1071.3716496676698	nan	nan
112.64	2.5931550061568682	21.2779	3.34981	0.10372620024627473	1069.0855503561208	nan	nan
113.04	2.605825006156868	21.2397	3.36186	0.10423300024627473	1067.1662318132385	nan	nan
113.47	2.620065006156868	21.1933	3.37542	0.10480260024627473	1064.8349129548676	nan	nan
113.87	2.631905006156868	21.1498	3.38705	0.10527620024627472	1062.6493015251453	nan	nan
114.28	2.645275006156868	21.1242	3.39968	0.10581100024627473	1061.3630566377683	nan	nan
114.69	2.658795006156868	21.0828	3.41217	0.10635180024627472	1059.2829574839636	nan	nan
115.09	2.6717250061568683	21.0249	3.42388	0.10686900024627473	1056.3738333050915	nan	nan
115.5	2.684495006156868	20.9776	3.43618	0.10737980024627472	1053.997294899899	nan	nan
115.9	2.697585006156868	20.944	3.44828	0.10790340024627472	1052.309098485217	nan	nan
116.32	2.711255006156868	20.8974	3.46049	0.10845020024627472	1049.9677308386638	nan	nan
116.74	2.724955006156868	20.8503	3.47353	0.10899820024627471	1047.601241221654	nan	nan
117.16	2.738415006156868	20.8081	3.48615	0.10953660024627472	1045.4809469151185	nan	nan
117.57	2.750735006156868	20.7486	3.49775	0.11002940024627472	1042.4914324307856	nan	nan
117.97	2.7640550061568683	20.7129	3.51033	0.11056220024627474	1040.697723740186	nan	nan
118.4	2.778245006156868	20.6697	3.52412	0.11112980024627472	1038.527185492737	nan	nan
118.81	2.791685006156868	20.6239	3.53624	0.11166740024627472	1036.2260129989145	nan	nan
119.21	2.804365006156868	20.5763	3.54837	0.11217460024627472	1033.8344014114482	nan	nan
119.62	2.817545006156868	20.5295	3.56065	0.11270180024627471	1031.4829849767123	nan	nan
120.02	2.830375006156868	20.4894	3.57228	0.11321500024627472	1029.4682029460946	nan	nan
120.43	2.844365006156868	20.4453	3.58488	0.11377460024627473	1027.2524451518243	nan	nan
120.83	2.857005006156868	20.3897	3.59677	0.11428020024627472	1024.4588820370527	nan	nan
121.25	2.869965006156868	20.3453	3.60873	0.11479860024627472	1022.2280510605084	nan	nan
121.67	2.883805006156868	20.3065	3.62176	0.11535220024627472	1020.2785861530778	nan	nan
122.09	2.897565006156868	20.2521	3.63432	0.11590260024627472	1017.5453157674017	nan	nan
122.52	2.911445006156868	20.2005	3.64689	0.11645780024627472	1014.9527284162828	nan	nan
122.92	2.924405006156868	20.1433	3.65932	0.11697620024627473	1012.07877499605	nan	nan
123.33	2.938085006156868	20.0954	3.67198	0.11752340024627472	1009.6720902263097	nan	nan
123.73	2.950855006156868	20.0536	3.68379	0.11803420024627473	1007.5718934961395	nan	nan
124.15	2.964825006156868	19.9958	3.69595	0.11859300024627473	1004.667793711359	nan	nan
124.56	2.9775850061568683	19.9555	3.70813	0.11910340024627473	1002.6429628925587	nan	nan
124.97	2.991045006156868	19.9037	3.72068	0.11964180024627473	1000.040326753257	nan	nan
125.37	3.004045006156868	19.849	3.73186	0.12016180024627472	997.2919831853071	nan	nan
125.77	3.017285006156868	19.8196	3.74475	0.12069140024627473	995.8148113224604	nan	nan
126.21	3.031575006156868	19.7431	3.75748	0.12126300024627472	991.9711498426035	nan	nan
126.62	3.044465006156868	19.7023	3.76945	0.12177860024627472	989.9211970533465	nan	nan
127.03	3.058145006156868	19.6434	3.78228	0.12232580024627472	986.9618289335616	nan	nan
127.43	3.071145006156868	19.5965	3.79436	0.12284580024627471	984.6053881047343	nan	nan
127.84	3.084465006156868	19.5531	3.80624	0.12337860024627473	982.4248010691033	nan	nan
128.24	3.0980450061568683	19.4894	3.8179	0.12392180024627474	979.2242620329349	nan	nan
128.65	3.1115950061568682	19.4286	3.83053	0.12446380024627474	976.1694304254147	nan	nan
129.05	3.124025006156868	19.3837	3.84267	0.12496100024627471	973.9134774784139	nan	nan
129.46	3.137475006156868	19.3305	3.85452	0.12549900024627472	971.2404998218339	nan	nan
129.89	3.151835006156868	19.2769	3.86715	0.12607340024627472	968.5474245888886	nan	nan
130.31	3.1654250061568683	19.2247	3.87923	0.12661700024627473	965.9246908732214	nan	nan
130.72	3.1786350061568682	19.1527	3.89164	0.12714540024627474	962.307127127474	nan	nan
131.14	3.1922650061568683	19.0959	3.90421	0.12769060024627474	959.4532712836066	nan	nan
131.56	3.206135006156868	19.0418	3.91702	0.12824540024627473	956.7350740802045	nan	nan
131.98	3.219965006156868	18.9841	3.92978	0.12879860024627474	953.8359986895153	nan	nan
132.4	3.233835006156868	18.9224	3.94268	0.12935340024627473	950.7359475351734	nan	nan
132.81	3.247365006156868	18.855	3.9545	0.12989460024627472	947.3495059176264	nan	nan
133.23	3.2610750061568683	18.7966	3.96734	0.13044300024627473	944.4152597682979	nan	nan
133.64	3.274435006156868	18.7552	3.97984	0.13097740024627472	942.3351606144929	nan	nan
134.05	3.288275006156868	18.6809	3.99163	0.13153100024627473	938.6020358046453	nan	nan
134.45	3.301165006156868	18.6228	4.0032	0.1320466002462747	935.6828628375908	nan	nan
134.86	3.314615006156868	18.5688	4.01541	0.13258460024627472	932.9696900282801	nan	nan
135.26	3.328025006156868	18.5056	4.02771	0.1331210002462747	929.7942729625685	nan	nan
135.67	3.342055006156868	18.4338	4.04009	0.13368220024627472	926.1867580050036	nan	nan
136.07	3.354995006156868	18.3758	4.05238	0.13419980024627473	923.2726094320404	nan	nan
136.48	3.368455006156868	18.315	4.0643	0.13473820024627473	920.2177778245201	nan	nan
136.88	3.381635006156868	18.2346	4.07622	0.13526540024627473	916.178164975102	nan	nan
137.3	3.395545006156868	18.1637	4.08879	0.13582180024627472	912.615869564359	nan	nan
137.52	3.404075006156868	18.0935	4.09513	0.13616300024627473	909.0887449122553	nan	nan