File: original_data/46NT9T.csv
Specimen name:	AWA_2_11_Rz
Specimen ID:	46NT9T
Material:	42CrMoS4
Specimen type:	Round Tensile Specimen
Gauge diameter:	4.996	mm
Gauge length:	25	mm
Parallel length:	30	mm
Original cross-section:	19.603550724770926	mm²
Cross-section after fracture:	9.315714430207356	mm²
Yield stress at 0.2% plastic strain:	1099.5010596488153	MPa
Yield stress at 1% plastic strain:	1132.1559819056492	MPa
Ultimate tensile strength:	1186.5503513405888	MPa
Uniform elongation:	4.972937536698853	%
Elongation after fracture:	13.901356236050288	%
Reduction of area:	52.47945353881184	%
Slope of linear-elastic region:	207966.16408097447	MPa
Crosshead seperation speed:	0.029910290304738178	mm/s
Strain rate:	0.000997009676824606	s-1
Test temperature:	RT	Cel
Machine type:	INSTRON 8852TT
Standard:	DIN EN ISO 6892-1
Date:	2022-08-23 00:00:00
Heat treatment batch:	Batch 2
Time	Displacement	Force	Machine Displacement	Engineering Strain	Engineering Stress	True Strain	True Stress
s	mm	kN	mm		MPa		MPa
0	0.001198319113390313	0.197327	0	4.793276453561252e-05	10.065880552478628	4.793161579726873e-05	10.066363037960993
0.430001	0.001004859113390313	0.200361	-6.1035e-05	4.019436453561252e-05	10.220648433185376	4.0193556763792276e-05	10.22105924565429
0.840001	0.001122693613390313	0.209516	0.000671387	4.490774453561252e-05	10.687655667157118	4.49067362131217e-05	10.688135625667504
1.24	0.002718449113390313	0.362678	0.0119553	0.00010873796453561253	18.50062802866229	0.00010873205299176888	18.50263974929676
1.65	0.004627909113390313	0.538741	0.0250702	0.00018511636453561253	27.48180712585145	0.00018509923261568836	27.486894458077458
2.06	0.006085899113390313	0.723306	0.0371552	0.00024343596453561253	36.896683164955164	0.00024340633880904258	36.905665144609586
2.46	0.008152859113390313	0.901211	0.0487289	0.00032611436453561254	45.97182483177577	0.0003260612008042799	45.98681690421733
2.87	0.010196379113390313	1.09719	0.061554	0.0004078551645356125	55.96894233112563	0.00040777201422614336	55.991769553308984
3.27	0.012155219113390313	1.3146	0.0730743	0.0004862087645356125	67.05928015065554	0.0004860906033534062	67.09188496040824
3.68001	0.013955319113390312	1.57028	0.085289	0.0005582127645356124	80.10181533163805	0.0005580570217460721	80.14652918741865
4.09001	0.015978919113390312	1.86271	0.0969086	0.0006391567645356124	95.01901090021876	0.0006389525908455031	95.07974294379513
4.51001	0.018419019113390313	2.22084	0.110687	0.0007367607645356125	113.28764014132197	0.0007364894895585759	113.37110602968494
4.93001	0.020601719113390315	2.55281	0.123627	0.0008240687645356126	130.2218172534573	0.0008237294062947689	130.32912898551692
5.34001	0.022629519113390315	2.89139	0.135277	0.0009051807645356126	147.49317817952527	0.0009047713354803841	147.6266861673136
5.76001	0.025042219113390315	3.26601	0.148529	0.0010016887645356127	166.60298156461474	0.001001187409118619	166.76986589938616
6.17001	0.027325319113390315	3.6208	0.160423	0.0010930127645356125	184.70123350790627	0.0010924158609931425	184.90311431375588
6.58001	0.029622419113390315	3.99015	0.172653	0.0011848967645356125	203.54220804285575	0.0011841953283958872	203.78338454661215
6.98001	0.03181991911339031	4.33222	0.184067	0.0012727967645356124	220.99159794178684	0.0012719874453934498	221.2728753326367
7.39001	0.034335119113390315	4.73875	0.196663	0.0013734047645356127	241.72916766614858	0.0013724625068473528	242.0611596567485
7.79001	0.03630891911339031	5.08506	0.207596	0.0014523567645356125	259.39484491319985	0.001451303114510405	259.77157877089525
8.20001	0.038973219113390314	5.5015	0.220863	0.0015589287645356126	280.63793530262546	0.0015577148964813542	281.07542985238865
8.61001	0.04144961911339031	5.89755	0.232666	0.0016579847645356125	300.840907996728	0.0016566118251282577	301.3396976387357
9.01001	0.04391001911339031	6.29715	0.244705	0.0017564007645356125	321.2249703337141	0.0017548600964693959	321.7891701171962
9.41001	0.04632441911339032	6.69859	0.256401	0.0018529767645356127	341.70289321799766	0.0018512621208938462	342.3360607395052
9.82001	0.04890621911339031	7.10231	0.269707	0.0019562487645356126	362.29712156306283	0.001954337801727895	363.00586485951544
10.23	0.051389119113390315	7.53366	0.282242	0.0020555647645356125	384.3007884525997	0.002053454981986856	385.09074361232615
10.63	0.05383821911339032	7.92053	0.294403	0.002153528764535613	404.0354786335553	0.002151213245228102	404.90558065868555
11.04	0.056353019113390315	8.33798	0.307121	0.0022541207645356124	425.33009030166045	0.0022515840456570515	426.28883568999123
11.44	0.058544819113390316	8.68708	0.318062	0.0023417927645356124	443.1380887046681	0.0023390550411472024	444.1758262744869
11.85	0.061096819113390315	9.10113	0.33075	0.0024438727645356125	464.2592624049411	0.0024408913639453926	465.3938529720159
12.25	0.06373521911339032	9.51935	0.342491	0.0025494087645356127	485.5931526716436	0.002546164534753392	486.8311281110632
12.66	0.06587051911339031	9.89694	0.355011	0.0026348207645356127	504.8544592227513	0.002631355709503178	506.18466023497984
13.06	0.06838341911339031	10.3137	0.366905	0.0027353367645356124	526.11387318562	0.002731602538954213	527.5529718052768
13.47	0.07108021911339031	10.7288	0.379257	0.0028432087645356126	547.2886086112529	0.002839174491540722	548.844664379987
13.87	0.07320461911339031	11.0896	0.39035	0.0029281847645356122	565.6934376682715	0.002923905982203228	567.3498925738495
14.29	0.07580571911339032	11.5346	0.403885	0.003032228764535613	588.3934069874877	0.0030276408309984014	590.1775504010183
14.72	0.07835581911339032	11.9408	0.416473	0.0031342327645356126	609.1141430267363	0.0031293312959163413	611.0232485311527
15.12	0.08065261911339032	12.3261	0.427414	0.003226104764535613	628.768745675487	0.0032209120537152166	630.7972195217018
15.54	0.08300831911339031	12.7282	0.439888	0.0033203327645356124	649.2803359299968	0.0033148326311879524	651.4361627027539
15.96	0.08583261911339031	13.1764	0.45327	0.003433304764535612	672.1435409836434	0.0034274244292109334	674.4512146053545
16.4	0.08820351911339032	13.5863	0.46566	0.0035281407645356127	693.0530183408271	0.0035219314764507147	695.4982069468198
16.81	0.09073561911339031	14.0074	0.477539	0.003629424764535613	714.533820768517	0.003622854295690729	717.1271675127125
17.21	0.09310231911339031	14.4139	0.490471	0.0037240927645356124	735.2698601578685	0.003717175499448336	738.0080733240636
17.62	0.09571481911339032	14.8133	0.502029	0.003828592764535613	755.6437202614527	0.003821282356366808	758.5367723414125
18.02	0.09807511911339031	15.2125	0.514778	0.003923004764535613	776.007378131635	0.003915329847287213	779.0516587733601
18.45	0.10062011911339032	15.6326	0.527634	0.004024804764535613	797.4371693923154	0.00401672690512334	800.6466983111034
18.86	0.10280931911339032	16.0073	0.539215	0.004112372764535613	816.5510536707657	0.00410394007067324	819.9090159847342
19.26	0.10533531911339031	16.4052	0.551727	0.0042134127645356125	836.8483970238357	0.004204561195804827	840.3743847418372
19.66	0.10757331911339031	16.7945	0.56353	0.0043029327645356125	856.7070443406241	0.004293701620535252	860.3933971513259
20.07	0.11009431911339032	17.201	0.575607	0.004403772764535613	877.4430837299756	0.004394104531330676	881.3071436845358
20.48	0.11247531911339032	17.59	0.588081	0.004499012764535613	897.2864276966613	0.004488922459562403	901.3233307883132
20.88	0.11500131911339032	17.9915	0.599876	0.004600052764535612	917.7674112509654	0.004589504856735996	921.9891897682911
21.28	0.11709031911339031	18.3677	0.611595	0.004683612764535612	936.9578122799298	0.004672678777354269	941.3461598493554
21.69	0.11974231911339031	18.7815	0.62516	0.004789692764535613	958.0662331884505	0.004778258682105211	962.6550760934991
22.1	0.12214131911339031	19.1712	0.637169	0.004885652764535613	977.9452849720427	0.004873756694046599	982.7231860571309
22.51	0.12445531911339032	19.5525	0.648682	0.004978212764535613	997.3958429527555	0.004965862434791583	1002.3610916694378
22.92	0.1268213191133903	19.9201	0.660774	0.005072852764535613	1016.1475479454386	0.005060029196714068	1021.3023148432097
23.34	0.1294213191133903	20.3045	0.673569	0.005176852764535612	1035.7562405438805	0.005163498929660024	1041.1181981011252
23.75	0.1321083191133903	20.6711	0.685951	0.005284332764535612	1054.456934369554	0.0052704196709067	1060.0290356966345
24.16	0.1352753191133903	21.0361	0.698273	0.005411012764535612	1073.0760103280124	0.00539642583136204	1078.8824383172143
24.56	0.1389133191133903	21.3221	0.709839	0.005556532764535612	1087.665204092722	0.005541152185178682	1093.7088514361087
24.97	0.1445763191133903	21.5457	0.722626	0.005783052764535612	1099.0713010360407	0.0057663951054565095	1105.4272883619187
25.37	0.1519873191133903	21.6005	0.734528	0.0060794927645356125	1101.8667129881599	0.006061087208358033	1108.565503697254
25.78	0.1621813191133903	21.5659	0.746407	0.006487252764535612	1100.101726609632	0.006466301103982006	1107.2383645768507
26.18	0.1733963191133903	21.5453	0.758598	0.006935852764535611	1099.0508965692368	0.00691191038122843	1106.6737517685717
26.59	0.1846123191133903	21.5552	0.771362	0.007384492764535611	1099.5559071226307	0.007357360886074287	1107.6755697629803
27	0.1944343191133903	21.5766	0.782547	0.007777372764535611	1100.6475460966333	0.007747284903294209	1109.2076923449981
27.4	0.2048343191133903	21.6069	0.79483	0.008193372764535613	1102.1931844570204	0.00815998931066436	1111.2238640758073
27.81	0.2149223191133903	21.6657	0.807564	0.008596892764535612	1105.1926410771778	0.008560149914651441	1114.6938636966722
28.21	0.2244493191133903	21.7113	0.819298	0.008977972764535613	1107.51875029281	0.008937910374540758	1117.4620234691513
28.62	0.2335013191133903	21.7489	0.830978	0.009340052764535612	1109.4367701723659	0.009296704181368421	1119.7989681446916
29.03	0.2433743191133903	21.7872	0.843697	0.009734972764535612	1111.3904978688288	0.009687893215993703	1122.2098540963457
29.43	0.2524923191133903	21.8221	0.856483	0.010099692764535612	1113.1707875974594	0.010049031689541259	1124.4134705466497
29.83	0.2618623191133903	21.8673	0.86866	0.010474492764535612	1115.4764923462876	0.01042001535050552	1127.1605427943784
30.24	0.2714463191133903	21.8966	0.880699	0.010857852764535611	1116.9711195396653	0.010799329524589004	1129.0990274978653
30.65	0.2809793191133903	21.9234	0.892319	0.011239172764535612	1118.3382188155194	0.011176482549103544	1130.90741526597
31.05	0.2905123191133903	21.9529	0.905563	0.011620492764535613	1119.843048242299	0.01155349338284018	1132.856176281814
31.45	0.3001553191133903	21.983	0.917152	0.01200621276453561	1121.378484369284	0.01193470994182045	1134.841993042194
31.86	0.3099483191133903	22.0027	0.928963	0.012397932764535612	1122.3834043593706	0.012321707771037624	1136.2986383426487
32.28	0.3204913191133903	22.0398	0.942528	0.012819652764535611	1124.2759186554222	0.012738176607876584	1138.688745544114
32.69	0.3306543191133903	22.0524	0.95459	0.013226172764535613	1124.9186593597415	0.013139470596722163	1139.797027894483
33.09	0.3400713191133903	22.0793	0.96608	0.01360285276453561	1126.2908597522965	0.013511164508337052	1141.611628487549
33.52	0.3504673191133903	22.1043	0.978775	0.014018692764535611	1127.5661389275333	0.013921339678104007	1143.373142200852
33.92	0.3601203191133903	22.125	0.991447	0.014404812764535613	1128.6220700846295	0.014302049134103826	1144.8796596861212
34.33	0.3705113191133903	22.1407	1.00423	0.014820452764535611	1129.4229454066783	0.014711703018148475	1146.1615048202607
34.73	0.38000031911339033	22.171	1.01611	0.015200012764535612	1130.9685837670652	0.015085649991460328	1148.1593206766133
35.14	0.3896933191133903	22.1937	1.02777	0.015587732764535612	1132.1265372581804	0.01546749196934746	1149.7738231766
35.54	0.3995863191133903	22.209	1.04014	0.015983452764535614	1132.9070081134253	0.015857062374582225	1151.0147737642176
35.9501	0.4100473191133903	22.237	1.05312	0.016401892764535613	1134.3353207896905	0.01626883468619895	1152.940567080308
36.3501	0.4199583191133903	22.2472	1.06511	0.016798332764535615	1134.8556346931873	0.01665880120306859	1153.9193172844716
36.7701	0.4301083191133903	22.2652	1.07733	0.01720433276453561	1135.7738356993577	0.017058014057872366	1155.3140667139826
37.1801	0.4400063191133903	22.2806	1.08971	0.017600252764535612	1136.5594076713037	0.017447161996511716	1156.5631405282295
37.5901	0.4499573191133903	22.3064	1.10167	0.017998292764535614	1137.8754957801482	0.01783824107833505	1158.3553120827905
37.9901	0.4600193191133903	22.3321	1.11391	0.01840077276453561	1139.1864827722918	0.01823352706334023	1160.1483943782155
38.4101	0.4703483191133903	22.3556	1.12645	0.018813932764535614	1140.3852451970142	0.018639139691742194	1161.8403765258192
38.8201	0.4798753191133903	22.3615	1.13838	0.019195012764535613	1140.6862110823702	0.01901311253938575	1162.5816974644258
39.2301	0.4903883191133903	22.3886	1.15157	0.019615532764535613	1142.068613708327	0.019425627578495662	1164.4708980198702
39.6301	0.4998513191133903	22.3997	1.16287	0.019994052764535614	1142.6348376621322	0.019796796656177347	1165.4807388969455
40.0401	0.5095333191133903	22.4126	1.17471	0.02038133276453561	1143.2928817165546	0.020176413081074016	1166.5947143861447
40.4401	0.5195553191133903	22.4566	1.18677	0.02078221276453561	1145.5373730649715	0.020569208656942766	1169.3441744817349
40.8501	0.5296613191133903	22.4578	1.1989	0.021186452764535613	1145.5985864653826	0.02096514030085562	1169.8697568046503
41.2501	0.5392673191133903	22.4711	1.21056	0.021570692764535614	1146.2770349866087	0.02134133774103849	1171.0030247313475
41.6601	0.5490953191133903	22.4864	1.22266	0.02196381276453561	1147.0575058418538	0.021726082900746638	1172.2512621303194
42.0701	0.5592953191133903	22.5161	1.23534	0.02237181276453561	1148.5725375020352	0.02212523458633283	1174.2681872575183
42.4701	0.5690673191133903	22.5278	1.24745	0.02276269276453561	1149.1693681560457	0.022507488177676463	1175.3275574177974
42.8801	0.5792293191133903	22.5517	1.25966	0.02316917276453561	1150.3885350475723	0.02290484256879451	1177.0420857624306
43.2801	0.5885873191133904	22.5553	1.27156	0.023543492764535615	1150.5721752488064	0.023270619368320814	1177.6606629318528
43.6901	0.5984743191133903	22.5857	1.28365	0.023938972764535615	1152.1229147258946	0.023656927931716462	1179.7035538029152
44.1001	0.6083253191133903	22.5914	1.29544	0.02433301276453561	1152.4136783778486	0.024041681526595308	1180.4553751238423
44.5001	0.6187343191133903	22.62	1.30811	0.02474937276453561	1153.8725977543195	0.024448068315794772	1182.4302207989242
44.9001	0.6279983191133903	22.6223	1.31921	0.025119932764535613	1153.989923438441	0.024809613320675696	1182.9780727261661
45.3101	0.6384523191133903	22.6374	1.3317	0.02553809276453561	1154.7601920602842	0.025217443393355087	1184.2505649659129
45.7201	0.6479333191133902	22.6541	1.34332	0.02591733276453561	1155.6120785493424	0.02558717114819756	1185.5624613358225
46.1201	0.6580253191133904	22.6792	1.35616	0.026321012764535613	1156.8924588412804	0.025980575750626733	1187.3430400176367
46.5201	0.6671873191133904	22.7039	1.36759	0.026687492764535616	1158.1524346664144	0.026337593271894204	1189.0606193868034
46.9301	0.6777103191133903	22.7093	1.37978	0.027108412764535614	1158.4278949682655	0.02674748795009493	1189.8310365030172
47.3401	0.6869743191133904	22.7196	1.39172	0.027478972764535613	1158.953309988463	0.02710820271611367	1190.8001564290043
47.7501	0.6972923191133903	22.7318	1.40404	0.02789169276453561	1159.5756462259787	0.027509804249568243	1191.9181738877517
48.1501	0.7065013191133903	22.7458	1.4154	0.028260052764535613	1160.2898025641114	0.02786810465686234	1193.0796536067257
48.5501	0.7165603191133904	22.77	1.42789	0.028662412764535614	1161.5242728057406	0.028259329909029112	1194.8163609489259
48.9601	0.7268063191133903	22.7962	1.44049	0.02907225276453561	1162.8607653813888	0.02865767087327953	1196.6677474825178
49.3701	0.7365673191133904	22.7909	1.45252	0.029462692764535614	1162.5904061962387	0.029037008620768377	1196.8434501449951
49.7701	0.7463383191133903	22.8157	1.46436	0.029853532764535614	1163.8554831380736	0.02941659093051515	1198.6006809371204
50.1801	0.7560093191133903	22.8243	1.47619	0.030240372764535613	1164.2941791743551	0.029792146630678612	1199.5028691601665
50.5801	0.7657953191133903	22.8458	1.48782	0.03063181276453561	1165.3909192650588	0.03017202463326016	1201.088955701476
50.9901	0.7757353191133903	22.8537	1.49976	0.031029412764535615	1165.7939074844337	0.030557733012508893	1201.9678078381492
51.3901	0.7857173191133903	22.8692	1.51183	0.03142869276453561	1166.5845805730805	0.03094492148816099	1203.2488089397564
51.8001	0.7956353191133902	22.8726	1.52412	0.03182541276453561	1166.7580185409126	0.03132947907011473	1203.8905740773089
52.2101	0.8058303191133903	22.8929	1.53577	0.03223321276453561	1167.7935452312051	0.03172462289041337	1205.4352830396938
52.6101	0.8154653191133903	22.9037	1.54769	0.032618612764535614	1168.3444658349074	0.03209791844577535	1206.4542415415644
53.0201	0.8259643191133903	22.9223	1.5608	0.03303857276453561	1169.2932735412837	0.032504529967501444	1207.9250544422596
53.4201	0.8356143191133903	22.9291	1.57273	0.033424572764535615	1169.640149476948	0.03287811514885298	1208.7348717614625
53.8301	0.8453193191133903	22.9314	1.58501	0.03381277276453561	1169.75747516107	0.033253688863601	1209.3102188583082
54.2401	0.8556553191133903	22.9524	1.5975	0.034226212764535614	1170.8287096682689	0.0336535265923876	1210.9017421962017
54.6401	0.8649713191133903	22.9594	1.60925	0.034598852764535615	1171.185787837335	0.03401376971805234	1211.7074724706356
55.0401	0.8750383191133903	22.9734	1.62123	0.03500153276453561	1171.899944175468	0.034402907648154325	1212.918238468283
55.4501	0.8850443191133903	22.985	1.63393	0.03540177276453561	1172.4916737127778	0.03478953763847259	1213.9999575138677
55.8601	0.8951713191133903	22.9951	1.64594	0.035806852764535615	1173.0068864995735	0.03518069090055528	1215.00857137625
56.2601	0.9050843191133903	23.0072	1.65797	0.03620337276453561	1173.624121620388	0.0355634303291112	1216.1132731808616
56.6601	0.9153973191133903	23.0078	1.67051	0.03661589276453561	1173.6547283205937	0.03596145828292887	1216.629143995371
57.0701	0.9250693191133903	23.0158	1.68204	0.03700277276453561	1174.0628176566695	0.03633460307654045	1217.5063973097097
57.4801	0.9354543191133903	23.0429	1.69475	0.03741817276453561	1175.4452202826262	0.03673510038779985	1219.428232610409
57.8901	0.9453073191133903	23.0438	1.70598	0.03781229276453561	1175.4911303329347	0.03711493290402892	1219.9391450951987
58.2901	0.9550563191133903	23.0544	1.71895	0.038202252764535614	1176.0318487032353	0.03749061428393659	1220.9589146465403
58.6901	0.9651823191133903	23.0737	1.7309	0.03860729276453561	1177.016364226518	0.03788067412934455	1222.4577795888604
59.1001	0.9758193191133903	23.0783	1.74324	0.03903277276453561	1177.2510155947616	0.03829025422265085	1223.2023869732907
59.5101	0.9857243191133903	23.0789	1.7551	0.039428972764535615	1177.2816222949675	0.038671497712603045	1223.7006273166241
59.9101	0.9958243191133903	23.0964	1.76749	0.03983297276453561	1178.1743177176331	0.03906009714419728	1225.104503227155
60.3201	1.0066983191133905	23.104	1.78004	0.04026793276453562	1178.5620025869052	0.03947830763118218	1226.0202580659113
60.7201	1.0165183191133904	23.0962	1.79145	0.04066073276453561	1178.1641154842314	0.039855831388889075	1226.0691317367011
61.1301	1.0268383191133905	23.1092	1.80386	0.04107353276453562	1178.8272606553546	0.04025242379959774	1227.2458607696099
61.5301	1.0363283191133905	23.1143	1.81576	0.04145313276453562	1179.0874176071027	0.04061698096036545	1227.9642848701633
61.9401	1.0466883191133904	23.1257	1.82831	0.041867532764535614	1179.6689449110106	0.04101480738461431	1229.0587731133776
62.3501	1.0567483191133904	23.1299	1.83997	0.04226993276453562	1179.8831918124506	0.041400962339991236	1229.7567750003686
62.7501	1.0670583191133904	23.1478	1.8528	0.04268233276453562	1180.7962917019202	0.04179655893200576	1231.1954319514712
63.1601	1.0777783191133905	23.1503	1.86523	0.04311113276453562	1180.923819619444	0.042207721411059974	1231.8347831918604
63.5601	1.0875183191133904	23.1367	1.87608	0.043500732764535616	1180.230067748115	0.04258114975292223	1231.5709405258956
63.9701	1.0975883191133904	23.1622	1.88773	0.04390353276453562	1181.5308525068565	0.042967083624622475	1233.404231002201
64.3801	1.1086683191133904	23.1789	1.9006	0.044346732764535615	1182.3827389959147	0.043391553827232275	1234.8175503475663
64.7801	1.1192783191133904	23.1899	1.91296	0.044771132764535614	1182.9438618330191	0.04379784972162951	1235.9055985241378
65.1801	1.1291683191133903	23.1679	1.92442	0.045166732764535616	1181.8216161588105	0.04417642557428957	1235.200637271207
65.5901	1.1397183191133904	23.1835	1.93723	0.045588732764535615	1182.6173903641584	0.04458010741340324	1236.5314185361626
66.0001	1.1503083191133905	23.1827	1.94994	0.04601233276453562	1182.576581430551	0.04498515597909069	1236.9896886148804
66.4001	1.1607683191133904	23.2033	1.96198	0.04643073276453562	1183.627411470946	0.0453850712861966	1238.5840995057326
66.8101	1.1705983191133904	23.1951	1.97375	0.046823932764535614	1183.2091199014683	0.045760754198648355	1238.61162417812
67.2101	1.1810483191133905	23.2045	1.98587	0.047241932764535616	1183.6886248713574	0.04615997755874656	1239.6083633016758
67.6201	1.1921583191133904	23.2161	1.99885	0.04768633276453562	1184.2803544086676	0.04658424030222874	1240.7543414755014
68.0301	1.2027683191133904	23.2164	2.01032	0.04811073276453562	1184.2956577587702	0.046989241351978656	1241.2729896634023
68.4301	1.2127483191133903	23.2171	2.02241	0.048509932764535614	1184.3313655756767	0.047370044624012834	1241.7832004906834
68.8301	1.2233283191133904	23.2225	2.03432	0.04893313276453561	1184.606825877528	0.04777358359267264	1242.5733489619683
69.2401	1.2346283191133904	23.2397	2.04736	0.04938513276453562	1185.484217950091	0.0482044048026068	1244.029513443818
69.6501	1.2447783191133903	23.2222	2.05858	0.04979113276453561	1184.5915225274252	0.048591223205357754	1243.5736762973315
70.0501	1.2551083191133905	23.2294	2.07103	0.05020433276453562	1184.9588029298932	0.048984747869686894	1244.4488689844513
70.4601	1.2663383191133903	23.2312	2.08434	0.050653532764535616	1185.0506230305105	0.049412382708022236	1245.0776235918197
70.8601	1.2768983191133905	23.2318	2.09618	0.05107593276453562	1185.0812297307161	0.04981433739592569	1245.6103589409554
71.2701	1.2871883191133904	23.2247	2.1077	0.05148753276453562	1184.7190504449486	0.050205859470770005	1245.7173113715025
71.6701	1.2978583191133903	23.2349	2.12041	0.051914332764535616	1185.2393643484456	0.05061167826636201	1246.7702751148577
72.0801	1.3094483191133903	23.2404	2.1329	0.05237793276453561	1185.5199257669976	0.05105230147740047	1247.6150087298386
72.4901	1.3198183191133903	23.233	2.1444	0.05279273276453561	1185.1424431311275	0.05144637879584344	1247.709351419258
72.8901	1.3303383191133904	23.2568	2.15711	0.053213532764535616	1186.356508905953	0.05184599774521457	1249.48672986304
73.3001	1.3419983191133904	23.2507	2.16984	0.053679932764535615	1186.045340787195	0.05228873489851574	1249.7121749363425
73.7001	1.3521983191133904	23.2305	2.18084	0.054087932764535614	1185.0149152136037	0.05267587430961343	1249.1099222726489
74.1101	1.3628983191133903	23.2466	2.19383	0.05451593276453561	1185.8361950024564	0.05308183012983628	1250.4831612789633
74.5201	1.3743383191133904	23.2509	2.20618	0.05497353276453562	1186.055543020597	0.053515679186354526	1251.2572062753989
74.9201	1.3848983191133903	23.247	2.21788	0.05539593276453561	1185.8565994692601	0.05391598824364556	1251.5482319218402
75.3201	1.3959283191133904	23.247	2.23042	0.05583713276453562	1185.8565994692601	nan	nan
75.7301	1.4071283191133903	23.2504	2.24246	0.05628513276453561	1186.0300374370922	nan	nan
76.1401	1.4187683191133904	23.2481	2.25497	0.056750732764535614	1185.9127117529706	nan	nan
76.5401	1.4294283191133905	23.2386	2.26614	0.05717713276453562	1185.4281056663806	nan	nan
76.9401	1.4401583191133904	23.2454	2.27821	0.05760633276453562	1185.774981602045	nan	nan
77.3501	1.4511983191133904	23.2415	2.29014	0.05804793276453561	1185.576038050708	nan	nan
77.7601	1.4629783191133905	23.2452	2.30254	0.05851913276453562	1185.764779368643	nan	nan
78.1701	1.4737983191133903	23.2243	2.31386	0.058951932764535614	1184.698645978145	nan	nan
78.5701	1.4850683191133904	23.2329	2.32631	0.059402732764535615	1185.1373420144266	nan	nan
78.9701	1.4959683191133903	23.2311	2.33842	0.059838732764535614	1185.0455219138096	nan	nan
79.3801	1.5076183191133905	23.2322	2.35065	0.06030473276453562	1185.1016341975198	nan	nan
79.7901	1.5190783191133903	23.2331	2.36285	0.06076313276453561	1185.1475442478284	nan	nan
80.1901	1.5304783191133904	23.2217	2.37469	0.06121913276453562	1184.5660169439202	nan	nan
80.6001	1.5423083191133904	23.2299	2.38795	0.06169233276453562	1184.9843085133982	nan	nan
81.0001	1.5538183191133903	23.2165	2.39938	0.06215273276453561	1184.300758875471	nan	nan
81.4101	1.5649483191133904	23.2105	2.4112	0.06259793276453561	1183.9946918734142	nan	nan
81.8101	1.5764483191133905	23.2072	2.423	0.06305793276453561	1183.826355022283	nan	nan
82.2201	1.5882483191133905	23.2039	2.43545	0.06352993276453561	1183.6580181711518	nan	nan
82.6301	1.5997883191133904	23.1875	2.44778	0.06399153276453562	1182.8214350321964	nan	nan
83.0301	1.6114883191133904	23.1812	2.45994	0.06445953276453562	1182.5000646800368	nan	nan
83.4301	1.6228583191133905	23.1638	2.47113	0.06491433276453562	1181.6124703740718	nan	nan
83.8401	1.6350283191133903	23.1532	2.48344	0.06540113276453562	1181.0717520037713	nan	nan
84.2501	1.6468383191133904	23.1642	2.49584	0.06587353276453561	1181.6328748408757	nan	nan
84.6601	1.6591983191133903	23.1514	2.50841	0.06636793276453562	1180.9799319031542	nan	nan
85.0601	1.6711383191133904	23.1319	2.51999	0.06684553276453561	1179.9852141464696	nan	nan
85.4601	1.6824283191133904	23.1091	2.53153	0.06729713276453561	1178.8221595386538	nan	nan
85.8701	1.6943683191133905	23.111	2.54328	0.06777473276453562	1178.9190807559714	nan	nan
86.2801	1.7073683191133904	23.0881	2.55581	0.06829473276453561	1177.7509250314547	nan	nan
86.6801	1.7194883191133905	23.0809	2.56783	0.06877953276453562	1177.3836446289865	nan	nan
87.0801	1.7314883191133905	23.0559	2.57932	0.06925953276453561	1176.1083654537495	nan	nan
87.4901	1.7446983191133905	23.0561	2.59247	0.06978793276453561	1176.1185676871514	nan	nan
87.9001	1.7574583191133903	23.0197	2.60389	0.07029833276453562	1174.2617612080064	nan	nan
88.3101	1.7698583191133903	23.006	2.61562	0.07079433276453562	1173.5629082199766	nan	nan
88.7101	1.7820583191133905	22.9735	2.62753	0.07128233276453562	1171.9050452921688	nan	nan
89.1101	1.7958283191133904	22.9543	2.64023	0.07183313276453561	1170.9256308855868	nan	nan
89.5201	1.8076083191133905	22.9344	2.65189	0.07230433276453561	1169.9105086620984	nan	nan
89.9301	1.8206483191133904	22.905	2.66411	0.07282593276453561	1168.4107803520196	nan	nan
90.3301	1.8327283191133905	22.8738	2.6759	0.07330913276453561	1166.819231941324	nan	nan
90.7401	1.8460083191133905	22.8516	2.68873	0.07384033276453562	1165.6867840337138	nan	nan
91.1401	1.8587083191133904	22.8316	2.70073	0.07434833276453562	1164.6665606935244	nan	nan
91.5501	1.8712183191133904	22.7944	2.7122	0.07484873276453562	1162.7689452807717	nan	nan
91.9501	1.8839783191133903	22.784	2.72486	0.07535913276453561	1162.2384291438732	nan	nan
92.3601	1.8970383191133904	22.7416	2.73682	0.07588153276453562	1160.0755556626714	nan	nan
92.7701	1.9103083191133905	22.7096	2.74955	0.07641233276453561	1158.4431983183683	nan	nan
93.1701	1.9228683191133904	22.6686	2.76134	0.07691473276453561	1156.35174047098	nan	nan
93.5901	1.9360883191133904	22.6615	2.77435	0.07744353276453561	1155.9895611852126	nan	nan
94.0101	1.9494683191133904	22.6153	2.78684	0.07797873276453561	1153.6328452693751	nan	nan
94.4201	1.9623283191133905	22.5953	2.79939	0.07849313276453562	1152.6126219291855	nan	nan
94.8301	1.9757683191133903	22.5456	2.81132	0.07903073276453561	1150.0773669288144	nan	nan
95.2301	1.9883983191133905	22.5229	2.82391	0.07953593276453562	1148.9194134376994	nan	nan
95.6401	2.0016683191133904	22.4909	2.83628	0.08006673276453562	1147.2870560933964	nan	nan
96.0401	2.0140683191133903	22.4478	2.84765	0.08056273276453561	1145.0884747952878	nan	nan
96.4501	2.0275683191133904	22.4265	2.86083	0.08110273276453561	1144.001936937986	nan	nan
96.8501	2.0395683191133904	22.3726	2.87186	0.08158273276453562	1141.2524350361753	nan	nan
97.2701	2.0532183191133906	22.3629	2.88516	0.08212873276453563	1140.7576267161835	nan	nan
97.6901	2.0664383191133906	22.3251	2.8973	0.08265753276453562	1138.8294046032252	nan	nan
98.1001	2.0792483191133906	22.2845	2.90956	0.08316993276453562	1136.7583512226406	nan	nan
98.5001	2.0923283191133906	22.2529	2.92239	0.08369313276453562	1135.1463983451413	nan	nan
98.9301	2.1064283191133906	22.2025	2.93521	0.08425713276453563	1132.5754355278636	nan	nan
99.3301	2.1193683191133905	22.1671	2.94674	0.08477473276453562	1130.7696402157285	nan	nan
99.7401	2.1320983191133904	22.1324	2.95897	0.08528393276453562	1128.9995527204997	nan	nan
100.16	2.1450983191133903	22.1019	2.97102	0.08580393276453561	1127.4437121267106	nan	nan
100.56	2.1576683191133905	22.0621	2.98258	0.08630673276453563	1125.4134676797335	nan	nan
100.99	2.1714983191133905	22.0262	2.99567	0.08685993276453562	1123.5821667840933	nan	nan
101.39	2.1843883191133906	21.9828	3.00788	0.08737553276453562	1121.368282135882	nan	nan
101.81	2.1986583191133904	21.9547	3.02141	0.08794633276453562	1119.934868342916	nan	nan
102.23	2.21164831911339	21.9061	3.03317	0.08846593276453561	1117.4557256262553	nan	nan
102.64	2.2245683191133905	21.8606	3.04572	0.08898273276453562	1115.1347175273245	nan	nan
103.04	2.2372283191133904	21.8269	3.05704	0.08948913276453561	1113.4156411991048	nan	nan
103.46	2.2506083191133905	21.802	3.0701	0.09002433276453563	1112.145463140569	nan	nan
103.87	2.2644583191133902	21.7608	3.08274	0.09057833276453561	1110.0438030597786	nan	nan
104.29	2.2774883191133903	21.7067	3.09481	0.09109953276453561	1107.2840989245663	nan	nan
104.7	2.2898983191133904	21.6764	3.10692	0.09159593276453562	1105.7384605641791	nan	nan
105.11	2.3035583191133906	21.6462	3.11977	0.09214233276453562	1104.197923320493	nan	nan
105.51	2.3163683191133906	21.6059	3.13179	0.09265473276453562	1102.142173290011	nan	nan
105.91	2.3293483191133904	21.5523	3.14333	0.09317393276453562	1099.4079747383032	nan	nan
106.32	2.3420883191133903	21.5323	3.1554	0.09368353276453562	1098.3877513981138	nan	nan
106.73	2.3557583191133906	21.4907	3.16838	0.09423033276453563	1096.2656868505196	nan	nan
107.13	2.3684183191133905	21.4389	3.18007	0.09473673276453562	1093.6233083994289	nan	nan
107.55	2.3820283191133904	21.4037	3.19312	0.09528113276453562	1091.8277153206952	nan	nan
107.96	2.3951683191133903	21.3729	3.20542	0.09580673276453561	1090.2565713768035	nan	nan
108.36	2.4076483191133904	21.3202	3.21672	0.09630593276453561	1087.568282875404	nan	nan
108.77	2.42090831911339	21.2816	3.22971	0.09683633276453561	1085.5992518288385	nan	nan
109.18	2.4331883191133903	21.2401	3.24112	0.09732753276453561	1083.4822883979452	nan	nan
109.58	2.4461083191133906	21.2058	3.25332	0.09784433276453562	1081.7326053695201	nan	nan
109.99	2.4596583191133905	21.1479	3.26541	0.09838633276453562	1078.7790587996717	nan	nan
110.39	2.4725383191133905	21.1239	3.27781	0.09890153276453562	1077.554790791444	nan	nan
110.8	2.4853883191133903	21.0764	3.28942	0.09941553276453562	1075.1317603584941	nan	nan
111.2	2.4987183191133906	21.0416	3.30202	0.09994873276453563	1073.3565717465644	nan	nan
111.63	2.5127183191133904	20.9878	3.31494	0.10050873276453562	1070.6121709614547	nan	nan
112.03	2.5246983191133903	20.9406	3.32629	0.1009879327645356	1068.2044438786074	nan	nan
112.43	2.5380383191133906	20.9253	3.33934	0.10152153276453563	1067.4239730233626	nan	nan
112.84	2.5510083191133903	20.866	3.35152	0.10204033276453561	1064.3990108197006	nan	nan
113.25	2.5639583191133903	20.8315	3.36362	0.10255833276453562	1062.6391255578737	nan	nan
113.66	2.5766683191133906	20.7865	3.37533	0.10306673276453562	1060.3436230424475	nan	nan
114.06	2.5900683191133904	20.7568	3.38785	0.10360273276453562	1058.828591382266	nan	nan
114.46	2.60277831911339	20.6952	3.39958	0.10411113276453561	1055.6863034944824	nan	nan
114.87	2.6163583191133903	20.6571	3.41264	0.10465433276453562	1053.7427780314213	nan	nan
115.28	2.6290683191133906	20.6081	3.42455	0.10516273276453562	1051.243230847957	nan	nan
115.68	2.6419583191133906	20.5748	3.43691	0.10567833276453563	1049.5445589865417	nan	nan
116.09	2.6551483191133904	20.5234	3.44883	0.10620593276453562	1046.9225850022544	nan	nan
116.49	2.6677683191133905	20.4771	3.461	0.10671073276453562	1044.560767969716	nan	nan
116.9	2.6803383191133903	20.4431	3.47321	0.10721353276453562	1042.8263882913939	nan	nan
117.3	2.6930783191133902	20.3932	3.4849	0.10772313276453561	1040.280931057621	nan	nan
117.72	2.7068583191133904	20.3513	3.49747	0.10827433276453562	1038.143563159924	nan	nan
118.15	2.7212083191133902	20.3073	3.51199	0.10884833276453561	1035.8990718115072	nan	nan
118.55	2.7340283191133903	20.2506	3.52303	0.10936113276453562	1033.0067386420699	nan	nan
118.96	2.7470683191133904	20.2213	3.53554	0.10988273276453561	1031.5121114486922	nan	nan
119.36	2.7597183191133903	20.164	3.5471	0.1103887327645356	1028.5891715790494	nan	nan
119.77	2.7732983191133904	20.1326	3.56044	0.11093193276453561	1026.9874209349518	nan	nan
120.18	2.7860983191133903	20.0631	3.57228	0.11144393276453561	1023.4421448277933	nan	nan
120.58	2.7988683191133905	20.0291	3.5845	0.11195473276453562	1021.7077651494711	nan	nan
120.98	2.8112883191133906	19.9857	3.59613	0.11245153276453562	1019.49388050126	nan	nan
121.39	2.8251583191133904	19.9333	3.60915	0.11300633276453562	1016.8208953499635	nan	nan
121.8	2.8377683191133904	19.8946	3.62019	0.11351073276453562	1014.846763186697	nan	nan
122.2	2.8505483191133902	19.8256	3.63227	0.11402193276453561	1011.3269926630433	nan	nan
122.62	2.8641783191133903	19.7946	3.645	0.11456713276453562	1009.7456464857494	nan	nan
123.04	2.8778483191133906	19.744	3.6576	0.11511393276453562	1007.16448143507	nan	nan
123.45	2.8915783191133904	19.6886	3.67088	0.11566313276453562	1004.3384627827452	nan	nan
123.86	2.90402831911339	19.6325	3.68262	0.1161611327645356	1001.4767363135136	nan	nan
124.26	2.9171183191133903	19.594	3.69507	0.11668473276453561	999.5128063836488	nan	nan
124.68	2.9311383191133906	19.537	3.70775	0.11724553276453563	996.6051698641087	nan	nan
125.09	2.9444383191133903	19.4887	3.7201	0.1177775327645356	994.141330497551	nan	nan
125.5	2.9572483191133903	19.4373	3.732	0.11828993276453562	991.519356513264	nan	nan
125.9	2.9709183191133905	19.3879	3.74458	0.11883673276453562	988.9994048629959	nan	nan
126.31	2.9844783191133906	19.3402	3.75717	0.11937913276453563	986.5661721966441	nan	nan
126.71	2.9971083191133903	19.2888	3.7693	0.11988433276453561	983.944198212357	nan	nan
127.12	3.0098983191133906	19.2419	3.78148	0.12039593276453563	981.5517744796127	nan	nan
127.52	3.0227183191133906	19.1845	3.79315	0.12090873276453562	978.6237334932688	nan	nan
127.93	3.0360583191133905	19.1451	3.80535	0.12144233276453562	976.6138935130955	nan	nan
128.34	3.0500783191133904	19.0932	3.8187	0.12200313276453562	973.9664139453038	nan	nan
128.74	3.0625983191133903	19.0279	3.8299	0.12250393276453561	970.635384739585	nan	nan
129.15	3.0754483191133906	18.9698	3.84147	0.12301793276453563	967.6716359363346	nan	nan
129.55	3.0885083191133904	18.9264	3.85361	0.12354033276453562	965.4577512881235	nan	nan
129.96	3.1023883191133903	18.875	3.86707	0.12409553276453561	962.8357773038364	nan	nan
130.36	3.1151483191133904	18.8129	3.87797	0.12460593276453562	959.6679838325479	nan	nan
130.78	3.1297783191133903	18.7508	3.89157	0.1251911327645356	956.5001903612598	nan	nan
131.2	3.1428983191133906	18.6855	3.90339	0.12571593276453563	953.1691611555409	nan	nan
131.61	3.1558283191133905	18.6419	3.91637	0.12623313276453563	950.9450742739278	nan	nan
132.02	3.1695483191133906	18.5831	3.92859	0.12678193276453562	947.9456176537708	nan	nan
132.42	3.1825183191133903	18.5354	3.94059	0.1273007327645356	945.5123849874186	nan	nan
132.83	3.1958083191133904	18.4817	3.95306	0.12783233276453562	942.77308531901	nan	nan
133.23	3.2090483191133905	18.4332	3.96513	0.1283619327645356	940.2990437190505	nan	nan
133.65	3.2233383191133904	18.3508	3.97799	0.12893353276453562	936.0957235574697	nan	nan
134.06	3.2365883191133906	18.298	3.98958	0.12946353276453562	933.4023339393694	nan	nan
134.46	3.2496683191133906	18.2476	4.00206	0.12998673276453562	930.8313711220918	nan	nan
134.88	3.2635683191133906	18.1811	4.01438	0.13054273276453562	927.439128515962	nan	nan
135.29	3.2766783191133904	18.1278	4.02703	0.1310671327645356	924.7202333143568	nan	nan
135.7	3.2897683191133904	18.0703	4.03881	0.13159073276453562	921.787091211312	nan	nan
136.1	3.3035383191133905	17.9993	4.05104	0.1321415327645356	918.1652983536395	nan	nan
136.51	3.31630831911339	17.9479	4.06331	0.1326523327645356	915.5433243693524	nan	nan
136.91	3.3299283191133906	17.9083	4.07572	0.13319713276453563	913.5232821557771	nan	nan
137.32	3.3441183191133903	17.8135	4.08813	0.1337647327645356	908.6874235232789	nan	nan
137.72	3.35718831911339	17.7646	4.09969	0.13428753276453562	906.1929774565157	nan	nan
138.13	3.3704083191133902	17.6923	4.11185	0.1348163327645356	902.5048700817306	nan	nan
138.54	3.3835183191133904	17.6325	4.12363	0.13534073276453562	899.454402294564	nan	nan
138.94	3.3971983191133903	17.582	4.13651	0.13588793276453562	896.8783383605855	nan	nan
139.35	3.4103183191133906	17.5075	4.14832	0.1364127327645356	893.0780064183797	nan	nan
139.75	3.4238383191133903	17.4608	4.16071	0.13695353276453562	890.6957849190371	nan	nan
140.16	3.4379683191133905	17.3729	4.17312	0.13751873276453563	886.2119033389044	nan	nan
140.57	3.4513683191133904	17.3252	4.1855	0.13805473276453561	883.7786706725523	nan	nan
140.97	3.4647583191133906	17.2402	4.19771	0.1385903327645356	879.442721476747	nan	nan
141.37	3.4780883191133904	17.1799	4.20999	0.13912353276453562	876.3667481060758	nan	nan
141.78	3.49194831911339	17.0951	4.22241	0.1396779327645356	872.0410011436721	nan	nan
142.19	3.5050183191133906	17.0507	4.23499	0.14020073276453562	869.7761053284516	nan	nan
142.59	3.5177683191133906	16.9852	4.24595	0.14071073276453563	866.434873889331	nan	nan
143.01	3.53268831911339	16.9181	4.25945	0.14130753276453561	863.0120245829951	nan	nan
143.43	3.5462183191133905	16.8291	4.27147	0.1418487327645356	858.472030719152	nan	nan
143.85	3.5601883191133905	16.7619	4.28439	0.14240753276453563	855.0440802961153	nan	nan
144.26	3.5751583191133904	16.6872	4.29745	0.14300633276453562	851.2335461205075	nan	nan
144.46	3.5818983191133906	16.6341	4.30325	0.14327593276453562	848.5248531523043	nan	nan