File: original_data/46NT75.csv
Specimen name:	AWA_1_03_Rz
Specimen ID:	46NT75
Material:	42CrMoS4
Specimen type:	Round Tensile Specimen
Gauge diameter:	5.013	mm
Gauge length:	25	mm
Parallel length:	30	mm
Original cross-section:	19.73718857846749	mm²
Cross-section after fracture:	8.408460170962467	mm²
Yield stress at 0.2% plastic strain:	1131.9124063134173	MPa
Yield stress at 1% plastic strain:	1147.9447523589256	MPa
Ultimate tensile strength:	1199.3096132153364	MPa
Uniform elongation:	4.955428909287775	%
Elongation after fracture:	15.296186528757818	%
Reduction of area:	57.3978829987176	%
Slope of linear-elastic region:	205699.73483288297	MPa
Crosshead seperation speed:	0.029807174515821325	mm/s
Strain rate:	0.000993572483860711	s-1
Test temperature:	RT	Cel
Machine type:	INSTRON 8852TT
Standard:	DIN EN ISO 6892-1
Date:	2022-08-18 00:00:00
Heat treatment batch:	Batch 1
Time	Displacement	Force	Machine Displacement	Engineering Strain	Engineering Stress	True Strain	True Stress
s	mm	kN	mm		MPa		MPa
0	0.0010316577626328196	0.171041	0	4.126631050531278e-05	8.665925206115684	4.126545907461559e-05	8.666282816876056
0.460001	0.0010064603626328196	0.171306	-0.000171661	4.0258414505312784e-05	8.679351637086159	4.025760415716927e-05	8.679701054022003
0.870001	0.0011944847626328195	0.25253	0.00639343	4.777939050531278e-05	12.794628728201973	4.777824910665404e-05	12.795240047764349
1.27	0.0020008687626328196	0.399172	0.0198288	8.003475050531278e-05	20.224359635266456	8.003154789545483e-05	20.225978286843993
1.67	0.0023963077626328196	0.500833	0.0292358	9.585231050531279e-05	25.37509321598059	9.58477169660573e-05	25.37752547729463
2.08	0.00347386776263282	0.667476	0.0427361	0.0001389547105053128	33.818190333763674	0.00013894505719374276	33.82288953061131
2.49	0.0043160877626328194	0.790698	0.0535698	0.00017264351050531277	40.061328737701835	0.00017262860932956445	40.06824506613062
2.94	0.00538786776263282	0.979065	0.0670395	0.0002155147105053128	49.60508920040021	0.0002154914905462843	49.615779826838825
3.31	0.0064384777626328195	1.15454	0.0788307	0.0002575391105053128	58.49566646282939	0.00025750595300136104	58.51073138473864
3.71001	0.0075319577626328195	1.32971	0.0895996	0.0003012783105053128	67.37079066319822	0.0003012329353087042	67.39108802118665
4.12001	0.00912046776263282	1.56509	0.103424	0.0003648187105053128	79.29650131161299	0.00036475218034012806	79.32543015896908
4.53001	0.01024510776263282	1.7521	0.113983	0.0004098043105053128	88.77150831458708	0.0004097203636526967	88.80788726134446
4.96001	0.01187705776263282	1.99822	0.127743	0.0004750823105053128	101.24136941063536	0.0004749694946342284	101.28946739433368
5.36001	0.01341785776263282	2.24067	0.139801	0.0005367143105053127	113.5252871041869	0.000536570330894706	113.58621775037994
5.76001	0.01487395776263282	2.47696	0.152359	0.0005949583105053128	125.49710360989648	0.0005947813929786487	125.57176915463354
6.17001	0.01652055776263282	2.70769	0.163498	0.0006608223105053128	137.1872183941124	0.0006606040635853146	137.2778747687434
6.58001	0.01817885776263282	2.97565	0.176319	0.0007271543105053128	150.7636200652366	0.0007268900619016783	150.87324848143444
6.98001	0.01975135776263282	3.22136	0.188118	0.0007900543105053128	163.21270819261358	0.000789742381881389	163.34165509625038
7.40001	0.02137565776263282	3.48056	0.199947	0.0008550263105053128	176.3452776550535	0.0008546609837373866	176.49605750718194
7.79001	0.02302465776263282	3.73549	0.21159	0.0009209863105053127	189.26150424864844	0.0009205624628318717	189.4358115031671
8.19001	0.02472985776263282	3.99665	0.223526	0.0009891943105053127	202.4933786344926	0.0009887053802182094	202.69368393255283
8.60001	0.02640245776263282	4.29313	0.236446	0.0010560983105053128	217.5147682727032	0.0010555410310112885	217.74448525198594
9.02001	0.02810155776263282	4.54556	0.247505	0.0011240623105053128	230.3043304231805	0.0011234310254912166	230.56320684095536
9.42001	0.03004135776263282	4.85652	0.261219	0.0012016543105053128	246.05936051592857	0.0012009329018290908	246.35503880713273
9.83001	0.03170985776263282	5.1163	0.27224	0.0012683943105053128	259.22131612917184	0.0012675905780033109	259.55011097171183
10.25	0.033440357762632815	5.42549	0.284973	0.0013376143105053126	274.8866677961926	0.0013367205014425212	275.25436013680394
10.64	0.03491865776263282	5.69411	0.296154	0.0013967463105053126	288.4965088802999	0.0013957717677311966	288.89946531467217
11.06	0.03687445776263282	6.02162	0.309689	0.0014749783105053127	305.09005758648703	0.00147389159845025	305.5400588041779
11.48	0.038714557762632815	6.33374	0.321926	0.0015485823105053126	320.90385998084173	0.0015473844933718795	321.4008060217809
11.89	0.04010245776263282	6.61397	0.333405	0.0016040983105053129	335.10193073878753	0.0016028131190091231	335.63946717973266
12.3	0.04203845776263282	6.93932	0.346302	0.0016815383105053129	351.586041366121	0.0016801261078540773	352.177246764117
12.71	0.043725057762632816	7.2077	0.357529	0.0017490023105053126	365.1837226636889	0.0017474745870328019	365.82242983838665
13.11	0.04548495776263282	7.5252	0.369461	0.0018193983105053127	381.27010693963285	0.001817745210194023	381.963789128045
13.53	0.04725815776263281	7.82304	0.381294	0.0018903263105053125	396.3604020348995	0.001888541892126593	397.1096525313085
13.93	0.04912895776263282	8.14745	0.39402	0.0019651583105053127	412.7968868316206	0.0019632299129037746	413.6080980643285
14.34	0.05089435776263282	8.45735	0.405739	0.0020357743105053126	428.49821120048694	0.0020337049300354106	429.37053685094634
14.75	0.052823957762632816	8.76503	0.418312	0.0021129583105053127	444.0870575438646	0.0021107291536190827	445.02539498268976
15.17	0.05477325776263282	9.097	0.431072	0.0021909303105053127	460.90657561657366	0.002188533722558882	461.91638980340315
15.58	0.05662605776263282	9.39375	0.442287	0.0022650423105053125	475.941645014641	0.0022624809691396425	477.0196729779306
16	0.05883345776263282	9.75661	0.456184	0.002353338310505313	494.32622894651195	0.0023505735466702138	495.48954579897935
16.41	0.06031195776263282	10.0247	0.466415	0.002412478310505313	507.9092171686782	0.002409572956503431	509.13453713880335
16.83	0.06268175776263282	10.4097	0.480854	0.002507270310505313	527.4155414087993	0.0025041323523454797	528.7379147370727
17.24	0.06434085776263282	10.6798	0.491383	0.002573634310505313	541.1003678432322	0.0025703281850137064	542.4929623153406
17.66	0.06640595776263282	11.0328	0.504711	0.002656238310505313	558.985387211447	0.0026527167442253097	560.4701856119707
18.07	0.06855545776263282	11.367	0.51741	0.0027422183105053127	575.9178899674171	0.0027384652893772637	577.4971825506333
18.47	0.07020575776263283	11.6549	0.528965	0.002808230310505313	590.5045672368478	0.0028042945983026333	592.1628400610541
18.88	0.07260125776263282	12.0311	0.542198	0.002904050310505313	609.5650326371947	0.0028998417024399315	611.335240159498
19.28	0.07420985776263282	12.3027	0.553127	0.002968394310505313	623.3258577374982	0.0029639973272848697	625.176134667197
19.7	0.07633435776263282	12.6685	0.566959	0.003053374310505313	641.8593990544755	0.0030487222304540554	643.8192360545047
20.11	0.07832025776263282	12.9687	0.578022	0.003132810310505313	657.0692653840453	0.003127913285252953	659.1277387533565
20.52	0.08051745776263282	13.3192	0.591106	0.0032206983105053126	674.8276203091424	0.003215522970862912	677.0010364857544
20.93	0.08250175776263283	13.6461	0.602985	0.003300070310505313	691.3902628912087	0.0032946370286713474	693.6718993707485
21.33	0.08457775776263282	13.9738	0.615929	0.003383110310505313	707.9934380950729	0.0033774004672144824	710.3886579952624
21.73	0.08649105776263283	14.2814	0.627064	0.003459642310505313	723.5782311762707	0.0034536715152945225	726.0815530398088
22.14	0.08864655776263282	14.6144	0.639229	0.0035458623105053128	740.4499349995443	0.003539590562207498	743.0754685168754
22.55	0.09081695776263282	14.9838	0.653114	0.0036326783105053127	759.1658731146111	0.0036260960706086818	761.9236785159505
22.96	0.09261695776263282	15.2741	0.664803	0.0037046783105053127	773.8741482494348	0.0036978328913211964	776.7411030215152
23.37	0.09495555776263283	15.6159	0.676811	0.0037982223105053133	791.1917109124824	0.003791027277280811	794.1968329207571
23.78	0.09699805776263282	15.9423	0.689018	0.0038799223105053125	807.7290206059253	0.0038724148246463606	810.8629464538168
24.2	0.09921035776263282	16.2893	0.702282	0.003968414310505312	825.3100453106579	0.003960560924571576	828.5852175050724
24.6	0.10111365776263283	16.6102	0.714073	0.004044546310505313	841.5686932292418	0.0040363891204343565	844.9724567824788
25.03	0.10317565776263282	16.9391	0.726006	0.004127026310505313	858.2326673658022	0.004118533496115201	861.774616164556
25.44	0.10533265776263283	17.282	0.739216	0.004213306310505313	875.6059623838217	0.004204455188421567	879.2951585106495
25.84	0.10743565776263282	17.6102	0.751404	0.0042974263105053125	892.2344704763093	0.004288218743859026	896.068782364874
26.24	0.10935665776263283	17.9062	0.762817	0.004374266310505313	907.2315405414412	0.00436472701578791	911.2000129050595
26.65	0.11157865776263283	18.2502	0.774982	0.004463146310505314	924.6605679144326	0.004453216008973376	928.7874633165897
27.06	0.11362965776263283	18.5738	0.787579	0.004545186310505313	941.0560134315836	0.004534888144139152	945.3332883412514
27.46	0.11571065776263283	18.8944	0.799732	0.004628426310505313	957.2994616169935	0.004617748081702426	961.7302516321743
27.86	0.11783265776263283	19.2249	0.811295	0.004713306310505313	974.0445009971494	0.004702233461837066	978.6354710904124
28.27	0.11993965776263282	19.5702	0.823788	0.004797586310505313	991.5393938805618	0.004786114569781236	996.29638970297
28.68	0.12206765776263283	19.8662	0.835972	0.004882706310505313	1006.5364639456938	0.004870824561080116	1011.451085889955
29.08	0.12413765776263282	20.2009	0.847626	0.004965506310505313	1023.4942995902874	0.004953218842923942	1028.5764669936693
29.51	0.12642965776263282	20.5495	0.86084	0.005057186310505312	1041.156389538615	0.005044441693690822	1046.4217113788848
29.91	0.12884565776263282	20.9004	0.873203	0.005153826310505313	1058.935010774611	0.005140590803876452	1064.3925778942564
30.31	0.13062065776263282	21.1301	0.883377	0.0052248263105053126	1070.5729398082624	0.005211224263833744	1076.1664974714874
30.72	0.1332406577626328	21.5065	0.896332	0.005329626310505312	1089.6435383640587	0.005315474113877269	1095.4509312351959
31.13	0.13572365776263282	21.7798	0.907928	0.005428946310505313	1103.4904952856823	0.005414262701858982	1109.4812859387412
31.53	0.1390756577626328	22.109	0.921455	0.005563026310505312	1120.1696691554168	0.005547609828077454	1126.4012024971585
31.95	0.1438696577626328	22.3294	0.935459	0.005754786310505312	1131.3364064606706	0.005738290782999469	1137.8470057251468
32.36	0.1492906577626328	22.4272	0.946663	0.005971626310505312	1136.291519475434	0.005953866817075843	1143.0770278095376
32.77	0.1578376577626328	22.3689	0.957092	0.006313506310505312	1133.3377046619298	0.00629365962053808	1140.4930394122466
33.17	0.1686026577626328	22.3938	0.970398	0.006744106310505312	1134.5992825153817	0.006721466558469419	1142.2511406964886
33.58	0.18021865776263282	22.3113	0.982155	0.007208746310505313	1130.4193558924985	0.007182887497533665	1138.5682622536124
33.99	0.18984665776263282	22.3535	0.993809	0.007593866310505313	1132.557451692325	0.007565178052725409	1141.157941569443
34.4	0.2027726577626328	22.3371	1.007	0.008110906310505312	1131.7265329454729	0.00807818969844113	1140.9058608233067
34.82	0.2140236577626328	22.3231	1.01951	0.008560946310505312	1131.017212064014	0.008524509219275262	1140.6997896927517
35.24	0.2250416577626328	22.3282	1.03166	0.009001666310505313	1131.2756075279742	0.008961392817586216	1141.4589730521552
35.66	0.23682665776263281	22.3382	1.0437	0.009473066310505313	1131.7822653004448	0.009428478187496593	1142.50371374869
36.0901	0.2488326577626328	22.3286	1.05599	0.009953306310505313	1131.2958738388731	0.00990409840872775	1142.5560081990022
36.4901	0.2603826577626328	22.3573	1.06915	0.010415306310505312	1132.7499816458637	0.010361440702769181	1144.5479196779245
36.9001	0.2703596577626328	22.3941	1.08049	0.010814386310505313	1134.614482248556	0.010756329029061706	1146.8846415730857
37.3201	0.2810016577626328	22.4348	1.09243	0.011240066310505312	1136.6765793825114	0.01117736616358264	1149.452899508369
37.7301	0.2924146577626328	22.4715	1.10587	0.011696586310505313	1138.536013407479	0.011628710012791709	1151.8529981559184
38.1401	0.3030026577626328	22.491	1.11797	0.012120106310505313	1139.5239960637966	0.012047245948112939	1153.3351480394617
38.5501	0.3138636577626328	22.5091	1.13006	0.012554546310505312	1140.4410466319684	0.012476391446729058	1154.7587665663104
38.9601	0.3238266577626328	22.5272	1.1418	0.012953066310505312	1141.3580972001405	0.01286989281167997	1156.142184317206
39.3601	0.3337566577626328	22.5488	1.1542	0.013350266310505312	1142.4524779886772	0.013261936785248075	1157.704522816923
39.7701	0.34513365776263283	22.5849	1.16726	0.013805346310505314	1144.2815125472964	0.01371092057791929	1160.0787151047207
40.1801	0.3565506577626328	22.5967	1.17995	0.014262026310505311	1144.8793687188115	0.014161280377484235	1161.207668397834
40.5801	0.3662216577626328	22.5943	1.19104	0.014648866310505312	1144.7577708534188	0.014542608119470803	1161.5271743965627
40.9901	0.3756196577626328	22.6142	1.20242	0.01502478631050531	1145.7660198206354	0.014913032205937106	1162.9809094302786
41.4101	0.3859116577626328	22.6472	1.21431	0.015436466310505312	1147.4379904697887	0.01531853613280079	1165.1503783530695
41.8101	0.39703765776263283	22.6736	1.22736	0.015881506310505313	1148.7755669891114	0.015756714707616856	1167.0198534056033
42.2201	0.4078196577626328	22.6825	1.23995	0.01631278631050531	1149.22649240661	0.016181162318793324	1167.9735785996106
42.6201	0.4178366577626328	22.695	1.25163	0.016713466310505312	1149.8598146221984	0.01657533332831306	1169.0779578956904
43.0501	0.4281656577626328	22.7104	1.26384	0.01712662631050531	1150.6400675918035	0.016981618962254676	1170.3466500473428
43.4701	0.4389636577626328	22.7289	1.27657	0.01755854631050531	1151.577384470874	0.017406176050790784	1171.7974093062364
43.8701	0.44868865776263284	22.7469	1.28833	0.017947546310505314	1152.4893684613214	0.017788390583231475	1173.173724774146
44.2801	0.4591016577626328	22.7707	1.30076	0.01836406631050531	1153.6952139598015	0.018197483183035466	1174.881749371072
44.6901	0.4700466577626328	22.7859	1.31335	0.018801866310505313	1154.465333773957	0.018627295992811516	1176.1714366396877
45.0901	0.48037665776263283	22.7981	1.32541	0.019215066310505312	1155.0834562563712	0.019032788213261476	1177.278461462505
45.4901	0.4904236577626328	22.8149	1.33727	0.019616946310505312	1155.934641314122	0.019427013929472645	1178.6105491112344
45.9001	0.5005716577626328	22.8329	1.34923	0.020022866310505313	1156.846625304569	0.019825044996376995	1180.0100106248017
46.3001	0.5106666577626328	22.8471	1.36142	0.020426666310505312	1157.5660793414777	0.020220840137414042	1181.2112953765459
46.7101	0.5216376577626328	22.8686	1.37392	0.02086550631050531	1158.6553935522895	0.020650803091905853	1182.8313249781556
47.1101	0.5319026577626328	22.8831	1.38643	0.021276106310505312	1159.3900473223719	0.02105292996008734	1184.0573532245444
47.5201	0.5419696577626328	22.9	1.39832	0.021678786310505314	1160.2462989578473	0.02144714327010135	1185.399030540509
47.9301	0.5523986577626329	22.9144	1.41098	0.022095946310505314	1160.9758861502053	0.02185536830501826	1186.6287469983715
48.3501	0.5630186577626328	22.9304	1.42389	0.022520746310505314	1161.786538586158	0.02227089851920995	1187.950838488617
48.7701	0.5735616577626328	22.9472	1.43588	0.02294246631050531	1162.6377236439089	0.022683245222268084	1189.3115004499318
49.1801	0.5838156577626328	22.9737	1.44815	0.02335262631050531	1163.9803667409562	0.023084125825434156	1191.1623652782228
49.6001	0.5953536577626328	22.9911	1.46224	0.023814146310505314	1164.861951265055	0.023535012400960165	1192.6021442040217
50.0001	0.6057426577626328	22.9923	1.47422	0.024229706310505313	1164.9227501977516	0.023940824029623428	1193.1484863094693
50.4201	0.6155716577626328	23.0038	1.48557	0.024622866310505313	1165.5054066360929	0.02432460957874452	1194.2034904478644
50.8301	0.6252566577626328	23.0202	1.49683	0.025010266310505312	1166.336325382945	0.02470262845290078	1195.5067074883887
51.2301	0.6351136577626328	23.0481	1.50872	0.025404546310505313	1167.7499005681382	0.025087214052295234	1197.4160569962094
51.6401	0.6458896577626329	23.0688	1.52208	0.025835586310505313	1168.7986821571524	0.025507486646897597	1198.9952813896284
52.0401	0.6566476577626328	23.0787	1.53475	0.02626590631050531	1169.3002733518983	0.02592688111432995	1200.0130047806076
52.4501	0.6671676577626328	23.0886	1.54687	0.02668670631050531	1169.8018645466443	0.026336827260486757	1201.0200233472822
52.8601	0.6768766577626328	23.101	1.55833	0.027075066310505314	1170.4301201845078	0.02671502108004859	1202.119593300316
53.2701	0.6870586577626329	23.1156	1.57027	0.027482346310505314	1171.1698405323152	0.027111486034333214	1203.3563356782436
53.6701	0.6969296577626328	23.1319	1.58142	0.027877186310505314	1171.9956927014423	0.0274956913264881	1204.6676349819902
54.0801	0.7070226577626328	23.1542	1.59401	0.028280906310505314	1173.125539534052	0.027888384871441588	1206.3025930080755
54.4801	0.7178116577626328	23.1704	1.60693	0.02871246631050531	1173.9463251254545	0.028307987590707566	1207.6532194359606
54.8901	0.7289826577626328	23.1827	1.62019	0.029159306310505312	1174.5695141855933	0.028742261497340178	1208.8191464327124
55.3101	0.7393576577626328	23.1894	1.63253	0.029574306310505314	1174.9089748931485	0.029145421967521484	1209.6560928036004
55.7301	0.7498316577626328	23.2032	1.64425	0.029993266310505313	1175.6081626191583	0.029552264657558294	1210.8684913173986
56.1401	0.7593996577626329	23.216	1.65631	0.030375986310505313	1176.2566845679207	0.029923770885303545	1211.9866415159963
56.5501	0.7699266577626328	23.2309	1.6679	0.030797066310505314	1177.011604648902	0.03033235376030517	1213.2601090855085
56.9601	0.7799416577626328	23.2503	1.68015	0.03119766631050531	1177.994520727495	0.03072090955892348	1214.745200700755
57.3801	0.7908766577626328	23.266	1.69322	0.03163506631050531	1178.7899734302741	0.031144986605635354	1216.0810724058997
57.7901	0.8013476577626328	23.2805	1.70558	0.032053906310505316	1179.5246272003565	0.031550900492182864	1217.3329990915706
58.1901	0.8122716577626328	23.29	1.71844	0.03249086631050531	1180.0059520842037	0.03197419962555036	1218.345367718972
58.6101	0.8229076577626329	23.2985	1.73046	0.032916306310505315	1180.4366111908037	0.03238616682664927	1219.2922242648951
59.0201	0.8327496577626328	23.3083	1.74225	0.03330998631050531	1180.933135807825	0.032767228674685636	1220.2700023952057
59.4301	0.8430656577626328	23.3211	1.75463	0.03372262631050531	1181.5816577565877	0.03316648701532519	1221.4276944564604
59.8301	0.8529876577626329	23.3389	1.7665	0.03411950631050532	1182.4835085915852	0.03355034611038123	1222.8292621250441
60.2401	0.8638526577626328	23.3577	1.77921	0.03455410631050531	1183.4360252038302	0.033970518730887744	1224.3285994304051
60.6401	0.8744566577626328	23.3662	1.79215	0.03497826631050531	1183.8666843104302	0.034380427763044674	1225.2762884703754
61.0401	0.8848446577626328	23.3713	1.80398	0.03539378631050531	1184.1250797743905	0.03478182422224918	1226.0357498128355
61.4501	0.8952936577626328	23.3792	1.81604	0.035811746310505314	1184.525339414642	0.03518541527015859	1226.9452603681243
61.8601	0.9052776577626328	23.391	1.82718	0.03621110631050531	1185.1231955861574	0.03557089364887443	1228.0378176125735
62.2701	0.9152376577626328	23.4008	1.83891	0.03660950631050531	1185.6197202031788	0.035955297395614684	1229.0246728318166
62.6801	0.9257176577626328	23.4164	1.85088	0.03702870631050531	1186.4101063282328	0.036359610938024305	1230.3413377192762
63.1101	0.9371126577626329	23.4312	1.8643	0.03748450631050532	1187.1599598314897	0.036799039334586524	1231.6600648373724
63.5101	0.9477406577626328	23.4429	1.87671	0.03790962631050531	1187.7527494252804	0.03720871574184202	1232.780012305268
63.9201	0.9583976577626329	23.4517	1.88904	0.03833590631050531	1188.1986082650544	0.03761934155588214	1233.7492787897763
64.3201	0.9688496577626328	23.4571	1.90071	0.03875398631050531	1188.4722034621889	0.03802190478353186	1234.5302389655785
64.7301	0.9796176577626328	23.466	1.91256	0.03918470631050531	1188.9231288796875	0.038436469474683044	1235.510732510605
65.1401	0.9901486577626328	23.4746	1.92508	0.03960594631050531	1189.3588545640123	0.03884174357502076	1236.4645375017988
65.5401	1.0003346577626329	23.4818	1.93688	0.040013386310505314	1189.7236481601913	0.03923358452285373	1237.3285200967687
65.9501	1.0109316577626328	23.4885	1.94909	0.040437266310505315	1190.0631088677467	0.03964107316511627	1238.1860077273395
66.3701	1.0213616577626328	23.4988	1.96115	0.04085446631050531	1190.5849663733914	0.0400419780445706	1239.2256797718871
66.7801	1.0318116577626328	23.5102	1.97353	0.04127246631050532	1191.162556234008	0.04044349055475115	1240.3247727065113
67.1901	1.0428416577626327	23.5196	1.9866	0.041713666310505305	1191.6388145401306	0.040867113160479085	1241.3464384125039
67.6101	1.0541616577626327	23.5359	1.99944	0.04216646631050531	1192.4646667092577	0.041301687107452245	1242.7466879045214
68.0301	1.065241657762633	23.5405	2.01204	0.04260966631050531	1192.697729284594	0.04172686465984445	1243.518181538708
68.4201	1.0758616577626328	23.5429	2.02397	0.04303446631050531	1192.819327149987	0.042134220832673805	1244.1516702987428
68.8301	1.0868216577626328	23.5452	2.03671	0.043472866310505315	1192.9358584376553	0.04255444461966677	1244.7961995285234
69.2501	1.0974016577626329	23.5499	2.04852	0.04389606631050531	1193.1739875907167	0.042959931162256146	1245.5496320699688
69.6401	1.1070516577626328	23.5574	2.06	0.04428206631050531	1193.5539809200695	0.043329631427158344	1246.4070174483395
70.0601	1.1176316577626328	23.5667	2.07166	0.044705266310505316	1194.0251726484673	0.043734803827374616	1247.4043859731644
70.4701	1.1287516577626329	23.5766	2.08381	0.04515006631050531	1194.526763843213	0.044160479231574505	1248.4597264404074
70.8801	1.1390716577626327	23.582	2.09597	0.04556286631050531	1194.8003590403475	0.04455536845708537	1249.2388880670464
71.2901	1.149841657762633	23.5913	2.10902	0.04599366631050532	1195.271550768745	0.04496731047191814	1250.246471625243
71.6901	1.1610416577626328	23.5965	2.12199	0.04644166631050531	1195.5350128104299	0.0453955196498662	1251.0576509378977
72.1101	1.1722016577626329	23.6013	2.13456	0.046888066310505315	1195.7782085412157	0.045822017205230034	1251.8459364759535
72.5101	1.1830016577626328	23.6049	2.14657	0.04732006631050531	1195.9606053393054	0.046234583653997394	1252.5535404887135
72.9201	1.1936416577626328	23.6093	2.15873	0.04774566631050531	1196.1835347591923	0.046640871627904604	1253.2961146559255
73.3301	1.205051657762633	23.6133	2.17096	0.04820206631050532	1196.3861978681807	0.047076378678114233	1254.0544847107963
73.7301	1.2155316577626327	23.6178	2.18281	0.04862126631050531	1196.6141938657925	0.04747622162059121	1254.7950912566716
74.1401	1.2261916577626328	23.6225	2.19495	0.04904766631050531	1196.8523230188537	0.04788276814396487	1255.5551363812356
74.5401	1.2369916577626328	23.6275	2.20688	0.04947966631050531	1197.105651905089	0.04829448544627213	1256.3380400997726
74.9501	1.2483516577626328	23.6335	2.21907	0.049934066310505315	1197.4096465685714	0.04872736820781186	1257.201179261165
75.3501	1.259451657762633	23.6363	2.23134	0.050378066310505315	1197.5515107448632	0.04915016251511319	1257.8818401634137
75.7701	1.2708616577626328	23.6399	2.24396	0.05083446631050531	1197.7339075429527	0.049584578358434155	1258.6200715148948
76.1901	1.2823116577626328	23.6424	2.25671	0.05129246631050531	1197.8605719860702	0.05002032750387304	1259.3017950193482
76.6001	1.2930816577626327	23.6445	2.26847	0.051723266310505306	1197.966970118289	0.0504300248726028	1259.9297347449067
77.0001	1.3038316577626328	23.6454	2.28038	0.05215326631050531	1198.0125693178113	0.050838794112926716	1260.4928378887757
77.4101	1.3152116577626327	23.6496	2.29209	0.05260846631050531	1198.2253655822492	0.051271337141472015	1261.262164359876
77.8301	1.3264416577626328	23.6507	2.3048	0.05305766631050531	1198.281097937221	0.05169799547999519	1261.85909657776
78.2401	1.3373616577626328	23.6541	2.31685	0.05349446631050531	1198.453361579861	0.05211270157674538	1262.5639845556066
78.6601	1.3485216577626329	23.6557	2.32925	0.05394086631050531	1198.5344268234564	0.052536344475548995	1263.1844121092786
79.0701	1.3600516577626327	23.6586	2.34205	0.05440206631050531	1198.6813575774727	0.05297384446686511	1263.892100277569
79.4901	1.3719516577626327	23.6674	2.35508	0.05487806631050531	1199.1272164172472	0.053425183291631644	1264.9329993145245
79.9101	1.3841516577626327	23.671	2.3684	0.05536606631050531	1199.3096132153364	nan	nan
80.3201	1.3961516577626327	23.6681	2.38165	0.05584606631050531	1199.16268246132	nan	nan
80.7201	1.4074116577626328	23.6635	2.39401	0.05629646631050531	1198.9296198859834	nan	nan
81.1301	1.4183016577626328	23.6593	2.40516	0.056732066310505314	1198.716823621546	nan	nan
81.5501	1.4294416577626328	23.66	2.41762	0.05717766631050531	1198.7522896656187	nan	nan
81.9501	1.4402316577626328	23.6625	2.42963	0.057609266310505315	1198.8789541087363	nan	nan
82.3601	1.4517916577626329	23.6648	2.44204	0.05807166631050532	1198.9954853964045	nan	nan
82.7601	1.4627716577626328	23.6661	2.4534	0.05851086631050531	1199.0613509068257	nan	nan
83.1801	1.474641657762633	23.6667	2.4661	0.058985666310505315	1199.091750373174	nan	nan
83.5901	1.4859216577626329	23.6656	2.47851	0.059436866310505314	1199.0360180182024	nan	nan
84.0001	1.4978116577626328	23.6659	2.49119	0.05991246631050531	1199.0512177513765	nan	nan
84.4101	1.5091216577626327	23.6644	2.50309	0.06036486631050531	1198.9752190855058	nan	nan
84.8201	1.5209616577626328	23.6627	2.51556	0.06083846631050531	1198.8890872641857	nan	nan
85.2401	1.532941657762633	23.6605	2.52827	0.061317666310505316	1198.7776225542423	nan	nan
85.6501	1.5442916577626329	23.6604	2.54053	0.06177166631050532	1198.7725559765174	nan	nan
86.0701	1.5563316577626327	23.659	2.55253	0.06225326631050531	1198.7016238883716	nan	nan
86.4801	1.5683816577626328	23.6567	2.56549	0.06273526631050531	1198.5850926007033	nan	nan
86.8801	1.579881657762633	23.6542	2.57768	0.06319526631050532	1198.4584281575858	nan	nan
87.2901	1.5913916577626328	23.6509	2.58891	0.06365566631050532	1198.2912310926704	nan	nan
87.6901	1.6028816577626328	23.6499	2.60141	0.0641152663105053	1198.2405653154233	nan	nan
88.1001	1.6151016577626327	23.6474	2.61415	0.0646040663105053	1198.1139008723057	nan	nan
88.5101	1.6265416577626328	23.6424	2.62612	0.0650616663105053	1197.8605719860702	nan	nan
88.9101	1.6381316577626328	23.6383	2.63797	0.06552526631050531	1197.6528422993572	nan	nan
89.3201	1.6500716577626329	23.6348	2.65044	0.06600286631050531	1197.4755120789926	nan	nan
89.7201	1.6618016577626329	23.6311	2.66206	0.06647206631050531	1197.2880487031784	nan	nan
90.1301	1.6731316577626327	23.6285	2.67417	0.06692526631050531	1197.156317682336	nan	nan
90.5301	1.6850016577626328	23.6243	2.68609	0.06740006631050531	1196.9435214178986	nan	nan
90.9401	1.6967516577626327	23.6192	2.69809	0.06787006631050531	1196.6851259539383	nan	nan
91.3601	1.7090616577626327	23.6152	2.71131	0.06836246631050531	1196.48246284495	nan	nan
91.7601	1.7213716577626328	23.6097	2.72341	0.06885486631050532	1196.2038010700912	nan	nan
92.1701	1.7332616577626327	23.606	2.73508	0.06933046631050531	1196.0163376942771	nan	nan
92.5701	1.7453316577626328	23.5998	2.74711	0.06981326631050531	1195.7022098753453	nan	nan
92.9801	1.7578316577626327	23.5905	2.76014	0.07031326631050532	1195.2310181469475	nan	nan
93.3901	1.7698716577626328	23.5834	2.77197	0.07079486631050531	1194.8712911284933	nan	nan
93.7901	1.7816716577626328	23.5757	2.78375	0.07126686631050531	1194.481164643691	nan	nan
94.2001	1.7943916577626329	23.5693	2.79697	0.07177566631050532	1194.1569036693097	nan	nan
94.6001	1.8061716577626328	23.5529	2.80866	0.07224686631050531	1193.3259849224578	nan	nan
95.0101	1.8171416577626327	23.5418	2.81935	0.07268566631050531	1192.7635947950153	nan	nan
95.4101	1.8285216577626329	23.5404	2.83038	0.07314086631050531	1192.6926627068694	nan	nan
95.8201	1.841001657762633	23.5396	2.84375	0.07364006631050532	1192.6521300850716	nan	nan
96.2301	1.8533316577626329	23.5321	2.85601	0.07413326631050532	1192.2721367557187	nan	nan
96.6501	1.866691657762633	23.5205	2.86863	0.07466766631050531	1191.6844137396529	nan	nan
97.0501	1.8794216577626328	23.5053	2.8815	0.07517686631050531	1190.9142939254973	nan	nan
97.4701	1.8926016577626328	23.4872	2.89415	0.07570406631050532	1189.9972433573255	nan	nan
97.8701	1.9051516577626328	23.4717	2.90625	0.07620606631050532	1189.2119238099958	nan	nan
98.2701	1.9177116577626327	23.4522	2.91835	0.0767084663105053	1188.2239411536782	nan	nan
98.6801	1.9279116577626327	23.3985	2.92766	0.07711646631050531	1185.5031889155105	nan	nan
99.0801	1.9406216577626327	23.4621	2.94129	0.0776248663105053	1188.725532348424	nan	nan
99.4901	1.9553816577626328	23.4114	2.95521	0.07821526631050531	1186.1567774419977	nan	nan
99.8901	1.9657016577626327	23.3501	2.96439	0.07862806631050531	1183.0509652967526	nan	nan
100.29	1.9765116577626327	23.3691	2.97578	0.07906046631050531	1184.0136150644466	nan	nan
100.71	1.9921516577626328	23.3771	2.99081	0.07968606631050532	1184.4189412824232	nan	nan
101.12	2.006931657762633	23.315	3.00425	0.08027726631050532	1181.2725965153804	nan	nan
101.55	2.018481657762633	23.2579	3.01455	0.08073926631050533	1178.3795806345727	nan	nan
101.96	2.029271657762633	23.2534	3.02489	0.08117086631050531	1178.151584636961	nan	nan
102.35	2.041211657762633	23.2528	3.03701	0.08164846631050532	1178.1211851706128	nan	nan
102.76	2.055731657762633	23.2387	3.05069	0.08222926631050533	1177.4067977114291	nan	nan
103.18	2.071371657762633	23.2004	3.06574	0.08285486631050532	1175.4662984428662	nan	nan
103.59	2.0831516577626332	23.0714	3.07568	0.08332606631050533	1168.9304131779948	nan	nan
104.02	2.095521657762633	23.1718	3.08955	0.08382086631050532	1174.0172572136003	nan	nan
104.42	2.108001657762633	23.0301	3.0993	0.08432006631050531	1166.837916577691	nan	nan
104.83	2.122211657762633	23.1135	3.11502	0.08488846631050531	1171.0634424000962	nan	nan
105.24	2.135421657762633	22.9922	3.1258	0.08541686631050531	1164.917683620027	nan	nan
105.65	2.146291657762633	22.9907	3.13633	0.08585166631050532	1164.8416849541563	nan	nan
106.06	2.160511657762633	22.9849	3.15016	0.08642046631050532	1164.5478234461234	nan	nan
106.46	2.174971657762633	22.9394	3.16438	0.08699886631050532	1162.2425305813817	nan	nan
106.87	2.188471657762633	22.8701	3.17598	0.08753886631050532	1158.7313922181602	nan	nan
107.29	2.1990016577626332	22.8224	3.1851	0.08796006631050533	1156.3146346434748	nan	nan
107.69	2.210381657762633	22.8403	3.19717	0.08841526631050532	1157.2215520561974	nan	nan
108.1	2.226211657762633	22.8191	3.21285	0.08904846631050532	1156.1474375785594	nan	nan
108.5	2.240521657762633	22.7424	3.22534	0.08962086631050532	1152.2613724637097	nan	nan
108.91	2.2520116577626332	22.6918	3.23561	0.09008046631050533	1149.6976841350079	nan	nan
109.33	2.264091657762633	22.6764	3.24722	0.09056366631050532	1148.917431165403	nan	nan
109.74	2.277591657762633	22.6572	3.26024	0.09110366631050532	1147.9446482422593	nan	nan
110.14	2.291251657762633	22.6169	3.27358	0.09165006631050533	1145.9028174192026	nan	nan
110.54	2.304901657762633	22.5768	3.28572	0.09219606631050531	1143.871119751595	nan	nan
110.98	2.318391657762633	22.5096	3.29809	0.09273566631050531	1140.466379520592	nan	nan
111.37	2.329761657762633	22.4782	3.30847	0.09319046631050533	1138.8754741150342	nan	nan
111.79	2.342151657762633	22.4571	3.32031	0.09368606631050533	1137.8064262151213	nan	nan
112.2	2.356081657762633	22.4318	3.33387	0.09424326631050532	1136.5245820507703	nan	nan
112.61	2.370161657762633	22.3907	3.34719	0.09480646631050532	1134.442218605916	nan	nan
113.03	2.385271657762633	22.3441	3.36073	0.09541086631050533	1132.0811933862026	nan	nan
113.46	2.398581657762633	22.2354	3.37183	0.09594326631050532	1126.5738233994462	nan	nan
113.86	2.407891657762633	22.2427	3.38054	0.09631566631050532	1126.94368357335	nan	nan
114.27	2.424421657762633	22.2437	3.39753	0.09697686631050532	1126.9943493505968	nan	nan
114.67	2.4364616577626332	22.1501	3.40768	0.09745846631050532	1122.2520326002714	nan	nan
115.07	2.448011657762633	22.136	3.41901	0.09792046631050531	1121.5376451410878	nan	nan
115.51	2.4622216577626332	22.1138	3.43261	0.09848886631050532	1120.412864886203	nan	nan
115.88	2.475551657762633	22.0745	3.44505	0.09902206631050532	1118.421699840393	nan	nan
116.28	2.489621657762633	22.0225	3.45774	0.09958486631050531	1115.7870794235455	nan	nan
116.7	2.503001657762633	21.9513	3.47008	0.10012006631050532	1112.1796760835543	nan	nan
117.11	2.513951657762633	21.9182	3.48019	0.10055806631050532	1110.5026388566762	nan	nan
117.53	2.526141657762633	21.9078	3.49195	0.10104566631050532	1109.9757147733071	nan	nan
117.93	2.539591657762633	21.8787	3.50492	0.10158366631050532	1108.5013406554172	nan	nan
118.33	2.553831657762633	21.8348	3.51839	0.10215326631050532	1106.2771130342712	nan	nan
118.73	2.568131657762633	21.7813	3.53184	0.10272526631050533	1103.566493951553	nan	nan
119.14	2.581721657762633	21.7065	3.54381	0.10326886631050533	1099.776693813472	nan	nan
119.56	2.592331657762633	21.6654	3.55397	0.10369326631050532	1097.6943303686178	nan	nan
119.97	2.604751657762633	21.6699	3.5657	0.10419006631050533	1097.9223263662295	nan	nan
120.39	2.620041657762633	21.6404	3.58044	0.10480166631050532	1096.427685937441	nan	nan
120.8	2.635301657762633	21.5787	3.59472	0.10541206631050531	1093.301607481297	nan	nan
121.21	2.648291657762633	21.4812	3.60563	0.10593166631050532	1088.361694199708	nan	nan
121.64	2.659051657762633	21.4628	3.61651	0.10636206631050532	1087.429443898362	nan	nan
122.07	2.673451657762633	21.4861	3.63069	0.10693806631050531	1088.6099565082186	nan	nan
122.48	2.690491657762633	21.3964	3.64534	0.10761966631050532	1084.0652362891567	nan	nan
122.89	2.701221657762633	21.2884	3.65432	0.10804886631050532	1078.593332346473	nan	nan
123.3	2.712691657762633	21.337	3.66682	0.10850766631050533	1081.0556891206807	nan	nan
123.71	2.729381657762633	21.2805	3.68214	0.10917526631050531	1078.1930727062215	nan	nan
124.13	2.741721657762633	21.1773	3.69217	0.10966886631050532	1072.964364494324	nan	nan
124.56	2.753381657762633	21.1702	3.70358	0.11013526631050531	1072.6046374758698	nan	nan
124.97	2.768331657762633	21.1627	3.71841	0.11073326631050533	1072.224644146517	nan	nan
125.38	2.784111657762633	21.0778	3.73232	0.11136446631050533	1067.9231196582407	nan	nan
125.8	2.7934316577626332	20.986	3.73989	0.11173726631050533	1063.27200130696	nan	nan
126.2	2.809851657762633	20.9882	3.75605	0.11239406631050532	1063.3834660169036	nan	nan
126.6	2.820291657762633	20.9053	3.76484	0.11281166631050532	1059.1832730831215	nan	nan
127.02	2.834831657762633	20.9624	3.78043	0.11339326631050532	1062.076288963929	nan	nan
127.43	2.848451657762633	20.7919	3.79081	0.11393806631050532	1053.4377739433041	nan	nan
127.83	2.859501657762633	20.8282	3.8031	0.11438006631050532	1055.2769416573728	nan	nan
128.25	2.875191657762633	20.7907	3.81742	0.11500766631050531	1053.3769750106078	nan	nan
128.66	2.889591657762633	20.6748	3.82941	0.11558366631050532	1047.5048114276728	nan	nan
129.07	2.900181657762633	20.642	3.83884	0.11600726631050533	1045.8429739339688	nan	nan
129.47	2.912701657762633	20.6754	3.85245	0.11650806631050532	1047.5352108940208	nan	nan
129.88	2.929921657762633	20.5751	3.86758	0.11719686631050533	1042.45343343614	nan	nan
130.28	2.939131657762633	20.4555	3.8747	0.11756526631050532	1036.3938064773906	nan	nan
130.68	2.952921657762633	20.5357	3.88939	0.11811686631050533	1040.4572018126053	nan	nan
131.09	2.968431657762633	20.3778	3.90182	0.11873726631050532	1032.4570755852935	nan	nan
131.5	2.978911657762633	20.4223	3.91314	0.11915646631050532	1034.711702672788	nan	nan
131.91	2.993951657762633	20.2901	3.92562	0.11975806631050531	1028.0136869207256	nan	nan
132.31	3.006151657762633	20.3326	3.93894	0.12024606631050531	1030.166982453726	nan	nan
132.72	3.0216716577626332	20.2241	3.95221	0.12086686631050533	1024.6697456224192	nan	nan
133.12	3.033421657762633	20.1704	3.96293	0.12133686631050532	1021.9489933842518	nan	nan
133.52	3.045441657762633	20.1425	3.97449	0.12181766631050532	1020.5354181990585	nan	nan
133.94	3.059171657762633	20.1023	3.98725	0.12236686631050532	1018.4986539537264	nan	nan
134.33	3.072881657762633	20.0541	3.99981	0.12291526631050533	1016.0565634904177	nan	nan
134.74	3.086821657762633	19.9831	4.01196	0.12347286631050532	1012.4592933058759	nan	nan
135.15	3.099131657762633	19.927	4.02302	0.12396526631050532	1009.6169432023155	nan	nan
135.55	3.111391657762633	19.8965	4.03483	0.12445566631050532	1008.07163699628	nan	nan
135.97	3.125311657762633	19.8538	4.0481	0.12501246631050533	1005.90820830783	nan	nan
136.38	3.139711657762633	19.8002	4.06076	0.12558846631050533	1003.1925226473874	nan	nan
136.79	3.154471657762633	19.7276	4.07431	0.12617886631050532	999.5141872192501	nan	nan
137.19	3.164001657762633	19.6251	4.08232	0.12656006631050531	994.3209450514257	nan	nan
137.61	3.178401657762633	19.7011	4.09756	0.1271360663105053	998.1715441222028	nan	nan
138.02	3.193611657762633	19.5286	4.10918	0.12774446631050532	989.4316975470839	nan	nan
138.44	3.204471657762633	19.514	4.11926	0.12817886631050532	988.6919771992766	nan	nan
138.84	3.219671657762633	19.5101	4.13383	0.12878686631050532	988.4943806680132	nan	nan
139.25	3.236011657762633	19.3872	4.14803	0.12944046631050532	982.2675566443485	nan	nan
139.66	3.246711657762633	19.3208	4.15665	0.12986846631050533	978.903349035143	nan	nan
140.06	3.257551657762633	19.3105	4.16735	0.13030206631050534	978.3814915294982	nan	nan
140.46	3.271411657762633	19.2778	4.17997	0.13085646631050532	976.7247206135191	nan	nan
140.87	3.287151657762633	19.2093	4.19465	0.13148606631050533	973.254114872095	nan	nan
141.29	3.303171657762633	19.13	4.20872	0.13212686631050533	969.2363187364026	nan	nan
141.71	3.313601657762633	19.0067	4.21706	0.13254406631050533	962.989228401839	nan	nan
142.12	3.326721657762633	19.0899	4.23107	0.13306886631050532	967.2046210687953	nan	nan
142.52	3.341051657762633	18.9204	4.24187	0.13364206631050532	958.6167718254173	nan	nan
142.93	3.352361657762633	18.9073	4.25267	0.1340944663105053	957.9530501434806	nan	nan
143.35	3.367191657762633	18.8701	4.2667	0.13468766631050533	956.0682832298899	nan	nan
143.76	3.382701657762633	18.7974	4.27991	0.13530806631050532	952.384881224028	nan	nan
144.16	3.396721657762633	18.6939	4.29218	0.13586886631050532	947.1409732789564	nan	nan
144.58	3.406841657762633	18.6278	4.30181	0.1362736663105053	943.7919654029253	nan	nan
145.01	3.4227016577626332	18.6564	4.31806	0.13690806631050534	945.2410066321914	nan	nan
145.43	3.4380216577626332	18.4881	4.32946	0.13752086631050534	936.7139563215098	nan	nan
145.84	3.448351657762633	18.461	4.33896	0.1379340663105053	935.3409137581144	nan	nan
146.25	3.462251657762633	18.4506	4.3521	0.1384900663105053	934.813989674745	nan	nan
146.66	3.478361657762633	18.3672	4.36631	0.1391344663105053	930.5884638523395	nan	nan
147.07	3.493381657762633	18.2489	4.37933	0.1397352663105053	924.5947024040113	nan	nan
147.48	3.503941657762633	18.2017	4.3886	0.14015766631050533	922.2032777179496	nan	nan
147.89	3.5161116577626332	18.1833	4.39948	0.14064446631050534	921.2710274166037	nan	nan
148.3	3.531031657762633	18.1284	4.41349	0.14124126631050532	918.4894762457396	nan	nan
148.71	3.547561657762633	18.0406	4.42772	0.14190246631050532	914.0410210034473	nan	nan
149.11	3.5577316577626332	17.8703	4.43497	0.14230926631050533	905.4126391382715	nan	nan
149.51	3.573221657762633	17.9588	4.4516	0.14292886631050533	909.8965604246371	nan	nan
149.94	3.584661657762633	17.8522	4.46027	0.1433864663105053	904.4955885700997	nan	nan
150.34	3.601521657762633	17.7767	4.47537	0.14406086631050533	900.6703223879462	nan	nan
150.76	3.612901657762633	17.6683	4.48486	0.14451606631050531	895.1781521343639	nan	nan
151.17	3.6254516577626332	17.669	4.49721	0.14501806631050532	895.2136181784368	nan	nan
151.57	3.642901657762633	17.592	4.51276	0.14571606631050532	891.3123533304126	nan	nan
151.98	3.655061657762633	17.4243	4.52148	0.14620246631050532	882.8157024860794	nan	nan
152.39	3.669031657762633	17.4857	4.53701	0.14676126631050532	885.9265812090495	nan	nan
152.81	3.683221657762633	17.2972	4.54708	0.14732886631050532	876.3760821979772	nan	nan
153.22	3.695241657762633	17.3245	4.55949	0.14780966631050532	877.7592579168221	nan	nan
153.62	3.712471657762633	17.2254	4.57496	0.14849886631050532	872.7382793916378	nan	nan
154.03	3.723921657762633	17.0909	4.58376	0.1489568663105053	865.9237323519072	nan	nan
154.43	3.735191657762633	17.1013	4.59489	0.14940766631050534	866.4506564352766	nan	nan
154.84	3.752361657762633	17.034	4.61095	0.15009446631050533	863.040849626549	nan	nan
155.24	3.766851657762633	16.8615	4.62214	0.15067406631050534	854.3010030514298	nan	nan
155.64	3.776111657762633	16.8707	4.6315	0.15104446631050533	854.7671282021029	nan	nan
156.05	3.795301657762633	16.7759	4.64813	0.1518120663105053	849.9640125190809	nan	nan
156.47	3.805781657762633	16.661	4.65662	0.15223126631050532	844.1425147133928	nan	nan
156.88	3.821261657762633	16.6768	4.67258	0.15285046631050533	844.9430339938964	nan	nan
157.28	3.835891657762633	16.5093	4.68362	0.15343566631050531	836.4565163050125	nan	nan
157.7	3.847911657762633	16.4681	4.69456	0.15391646631050532	834.3690862824334	nan	nan
158.09	3.861571657762633	16.4167	4.70679	0.15446286631050532	831.7648653319341	nan	nan
158.5	3.877421657762633	16.3289	4.72141	0.15509686631050532	827.3164100896417	nan	nan
158.9	3.892491657762633	16.1563	4.73227	0.15569966631050533	818.5714969367979	nan	nan
159.31	3.903401657762633	16.1913	4.74376	0.1561360663105053	820.344799140445	nan	nan
159.73	3.922291657762633	16.0303	4.75954	0.15689166631050533	812.1876090036673	nan	nan