File: original_data/46NTBZ.csv
Specimen name:	AWA_5_08_Rz
Specimen ID:	46NTBZ
Material:	42CrMoS4
Specimen type:	Round Tensile Specimen
Gauge diameter:	5.003	mm
Gauge length:	25	mm
Parallel length:	30	mm
Original cross-section:	19.6585230984216	mm²
Cross-section after fracture:	10.463467031862505	mm²
Yield stress at 0.2% plastic strain:	1079.7208386376167	MPa
Yield stress at 1% plastic strain:	1132.6192725556882	MPa
Ultimate tensile strength:	1184.331085475559	MPa
Uniform elongation:	5.176642848976898	%
Elongation after fracture:	12.927914011034089	%
Reduction of area:	46.77389049280805	%
Slope of linear-elastic region:	208577.38390072534	MPa
Crosshead seperation speed:	0.029914890708168225	mm/s
Strain rate:	0.0009971630236056074	s-1
Test temperature:	RT	Cel
Machine type:	INSTRON 8852TT
Standard:	DIN EN ISO 6892-1
Date:	2022-09-13 00:00:00
Heat treatment batch:	Batch 5
Time	Displacement	Force	Machine Displacement	Engineering Strain	Engineering Stress	True Strain	True Stress
s	mm	kN	mm		MPa		MPa
0	0.00042772856651866346	0.0706315	0	1.710914266074654e-05	3.592919958756773	1.7108996301130832e-05	3.5929814305369163
0.450001	0.00040460456651866345	0.0682276	-0.000991821	1.6184182660746537e-05	3.470637120520923	1.618405169822336e-05	3.4706932899460305
0.880001	0.0005318195665186635	0.0683897	-0.000656128	2.1272782660746538e-05	3.478882907815749	2.1272556398298378e-05	3.478956913335749
1.28	0.0007751755665186635	0.126421	0.00610351	3.100702266074654e-05	6.430849325102681	3.100654195299918e-05	6.431048726593432
1.68	0.0016481585665186634	0.257665	0.0188293	6.592634266074653e-05	13.107037528200076	6.592416961496103e-05	13.107901627247427
2.09	0.0028381685665186634	0.451825	0.0309143	0.00011352674266074654	22.983669614340325	0.00011352029898788409	22.986278875486036
2.51	0.004181968566518663	0.687196	0.0434418	0.00016727874266074652	34.95664432976532	0.00016726475313196484	34.96249183327644
2.93	0.0056361085665186635	0.939291	0.056572	0.00022544434266074653	47.780344194596005	0.00022541893390375743	47.79111600288506
3.35	0.007244568566518663	1.22159	0.069252	0.0002897827426607465	62.140476875299065	0.00028974076375134594	62.158484113118234
3.79001	0.009204578566518663	1.53596	0.0825348	0.0003681831426607465	78.13201390105056	0.00036811537987970096	78.16078079147105
4.21001	0.011098728566518664	1.83943	0.0949707	0.00044394914266074657	93.56908404516356	0.00044385062639642114	93.61062395980495
4.62001	0.013016628566518664	2.17145	0.107018	0.0005206651426607465	110.45845047099941	0.0005205296435964653	110.51596233587199
5.02001	0.014940728566518664	2.49215	0.119225	0.0005976291426607465	126.77198523627123	0.000597450633482721	126.84774786912139
5.44001	0.016997928566518664	2.83173	0.131302	0.0006799171426607465	144.0459176827664	0.0006796861037193197	144.14385697152923
5.87001	0.019346728566518662	3.22137	0.145523	0.0007738691426607464	163.86632830309853	0.0007735698603292834	163.9931393980934
6.27001	0.021354528566518663	3.56263	0.157593	0.0008541811426607465	181.22571986529582	0.0008538165375596384	181.38051945776988
6.69001	0.023675228566518665	3.93797	0.170364	0.0009470091426607466	200.31871063173523	0.0009465610124025031	200.5084142821495
7.11001	0.026091528566518665	4.33431	0.183258	0.0010436611426607465	220.47994034445068	0.0010431169070025533	220.71004669092434
7.53001	0.028379228566518665	4.72567	0.195274	0.0011351691426607466	240.38784482133494	0.001134525325351061	240.66072568504683
7.96001	0.030824828566518664	5.1188	0.207642	0.0012329931426607467	260.3857865808339	0.001232233630866869	260.70684047013435
8.37001	0.03335522856651866	5.53246	0.220665	0.0013342091426607463	281.42805908162075	0.0013333198765326292	281.80354297104867
8.77001	0.03567532856651866	5.92164	0.232437	0.0014270131426607463	301.2250701821773	0.001425995927011217	301.6549223162262
9.18001	0.037935128566518664	6.29558	0.244621	0.0015174051426607466	320.246845018865	0.0015162550467712034	320.73278922841746
9.58001	0.04036872856651866	6.69686	0.256233	0.0016147491426607462	340.65936522656153	0.0016134468370067438	341.2094446445005
9.98001	0.04260282856651866	7.07833	0.268097	0.0017041131426607464	360.06418002827104	0.0017026627893362257	360.6777701296586
10.42	0.04549562856651866	7.52688	0.28157	0.0018198251426607465	382.8812552355136	0.0018181712670912945	383.57803217044466
10.84	0.04803022856651866	7.93878	0.294144	0.0019212091426607464	403.83399913889826	0.0019193659807313502	404.6098487101612
11.25	0.05055622856651866	8.34972	0.30674	0.0020222491426607463	424.7379092618817	0.002020207149345921	425.59683513474204
11.65	0.05302792856651866	8.75902	0.319115	0.0021211171426607466	445.5583950100132	0.002118870749708488	446.50347655972536
12.08	0.05552142856651866	9.14706	0.330536	0.0022208571426607466	465.2974159963433	0.0022183946846077766	466.33077508612035
12.49	0.05814992856651866	9.59368	0.343369	0.0023259971426607463	488.016314957571	0.0023232961987546845	489.15143951173417
12.89	0.06058252856651866	9.99366	0.355309	0.0024233011426607466	508.3627060876409	0.0024203696833639456	509.59462201418916
13.29	0.06288142856651867	10.385	0.366722	0.002515257142660747	528.2695931941001	0.002512099177701405	529.5983270616321
13.7	0.06523342856651866	10.7689	0.378815	0.0026093371426607463	547.7980185024502	0.0026059387329461672	549.2274082188046
14.1	0.06765452856651867	11.1616	0.391167	0.0027061811426607467	567.7740867978112	0.0027025260272569218	569.3105863247948
14.51	0.07021852856651867	11.5814	0.40332	0.0028087411426607465	589.1286920190805	0.002804803999811232	590.7834020146764
14.91	0.07281002856651866	12.0038	0.415833	0.0029124011426607467	610.6155553956032	0.0029081683189150663	612.3939128368637
15.32	0.07513412856651867	12.3932	0.42733	0.003005365142660747	630.423757570835	0.003000858060866694	632.3184111569436
15.72	0.07746012856651867	12.7942	0.439156	0.0030984051426607468	650.8220345925813	0.0030936149774778176	652.8385449315199
16.15	0.08023902856651867	13.2274	0.452049	0.0032095611426607466	672.8582779986173	0.003204421495700978	675.0178577821993
16.55	0.08274272856651867	13.6387	0.465096	0.0033097091426607466	693.7805007892513	0.0033042441104809916	696.0767124557133
16.97	0.08514272856651867	14.0523	0.47673	0.0034057091426607468	714.8197211787631	0.0033999228491784187	717.2541892385358
17.4	0.08756742856651867	14.4506	0.488785	0.003502697142660747	735.0806531931308	0.0034965769862300997	737.6554180966957
17.8	0.09001792856651866	14.8512	0.500664	0.0036007171426607463	755.4585828063765	0.0035942500800827536	758.1787754760576
18.21	0.09245442856651867	15.2454	0.513306	0.003698177142660747	775.5109538836143	0.0036913556983383623	778.3789307671498
18.61	0.09534982856651866	15.6577	0.5252	0.0038139931426607464	796.4840451954994	0.003806738311547757	799.5218298821138
19.02	0.09734122856651867	16.0379	0.537369	0.003893649142660747	815.8242569752199	0.003886088510116451	819.0007903939533
19.42	0.09979982856651867	16.4402	0.549194	0.003991993142660747	836.2886630745927	0.0039840462802282015	839.6271216828715
19.83	0.10243172856651866	16.8555	0.561798	0.004097269142660747	857.4143599502316	0.004088898193012822	860.92741734973
20.23	0.10465472856651867	17.23	0.572914	0.004186189142660747	876.46462115882	0.004177451429550311	880.1336678398412
20.64	0.10724072856651867	17.6305	0.585213	0.004289629142660747	896.8374639199405	0.004280454910249362	900.6845640414016
21.05	0.10983972856651866	18.041	0.597733	0.004393589142660747	917.7189918935735	0.004383965507785464	921.7510720923707
21.45	0.11204272856651867	18.3955	0.609421	0.004481709142660747	935.7518826771371	0.004471696189855933	939.9456504449932
21.87	0.11482972856651867	18.8219	0.622147	0.004593189142660747	957.4422201386647	0.004582672639971854	961.8399333489306
22.28	0.11746272856651867	19.2003	0.634048	0.004698509142660747	976.6908685801329	0.004687505601941893	981.27985955571
22.69	0.12012872856651867	19.5622	0.646263	0.004805149142660747	995.1001864209559	0.00479364126351232	999.8817912285982
23.09	0.12337772856651867	19.8976	0.658089	0.004935109142660747	1012.161488448621	0.004922971409182	1017.156615864113
23.49	0.12772772856651865	20.1977	0.670441	0.005109109142660746	1027.4271316761171	0.005096101929248821	1032.6763690279813
23.91	0.13360972856651865	20.432	0.682457	0.005344389142660746	1039.345626205282	0.0053301585749507266	1044.9002936854456
24.32	0.14035372856651865	20.5938	0.694725	0.005614149142660746	1047.5761529437325	0.005598448543622096	1053.4574017046534
24.74	0.14799572856651866	20.7257	0.706383	0.005919829142660747	1054.2857108967705	0.005902375800782993	1060.526902172828
25.16	0.15606272856651865	20.8768	0.720016	0.006242509142660746	1061.9719444578325	0.006223105392651908	1068.6013140303598
25.58	0.16362472856651866	20.9971	0.732124	0.006544989142660746	1068.0914275643563	0.006523663700505793	1075.0820743611341
26.02	0.17229672856651865	21.1296	0.745522	0.006891869142660746	1074.8315066301452	0.006868228767947038	1082.239104724249
26.43	0.18053172856651864	21.2412	0.758492	0.007221269142660746	1080.5084336017833	0.007195320624581581	1088.3110758117366
26.83	0.18839472856651865	21.321	0.769997	0.007535789142660746	1084.567741597632	0.007507536930028051	1092.7408154092436
27.24	0.19655572856651865	21.408	0.782204	0.007862229142660746	1088.9933029464898	0.007831482870128054	1097.555217829078
27.64	0.20498672856651864	21.4992	0.7938	0.008199469142660745	1093.6325120846025	0.008166036126541232	1102.5997181208509
28.06	0.21373472856651865	21.5734	0.806122	0.008549389142660745	1097.4069563614444	0.00851305008623556	1106.7891154792412
28.47	0.22302072856651867	21.6514	0.819176	0.008920829142660746	1101.374701019041	0.008881273617696382	1111.1998765488809
28.88	0.23206972856651864	21.7047	0.831429	0.009282789142660746	1104.085993201732	0.009239968846068236	1114.3349906719889
29.28	0.24061972856651864	21.747	0.842873	0.009624789142660746	1106.2377316506593	0.009578765933116528	1116.8850365594524
29.7	0.24971172856651866	21.7877	0.854622	0.009988469142660746	1108.3080804655847	0.009938914097562352	1119.3783815278769
30.12	0.25968372856651867	21.8613	0.868759	0.010387349142660747	1112.0520036296757	0.010333771333104726	1123.6032760561725
30.54	0.26944172856651866	21.9049	0.88195	0.010777669142660746	1114.2698711562296	0.01072000402694312	1126.2791031631866
30.98	0.2791497285665187	21.9453	0.89447	0.011165989142660749	1116.3249594147796	0.011104109690009635	1128.7898317912864
31.39	0.2890777285665187	21.9782	0.906357	0.011563109142660748	1117.9985337639453	0.011496767318200074	1130.9260728311924
31.8	0.29862272856651867	22.0225	0.918747	0.011944909142660746	1120.252009255375	0.011874131777427011	1133.6333177228134
32.2	0.3079497285665187	22.0492	0.930099	0.012317989142660747	1121.6101987727832	0.012242740029389165	1135.426181023564
32.61	0.3181457285665187	22.0876	0.942749	0.012725829142660747	1123.5635499888306	0.012645536257136514	1137.8618277569099
33.01	0.3274097285665187	22.1109	0.954712	0.013096389142660748	1124.7487865339845	0.013011372904388242	1139.478934330169
33.42	0.3372927285665187	22.1422	0.968163	0.013491709142660749	1126.3409712491482	0.013401506454810813	1141.5372360287038
33.82	0.34656672856651866	22.1713	0.979759	0.013862669142660745	1127.8212452175592	0.013767461226323103	1143.4558579920738
34.23	0.3563067285665187	22.1955	0.991394	0.014252269142660748	1129.0522634318393	0.014151660363598688	1145.1438201664002
34.63	0.3662347285665187	22.2176	1.0033	0.014649389142660747	1130.1764577514916	0.014543123403169433	1146.732852480967
35.05	0.37630572856651867	22.2434	1.01613	0.015052229142660746	1131.4888655997736	0.014940068453279607	1148.5202952771506
35.47	0.38664472856651866	22.2692	1.02835	0.015465789142660747	1132.8012734480553	0.015347412788069465	1150.3209390837405
35.9101	0.3969527285665187	22.2903	1.04117	0.01587810914266075	1133.8745992464565	0.01575337064287735	1151.8783838873824
36.3201	0.4069887285665187	22.3163	1.05307	0.01627954914266075	1135.1971807989887	0.016148458104310516	1153.677679090416
36.7201	0.4169937285665187	22.327	1.06564	0.01667974914266075	1135.741473976377	0.016542169877592886	1154.6853568532185
37.1401	0.4270477285665187	22.361	1.07865	0.017081909142660747	1137.471003698919	0.01693765378653918	1156.9011800365151
37.5501	0.4368777285665187	22.3694	1.09048	0.017475109142660747	1137.8982992774293	0.017324175276339122	1157.7831962505504
37.9701	0.4467867285665187	22.3858	1.10341	0.01787146914266075	1138.7325430259496	0.017713651947525194	1159.0833665303815
38.3901	0.4570377285665187	22.4181	1.11668	0.01828150914266075	1140.3755962623645	0.01811641147484538	1161.223383151502
38.8101	0.46712472856651865	22.4361	1.12856	0.018684989142660747	1141.2912296448867	0.018512569198221432	1162.6162438794154
39.2301	0.47741072856651867	22.4563	1.14117	0.019096429142660746	1142.3187737741619	0.01891638091413849	1164.1329832958713
39.6401	0.48784272856651867	22.4757	1.15407	0.01951370914266075	1143.3056230864358	0.019325757869536726	1165.615756476513
40.0601	0.4981777285665187	22.4878	1.16655	0.01992710914266075	1143.9211321935759	0.01973116311783371	1166.7161734453932
40.4701	0.5077677285665186	22.5102	1.17873	0.020310709142660744	1145.0605870696036	0.020107197716430134	1168.3175796042985
40.8801	0.5179967285665186	22.5224	1.19132	0.020719869142660743	1145.6811830288686	0.0205081324303282	1169.4195472204356
41.2801	0.5276937285665186	22.5445	1.20344	0.021107749142660746	1146.805377348521	0.020888066565014574	1171.011857569048
41.6801	0.5370527285665186	22.5587	1.21507	0.021482109142660747	1147.5277103502885	0.021254620822270913	1172.1790258682609
42.1001	0.5470817285665186	22.5808	1.22762	0.021883269142660745	1148.651904669941	0.02164726719811446	1173.7881634510632
42.5101	0.5571877285665187	22.6057	1.24061	0.022287509142660745	1149.9185308490967	0.022042772318883713	1175.5473506187109
42.9201	0.5672147285665187	22.6186	1.25313	0.022688589142660746	1150.5747347732379	0.022435031187316552	1176.6796522084337
43.3401	0.5772487285665187	22.6393	1.26525	0.023089949142660746	1151.6277131631382	0.022827409929823076	1178.2187384913539
43.7401	0.5872707285665186	22.6577	1.27759	0.023490829142660746	1152.563693954161	0.023219165788551325	1179.6383707648722
44.1601	0.5974317285665186	22.6674	1.29005	0.023897269142660743	1153.0571186102982	0.02361619848174651	1180.6120349105893
44.5701	0.6070127285665187	22.6854	1.3021	0.024280509142660747	1153.9727519928203	0.02399042381368377	1181.9917979479635
44.9901	0.6171897285665187	22.7021	1.315	0.024687589142660747	1154.8222562977162	0.024387775051798954	1183.3320336939946
45.4001	0.6271117285665186	22.7181	1.32777	0.025084469142660746	1155.6361526377357	0.02477501811461212	1184.6246720487202
45.8001	0.6369587285665186	22.7345	1.33955	0.02547834914266074	1156.4703963862562	0.025159185818553455	1185.9353529185364
46.2201	0.6470667285665186	22.7567	1.35183	0.025882669142660745	1157.5996775580334	0.02555338264849393	1187.5614470119187
46.6301	0.6567727285665186	22.7567	1.3637	0.026270909142660743	1157.5996775580334	0.02593175589379093	1188.0108735107337
47.0401	0.6666977285665187	22.7807	1.37646	0.026667909142660748	1158.8205220680634	0.026318518520531412	1189.723842463225
47.4401	0.6768127285665186	22.797	1.38835	0.027072509142660746	1159.6496789644584	0.026712531319453836	1191.0443055005073
47.8601	0.6869807285665186	22.802	1.40102	0.027479229142660745	1159.9040215707146	0.027108452237612175	1191.77728996295
48.2701	0.6967097285665186	22.824	1.4129	0.027868389142660745	1161.023129038242	0.027487132711112996	1193.3789734019092
48.6701	0.7065927285665187	22.8314	1.42479	0.028263709142660746	1161.3995560955009	0.027871660539067925	1194.2250153473994
49.0901	0.7162647285665186	22.8408	1.4369	0.02865058914266074	1161.8777201952628	0.028247835671774912	1195.1662013905886
49.5001	0.7263387285665186	22.8583	1.44954	0.029053549142660742	1162.7679193171593	0.02863949548102895	1196.5504542025496
49.9001	0.7359877285665186	22.8645	1.46162	0.029439509142660743	1163.083304148917	0.02901448824864538	1197.3239057150852
50.3401	0.7466897285665186	22.8911	1.47467	0.029867589142660744	1164.4364068142	0.02943023974731462	1199.2153149956825
50.7501	0.7566047285665186	22.898	1.48625	0.030264189142660745	1164.7873996108335	0.029815263665764646	1200.0387457836437
51.1501	0.7663117285665186	22.9206	1.49918	0.030652469142660746	1165.9370281911113	0.03019206687421384	1201.675876970025
51.5601	0.7765667285665186	22.9271	1.51121	0.031062669142660745	1166.2676735792443	0.030589988000944954	1202.495060455417
51.9601	0.7861137285665186	22.938	1.52309	0.031444549142660747	1166.822140460883	0.030960294587974755	1203.5123365973498
52.4001	0.7972027285665186	22.9459	1.53632	0.03188810914266074	1167.2240017787678	0.03139023980795834	1204.4445681414225
52.8101	0.8065487285665186	22.9559	1.54762	0.03226194914266074	1167.7326869912802	0.03175246153945199	1205.4060195512154
53.2101	0.8163007285665186	22.9797	1.56009	0.03265202914266074	1168.9433577970597	0.032130278735463404	1207.111730381969
53.6201	0.8263587285665186	22.9806	1.5729	0.03305434914266074	1168.9891394661856	0.03251980166990943	1207.6293146260793
54.0201	0.8360287285665187	22.9788	1.58315	0.03344114914266075	1168.8975761279335	0.032894155260167104	1207.9868543037223
54.4401	0.8464147285665187	23.0037	1.59628	0.033856589142660744	1170.164202307089	0.03329607124730209	1209.7819709340495
54.8501	0.8563277285665186	23.0193	1.60896	0.03425310914266075	1170.9577512386086	0.03367953253582808	1211.0666948932292
55.2701	0.8666947285665186	23.0241	1.6214	0.03466778914266075	1171.2019201406147	0.03408039851953651	1211.804901351529
55.6801	0.8768497285665187	23.0365	1.63334	0.035073989142660744	1171.8326898041298	0.034472911256610096	1212.9335368433349
56.0801	0.8867597285665186	23.0496	1.64542	0.03547038914266074	1172.499067432521	0.034855805734989816	1214.0880656237593
56.5101	0.8973047285665187	23.0593	1.65831	0.03589218914266075	1172.992492088658	0.03526307388809069	1215.0937604776252
56.9101	0.9069907285665186	23.0676	1.6698	0.036279629142660745	1173.4147008150433	0.035637019717385435	1215.9857509911594
57.3101	0.9169867285665186	23.0758	1.68168	0.036679469142660744	1173.8318226893034	0.03602278710207656	1216.887350808309
57.7201	0.9273917285665186	23.0927	1.69409	0.03709566914266074	1174.6915006984493	0.03642418067450801	1218.2674679530546
58.1401	0.9378807285665186	23.1041	1.70647	0.03751522914266074	1175.2714018407135	0.036828651706706635	1219.361977785584
58.5501	0.9480987285665187	23.1001	1.71794	0.03792394914266075	1175.0679277557085	0.03722251533765281	1219.631144087088
58.9501	0.9583457285665187	23.1097	1.72968	0.038333829142660744	1175.5562655597205	0.03761734107616295	1220.619838591271
59.3701	0.9687507285665187	23.1114	1.74289	0.03875002914266075	1175.6427420458476	0.038018095243030285	1221.1989325614818
59.7801	0.9797047285665186	23.1283	1.75516	0.03918818914266074	1176.5024200549933	0.038439820973505	1222.6074194189064
60.2001	0.9907147285665187	23.1462	1.76776	0.03962858914266074	1177.4129665853907	0.03886352354430279	1224.0721812894444
60.6101	1.0009277285665186	23.1315	1.7799	0.040037109142660746	1176.6651993229973	0.03925639438464165	1223.775472332663
61.0101	1.0112177285665187	23.1596	1.79183	0.04044870914266075	1178.0946047701573	0.03965207120373125	1225.7470107810434
61.4301	1.0218577285665187	23.1622	1.80482	0.04087430914266075	1178.2268629254102	0.04006104184614742	1226.3860719608106
61.8401	1.0325377285665187	23.1514	1.81688	0.04130150914266075	1177.677482895897	0.04047138183976637	1226.3173402228274
62.2401	1.0426277285665186	23.1701	1.82903	0.04170510914266075	1178.6287242432952	0.04085889861624496	1227.783563826537
62.6501	1.0530177285665185	23.1845	1.84102	0.042120709142660744	1179.361230949313	0.0412577803287792	1229.0367623322595
63.0701	1.0639677285665186	23.186	1.85346	0.042558709142660744	1179.43753373119	0.04167798882952335	1229.6328726811926
63.4801	1.0752377285665187	23.2039	1.8657	0.043009509142660746	1180.348080261587	0.04211029308413213	1231.1142718111198
63.8801	1.0855677285665186	23.2093	1.87811	0.04342270914266075	1180.6227702763435	0.042506375930035874	1231.8886094372556
64.3001	1.0965177285665186	23.1991	1.8909	0.04386070914266074	1180.1039113595812	0.04292606019772281	1231.86410577384
64.7301	1.1070977285665187	23.2009	1.9028	0.04428390914266075	1180.1954746978333	0.043331396113720506	1232.4591438699315
65.1301	1.1176477285665187	23.224	1.91574	0.044705909142660746	1181.370537538737	0.04373541915112021	1234.18478145376
65.5401	1.1286177285665187	23.2223	1.92764	0.04514470914266075	1181.2840610526098	0.04415535347810893	1234.612786403691
65.9701	1.1395377285665187	23.225	1.94009	0.04558150914266075	1181.4214060599882	0.0445731987249281	1235.2723766816466
66.3901	1.1506477285665186	23.2284	1.95293	0.04602590914266075	1181.5943590322424	0.0449981350708236	1235.9783136445408
66.8001	1.1615777285665185	23.2392	1.96597	0.04646310914266074	1182.1437390617557	0.04541601062719845	1237.0698126320951
67.2201	1.1729777285665186	23.2434	1.97839	0.046919109142660745	1182.357386851011	0.04585166925009997	1237.8325421303048
67.6301	1.1832277285665187	23.2374	1.99008	0.047329109142660745	1182.0521757235035	0.04624321787519427	1237.9976521606407
68.0301	1.1939277285665186	23.2415	2.0021	0.04775710914266074	1182.2607366606335	0.04665179295169336	1238.722091696418
68.4401	1.2048077285665186	23.2413	2.01495	0.04819230914266075	1182.2505629563832	0.04706707015490992	1239.225947570462
68.8501	1.2154677285665185	23.2565	2.02642	0.04861870914266074	1183.023764479402	0.0474737830175944	1240.5408527934815
69.2601	1.2266977285665186	23.2612	2.03889	0.049067909142660744	1183.2628465292828	0.047902064347084335	1241.3230803746676
69.6701	1.2372377285665186	23.263	2.05088	0.049489509142660745	1183.354409867535	0.04830386417586066	1241.9180387536824
70.0901	1.2485577285665186	23.2548	2.06376	0.04994230914266074	1182.9372879932748	0.04873521898631663	1242.0159077266158
70.5101	1.2596477285665186	23.262	2.07658	0.050385909142660744	1183.3035413462837	0.04915762916272061	1242.9253660687464
70.9201	1.2709277285665186	23.2655	2.08891	0.05083710914266074	1183.4815811706633	0.04958709333954368	1243.646363480965
71.3201	1.2818677285665185	23.2702	2.10113	0.05127470914266074	1183.720663220544	0.05000343656402359	1244.4155959333348
71.7301	1.2926677285665187	23.2653	2.11263	0.05170670914266075	1183.471407466413	0.05041428185473379	1244.6648193109343
72.1301	1.3032677285665186	23.2737	2.12466	0.05213070914266074	1183.8987030449234	0.050817354831814	1245.6161819877318
72.5601	1.3150777285665187	23.2608	2.13724	0.052603109142660746	1183.2424991207822	0.05126624770731999	1245.4847334442672
72.9601	1.3259577285665187	23.263	2.14951	0.05303830914266075	1183.354409867535	0.05167961344226208	1246.1175268834202
73.3801	1.3375777285665187	23.2766	2.16219	0.053503109142660744	1184.0462217565519	0.0521209055084976	1247.3963759891478
73.8101	1.3490877285665186	23.2675	2.17503	0.053963509142660744	1183.5833182131657	0.05255782821306576	1247.4536274266625
74.2101	1.3602777285665186	23.277	2.18761	0.054411109142660743	1184.0665691650524	0.05298242069567534	1248.4929444920679
74.6301	1.3710077285665185	23.2724	2.19941	0.05484030914266074	1183.8325739672969	0.05338938972952608	1248.7543182968152
75.0501	1.3827177285665186	23.2672	2.21203	0.05530870914266075	1183.5680576567904	0.05383333942562259	1249.0296791082737
75.4701	1.3945977285665185	23.2665	2.22475	0.055783909142660744	1183.5324496919145	0.05428353285049656	1249.554516332919
75.8901	1.4061877285665185	23.2704	2.23765	0.05624750914266074	1183.7308369247942	0.05472254147833403	1250.3127479971708
76.3301	1.4182877285665185	23.2751	2.25048	0.056731509142660744	1183.969918974675	0.055180662457554985	1251.1383192576222
76.7501	1.4304177285665187	23.2712	2.26393	0.05721670914266075	1183.7715317417953	0.05563970871452884	1251.5030431648277
77.1601	1.4415177285665186	23.2739	2.27567	0.05766070914266074	1183.9088767491737	nan	nan
77.5601	1.4527677285665186	23.2726	2.28761	0.05811070914266074	1183.8427476715472	nan	nan
77.9801	1.4644277285665186	23.2594	2.29987	0.05857710914266075	1183.1712831910304	nan	nan
78.4201	1.4768377285665186	23.2672	2.31326	0.05907350914266075	1183.5680576567904	nan	nan
78.8301	1.4889977285665186	23.2657	2.32592	0.059559909142660745	1183.4917548749133	nan	nan
79.2401	1.4999677285665187	23.2571	2.33788	0.05999870914266075	1183.0542855921528	nan	nan
79.6401	1.5118877285665187	23.2558	2.35036	0.06047550914266075	1182.988156514526	nan	nan
80.0501	1.5234577285665187	23.2502	2.36243	0.06093830914266075	1182.7032927955192	nan	nan
80.4501	1.5350877285665185	23.2556	2.37495	0.06140350914266074	1182.977982810276	nan	nan
80.8601	1.5463577285665187	23.2505	2.38721	0.06185430914266075	1182.7185533518946	nan	nan
81.2601	1.5577977285665185	23.2447	2.39897	0.06231190914266074	1182.4235159286375	nan	nan
81.6701	1.5696077285665186	23.2255	2.41107	0.06278430914266074	1181.4468403206138	nan	nan
82.0701	1.5810877285665186	23.2285	2.42313	0.06324350914266075	1181.5994458843675	nan	nan
82.4901	1.5935277285665186	23.2191	2.43555	0.06374110914266075	1181.1212817846058	nan	nan
82.9101	1.6059377285665186	23.2203	2.44839	0.06423750914266074	1181.1823240101073	nan	nan
83.3501	1.6189477285665186	23.2084	2.4614	0.06475790914266075	1180.5769886072176	nan	nan
83.7601	1.6305977285665185	23.203	2.47371	0.06522390914266074	1180.3022985924608	nan	nan
84.1601	1.6421777285665187	23.1911	2.48599	0.06568710914266075	1179.696963189571	nan	nan
84.5901	1.6552377285665185	23.1823	2.49887	0.06620950914266074	1179.2493202025603	nan	nan
84.9901	1.6668277285665187	23.1744	2.51096	0.06667310914266075	1178.8474588846752	nan	nan
85.3901	1.6788577285665187	23.1543	2.52244	0.06715430914266075	1177.8250016075256	nan	nan
85.8301	1.6923577285665186	23.1587	2.53577	0.06769430914266074	1178.048823101031	nan	nan
86.2401	1.7042377285665187	23.1414	2.54778	0.06816950914266075	1177.1687976833846	nan	nan
86.6501	1.7170277285665185	23.1229	2.56044	0.06868110914266073	1176.2277300402368	nan	nan
87.0501	1.7292577285665187	23.1045	2.57257	0.06917030914266074	1175.291749249214	nan	nan
87.4501	1.7414577285665187	23.0958	2.58462	0.06965830914266075	1174.849193114328	nan	nan
87.8901	1.7545077285665187	23.0774	2.59753	0.07018030914266075	1173.9132123233055	nan	nan
88.3101	1.7671077285665187	23.0596	2.61033	0.07068430914266075	1173.0077526450334	nan	nan
88.7301	1.7801477285665186	23.0371	2.62318	0.07120590914266074	1171.8632109168805	nan	nan
89.1601	1.7932277285665186	23.0299	2.63615	0.07172910914266074	1171.4969575638718	nan	nan
89.5601	1.8052877285665185	23.0037	2.64758	0.07221150914266074	1170.164202307089	nan	nan
89.9801	1.8185177285665186	22.9931	2.66017	0.07274070914266074	1169.624995981826	nan	nan
90.4001	1.8315577285665186	22.9555	2.67302	0.07326230914266074	1167.7123395827796	nan	nan
90.8201	1.8446977285665187	22.939	2.68571	0.07378790914266074	1166.8730089821343	nan	nan
91.2301	1.8579277285665186	22.9203	2.69843	0.07431710914266074	1165.921767634736	nan	nan
91.6301	1.8705077285665186	22.8849	2.71082	0.07482030914266075	1164.121021982442	nan	nan
92.0601	1.8833577285665186	22.8595	2.72347	0.07533430914266075	1162.8289615426609	nan	nan
92.4701	1.8960877285665185	22.8356	2.73519	0.07584350914266075	1161.613203884756	nan	nan
92.8701	1.9086277285665185	22.8059	2.7478	0.07634510914266074	1160.1024088035945	nan	nan
93.2701	1.9210377285665186	22.7744	2.75987	0.07684150914266075	1158.5000503841807	nan	nan
93.7001	1.9342977285665186	22.751	2.77258	0.07737190914266075	1157.3097269869015	nan	nan
94.1001	1.9472377285665186	22.7222	2.78453	0.07788950914266074	1155.8447135748659	nan	nan
94.5201	1.9608277285665185	22.6987	2.7978	0.07843310914266075	1154.6493033254617	nan	nan
94.9401	1.9737277285665187	22.6405	2.80973	0.07894910914266075	1151.6887553886397	nan	nan
95.3501	1.9870877285665187	22.6233	2.82223	0.07948350914266075	1150.8138168231185	nan	nan
95.7501	1.9997477285665186	22.5915	2.83472	0.07998990914266074	1149.1961978473291	nan	nan
96.1801	2.0129477285665187	22.5556	2.84744	0.08051790914266074	1147.3700179344096	nan	nan
96.5801	2.025567728566519	22.5316	2.85909	0.08102270914266076	1146.1491734243803	nan	nan
97.0001	2.0385777285665188	22.4979	2.87163	0.08154310914266075	1144.4349042582135	nan	nan
97.4101	2.0517277285665187	22.4622	2.88384	0.08206910914266075	1142.6188980495442	nan	nan
97.8101	2.064637728566519	22.4351	2.8958	0.08258550914266076	1141.2403611236355	nan	nan
98.2401	2.078137728566519	22.3835	2.90894	0.08312550914266076	1138.6155454270718	nan	nan
98.6401	2.090677728566519	22.3558	2.92139	0.08362710914266076	1137.2064873884126	nan	nan
99.0401	2.103127728566519	22.3214	2.93285	0.08412510914266075	1135.4566102573701	nan	nan
99.4801	2.116887728566519	22.2844	2.94643	0.08467550914266075	1133.5744749710743	nan	nan
99.8901	2.130137728566519	22.2602	2.95827	0.08520550914266076	1132.3434567567942	nan	nan
100.29	2.1428977285665187	22.2205	2.97103	0.08571590914266075	1130.32397646312	nan	nan
100.71	2.156167728566519	22.1773	2.98336	0.08624670914266076	1128.1264563450666	nan	nan
101.14	2.1694777285665188	22.1517	2.99561	0.08677910914266075	1126.824222201035	nan	nan
101.54	2.182587728566519	22.1274	3.00828	0.08730350914266076	1125.58811713463	nan	nan
101.96	2.195787728566519	22.0661	3.02092	0.08783150914266075	1122.469876781929	nan	nan
102.37	2.209017728566519	22.0377	3.03332	0.08836070914266075	1121.025210778394	nan	nan
102.78	2.2217377285665187	21.9981	3.04504	0.08886950914266074	1119.010817336845	nan	nan
103.18	2.234987728566519	21.9711	3.05757	0.08939950914266076	1117.6373672630614	nan	nan
103.58	2.2476377285665188	21.9281	3.06989	0.08990550914266075	1115.4500208492584	nan	nan
104.02	2.2615277285665187	21.8939	3.08347	0.09046110914266076	1113.7103174224658	nan	nan
104.43	2.2744677285665187	21.8517	3.09576	0.09097870914266075	1111.5636658256637	nan	nan
104.83	2.2874177285665187	21.8174	3.10825	0.09149670914266075	1109.8188755467463	nan	nan
105.25	2.3004977285665187	21.7711	3.12041	0.09201990914266074	1107.463663012814	nan	nan
105.67	2.314307728566519	21.7407	3.13361	0.09257230914266076	1105.9172599667766	nan	nan
106.08	2.327017728566519	21.6961	3.1451	0.09308070914266076	1103.6485239189713	nan	nan
106.49	2.340447728566519	21.656	3.15791	0.09361790914266076	1101.6086962167967	nan	nan
106.89	2.3531077285665187	21.6321	3.17034	0.09412430914266075	1100.3929385588922	nan	nan
107.3	2.365967728566519	21.5886	3.18187	0.09463870914266076	1098.1801578844631	nan	nan
107.7	2.378367728566519	21.548	3.19341	0.09513470914266076	1096.114895921663	nan	nan
108.12	2.3920877285665187	21.507	3.2068	0.09568350914266074	1094.0292865503623	nan	nan
108.53	2.405317728566519	21.4681	3.21905	0.09621270914266075	1092.050501073689	nan	nan
108.94	2.4182477285665187	21.4331	3.23105	0.09672990914266075	1090.2701028298957	nan	nan
109.35	2.431497728566519	21.382	3.243	0.09725990914266075	1087.6707213939576	nan	nan
109.75	2.4446777285665187	21.3477	3.25496	0.09778710914266074	1085.9259311150402	nan	nan
110.15	2.457387728566519	21.3058	3.26711	0.09829550914266076	1083.7945400746135	nan	nan
110.57	2.4707077285665187	21.2637	3.2802	0.09882830914266075	1081.6529753299362	nan	nan
110.99	2.4839277285665187	21.2289	3.29269	0.09935710914266074	1079.882750790393	nan	nan
111.42	2.4976377285665188	21.1843	3.30537	0.09990550914266075	1077.6140147425879	nan	nan
111.83	2.5109177285665187	21.1356	3.31827	0.10043670914266074	1075.1367177576526	nan	nan
112.23	2.523367728566519	21.0971	3.33009	0.10093470914266076	1073.1782796894802	nan	nan
112.64	2.536357728566519	21.0578	3.34268	0.10145430914266075	1071.1791468043064	nan	nan
113.04	2.549267728566519	21.0133	3.35404	0.10197070914266076	1068.9154976086263	nan	nan
113.45	2.5630477285665187	20.9781	3.3669	0.10252190914266075	1067.124925660583	nan	nan
113.86	2.576407728566519	20.9272	3.37952	0.10305630914266076	1064.5357179288949	nan	nan
114.3	2.590657728566519	20.8843	3.39307	0.10362630914266076	1062.3534583672167	nan	nan
114.71	2.603607728566519	20.85	3.4053	0.10414430914266076	1060.6086680882993	nan	nan
115.11	2.6161077285665186	20.7986	3.41706	0.10464430914266075	1057.9940260959859	nan	nan
115.53	2.6293277285665186	20.7522	3.42991	0.10517310914266075	1055.6337267099282	nan	nan
115.97	2.643547728566519	20.7164	3.44328	0.10574190914266075	1053.812633649134	nan	nan
116.38	2.656437728566519	20.6649	3.45532	0.10625750914266076	1051.1929048046952	nan	nan
116.78	2.670127728566519	20.6185	3.46777	0.10680510914266077	1048.8326054186377	nan	nan
117.2	2.683047728566519	20.5821	3.47949	0.10732190914266075	1046.9809912450928	nan	nan
117.61	2.696617728566519	20.5304	3.49181	0.10786470914266076	1044.3510886964038	nan	nan
118.02	2.709907728566519	20.4785	3.50385	0.10839630914266075	1041.7110124434646	nan	nan
118.42	2.7228177285665187	20.442	3.51694	0.10891270914266075	1039.8543114177944	nan	nan
118.84	2.7364977285665186	20.3949	3.52949	0.10945990914266074	1037.4584040668612	nan	nan
119.25	2.749417728566519	20.3546	3.54158	0.10997670914266075	1035.4084026604364	nan	nan
119.66	2.7625977285665186	20.3071	3.55421	0.11050390914266074	1032.9921479010025	nan	nan
120.06	2.775397728566519	20.251	3.56629	0.11101590914266075	1030.138423858808	nan	nan
120.46	2.7883677285665187	20.2211	3.57874	0.11153470914266075	1028.617455073396	nan	nan
120.89	2.802217728566519	20.1754	3.59098	0.11208870914266075	1026.2927636522147	nan	nan
121.29	2.815367728566519	20.125	3.6032	0.11261470914266075	1023.7289901811522	nan	nan
121.7	2.829007728566519	20.0711	3.61562	0.11316030914266076	1020.9871768857106	nan	nan
122.1	2.8415177285665187	20.0142	3.62688	0.11366070914266074	1018.092758026515	nan	nan
122.51	2.854577728566519	19.9706	3.63922	0.11418310914266076	1015.8748904999612	nan	nan
122.91	2.867367728566519	19.928	3.65136	0.11469470914266075	1013.7078914946584	nan	nan
123.33	2.880707728566519	19.8911	3.66397	0.11522830914266075	1011.8308430604878	nan	nan
123.74	2.8946477285665186	19.8403	3.6767	0.11578590914266075	1009.2467221809248	nan	nan
124.16	2.908467728566519	19.7748	3.68909	0.11633870914266076	1005.9148340389688	nan	nan
124.57	2.921407728566519	19.7244	3.70007	0.11685630914266076	1003.3510605679064	nan	nan
124.97	2.9347177285665187	19.6811	3.71303	0.11738870914266075	1001.148453597728	nan	nan
125.39	2.948247728566519	19.6273	3.72602	0.11792990914266076	998.4117271544114	nan	nan
125.8	2.9618277285665187	19.5705	3.73769	0.11847310914266075	995.5223951473411	nan	nan
126.2	2.974677728566519	19.5292	3.74988	0.11898710914266075	993.421525219665	nan	nan
126.63	2.988097728566519	19.4716	3.76237	0.11952390914266076	990.4914983955936	nan	nan
127.04	3.0013577285665187	19.4201	3.77399	0.12005430914266074	987.8717695511551	nan	nan
127.45	3.014457728566519	19.3828	3.78625	0.12057830914266075	985.9743737084838	nan	nan
127.86	3.028377728566519	19.3142	3.79957	0.12113510914266076	982.484793150649	nan	nan
128.26	3.0418177285665187	19.2679	3.81166	0.12167270914266075	980.1295806167167	nan	nan
128.67	3.0546377285665187	19.22	3.8238	0.12218550914266074	977.6929784487824	nan	nan
129.09	3.068357728566519	19.1592	3.83584	0.12273430914266076	974.6001723567069	nan	nan
129.51	3.082037728566519	19.0977	3.8485	0.12328150914266076	971.4717582997561	nan	nan
129.92	3.095897728566519	19.0461	3.86051	0.12383590914266077	968.8469426031921	nan	nan
130.32	3.1093477285665188	18.9997	3.87316	0.12437390914266075	966.4866432171348	nan	nan
130.74	3.1228377285665188	18.934	3.88527	0.12491350914266075	963.1445813709284	nan	nan
131.18	3.137307728566519	18.8781	3.89835	0.12549230914266077	960.3010310329843	nan	nan
131.59	3.150187728566519	18.8188	3.91019	0.12600750914266076	957.2845277227859	nan	nan
132	3.164077728566519	18.7677	3.92316	0.12656310914266075	954.6851462868477	nan	nan
132.4	3.1771977285665187	18.7091	3.93488	0.12708790914266074	951.7042509415251	nan	nan
132.8	3.190767728566519	18.6442	3.94719	0.12763070914266075	948.4028839123199	nan	nan
133.21	3.2037077285665188	18.5996	3.95893	0.12814830914266076	946.1341478645146	nan	nan
133.61	3.2169077285665186	18.529	3.97069	0.12867630914266073	942.5428302641774	nan	nan
134.05	3.231387728566519	18.4735	3.98344	0.12925550914266076	939.7196273347337	nan	nan
134.47	3.245287728566519	18.4151	3.99655	0.12981150914266076	936.7489056936613	nan	nan
134.88	3.2586677285665187	18.3435	4.00864	0.13034670914266075	933.1067195720728	nan	nan
135.28	3.271997728566519	18.2962	4.02124	0.13087990914266076	930.7006385168892	nan	nan
135.72	3.286837728566519	18.219	4.03448	0.13147350914266076	926.7735886762938	nan	nan
136.13	3.300397728566519	18.16	4.04629	0.13201590914266076	923.7723459224708	nan	nan
136.53	3.313887728566519	18.1052	4.05856	0.13255550914266076	920.984750957903	nan	nan
136.94	3.328057728566519	18.0178	4.07102	0.13312230914266077	916.538842200545	nan	nan
137.34	3.341157728566519	17.9259	4.08278	0.13364630914266076	911.864025097556	nan	nan