File: original_data/46NT87.csv
Specimen name:	AWA_1_09_Rz
Specimen ID:	46NT87
Material:	42CrMoS4
Specimen type:	Round Tensile Specimen
Gauge diameter:	5.003	mm
Gauge length:	25	mm
Parallel length:	30	mm
Original cross-section:	19.6585230984216	mm²
Cross-section after fracture:	8.92233539004867	mm²
Yield stress at 0.2% plastic strain:	1128.8924582741934	MPa
Yield stress at 1% plastic strain:	1144.7186391667112	MPa
Ultimate tensile strength:	1197.4755113668787	MPa
Uniform elongation:	5.14791843027939	%
Elongation after fracture:	14.862866503313601	%
Reduction of area:	54.6133992600642	%
Slope of linear-elastic region:	204959.8813590441	MPa
Crosshead seperation speed:	0.030110414403380907	mm/s
Strain rate:	0.0010036804801126968	s-1
Test temperature:	RT	Cel
Machine type:	INSTRON 8852TT
Standard:	DIN EN ISO 6892-1
Date:	2022-08-18 00:00:00
Heat treatment batch:	Batch 1
Time	Displacement	Force	Machine Displacement	Engineering Strain	Engineering Stress	True Strain	True Stress
s	mm	kN	mm		MPa		MPa
0	0.0010098733739165296	0.166762	0	4.0394934956661184e-05	8.482936340898847	4.039411910314152e-05	8.48327900856058
0.460001	0.0011015181739165295	0.171807	0.000663757	4.4060726956661184e-05	8.73956803061134	4.4059756311410946e-05	8.739953102332056
0.860001	0.0011593713739165297	0.170503	0.000740051	4.6374854956661186e-05	8.673235478899725	4.637377967627892e-05	8.673637698937064
1.27	0.0025613533739165294	0.297832	0.00933838	0.00010245413495666118	15.15027342129853	0.00010244888689014502	15.151825629456265
1.68	0.004436953373916529	0.451092	0.0215759	0.00017747813495666117	22.94638298826317	0.00017746238757559928	22.950455469519927
2.08	0.006600243373916529	0.610554	0.0339623	0.0002640097349566612	31.057979124027987	0.00026397489051929686	31.066178732864813
2.48	0.008801113373916529	0.773363	0.0457191	0.00035204453495666114	39.339832200420695	0.0003519825818191941	39.353681573352965
2.89	0.011095573373916529	0.970301	0.0580482	0.00044382293495666116	49.35777703859687	0.0004437244746893373	49.37968315206508
3.29	0.013070773373916529	1.20428	0.0698967	0.0005228309349566612	61.25994277244015	0.0005226943064837995	61.29197136559526
3.70001	0.01497067337391653	1.47059	0.0813675	0.0005988269349566612	74.80673866685719	0.0005986477096539838	74.85153495688716
4.11001	0.01699877337391653	1.76833	0.0935898	0.0006799509349566613	89.95233218420059	0.0006797198730542498	90.01349535657076
4.51001	0.01885737337391653	2.0715	0.105713	0.0007542949349566612	105.37414177193823	0.0007540105975060321	105.4536249533522
4.93001	0.02099907337391653	2.39228	0.118126	0.0008399629349566612	121.69174601891014	0.0008396103635081302	121.79396257505618
5.34001	0.02299457337391653	2.72746	0.130241	0.0009197829349566612	138.7418569718999	0.0009193601938332284	138.86946936430687
5.74001	0.02503267337391653	3.06608	0.142414	0.0010013069349566613	155.9669556379939	0.0010008059615584644	156.12312643229828
6.17001	0.02728367337391653	3.44429	0.155804	0.0010913469349566613	175.20593906042438	0.0010907518488147679	175.39714952500418
6.57001	0.02937927337391653	3.80078	0.167774	0.0011751709349566613	193.340058201278	0.0011744809620978386	193.56726581823895
6.98001	0.031433473373916526	4.14758	0.179634	0.0012573389349566611	210.9812613712071	0.0012565491463099549	211.24653632567538
7.38001	0.03364247337391653	4.51444	0.191696	0.0013456989349566611	229.64288707743603	0.0013447942936372506	229.9519172659965
7.79001	0.03590817337391653	4.91745	0.204586	0.0014363269349566613	250.14340982689723	0.0014352964040927505	250.5026975440335
8.20001	0.03800117337391653	5.28547	0.217026	0.001520046934956661	268.86404301777765	0.001518892832992396	269.2727289822868
8.60001	0.04018417337391653	5.64913	0.228077	0.0016073669349566614	287.3628894560026	0.0016060765033377737	287.82478706284775
9.00001	0.04248447337391653	6.04194	0.240803	0.0016993789349566612	307.34455328870115	0.0016979366243646537	307.86684814833364
9.41001	0.04488607337391653	6.44611	0.253407	0.001795442934956661	327.9040835228137	0.0017938330539686207	328.4928165929182
9.82001	0.04709057337391653	6.83536	0.265259	0.0018836229349566613	347.7046554198579	0.0018818511418538949	348.3595998833979
10.23	0.04958217337391653	7.23069	0.277843	0.001983286934956661	367.8145079261096	0.001981322817933235	368.543989634167
10.63	0.05190407337391653	7.64259	0.290051	0.0020761629349566615	388.7672518294943	0.0020740106871203227	389.57439598806764
11.03	0.05422867337391653	8.02158	0.301895	0.002169146934956661	408.04591269850073	0.0021667977323077963	408.9310242393523
11.44	0.05677487337391653	8.42936	0.313984	0.0022709949349566613	428.7890782943303	0.002268420123478372	429.76285611930143
11.85	0.059293173373916534	8.84836	0.326885	0.0023717269349566614	450.10298869859866	0.0023689188297922404	451.1705100803996
12.25	0.06163207337391653	9.23704	0.339111	0.002465282934956661	469.87456553852974	0.002462249110116766	471.0329392865221
12.65	0.06421457337391653	9.64922	0.351269	0.0025685829349566614	490.8415526278647	0.0025652897637932037	492.10231986371224
13.06	0.06662867337391654	10.0353	0.362755	0.0026651469349566613	510.4808713125424	0.0026616017284645925	511.84137784207496
13.47	0.06908567337391654	10.4573	0.376293	0.0027634269349566614	531.9473872805646	0.0027596156905266094	533.4173850185555
13.87	0.07163227337391653	10.8538	0.387901	0.0028652909349566615	552.1167559566802	0.0028611938133168437	553.6987310925606
14.28	0.07403297337391652	11.2353	0.399826	0.002961318934956661	571.5230968140273	0.0029569428671989864	573.2155589823877
14.68	0.07648297337391653	11.6464	0.411697	0.0030593189349566612	592.4351459004109	0.003054648741433615	594.2475939599979
15.09	0.07918847337391653	12.0724	0.424709	0.0031675389349566613	614.1051359534381	0.003162532852027028	616.0503378817274
15.49	0.08144487337391654	12.4522	0.437351	0.0032577949349566616	633.425000324658	0.0032524998181904853	635.4885690823905
15.9	0.08394877337391653	12.8527	0.448933	0.003357950934956661	653.7978430857787	0.0033523256072478425	655.9932641642412
16.31	0.08664167337391653	13.2527	0.461628	0.003465666934956661	674.1452515862736	0.003459675350537998	676.4816144940542
16.71	0.08922457337391652	13.6593	0.473793	0.0035689829349566608	694.8283923270267	0.003562629228387455	697.3082230019652
17.12	0.09173387337391653	14.051	0.48542	0.0036693549349566612	714.7535921011364	0.0036626392752165736	717.3762767215907
17.52	0.09432357337391653	14.4542	0.497047	0.003772942934956661	735.2637798696353	0.0037658432379923386	738.037888153224
17.93	0.09679077337391653	14.857	0.509644	0.003871630934956661	755.7536202296337	0.0038641554605480183	758.6796193249203
18.33	0.09924487337391653	15.238	0.521511	0.003969794934956661	775.1345268263551	0.003961936090844197	778.2116519448604
18.76	0.10187887337391653	15.6402	0.534222	0.004075154934956662	795.5938460736029	0.004066873980908425	798.8360142616509
19.16	0.10440587337391653	16.0247	0.546116	0.004176234934956662	815.1527924947035	0.0041675386691990375	818.5570620640473
19.58	0.10694187337391653	16.4394	0.559029	0.004277674934956661	836.2479682575917	0.004268551691791071	839.8251652308156
19.99	0.10958487337391654	16.8451	0.571568	0.004383394934956661	856.8853273292186	0.004373815841809723	860.6413941328723
20.4	0.11204087337391654	17.2317	0.583778	0.0044816349349566615	876.5510976449472	0.004471622313242482	880.4794796664273
20.8	0.11464587337391653	17.6262	0.596207	0.004585834934956661	896.6187292785603	0.004575352030293922	900.7304747706223
21.2	0.11700687337391653	17.9997	0.60788	0.0046802749349566615	915.6181219658974	0.004669356502479729	919.9034665121264
21.61	0.11962987337391653	18.3952	0.620895	0.004785194934956661	935.7366221207618	0.004773782283035391	940.2143042653876
22.02	0.12206287337391653	18.7738	0.632648	0.004882514934956661	954.9954442664804	0.004870634115403679	959.6582237859271
22.42	0.12459487337391653	19.1606	0.644665	0.004983794934956661	974.6713882864588	0.004971416938209703	979.528950614648
22.84	0.12727387337391652	19.5571	0.657589	0.005090954934956661	994.8407569625745	0.00507803983878437	999.9054464237291
23.25	0.12969087337391652	19.9548	0.670368	0.005187634934956661	1015.0711678641916	0.005174225512314082	1020.3369865160711
23.66	0.13214787337391654	20.3222	0.682144	0.005285914934956662	1033.760262571896	0.0052719935233228815	1039.2246313829894
24.06	0.13483187337391653	20.69	0.694241	0.005393274934956661	1052.4697046881013	0.005378783309224892	1058.1459631661967
24.47	0.13745387337391654	21.0913	0.706783	0.0054981549349566615	1072.8832422662229	0.0054830952561925805	1078.7821205593211
24.87	0.14014987337391654	21.4393	0.718864	0.005605994934956662	1090.5854876616534	0.00559033982640583	1096.699304381622
25.28	0.14307787337391653	21.7962	0.731201	0.005723114934956661	1108.74046289622	0.005706800130746385	1115.085911998412
25.68	0.14650987337391652	22.1063	0.742767	0.005860394934956661	1124.5147913362287	0.005843289617302304	1131.1048921236593
26.09	0.15181687337391653	22.3466	0.75547	0.006072674934956661	1136.738496992901	0.006054310554297402	1143.64154037119
26.49	0.16086487337391653	22.3865	0.767097	0.006434594934956661	1138.7681509908255	0.006413981308604788	1146.095662767281
26.9	0.17259087337391654	22.2783	0.779945	0.006903634934956662	1133.2641769914417	0.0068799139586948705	1141.0878191542547
27.3	0.18499487337391654	22.2005	0.791805	0.007399794934956662	1129.3066060380954	0.007372550770683495	1137.6632433414693
27.72	0.19689887337391654	22.1883	0.804527	0.007875954934956662	1128.6860100788303	0.007845101496202328	1137.5754902299273
28.15	0.20940387337391653	22.1825	0.817551	0.008376154934956661	1128.390972655573	0.00834126961705685	1137.8425502697426
28.55	0.22119787337391653	22.1771	0.829597	0.00884791493495666	1128.1162826408163	0.00880900150232161	1138.0977595463619
28.96	0.23274687337391653	22.1781	0.841572	0.009309874934956662	1128.1671511620677	0.009266805159089255	1138.670246245113
29.36	0.24420987337391653	22.1995	0.853531	0.00976839493495666	1129.2557375168442	0.00972099261157643	1140.2867535434746
29.78	0.2562178733739165	22.2351	0.866604	0.01024871493495666	1131.0666568733882	0.010196552948867964	1142.658636612118
30.21	0.2671188733739165	22.2508	0.878502	0.01068475493495666	1131.8652926570328	0.010628076314943433	1143.9589959284563
30.61	0.2780418733739165	22.2858	0.891331	0.01112167493495666	1133.645690900826	0.011060283869877053	1146.2537297664394
31.02	0.2891668733739165	22.3111	0.903072	0.01156667493495666	1134.932664488482	0.011500292343953682	1148.0600616916845
31.42	0.2996528733739165	22.3286	0.915436	0.01198611493495666	1135.822863610379	0.011914850351144732	1149.4369669993648
31.83	0.3106998733739165	22.3483	0.928051	0.01242799493495666	1136.8249734790281	0.012351401356063347	1150.9534284913577
32.24	0.3211388733739165	22.3745	0.940571	0.01284555493495666	1138.1577287358107	0.012763750597422277	1152.777996364932
32.65	0.3321348733739165	22.3977	0.953281	0.01328539493495666	1139.3378784288393	0.013197918001002507	1154.474432108122
33.06	0.3424118733739165	22.4169	0.965096	0.013696474934956659	1140.314554036863	0.013603525975840596	1155.9328437441952
33.47	0.3530068733739165	22.4285	0.977386	0.014120274934956661	1140.9046288833774	0.014021512469144334	1157.0145159177755
33.88	0.3632798733739165	22.4387	0.989162	0.01453119493495666	1141.42348780014	0.014426628884381816	1158.009735004702
34.29	0.3742838733739165	22.4694	1.00187	0.01497135493495666	1142.9851514025531	0.014860390356550877	1160.0971877895859
34.7	0.38486187337391653	22.4842	1.01408	0.01539447493495666	1143.7380055170715	0.01527718224685994	1161.3452515751615
35.11	0.3959318733739165	22.5048	1.02678	0.01583727493495666	1144.7858970548468	0.015713173863318976	1162.9161860481654
35.52	0.4065808733739165	22.5293	1.03939	0.016263234934956662	1146.0321758255022	0.01613240510131127	1164.670366343972
35.9501	0.4177498733739165	22.5425	1.05286	0.01670999493495666	1146.7036403060185	0.01657191901190063	1165.8650523274287
36.3501	0.4285838733739165	22.5633	1.06496	0.01714335493495666	1147.7617055480443	0.016998065770796374	1167.4381918470058
36.7601	0.4388168733739165	22.5756	1.07718	0.01755267493495666	1148.3873883594347	0.01740040597249004	1168.5446588867117
37.1701	0.44999687337391653	22.5989	1.08978	0.01799987493495666	1149.5726249045883	0.017839795274646228	1170.2647883815207
37.5701	0.4607688733739165	22.6171	1.10181	0.018430754934956658	1150.498431991361	0.018262967073488814	1171.7029866444457
37.9801	0.4709238733739165	22.6288	1.11372	0.01883695493495666	1151.0935936900003	0.018661736467825003	1172.7766918402563
38.3801	0.4820848733739165	22.6482	1.12677	0.01928339493495666	1152.0804430022745	0.01909982640414167	1174.296465181527
38.7901	0.4924458733739165	22.6665	1.13828	0.019697834934956658	1153.011336941172	0.019506343148519675	1175.7231639343727
39.1901	0.5028898733739166	22.6795	1.15046	0.02011559493495666	1153.672627717438	0.019915949242610035	1176.8794389841491
39.6001	0.5134198733739166	22.696	1.16261	0.020536794934956665	1154.5119583180835	0.02032875840900431	1178.2219336560172
40.0001	0.5238608733739165	22.7043	1.17511	0.02095443493495666	1154.9341670444687	0.02073791030710271	1179.1351599019604
40.4101	0.5351278733739165	22.7356	1.18824	0.02140511493495666	1156.5263517596327	0.0211792429875739	1181.2819312443537
40.8201	0.5461468733739165	22.7637	1.20081	0.021845874934956662	1157.9557572067922	0.021610673104600027	1183.2523138589447
41.2301	0.5565158733739166	22.7633	1.21231	0.022260634934956666	1157.9354097982916	0.02201648366651475	1183.7117872340707
41.6601	0.5677778733739166	22.7868	1.2253	0.022711114934956665	1159.1308200476958	0.022457056996992672	1185.4559733264496
42.0601	0.5781328733739166	22.8039	1.23723	0.023125314934956665	1160.0006717610918	0.02286197695991046	1186.8260526203283
42.4701	0.5886078733739165	22.8059	1.24932	0.02354431493495666	1160.1024088035945	0.02327142262689894	1187.416225273268
42.8701	0.5991588733739166	22.8411	1.26139	0.023966354934956663	1161.892980751638	0.023683669568697774	1189.7393203247666
43.2801	0.6100818733739165	22.845	1.27366	0.02440327493495666	1162.0913679845178	0.02411027226799093	1190.4502031369839
43.6901	0.6208748733739166	22.8654	1.28675	0.024834994934956663	1163.1290858180432	0.024531619080350012	1192.015390773035
44.0901	0.6310948733739166	22.8886	1.2983	0.025243794934956664	1164.3092355110716	0.024930433025880678	1193.7008190931892
44.4901	0.6414898733739166	22.9016	1.31052	0.025659594934956665	1164.9705262873379	0.025335912881978038	1194.8631981030344
44.9001	0.6523938733739165	22.9165	1.32254	0.02609575493495666	1165.7284672539813	0.02576107079039794	1196.149031656144
45.3101	0.6625838733739166	22.9249	1.33471	0.02650335493495666	1166.1557628324917	0.026158225795871383	1197.0628029242864
45.7201	0.6733858733739165	22.947	1.34672	0.026935434934956662	1167.279957152144	0.026579061331372483	1198.7211504888946
46.1201	0.6839988733739165	22.9593	1.35876	0.02735995493495666	1167.9056399635342	0.026992361198700462	1199.859485641218
46.5201	0.6944078733739165	22.9825	1.37158	0.02777631493495666	1169.085789656563	0.02739755088057281	1201.5586847360462
46.9301	0.7053128733739166	22.9928	1.3837	0.028212514934956662	1169.6097354254507	0.02782187225840088	1202.6073675542118
47.3401	0.7161738733739166	23.0195	1.39566	0.028646954934956663	1170.9679249428589	0.028244302679948256	1204.5125903189767
47.7401	0.7266288733739166	23.021	1.40821	0.029065154934956663	1171.0442277247357	0.02865077354023245	1205.080809639242
48.1401	0.7370678733739165	23.0419	1.41986	0.02948271493495666	1172.1073798188863	0.02905645757783807	1206.6642875712455
48.5501	0.7471868733739165	23.0301	1.432	0.02988747493495666	1171.507131268122	0.029449548637622384	1206.5205212900212
48.9601	0.7584848733739166	23.0777	1.44479	0.030339394934956663	1173.9284728796808	0.02988825761075283	1209.544752443768
49.3601	0.7687528733739165	23.0744	1.45708	0.03075011493495666	1173.7606067595518	0.03028680411100895	1209.8538803235326
49.7701	0.7790018733739166	23.0821	1.46922	0.031160074934956664	1174.1522943731864	0.03068445480153492	1210.7389678509062
50.1701	0.7896058733739165	23.1071	1.48077	0.03158423493495666	1175.4240074044671	0.03109571275914862	1212.548875402518
50.5801	0.8003938733739165	23.1106	1.49322	0.03201575493495666	1175.6020472288467	0.03151393335268228	1213.2398342739589
50.9901	0.8109628733739166	23.1391	1.50499	0.03243851493495666	1177.0518000845068	0.03192349438009714	1215.2336124807657
51.3901	0.8214908733739166	23.1471	1.51725	0.032859634934956666	1177.4587482545166	0.03233129991254549	1216.149612873131
51.8001	0.8324278733739165	23.16	1.5299	0.03329711493495666	1178.1149521786576	0.03275477214577781	1217.3427811479412
52.2001	0.8432008733739166	23.1794	1.54234	0.033728034934956665	1179.1018014909316	0.03317171918318565	1218.870588243488
52.6101	0.8537078733739165	23.1853	1.55353	0.03414831493495666	1179.401925766314	0.03357820384152925	1219.6765141622764
53.0101	0.8641948733739165	23.2086	1.56599	0.03456779493495666	1180.5871623114679	0.03398375006775916	1221.3974572410932
53.4201	0.8752118733739166	23.2057	1.57835	0.035008474934956665	1180.4396435998392	0.03440961502676136	1221.7650352750334
53.8301	0.8857308733739165	23.2192	1.58973	0.035429234934956665	1181.1263686367308	0.0348160604887878	1222.972772239034
54.2301	0.8964528733739165	23.2311	1.60202	0.035858114934956664	1181.7317040396208	0.03523017976215276	1224.1063753053556
54.6301	0.9071138733739166	23.2454	1.61416	0.036284554934956664	1182.4591238935134	0.035641773048870826	1225.3641269327682
55.0501	0.9181008733739165	23.2488	1.62607	0.03672403493495666	1182.6320768657674	0.036065775157431014	1226.0630985717862
55.4601	0.9294438733739165	23.276	1.63907	0.03717775493495666	1184.0157006438012	0.03650332722422115	1228.0347462014774
55.8701	0.9398078733739166	23.2829	1.65132	0.03759231493495666	1184.3666934404348	0.03690294741494718	1228.8897791787208
56.2801	0.9511118733739166	23.2883	1.66383	0.03804447493495666	1184.6413834551913	0.037338630583947846	1229.7104428749647
56.6801	0.9617528733739166	23.2964	1.67622	0.03847011493495666	1185.0534184773262	0.03774858677499768	1230.6425596902122
57.0801	0.9725198733739165	23.3136	1.68775	0.03890079493495666	1185.928357042848	0.03816322626390571	1232.0619128677217
57.5001	0.9836258733739166	23.3244	1.70059	0.03934503493495666	1186.4777370723612	0.038590740661270224	1233.1597450870215
57.9101	0.9942238733739166	23.3263	1.7122	0.03976895493495666	1186.5743872627384	0.03899852975599041	1233.763210596764
58.3301	1.0055298733739166	23.3439	1.72509	0.04022119493495666	1187.4696732367602	0.03943337797597315	1235.2311224433652
58.7401	1.0169398733739166	23.3563	1.73761	0.040677594934956665	1188.1004429002755	0.039872034588721635	1236.4295114586157
59.1501	1.0273598733739167	23.359	1.7492	0.04109439493495667	1188.237787907654	0.04027246269285351	1237.0677008405703
59.5501	1.0381198733739165	23.3706	1.7604	0.041524794934956664	1188.827862754168	0.04068578838217862	1238.1936959679977
59.9501	1.0490798733739166	23.3782	1.77334	0.04196319493495666	1189.2144635156776	0.041106621147811585	1239.1177018676558
60.3601	1.0603398733739167	23.3873	1.78589	0.04241359493495667	1189.6773670590637	0.041538788699474104	1240.1358610087925
60.7701	1.0713798733739166	23.3965	1.79816	0.04285519493495667	1190.1453574545753	0.04196233122669821	1241.1492687492248
61.1801	1.0827498733739165	23.3948	1.81074	0.04330999493495666	1190.0588809684482	0.042398346561834235	1241.6003250754918
61.5801	1.0936498733739166	23.4157	1.82275	0.043745994934956664	1191.122033062599	0.042816159987500595	1243.2288514878705
61.9801	1.1046198733739165	23.4287	1.83532	0.04418479493495666	1191.783323838865	0.04323648043929845	1244.4420256095864
62.3901	1.1154498733739167	23.4166	1.84655	0.04461799493495667	1191.167814731725	0.043651263499060476	1244.3153342561086
62.7901	1.1261298733739165	23.4325	1.8589	0.04504519493495666	1191.97662421962	0.04406013322315975	1245.6694436155042
63.2101	1.1376098733739166	23.4378	1.87117	0.045504394934956664	1192.2462273822514	0.04449944354577582	1246.4986705727656
63.6401	1.1488798733739165	23.4431	1.88366	0.04595519493495666	1192.515830544883	0.04493053005508689	1247.318128000595
64.0401	1.1597998733739165	23.4537	1.8956	0.04639199493495666	1193.055036870146	0.045348051591149637	1248.4032400977505
64.4501	1.1708898733739166	23.4598	1.90857	0.04683559493495666	1193.3653348497787	0.04577189466372088	1249.2573102822219
64.8501	1.1819598733739165	23.4699	1.92048	0.04727839493495666	1193.879106914416	0.0461947942849845	1250.3237948357091
65.2601	1.1933198733739165	23.4664	1.93242	0.04773279493495666	1193.7010670900368	0.04662858672420653	1250.6797553390843
65.6701	1.2043598733739165	23.4782	1.94498	0.048174394934956656	1194.3013156408015	0.047049979435361926	1251.83605889182
66.0701	1.2153098733739165	23.4758	1.95699	0.04861239493495666	1194.1792311897984	0.04746776154700704	1252.2311435995198
66.4801	1.2268198733739166	23.4823	1.96917	0.049072794934956664	1194.5098765779314	0.04790672160604374	1253.1278147990208
66.8801	1.2380798733739165	23.4864	1.98159	0.04952319493495666	1194.7184375150616	0.0483359609728293	1253.884711588507
67.2901	1.2486898733739165	23.4832	1.99299	0.04994759493495666	1194.5556582470576	0.04874025333815156	1254.2208403924421
67.7001	1.2602898733739165	23.4892	2.00588	0.05041159493495666	1194.860869374565	0.04918208253554422	1255.0957115251058
68.1101	1.2716198733739166	23.4991	2.01858	0.050864794934956666	1195.364467734952	0.049613439409120864	1256.1664362588242
68.5301	1.2829498733739166	23.5005	2.03074	0.051317994934956666	1195.435683664704	0.050044610294169456	1256.7830460240757
68.9401	1.2946698733739166	23.5017	2.04364	0.051786794934956665	1195.4967258902054	0.050490427364267565	1257.4076696792936
69.3501	1.3061998733739166	23.5078	2.05571	0.05224799493495667	1195.8070238698378	0.05092882316419157	1258.2855431961746
69.7501	1.3172698733739165	23.5132	2.06784	0.05269079493495666	1196.0817138845946	0.051349547993495594	1259.1042101963392
70.1701	1.3292198733739164	23.5211	2.07999	0.05316879493495666	1196.4835752024796	0.05180351938884276	1260.099165055464
70.5801	1.3407998733739166	23.5158	2.09286	0.05363199493495666	1196.213972039848	0.05224323823619711	1260.3693137294133
70.9901	1.3519898733739166	23.5197	2.10463	0.05407959493495666	1196.4123592727278	0.05266796428399215	1261.1138550373728
71.4001	1.3636198733739167	23.5229	2.11743	0.05454479493495667	1196.5751385407318	0.0531091998210393	1261.8420840967035
71.8101	1.3750198733739165	23.5244	2.12968	0.05500079493495666	1196.6514413226087	0.05354152042059588	1262.4682218554137
72.2201	1.3870298733739166	23.522	2.14262	0.055481194934956665	1196.5293568716056	0.053996771885050907	1262.9142353655975
72.6301	1.3983298733739165	23.5326	2.15476	0.05593319493495666	1197.0685631968686	0.054424920910721306	1264.0244324926675
73.0301	1.4094998733739166	23.5294	2.1665	0.05637999493495666	1196.9057839288646	0.05484796424426312	1264.3873259643942
73.4301	1.4210698733739167	23.5359	2.17916	0.05684279493495667	1197.2364293169978	0.05528596823477223	1265.2906941573235
73.8401	1.4329698733739165	23.5273	2.19143	0.05731879493495666	1196.798960034237	0.05573626494844256	1265.398034202809
74.2401	1.4447098733739165	23.5354	2.20326	0.05778839493495666	1197.210995056372	nan	nan
74.6501	1.4561798733739166	23.5228	2.21583	0.05824719493495666	1196.5700516886066	nan	nan
75.0601	1.4680298733739165	23.5161	2.22788	0.058721194934956665	1196.2292325962233	nan	nan
75.4601	1.4793598733739166	23.5274	2.24024	0.059174394934956666	1196.8040468863624	nan	nan
75.8701	1.4918298733739166	23.5348	2.25299	0.059673194934956666	1197.1804739436213	nan	nan
76.3001	1.5039598733739166	23.5312	2.26547	0.060158394934956665	1196.9973472671168	nan	nan
76.7101	1.5152498733739166	23.5269	2.27786	0.06060999493495666	1196.7786126257367	nan	nan
77.1201	1.5275398733739165	23.5116	2.28988	0.06110159493495666	1196.0003242505927	nan	nan
77.5201	1.5391998733739165	23.5214	2.30214	0.06156799493495666	1196.498835758855	nan	nan
77.9301	1.5506498733739165	23.5041	2.31364	0.06202599493495666	1195.6188103412085	nan	nan
78.3301	1.5627398733739166	23.5213	2.32591	0.06250959493495667	1196.4937489067297	nan	nan
78.7401	1.5752798733739166	23.5147	2.33849	0.06301119493495666	1196.1580166664717	nan	nan
79.1501	1.5866798733739165	23.5062	2.34976	0.06346719493495666	1195.725634235836	nan	nan
79.5501	1.5993298733739165	23.5024	2.36319	0.06397319493495666	1195.5323338550813	nan	nan
79.9601	1.6108898733739165	23.5116	2.37466	0.06443559493495667	1196.0003242505927	nan	nan
80.3601	1.6227498733739165	23.4951	2.38686	0.06490999493495667	1195.1609936499474	nan	nan
80.7701	1.6352098733739167	23.4887	2.39891	0.06540839493495666	1194.8354351139394	nan	nan
81.1801	1.6469798733739165	23.4815	2.41104	0.06587919493495666	1194.4691817609305	nan	nan
81.5801	1.6589198733739166	23.4881	2.42357	0.06635679493495666	1194.8049140011885	nan	nan
81.9801	1.6711598733739166	23.4841	2.43564	0.06684639493495666	1194.6014399161838	nan	nan
82.3901	1.6839298733739165	23.4789	2.44829	0.06735719493495666	1194.3369236056772	nan	nan
82.8001	1.6956298733739166	23.4699	2.45996	0.06782519493495666	1193.879106914416	nan	nan
83.2001	1.7079698733739166	23.4573	2.47189	0.06831879493495667	1193.2381635466504	nan	nan
83.6001	1.7197298733739166	23.4473	2.48367	0.06878919493495667	1192.729478334138	nan	nan
84.0101	1.7329498733739166	23.4562	2.49673	0.06931799493495666	1193.1822081732741	nan	nan
84.4201	1.7447098733739166	23.4295	2.5087	0.06978839493495666	1191.824018655866	nan	nan
84.8201	1.7569798733739166	23.4233	2.52075	0.07027919493495666	1191.5086338241085	nan	nan
85.2301	1.7698698733739167	23.4178	2.53313	0.07079479493495666	1191.2288569572265	nan	nan
85.6301	1.7818898733739166	23.4076	2.54461	0.07127559493495667	1190.709998040464	nan	nan
86.0401	1.7941698733739166	23.3767	2.55649	0.07176679493495666	1189.1381607338008	nan	nan
86.4501	1.8074298733739165	23.3844	2.56995	0.07229719493495666	1189.5298483474353	nan	nan
86.8501	1.8195298733739165	23.3731	2.58141	0.07278119493495666	1188.9550340572964	nan	nan
87.2601	1.8317398733739165	23.3519	2.59336	0.07326959493495666	1187.8766214067703	nan	nan
87.6601	1.8441098733739165	23.3363	2.6051	0.07376439493495666	1187.083072475251	nan	nan
88.0801	1.8572298733739165	23.3209	2.61767	0.07428919493495666	1186.2996972479818	nan	nan
88.5001	1.8703098733739165	23.2974	2.62999	0.07481239493495666	1185.1042869985777	nan	nan
88.9301	1.8839198733739166	23.295	2.64355	0.07535679493495667	1184.9822025475746	nan	nan
89.3301	1.8965298733739167	23.259	2.65561	0.07586119493495666	1183.15093578253	nan	nan
89.7401	1.9093098733739167	23.2487	2.66762	0.07637239493495666	1182.6269900136424	nan	nan
90.1401	1.9218898733739165	23.2223	2.67916	0.07687559493495666	1181.2840610526098	nan	nan
90.5601	1.9351198733739166	23.2028	2.69197	0.07740479493495667	1180.2921248882105	nan	nan
90.9701	1.9483798733739166	23.1809	2.70446	0.07793519493495667	1179.1781042728085	nan	nan
91.3801	1.9613398733739165	23.1462	2.71656	0.07845359493495666	1177.4129665853907	nan	nan
91.7801	1.9735998733739166	23.1161	2.7283	0.07894399493495667	1175.8818240957282	nan	nan
92.1801	1.9863298733739165	23.1083	2.74045	0.07945319493495666	1175.4850496299687	nan	nan
92.5901	1.9998698733739166	23.0517	2.753	0.07999479493495666	1172.6058913271486	nan	nan
93.0001	2.0126398733739164	23.0479	2.76537	0.08050559493495665	1172.4125909463937	nan	nan
93.4001	2.0251498733739166	23.014	2.77734	0.08100599493495667	1170.6881480759769	nan	nan
93.8201	2.0387098733739166	22.9905	2.79036	0.08154839493495666	1169.492737826573	nan	nan
94.2301	2.0519698733739165	22.9484	2.80175	0.08207879493495666	1167.3511730818957	nan	nan
94.6401	2.0649298733739165	22.9293	2.81386	0.08259719493495667	1166.3795843259973	nan	nan
95.0501	2.0785298733739164	22.8943	2.8269	0.08314119493495666	1164.599186082204	nan	nan
95.4601	2.0914298733739165	22.8592	2.83899	0.08365719493495666	1162.8137009862855	nan	nan
95.8801	2.1048498733739165	22.8153	2.85172	0.08419399493495666	1160.5805729033561	nan	nan
96.2901	2.1182398733739167	22.7799	2.86457	0.08472959493495667	1158.7798272510624	nan	nan
96.7001	2.1313098733739166	22.7483	2.87689	0.08525239493495666	1157.1723819795232	nan	nan
97.1001	2.1440398733739165	22.7216	2.8883	0.08576159493495666	1155.814192462115	nan	nan
97.5001	2.1564298733739165	22.6682	2.9001	0.08625719493495666	1153.097813427299	nan	nan
97.9101	2.1705298733739165	22.6593	2.91387	0.08682119493495666	1152.6450835881633	nan	nan
98.3101	2.1834798733739165	22.6135	2.92499	0.08733919493495666	1150.3153053148565	nan	nan
98.7201	2.1962098733739164	22.5736	2.93697	0.08784839493495665	1148.285651316932	nan	nan
99.1301	2.2099098733739164	22.5369	2.94949	0.08839639493495666	1146.4187765870115	nan	nan
99.5301	2.2230198733739166	22.5048	2.96211	0.08892079493495667	1144.7858970548468	nan	nan
99.9401	2.2359298733739164	22.4728	2.97375	0.08943719493495665	1143.1581043748072	nan	nan
100.34	2.2488998733739165	22.4393	2.98616	0.08995599493495667	1141.454008912891	nan	nan
100.76	2.2624098733739166	22.3808	2.99843	0.09049639493495666	1138.4782004196934	nan	nan
101.17	2.2761798733739167	22.3606	3.01085	0.09104719493495667	1137.4506562904185	nan	nan
101.58	2.2888398733739166	22.312	3.02279	0.09155359493495667	1134.9784461576082	nan	nan
101.98	2.3017998733739167	22.2959	3.03486	0.09207199493495667	1134.1594629654633	nan	nan
102.39	2.3159198733739164	22.2459	3.04753	0.09263679493495665	1131.6160369029014	nan	nan
102.79	2.3291198733739167	22.2001	3.05955	0.09316479493495666	1129.2862586295948	nan	nan
103.2	2.3414898733739165	22.1576	3.07095	0.09365959493495665	1127.1243464764173	nan	nan
103.6	2.3548398733739164	22.1376	3.08405	0.09419359493495666	1126.1069760513924	nan	nan
104.02	2.3685798733739167	22.0861	3.09684	0.09474319493495667	1123.4872472069537	nan	nan
104.43	2.3822598733739166	22.0585	3.10937	0.09529039493495667	1122.0832760204196	nan	nan
104.84	2.3950698733739166	22.0022	3.12108	0.09580279493495666	1119.2193782739748	nan	nan
105.24	2.4084398733739167	21.9807	3.13332	0.09633759493495667	1118.1257050670733	nan	nan
105.66	2.4217898733739167	21.9204	3.14619	0.09687159493495667	1115.0583332356239	nan	nan
106.07	2.4353198733739165	21.9036	3.15899	0.09741279493495666	1114.203742078603	nan	nan
106.48	2.4487198733739164	21.8588	3.17128	0.09794879493495666	1111.9248323265474	nan	nan
106.89	2.4623198733739167	21.8081	3.18344	0.09849279493495666	1109.3457982991097	nan	nan
107.3	2.4753398733739167	21.7735	3.19569	0.09901359493495666	1107.585747463817	nan	nan
107.72	2.4891798733739168	21.7125	3.20832	0.09956719493495667	1104.4827676674915	nan	nan
108.13	2.5025698733739166	21.6894	3.22099	0.10010279493495666	1103.3077048265877	nan	nan
108.53	2.5158198733739168	21.6465	3.23283	0.10063279493495667	1101.1254452649098	nan	nan
108.95	2.5294398733739167	21.5943	3.24578	0.10117759493495666	1098.4701084555952	nan	nan
109.36	2.5428798733739164	21.5699	3.25843	0.10171519493495666	1097.228916537065	nan	nan
109.77	2.5563498733739167	21.505	3.2707	0.10225399493495667	1093.9275495078598	nan	nan
110.17	2.5694698733739165	21.4718	3.28262	0.10277879493495666	1092.2387146023189	nan	nan
110.58	2.5830298733739165	21.447	3.29517	0.10332119493495666	1090.977175275288	nan	nan
110.98	2.5960998733739165	21.3934	3.3069	0.10384399493495666	1088.2506225362217	nan	nan
111.39	2.6098298733739167	21.3578	3.3197	0.10439319493495666	1086.4397031796775	nan	nan
111.8	2.6227798733739167	21.3018	3.33123	0.10491119493495667	1083.5910659896083	nan	nan
112.2	2.6356898733739165	21.2567	3.34275	0.10542759493495665	1081.2968956811774	nan	nan
112.61	2.6494098733739166	21.2281	3.35553	0.10597639493495667	1079.8420559733922	nan	nan
113.01	2.6627798733739168	21.1867	3.36734	0.10651119493495667	1077.7360991935907	nan	nan
113.42	2.6759398733739164	21.1435	3.37977	0.10703759493495665	1075.5385790755374	nan	nan
113.82	2.6893398733739167	21.0978	3.39186	0.10757359493495666	1073.2138876543559	nan	nan
114.23	2.7033698733739167	21.0508	3.40505	0.10813479493495666	1070.8230671555477	nan	nan
114.64	2.7160498733739167	21.0098	3.41676	0.10864199493495667	1068.737457784247	nan	nan
115.05	2.7297998733739166	20.9543	3.42855	0.10919199493495667	1065.9142548548034	nan	nan
115.48	2.7436898733739166	20.9231	3.44113	0.10974759493495666	1064.327156991765	nan	nan
115.88	2.7570898733739164	20.8696	3.45358	0.11028359493495665	1061.6056911048236	nan	nan
116.29	2.7708498733739164	20.8337	3.46686	0.11083399493495666	1059.7795111919042	nan	nan
116.69	2.7836298733739167	20.7782	3.47803	0.11134519493495666	1056.9563082624602	nan	nan
117.1	2.7975798733739166	20.7421	3.49068	0.11190319493495667	1055.1199546452908	nan	nan
117.5	2.8105398733739166	20.6877	3.50223	0.11242159493495667	1052.3527070892235	nan	nan
117.91	2.8242098733739165	20.6477	3.51503	0.11296839493495665	1050.317966239174	nan	nan
118.32	2.8378098733739168	20.603	3.52731	0.11351239493495667	1048.0441433392436	nan	nan
118.72	2.8507398733739167	20.5499	3.53899	0.11402959493495667	1045.343024860803	nan	nan
119.13	2.8647698733739166	20.5104	3.55195	0.11459079493495666	1043.3337182713792	nan	nan
119.53	2.8780198733739164	20.462	3.56373	0.11512079493495665	1040.8716818428193	nan	nan
119.95	2.8920198733739166	20.406	3.57644	0.11568079493495667	1038.0230446527498	nan	nan
120.37	2.9059298733739167	20.36	3.58882	0.11623719493495667	1035.683092675193	nan	nan
120.79	2.9197898733739165	20.3101	3.6021	0.11679159493495667	1033.1447534647561	nan	nan
121.2	2.9338698733739164	20.277	3.61449	0.11735479493495665	1031.4610054113402	nan	nan
121.61	2.9472198733739168	20.2114	3.62579	0.11788879493495667	1028.124030417259	nan	nan
122.02	2.9607198733739164	20.1605	3.63792	0.11842879493495666	1025.534822685571	nan	nan
122.42	2.9740798733739164	20.1323	3.65093	0.11896319493495666	1024.1003303862863	nan	nan
122.83	2.9878698733739166	20.0758	3.66318	0.11951479493495666	1021.2262589355913	nan	nan
123.23	3.0013798733739168	20.0147	3.67551	0.12005519493495667	1018.1181922871407	nan	nan
123.63	3.0143598733739165	19.9689	3.68693	0.12057439493495666	1015.7884140138341	nan	nan
124.05	3.0282298733739164	19.9081	3.69921	0.12112919493495665	1012.6956079217589	nan	nan
124.46	3.0423498733739165	19.8721	3.71206	0.12169399493495665	1010.8643411567142	nan	nan
124.87	3.0557098733739165	19.8163	3.72394	0.12222839493495666	1008.0258776708952	nan	nan
125.27	3.0692098733739166	19.7743	3.73621	0.12276839493495667	1005.8893997783432	nan	nan
125.68	3.0829498733739165	19.7165	3.74866	0.12331799493495665	1002.9491992500217	nan	nan
126.08	3.0966998733739164	19.6737	3.76059	0.12386799493495665	1000.7720265404688	nan	nan
126.51	3.1108898733739165	19.6177	3.77366	0.12443559493495666	997.9233893503995	nan	nan
126.91	3.1241998733739167	19.5508	3.78516	0.12496799493495667	994.5202852786916	nan	nan
127.32	3.1380398733739168	19.5053	3.79759	0.12552159493495668	992.2057675617604	nan	nan
127.72	3.1511298733739164	19.4484	3.80898	0.12604519493495667	989.3113487025648	nan	nan
128.13	3.1647898733739166	19.3929	3.82166	0.12659159493495667	986.4881457731213	nan	nan
128.54	3.1790998733739166	19.357	3.83526	0.12716399493495667	984.6619658602019	nan	nan
128.94	3.1924698733739167	19.2816	3.84688	0.12769879493495667	980.8264793578587	nan	nan
129.34	3.2056998733739164	19.2443	3.85925	0.12822799493495665	978.9290835151874	nan	nan
129.75	3.2194198733739166	19.1768	3.87126	0.12877679493495667	975.4954583307289	nan	nan
130.16	3.2335898733739166	19.1239	3.88406	0.12934359493495667	972.8045135565384	nan	nan
130.56	3.2465498733739167	19.0625	3.89623	0.12986199493495668	969.6811863517124	nan	nan
130.98	3.2611298733739167	19.0126	3.90895	0.13044519493495665	967.1428471412756	nan	nan
131.39	3.2744098733739166	18.9335	3.92078	0.13097639493495666	963.1191471103028	nan	nan
131.8	3.2884898733739165	18.9118	3.93423	0.13153959493495665	962.0153001991509	nan	nan
132.2	3.302019873373917	18.8276	3.94536	0.13208079493495667	957.7321707097967	nan	nan
132.6	3.3154998733739167	18.7918	3.95798	0.13261999493495666	955.9110776490024	nan	nan
133.01	3.3292498733739166	18.7213	3.97059	0.13316999493495665	952.3248469007902	nan	nan
133.42	3.3434798733739166	18.6658	3.98332	0.13373919493495667	949.5016439713465	nan	nan
133.82	3.3567898733739168	18.6036	3.9951	0.13427159493495666	946.3376219495195	nan	nan
134.24	3.3713798733739164	18.5476	4.00824	0.13485519493495665	943.4889847594503	nan	nan
134.65	3.3846998733739166	18.4749	4.01978	0.13538799493495668	939.7908432644855	nan	nan
135.06	3.3989898733739166	18.403	4.03272	0.13595959493495666	936.1333965865214	nan	nan
135.46	3.4127098733739167	18.3615	4.04428	0.13650839493495667	934.022352954595	nan	nan
135.86	3.4259398733739164	18.2909	4.05658	0.13703759493495665	930.4310353542578	nan	nan
136.29	3.4405798733739164	18.2263	4.06918	0.13762319493495664	927.1449288814277	nan	nan
136.69	3.4540698733739164	18.188	4.08201	0.13816279493495665	925.1966645175054	nan	nan
137.1	3.4685798733739164	18.1159	4.09424	0.13874319493495665	921.5290441352912	nan	nan
137.52	3.4830598733739166	18.0423	4.10756	0.13932239493495666	917.7851209712001	nan	nan
137.93	3.4965798733739164	17.9925	4.1198	0.13986319493495666	915.2518686128885	nan	nan
138.33	3.5101398733739164	17.9089	4.13137	0.14040559493495666	910.999260236285	nan	nan
138.74	3.5244198733739167	17.8498	4.14381	0.14097679493495666	907.9929306303369	nan	nan
139.14	3.5383598733739166	17.7801	4.15658	0.14153439493495668	904.4473946991258	nan	nan
139.55	3.5524998733739164	17.7178	4.16805	0.14209999493495665	901.2782858251735	nan	nan
139.96	3.5664298733739166	17.6435	4.17982	0.14265719493495665	897.4987546962067	nan	nan
140.36	3.5804398733739164	17.5958	4.19164	0.14321759493495667	895.0723262325225	nan	nan
140.76	3.5942598733739164	17.5053	4.20466	0.14377039493495666	890.4687250592856	nan	nan
141.17	3.6076098733739164	17.4559	4.21615	0.14430439493495664	887.9558201094745	nan	nan
141.58	3.6221498733739166	17.3763	4.22828	0.14488599493495666	883.906685817876	nan	nan
141.99	3.6359198733739166	17.3034	4.24001	0.14543679493495668	880.1983706186609	nan	nan
142.42	3.6513598733739165	17.23	4.25327	0.14605439493495667	876.46462115882	nan	nan
142.82	3.6645098733739165	17.163	4.26451	0.14658039493495667	873.056430234987	nan	nan
143.23	3.6788198733739166	17.1019	4.27731	0.14715279493495667	869.9483635865365	nan	nan
143.64	3.6930698733739167	17.0144	4.28976	0.14772279493495666	865.497367977053	nan	nan
144.04	3.7075398733739164	16.9461	4.30213	0.14830159493495665	862.0230479755938	nan	nan
144.44	3.7217298733739166	16.8519	4.31392	0.14886919493495665	857.2312332737272	nan	nan
144.85	3.7356998733739166	16.7854	4.32611	0.14942799493495668	853.8484766105197	nan	nan
145.27	3.7498898733739168	16.7299	4.3387	0.14999559493495668	851.0252736810762	nan	nan
145.69	3.7649298733739167	16.6363	4.35209	0.15059719493495666	846.2639800919603	nan	nan
146.1	3.7794198733739166	16.542	4.36397	0.15117679493495667	841.4670785379686	nan	nan
146.5	3.7929798733739166	16.4738	4.3758	0.15171919493495667	837.9978453886342	nan	nan
146.91	3.8073898733739164	16.3928	4.38808	0.15229559493495665	833.8774951672842	nan	nan
147.32	3.8226198733739167	16.274	4.40042	0.15290479493495668	827.834314842637	nan	nan