File: original_data/46NT93.csv
Specimen name:	AWA_1_12_Rz
Specimen ID:	46NT93
Material:	42CrMoS4
Specimen type:	Round Tensile Specimen
Gauge diameter:	4.998	mm
Gauge length:	25	mm
Parallel length:	30	mm
Original cross-section:	19.61924926326091	mm²
Cross-section after fracture:	8.70658651456339	mm²
Yield stress at 0.2% plastic strain:	1131.9962024948527	MPa
Yield stress at 1% plastic strain:	1148.4492823862206	MPa
Ultimate tensile strength:	1201.7738132392292	MPa
Uniform elongation:	5.252826048735211	%
Elongation after fracture:	14.154201887064243	%
Reduction of area:	55.622223879547825	%
Slope of linear-elastic region:	196476.55676196955	MPa
Crosshead seperation speed:	0.029978850960202617	mm/s
Strain rate:	0.0009992950320067539	s-1
Test temperature:	RT	Cel
Machine type:	INSTRON 8852TT
Standard:	DIN EN ISO 6892-1
Date:	2022-08-18 00:00:00
Heat treatment batch:	Batch 1
Time	Displacement	Force	Machine Displacement	Engineering Strain	Engineering Stress	True Strain	True Stress
s	mm	kN	mm		MPa		MPa
0	0.00041960551739923915	0.0691517	0	1.6784220695969567e-05	3.5246863461536093	1.6784079842497313e-05	3.524745505267127
0.450001	0.00046743871739923917	0.0720306	0.00031662	1.8697548695969568e-05	3.67142488652126	1.8697373899004725e-05	3.6714935331668594
0.870001	0.00042738857739923916	0.0720318	0.000148774	1.7095543095969565e-05	3.671486050941157	1.7095396968903653e-05	3.671548816989167
1.29	0.00047064921739923914	0.0857954	0.00213623	1.8825968695969566e-05	4.373021559018612	1.8825791489632254e-05	4.373103885385589
1.69	0.0005917725173992392	0.18851	0.0144272	2.367090069596957e-05	9.608420662303558	2.3670620544644494e-05	9.608648102274902
2.11	0.0009433045173992392	0.33169	0.0270653	3.7732180695969564e-05	16.90635536300179	3.773146885509133e-05	16.906993276657257
2.52	0.001533065517399239	0.500931	0.0394096	6.132262069596956e-05	25.532628352810907	6.132074054098402e-05	25.534194080494757
2.94	0.002267675517399239	0.708311	0.0524635	9.070702069596957e-05	36.10285951799319	9.070290706286593e-05	36.10613430081867
3.34	0.0030934855173992393	0.916381	0.063549	0.00012373942069596959	46.70826022461618	0.00012373176560524603	46.71403987767809
3.75001	0.0038583655173992392	1.13033	0.0754089	0.00015433462069596956	57.61331561838408	0.00015432271233368827	57.62220734759708
4.15001	0.005180855517399239	1.39762	0.0881615	0.00020723422069596954	71.237180446919	0.00020721275065107133	71.2519432284935
4.56001	0.006739725517399239	1.6616	0.100403	0.00026958902069596955	84.69233341723829	0.0002695526881057955	84.71516554046471
4.97001	0.00836731551739924	1.94739	0.112869	0.0003346926206959696	99.25914971918372	0.0003346366236149817	99.29237102413128
5.37001	0.01015315551739924	2.24426	0.124424	0.0004061262206959696	114.39071749817721	0.0004060437737642738	114.43717456795746
5.77001	0.01196300551739924	2.54187	0.136196	0.0004785202206959696	129.56000333610706	0.000478405766406253	129.62200041749682
6.18001	0.01402870551739924	2.88422	0.148556	0.0005611482206959697	147.00970262919296	0.0005609908359078878	147.0921968622484
6.59001	0.01622270551739924	3.20502	0.160576	0.0006489082206959695	163.3609908816304	0.0006486977707933814	163.46699717155454
7.00001	0.01840040551739924	3.55096	0.172871	0.0007360162206959696	180.99367373090786	0.000735745493588954	181.12688801061717
7.40001	0.02055500551739924	3.90147	0.184772	0.0008222002206959696	198.8592910792927	0.0008218623992530064	199.0227932323055
7.82001	0.02281460551739924	4.25274	0.19651	0.0009125842206959696	216.76364589361216	0.0009121680688792777	216.96146097647522
8.23001	0.025071205517399237	4.61531	0.208767	0.0010028482206959695	235.24396566196083	0.0010023457043562129	235.47987965435442
8.64001	0.02748430551739924	4.99192	0.221241	0.0010993722206959695	254.43990914310316	0.0010987683535988032	254.7196333110515
9.05001	0.029792705517399237	5.37938	0.234039	0.0011917082206959694	274.1888809208133	0.001190998700092806	274.5156340642301
9.45001	0.03225240551739924	5.74426	0.246067	0.0012900962206959697	292.7869421974634	0.0012892647615978749	293.1646655250615
9.86001	0.03485850551739924	6.13907	0.258835	0.0013943402206959695	312.9105460470421	0.0013933690310448047	313.3468498068754
10.27	0.037083705517399236	6.50531	0.270844	0.0014833482206959695	331.57792699957537	0.0014822491464629964	332.06977252761226
10.67	0.03976840551739924	6.90206	0.282825	0.0015907362206959697	351.8004133279873	0.001589472339990378	352.36003498792394
11.09	0.04200250551739924	7.28247	0.295082	0.0016801002206959694	371.1900441388032	0.0016786904311576697	371.81368061388093
11.48	0.04459440551739924	7.67496	0.306702	0.0017837762206959695	391.1953967765811	0.001782187181273135	391.8932018229969
11.91	0.04709990551739924	8.06888	0.319164	0.0018839962206959695	411.27363701473627	0.0018822237257162765	412.04847499254396
12.32	0.04966960551739924	8.47652	0.332352	0.0019867842206959694	432.0511904537126	0.001984813175189135	432.90958294143894
12.73	0.052258905517399236	8.86858	0.344372	0.0020903562206959696	452.0346258410275	0.0020881744660318563	452.9795392331243
13.15	0.05480770551739924	9.29037	0.357082	0.0021923082206959698	473.533409731288	0.0021899086194990956	474.5715409182161
13.56	0.05759470551739924	9.70314	0.369942	0.0023037882206959695	494.5724410653235	0.002301138569323184	495.7118312293307
13.97	0.06024640551739924	10.1051	0.382019	0.0024098562206959695	515.0604829167879	0.0024069571737838184	516.3017046255796
14.38	0.06272680551739925	10.5012	0.394592	0.00250907222069597	535.2498385177557	0.002505929754344048	536.5928190187126
14.79	0.06533760551739924	10.8922	0.40641	0.0026135042206959697	555.1792453341617	0.0026100949573311565	556.6302086350854
15.2	0.06802830551739923	11.307	0.41901	0.002721132220695969	576.3217464785228	0.0027174366430003337	577.8899941523532
15.61	0.07059800551739924	11.6972	0.430832	0.0028239202206959695	596.2103770149976	0.0028199404486015478	597.8940275544389
16.02	0.07326450551739924	12.1031	0.443031	0.0029305802206959696	616.8992420451233	0.0029262944416522554	618.7071147620231
16.43	0.07585880551739924	12.5085	0.455479	0.0030343522206959695	637.562621900292	0.0030297578655777814	639.4972114578878
16.84	0.07870130551739923	12.9273	0.467983	0.0031480522206959695	658.9090044443095	0.0031431074791224076	660.9832843989869
17.27	0.08150330551739923	13.3455	0.481216	0.003260132220695969	680.2248047783785	0.0032548295115440947	682.4424275817531
17.67	0.08384990551739924	13.7155	0.492504	0.0033539962206959695	699.0838342465888	0.0033483841205124445	701.4285587846015
18.07	0.08655400551739924	14.1231	0.505333	0.0034621602206959695	719.8593488715685	0.0034561807413016296	722.3516172737277
18.49	0.08935830551739923	14.5329	0.517696	0.0035743322206959693	740.7469982663592	0.003567959476306571	743.3946741296465
18.9	0.09193680551739924	14.9297	0.529499	0.00367747222069597	760.9720331122669	0.0036707268519418144	763.7704866247639
19.31	0.09446760551739924	15.31	0.541439	0.0037787042206959697	780.3560571845921	0.00377158285196197	783.3047919115213
19.72	0.09731730551739924	15.7333	0.554222	0.00389269222069597	801.931806303223	0.0038851352991646037	805.0534800071481
20.13	0.09983970551739924	16.1184	0.565731	0.0039935882206959695	821.5604880551359	0.0039856350147789025	824.8414623428222
20.54	0.10247860551739923	16.5342	0.579052	0.004099144220695969	842.753959549411	0.004090765617954512	846.2085295721665
20.95	0.10506860551739924	16.9037	0.59005	0.00420274422069597	861.5875038426643	0.004193937357908799	865.2085357450629
21.36	0.10809860551739923	17.3309	0.603203	0.004323944220695969	883.3620373259602	0.004314622834327426	887.1816455020379
21.77	0.11054260551739924	17.7218	0.615456	0.00442170422069597	903.2863471073748	0.004411957208296667	907.2804121608765
22.18	0.11292760551739923	18.0983	0.627384	0.004517104220695969	922.4766838500263	0.00450693272439583	926.6436071721389
22.6	0.11554260551739924	18.4931	0.639793	0.004621704220695969	942.5997779961059	0.004611056938865272	946.9561953684976
23	0.11832860551739924	18.8857	0.651611	0.004733144220695969	962.6107373723745	0.0047219781135902465	967.1669128207484
23.41	0.12078260551739924	19.2885	0.664455	0.004831304220695969	983.1415943177666	0.004819670924740713	987.8914504519358
23.81	0.12342460551739924	19.6783	0.676247	0.0049369842206959695	1003.0098367142756	0.004924837277205398	1007.9616804513367
24.22	0.12597060551739925	20.0852	0.688759	0.00503882422069597	1023.7496720943155	0.0050261718302478525	1028.908166737994
24.63	0.12838560551739925	20.4568	0.70108	0.00513542422069597	1042.6902541223885	0.005122282901364461	1048.0449109080923
25.04	0.13124260551739925	20.858	0.713299	0.00524970422069597	1063.1395585079179	0.005235972560630607	1068.7207267354058
25.45	0.13382360551739925	21.2364	0.725483	0.00535294422069597	1082.4267389154065	0.0053386681381686184	1088.2209088718105
25.86	0.13657160551739925	21.586	0.737705	0.00546286422069597	1100.2459732453694	0.005447996898812075	1106.2564676065763
26.26	0.13972860551739924	21.9362	0.750179	0.005589144220695969	1118.0957897852809	0.005573582910149261	1124.3449884069437
26.66	0.14372260551739927	22.232	0.76162	0.005748904220695971	1133.1728192898663	0.005732442332571906	1139.6873212934597
27.07	0.15072260551739924	22.4107	0.775269	0.00602890422069597	1142.2812208195126	0.006010803094514063	1149.1679248929331
27.48	0.16085560551739925	22.3804	0.786865	0.00643422422069597	1140.7368192171161	0.006413612964421506	1148.0765756887627
27.89	0.17361260551739927	22.2938	0.799152	0.006944504220695971	1136.3227869145564	0.006920502208573489	1144.2139853043575
28.3	0.18640560551739926	22.2187	0.811928	0.00745622422069597	1132.494913636009	0.007428563989710069	1140.9390496408766
28.71	0.19811160551739926	22.2098	0.823925	0.007924464220695971	1132.041277521774	0.007893230552320758	1141.012098121846
29.12	0.20870860551739925	22.2199	0.835884	0.00834834422069597	1132.5560780559058	0.008313689534329616	1142.011046044758
29.52	0.21992060551739925	22.2523	0.848225	0.00879682422069597	1134.2075173931223	0.008758357587384342	1144.1849415534216
29.93	0.23062860551739925	22.2586	0.860554	0.00922514422069597	1134.528630597581	0.009182852477063397	1144.9948208373523
30.33	0.24130960551739924	22.2581	0.871876	0.00965238422069597	1134.5031454226237	0.00960609757277531	1145.453805681831
30.74	0.25234660551739924	22.2684	0.884789	0.01009386422069597	1135.028140026739	0.010043261406966668	1146.484959958838
31.15	0.2645476055173992	22.2373	0.896591	0.010581904220695968	1133.442962144411	0.010526307739398463	1145.4369470094452
31.57	0.2755786055173992	22.2777	0.9095	0.011023144220695969	1135.50216428094	0.010962832180556591	1148.0189684007212
31.97	0.28540960551739925	22.3172	0.920643	0.01141638422069597	1137.515493102546	0.011351709078407442	1150.5018070287992
32.38	0.29595960551739925	22.3437	0.932304	0.01183838422069597	1138.8662073752691	0.011768858725304848	1152.3485431141444
32.78	0.3062616055173992	22.3789	0.945038	0.01225046422069597	1140.660363692245	0.01217603453283983	1154.6339826656229
33.18	0.31645660551739924	22.3875	0.956646	0.012658264220695969	1141.098708701506	0.012578818124796819	1155.5430376581446
33.6	0.3272156055173992	22.4058	0.969196	0.013088624220695969	1142.0314661049338	0.013003708330903023	1156.9790868129917
34.02	0.3378996055173992	22.4413	0.982391	0.013515984220695968	1143.8409135268837	0.013425458093589394	1159.3010492650997
34.43	0.34820060551739923	22.4398	0.994621	0.013928024220695969	1143.7644580020126	0.013831920618776108	1159.694837075836
34.85	0.35904960551739923	22.4703	1.00644	0.01436198422069597	1145.319053674392	0.014259827875445965	1161.768107850926
35.26	0.3690546055173992	22.4973	1.01882	0.014762184220695968	1146.6952531220722	0.014654283780524049	1163.622979693658
35.67	0.3800866055173992	22.5138	1.03187	0.015203464220695968	1147.5362638956544	0.015089049765150193	1164.9827904257431
36.0801	0.39014360551739924	22.5266	1.04339	0.01560574422069597	1148.1886843745547	0.015485226819685541	1166.1070233000014
36.4901	0.40112760551739923	22.5525	1.05595	0.01604510422069597	1149.5088164373296	0.015917742088917147	1167.9528051996754
36.9001	0.4110316055173992	22.5667	1.06761	0.01644126422069597	1150.2325954061096	0.016307570046602958	1169.1438734224382
37.3101	0.42186660551739924	22.5882	1.08027	0.01687466422069597	1151.3284579292622	0.016733868784050865	1170.7567390645502
37.7201	0.4321196055173992	22.5972	1.09173	0.01728478422069597	1151.787191078489	0.017137101682898805	1171.6955841444424
38.1301	0.4430966055173992	22.6075	1.105	0.017723864220695967	1152.312185682604	0.017568628111201638	1172.735610401496
38.5401	0.4528376055173992	22.6312	1.1172	0.018113504220695967	1153.5201829755679	0.017951409182811212	1174.4144756785538
38.9601	0.4637466055173992	22.6415	1.12914	0.018549864220695968	1154.0451775796828	0.018379913974951676	1175.452558928335
39.3801	0.47421660551739925	22.6683	1.14145	0.01896866422069597	1155.41118295738	0.018791002266961534	1177.3277897237356
39.7801	0.4844526055173992	22.6868	1.15405	0.01937810422069597	1156.354134430791	0.019192739608071455	1178.7620853638234
40.1901	0.49554960551739924	22.7028	1.16606	0.01982198422069597	1157.169660029416	0.01962808679104439	1180.1070587711872
40.5901	0.5058996055173993	22.7273	1.17846	0.020235984220695974	1158.418433602311	0.020033957616371632	1181.860170745651
41.0201	0.5161846055173993	22.7383	1.19048	0.020647384220695973	1158.979107451366	0.020437116377850926	1182.9089943866736
41.4401	0.5269796055173993	22.7547	1.20341	0.021079184220695973	1159.815021189957	0.020860091729312615	1184.2629756835504
41.8601	0.5374836055173993	22.7761	1.21508	0.021499344220695972	1160.9057866781181	0.021271493298530772	1185.8644997937088
42.2501	0.5477596055173993	22.7856	1.22767	0.021910384220695973	1161.390005002302	0.021673801264302885	1186.8365062419784
42.6701	0.5584636055173993	22.8175	1.23944	0.02233854422069597	1163.0159591645613	0.02209269350418998	1188.996042597734
43.0801	0.5685126055173992	22.8278	1.25172	0.02274050422069597	1163.5409537686762	0.022485793228606533	1190.0004617388056
43.4801	0.5788626055173993	22.8393	1.2635	0.02315450422069597	1164.1271127926884	0.022890506084293247	1191.0818989392733
43.8901	0.5892616055173993	22.8634	1.27638	0.02357046422069597	1165.3554982256173	0.023296970081303638	1192.8234683009355
44.3001	0.6000456055173993	22.8753	1.28836	0.02400182422069597	1165.962045389595	0.023718308081252748	1193.9472614510394
44.7001	0.6097996055173993	22.8874	1.29976	0.024391984220695974	1166.5787866235555	0.024099250459725288	1195.033957979076
45.1201	0.6205286055173993	22.9034	1.31247	0.024821144220695972	1167.3943122221808	0.024518103921396035	1196.3703748082678
45.5301	0.6307326055173993	22.9196	1.32452	0.025229304220695973	1168.220031890789	0.024916299005525135	1197.6934104720729
45.9301	0.6411096055173993	22.9401	1.33735	0.02564438422069597	1169.2649240640278	0.025321082594106863	1199.2500030325086
46.3301	0.6514776055173993	22.9595	1.35002	0.02605910422069597	1170.2537488523608	0.025725351542309788	1200.7495132583645
46.7401	0.6613306055173993	22.9655	1.36165	0.026453224220695973	1170.5595709518452	0.026109388217152387	1201.5246457459161
47.1501	0.6719946055173993	22.9932	1.37384	0.026879784220695972	1171.9714496444653	0.02652486880834978	1203.473789323725
47.5601	0.6823216055173993	23.0005	1.38601	0.027292864220695972	1172.3435331988383	0.02692705506653162	1204.3401460704451
47.9601	0.6925206055173992	23.006	1.39835	0.02770082422069597	1172.6238701233656	0.027324097653721978	1205.1065178266451
48.3801	0.7031456055173992	23.0358	1.41111	0.02812582422069597	1174.142786550805	0.027737556644903485	1207.166520175331
48.7901	0.7137176055173993	23.039	1.42393	0.02854870422069597	1174.3058916705304	0.028148783603871998	1207.830803236453
49.1901	0.7235656055173992	23.0561	1.43571	0.02894262422069597	1175.1774846540613	0.028531696522500507	1209.1902049850266
49.5901	0.7338636055173993	23.0883	1.44833	0.02935454422069597	1176.8187299212946	0.028931949714133706	1211.3637073685125
50.0001	0.7443816055173993	23.0843	1.46029	0.02977526422069597	1176.6148485216381	0.029340588357632237	1211.648866522364
50.4101	0.7545396055173993	23.1123	1.4722	0.030181584220695973	1178.0420183192327	0.029735082063242706	1213.5971927106534
50.8201	0.7648336055173993	23.1214	1.48469	0.030593344220695973	1178.5058485034508	0.03013469873151324	1214.5602835928203
51.2201	0.7753146055173993	23.1396	1.49731	0.03101258422069597	1179.4335088718872	0.030541410799998427	1216.0107898984875
51.6201	0.7850846055173992	23.1302	1.50838	0.03140338422069597	1178.9543875826944	0.03092038382062793	1215.977545194629
52.0301	0.7961426055173992	23.1597	1.52224	0.03184570422069597	1180.45801290516	0.03134914446737098	1218.0505296290883
52.4401	0.8063296055173993	23.1768	1.53422	0.03225318422069597	1181.3296058886908	0.031743970517203436	1219.4312472927809
52.8401	0.8160516055173993	23.1642	1.54553	0.032642064220695974	1180.6873794797734	0.03212062885364074	1219.2274527453174
53.2501	0.8271976055173993	23.1931	1.55783	0.03308790422069597	1182.1604225922904	0.032552282568050483	1221.2756334285216
53.6701	0.8377326055173993	23.2167	1.57059	0.03350930422069597	1183.3633228502626	0.032960102731669445	1223.0170044392657
54.0701	0.8480686055173993	23.2321	1.58282	0.03392274422069597	1184.1482662389394	0.033360057841026455	1224.3178249939435
54.4801	0.8581136055173992	23.2231	1.59398	0.03432454422069597	1183.6895330897128	0.033748599392416555	1224.3191368118255
54.8901	0.8688226055173993	23.2382	1.60691	0.03475290422069597	1184.4591853734155	0.03416265833104431	1225.6225819960214
55.3001	0.8795306055173993	23.2652	1.61987	0.03518122422069597	1185.8353848210957	0.0345765072552472	1227.5545253833218
55.7101	0.8902196055173993	23.2747	1.63139	0.03560878422069597	1186.3196031452794	0.0349894511117782	1228.5630019104615
56.1201	0.9002746055173992	23.2892	1.64345	0.03601098422069597	1187.0586732190336	0.03537774631071417	1229.8058243693645
56.5301	0.9105666055173993	23.2942	1.65533	0.036422664220695976	1187.313524968604	0.03577503768428805	1230.5586468132265
56.9401	0.9213756055173993	23.3179	1.66858	0.03685502422069597	1188.5215222615677	0.03619211640816381	1232.3245117513363
57.3501	0.9324966055173993	23.3167	1.68167	0.03729986422069597	1188.4603578416709	0.036621052558785165	1232.7897678208449
57.7601	0.9423256055173993	23.3202	1.69308	0.037693024220695974	1188.6387540663702	0.03700000325967191	1233.4421434130516
58.1601	0.9526956055173993	23.3478	1.70597	0.038107824220695974	1190.0455357239987	0.037399656247416556	1235.3955818139927
58.5601	0.9633996055173992	23.3418	1.71774	0.03853598422069597	1189.7397136245143	0.03781201392216709	1235.587504455484
58.9801	0.9740056055173992	23.364	1.73035	0.03896022422069597	1190.8712553926068	0.03822042863231009	1237.2678665206845
59.3901	0.9850816055173993	23.368	1.74298	0.039403264220695976	1191.0751367922633	0.03864676407283793	1238.0073851139905
59.8001	0.9954376055173992	23.3701	1.75469	0.03981750422069597	1191.182174527083	0.039045221044572774	1238.612075788933
60.2001	1.0056696055173993	23.3866	1.76691	0.04022678422069597	1192.0231853006653	0.039438751131942784	1239.974444761822
60.6101	1.0167896055173993	23.3873	1.77968	0.04067158422069597	1192.058864545605	0.03986625880220684	1240.541787050999
61.0101	1.0272096055173994	23.4071	1.7914	0.041088384220695974	1193.0680774739037	0.040266689218669646	1242.0893170425984
61.4201	1.0376496055173994	23.4126	1.80377	0.04150598422069598	1193.3484143984315	0.040667727473574264	1242.8795148562454
61.8301	1.0485596055173994	23.4159	1.81635	0.041942384220695975	1193.5166165531477	0.04108664834820936	1243.5755490584052
62.2601	1.0594396055173994	23.4311	1.82867	0.04237758422069597	1194.291365871842	0.04150424258797444	1244.9025488131258
62.6801	1.0705696055173992	23.4486	1.84227	0.04282278422069597	1195.183346995338	0.04193125191859105	1246.3644255678887
63.1001	1.0817596055173992	23.4483	1.85494	0.04327038422069597	1195.168055890364	0.04236037945099482	1246.8834368770424
63.5201	1.0924796055173993	23.4415	1.86671	0.04369918422069597	1194.8214575109482	0.04277131022115858	1247.0341804935597
63.9501	1.1042596055173992	23.4687	1.88021	0.04417038422069597	1196.2078510286112	0.04322267942076976	1249.044811416358
64.3501	1.1150496055173993	23.4648	1.8923	0.04460198422069597	1196.0090666639462	0.04363593652112528	1249.353444183101
64.7601	1.1252796055173993	23.4698	1.90404	0.04501118422069597	1196.2639184135166	0.04402758796303866	1250.109174021799
65.1701	1.1364296055173992	23.4863	1.91695	0.04545718422069597	1197.104929187099	0.04445428660483584	1251.5219484846602
65.5901	1.1477196055173993	23.4874	1.92976	0.04590878422069597	1197.1609965720047	0.044886157462288634	1252.1212024410622
66.0101	1.1590796055173993	23.4919	1.94248	0.04636318422069597	1197.390363146618	0.04532051782652247	1252.9051931372708
66.4201	1.1694696055173992	23.4895	1.95395	0.046778784220695965	1197.2680343068241	0.0457176241974495	1253.274777338
66.8301	1.1803796055173992	23.5047	1.96662	0.04721518422069597	1198.0427836255183	0.04613443533720935	1254.6085943586727
67.2401	1.1917796055173993	23.5077	1.97932	0.04767118422069597	1198.1956946752605	0.046569781152687895	1255.3151023685698
67.6601	1.2024096055173992	23.5123	1.9916	0.04809638422069597	1198.4301582848652	0.046975551346135735	1256.0703156394038
68.0501	1.2134696055173992	23.5233	2.00354	0.04853878422069597	1198.99083213392	0.047397560871898274	1257.1883894174612
68.4601	1.2245796055173992	23.5228	2.01563	0.04898318422069597	1198.965346958963	0.04782129899081755	1257.6944874232845
68.8801	1.2358496055173993	23.5198	2.02857	0.049433984220695976	1198.8124359092208	0.04825095617597078	1258.0745109495313
69.3001	1.2473396055173993	23.5368	2.04124	0.04989358422069597	1199.6789318577603	0.04868881067209792	1259.5352136822
69.7101	1.2580396055173992	23.5189	2.05266	0.05032158422069597	1198.766562594298	0.04909638796451641	1259.090395134841
70.1201	1.2694396055173993	23.5401	2.06491	0.050777584220695976	1199.8471340124765	0.04953044649350791	1260.7724729117556
70.5501	1.2806596055173993	23.5435	2.07806	0.051226384220695975	1200.0204332021847	0.0499574675777284	1261.4931409860858
70.9501	1.2916796055173994	23.5383	2.08945	0.05166718422069597	1199.7553873826314	0.050376699452390324	1261.7433700023023
71.3601	1.3030596055173993	23.5451	2.1022	0.05212238422069597	1200.1019857620472	0.050809442359696276	1262.6541625679567
71.7801	1.3144096055173993	23.5498	2.1151	0.05257638422069597	1200.3415464066434	0.05124085802244946	1263.4511647465833
72.1801	1.3255296055173993	23.5586	2.12723	0.053021184220695974	1200.7900854858872	0.05166335091784712	1264.4573978188198
72.6101	1.3366996055173992	23.5476	2.13926	0.053467984220695965	1200.2294116368323	0.05208756388166782	1264.4032588794457
73.0101	1.3480296055173993	23.5577	2.15157	0.05392118422069597	1200.7442121709646	0.05251766954394718	1265.4897620373695
73.4201	1.3596896055173993	23.5499	2.16427	0.05438758422069597	1200.3466434416348	0.05296010948878804	1265.6305976058466
73.8201	1.3706496055173993	23.5596	2.17604	0.05482598422069598	1200.8410558358012	0.053375809456655314	1266.6783486146187
74.2301	1.3815796055173992	23.5568	2.18771	0.05526318422069597	1200.6983388560418	0.05379019953343027	1267.0527523497267
74.6401	1.3932196055173993	23.5653	2.2007	0.05572878422069597	1201.1315868303116	0.054231319172453614	1268.06918985344
75.0501	1.4042396055173993	23.5687	2.21265	0.05616958422069598	1201.3048860200195	0.05464876350877977	1268.7816819900545
75.4601	1.4162596055173993	23.5586	2.22528	0.05665038422069597	1200.7900854858872	0.05510388984749395	1268.815305197065
75.8701	1.4273596055173994	23.5744	2.23744	0.05709438422069597	1201.5954170145299	0.05552399733933406	1270.1997674313848
76.2701	1.4382496055173992	23.559	2.24858	0.05752998422069597	1200.8104736258529	0.055935985409331104	1269.8930812255946
76.6901	1.4500296055173993	23.5629	2.26067	0.05800118422069597	1201.0092579905177	0.056381452736706174	1270.6692172139872
77.1001	1.4618596055173994	23.5779	2.27336	0.05847438422069597	1201.7738132392292	nan	nan
77.5001	1.4734696055173993	23.5689	2.28567	0.05893878422069597	1201.315080090002	nan	nan
77.9101	1.4847296055173993	23.5633	2.29753	0.05938918422069597	1201.0296461304836	nan	nan
78.3201	1.4964896055173993	23.5675	2.30949	0.05985958422069597	1201.2437216001226	nan	nan
78.7301	1.5079596055173994	23.5515	2.32179	0.06031838422069598	1200.4281960014973	nan	nan
79.1701	1.5202696055173992	23.5587	2.33409	0.06081078422069597	1200.7951825208786	nan	nan
79.5801	1.5325996055173994	23.5534	2.34707	0.061303984220695974	1200.5250396663341	nan	nan
79.9801	1.5440396055173993	23.5501	2.35906	0.06176158422069597	1200.3568375116176	nan	nan
80.4001	1.5563996055173992	23.5549	2.3717	0.06225598422069597	1200.6014951912052	nan	nan
80.8101	1.5676096055173994	23.5414	2.38325	0.06270438422069598	1199.9133954673648	nan	nan
81.2301	1.5797196055173992	23.5353	2.39589	0.06318878422069597	1199.6024763328892	nan	nan
81.6501	1.5919996055173993	23.5379	2.40834	0.06367998422069597	1199.7349992426657	nan	nan
82.0601	1.6041896055173992	23.5312	2.42093	0.06416758422069596	1199.3934978982413	nan	nan
82.4601	1.6157696055173993	23.5085	2.43306	0.06463078422069597	1198.2364709551916	nan	nan
82.8801	1.6281496055173992	23.5165	2.44575	0.06512598422069597	1198.6442337545043	nan	nan
83.3001	1.6403296055173993	23.5056	2.45858	0.06561318422069597	1198.088656940441	nan	nan
83.7101	1.6527896055173992	23.5107	2.4709	0.06611158422069596	1198.3486057250027	nan	nan
84.1201	1.6649296055173992	23.4887	2.48347	0.06659718422069597	1197.227258026893	nan	nan
84.5201	1.6765396055173993	23.4659	2.49473	0.06706158422069597	1196.0651340488519	nan	nan
84.9401	1.6895896055173993	23.4762	2.50851	0.06758358422069598	1196.5901286529668	nan	nan
85.3601	1.7021196055173993	23.455	2.52094	0.06808478422069597	1195.5095572347884	nan	nan
85.7701	1.7138296055173994	23.4324	2.53265	0.06855318422069598	1194.3576273267302	nan	nan
86.1801	1.7265296055173993	23.4345	2.54511	0.06906118422069597	1194.4646650615496	nan	nan
86.6001	1.7391996055173993	23.404	2.55722	0.06956798422069597	1192.91006938917	nan	nan
87.0101	1.7514496055173994	23.3926	2.56981	0.07005798422069598	1192.3290074001497	nan	nan
87.4201	1.7641096055173993	23.3869	2.58306	0.07056438422069597	1192.0384764056394	nan	nan
87.8301	1.7764496055173993	23.3447	2.5946	0.07105798422069597	1189.8875276392653	nan	nan
88.2401	1.7894896055173992	23.3365	2.60721	0.07157958422069596	1189.4695707699696	nan	nan
88.6601	1.8024696055173992	23.3073	2.62101	0.07209878422069597	1187.9812365524785	nan	nan
89.0601	1.8146696055173992	23.2781	2.63261	0.07258678422069596	1186.492902334987	nan	nan
89.4701	1.8269596055173993	23.2747	2.64457	0.07307838422069597	1186.3196031452794	nan	nan
89.8801	1.8401596055173992	23.2411	2.6573	0.07360638422069597	1184.6069993881663	nan	nan
90.2901	1.8527996055173992	23.2108	2.66971	0.07411198422069597	1183.0625977857696	nan	nan
90.7001	1.8656096055173992	23.1797	2.68185	0.07462438422069596	1181.4774199034416	nan	nan
91.1101	1.8778696055173993	23.1367	2.69315	0.07511478422069598	1179.2856948571361	nan	nan
91.5201	1.8912596055173994	23.1258	2.7063	0.07565038422069598	1178.7301180430727	nan	nan
91.9301	1.9035996055173994	23.0915	2.71877	0.07614398422069597	1176.9818350410196	nan	nan
92.3401	1.9171096055173993	23.0502	2.73109	0.07668438422069597	1174.876759589568	nan	nan
92.7401	1.9298296055173993	23.0328	2.74325	0.07719318422069597	1173.9898755010631	nan	nan
93.1501	1.9420496055173992	22.9964	2.75517	0.07768198422069597	1172.1345547641906	nan	nan
93.5601	1.9553596055173992	22.9734	2.76817	0.07821438422069597	1170.9622367161667	nan	nan
93.9701	1.9678996055173992	22.9393	2.77963	0.07871598422069596	1169.2241477840964	nan	nan
94.3701	1.9801696055173992	22.8988	2.7913	0.07920678422069596	1167.1598486125763	nan	nan
94.7701	1.9931996055173993	22.868	2.80397	0.07972798422069598	1165.5899618352223	nan	nan
95.1801	2.0061296055173994	22.811	2.81603	0.08024518422069597	1162.6846518901198	nan	nan
95.5801	2.0190696055173993	22.7861	2.82819	0.08076278422069598	1161.4154901772592	nan	nan
96.0101	2.0323496055173993	22.7652	2.84067	0.08129398422069598	1160.3502098640547	nan	nan
96.4101	2.0450396055173994	22.713	2.85303	0.08180158422069597	1157.6895575985397	nan	nan
96.8201	2.058769605517399	22.6749	2.86579	0.08235078422069597	1155.7475872668133	nan	nan
97.2201	2.0712896055173995	22.6436	2.87785	0.08285158422069598	1154.1522153145022	nan	nan
97.6301	2.0838896055173994	22.6035	2.88915	0.08335558422069597	1152.1083042829478	nan	nan
98.0401	2.0977196055173994	22.5719	2.90239	0.08390878422069598	1150.4976412256626	nan	nan
98.4401	2.1096296055173993	22.5423	2.91434	0.08438518422069598	1148.988918868206	nan	nan
98.8501	2.122829605517399	22.5063	2.92697	0.08491318422069596	1147.153986271299	nan	nan
99.2501	2.1353196055173993	22.4591	2.93905	0.08541278422069597	1144.7481857553541	nan	nan
99.6501	2.148109605517399	22.4171	2.95061	0.08592438422069597	1142.607431058963	nan	nan
100.07	2.1617096055173994	22.3914	2.96358	0.08646838422069597	1141.297493066171	nan	nan
100.48	2.1748496055173994	22.3448	2.97575	0.08699398422069597	1138.9222747601748	nan	nan
100.89	2.187559605517399	22.3033	2.98818	0.08750238422069596	1136.8070052387402	nan	nan
101.3	2.2009996055173993	22.2775	3.00077	0.08803998422069598	1135.491970210957	nan	nan
101.7	2.2136096055173993	22.2212	3.01286	0.08854438422069597	1132.6223395107943	nan	nan
102.1	2.2266996055173993	22.1974	3.02455	0.08906798422069598	1131.409245182839	nan	nan
102.51	2.239139605517399	22.1462	3.03674	0.08956558422069597	1128.7995632672382	nan	nan
102.91	2.2519196055173993	22.1099	3.04849	0.09007678422069597	1126.949339565357	nan	nan
103.32	2.2658096055173993	22.0847	3.06182	0.09063238422069597	1125.6648867475221	nan	nan
103.73	2.278119605517399	22.0188	3.07312	0.09112478422069596	1122.3059406881841	nan	nan
104.15	2.291669605517399	21.9742	3.08643	0.09166678422069596	1120.0326630820161	nan	nan
104.56	2.3050196055173995	21.9503	3.09829	0.09220078422069598	1118.8144717190694	nan	nan
104.98	2.317579605517399	21.8984	3.11039	0.09270318422069597	1116.1691105585285	nan	nan
105.38	2.3312296055173993	21.8657	3.12289	0.09324918422069597	1114.5023801163381	nan	nan
105.8	2.3448496055173993	21.8455	3.13597	0.09379398422069597	1113.4727790480738	nan	nan
106.21	2.357969605517399	21.7678	3.14801	0.09431878422069596	1109.5123828597498	nan	nan
106.62	2.3711796055173995	21.7307	3.16022	0.09484718422069598	1107.6213828779369	nan	nan
107.02	2.383999605517399	21.6946	3.17282	0.09535998422069597	1105.7813532460389	nan	nan
107.42	2.3964396055173993	21.6527	3.18452	0.09585758422069597	1103.6456955846388	nan	nan
107.83	2.4099196055173993	21.619	3.19717	0.09639678422069597	1101.9279947925343	nan	nan
108.24	2.4229696055173995	21.5699	3.20939	0.09691878422069598	1099.425350611753	nan	nan
108.65	2.436549605517399	21.5375	3.22285	0.09746198422069596	1097.7739112745364	nan	nan
109.05	2.4493396055173995	21.492	3.23422	0.09797358422069598	1095.4547603534459	nan	nan
109.45	2.4623496055173995	21.4417	3.24635	0.09849398422069598	1092.8909517527675	nan	nan
109.86	2.4753396055173993	21.3992	3.25839	0.09901358422069598	1090.7247118814191	nan	nan
110.27	2.4884396055173994	21.3546	3.27069	0.09953758422069597	1088.4514342752511	nan	nan
110.68	2.501419605517399	21.3252	3.28315	0.10005678422069597	1086.9529059877768	nan	nan
111.11	2.5153496055173994	21.2671	3.29542	0.10061398422069598	1083.9915286577686	nan	nan
111.51	2.5281396055173992	21.2135	3.30825	0.10112558422069597	1081.259517902374	nan	nan
111.92	2.5415796055173994	21.196	3.32109	0.10166318422069598	1080.3675367788776	nan	nan
112.35	2.5556796055173994	21.1417	3.33384	0.10222718422069597	1077.599846778543	nan	nan
112.76	2.568459605517399	21.0864	3.34629	0.10273838422069596	1074.7811864282944	nan	nan
113.17	2.582139605517399	21.0543	3.35929	0.10328558422069596	1073.1450381960524	nan	nan
113.59	2.595699605517399	20.9925	3.37149	0.10382798422069596	1069.995070571362	nan	nan
114	2.6087096055173995	20.9415	3.38385	0.10434838422069598	1067.3955827257437	nan	nan
114.4	2.6215496055173992	20.9223	3.39534	0.10486198422069597	1066.4169520073933	nan	nan
114.81	2.6350596055173994	20.8537	3.40829	0.10540238422069598	1062.9203860032874	nan	nan
115.21	2.648099605517399	20.8199	3.42034	0.10592398422069596	1061.1975881761914	nan	nan
115.62	2.6613596055173994	20.7737	3.43251	0.10645438422069597	1058.8427580101609	nan	nan
116.02	2.674059605517399	20.7231	3.4445	0.10696238422069597	1056.2636583045082	nan	nan
116.43	2.6875296055173994	20.6892	3.45744	0.10750118422069598	1054.535763442421	nan	nan
116.84	2.7007396055173993	20.6308	3.46919	0.10802958422069597	1051.5590950074386	nan	nan
117.25	2.7141696055173994	20.5873	3.48195	0.10856678422069597	1049.341884786176	nan	nan
117.66	2.7274496055173993	20.562	3.49425	0.10909798422069597	1048.0523349333498	nan	nan
118.07	2.740709605517399	20.4795	3.50633	0.10962838422069597	1043.847281065438	nan	nan
118.48	2.7536196055173994	20.4514	3.5181	0.11014478422069597	1042.4150142328522	nan	nan
118.89	2.767609605517399	20.4042	3.53128	0.11070438422069596	1040.0092137169077	nan	nan
119.31	2.7808596055173993	20.3374	3.54397	0.11123438422069597	1036.6043943426469	nan	nan
119.73	2.7941596055173994	20.3154	3.55588	0.11176638422069597	1035.4830466445371	nan	nan
120.14	2.8077096055173993	20.2484	3.56828	0.11230838422069597	1032.0680332002937	nan	nan
120.54	2.8207896055173993	20.1835	3.57969	0.11283158422069597	1028.7600574908697	nan	nan
120.96	2.8346996055173994	20.1461	3.59294	0.11338798422069597	1026.8537664040832	nan	nan
121.38	2.8483096055173993	20.0937	3.60529	0.11393238422069597	1024.1829200685852	nan	nan
121.78	2.861709605517399	20.054	3.61796	0.11446838422069597	1022.1593971769962	nan	nan
122.19	2.875319605517399	19.9952	3.63015	0.11501278422069597	1019.1623406020482	nan	nan
122.59	2.8880996055173993	19.9454	3.64288	0.11552398422069597	1016.6240171763268	nan	nan
122.99	2.901439605517399	19.8967	3.65422	0.11605758422069597	1014.1417611355112	nan	nan
123.4	2.9144796055173994	19.8281	3.6659	0.11657918422069598	1010.645195131405	nan	nan
123.82	2.9282296055173993	19.7836	3.67867	0.11712918422069597	1008.3770145602284	nan	nan
124.23	2.9412696055173995	19.7466	3.69091	0.11765078422069598	1006.4911116134076	nan	nan
124.63	2.9549996055173993	19.6776	3.70379	0.11819998422069597	1002.9741574693359	nan	nan
125.04	2.9684896055173993	19.6391	3.71558	0.11873958422069597	1001.0117989976436	nan	nan
125.46	2.9823896055173993	19.5837	3.72878	0.11929558422069597	998.1880416124036	nan	nan
125.88	2.9956396055173995	19.5164	3.74122	0.11982558422069597	994.7577370631859	nan	nan
126.28	3.0088196055173992	19.4744	3.75227	0.12035278422069597	992.6169823667942	nan	nan
126.7	3.0227396055173994	19.4075	3.76537	0.12090958422069598	989.2070659575423	nan	nan
127.1	3.035989605517399	19.3677	3.77741	0.12143958422069596	987.1784460309619	nan	nan
127.5	3.0495796055173994	19.3166	3.78878	0.12198318422069597	984.5738611503524	nan	nan
127.91	3.063239605517399	19.2452	3.80223	0.12252958422069597	980.9345781664869	nan	nan
128.32	3.0764996055173994	19.2036	3.81446	0.12305998422069597	978.8142116100612	nan	nan
128.72	3.0898396055173993	19.1361	3.82608	0.12359358422069597	975.3737129908604	nan	nan
129.13	3.103709605517399	19.0795	3.83868	0.12414838422069596	972.4887911857235	nan	nan
129.54	3.1165596055173994	19.0353	3.85044	0.12466238422069598	970.235901719521	nan	nan
129.97	3.1303896055173994	18.9646	3.86257	0.12521558422069598	966.6322979805956	nan	nan
130.36	3.1440596055173993	18.9038	3.87489	0.12576238422069597	963.5333007058193	nan	nan
130.76	3.1571596055173994	18.8524	3.88661	0.12628638422069596	960.9134247202354	nan	nan
131.18	3.171029605517399	18.788	3.89867	0.12684118422069596	957.6309341857686	nan	nan
131.59	3.185059605517399	18.731	3.91135	0.12740238422069597	954.725624240666	nan	nan
132	3.198819605517399	18.6684	3.92434	0.12795278422069598	951.5348803360444	nan	nan
132.41	3.2125596055173995	18.6078	3.93658	0.128502384220696	948.4460771312511	nan	nan
132.83	3.2255696055173995	18.5529	3.94817	0.129022784220696	945.647804920968	nan	nan
133.23	3.239879605517399	18.4919	3.96119	0.12959518422069596	942.5386135762091	nan	nan
133.64	3.253189605517399	18.4339	3.97311	0.13012758422069598	939.5823332811924	nan	nan
134.05	3.2669896055173995	18.3745	3.98566	0.13067958422069598	936.5546944962958	nan	nan
134.46	3.2807196055173993	18.3076	3.99794	0.13122878422069598	933.1447780870438	nan	nan
134.87	3.2946496055173995	18.2357	4.00985	0.13178598422069598	929.4800099282213	nan	nan
135.29	3.308829605517399	18.1738	4.02293	0.13235318422069597	926.3249452685395	nan	nan
135.71	3.3224396055173995	18.1067	4.03479	0.13289758422069597	922.9048347893048	nan	nan
136.1	3.335199605517399	18.0431	4.04649	0.13340798422069597	919.6631205347691	nan	nan
136.51	3.348769605517399	17.9798	4.05828	0.13395078422069598	916.4366973852077	nan	nan
136.91	3.3632296055173994	17.922	4.07105	0.13452918422069599	913.4906111601738	nan	nan
137.32	3.3767796055173993	17.8622	4.08368	0.13507118422069597	910.4425842353118	nan	nan
137.74	3.390659605517399	17.7855	4.09619	0.13562638422069598	906.5331583969016	nan	nan
138.16	3.405079605517399	17.7383	4.10903	0.13620318422069597	904.127357880957	nan	nan
138.55	3.4185596055173995	17.6564	4.12075	0.13674238422069598	899.9528862229938	nan	nan
138.98	3.4326996055173993	17.5689	4.13325	0.13730798422069598	895.4929806055114	nan	nan
139.39	3.446849605517399	17.5183	4.14544	0.13787398422069597	892.913880899859	nan	nan
139.8	3.4598796055173993	17.4379	4.15728	0.13839518422069597	888.8158647667667	nan	nan
140.21	3.474159605517399	17.3713	4.16987	0.13896638422069596	885.4212394624891	nan	nan
140.63	3.488269605517399	17.304	4.183	0.13953078422069598	881.9909349132713	nan	nan
141.04	3.502029605517399	17.2278	4.19469	0.14008118422069596	878.1069942498182	nan	nan
141.45	3.5162196055173993	17.1676	4.20739	0.14064878422069596	875.0385791849905	nan	nan
141.85	3.529549605517399	17.0748	4.21898	0.14118198422069597	870.3085307129637	nan	nan
142.26	3.543239605517399	17.017	4.23149	0.14172958422069595	867.3624444879298	nan	nan
142.68	3.5573796055173994	16.955	4.24393	0.14229518422069598	864.2022827932567	nan	nan
143.1	3.5714796055173994	16.8652	4.25608	0.142859184220696	859.6251453709722	nan	nan
143.5	3.5850996055173994	16.789	4.26767	0.14340398422069597	855.7412047075192	nan	nan
143.91	3.598559605517399	16.7282	4.28036	0.14394238422069597	852.642207432743	nan	nan
144.32	3.6131696055173994	16.6432	4.29286	0.14452678422069598	848.3097276900461	nan	nan
144.73	3.6270496055173993	16.5581	4.30505	0.14508198422069596	843.9721509123576	nan	nan
145.14	3.641199605517399	16.4846	4.31796	0.14564798422069597	840.2258301936726	nan	nan