File: original_data/46NTA9.csv
Specimen name:	AWA_3_05_Rz
Specimen ID:	46NTA9
Material:	42CrMoS4
Specimen type:	Round Tensile Specimen
Gauge diameter:	5.001	mm
Gauge length:	25	mm
Parallel length:	30	mm
Original cross-section:	19.642808851968347	mm²
Cross-section after fracture:	9.9230897298497	mm²
Yield stress at 0.2% plastic strain:	1085.6115802506465	MPa
Yield stress at 1% plastic strain:	1130.9271687909604	MPa
Ultimate tensile strength:	1185.9098245852815	MPa
Uniform elongation:	5.124140519054482	%
Elongation after fracture:	13.245084783357036	%
Reduction of area:	49.48232808947109	%
Slope of linear-elastic region:	209032.26959740033	MPa
Crosshead seperation speed:	0.029868507910122206	mm/s
Strain rate:	0.0009956169303374069	s-1
Test temperature:	RT	Cel
Machine type:	INSTRON 8852TT
Standard:	DIN EN ISO 6892-1
Date:	2022-09-06 00:00:00
Heat treatment batch:	Batch 3
Time	Displacement	Force	Machine Displacement	Engineering Strain	Engineering Stress	True Strain	True Stress
s	mm	kN	mm		MPa		MPa
0	0.0005044479068242259	0.0832337	0	2.0177916272969038e-05	4.237362417323498	2.0177712701542375e-05	4.237447918467573
0.460001	0.000539427106824226	0.0828862	-0.000267029	2.157708427296904e-05	4.21967146474035	2.1576851490926953e-05	4.219762512947149
0.870001	0.0006224779068242259	0.106211	0.00170136	2.4899116272969036e-05	5.407118747650844	2.4898806295163737e-05	5.4072533801292435
1.3	0.0015966879068242258	0.297872	0.0149155	6.386751627296903e-05	15.164430008193618	6.386547682998226e-05	15.165398522673936
1.72	0.002505227906824226	0.53297	0.0279465	0.00010020911627296904	27.13308488702178	0.00010020409567486504	27.135803869480068
2.12	0.0038502679068242256	0.783285	0.0399475	0.00015401071627296902	39.87642530673556	0.00015399885784013898	39.882566703559455
2.55	0.005255427906824226	1.07075	0.0530624	0.00021021711627296905	54.51104310332396	0.0002101950237511133	54.52250225761018
2.98	0.0069839979068242256	1.37494	0.064827	0.00027935991627296903	69.99711753862643	0.00027932090255725853	70.01667192752136
3.39	0.008636557906824226	1.69667	0.0770874	0.00034546231627296907	86.37613962373725	0.0003454026579062937	86.40597932500236
3.80001	0.010655947906824228	2.03716	0.0898895	0.0004262379162729691	103.71021860225771	0.0004261471026968513	103.75442382973095
4.20001	0.012580947906824227	2.38427	0.102493	0.0005032379162729691	121.38131659113913	0.0005031113345382316	121.44240027197493
4.61001	0.014431647906824227	2.71083	0.114151	0.000577265916272969	138.0062301898517	0.0005770993623981733	138.08589648277362
5.02001	0.016580047906824224	3.07875	0.126312	0.0006632019162729689	156.73674896507927	0.0006629820950672128	156.8406970773433
5.44001	0.019034747906824225	3.46848	0.139236	0.000761389916272969	176.57759774271966	0.0007611002060164095	176.7120421450807
5.85001	0.021064947906824224	3.82743	0.150558	0.000842597916272969	194.85146084982978	0.0008422431299295281	195.01564228472458
6.27001	0.023557847906824227	4.24557	0.163773	0.000942313916272969	216.13864045592257	0.0009418702172285526	216.3423109046685
6.66001	0.026046447906824224	4.64812	0.175865	0.001041857916272969	236.63214538353694	0.001041315558987597	236.87868245744943
7.08001	0.028331947906824227	5.01853	0.186172	0.001133277916272969	255.4894281067704	0.0011326362416065746	255.778968633485
7.47001	0.030852747906824227	5.4313	0.199036	0.0012341099162729691	276.5032252225855	0.0012333490285785689	276.8444605947142
7.88001	0.033426947906824225	5.86743	0.211212	0.001337077916272969	298.7062616257166	0.0013361848235968416	299.10565517158875
8.30001	0.036269747906824225	6.30555	0.224045	0.001450789916272969	321.0106073688204	0.0014497385373462145	321.4763263210077
8.71001	0.03876684790682423	6.7116	0.236198	0.001550673916272969	341.6822945526678	0.0015494728629433768	342.21213237448296
9.13001	0.041267947906824226	7.11597	0.248962	0.001650717916272969	362.26845425352343	0.00164935697893007	362.86645728146027
9.54001	0.04382904790682422	7.52223	0.260986	0.001753161916272969	382.9508323727449	0.0017516269217214121	383.62220718786585
9.96001	0.04628954790682423	7.93428	0.273155	0.001851581916272969	403.92797485299207	0.0018498698515030047	404.6758805867066
10.36	0.049161947906824224	8.39051	0.286331	0.001966477916272969	427.1542864990621	0.001964546929655935	427.9942759703038
10.77	0.051662647906824226	8.79082	0.298325	0.002066505916272969	447.5337547826872	0.002064373630004806	448.4585859346775
11.17	0.054055847906824224	9.19539	0.309715	0.002162233916272969	468.1300963267561	0.0021598996527289493	469.14230309826195
11.58	0.056939447906824224	9.65475	0.322128	0.0022775779162729688	491.51575381911465	0.0022749881671820403	492.6352192455133
11.98	0.05918404790682422	10.0356	0.333817	0.002367361916272969	510.90452875808353	0.0023645641297637948	512.1140246823168
12.39	0.06178404790682422	10.451	0.346207	0.002471361916272969	532.0522171121538	0.0024683131234929058	533.3671106989934
12.8	0.06457374790682423	10.8877	0.358925	0.002582949916272969	554.284271768443	0.0025796198341956353	555.7159602817987
13.2	0.06687424790682424	11.2728	0.37117	0.0026749699162729695	573.8894108756949	0.002671398551690626	575.424547785055
13.62	0.06931604790682423	11.6837	0.383202	0.002772641916272969	594.8080077574655	0.0027688052348680335	596.4571973719087
14.03	0.07192584790682423	12.116	0.395317	0.002877033916272969	616.8160618630615	0.0028729031751534764	618.5906625931434
14.45	0.07446214790682423	12.5327	0.408104	0.0029784859162729693	638.0299321980184	0.0029740590152261257	639.9302953652308
14.85	0.07701904790682423	12.9553	0.420967	0.0030807619162729694	659.5441669077683	0.0030760260934159975	661.5760654592776
15.28	0.07939394790682423	13.3484	0.432526	0.0031757579162729694	679.5565797435531	0.003170725848040588	681.7146869312292
15.68	0.08207244790682423	13.7831	0.444572	0.0032828979162729693	701.686815967709	0.0032775209716682592	703.9903821537256
16.09	0.08450654790682423	14.1847	0.45665	0.0033802619162729692	722.1319571400601	0.0033745616728935567	724.5729522933043
16.51	0.08691884790682423	14.5894	0.469215	0.0034767539162729694	742.7349168822177	0.0034707239797375994	745.3172234132406
16.93	0.08955114790682424	14.9979	0.481819	0.0035820459162729697	763.5313316454284	0.0035756456692320544	766.2663359338953
17.34	0.09204744790682423	15.4293	0.494446	0.0036818979162729693	785.4935674565644	0.0036751363220573815	788.3856745858285
17.75	0.09459224790682423	15.8223	0.506195	0.003783689916272969	805.5008893707427	0.0037765497666555326	808.5486549634036
18.17	0.09696554790682423	16.2305	0.518661	0.003878621916272969	826.2820313691334	0.0038711194555034576	829.4868669650243
18.57	0.09940164790682424	16.6254	0.530594	0.00397606591627297	846.386080793838	0.003968182256578553	849.7513676416902
18.98	0.10204744790682423	17.0688	0.543861	0.004081897916272969	868.9592271977735	0.004073589572506852	872.5062300565983
19.39	0.10438244790682423	17.4462	0.554939	0.0041752979162729695	888.1723653413127	0.004166605547015788	891.8807495676135
19.8	0.10680244790682424	17.8612	0.567375	0.00427209791627297	909.2996900089563	0.004262998412744514	913.1843073199112
20.21	0.10936844790682423	18.2503	0.579582	0.004374737916272969	929.1084659804746	0.00436519656750072	933.1730720149297
20.61	0.11189644790682424	18.6241	0.591484	0.00447585791627297	948.1383309461739	0.0044658710529950916	952.3820634004611
21.03	0.11405844790682423	19.0244	0.604263	0.0045623379162729695	968.5172901376385	0.004551961999630952	972.9359932929993
21.44	0.11673144790682423	19.433	0.616852	0.004669257916272969	989.3187958224557	0.004658390746145604	993.9381804415674
21.84	0.11899944790682424	19.7848	0.628746	0.004759977916272969	1007.2286580346896	0.004748685043097085	1012.023044203572
22.25	0.12155244790682423	20.1445	0.64045	0.004862097916272969	1025.5407030538497	0.004850316092353524	1030.526982369221
22.65	0.12467844790682424	20.5331	0.653709	0.00498713791627297	1045.3240244173348	0.004974743335882005	1050.5371994942975
23.07	0.1283494479068242	20.8311	0.665878	0.005133977916272969	1060.494970805185	0.00512084398534497	1065.9395285656171
23.49	0.13410544790682422	21.0502	0.677956	0.005364217916272968	1071.6491800453796	0.005349881744726003	1077.3977397769381
23.91	0.1430944479068242	21.1272	0.691093	0.005723777916272968	1075.5691896825083	0.0057074593391188725	1081.7255088578365
24.32	0.15359244790682422	21.1706	0.704216	0.006143697916272969	1077.7786496597994	0.00612490234780835	1084.4001961039178
24.73	0.16278944790682423	21.2128	0.715912	0.006511577916272969	1079.9270185778105	0.006490469177373577	1086.9590475031682
25.14	0.1723194479068242	21.2773	0.728325	0.006892777916272968	1083.2106630141068	0.0068691313208726346	1090.6769935508019
25.55	0.1808314479068242	21.3521	0.741119	0.007233257916272968	1087.0186723758893	0.0072072233738880625	1094.8813587929887
25.97	0.1902684479068242	21.4245	0.754158	0.007610737916272968	1090.704499619112	0.007581922363186573	1099.0055657098128
26.38	0.19938044790682422	21.5142	0.767075	0.007975217916272969	1095.271056300287	0.007943583946428015	1104.0060816516682
26.79	0.20840844790682422	21.5672	0.778938	0.008336337916272968	1097.9692447518175	0.008301782561931209	1107.1222873977435
27.19	0.2169454479068242	21.6118	0.789993	0.008677817916272968	1100.2397957883882	0.00864038207277273	1109.787476400477
27.6	0.22660944790682422	21.6719	0.802925	0.00906437791627297	1103.2994396739916	0.00902354301922827	1113.300162750009
28.01	0.23602844790682423	21.7244	0.815254	0.00944113791627297	1105.9721735174885	0.009396848914525696	1116.413809339227
28.43	0.2456434479068242	21.7881	0.827774	0.009825737916272968	1109.2150905809317	0.009777779250435065	1120.1139473537548
28.86	0.2552874479068242	21.8319	0.840836	0.010211497916272969	1111.4449142446495	0.010159712808734523	1122.794431670511
29.27	0.26497744790682426	21.8719	0.853104	0.01059909791627297	1113.481282887314	0.010543321253338166	1125.2831800325737
29.67	0.2744624479068242	21.9104	0.865379	0.01097849791627297	1115.4412877058783	0.010918671677914176	1127.6871575586822
30.1	0.2848344479068243	21.9287	0.878021	0.01139337791627297	1116.3729263598975	0.011328962199432746	1129.0921850054115
30.51	0.2943884479068242	21.9786	0.890182	0.01177553791627297	1118.9132962416213	0.01170674578591883	1132.0891021865364
30.93	0.3051854479068242	22.023	0.90313	0.012207417916272969	1121.1736654349788	0.012133508279456848	1134.8603009256633
31.33	0.31513444790682427	22.0305	0.915268	0.01260537791627297	1121.5554845554784	0.012526591537270324	1135.693115292369
31.75	0.32544244790682425	22.0725	0.927345	0.01301769791627297	1123.6936716302762	0.012933695909859764	1138.3215763979867
32.15	0.3346304479068242	22.0858	0.938797	0.013385217916272969	1124.370764203962	0.013296427330307444	1139.4207119015184
32.56	0.34485944790682427	22.1014	0.951225	0.01379437791627297	1125.1649479746013	0.013700101485668238	1140.6858984851067
32.96	0.35477044790682427	22.1516	0.963341	0.01419081791627297	1127.720590621145	0.014091070814107728	1143.7238681830815
33.38	0.3651064479068242	22.166	0.975731	0.01460425791627297	1128.4536833325042	0.014498642786899054	1144.9339119704605
33.78	0.37497144790682424	22.1795	0.987854	0.01499885791627297	1129.1409577494035	0.014887487287475226	1146.0767825421312
34.2	0.38557044790682427	22.2223	1.00075	0.01542281791627297	1131.3198721970543	0.01530509512845494	1148.7680125910108
34.62	0.39599744790682423	22.2328	1.01282	0.01583989791627297	1131.854418965754	0.01571575594806297	1149.782877418254
35.02	0.40596144790682426	22.2684	1.02499	0.016238457916272972	1133.6667870577253	0.0161080242914234	1152.0757874704384
35.44	0.41652844790682425	22.2859	1.03715	0.01666113791627297	1134.557698338891	0.016523863821282535	1153.4607206248843
35.8501	0.42661644790682424	22.291	1.04919	0.01706465791627297	1134.8173353408306	0.016920692150964214	1154.1826049658782
36.2701	0.43703944790682425	22.3215	1.06184	0.01748157791627297	1136.3700664308624	0.01733053292871891	1156.2356082888937
36.6801	0.4470284479068242	22.3394	1.07349	0.01788113791627297	1137.2813413984547	0.017723150914716726	1157.6172259136044
37.0901	0.4571344479068242	22.3631	1.08615	0.01828537791627297	1138.4878898192333	0.018120210784003304	1159.3055711376783
37.5101	0.46696744790682426	22.3759	1.0974	0.018678697916272972	1139.139527784886	0.018506393348099212	1160.4171709088657
37.9101	0.4772204479068242	22.3853	1.11065	0.019088817916272968	1139.6180744159121	0.018908912283503634	1161.372036332531
38.3301	0.48802744790682423	22.4328	1.12325	0.01952109791627297	1142.0362621790762	0.01933300519418929	1164.3300638770083
38.7401	0.4979844479068242	22.4472	1.13515	0.01991937791627297	1142.7693548904351	0.019723582913698905	1165.532609541633
39.1501	0.5088194479068242	22.4622	1.14754	0.02035277791627297	1143.5329931314345	0.020148428202382353	1166.8070661805693
39.5601	0.5186204479068243	22.4638	1.15868	0.02074481791627297	1143.614447877141	0.020532574463317316	1167.3385213647714
39.9701	0.5286994479068242	22.4957	1.17134	0.02114797791627297	1145.238451869666	0.020927462976623838	1169.4579293586723
40.3801	0.5390474479068242	22.5351	1.1843	0.02156189791627297	1147.2442749826903	0.021332728560897445	1171.9810389248958
40.7901	0.5490134479068243	22.5466	1.19633	0.02196053791627297	1147.8297309674565	0.021722878429640376	1173.036689295793
41.1901	0.5585694479068243	22.5505	1.2077	0.022342777916272972	1148.0282769101163	0.022096834683092703	1173.6784177427207
41.6101	0.5688324479068243	22.5699	1.2199	0.022753297916272973	1149.0159157018086	0.022498302379759902	1175.159817142311
42.0101	0.5787524479068242	22.5842	1.23168	0.02315009791627297	1149.743917491561	0.022886199487495765	1176.3606017601298
42.4201	0.5888974479068243	22.6052	1.24387	0.023555897916272973	1150.8130110289599	0.023282739103975856	1177.9214448374767
42.8301	0.5994494479068242	22.6161	1.25598	0.023977977916272968	1151.3679214840859	0.023695020444920313	1178.9753960789365
43.2501	0.6096114479068242	22.6369	1.26846	0.02438445791627297	1152.4268331782716	0.024091903338518444	1180.5281367934908
43.6601	0.6197454479068243	22.6583	1.27993	0.024789817916272973	1153.516290402097	0.024487535872137624	1182.1117492046194
44.0601	0.6294164479068243	22.6663	1.29193	0.025176657916272972	1153.9235641306298	0.024864946926564407	1182.975502966273
44.4901	0.6397894479068242	22.6987	1.30527	0.025591577916272968	1155.5730227311878	0.025269595290442783	1185.1459597803562
44.8801	0.6492094479068242	22.695	1.3168	0.025968377916272968	1155.3846586317416	0.025636925529235532	1185.3881240857547
45.2901	0.6598664479068242	22.7113	1.32942	0.02639465791627297	1156.2144788536275	0.02605232962557477	1186.732364500811
45.7001	0.6697354479068243	22.7341	1.34135	0.02678941791627297	1157.3752089799461	0.026436864075759497	1188.3806171392437
46.1101	0.6800184479068242	22.7526	1.35391	0.027200737916272966	1158.3170294771785	0.026837372329735508	1189.824107419943
46.5101	0.6904554479068242	22.7815	1.36631	0.027618217916272968	1159.7883058215034	0.02724371470316884	1191.8195919884267
46.9301	0.7006204479068242	22.7938	1.37837	0.028024817916272968	1160.4144891791227	0.027639308683461164	1192.9348939457725
47.3501	0.7110544479068243	22.8032	1.39075	0.02844217791627297	1160.8930358101488	0.02804520871159279	1193.9113620764233
47.7601	0.7209724479068242	22.8177	1.40275	0.02883889791627297	1161.6312194431146	0.02843088280307013	1195.1313835969902
48.1801	0.7311724479068242	22.8234	1.41556	0.029246897916272968	1161.9214019746944	0.028827367736954754	1195.903998604981
48.5901	0.7417184479068243	22.8462	1.42818	0.02966873791627297	1163.0821321010133	0.029237136839254132	1197.5893110534182
48.9901	0.7512604479068242	22.8673	1.44006	0.03005041791627297	1164.1563165600187	0.029607750476834796	1199.1397003925163
49.4101	0.7615634479068243	22.8807	1.45272	0.030462537916272972	1164.8385000553112	0.030007767379741285	1200.3224370295807
49.8101	0.7714174479068242	22.8911	1.46494	0.03085669791627297	1165.3679559024042	0.030390202082675354	1201.3273628789893
50.2401	0.7821104479068243	22.9003	1.47767	0.03128441791627297	1165.836320690217	0.03080503305893569	1202.3088313686599
50.6501	0.7927794479068242	22.9186	1.48998	0.03171117791627297	1166.767959344236	0.031218761529272103	1203.7675456900076
51.0701	0.8028514479068243	22.9332	1.50226	0.03211405791627297	1167.5112338988083	0.03160918218904759	1205.0047572821338
51.4801	0.8131624479068242	22.9394	1.51503	0.03252649791627297	1167.8268710384211	0.032008709365166595	1205.8121893258199
51.8901	0.8233294479068243	22.9508	1.5274	0.03293317791627297	1168.4072361015806	0.03240250064563925	1206.8865994867747
52.3001	0.8331244479068243	22.9509	1.53851	0.03332497791627297	1168.4123270231873	0.03278173690282214	1207.3496420183362
52.7101	0.8436054479068242	22.9807	1.5519	0.03374421791627297	1169.9294216619721	0.03318737403059108	1209.407775013193
53.1201	0.8530874479068242	22.9754	1.56331	0.03412349791627297	1169.6596028168194	0.033554206010556926	1209.5724798362878
53.5401	0.8639414479068243	23.0018	1.57616	0.03455765791627297	1171.0036061209778	0.03397395170713302	1211.4707481600285
53.9501	0.8744184479068242	23.0139	1.58822	0.03497673791627297	1171.6196076353838	0.03437895102154122	1212.5990395892131
54.3601	0.8845834479068242	23.0311	1.60068	0.03538333791627297	1172.4952461517296	0.03477173294384908	1213.9820416515397
54.7601	0.8946954479068242	23.0343	1.61266	0.03578781791627297	1172.658155643143	0.03516231389994541	1214.625032195332
55.1601	0.9048094479068243	23.0594	1.62449	0.03619237791627297	1173.9359769664147	0.035552819567861355	1216.4235114942924
55.5701	0.9153184479068243	23.0507	1.6374	0.036612737916272974	1173.4930667866352	0.0359584148672477	1216.4578608874579
55.9701	0.9250904479068243	23.0453	1.64837	0.03700361791627297	1173.2181570198754	0.036335418070882856	1216.631473434673
56.3801	0.9352454479068243	23.0738	1.66146	0.03740981791627297	1174.669069677774	0.0367270468543984	1218.6132256862973
56.8001	0.9456274479068243	23.064	1.67307	0.03782509791627297	1174.1701593603211	0.03712727142885492	1218.583260608491
57.2201	0.9559734479068243	23.091	1.68567	0.03823893791627297	1175.5447081941195	0.037525948924672606	1220.4962893085576
57.6101	0.9662574479068242	23.0907	1.69811	0.03865029791627297	1175.5294354292994	0.037922079828798076	1220.96399831799
58.0201	0.9760254479068242	23.1028	1.70992	0.03904101791627297	1176.1454369437056	0.03829818960182206	1222.0633520195674
58.4301	0.9875354479068242	23.1303	1.72388	0.03950141791627297	1177.5454403855374	0.03874119235181886	1224.060154941608
58.8301	0.9975964479068242	23.1403	1.73558	0.03990385791627297	1178.0545325462035	0.039128264568766565	1225.0634532305485
59.2401	1.007544447906824	23.1268	1.74722	0.040301777916272964	1177.3672581293042	0.03951084213513699	1224.8172518923225
59.6501	1.0179344479068242	23.1496	1.75967	0.040717377916272966	1178.5279882556229	0.039910261817902165	1226.514557738332
60.0601	1.028484447906824	23.1609	1.77219	0.04113937791627296	1179.1032623971757	0.04031566915882268	1227.6108371112434
60.4801	1.0388744479068241	23.1515	1.78471	0.04155497791627297	1178.6247157661496	0.040714767571273326	1227.6024398013853
60.8901	1.049474447906824	23.1568	1.79697	0.04197897791627296	1178.8945346113026	0.04112176838320251	1228.3833222453652
61.3001	1.059644447906824	23.1674	1.80914	0.04238577791627297	1179.4341723016087	0.04151210314013685	1229.425407195648
61.7001	1.0700344479068242	23.1747	1.82124	0.04280137791627297	1179.805809578895	0.04191072443831689	1230.3031239024956
62.1201	1.0810044479068242	23.1864	1.83452	0.043240177916272965	1180.4014474068742	0.04233142555545907	1231.4422160053737
62.5401	1.092034447906824	23.1858	1.84666	0.04368137791627296	1180.3709018772342	0.04275424931262435	1231.9311293235057
62.9601	1.1030744479068242	23.2094	1.85996	0.04412297791627297	1181.5723593764062	0.04317727746212681	1233.70685049565
63.3901	1.114404447906824	23.1988	1.87286	0.04457617791627296	1181.0327216861003	0.04361123177847388	1233.67864641292
63.7901	1.1247044479068242	23.2178	1.88509	0.04498817791627297	1181.999996791366	0.04400557235400013	1235.1760229440501
64.2001	1.134784447906824	23.2131	1.89652	0.045391377916272964	1181.760723475853	0.04439133962183917	1235.4024710817534
64.6201	1.1455444479068242	23.2259	1.90907	0.04582177791627297	1182.4123614415053	0.04480296672439147	1236.592598072934
65.0301	1.156334447906824	23.2125	1.92124	0.04625337791627296	1181.730177946213	0.04521557141014548	1236.3891904618238
65.4501	1.1673944479068241	23.2226	1.93513	0.04669577791627297	1182.2443610284856	0.045638324161071886	1237.4501811538378
65.8601	1.177764447906824	23.2426	1.94659	0.04711057791627296	1183.2625453498179	0.046034540367285236	1239.006727687928
66.2801	1.1887644479068242	23.228	1.959	0.04755057791627297	1182.5192707952453	0.04645465605544453	1238.748745518689
66.6801	1.1996344479068242	23.2471	1.9714	0.04798537791627297	1183.4916368221175	0.046869633431546584	1240.2819302757753
67.0901	1.210764447906824	23.245	1.98442	0.04843057791627296	1183.3847274683778	0.04729435831064707	1240.6967337169626
67.4901	1.2214544479068241	23.2595	1.99609	0.04885817791627296	1184.1229111013436	0.04770212286355905	1241.976998966668
67.8901	1.231924447906824	23.2582	2.00839	0.04927697791627297	1184.0567291204568	0.048101334520060636	1242.40346641294
68.3001	1.242054447906824	23.2465	2.01924	0.04968217791627296	1183.4610912924777	0.048487430651476766	1242.2580157870573
68.7001	1.253064447906824	23.2698	2.03184	0.05012257791627296	1184.6472760268296	0.048906898228387626	1244.0248514227849
69.1301	1.2642144479068242	23.2601	2.04417	0.05056857791627297	1184.1534566309838	0.04933152038711184	1244.0344129674518
69.5401	1.275104447906824	23.2795	2.05652	0.051004177916272965	1185.1410954226758	0.04974606706890437	1245.5882427095005
69.9401	1.2858544479068241	23.2703	2.06848	0.051434177916272965	1184.672730634863	0.05015511592858002	1245.6053986348936
70.3401	1.2967444479068242	23.2664	2.07975	0.051869777916272966	1184.4741846922034	0.05056932140280051	1245.9125975997463
70.7501	1.3080044479068242	23.2712	2.09211	0.05232017791627297	1184.7185489293229	0.05099741964139373	1246.7032341900137
71.1501	1.3185344479068242	23.2636	2.10401	0.052741377916272966	1184.3316388872165	0.05139759796820216	1246.794921431966
71.5601	1.329604447906824	23.2814	2.11632	0.053184177916272966	1185.2378229332026	0.051818125659980466	1248.273722181178
71.9601	1.3399644479068242	23.2756	2.12786	0.05359857791627297	1184.9425494800162	0.052211521708241324	1248.453785044628
72.3701	1.3510044479068242	23.2793	2.14042	0.05404017791627297	1185.1309135794625	0.0526305688577968	1249.1755990033716
72.7801	1.3622544479068242	23.279	2.15253	0.05449017791627297	1185.1156408146426	0.053057406446914195	1249.6928029339904
73.1801	1.373794447906824	23.2761	2.16495	0.05495177791627296	1184.9680040880492	0.05349505774714693	1250.0841026865849
73.5901	1.3844244479068242	23.2687	2.17665	0.05537697791627297	1184.5912758891563	0.053898028141763116	1250.1903608138798
74.0601	1.3977444479068242	23.2714	2.19095	0.05590977791627297	1184.7287307725364	0.05440274405478487	1250.9666510010568
74.5001	1.4093744479068242	23.2711	2.20406	0.05637497791627297	1184.7134580077163	0.054843214977312545	1251.5016530400128
74.9001	1.421254447906824	23.2946	2.21677	0.05685017791627296	1185.9098245852815	nan	nan
75.3101	1.431894447906824	23.2682	2.22786	0.05727577791627296	1184.5658212811231	nan	nan
75.7201	1.4437344479068241	23.2637	2.24035	0.057749377916272965	1184.3367298088233	nan	nan
76.1401	1.454974447906824	23.2518	2.25286	0.05819897791627296	1183.7309101376306	nan	nan
76.5401	1.4665144479068242	23.2753	2.26531	0.058660577916272966	1184.9272767151963	nan	nan
76.9501	1.4771144479068241	23.256	2.27626	0.059084577916272966	1183.9447288451104	nan	nan
77.3501	1.4884144479068242	23.281	2.28808	0.05953657791627297	1185.2174592467757	nan	nan
77.7601	1.5006444479068242	23.2687	2.30122	0.06002577791627297	1184.5912758891563	nan	nan
78.1701	1.512554447906824	23.2707	2.31369	0.060502177916272964	1184.6930943212897	nan	nan
78.6001	1.5258044479068242	23.2712	2.32646	0.06103217791627297	1184.7185489293229	nan	nan
79.0201	1.537744447906824	23.247	2.33857	0.06150977791627296	1183.486545900511	nan	nan
79.4401	1.5500044479068242	23.2435	2.35103	0.06200017791627297	1183.3083636442777	nan	nan
79.8501	1.5618644479068242	23.2445	2.36333	0.06247457791627297	1183.3592728603444	nan	nan
80.2601	1.5737244479068242	23.2232	2.375	0.06294897791627296	1182.2749065581254	nan	nan
80.6801	1.5858944479068242	23.2162	2.3877	0.06343577791627297	1181.9185420456595	nan	nan
81.1001	1.5982644479068242	23.2175	2.40059	0.06393057791627296	1181.984724026546	nan	nan
81.5001	1.610374447906824	23.2078	2.41214	0.06441497791627296	1181.4909046306998	nan	nan
81.9301	1.6231144479068242	23.1993	2.42516	0.06492457791627297	1181.0581762941335	nan	nan
82.3501	1.6358544479068242	23.1926	2.43731	0.06543417791627297	1180.7170845464873	nan	nan
82.7601	1.6485944479068242	23.1924	2.45037	0.06594377791627297	1180.706902703274	nan	nan
83.1801	1.6612044479068242	23.174	2.46256	0.06644817791627297	1179.7701731276484	nan	nan
83.5901	1.673084447906824	23.167	2.47514	0.06692337791627297	1179.413808615182	nan	nan
84.0101	1.6858044479068242	23.1609	2.48775	0.06743217791627297	1179.1032623971757	nan	nan
84.4201	1.6988844479068241	23.1483	2.50058	0.06795537791627297	1178.4618062747363	nan	nan
84.8301	1.7107944479068242	23.1094	2.51189	0.06843177791627297	1176.4814377697453	nan	nan
85.2501	1.7237644479068241	23.1142	2.52429	0.06895057791627296	1176.725802006865	nan	nan
85.6501	1.736434447906824	23.1075	2.53641	0.06945737791627296	1176.3847102592188	nan	nan
86.0801	1.749074447906824	23.067	2.54846	0.06996297791627297	1174.3228870085209	nan	nan
86.4801	1.762354447906824	23.055	2.56148	0.07049417791627297	1173.7119764157217	nan	nan
86.8901	1.7750544479068242	23.0347	2.57394	0.07100217791627297	1172.6785193295693	nan	nan
87.3001	1.7880344479068242	23.0088	2.58714	0.07152137791627297	1171.3599706334442	nan	nan
87.7101	1.800144447906824	22.9946	2.59823	0.07200577791627297	1170.6370597652983	nan	nan
88.1201	1.8129444479068242	22.9607	2.6105	0.07251777791627297	1168.9112373406401	nan	nan
88.5301	1.825904447906824	22.9566	2.62306	0.07303617791627297	1168.7025095547672	nan	nan
88.9401	1.8388044479068242	22.9189	2.63522	0.07355217791627297	1166.783232109056	nan	nan
89.3501	1.8515744479068241	22.9046	2.64726	0.07406297791627296	1166.0552303193033	nan	nan
89.7601	1.865154447906824	22.8836	2.65992	0.07460617791627296	1164.9861367819046	nan	nan
90.1801	1.8780144479068241	22.8443	2.67281	0.07512057791627297	1162.9854045904865	nan	nan
90.5901	1.891214447906824	22.8064	2.68444	0.07564857791627295	1161.0559453015621	nan	nan
91.0101	1.9040844479068242	22.7854	2.69712	0.07616337791627296	1159.986851764163	nan	nan
91.4201	1.9173044479068242	22.7616	2.70979	0.07669217791627297	1158.775212421778	nan	nan
91.8301	1.9300044479068241	22.7206	2.72125	0.07720017791627297	1156.6879345630468	nan	nan
92.2501	1.9432044479068242	22.6942	2.73397	0.07772817791627297	1155.3439312588882	nan	nan
92.6501	1.9558344479068241	22.6772	2.74635	0.07823337791627297	1154.478474585756	nan	nan
93.0601	1.969414447906824	22.6376	2.75858	0.07877657791627296	1152.462469629518	nan	nan
93.4701	1.9821344479068241	22.6138	2.77035	0.07928537791627296	1151.2508302871329	nan	nan
93.8701	1.995004447906824	22.5716	2.78248	0.07980017791627296	1149.1024613691216	nan	nan
94.2701	2.0075744479068245	22.5411	2.79443	0.08030297791627299	1147.54973027909	nan	nan
94.6801	2.021014447906824	22.502	2.80712	0.08084057791627297	1145.5591799308856	nan	nan
95.0801	2.0337044479068243	22.4695	2.81872	0.08134817791627297	1143.9046304087208	nan	nan
95.5101	2.0468544479068242	22.4246	2.83139	0.08187417791627297	1141.61880660733	nan	nan
95.9201	2.0602944479068244	22.4018	2.84492	0.08241177791627298	1140.4580764810114	nan	nan
96.3201	2.0727144479068245	22.3549	2.8561	0.08290857791627299	1138.0704342474871	nan	nan
96.7201	2.0855744479068243	22.3304	2.8683	0.08342297791627297	1136.8231584538553	nan	nan
97.1301	2.098564447906824	22.3002	2.8802	0.08394257791627296	1135.2857001286434	nan	nan
97.5301	2.111314447906824	22.2593	2.89184	0.08445257791627298	1133.203513191519	nan	nan
97.9501	2.1251044479068244	22.2282	2.90527	0.08500417791627297	1131.6202365718475	nan	nan
98.3801	2.1389444479068245	22.1757	2.91767	0.08555777791627298	1128.9475027283504	nan	nan
98.8001	2.1523644479068245	22.1578	2.93106	0.08609457791627298	1128.0362277607583	nan	nan
99.2001	2.1651744479068245	22.1176	2.94314	0.08660697791627298	1125.9896772748803	nan	nan
99.6201	2.1785244479068244	22.0557	2.95544	0.08714097791627298	1122.838396800357	nan	nan
100.04	2.1910144479068245	22.033	2.96748	0.08764057791627299	1121.682757595645	nan	nan
100.44	2.2046744479068243	21.9955	2.98051	0.08818697791627297	1119.773661993147	nan	nan
100.86	2.2181244479068245	21.9698	2.99251	0.08872497791627298	1118.465295140235	nan	nan
101.27	2.231024447906824	21.9212	3.00486	0.08924097791627297	1115.9911072393977	nan	nan
101.67	2.243634447906824	21.8934	3.01675	0.08974537791627296	1114.575831032746	nan	nan
102.07	2.2564944479068245	21.848	3.02844	0.09025977791627299	1112.2645526233218	nan	nan
102.48	2.269934447906824	21.802	3.04087	0.09079737791627297	1109.9227286842577	nan	nan
102.89	2.2824944479068243	21.777	3.05281	0.09129977791627297	1108.6499982825924	nan	nan
103.3	2.2961144479068243	21.7433	3.06606	0.09184457791627297	1106.9343577011477	nan	nan
103.71	2.3087844479068242	21.6922	3.07758	0.09235137791627297	1104.332896760144	nan	nan
104.12	2.3222344479068244	21.6539	3.09004	0.09288937791627298	1102.3830737847927	nan	nan
104.54	2.3359144479068243	21.6326	3.10329	0.09343657791627297	1101.2987074825737	nan	nan
104.95	2.3488844479068245	21.5682	3.11443	0.09395537791627298	1098.020153967884	nan	nan
105.37	2.3626544479068246	21.5414	3.12774	0.09450617791627298	1096.6557869772987	nan	nan
105.77	2.375544447906824	21.4976	3.13885	0.09502177791627296	1094.4259633135812	nan	nan
106.18	2.388764447906824	21.4557	3.1519	0.09555057791627297	1092.2928671603904	nan	nan
106.59	2.4011844479068243	21.4194	3.16393	0.09604737791627298	1090.4448626171722	nan	nan
106.99	2.4142144479068244	21.3766	3.17627	0.09656857791627298	1088.2659481695212	nan	nan
107.41	2.4279344479068246	21.3515	3.18903	0.09711737791627298	1086.9881268462493	nan	nan
107.81	2.440624447906824	21.2976	3.20091	0.09762497791627296	1084.244120100259	nan	nan
108.23	2.4542144479068244	21.2654	3.21383	0.09816857791627298	1082.6048433429141	nan	nan
108.66	2.468204447906824	21.2008	3.22626	0.09872817791627296	1079.316107985011	nan	nan
109.07	2.4813044479068243	21.1884	3.23908	0.09925217791627297	1078.6848337057852	nan	nan
109.47	2.4942044479068244	21.1331	3.25143	0.09976817791627297	1075.8695540573015	nan	nan
109.88	2.507724447906824	21.0917	3.26324	0.10030897791627297	1073.761912512144	nan	nan
110.3	2.5212744479068245	21.0584	3.27577	0.10085097791627298	1072.0666356171255	nan	nan
110.71	2.5337944479068244	21.0147	3.28803	0.10135177791627298	1069.8419028750147	nan	nan
111.13	2.5473044479068245	20.9635	3.30117	0.10189217791627297	1067.2353510124042	nan	nan
111.53	2.5603044479068244	20.9297	3.31297	0.10241217791627298	1065.5146195093528	nan	nan
111.95	2.5738744479068245	20.8871	3.32578	0.10295497791627298	1063.345886904915	nan	nan
112.35	2.5866944479068246	20.8288	3.33766	0.10346777791627298	1060.3778796082318	nan	nan
112.76	2.6002144479068243	20.8174	3.35083	0.10400857791627298	1059.7975145450723	nan	nan
113.16	2.6130944479068243	20.7582	3.3624	0.10452377791627297	1056.7836889539287	nan	nan
113.58	2.6270244479068245	20.6957	3.37507	0.10508097791627298	1053.6018629497655	nan	nan
113.99	2.6402344479068245	20.6543	3.38757	0.10560937791627298	1051.494221404608	nan	nan
114.41	2.653674447906824	20.6211	3.40037	0.10614697791627296	1049.8040354311966	nan	nan
114.83	2.6670044479068244	20.5678	3.41256	0.10668017791627298	1047.0905742148461	nan	nan
115.26	2.680654447906824	20.5301	3.42545	0.10722617791627297	1045.171296769135	nan	nan
115.67	2.6941044479068244	20.4812	3.43778	0.10776417791627298	1042.6818361034777	nan	nan
116.07	2.7069244479068244	20.4554	3.45	0.10827697791627297	1041.3683783289591	nan	nan
116.49	2.7209744479068245	20.3868	3.46266	0.10883897791627298	1037.8760061067894	nan	nan
116.9	2.7336544479068245	20.3549	3.47442	0.10934617791627298	1036.2520021142648	nan	nan
117.32	2.747094447906824	20.3043	3.4872	0.10988377791627296	1033.6759957812942	nan	nan
117.75	2.760784447906824	20.2566	3.49953	0.11043137791627297	1031.2476261749166	nan	nan
118.14	2.7734444479068245	20.2041	3.51125	0.11093777791627298	1028.5748923314197	nan	nan
118.56	2.7874544479068244	20.1654	3.52481	0.11149817791627298	1026.6047056696418	nan	nan
118.97	2.8008244479068245	20.1088	3.53703	0.11203297791627298	1023.7232440402717	nan	nan
119.37	2.813864447906824	20.072	3.54954	0.11255457791627296	1021.8497848890204	nan	nan
119.8	2.827484447906824	20.012	3.56149	0.11309937791627296	1018.7952319250237	nan	nan
120.21	2.841454447906824	19.984	3.57513	0.11365817791627297	1017.3697738751586	nan	nan
120.63	2.854324447906824	19.921	3.58689	0.11417297791627297	1014.162493262962	nan	nan
121.04	2.8678344479068243	19.8714	3.59927	0.11471337791627297	1011.6373961460582	nan	nan
121.45	2.881504447906824	19.8228	3.61185	0.11526017791627297	1009.1632082452207	nan	nan
121.87	2.8949744479068245	19.7854	3.62433	0.11579897791627297	1007.2592035643295	nan	nan
122.28	2.9076944479068243	19.719	3.63614	0.11630777791627298	1003.8788316175065	nan	nan
122.69	2.9214744479068244	19.6873	3.64941	0.11685897791627298	1002.265009468195	nan	nan
123.09	2.9348244479068244	19.632	3.66184	0.11739297791627297	999.4497298197114	nan	nan
123.52	2.948214447906824	19.572	3.67336	0.11792857791627297	996.3951768557147	nan	nan
123.91	2.961224447906824	19.5274	3.68578	0.11844897791627297	994.124625819144	nan	nan
124.33	2.9751344479068242	19.4804	3.69914	0.11900537791627297	991.731892664013	nan	nan
124.76	2.988684447906824	19.4192	3.71157	0.11954737791627297	988.6162486407366	nan	nan
125.15	3.0014744479068245	19.3621	3.72315	0.12005897791627299	985.7093324033332	nan	nan
125.58	3.0152944479068244	19.336	3.73601	0.12061177791627298	984.3806018639945	nan	nan
125.98	3.0287244479068245	19.263	3.74827	0.12114897791627298	980.6642290911319	nan	nan
126.39	3.0422444479068242	19.2087	3.75985	0.12168977791627297	977.899858658715	nan	nan
126.82	3.0559044479068245	19.1593	3.77285	0.12223617791627298	975.3849433850245	nan	nan
127.22	3.0689544479068243	19.1048	3.78469	0.12275817791627297	972.610391109394	nan	nan
127.64	3.0822844479068245	19.0391	3.7974	0.12329137791627298	969.2656556138177	nan	nan
128.05	3.096264447906824	19.0019	3.8107	0.12385057791627296	967.3718327761395	nan	nan
128.46	3.1097644479068243	18.9443	3.82228	0.12439057791627298	964.4394619307028	nan	nan
128.87	3.1230844479068245	18.8738	3.83451	0.12492337791627298	960.8503621980068	nan	nan
129.29	3.1369244479068246	18.8313	3.84711	0.125476977916273	958.6867205151758	nan	nan
129.71	3.1510844479068245	18.773	3.85986	0.126043377916273	955.7187132184923	nan	nan
130.11	3.1638944479068245	18.7146	3.8716	0.12655577791627298	952.7456150002024	nan	nan
130.53	3.177534447906824	18.6539	3.88458	0.12710137791627296	949.6554255849591	nan	nan
130.93	3.1910044479068245	18.6127	3.89665	0.12764017791627297	947.5579658830146	nan	nan
131.36	3.2048344479068245	18.5375	3.90927	0.12819337791627297	943.7295928348054	nan	nan
131.79	3.2189744479068243	18.4818	3.92213	0.12875897791627297	940.8939494998951	nan	nan
132.2	3.2320044479068244	18.4326	3.93442	0.12928017791627297	938.389216069418	nan	nan
132.62	3.246204447906824	18.3641	3.94748	0.12984817791627296	934.9019347688552	nan	nan
133.03	3.2593644479068242	18.2927	3.95939	0.13037457791627297	931.2670167416991	nan	nan
133.43	3.2733144479068246	18.2654	3.97199	0.130932577916273	929.8771951430806	nan	nan
133.84	3.2861444479068243	18.181	3.9837	0.13144577791627296	925.5804573070585	nan	nan
134.25	3.2999244479068244	18.1206	3.99606	0.13199697791627296	922.5055406566352	nan	nan
134.65	3.3131644479068245	18.0515	4.00759	0.13252657791627298	918.9877138264324	nan	nan
135.06	3.3267544479068243	18.0096	4.02037	0.13307017791627296	916.8546176732413	nan	nan
135.46	3.3399344479068245	17.953	4.03243	0.133597377916273	913.9731560438712	nan	nan
135.87	3.354124447906824	17.8887	4.04592	0.13416497791627296	910.6996934507881	nan	nan
136.27	3.3669244479068245	17.8046	4.05717	0.13467697791627298	906.4182283795861	nan	nan
136.69	3.3804444479068243	17.7346	4.06951	0.13521777791627299	902.8545832549232	nan	nan
137.1	3.3942444479068246	17.6935	4.08215	0.13576977791627298	900.7622144745856	nan	nan
137.52	3.4082544479068244	17.5953	4.0947	0.13633017791627297	895.7629294568445	nan	nan
137.73	3.4165244479068244	17.5518	4.10134	0.13666097791627296	893.5483785579468	nan	nan