File: original_data/46NTBR.csv
Specimen name:	AWA_5_04_Rz
Specimen ID:	46NTBR
Material:	42CrMoS4
Specimen type:	Round Tensile Specimen
Gauge diameter:	5.015	mm
Gauge length:	25	mm
Parallel length:	30	mm
Original cross-section:	19.752940524032585	mm²
Cross-section after fracture:	10.676678285881847	mm²
Yield stress at 0.2% plastic strain:	1081.825547631855	MPa
Yield stress at 1% plastic strain:	1135.5117776508364	MPa
Ultimate tensile strength:	1187.9041488254163	MPa
Uniform elongation:	5.0401322581752765	%
Elongation after fracture:	12.998166824873492	%
Reduction of area:	45.94891695799937	%
Slope of linear-elastic region:	214032.602123553	MPa
Crosshead seperation speed:	0.02993803847221003	mm/s
Strain rate:	0.0009979346157403344	s-1
Test temperature:	RT	Cel
Machine type:	INSTRON 8852TT
Standard:	DIN EN ISO 6892-1
Date:	2022-09-13 00:00:00
Heat treatment batch:	Batch 5
Time	Displacement	Force	Machine Displacement	Engineering Strain	Engineering Stress	True Strain	True Stress
s	mm	kN	mm		MPa		MPa
0	0.0010822077699407572	0.179565	0	4.3288310797630283e-05	9.09054526750236	4.328737388580784e-05	9.09093878185122
0.440001	0.001100772169940757	0.180602	-1.5258e-05	4.403088679763028e-05	9.143043780254844	4.402991746667652e-05	9.143446356580519
0.880001	0.0008804097699407572	0.176128	-0.000236511	3.521639079763029e-05	8.916545857347788	3.521577071519968e-05	8.916859865911267
1.28	0.0014603347699407572	0.24678	0.00410462	5.8413390797630284e-05	12.493329775369546	5.841168480202967e-05	12.494059553124078
1.69	0.002733787769940757	0.477106	0.0167847	0.00010935151079763028	24.153669648299953	0.0001093455323570907	24.156310888567305
2.11	0.0040841677699407575	0.703048	0.0287323	0.0001633667107976303	35.59206788197588	0.00016335336790971203	35.59788244103624
2.54	0.005405037769940757	0.959791	0.0412521	0.00021620151079763028	48.589778257685836	0.0002161781426190586	48.60028344115447
2.95	0.006947447769940757	1.24406	0.0540085	0.0002778979107976303	62.981002675849886	0.0002778593043254356	62.998504964913444
3.36	0.008648267769940758	1.53804	0.0656662	0.0003459307107976303	77.86385010012714	0.00034587089056461816	77.89078559713771
3.77001	0.010414157769940757	1.85138	0.0774536	0.0004165663107976303	93.72680476344789	0.0004164795711396259	93.76584819273104
4.17001	0.012190507769940757	2.17378	0.0899811	0.0004876203107976303	110.0484253144615	0.0004875014626473814	110.10208716181612
4.59001	0.014057407769940756	2.49883	0.102142	0.0005622963107976303	126.50420310635658	0.0005621382814638251	126.57533595306369
4.99001	0.01588700776994076	2.83466	0.113403	0.0006354803107976304	143.5057224290827	0.0006352784786871762	143.59691749017315
5.41001	0.018177807769940758	3.21775	0.126366	0.0007271123107976303	162.8997969231516	0.0007268480927111631	163.01824337092086
5.82001	0.020212607769940757	3.56397	0.137726	0.0008085043107976303	180.42731388088092	0.0008081776472481535	180.57319014193925
6.24001	0.022267107769940758	3.93175	0.150467	0.0008906843107976303	199.04631390027234	0.0008902878869017893	199.2236013291854
6.64001	0.024464407769940757	4.32879	0.16362	0.0009785763107976304	219.14661236049085	0.0009780978171359121	219.3610640439384
7.05001	0.02657250776994076	4.68579	0.174751	0.0010629003107976303	237.21987084905123	0.0010623358322164713	237.47201192350406
7.47001	0.02884910776994076	5.09477	0.187691	0.0011539643107976304	257.92463627384507	0.0011532990057586449	258.22227209898057
7.87001	0.031218807769940758	5.50362	0.200287	0.0012487523107976304	278.6228204000297	0.0012479732681174988	278.97075129084516
8.29001	0.03357570776994076	5.9058	0.212372	0.0013430283107976305	298.9833332821844	0.0013421272549478927	299.384876363239
8.71001	0.03607030776994076	6.3334	0.225327	0.0014428123107976304	320.63074316932284	0.0014417724572044631	321.09335315278776
9.10001	0.03846210776994076	6.74584	0.237579	0.0015384843107976304	341.51067238787135	0.0015373020562418312	342.03608119931005
9.51001	0.040567607769940756	7.12021	0.248596	0.0016227043107976302	360.4632936213793	0.0016213891487114544	361.04821896182307
9.92001	0.04318230776994076	7.55284	0.261917	0.0017272923107976303	382.365349139323	0.0017258022570263265	383.02580586680676
10.34	0.045776207769940756	7.99199	0.27446	0.0018310483107976303	404.59748209520893	0.001829373985375082	405.33831963135236
10.76	0.04818690776994076	8.39855	0.286186	0.0019274763107976303	425.1797341151223	0.0019256211118521911	425.99925798046047
11.16	0.05060580776994076	8.81654	0.298485	0.00202423231079763	446.3406341589132	0.002022186313158135	447.2441312921996
11.58	0.053250607769940755	9.2413	0.31163	0.00213002431079763	467.8442679841259	0.002127759025187218	468.84078764859936
12	0.05580950776994076	9.68064	0.323914	0.00223238031079763	490.0860197610562	0.00222989225204573	491.18007814216793
12.41	0.058252407769940756	10.0886	0.335899	0.00233009631079763	510.73914730445415	0.0023273858460017313	511.92921870736825
12.83	0.06091820776994076	10.5138	0.34816	0.0024367283107976302	532.2650562941905	0.002433764302379583	533.5620416257108
13.25	0.06335950776994076	10.9412	0.361519	0.0025343803107976304	553.9023411065455	0.002531174184903381	555.3061402939505
13.66	0.06582420776994075	11.3623	0.373672	0.0026329683107976297	575.2206860632198	0.0026295081221155456	576.7352239013395
14.06	0.06841550776994075	11.7739	0.385597	0.00273662031079763	596.0580899676776	0.002732882583043224	597.6892746430984
14.48	0.07065930776994075	12.1692	0.397552	0.00282637231079763	616.0703002772797	0.0028223856307060917	617.811544315488
14.89	0.07330130776994075	12.5917	0.41082	0.00293205231079763	637.4595207574386	0.0029277622292043248	639.3285854183154
15.31	0.07567140776994075	12.9901	0.423042	0.00302685631079763	657.628669726185	0.0030222846041772786	659.6192172153071
15.72	0.07818300776994075	13.4041	0.43499	0.00312732031079763	678.5875745280449	0.0031224404159834592	680.7097352325213
16.13	0.08077250776994076	13.7996	0.447281	0.0032309003107976303	698.6099099124305	0.003225692167368038	700.8670488874927
16.55	0.08311860776994075	14.2178	0.459915	0.00332474431079763	719.781441284744	0.0033192295684562885	722.1745305366732
16.97	0.08580300776994075	14.6466	0.471855	0.00343212031079763	741.4896016205834	0.0034262440274528687	744.0344831425506
17.38	0.08857410776994075	15.0615	0.484535	0.00354296431079763	762.4940692589691	0.0035367027979298768	765.1955585335485
17.78	0.09055000776994075	15.4271	0.496155	0.00362200031079763	781.0027059632203	0.0036154566636399455	783.8314980069529
18.2	0.09309450776994076	15.8423	0.508354	0.00372378031079763	802.0223612137812	0.0037168642049512936	805.0089162912885
18.61	0.09562760776994075	16.2583	0.521477	0.00382510431079763	823.0825167634763	0.00381780720151995	826.2308932464904
19.01	0.09790310776994075	16.6259	0.533134	0.00391612431079763	841.6924042155626	0.0039084762566401745	844.9885763019249
19.42	0.10032180776994075	17.0287	0.54631	0.00401287231079763	862.0843048295461	0.00400484221403975	865.5437390659699
19.83	0.10281820776994074	17.4243	0.558228	0.00411272831079763	882.1117027513233	0.0041042941607220065	885.7395885245145
20.25	0.10525220776994075	17.8284	0.570648	0.00421008831079763	902.5694163513995	0.00420125068511194	906.369313300864
20.66	0.10791820776994075	18.2455	0.583794	0.00431672831079763	923.685259812404	0.0043074379654785755	927.6725581237026
21.08	0.11015320776994075	18.6124	0.595604	0.00440612831079763	942.2597095027479	0.004396449747033551	946.4114266849119
21.48	0.11264920776994075	19.0007	0.607674	0.00450596831079763	961.917542194927	0.004495846828916778	966.2519121576576
21.88	0.11530720776994074	19.3882	0.619873	0.00461228831079763	981.5348745879724	0.004601684302394563	986.0619964166748
22.28	0.11792020776994075	19.7419	0.632584	0.00471680831079763	999.4410693426049	0.004705719027487468	1004.1552412846326
22.7	0.12108820776994075	20.0971	0.645348	0.00484352831079763	1017.4232021581138	0.004831836166504189	1022.3511202418291
23.11	0.12482920776994075	20.3769	0.656761	0.00499316831079763	1031.5881817802401	0.004980743787235643	1036.7390751992984
23.53	0.13033320776994076	20.6086	0.669434	0.00521332831079763	1043.3180809169332	0.005199785961510071	1048.7572406053446
23.95	0.13735920776994076	20.7841	0.682289	0.00549436831079763	1052.2028340394609	0.0054793293305460625	1057.9840239473385
24.34	0.14495720776994075	20.9061	0.694458	0.00579828831079763	1058.3791296574002	0.005781542935625082	1064.515916993285
24.77	0.15337020776994076	21.0639	0.70742	0.00613480831079763	1066.3678136615877	0.0061160669848624736	1072.909775787206
25.18	0.16096620776994075	21.1729	0.719879	0.00643864831079763	1071.8859794185987	0.0064180087612569405	1078.78747626935
25.59	0.16873920776994075	21.285	0.732399	0.00674956831079763	1077.5610838347548	0.0067268919544973636	1084.8341559791545
26	0.17684420776994075	21.3822	0.744545	0.00707376831079763	1082.4818701795393	0.007048866575513049	1090.1390961298282
26.4	0.18477420776994075	21.4752	0.755943	0.00739096831079763	1087.1900299538702	0.0073637889435794555	1095.2254170130743
26.83	0.19353620776994074	21.5805	0.769684	0.0077414483107976296	1092.5208818273866	0.007711637055835607	1100.9785757625202
27.24	0.20232220776994075	21.6513	0.781349	0.00809288831079763	1096.1051583007481	0.008060316505506622	1104.9758149237653
27.65	0.21057520776994076	21.7296	0.793777	0.00842300831079763	1100.0691250784914	0.00838773272226175	1109.3350164614794
28.06	0.21990120776994077	21.8	0.806282	0.008796048310797631	1103.6331514022859	0.008757588443213686	1113.3407619194181
28.49	0.22914020776994076	21.8653	0.818848	0.009165608310797631	1106.938988319101	0.009123859034053551	1117.0847575099845
28.91	0.23863020776994076	21.9201	0.831261	0.00954520831079763	1109.713258809782	0.009499940641531585	1120.3057030303755
29.33	0.24797720776994076	21.977	0.843849	0.00991908831079763	1112.5938425856896	0.009870217060775175	1123.6297591643468
29.73	0.2572422077699408	22.029	0.855827	0.01028968831079763	1115.2263620294016	0.010237109837844564	1126.701693690669
30.14	0.2671342077699408	22.0612	0.86853	0.010685368310797631	1116.8564990695463	0.010628683206114875	1128.7905221124124
30.56	0.27651520776994076	22.1076	0.880363	0.01106060831079763	1119.20551641932	0.010999887114664942	1131.584610255718
30.96	0.2857122077699408	22.1325	0.892334	0.011428488310797631	1120.4660882298665	0.011363676471721736	1133.2713218218466
31.36	0.29495120776994077	22.1745	0.90406	0.011798048310797631	1122.592353934403	0.011728993945984518	1135.836752759453
31.79	0.30507820776994077	22.2215	0.916641	0.012203128310797631	1124.9717465085273	0.01212927039847636	1138.699921077193
32.2	0.31517820776994077	22.2458	0.929443	0.012607128310797631	1126.2019430947232	0.012528320140584075	1140.400115495188
32.61	0.3249912077699408	22.2722	0.940887	0.012999648310797631	1127.5384529661462	0.012915878090570659	1142.196056311607
33.03	0.3351142077699408	22.3159	0.954063	0.013404568310797631	1129.7507818063425	0.013315521954384202	1144.8946033352427
33.43	0.3448692077699408	22.3434	0.965874	0.013794768310797631	1131.1429795890747	0.013700486568144571	1146.7468349188914
33.84	0.3552332077699408	22.373	0.978783	0.014209328310797631	1132.641490657034	0.014109322039892186	1148.735565456211
34.26	0.36538320776994077	22.3979	0.991074	0.014615328310797631	1133.9020624675807	0.014509553774157294	1150.474413382835
34.66	0.37504520776994077	22.4071	1.00297	0.01500180831079763	1134.367815907622	0.01489039407915641	1151.3853844358061
35.06	0.3846712077699408	22.4411	1.01472	0.015386848310797632	1136.089078620818	0.015269671222337891	1153.5699089411105
35.47	0.3943582077699408	22.4502	1.02629	0.01577432831079763	1136.5497695234676	0.015651206680144157	1154.4780787294922
35.8901	0.4048572077699408	22.4778	1.03925	0.016194288310797632	1137.9470298435917	0.01606455952678201	1156.3752721272947
36.3001	0.41507820776994075	22.5033	1.05128	0.01660312831079763	1139.2379768784888	0.016466803254730034	1158.1528911851358
36.7101	0.4249842077699408	22.5272	1.0631	0.01699936831079763	1140.447923315118	0.016856495936237496	1159.834817602836
37.1201	0.43543120776994076	22.5581	1.07601	0.01741724831079763	1142.0122473691697	0.017267306585799537	1161.9029582555706
37.5301	0.44522020776994076	22.564	1.08773	0.01780880831079763	1142.3109370752834	0.01765208940003007	1162.6541335849847
37.9401	0.4554742077699408	22.5756	1.09956	0.018218968310797633	1142.8981914127269	0.018054991570872717	1163.7206173445431
38.3501	0.4651342077699408	22.6004	1.1114	0.01860536831079763	1144.1537006858816	0.018434405738003368	1165.4411016913045
38.7401	0.4751742077699408	22.6291	1.12412	0.019006968310797633	1145.606648917315	0.018828592598754343	1167.3811581899254
39.1601	0.4851722077699408	22.6398	1.13605	0.01940688831079763	1146.1483404182325	0.01922097612169011	1168.391513248335
39.5501	0.4956082077699408	22.6717	1.14847	0.019824328310797633	1147.763289846202	0.019630385317104915	1170.5169261271944
39.9801	0.5060372077699408	22.6831	1.16064	0.02024148831079763	1148.3404191088619	0.020039352520432645	1171.58453827907
40.3901	0.5171162077699407	22.7081	1.17344	0.020684648310797627	1149.6060534568003	0.0204736259603313	1173.3852503685182
40.7901	0.5272032077699407	22.7171	1.18554	0.02108812831079763	1150.061681822058	0.020868851139030743	1174.3143301336531
41.1901	0.5371772077699407	22.7466	1.19662	0.02148708831079763	1151.5551303526256	0.021259495264962586	1176.2986971332646
41.6101	0.5477662077699407	22.7528	1.20941	0.02191064831079763	1151.869007670914	0.021674059692117612	1177.107204398099
42.0201	0.5576882077699408	22.7606	1.22077	0.02230752831079763	1152.263885587471	0.02206235484527247	1177.968044836723
42.4301	0.5683392077699407	22.7985	1.23382	0.02273356831079763	1154.1825872589454	0.022479011514781273	1180.42127594953
42.8701	0.5787372077699408	22.8073	1.24644	0.02314948831079763	1154.62809054942	0.02288560367495755	1181.3571400349124
43.2701	0.5894182077699407	22.8309	1.25842	0.02357672831079763	1155.8228493738739	0.023303089905148847	1183.0733706689737
43.6801	0.5996582077699407	22.8578	1.27068	0.02398632831079763	1157.1846719322555	0.023703175269200592	1184.9412833894453
44.0801	0.6095092077699408	22.846	1.28288	0.02438036831079763	1156.5872925200285	0.024087911074083982	1184.7853166952552
44.4801	0.6197392077699407	22.8801	1.29466	0.02478956831079763	1158.3136177706165	0.024487292304626304	1187.0277123236683
44.9101	0.6308302077699407	22.9053	1.30754	0.025233208310797627	1159.5893771933384	0.024920107014769675	1188.849537503046
45.3101	0.6409992077699407	22.9019	1.32003	0.025639968310797626	1159.4172509220189	0.025316777086786292	1189.1446724946516
45.7201	0.6510792077699408	22.9333	1.33156	0.02604316831079763	1161.0068876630294	0.025709820240471692	1191.243185448433
46.1501	0.6621992077699407	22.946	1.34477	0.026487968310797628	1161.649829911782	0.026143236327591534	1192.4195737947289
46.5601	0.6724162077699407	22.9614	1.35728	0.02689664831079763	1162.4294606701121	0.026541291326239013	1193.6949170598662
46.9601	0.6820262077699407	22.9725	1.36877	0.02728104831079763	1162.9914023205968	0.02691555301267378	1194.7190269523473
47.3901	0.6935172077699407	22.9876	1.38226	0.02774068831079763	1163.7558454667517	0.02736288648800751	1196.0392336457135
47.8101	0.7041132077699407	23.0003	1.39401	0.02816452831079763	1164.3987877155043	0.027775201221758774	1197.193530337176
48.2201	0.7143722077699407	23.0157	1.40656	0.028574888310797627	1165.1784184738344	0.028174240596537063	1198.4732616438762
48.6401	0.7249822077699407	23.0367	1.41941	0.02899928831079763	1166.2415513261026	0.028586765219795512	1200.0617263130403
49.0401	0.7349702077699407	23.0516	1.43168	0.02939880831079763	1166.995869397474	0.02897495058167727	1201.3041572613831
49.4501	0.7455122077699408	23.0578	1.44405	0.02982048831079763	1167.3097467157627	0.029384503859063372	1202.1194933727802
49.8601	0.7556442077699407	23.0834	1.45602	0.030225768310797627	1168.6057562880517	0.029777970757125523	1203.9277631242787
50.2701	0.7663762077699408	23.0872	1.46933	0.03065504831079763	1168.7981327089383	0.030194569332595234	1204.6276959327008
50.6801	0.7763392077699407	23.0934	1.48108	0.031053568310797627	1169.1120100272267	0.03058116130951215	1205.4171096935809
51.1001	0.7867312077699408	23.1091	1.49282	0.03146924831079763	1169.9068283977324	0.03098424049222789	1206.7229168810784
51.5101	0.7974582077699407	23.1212	1.50551	0.03189832831079763	1170.5193954221345	0.031400143127363334	1207.8570073914661
51.9301	0.8083562077699408	23.1393	1.51825	0.032334248310797634	1171.4357146900418	0.03182249864235426	1209.3132079689663
52.3301	0.8183902077699408	23.1422	1.52985	0.03273560831079763	1171.5825282744026	0.03221121188976998	1209.9349950237677
52.7401	0.8288692077699408	23.1595	1.54315	0.03315476831079763	1172.458347243176	0.032617003029992174	1211.330932100084
53.1401	0.8387452077699408	23.1769	1.55423	0.03354980831079763	1173.3392287493411	0.03299929279629926	1212.7045349574207
53.5501	0.8494252077699407	23.1856	1.56673	0.03397700831079763	1173.7796695024238	0.03341254016280979	1213.6611910881527
53.9501	0.8595842077699407	23.1937	1.57833	0.03438336831079763	1174.1897350311558	0.03380546976039973	1214.56233315749
54.3601	0.8700632077699407	23.2123	1.59044	0.03480252831079763	1175.131366986022	0.03421061461124925	1216.028909654459
54.7701	0.8804242077699407	23.2205	1.60255	0.035216968310797625	1175.5464950521457	0.034611035965940874	1216.9456787162665
55.1701	0.8910512077699407	23.2266	1.61469	0.035642048310797626	1175.8553098330428	0.03502157092033245	1217.7652015926199
55.5701	0.9010652077699407	23.2332	1.62679	0.03604260831079763	1176.1894373008984	0.035408270704695245	1218.582372488832
55.9901	0.9116682077699407	23.2457	1.64016	0.03646672831079763	1176.8222544748676	0.035817552340658046	1219.7371118989029
56.3901	0.9217152077699408	23.2536	1.65134	0.03686860831079763	1177.2221949288162	0.03620521756580001	1220.6247389284242
56.8101	0.9327602077699407	23.2703	1.66443	0.03731040831079763	1178.067638673239	0.03663121744637047	1222.0218232898746
57.2201	0.9429022077699407	23.2682	1.6765	0.037716088310797626	1177.9613253880123	0.03702222932581324	1222.3894187630508
57.6301	0.9540532077699407	23.2857	1.68909	0.03816212831079763	1178.847269431569	0.037451965524490774	1223.8345901864498
58.0501	0.9649902077699407	23.2945	1.70174	0.03859960831079763	1179.2927727220433	0.03787327529609972	1224.8130118328686
58.4501	0.9751862077699407	23.3037	1.71413	0.03900744831079763	1179.7585261620848	0.03826588082171043	1225.777895890575
58.8601	0.9852082077699407	23.3043	1.72481	0.03940832831079763	1179.7889013864353	0.03865163617391691	1226.282409749707
59.2801	0.9964512077699407	23.3291	1.73849	0.039858048310797624	1181.0444106595903	0.039084211828550826	1228.1185358368577
59.6801	1.0064622077699408	23.3239	1.74986	0.04025848831079763	1180.781158715219	0.03946922872341888	1228.3176231909656
60.0801	1.0171722077699408	23.3343	1.76196	0.04068688831079763	1181.3076626039613	0.03988096466888371	1229.371395533018
60.4901	1.0283622077699408	23.3354	1.77534	0.041134488310797634	1181.3633505152707	0.04031097274923438	1229.9581274478458
60.9001	1.038752207769941	23.3503	1.78657	0.04155008831079764	1182.117668586642	0.04071007303564506	1231.234762110171
61.3201	1.049702207769941	23.3619	1.79958	0.04198808831079764	1182.7049229240852	0.041130511702300476	1232.3644416734369
61.7301	1.0605722077699409	23.361	1.8119	0.042422888310797637	1182.6593600875594	0.04154770390785195	1232.8311860302733
62.1401	1.0714022077699408	23.3715	1.82478	0.04285608831079763	1183.1909265136937	0.04196318788969662	1233.897861348899
62.5501	1.082032207769941	23.3593	1.83645	0.04328128831079764	1182.5732969518997	0.042370831231552344	1233.7565927659252
62.9501	1.092402207769941	23.3756	1.84834	0.04369608831079764	1183.3984905467555	0.04276834393112337	1235.1083754965514
63.3601	1.1029922077699408	23.3818	1.86086	0.04411968831079763	1183.7123678650441	0.04317412686518848	1235.9373885848863
63.7701	1.1143622077699409	23.403	1.87323	0.04457448831079763	1184.785625792096	0.04360961427380788	1237.5968388197668
64.1701	1.1246222077699408	23.3947	1.88444	0.04498488831079763	1184.3654351885805	0.04400242436560878	1237.643982009708
64.5901	1.1359422077699408	23.4035	1.89698	0.045437688310797635	1184.8109384790548	0.0444356382163827	1238.6460086088898
64.9801	1.1459822077699409	23.3987	1.90847	0.045839288310797636	1184.5679366842508	0.044819709775938125	1238.8676878576468
65.4001	1.157442207769941	23.4121	1.92144	0.046297688310797634	1185.2463166947455	0.045257922008175286	1240.1204812365997
65.8201	1.1687922077699409	23.4252	1.93482	0.04675168831079764	1185.9095090930655	0.04569173882319269	1241.3527808269955
66.2401	1.179412207769941	23.4121	1.94614	0.04717648831079764	1185.2463166947455	0.04609748340466467	1241.162075699711
66.6401	1.1898922077699408	23.4069	1.95784	0.04759568831079763	1184.9830647503745	0.04649771786478797	1241.3831493538069
67.0501	1.2011622077699409	23.4218	1.97063	0.048046488310797636	1185.7373828217458	0.04692794399020429	1242.7079001251666
67.4601	1.2123722077699408	23.4295	1.98295	0.04849488831079763	1186.1271982009107	0.04735569610789407	1243.6483042000632
67.8701	1.2232522077699408	23.4185	1.99526	0.048930088310797634	1185.5703190878178	0.047770681159656596	1243.5803794994454
68.2701	1.2340022077699409	23.4289	2.00764	0.049360088310797634	1186.0968229765601	0.0481805386815668	1244.6426669038397
68.6801	1.2452822077699408	23.4412	2.01996	0.04981128831079763	1186.7195150757457	0.04861042259859576	1245.8315429852337
69.0801	1.255972207769941	23.4424	2.03176	0.05023888831079763	1186.7802655244468	0.04901765096929784	1246.4027867335883
69.5101	1.2677122077699408	23.4415	2.04514	0.050708488310797634	1186.7347026879213	0.04946468739966818	1246.9122254871895
69.9301	1.2792022077699408	23.4579	2.05792	0.05116808831079763	1187.5649588201686	0.0499020108966204	1248.3303875078877
70.3401	1.2902322077699409	23.4499	2.06979	0.051609288310797634	1187.1599558288283	0.05032164638574029	1248.428436260232
70.7601	1.3018422077699408	23.4575	2.0829	0.05207368831079763	1187.5447086706017	0.050763157785228545	1249.3845416850518
71.1801	1.3133622077699407	23.4444	2.09518	0.05253448831079763	1186.8815162722822	0.05120105402879721	1249.2337294151903
71.5801	1.324202207769941	23.4366	2.10712	0.052968088310797634	1186.4866383557253	0.05161292719479962	1249.332567395733
71.9901	1.3358222077699409	23.4501	2.11928	0.053432888310797635	1187.170080903612	0.05205424868363543	1250.6040072424553
72.4001	1.3465922077699408	23.4552	2.13103	0.05386368831079763	1187.4282703105914	0.052463113777216165	1251.3875365540307
72.8101	1.3584622077699409	23.4471	2.14474	0.054338488310797635	1187.0182047818594	0.05291354496763299	1251.5189796271025
73.2201	1.3694922077699407	23.4417	2.15659	0.05477968831079763	1186.7448277627047	0.0533319188751039	1251.754339531997
73.6301	1.3814722077699408	23.4518	2.16901	0.05525888831079764	1187.2561440392717	0.05378612858818485	1252.862598699046
74.0401	1.3924522077699408	23.4589	2.18142	0.05569808831079763	1187.6155841940863	0.0542022431856886	1253.763501881808
74.4401	1.403782207769941	23.4541	2.19341	0.05615128831079764	1187.3725823992822	nan	nan
74.8501	1.4152322077699409	23.449	2.20588	0.05660928831079763	1187.1143929923028	nan	nan
75.2501	1.4263522077699409	23.4488	2.21755	0.057054088310797633	1187.104267917519	nan	nan
75.6501	1.4376922077699408	23.449	2.22985	0.05750768831079763	1187.1143929923028	nan	nan
76.0601	1.4489222077699409	23.4377	2.24197	0.057956888310797636	1186.5423262670347	nan	nan
76.4601	1.4610422077699408	23.4586	2.25447	0.05844168831079763	1187.6003965819111	nan	nan
76.8701	1.472622207769941	23.4462	2.26641	0.05890488831079763	1186.9726419453336	nan	nan
77.2701	1.4838022077699409	23.4329	2.27853	0.059352088310797635	1186.2993244722304	nan	nan
77.6801	1.4951222077699409	23.4298	2.29015	0.05980488831079764	1186.142385813086	nan	nan
78.1001	1.5077822077699408	23.4335	2.30418	0.06031128831079763	1186.329699696581	nan	nan
78.5101	1.5192822077699408	23.432	2.31564	0.06077128831079763	1186.2537616357047	nan	nan
78.9201	1.5318922077699408	23.4462	2.32898	0.06127568831079763	1186.9726419453336	nan	nan
79.3301	1.5429822077699409	23.4113	2.34081	0.061719288310797635	1185.2058163956115	nan	nan
79.7501	1.554952207769941	23.4141	2.35307	0.062198088310797636	1185.3475674425808	nan	nan
80.1601	1.5674122077699408	23.4152	2.36614	0.06269648831079763	1185.4032553538898	nan	nan
80.5801	1.5800222077699408	23.3958	2.37857	0.06320088831079763	1184.4211230998899	nan	nan
81.0001	1.5921422077699408	23.3983	2.39096	0.06368568831079763	1184.5476865346836	nan	nan
81.4301	1.6043622077699409	23.3944	2.40392	0.06417448831079764	1184.3502475764053	nan	nan
81.8501	1.6165522077699408	23.3752	2.41645	0.06466208831079763	1183.3782403971886	nan	nan
82.2701	1.6293422077699409	23.3763	2.42975	0.06517368831079763	1183.4339283084978	nan	nan
82.6901	1.641242207769941	23.3629	2.44162	0.06564968831079764	1182.7555482980029	nan	nan
83.1001	1.6536322077699408	23.3713	2.45421	0.06614528831079763	1183.1808014389103	nan	nan
83.5101	1.6660722077699408	23.3538	2.46619	0.06664288831079763	1182.2948573953533	nan	nan
83.9301	1.678802207769941	23.3428	2.47923	0.06715208831079764	1181.7379782822604	nan	nan
84.3401	1.6916522077699407	23.3192	2.49146	0.06766608831079762	1180.5432194578063	nan	nan
84.7601	1.7036322077699408	23.309	2.50406	0.06814528831079764	1180.0268406438477	nan	nan
85.1501	1.7156022077699409	23.2928	2.51604	0.06862408831079764	1179.2067095863836	nan	nan
85.5601	1.7287522077699409	23.2853	2.52914	0.06915008831079764	1178.827019282002	nan	nan
85.9801	1.7403322077699408	23.2698	2.5407	0.06961328831079763	1178.0423259862803	nan	nan
86.3901	1.752962207769941	23.2548	2.55344	0.07011848831079764	1177.282945377517	nan	nan
86.7901	1.7654822077699408	23.2339	2.56554	0.07061928831079763	1176.2248750626406	nan	nan
87.2001	1.7785622077699408	23.2179	2.57805	0.07114248831079763	1175.4148690799602	nan	nan
87.6101	1.790922207769941	23.2074	2.59045	0.07163688831079763	1174.8833026538261	nan	nan
88.0201	1.804102207769941	23.1741	2.60233	0.07216408831079764	1173.197477702372	nan	nan
88.4301	1.8165222077699408	23.1637	2.61489	0.07266088831079763	1172.6709738136294	nan	nan
88.8301	1.8287522077699407	23.1168	2.62687	0.07315008831079763	1170.2966437768973	nan	nan
89.2501	1.8415822077699409	23.0939	2.63941	0.07366328831079763	1169.1373227141858	nan	nan
89.6501	1.853992207769941	23.0679	2.65112	0.07415968831079764	1167.8210629923299	nan	nan
90.0501	1.8664422077699407	23.0652	2.66308	0.07465768831079762	1167.6843744827524	nan	nan
90.4601	1.8794222077699407	23.0255	2.67572	0.07517688831079763	1165.6745471382262	nan	nan
90.8801	1.892972207769941	23.0113	2.68855	0.07571888831079764	1164.9556668285973	nan	nan
91.3001	1.9060722077699408	22.9724	2.70103	0.07624288831079763	1162.986339783205	nan	nan
91.7101	1.9187422077699408	22.9502	2.71315	0.07674968831079763	1161.8624564822355	nan	nan
92.1201	1.9316222077699408	22.934	2.72532	0.07726488831079763	1161.0423254247717	nan	nan
92.5301	1.944562207769941	22.8873	2.73781	0.07778248831079763	1158.6781204628228	nan	nan
92.9401	1.957712207769941	22.8511	2.75052	0.07830848831079763	1156.8454819270078	nan	nan
93.3501	1.9702422077699409	22.8288	2.76216	0.07880968831079764	1155.716536088647	nan	nan
93.7501	1.9827822077699409	22.7976	2.77404	0.07931128831079763	1154.1370244224197	nan	nan
94.1601	1.9963422077699409	22.7708	2.78776	0.07985368831079763	1152.7802644014298	nan	nan
94.5901	2.0093222077699404	22.7438	2.80016	0.08037288831079761	1151.4133793056562	nan	nan
94.9901	2.0218022077699405	22.6982	2.81158	0.08087208831079762	1149.1048622550168	nan	nan
95.4101	2.0351922077699407	22.6616	2.82443	0.08140768831079763	1147.2519735696349	nan	nan
95.8201	2.0487322077699406	22.6296	2.83743	0.08194928831079762	1145.6319616042736	nan	nan
96.2501	2.0620922077699406	22.6019	2.84967	0.08248368831079762	1144.229638746758	nan	nan
96.6601	2.0755822077699406	22.566	2.86253	0.08302328831079762	1142.4121878231183	nan	nan
97.0601	2.0879022077699405	22.5232	2.8744	0.08351608831079763	1140.245421819448	nan	nan
97.4701	2.1006822077699407	22.4979	2.88681	0.08402728831079763	1138.9645998593342	nan	nan
97.8801	2.113772207769941	22.4653	2.89935	0.08455088831079763	1137.3142126696225	nan	nan
98.3101	2.1276122077699404	22.439	2.91242	0.08510448831079762	1135.9827653355912	nan	nan
98.7201	2.1414122077699407	22.3983	2.92569	0.08565648831079763	1133.9223126171476	nan	nan
99.1401	2.154242207769941	22.3501	2.93727	0.08616968831079763	1131.4821695943224	nan	nan
99.5401	2.1669122077699408	22.3324	2.94965	0.08667648831079763	1130.586100475982	nan	nan
99.9401	2.1801222077699407	22.2802	2.96178	0.08720488831079763	1127.9434559574865	nan	nan
100.35	2.1929822077699406	22.2445	2.97355	0.08771928831079762	1126.1361301086306	nan	nan
100.75	2.2053822077699405	22.2172	2.98571	0.08821528831079763	1124.7540574006816	nan	nan
101.17	2.2184522077699405	22.1751	2.9981	0.08873808831079762	1122.6227291587536	nan	nan
101.59	2.2319622077699406	22.1401	3.01093	0.08927848831079763	1120.8508410716397	nan	nan
101.99	2.2445722077699406	22.0974	3.02291	0.08978288831079763	1118.689137605361	nan	nan
102.42	2.258632207769941	22.0556	3.03618	0.09034528831079763	1116.572996975608	nan	nan
102.84	2.2719122077699407	22.0211	3.04875	0.09087648831079763	1114.8264215754532	nan	nan
103.26	2.2857622077699404	21.992	3.06081	0.09143048831079761	1113.3532231944528	nan	nan
103.68	2.2994022077699405	21.9445	3.07338	0.09197608831079762	1110.9485179333697	nan	nan
104.08	2.3124722077699404	21.9142	3.08574	0.09249888831079761	1109.4145691036683	nan	nan
104.5	2.3253622077699405	21.8643	3.09812	0.09301448831079762	1106.8883629451834	nan	nan
104.91	2.3378722077699408	21.828	3.11017	0.09351488831079763	1105.0506618719767	nan	nan
105.31	2.3505322077699407	21.7888	3.12184	0.09402128831079763	1103.0661472144093	nan	nan
105.72	2.3642022077699405	21.7627	3.13472	0.09456808831079762	1101.7448249551614	nan	nan
106.13	2.376652207769941	21.717	3.14626	0.09506608831079763	1099.4312453671303	nan	nan
106.52	2.3896522077699407	21.6847	3.1585	0.09558608831079762	1097.7960457895938	nan	nan
106.94	2.403772207769941	21.6366	3.17162	0.09615088831079763	1095.3609653041606	nan	nan
107.35	2.416102207769941	21.5966	3.18279	0.09664408831079763	1093.335950347459	nan	nan
107.77	2.4297422077699404	21.5586	3.19499	0.09718968831079762	1091.4121861385925	nan	nan
108.19	2.4434122077699407	21.5127	3.20843	0.09773648831079763	1089.0884814757776	nan	nan
108.62	2.4571322077699405	21.468	3.22103	0.09828528831079762	1086.8255272616639	nan	nan
109.04	2.4702522077699407	21.4407	3.23409	0.09881008831079763	1085.4434545537151	nan	nan
109.46	2.4837422077699407	21.3964	3.24689	0.09934968831079763	1083.2007504891683	nan	nan
109.86	2.496572207769941	21.3476	3.25809	0.09986288831079763	1080.7302322419923	nan	nan
110.28	2.5099122077699407	21.313	3.27053	0.10039648831079763	1078.9785943044458	nan	nan
110.7	2.523822207769941	21.2586	3.28323	0.10095288831079763	1076.224573963332	nan	nan
111.11	2.5364922077699408	21.223	3.29539	0.10145968831079763	1074.4223106518675	nan	nan
111.52	2.5495922077699404	21.1772	3.3076	0.10198368831079761	1072.1036685264444	nan	nan
111.92	2.5629122077699407	21.1361	3.32003	0.10251648831079763	1070.0229656584336	nan	nan
112.34	2.575472207769941	21.094	3.33174	0.10301888831079763	1067.8916374165053	nan	nan
112.73	2.5881422077699408	21.0692	3.34362	0.10352568831079763	1066.6361281433503	nan	nan
113.15	2.6011822077699405	21.0124	3.35613	0.10404728831079763	1063.7606069048343	nan	nan
113.57	2.614992207769941	20.9747	3.36874	0.10459968831079763	1061.8520303081432	nan	nan
113.98	2.6280022077699408	20.9226	3.38091	0.10512008831079762	1059.2144483270395	nan	nan
114.4	2.6419122077699404	20.882	3.39422	0.10567648831079762	1057.1590581459877	nan	nan
114.82	2.6557522077699405	20.833	3.4068	0.10623008831079762	1054.6784148240283	nan	nan
115.25	2.669832207769941	20.7963	3.41966	0.10679328831079764	1052.820463601255	nan	nan
115.66	2.682982207769941	20.75	3.43167	0.10731928831079764	1050.476508788873	nan	nan
116.07	2.6956922077699406	20.6984	3.44383	0.10782768831079763	1047.864239494728	nan	nan
116.49	2.7090522077699406	20.6538	3.45571	0.10836208831079762	1045.6063478180058	nan	nan
116.91	2.7220522077699405	20.6083	3.46824	0.10888208831079763	1043.302893304758	nan	nan
117.34	2.7358822077699405	20.5654	3.48111	0.10943528831079762	1041.1310647636958	nan	nan
117.73	2.7487022077699406	20.5226	3.49318	0.10994808831079762	1038.9642987600253	nan	nan
118.14	2.7624122077699407	20.4644	3.50577	0.11049648831079763	1036.0179019980246	nan	nan
118.54	2.7751422077699406	20.4251	3.51759	0.11100568831079763	1034.0283248030655	nan	nan
118.95	2.7884822077699405	20.3874	3.53008	0.11153928831079762	1032.1197482063742	nan	nan
119.36	2.802222207769941	20.3269	3.54261	0.11208888831079764	1029.0569130843633	nan	nan
119.77	2.8145722077699404	20.2781	3.55413	0.11258288831079762	1026.5863948371875	nan	nan
120.19	2.828122207769941	20.2405	3.56676	0.11312488831079763	1024.6828807778884	nan	nan
120.6	2.8414422077699406	20.1915	3.5796	0.11365768831079763	1022.2022374559291	nan	nan
121.01	2.8545022077699405	20.1463	3.59176	0.11418008831079762	1019.9139705548564	nan	nan
121.42	2.8680322077699407	20.0916	3.60423	0.11472128831079763	1017.1447626015671	nan	nan
121.84	2.8819022077699405	20.0455	3.61768	0.11527608831079762	1014.8109328639688	nan	nan
122.25	2.8956022077699406	19.9993	3.62941	0.11582408831079763	1012.4720405889788	nan	nan
122.67	2.9097122077699407	19.9451	3.64169	0.11638848831079762	1009.7281453226481	nan	nan
123.09	2.9231722077699405	19.892	3.65414	0.11692688831079762	1007.039937967627	nan	nan
123.5	2.936242207769941	19.8387	3.66688	0.11744968831079763	1004.3416055378224	nan	nan
123.91	2.9490822077699406	19.7794	3.67875	0.11796328831079762	1001.3395208645123	nan	nan
124.31	2.9620122077699405	19.7468	3.69116	0.11848048831079762	999.6891336748007	nan	nan
124.71	2.9749922077699407	19.691	3.70298	0.11899968831079763	996.8642378102022	nan	nan
125.14	2.9887822077699404	19.6375	3.71513	0.11955128831079762	994.155780305614	nan	nan
125.55	3.0023822077699407	19.5912	3.72787	0.12009528831079763	991.8118254932322	nan	nan
125.96	3.0158722077699407	19.5435	3.74052	0.12063488831079763	989.3969951573657	nan	nan
126.37	3.0297122077699408	19.4777	3.75289	0.12118848831079763	986.0658455535917	nan	nan
126.77	3.0426522077699407	19.428	3.76449	0.12170608831079763	983.5497644698903	nan	nan
127.2	3.0565222077699405	19.3741	3.77754	0.12226088831079762	980.821056815735	nan	nan
127.61	3.0699622077699407	19.3255	3.78973	0.12279848831079762	978.3606636433428	nan	nan
128.02	3.0828822077699405	19.2616	3.80133	0.12331528831079762	975.1257022500124	nan	nan
128.43	3.096152207769941	19.2103	3.81378	0.12384608831079763	972.5286205680427	nan	nan
128.83	3.1093522077699407	19.1712	3.82613	0.12437408831079763	970.5491684478669	nan	nan
129.26	3.1231722077699406	19.1038	3.83851	0.12492688831079762	967.1370182458251	nan	nan
129.67	3.137022207769941	19.0499	3.85098	0.12548088831079762	964.40831059167	nan	nan
130.07	3.1499622077699407	18.9975	3.86225	0.12599848831079763	961.755540998391	nan	nan
130.47	3.1638522077699407	18.931	3.87532	0.12655408831079762	958.3889536328749	nan	nan
130.89	3.1773722077699404	18.878	3.88787	0.12709488831079763	955.7058088152454	nan	nan
131.3	3.190302207769941	18.8114	3.89915	0.12761208831079762	952.3341589123374	nan	nan
131.71	3.2045622077699405	18.7688	3.91241	0.12818248831079762	950.1775179834505	nan	nan
132.13	3.2179822077699405	18.6934	3.92477	0.12871928831079762	946.3603647900684	nan	nan
132.55	3.2316822077699405	18.6382	3.9367	0.12926728831079762	943.5658441498204	nan	nan
132.96	3.2442422077699407	18.5868	3.948	0.12976968831079763	940.9636999304589	nan	nan
133.37	3.2586022077699406	18.5291	3.96118	0.13034408831079763	938.042615855417	nan	nan
133.79	3.2728322077699405	18.442	3.97383	0.13091328831079763	933.6331457871997	nan	nan
134.2	3.2860322077699404	18.3873	3.98579	0.13144128831079763	930.8639378339104	nan	nan
134.62	3.2999622077699406	18.3346	3.99825	0.13199848831079763	928.1959806284563	nan	nan
135.03	3.3135722077699405	18.2607	4.01099	0.13254288831079764	924.4547654959505	nan	nan
135.45	3.3270222077699407	18.2055	4.02323	0.13308088831079762	921.6602448557024	nan	nan
135.85	3.340592207769941	18.1273	4.03515	0.13362368831079763	917.7013406153513	nan	nan
136.26	3.3554022077699406	17.9924	4.04721	0.13421608831079762	910.8719776738756	nan	nan