File: original_data/46NT9D.csv
Specimen name:	AWA_2_03_Rz
Specimen ID:	46NT9D
Material:	42CrMoS4
Specimen type:	Round Tensile Specimen
Gauge diameter:	5.001	mm
Gauge length:	25	mm
Parallel length:	30	mm
Original cross-section:	19.642808851968347	mm²
Cross-section after fracture:	9.275184939732934	mm²
Yield stress at 0.2% plastic strain:	1090.0613982135765	MPa
Yield stress at 1% plastic strain:	1122.0946918175598	MPa
Ultimate tensile strength:	1175.3665259378865	MPa
Uniform elongation:	5.043896798368011	%
Elongation after fracture:	14.491399342237472	%
Reduction of area:	52.78076058453577	%
Slope of linear-elastic region:	207076.24253279125	MPa
Crosshead seperation speed:	0.03007181246249116	mm/s
Strain rate:	0.0010023937487497053	s-1
Test temperature:	RT	Cel
Machine type:	INSTRON 8852TT
Standard:	DIN EN ISO 6892-1
Date:	2022-08-23 00:00:00
Heat treatment batch:	Batch 2
Time	Displacement	Force	Machine Displacement	Engineering Strain	Engineering Stress	True Strain	True Stress
s	mm	kN	mm		MPa		MPa
0	0.0009504265789959489	0.15682	0	3.8017063159837954e-05	7.98358326356597	3.801634052952565e-05	7.983886775955143
0.430001	0.000689873578995949	0.162231	0.000694275	2.759494315983796e-05	8.259053031702404	2.7594562426407873e-05	8.259280939801368
0.850001	0.000802693578995949	0.214443	0.00505829	3.210774315983796e-05	10.917125020972309	3.2107227717207086e-05	10.917475545218526
1.26	0.001819825578995949	0.356769	0.0172348	7.279302315983796e-05	18.162830106868817	7.279037387633343e-05	18.164152234181437
1.66	0.0028648365789959492	0.515941	0.0296936	0.00011459346315983798	26.26615184662346	0.00011458689783055376	26.269161775927447
2.1	0.003912776578995949	0.67674	0.0422554	0.00015651106315983795	34.452302880918474	0.00015649881658119085	34.45769504747067
2.53	0.004674826578995949	0.850374	0.054512	0.00018699306315983797	43.29187370342844	0.0001869755821362971	43.29996898350218
2.95	0.005284006578995949	1.03539	0.0676689	0.00021136026315983798	52.71089322320859	0.0002113379297263887	52.722034211471644
3.37	0.005954206578995949	1.21483	0.07967	0.00023816826315983797	61.84604295420131	0.00023813990560151297	61.860772718835015
3.80001	0.006718936578995949	1.44242	0.0926247	0.00026875746315983796	73.43247143880136	0.0002687213543424368	73.45220696353881
4.20001	0.007464896578995949	1.67025	0.105221	0.00029859586315983795	85.03111813525739	0.00029855129228731727	85.05650807537243
4.62001	0.008511336578995948	1.9175	0.117336	0.0003404534631598379	97.618421807727	0.00034039552203009467	97.65165633749965
5.04001	0.00959621657899595	2.18815	0.130112	0.00038384866315983797	111.39700113615531	0.0003837750121083002	111.43976072612143
5.46001	0.011093026578995949	2.46991	0.142071	0.000443721063159838	125.74118185508371	0.00044362264808035914	125.79697586597942
5.87001	0.01268862657899595	2.76841	0.153809	0.000507545063159838	140.93758285096715	0.0005074163057291411	141.00911502535683
6.29001	0.014654626578995949	3.11046	0.16711	0.000586185063159838	158.3510802065515	0.0005860133238064989	158.44390324450382
6.70001	0.01708642657899595	3.49147	0.180122	0.000683457063159838	177.7480006200911	0.0006832236127439965	177.86948374657743
7.10001	0.01894712657899595	3.79209	0.191502	0.000757885063159838	193.05232915403573	0.0007575980132999997	193.19864063070978
7.52001	0.02132742657899595	4.16152	0.204407	0.000853097063159838	211.85972084552392	0.0008527333826821613	212.04045775117913
7.94001	0.02350042657899595	4.52767	0.216553	0.000940017063159838	230.5001303083136	0.0009395755238017769	230.71680436386401
8.38001	0.026092826578995948	4.93584	0.229904	0.001043713063159838	251.2797450302223	0.0010431687733693067	251.5420089826178
8.79001	0.02847132657899595	5.29666	0.241768	0.001138853063159838	269.64880837137696	0.0011382050619487957	269.95589874276806
9.20001	0.030901426578995948	5.67698	0.253948	0.0012360570631598379	289.01060142583054	0.0012352937735430104	289.367835021051
9.60001	0.03329192657899595	6.07254	0.266556	0.001331677063159838	309.14825093313925	0.0013307911676567223	309.55993656802286
10	0.03563352657899595	6.44587	0.278854	0.001425341063159838	328.15418856728724	0.0014243262287957218	328.62192020730015
10.41	0.03813222657899595	6.83711	0.291157	0.0015252890631598378	348.0719102611882	0.0015241269913103329	348.6028205391027
10.82	0.04065612657899594	7.24114	0.303337	0.0016262450631598377	368.6407608285811	0.0016249241585396706	369.2402610459581
11.22	0.042966726578995945	7.62558	0.315849	0.0017186690631598377	388.2122998532292	0.0017171938415222034	388.87950832292506
11.64	0.045796526578995946	8.07351	0.32885	0.0018318610631598378	411.01606500594636	0.0018301852519392089	411.7689893317639
12.05	0.048073226578995945	8.44736	0.340328	0.001922929063159838	430.048475432449	0.0019210826017662308	430.87542814442565
12.45	0.05077282657899595	8.86773	0.352497	0.002030913063159838	451.44918259037024	0.0020288535472186902	452.3660366326459
12.88	0.05346432657899595	9.29406	0.365597	0.002138573063159838	473.1533086760486	0.0021362895708171583	474.16518159672813
13.28	0.05573692657899595	9.67575	0.37775	0.0022294770631598377	492.5848473565135	0.0022269954669291137	493.68305397535494
13.7	0.058163926578995946	10.0715	0.389759	0.002326557063159838	512.7321696148749	0.0023238548197465386	513.9250702656017
14.11	0.060871326578995945	10.5019	0.402428	0.002434853063159838	534.6434962099444	0.002431893611353744	535.9452745643897
14.51	0.06309012657899594	10.868	0.413475	0.002523605063159838	553.2813602119307	0.0025204261190455244	554.6776238539136
14.92	0.06601292657899595	11.3101	0.427296	0.002640517063159838	575.7883246349795	0.0026370370227040986	577.3087035309463
15.33	0.06835652657899595	11.7058	0.439522	0.002734261063159838	595.9331014325376	0.0027305297713820518	597.5625381080326
15.73	0.07088562657899596	12.1144	0.451443	0.0028354250631598384	616.7346071173549	0.0028314128279876257	618.4833118796936
16.13	0.07330462657899595	12.4913	0.463024	0.002932185063159838	635.9222906528607	0.0029278945934588345	637.7869324948434
16.57	0.07580372657899595	12.9198	0.475632	0.003032149063159838	657.7368897374037	0.0030275613705615136	659.7312460314265
16.98	0.07833812657899596	13.3344	0.488239	0.0031335250631598383	678.8438507186206	0.0031286258054622753	680.9710249388194
17.38	0.08081722657899595	13.721	0.500057	0.003232689063159838	698.5253536499725	0.003227475157472323	700.7834689210566
17.79	0.08315352657899595	14.1198	0.512417	0.003326141063159838	718.827949017337	0.003320621691393463	721.2188721759105
18.2	0.08562552657899596	14.5241	0.5256	0.0034250210631598384	739.410545073068	0.003419169036920236	741.9430417642658
18.6	0.08797542657899596	14.8974	0.537441	0.003519017063159838	758.4149554307339	0.0035128398102781343	761.0838305998503
19.01	0.09044632657899596	15.3316	0.550106	0.0036178530631598383	780.5197370468566	0.003611324374585612	783.3435427683883
19.41	0.09294012657899595	15.7113	0.562099	0.0037176050631598377	799.8499663873488	0.003710711848341612	802.8234926721585
19.83	0.09550022657899596	16.1522	0.575912	0.003820009063159838	822.2958397511177	0.0038127313565873406	825.4370173115657
20.25	0.09784762657899596	16.5227	0.586643	0.003913905063159838	841.1577043037972	0.003906265663506877	844.4499157015878
20.67	0.10039522657899595	16.9376	0.60025	0.004015809063159838	862.2799380498341	0.00400776722441378	865.7426896400356
21.08	0.10257142657899596	17.2948	0.611599	0.004102857063159838	880.4647100288277	0.004094463296237426	884.0771308832324
21.5	0.10518342657899596	17.7305	0.625149	0.004207337063159839	902.6458554690502	0.00419851096815574	906.4435908316727
21.91	0.10772742657899595	18.1376	0.637798	0.004309097063159838	923.3709973297675	0.004299839489404592	927.3498925825683
22.32	0.11010342657899595	18.5188	0.649555	0.004404137063159838	942.7775904943597	0.0043944672326346424	946.9297122229724
22.72	0.11245942657899595	18.8844	0.661968	0.004498377063159838	961.3899998883128	0.0044882896052053185	965.7146946125617
23.13	0.11514842657899595	19.2885	0.674477	0.004605937063159838	981.9624141008304	0.004595362194066431	986.4852711785675
23.53	0.11781642657899595	19.6792	0.686558	0.004712657063159838	1001.8526448180555	0.004701587260028913	1006.5740327609028
23.94	0.12037942657899595	20.0215	0.69825	0.004815177063159838	1019.2788694776565	0.004803621178990291	1024.186877710929
24.34	0.12355142657899595	20.3822	0.710655	0.004942057063159838	1037.6418237128833	0.004929885185422443	1042.7699088167935
24.76	0.12710742657899593	20.6996	0.72279	0.005084297063159837	1053.8004088924254	0.00507141566828961	1059.158243216514
25.17	0.13159442657899595	20.9794	0.736031	0.005263777063159838	1068.0448075478632	0.005249971812657547	1073.6667573082607
25.57	0.13660242657899593	21.172	0.748268	0.005464097063159837	1077.8499225622927	0.005449223042264951	1083.7393991586923
26	0.14327542657899595	21.3049	0.760162	0.005731017063159838	1084.6157573775454	0.005714657260648255	1090.8317087900482
26.4	0.15149042657899595	21.3866	0.772594	0.006059617063159838	1088.7750403301875	0.006041331415849257	1095.372600142515
26.82	0.16248542657899595	21.4068	0.785419	0.006499417063159838	1089.803406494733	0.006478386925320655	1096.8864933503946
27.23	0.17442442657899593	21.4072	0.79826	0.006976977063159837	1089.8237701811597	0.006952750578500994	1097.4274456286
27.63	0.18591742657899593	21.3993	0.809959	0.0074366970631598375	1089.4215873742335	0.007409181165610188	1097.5232856936025
28.04	0.19732742657899593	21.4665	0.821564	0.007893097063159837	1092.8426866939096	0.0078621095241672	1101.468600094749
28.44	0.20729642657899594	21.5297	0.834118	0.008291857063159838	1096.0601491493194	0.008257668477608684	1105.1485232386913
28.85	0.21780242657899593	21.5704	0.846016	0.008712097063159837	1098.1321542432304	0.008674365733180247	1107.6991881591741
29.25	0.22791242657899594	21.6287	0.858074	0.009116497063159838	1101.1001615399139	0.009075192648401455	1111.1383379288372
29.69	0.23885742657899595	21.6661	0.871071	0.009554297063159838	1103.0041662208052	0.009508943419589966	1113.5425956867819
30.1	0.24855942657899593	21.6989	0.883083	0.009942377063159837	1104.67398850779	0.009893276812904334	1115.6570738333992
30.5	0.25894742657899594	21.7395	0.895252	0.010357897063159838	1106.7409026800945	0.010304621612665531	1118.2044110256436
30.92	0.26918542657899597	21.7634	0.907482	0.010767417063159838	1107.9576329440865	0.010709861211360189	1119.8874748663068
31.33	0.28000942657899597	21.7932	0.91996	0.01120037706315984	1109.4747275828713	0.01113811729721384	1121.901262873846
31.73	0.28988742657899597	21.8289	0.93198	0.011595497063159838	1111.2921865964497	0.011528784502025907	1124.1781718824413
32.16	0.30116442657899595	21.8755	0.944653	0.012046577063159838	1113.6645560651536	0.011974594572135061	1127.0804019623024
32.56	0.31093242657899595	21.8788	0.955948	0.012437297063159838	1113.8325564781735	0.012360589254379443	1127.6856228617114
32.97	0.32166042657899596	21.9146	0.968815	0.012866417063159838	1115.655106413358	0.012784347926650026	1130.0095903111162
33.37	0.332247426578996	21.9407	0.981079	0.013289897063159839	1116.9838369526967	0.013202361090998635	1131.8284371670113
33.79	0.34267142657899596	21.9606	0.993084	0.013706857063159838	1117.9969303524222	0.013613767774341543	1133.3211544738142
34.22	0.35332742657899596	21.9847	1.00605	0.01413309706315984	1119.2238424596276	0.014034155986350208	1135.0419416605123
34.62	0.363669426578996	22.0097	1.0177	0.014546777063159839	1120.4965728612926	0.01444198771082261	1136.7961867067404
35.04	0.37476242657899594	22.041	1.03094	0.014990497063159837	1122.0900313241777	0.014879249950572236	1138.9107186433437
35.46	0.38525242657899594	22.0392	1.04342	0.015410097063159838	1121.998394735258	0.015292567408405261	1139.2884989028378
35.8801	0.39621542657899594	22.0718	1.05541	0.015848617063159837	1123.6580351790294	0.015724339101260407	1141.4664610885243
36.2901	0.40708042657899596	22.0796	1.06859	0.016283217063159838	1124.0551270643489	0.016152067262718898	1142.3583606892955
36.7101	0.417689426578996	22.1201	1.08121	0.01670757706315984	1126.1169503150468	0.01656954087586965	1144.931636044566
37.1201	0.427918426578996	22.1354	1.0932	0.01711673706315984	1126.895861320866	0.01697189618520293	1146.1846414766583
37.5201	0.438144426578996	22.1448	1.10479	0.01752577706315984	1127.374407951892	0.017373971736726865	1147.1325204923687
37.9401	0.44886142657899597	22.1798	1.11789	0.01795445706315984	1129.1562305142234	0.01779517946859349	1149.4296175725904
38.3501	0.45970242657899596	22.1919	1.12984	0.018388097063159838	1129.7722320286296	0.018221080312904973	1150.5465934904346
38.7501	0.46997842657899597	22.2011	1.14174	0.01879913706315984	1130.2405968164421	0.018624617109810438	1151.488144710342
39.1601	0.48005342657899597	22.2148	1.15344	0.01920213706315984	1130.9380530765548	0.019020102638076776	1152.6544805816739
39.5801	0.491136426578996	22.2564	1.16698	0.01964545706315984	1133.0558764649259	0.019454975757836883	1155.3152770361785
40.0001	0.5019374265789959	22.26	1.17899	0.020077497063159835	1133.2391496427656	0.019878601922936497	1155.991755341576
40.4201	0.5126564265789959	22.2835	1.19108	0.020506257063159835	1134.435516220331	0.02029883461903894	1157.6985425375235
40.8601	0.5239724265789959	22.3148	1.20447	0.020958897063159836	1136.0289746832161	0.020742280843435705	1159.8388890243687
41.2701	0.5343844265789959	22.3068	1.21672	0.021375377063159836	1135.621700954683	0.02115012789477228	1159.8960430136963
41.6701	0.5444394265789959	22.3319	1.22836	0.021777577063159838	1136.8995222779552	0.021543833128032534	1161.658439237433
42.0801	0.5544434265789959	22.3525	1.24038	0.022177737063159838	1137.9482521289272	0.021935387681448454	1163.1853692561247
42.4801	0.5646544265789959	22.362	1.25224	0.022586177063159837	1138.43188968156	0.022334886129763854	1164.1447139162556
42.9001	0.575096426578996	22.3807	1.26506	0.023003857063159838	1139.3838920220057	0.022743257307601523	1165.5941162141467
43.3301	0.5868264265789959	22.4177	1.27785	0.023473057063159834	1141.2675330164702	0.023201801457288673	1168.0565709432974
43.7301	0.5969394265789959	22.4139	1.29038	0.023877577063159836	1141.0740779954172	0.02359696582095091	1168.320162227527
44.1401	0.6069734265789959	22.4368	1.3022	0.024278937063159835	1142.2398990433428	0.023988888999056903	1169.9722696632462
44.5401	0.6173824265789959	22.4632	1.31429	0.024695297063159836	1143.5839023475012	0.024395297238649343	1171.8250465326203
44.9601	0.6281904265789959	22.471	1.32709	0.025127617063159836	1143.9809942328206	0.024817109292198724	1172.7265105834358
45.3701	0.6381374265789959	22.482	1.33883	0.025525497063159833	1144.5409956095534	0.02520516127646848	1173.755973431651
45.7701	0.648472426578996	22.4989	1.35092	0.025938897063159837	1145.401361361079	0.02560819045579954	1175.111809369427
46.2101	0.6595384265789959	22.5264	1.36433	0.026381537063159835	1146.8013648029107	0.026039546105242273	1177.055747512541
46.6201	0.6694984265789959	22.5417	1.37576	0.02677993706315984	1147.58027580873	0.026427630539925792	1178.3124033698114
47.0201	0.6798854265789959	22.5489	1.38847	0.027195417063159835	1147.9468221644097	0.026832192361792018	1179.1657147595
47.4401	0.6904454265789959	22.5789	1.40099	0.027617817063159834	1149.474098646408	0.02724332462328865	1181.220064021665
47.8701	0.7018544265789959	22.5872	1.41376	0.028074177063159834	1149.896645139761	0.027687321106031157	1182.179047159748
48.2801	0.7117554265789959	22.5918	1.42546	0.028470217063159838	1150.1308275336673	0.02807247204760764	1182.8753018445825
48.6801	0.7219984265789959	22.6008	1.43731	0.028879937063159836	1150.5890104782668	0.02847077080544889	1183.8179486864426
49.0801	0.7319674265789959	22.621	1.44982	0.029278697063159838	1151.6173766428124	0.028858262807646966	1185.335232946208
49.4901	0.742438426578996	22.6352	1.46195	0.029697537063159838	1152.3402875109582	0.029265105780222605	1186.5619559086872
49.8901	0.752878426578996	22.6416	1.47427	0.03011513706315984	1152.6661064937846	0.029670579550694066	1187.3788042789038
50.3101	0.7634744265789959	22.6564	1.48619	0.030538977063159837	1153.4195628915704	0.030081944081084108	1188.643816466916
50.7501	0.7744854265789959	22.6647	1.49857	0.030979417063159834	1153.8421093849233	0.030509240784287215	1189.587465316595
51.1601	0.7852744265789959	22.7075	1.51144	0.03141097706315984	1156.0210238325742	0.030927745454914	1192.3327736967099
51.5601	0.794657426578996	22.7017	1.52336	0.03178629706315984	1155.7257503793878	0.03129156912688838	1192.4619924044905
51.9801	0.805911426578996	22.7278	1.53604	0.032236457063159835	1157.0544809187263	0.031727765875434494	1194.3538180125997
52.4101	0.817073426578996	22.7235	1.54888	0.03268293706315984	1156.83557128964	0.03216020891241486	1194.644355458524
52.8101	0.8269404265789959	22.7362	1.56066	0.033077617063159835	1157.482118333686	0.03254232483965926	1195.7688686013828
53.2301	0.8374834265789959	22.7517	1.57294	0.033499337063159836	1158.2712111827184	0.032950458691158716	1197.0725288966826
53.6401	0.8483384265789959	22.7773	1.58586	0.03393353706315984	1159.5744871140237	0.033370496518570686	1198.9229509500021
54.0401	0.8577304265789959	22.7683	1.59686	0.034309217063159834	1159.1163041694242	0.03373378076398344	1198.8846770506207
54.4501	0.868824426578996	22.8017	1.61	0.034752977063159836	1160.816671986049	0.03416272872704028	1201.1585071621137
54.8501	0.8791344265789959	22.8192	1.62204	0.035165377063159836	1161.7075832672144	0.034561198555219406	1202.5594684699383
55.2901	0.8903284265789959	22.8183	1.63509	0.035613137063159835	1161.6617649727548	0.03499365427554262	1203.0321846297616
55.7001	0.9006124265789959	22.8299	1.64712	0.036024497063159834	1162.2523118791273	0.035390789371594275	1204.1218668750676
56.1001	0.9107514265789959	22.8297	1.65863	0.03643005706315983	1162.2421300359142	0.0357821706970565	1204.5826771543311
56.5101	0.9217144265789959	22.8513	1.67154	0.03686857706315984	1163.3417691029529	0.03620518742925423	1206.2325247679178
56.9101	0.9318234265789959	22.8699	1.68342	0.03727293706315984	1164.288680521792	0.036595093327544126	1207.6851392342303
57.3201	0.9419664265789959	22.8667	1.69547	0.037678657063159836	1164.1257710303787	0.036986157877019823	1207.9884667354188
57.7201	0.9522114265789959	22.8785	1.70776	0.03808845706315984	1164.7264997799648	0.03738099986342117	1209.0891350571585
58.1601	0.964285426578996	22.9006	1.72189	0.038571417063159835	1165.851593455037	0.03784613140925073	1210.8201414999407
58.5701	0.9747204265789959	22.8992	1.73403	0.03898881706315984	1165.7803205525436	0.03824794888607729	1211.2327162063984
58.9701	0.9849494265789959	22.8962	1.74608	0.03939797706315983	1165.6275929043438	0.03864167733589431	1211.5509620737753
59.3901	0.9958804265789959	22.9162	1.75889	0.03983521706315984	1166.645777225676	0.039062255467948184	1213.1193649972795
59.8001	1.0065604265789958	22.9197	1.77146	0.04026241706315983	1166.823959481909	0.03947300542410183	1213.8031123778571
60.2101	1.017060426578996	22.9376	1.78315	0.04068241706315984	1167.7352344495014	0.03987666822074627	1215.2415262767229
60.6101	1.0278804265789958	22.9375	1.79577	0.041115217063159834	1167.7301435278948	0.040292462723670694	1215.7416218502392
61.0301	1.038690426578996	22.9501	1.80817	0.04154761706315984	1168.371599650334	0.04070770036956103	1216.9146554600777
61.4401	1.049160426578996	22.9477	1.82053	0.04196641706315984	1168.2494175317743	0.04110971350581119	1217.276659821706
61.8401	1.059530426578996	22.9488	1.83249	0.04238121706315984	1168.3054176694475	0.04150772773211843	1217.819623171762
62.2601	1.0703904265789959	22.9656	1.84527	0.04281561706315983	1169.1606924993664	0.04192437905172021	1219.219028994718
62.6701	1.0810704265789959	22.9766	1.85707	0.043242817063159834	1169.7206938760994	0.042333955311889535	1220.302711856376
63.0801	1.0925904265789959	22.9881	1.8702	0.04370361706315983	1170.3061498608652	0.042775557453615144	1221.4527616810453
63.4901	1.1026604265789959	22.9794	1.88148	0.04410641706315983	1169.8632396810856	0.0431614163185633	1221.4617156373188
63.8901	1.1133704265789959	22.9978	1.89419	0.044534817063159836	1170.7999692567116	0.043571635171861856	1222.9413317051124
64.2901	1.124120426578996	22.9981	1.90583	0.044964817063159836	1170.8152420215315	0.04398321696785473	1223.4607351937889
64.7101	1.135040426578996	23.0009	1.91897	0.04540161706315984	1170.957787826518	0.04440113413225861	1224.1211649065424
65.1301	1.145930426578996	23.0088	1.93143	0.04583721706315984	1171.3599706334442	0.04481772930942476	1225.0518518664658
65.5701	1.1577004265789959	23.0238	1.94508	0.04630801706315983	1172.1236088744436	0.04526779367423796	1226.4023289543338
65.9901	1.1689504265789958	23.0296	1.95741	0.04675801706315983	1172.4188823276295	0.045697784892476195	1227.2388644326757
66.4001	1.1799604265789958	23.0074	1.96905	0.04719841706315983	1171.288697730951	0.046118424022609156	1226.5716701878218
66.8001	1.1907404265789958	23.034	1.98202	0.04762961706315983	1172.6428828783228	0.046530104598833465	1228.4954143416571
67.2201	1.2018304265789959	23.0412	1.99386	0.04807321706315983	1173.0094292340025	0.04695344706838751	1229.399766142702
67.6501	1.213580426578996	23.051	2.00641	0.04854321706315984	1173.5083395514553	0.04740178850101462	1230.4742096037298
68.0501	1.224450426578996	23.0401	2.01847	0.04897801706315984	1172.953429096329	0.04781637310607465	1230.4023621609008
68.4601	1.2357904265789958	23.051	2.03078	0.049431617063159836	1173.5083395514553	0.04824870052174066	1231.5167544125875
68.8701	1.2466404265789959	23.0466	2.0429	0.04986561706315983	1173.2843390007622	0.048662172229441414	1231.7908865555767
69.2801	1.257640426578996	23.05	2.05532	0.05030561706315984	1173.4574303353886	0.0490811856882377	1232.4889304657604
69.7101	1.2689404265789959	23.0526	2.0683	0.050757617063159836	1173.589794297162	0.04951144404470339	1233.1584156653298
70.1101	1.2798204265789959	23.0534	2.08035	0.05119281706315983	1173.630521670015	0.04992553564187246	1233.7119742656091
70.5301	1.2907604265789958	23.0546	2.09235	0.05163041706315983	1173.691612729295	0.05034173801134899	1234.2898001980411
70.9501	1.302310426578996	23.0542	2.1049	0.05209241706315984	1173.6712490428683	0.05078095937638121	1234.8106212430491
71.3701	1.314160426578996	23.0622	2.11821	0.052566417063159836	1174.0785227714011	0.05123138868143375	1235.7956240643014
71.7801	1.3256404265789958	23.0711	2.13038	0.053025617063159836	1174.531614794394	0.0516675605512333	1236.8118784290564
72.1901	1.336540426578996	23.0643	2.14242	0.05346161706315984	1174.185432125141	0.05208151986621306	1236.9592840585562
72.5901	1.3477704265789958	23.0662	2.15438	0.05391081706315983	1174.2821596356675	0.05250783274715335	1237.5886703243184
73.0101	1.359000426578996	23.0628	2.16685	0.054360017063159835	1174.1090683010411	0.052933963962864455	1237.9336572878963
73.4301	1.370610426578996	23.0804	2.17982	0.05482441706315984	1175.0050705038136	0.05337432375311388	1239.424038540442
73.8401	1.3820704265789958	23.0676	2.19232	0.05528281706315983	1174.3534325381609	0.0538088040485203	1239.2749985166618
74.2401	1.393270426578996	23.0706	2.20413	0.05573081706315983	1174.5061601863606	0.05423324470535292	1239.962348139261
74.6701	1.4050504265789958	23.0629	2.21673	0.05620201706315983	1174.1141592226477	nan	nan
75.0701	1.415950426578996	23.067	2.22832	0.05663801706315984	1174.3228870085209	nan	nan
75.4901	1.427850426578996	23.0653	2.24038	0.05711401706315984	1174.2363413412077	nan	nan
75.9101	1.439910426578996	23.076	2.25422	0.057596417063159835	1174.7810699531203	nan	nan
76.3501	1.452160426578996	23.0819	2.26741	0.05808641706315984	1175.0814343279135	nan	nan
76.7601	1.463810426578996	23.0664	2.27912	0.05855241706315984	1174.292341478881	nan	nan
77.1601	1.4750804265789959	23.0663	2.2911	0.059003217063159835	1174.2872505572743	nan	nan
77.5801	1.4868004265789958	23.0625	2.303	0.059472017063159834	1174.0937955362213	nan	nan
77.9901	1.498450426578996	23.0642	2.31583	0.05993801706315984	1174.1803412035345	nan	nan
78.3901	1.509770426578996	23.0576	2.32744	0.06039081706315984	1173.844340377495	nan	nan
78.8101	1.521540426578996	23.0468	2.33976	0.06086161706315984	1173.2945208439753	nan	nan
79.2101	1.533260426578996	23.0579	2.3525	0.06133041706315984	1173.8596131423149	nan	nan
79.6101	1.544740426578996	23.0585	2.36387	0.06178961706315984	1173.8901586719549	nan	nan
80.0201	1.5569704265789959	23.0536	2.37611	0.06227881706315983	1173.6407035132283	nan	nan
80.4201	1.568810426578996	23.0684	2.38903	0.06275241706315984	1174.3941599110142	nan	nan
80.8401	1.580540426578996	23.0448	2.40082	0.06322161706315983	1173.1927024118422	nan	nan
81.2601	1.5931004265789959	23.0545	2.41426	0.06372401706315983	1173.6865218076882	nan	nan
81.7001	1.605290426578996	23.0348	2.42719	0.06421161706315984	1172.683610251176	nan	nan
82.1101	1.616610426578996	23.0319	2.43851	0.06466441706315984	1172.535973524583	nan	nan
82.5101	1.6284204265789959	23.0224	2.45021	0.06513681706315984	1172.0523359719502	nan	nan
82.9301	1.640870426578996	23.0323	2.46315	0.06563481706315984	1172.5563372110096	nan	nan
83.3701	1.6542804265789959	23.0213	2.47686	0.06617121706315983	1171.9963358342768	nan	nan
83.7801	1.6664704265789958	23.0057	2.48962	0.06665881706315983	1171.2021520636376	nan	nan
84.1901	1.6779304265789958	22.9965	2.50119	0.06711721706315983	1170.7337872758249	nan	nan
84.5901	1.690080426578996	23.0104	2.51351	0.06760321706315983	1171.4414253791508	nan	nan
85.0001	1.702660426578996	23.0033	2.5262	0.06810641706315984	1171.0799699450777	nan	nan
85.4001	1.714390426578996	22.9829	2.53804	0.06857561706315984	1170.041421937319	nan	nan
85.8001	1.726560426578996	22.9795	2.55	0.06906241706315984	1169.8683306026924	nan	nan
86.2401	1.739670426578996	22.9688	2.56297	0.06958681706315983	1169.32360199078	nan	nan
86.6601	1.752050426578996	22.9665	2.5758	0.07008201706315983	1169.2065107938265	nan	nan
87.0701	1.764140426578996	22.949	2.58742	0.07056561706315984	1168.3155995126608	nan	nan
87.4801	1.776640426578996	22.9276	2.59922	0.07106561706315984	1167.2261422888355	nan	nan
87.8801	1.788850426578996	22.9136	2.61123	0.07155401706315984	1166.5134132639027	nan	nan
88.2801	1.8013404265789958	22.9053	2.62325	0.07205361706315984	1166.0908667705498	nan	nan
88.7101	1.8141804265789958	22.8851	2.63602	0.07256721706315983	1165.0625006060045	nan	nan
89.1101	1.826170426578996	22.8734	2.64751	0.07304681706315984	1164.4668627780252	nan	nan
89.5301	1.839550426578996	22.8636	2.66031	0.07358201706315984	1163.9679524605724	nan	nan
89.9601	1.8531604265789958	22.8454	2.6744	0.07412641706315984	1163.04140472816	nan	nan
90.3601	1.865120426578996	22.8081	2.68561	0.07460481706315984	1161.142490968875	nan	nan
90.7801	1.877960426578996	22.7899	2.69746	0.07511841706315985	1160.2159432364629	nan	nan
91.2001	1.891370426578996	22.7725	2.71117	0.07565481706315984	1159.330122876904	nan	nan
91.6201	1.9045504265789959	22.7539	2.72375	0.07618201706315983	1158.383211458065	nan	nan
92.0301	1.916700426578996	22.7149	2.73526	0.07666801706315984	1156.3977520314672	nan	nan
92.4301	1.929810426578996	22.6894	2.74812	0.07719241706315984	1155.0995670217685	nan	nan
92.8701	1.9431504265789958	22.6749	2.76095	0.07772601706315983	1154.3613833888028	nan	nan
93.2801	1.955840426578996	22.6292	2.77292	0.07823361706315984	1152.0348322145585	nan	nan
93.6801	1.9685104265789959	22.6145	2.78496	0.07874041706315983	1151.2864667383794	nan	nan
94.0901	1.9809804265789959	22.5833	2.79715	0.07923921706315984	1149.6980991971013	nan	nan
94.4901	1.994280426578996	22.5604	2.81009	0.07977121706315984	1148.5322781491757	nan	nan
94.9201	2.007260426578996	22.529	2.82299	0.08029041706315984	1146.933728764684	nan	nan
95.3201	2.019900426578996	22.5066	2.83403	0.08079601706315984	1145.793362324792	nan	nan
95.7401	2.033830426578996	22.4757	2.84778	0.08135321706315984	1144.2202675483338	nan	nan
96.1601	2.046920426578996	22.4247	2.8602	0.08187681706315984	1141.6238975289366	nan	nan
96.5701	2.060030426578996	22.4066	2.87292	0.08240121706315984	1140.702440718131	nan	nan
96.9801	2.072640426578996	22.365	2.88486	0.08290561706315984	1138.5846173297598	nan	nan
97.3801	2.084980426578996	22.339	2.89658	0.08339921706315984	1137.260977712028	nan	nan
97.7901	2.098550426578996	22.3089	2.90932	0.08394201706315985	1135.728610308423	nan	nan
98.1901	2.1105104265789962	22.2781	2.92049	0.08442041706315985	1134.1606064535713	nan	nan
98.6101	2.124510426578996	22.2383	2.93425	0.08498041706315984	1132.1344196541202	nan	nan
99.0401	2.137410426578996	22.1977	2.94651	0.08549641706315984	1130.067505481816	nan	nan
99.4401	2.1501804265789963	22.1776	2.95816	0.08600721706315985	1129.044230238877	nan	nan
99.8401	2.1632604265789963	22.1342	2.97002	0.08653041706315985	1126.834770261586	nan	nan
100.25	2.1767404265789962	22.0903	2.983	0.08706961706315985	1124.5998556762618	nan	nan
100.67	2.189990426578996	22.0609	2.99585	0.08759961706315984	1123.1031247239034	nan	nan
101.09	2.203270426578996	22.03	3.008	0.08813081706315984	1121.5300299474452	nan	nan
101.52	2.2166104265789963	21.982	3.01978	0.08866441706315985	1119.0863875762477	nan	nan
101.92	2.2290204265789964	21.9458	3.03225	0.08916081706315986	1117.2434739546363	nan	nan
102.33	2.242520426578996	21.91	3.04436	0.08970081706315984	1115.4209240194518	nan	nan
102.73	2.255280426578996	21.8783	3.05687	0.09021121706315985	1113.80710187014	nan	nan
103.14	2.268500426578996	21.8457	3.06858	0.09074001706315984	1112.1474614263686	nan	nan
103.54	2.281430426578996	21.806	3.08133	0.09125721706315984	1110.1263655485243	nan	nan
103.95	2.295130426578996	21.786	3.09414	0.09180521706315985	1109.108181227192	nan	nan
104.36	2.3076504265789963	21.7236	3.10589	0.09230601706315986	1105.9314461446356	nan	nan
104.76	2.320310426578996	21.6844	3.11741	0.09281241706315985	1103.9358048748243	nan	nan
105.17	2.333360426578996	21.6497	3.1294	0.09333441706315984	1102.169255077313	nan	nan
105.57	2.345850426578996	21.6179	3.1423	0.09383401706315984	1100.5503420063944	nan	nan
105.99	2.359820426578996	21.5842	3.15491	0.09439281706315984	1098.8347014249498	nan	nan
106.41	2.3728604265789963	21.5326	3.16682	0.09491441706315985	1096.2077858759126	nan	nan
106.83	2.386590426578996	21.5079	3.17992	0.09546361706315984	1094.9503282390672	nan	nan
107.25	2.400160426578996	21.4659	3.19259	0.09600641706315985	1092.8121411642699	nan	nan
107.69	2.4145504265789963	21.4163	3.2061	0.09658201706315986	1090.2870440473657	nan	nan
108.1	2.427540426578996	21.3799	3.21812	0.09710161706315984	1088.433948582541	nan	nan
108.51	2.440530426578996	21.3359	3.23057	0.09762121706315983	1086.1939430756102	nan	nan
108.91	2.453700426578996	21.3065	3.243	0.09814801706315984	1084.6972121232518	nan	nan
109.32	2.4666804265789963	21.2537	3.25438	0.09866721706315985	1082.0092055149346	nan	nan
109.72	2.4792104265789963	21.2192	3.26674	0.09916841706315985	1080.2528375606369	nan	nan
110.13	2.492390426578996	21.1758	3.279	0.09969561706315984	1078.0433775833458	nan	nan
110.53	2.505220426578996	21.1422	3.2901	0.10020881706315984	1076.3328279235077	nan	nan
110.95	2.518840426578996	21.1062	3.30339	0.10075361706315984	1074.5000961451096	nan	nan
111.37	2.532950426578996	21.0513	3.31618	0.10131801706315985	1071.7051801830528	nan	nan
111.79	2.546880426578996	21.022	3.32887	0.10187521706315984	1070.213540152301	nan	nan
112.22	2.559530426578996	20.9699	3.34064	0.10238121706315985	1067.5611699952303	nan	nan
112.62	2.5724204265789963	20.9426	3.35328	0.10289681706315985	1066.171348396612	nan	nan
113.03	2.586010426578996	20.9047	3.36584	0.10344041706315985	1064.2418891076873	nan	nan
113.43	2.598620426578996	20.8418	3.37752	0.10394481706315985	1061.0396994170976	nan	nan
113.85	2.611930426578996	20.8064	3.3902	0.10447721706315985	1059.2375131683398	nan	nan
114.28	2.625420426578996	20.7607	3.40222	0.10501681706315985	1056.9109619940955	nan	nan
114.68	2.6385204265789963	20.7282	3.41471	0.10554081706315985	1055.2564124719306	nan	nan
115.1	2.652290426578996	20.6697	3.42689	0.10609161706315984	1052.2782233320338	nan	nan
115.51	2.666090426578996	20.651	3.44067	0.10664361706315985	1051.3262209915883	nan	nan
115.91	2.678820426578996	20.575	3.45206	0.10715281706315985	1047.4571205705258	nan	nan
116.33	2.692020426578996	20.5673	3.46521	0.10768081706315984	1047.065119606813	nan	nan
116.77	2.7060304265789963	20.4999	3.47711	0.10824121706315985	1043.6338384439234	nan	nan
117.19	2.719490426578996	20.4384	3.48967	0.10877961706315985	1040.5029216558269	nan	nan
117.6	2.732480426578996	20.4143	3.50206	0.10929921706315984	1039.2760095486212	nan	nan
118	2.745440426578996	20.3845	3.51416	0.10981761706315984	1037.7589149098364	nan	nan
118.42	2.758670426578996	20.3282	3.52641	0.11034681706315984	1034.8927260452863	nan	nan
118.86	2.773120426578996	20.3049	3.54023	0.11092481706315985	1033.7065413109342	nan	nan
119.27	2.787070426578996	20.2297	3.55234	0.11148281706315984	1029.878168262725	nan	nan
119.67	2.7995104265789963	20.1918	3.56429	0.11198041706315985	1027.9487089738004	nan	nan
120.09	2.8132004265789963	20.1425	3.57705	0.11252801706315985	1025.4388846217164	nan	nan
120.5	2.826050426578996	20.1038	3.58937	0.11304201706315985	1023.4686979599386	nan	nan
120.9	2.838790426578996	20.0576	3.60089	0.11355161706315985	1021.1166921776612	nan	nan
121.34	2.8526504265789963	19.9998	3.61403	0.11410601706315986	1018.1741394890109	nan	nan
121.76	2.866580426578996	19.9768	3.62769	0.11466321706315984	1017.003227519479	nan	nan
122.19	2.880340426578996	19.897	3.63976	0.11521361706315984	1012.9406720773634	nan	nan
122.59	2.893450426578996	19.8528	3.65151	0.11573801706315985	1010.6904847272191	nan	nan
123.01	2.907190426578996	19.8255	3.66423	0.11628761706315985	1009.3006631286007	nan	nan
123.42	2.920700426578996	19.7773	3.67674	0.11682801706315984	1006.84683891419	nan	nan
123.82	2.9334604265789963	19.7219	3.68846	0.11733841706315985	1004.0264683440998	nan	nan
124.24	2.947060426578996	19.6662	3.70064	0.11788241706315984	1001.1908250091896	nan	nan
124.65	2.960080426578996	19.6167	3.71308	0.11840321706315984	998.6708188138923	nan	nan
125.05	2.972810426578996	19.5854	3.72494	0.11891241706315984	997.0773603510074	nan	nan
125.48	2.9866804265789964	19.5265	3.73726	0.11946721706315985	994.078807524684	nan	nan
125.88	2.999930426578996	19.4873	3.74974	0.11999721706315984	992.0831662548729	nan	nan
126.3	3.013150426578996	19.4207	3.76194	0.12052601706315985	988.6926124648365	nan	nan
126.71	3.026770426578996	19.3772	3.7741	0.12107081706315985	986.4780615659387	nan	nan
127.11	3.0400804265789962	19.3298	3.78675	0.12160321706315985	984.0649647243814	nan	nan
127.54	3.053870426578996	19.268	3.79916	0.12215481706315984	980.918775171465	nan	nan
127.94	3.066740426578996	19.2247	3.81117	0.12266961706315983	978.7144061157805	nan	nan
128.35	3.0804904265789963	19.1659	3.82465	0.12321961706315986	975.720944211064	nan	nan
128.76	3.093810426578996	19.1384	3.83667	0.12375241706315984	974.3209407692322	nan	nan
129.16	3.106150426578996	19.0627	3.8484	0.12424601706315984	970.4671131129896	nan	nan
129.56	3.119240426578996	19.0059	3.86001	0.12476961706315985	967.5754696404061	nan	nan
129.98	3.132520426578996	18.9655	3.8727	0.12530081706315985	965.518737311315	nan	nan
130.41	3.146800426578996	18.9117	3.88579	0.12587201706315984	962.7798214869314	nan	nan
130.81	3.160320426578996	18.8576	3.89834	0.12641281706315985	960.0256328977277	nan	nan
131.22	3.173340426578996	18.8129	3.91016	0.12693361706315984	957.74999093955	nan	nan
131.62	3.186340426578996	18.7434	3.92214	0.12745361706315983	954.2118004229208	nan	nan
132.04	3.2007404265789963	18.6933	3.93436	0.12802961706315985	951.6612486979834	nan	nan
132.47	3.214520426578996	18.6376	3.94877	0.12858081706315982	948.8256053630731	nan	nan
132.87	3.227330426578996	18.5928	3.96124	0.12909321706315985	946.5448724832889	nan	nan
133.29	3.240900426578996	18.5178	3.97284	0.12963601706315983	942.7266812782933	nan	nan
133.71	3.254140426578996	18.4675	3.9855	0.13016561706315985	940.1659477101426	nan	nan
134.13	3.268080426578996	18.4183	3.99807	0.13072321706315984	937.6612142796654	nan	nan
134.56	3.282400426578996	18.3606	4.01085	0.13129601706315985	934.723752512622	nan	nan
134.96	3.296350426578996	18.292	4.02322	0.13185401706315983	931.2313802904524	nan	nan
135.38	3.3102104265789962	18.2368	4.03695	0.13240841706315984	928.4211915635753	nan	nan
135.79	3.323210426578996	18.1746	4.04792	0.13292841706315983	925.2546383242324	nan	nan
136.19	3.336030426578996	18.1271	4.06044	0.13344121706315984	922.8364505610681	nan	nan
136.61	3.350120426578996	18.0686	4.07304	0.13400481706315984	919.8582614211714	nan	nan
137.05	3.363880426578996	17.994	4.08527	0.13455521706315984	916.0604339026022	nan	nan
137.46	3.377340426578996	17.9467	4.09756	0.13509361706315984	913.6524279826516	nan	nan
137.86	3.391590426578996	17.8896	4.11099	0.13566361706315985	910.7455117452481	nan	nan
138.28	3.405030426578996	17.827	4.12319	0.13620121706315985	907.5585948194781	nan	nan
138.69	3.418460426578996	17.7772	4.13525	0.13673841706315984	905.023315859361	nan	nan
139.09	3.431750426578996	17.7039	4.1468	0.13727001706315986	901.2916703216783	nan	nan
139.52	3.4453204265789963	17.6374	4.15918	0.13781281706315984	897.9062074532486	nan	nan
139.92	3.458860426578996	17.5654	4.17138	0.13835441706315985	894.2407438964527	nan	nan
140.33	3.472530426578996	17.5282	4.18441	0.13890121706315983	892.3469210587746	nan	nan
140.73	3.4856604265789963	17.4591	4.19621	0.13942641706315986	888.8290942285718	nan	nan
141.15	3.4990004265789962	17.3927	4.20776	0.13996001706315986	885.4487222817489	nan	nan
141.57	3.513020426578996	17.3131	4.22025	0.14052081706315986	881.3963486828466	nan	nan
141.98	3.527440426578996	17.2707	4.23339	0.14109761706315985	879.2377979216224	nan	nan
142.39	3.540790426578996	17.1859	4.24491	0.14163161706315985	874.9206963991738	nan	nan
142.79	3.553620426578996	17.1296	4.25647	0.14214481706315985	872.0545075346234	nan	nan
143.2	3.567830426578996	17.0686	4.26898	0.14271321706315984	868.9490453545601	nan	nan
143.6	3.580930426578996	17.0002	4.28078	0.14323721706315984	865.4668549756041	nan	nan
144.02	3.595310426578996	16.9231	4.29341	0.14381241706315984	861.5417544168683	nan	nan
144.46	3.6098404265789963	16.843	4.30679	0.14439361706315984	857.4639262099328	nan	nan
144.88	3.623310426578996	16.7747	4.31897	0.14493241706315985	853.9868267525832	nan	nan
145.29	3.636260426578996	16.7066	4.33104	0.14545041706315984	850.519909138447	nan	nan
145.7	3.650070426578996	16.6318	4.3427	0.14600281706315985	846.7118997766644	nan	nan
146.1	3.663650426578996	16.5687	4.35527	0.14654601706315984	843.4995282428613	nan	nan
146.51	3.677540426578996	16.5055	4.36729	0.14710161706315986	840.2820657874514	nan	nan
146.91	3.6915204265789963	16.427	4.37941	0.14766081706315984	836.2856923262225	nan	nan
147.33	3.705510426578996	16.3477	4.39132	0.14822041706315983	832.2485914921401	nan	nan
147.74	3.719550426578996	16.2661	4.40388	0.14878201706315985	828.0943994611048	nan	nan