File: original_data/46NT9B.csv
Specimen name:	AWA_2_02_Rz
Specimen ID:	46NT9B
Material:	42CrMoS4
Specimen type:	Round Tensile Specimen
Gauge diameter:	5.001	mm
Gauge length:	25	mm
Parallel length:	30	mm
Original cross-section:	19.642808851968347	mm²
Cross-section after fracture:	9.275184939732934	mm²
Yield stress at 0.2% plastic strain:	1103.2843170596245	MPa
Yield stress at 1% plastic strain:	1139.2188562583005	MPa
Ultimate tensile strength:	1192.4211133202011	MPa
Uniform elongation:	5.028851943531567	%
Elongation after fracture:	14.359302400578306	%
Reduction of area:	52.78076058453577	%
Slope of linear-elastic region:	210642.11055659756	MPa
Crosshead seperation speed:	0.029878455429505638	mm/s
Strain rate:	0.0009959485143168545	s-1
Test temperature:	RT	Cel
Machine type:	INSTRON 8852TT
Standard:	DIN EN ISO 6892-1
Date:	2022-08-23 00:00:00
Heat treatment batch:	Batch 2
Time	Displacement	Force	Machine Displacement	Engineering Strain	Engineering Stress	True Strain	True Stress
s	mm	kN	mm		MPa		MPa
0	0.0011454452402568317	0.188998	0	4.581780961027327e-05	9.621740018157386	4.581676000654827e-05	9.622180865209657
0.430001	0.0012691422402568318	0.1868	-0.000675201	5.076568961027327e-05	9.509841561242974	5.0764401076253844e-05	9.510324334907914
0.840001	0.0012222431402568318	0.184124	-0.000740051	4.888972561027327e-05	9.373608499048725	4.888853054666159e-05	9.374066772196223
1.24	0.0011901299402568317	0.189414	-0.000740051	4.760519761027327e-05	9.642918252041097	4.7604064518919416e-05	9.643377305070027
1.64	0.0022684952402568315	0.339367	0.00931931	9.073980961027326e-05	17.276907928877648	9.07356930026639e-05	17.278475632213766
2.05	0.0034675552402568316	0.547388	0.021553	0.00013870220961027327	27.867093964270182	0.00013869259134810578	27.870959191778443
2.46	0.004829465240256832	0.787573	0.0343704	0.00019317860961027327	40.0947240252292	0.00019315995302538066	40.1024694682691
2.87	0.006325365240256832	1.03161	0.0468216	0.00025301460961027326	52.51845638647679	0.00025298260681191214	52.53174432321675
3.28	0.007903205240256832	1.29601	0.0595627	0.00031612820961027325	65.97885311448881	0.0003160782516162658	65.99971089119603
3.71001	0.009484235240256832	1.55853	0.0711784	0.0003793694096102733	79.34354051629558	0.00037929746723047356	79.37364102841764
4.11001	0.011213945240256831	1.83439	0.0835838	0.0004485578096102732	93.38735686043094	0.0004484572376297769	93.42924648866955
4.51001	0.013038445240256833	2.12757	0.0960617	0.0005215378096102733	108.31292082684003	0.0005214018560346461	108.36941011032054
4.93001	0.015021545240256833	2.42687	0.107624	0.0006008618096102733	123.55004919557676	0.0006006813644312782	123.62428570171386
5.34001	0.016715745240256832	2.70352	0.1189	0.0006686298096102733	137.63408382040475	0.0006684063762897768	137.7261100716655
5.76001	0.01925934524025683	3.04574	0.132744	0.0007703738096102731	155.05623574272045	0.0007700772240184542	155.1756870057534
6.17001	0.02115874524025683	3.36085	0.14465	0.0008463498096102733	171.0982388174703	0.0008459918575643704	171.24304777931812
6.58001	0.02311144524025683	3.67697	0.156532	0.0009244578096102732	187.19166020044744	0.0009240307616611023	187.36471099261368
7.01001	0.02535214524025683	4.03065	0.1688	0.0010140858096102732	205.19723173888647	0.0010135719719500628	205.40531933976422
7.43001	0.02776124524025683	4.41348	0.182228	0.0011104498096102733	224.68680692566724	0.0011098337162719777	224.93631034763976
7.85001	0.02985954524025683	4.77032	0.194115	0.0011943818096102731	242.8532515868768	0.0011936691030960754	243.1433110929769
8.26001	0.03214854524025683	5.1817	0.206791	0.0012859418096102732	263.7962848923593	0.0012851156945894824	264.13551156432226
8.67001	0.03430984524025683	5.53498	0.218952	0.001372393809610273	281.78149274437175	0.0013714529379584316	282.1682079206768
9.08001	0.03643974524025683	5.93625	0.231701	0.0014575898096102732	302.2098338754208	0.001456528556706213	302.65033184964165
9.48001	0.03876824524025683	6.33396	0.243351	0.0015507298096102732	322.4569381972728	0.0015495286697409637	322.956981783651
9.91001	0.04104024524025683	6.74137	0.256203	0.0016416098096102732	343.1978619149709	0.0016402638410623076	343.7612588917278
10.33	0.04347514524025683	7.16046	0.269135	0.0017390058096102732	364.53340527632696	0.0017374954897238816	365.1673309858995
10.75	0.04592064524025683	7.58179	0.281071	0.0018368258096102732	385.98298528167226	0.0018351409080144222	386.691968791108
11.17	0.04830414524025683	8.00601	0.293003	0.0019321658096102731	407.5796929214501	0.0019303015782022703	408.3672044688044
11.57	0.05079454524025683	8.41248	0.30505	0.0020317818096102732	428.2727619760455	0.002029720532520653	429.14291878337997
11.98	0.05330494524025683	8.84336	0.317802	0.002132197809610273	450.208524994827	0.0021299279018828126	451.1684586256888
12.38	0.05555974524025683	9.25123	0.329975	0.0022223898096102733	470.97286695191565	0.0022199239540963574	472.01955225203255
12.78	0.05799514524025683	9.65547	0.342121	0.0023198058096102732	491.55240845468256	0.0023171192142306687	492.69271458754366
13.19	0.06035274524025683	10.0697	0.354286	0.002414109809610273	512.6405330259549	0.0024112005278002146	513.8781035655367
13.61	0.06288124524025683	10.478	0.365959	0.002515249809610273	533.4267659459523	0.0025120918630492203	534.7684675174389
14.02	0.06535534524025684	10.9033	0.378754	0.0026142138096102736	555.078455539082	0.002610802696315526	556.5295493029695
14.44	0.06787884524025684	11.3323	0.391453	0.0027151538096102735	576.9185092316583	0.002711474438040344	578.4849317198332
14.84	0.07052684524025683	11.757	0.403786	0.0028210738096102733	598.5396532951481	0.002817102048890536	600.2281778350722
15.25	0.07283354524025684	12.1507	0.415928	0.0029133418096102736	618.582611660573	0.0029091062537810156	620.3847542458217
15.66	0.07539924524025683	12.5868	0.427937	0.003015969809610273	640.7841207872222	0.0030114308965238147	642.716706349994
16.08	0.07804804524025684	13.0144	0.440285	0.0031219218096102735	662.552901577305	0.0031170587305239797	664.6213399307597
16.49	0.08030314524025683	13.3972	0.452385	0.0032121258096102735	682.0409494876037	0.0032069779542621647	684.2317508246639
16.9	0.08293574524025683	13.8406	0.465202	0.003317429809610273	704.6140958915393	0.0033119392789552	706.9516036975215
17.32	0.08550954524025683	14.2686	0.477642	0.0034203818096102735	726.4032403680487	0.0034145456079875333	728.8878167978456
17.75	0.08808904524025683	14.6759	0.48983	0.0035235618096102735	747.1385640719795	0.003517368609515735	749.7711529828307
18.18	0.09078674524025683	15.1247	0.502922	0.0036314698096102734	769.9866202426747	0.003624891943193498	772.7828034078898
18.57	0.09316954524025683	15.5051	0.514111	0.0037267818096102735	789.3524860344136	0.003719854563836582	792.2942305207373
18.98	0.09544424524025684	15.8975	0.52594	0.0038177698096102737	809.3292624189518	0.003810500621966522	812.419095243049
19.39	0.09823984524025683	16.349	0.539185	0.003929593809610273	832.3147734730268	0.003921893122977241	835.5854324545135
19.8	0.10079964524025684	16.7616	0.55154	0.004031985809610273	853.3199160221106	0.004023879138176027	856.7604898145696
20.22	0.10352444524025683	17.1739	0.563889	0.0041409778096102735	874.3097858063744	0.004132427557143392	877.9302832281237
20.63	0.10582044524025684	17.5814	0.576054	0.004232817809610274	895.0552913535183	0.004223884635765318	898.8438973313454
21.04	0.10834644524025684	17.9643	0.588364	0.004333857809610274	914.5484301854241	0.004324493693270652	918.5119530418501
21.46	0.11105944524025683	18.3779	0.600426	0.004442377809610274	935.6044819505744	0.004432539575316907	939.7607905397635
21.87	0.11339044524025683	18.7886	0.612797	0.004535617809610273	956.5128969891314	0.004525362891719835	960.8512739198372
22.29	0.11591344524025683	19.176	0.625153	0.004636537809610273	976.2351272933367	0.004625822177702444	980.761478372102
22.69	0.11836844524025683	19.5689	0.638107	0.004734737809610273	996.2373582859082	0.004723564194093084	1000.9542809735308
23.1	0.12090444524025684	19.9562	0.649971	0.0048361778096102735	1015.9544976685067	0.00482452106931219	1020.8678342657049
23.53	0.12370244524025684	20.3915	0.662868	0.004948097809610273	1038.1152794223026	0.0049358962069063605	1043.2519753625352
23.95	0.12647344524025683	20.7621	0.675365	0.005058937809610273	1056.9822348965886	0.005046184378189341	1062.3294422887932
24.36	0.12960044524025685	21.1411	0.687962	0.005184017809610274	1076.2768277858345	0.005170627047978971	1081.856266029147
24.77	0.13324244524025683	21.4375	0.700333	0.005329697809610273	1091.366319427978	0.0053155452339362485	1097.1829721101155
25.19	0.13894444524025684	21.659	0.71302	0.005557777809610274	1102.6427107867323	0.005542390349581419	1108.7709539766713
25.59	0.14693244524025684	21.6985	0.725216	0.005877297809610274	1104.6536248213636	0.00586009387037651	1111.146003150904
26	0.15790944524025682	21.6976	0.73782	0.006316377809610273	1104.6078065269037	0.006296513100085013	1111.5849267643725
26.41	0.16919344524025684	21.6755	0.749947	0.006767737809610274	1103.4827128518314	0.0067449394763715274	1110.95079452985
26.82	0.18105244524025685	21.6715	0.76215	0.007242097809610274	1103.279075987565	0.007215999746666476	1111.2691309671634
27.23	0.19146844524025683	21.7278	0.774483	0.0076587378096102735	1106.1452648521151	0.007629558566607118	1114.6169414149595
27.64	0.20193944524025684	21.801	0.787403	0.008077577809610274	1109.8718194681912	0.008045128800454023	1118.8368954486393
28.06	0.21230344524025685	21.8382	0.80024	0.008492137809610273	1111.765642305869	0.008456282456714093	1121.2069093523205
28.47	0.22164944524025684	21.8561	0.811264	0.008865977809610273	1112.6769172734614	0.008826905799575043	1122.5418861312735
28.87	0.23143244524025683	21.923	0.823586	0.009257297809610272	1116.0827438283177	0.009214711648337521	1126.4146541681034
29.27	0.24095944524025684	21.9745	0.836231	0.009638377809610273	1118.7045684557481	0.009592224968245825	1129.4870657438616
29.74	0.2516544452402568	22.0061	0.849567	0.010066177809610272	1120.3132996834531	0.010015851290429905	1131.590572560538
30.09	0.26017044524025684	22.0455	0.860619	0.010406817809610273	1122.3191227964776	0.01035303966559346	1133.998893431662
30.49	0.26962644524025686	22.0664	0.871811	0.010785057809610275	1123.38312541227	0.01072731388367042	1135.498877362182
30.9	0.2799814452402568	22.1272	0.884781	0.011199257809610272	1126.4784057491195	0.01113701044026003	1139.0941278320627
31.32	0.29051844524025683	22.1643	0.898396	0.011620737809610274	1128.367137665191	0.011553735613050767	1141.4795963249785
31.74	0.3013824452402568	22.1921	0.911514	0.012055297809610272	1129.7824138718427	0.011983211476806335	1143.402277331128
32.14	0.31068644524025685	22.18	0.922535	0.012427457809610274	1129.1664123574367	0.012350870824023943	1143.1990803070375
32.56	0.32155844524025684	22.2317	0.935135	0.012862337809610274	1131.7984188280807	0.012780320483647294	1146.35599242343
32.98	0.33186544524025685	22.2419	0.947853	0.013274617809610274	1132.3176928319601	0.0131872821202206	1147.3487774433643
33.38	0.3416614452402568	22.2683	0.95937	0.013666457809610273	1133.6616961361185	0.013573913985936048	1149.1548358767338
33.8	0.35218144524025685	22.2947	0.971256	0.014087257809610274	1135.0056994402769	0.013988954533315489	1150.9948173436692
34.21	0.3621604452402568	22.3127	0.983963	0.014486417809610273	1135.922065329476	0.014382492130642008	1152.3775069669941
34.62	0.37286144524025683	22.3429	0.996647	0.014914457809610274	1137.459523654688	0.014804330922070412	1154.4241157303752
35.04	0.3834614452402568	22.3765	1.00934	0.015338457809610273	1139.1700733145258	0.015222012879724295	1156.6431854220314
35.46	0.39443144524025686	22.3933	1.0222	0.015777257809610274	1140.025348144445	0.015654090681547477	1158.0118219716105
35.8701	0.4046304452402568	22.392	1.03348	0.016185217809610273	1139.9591661635584	0.016055633535194097	1158.4096535619772
36.2801	0.41534744524025685	22.4326	1.04676	0.016613897809610274	1142.0260803358628	0.016477396810336015	1160.9995849304726
36.6801	0.42532044524025686	22.4279	1.0579	0.017012817809610274	1141.7868070203497	0.016869720536271487	1161.2118179456036
37.0901	0.43539844524025684	22.4544	1.0704	0.017415937809610274	1143.135901246115	0.017266018518358645	1163.0446850101503
37.5001	0.44560644524025683	22.4792	1.08247	0.017824257809610274	1144.3984498045668	0.017667268460608246	1164.7965028108015
37.9201	0.45673944524025684	22.5049	1.0957	0.018269577809610273	1145.7068166574786	0.018104694279900437	1166.6383964914032
38.3301	0.46661544524025683	22.515	1.1074	0.018664617809610273	1146.2209997397515	0.018492571321586413	1167.6147766252434
38.7301	0.4764174452402568	22.5247	1.11857	0.019056697809610272	1146.7148191355977	0.01887739333020273	1168.5674169176668
39.1501	0.48718844524025684	22.5676	1.13141	0.019487537809610274	1148.8988245048552	0.019300087131874304	1171.2880337868103
39.5601	0.49801044524025684	22.5715	1.14453	0.019920417809610274	1149.097370447515	0.0197246024970401	1171.987870170754
39.9701	0.5082874452402568	22.5926	1.15662	0.02033149780961027	1150.1715549065207	0.02012757234837644	1173.5562653557786
40.4001	0.5189674452402568	22.6023	1.16928	0.020758697809610274	1150.6653743023667	0.020546172180128126	1174.5516890874917
40.7901	0.5291404452402568	22.6388	1.18216	0.021165617809610272	1152.523560688798	0.020944737398509605	1176.9174338909081
41.2101	0.5391494452402569	22.6435	1.19398	0.021565977809610275	1152.7628340043111	0.021336722332785784	1177.6232917021914
41.6101	0.5493734452402569	22.685	1.20623	0.021974937809610275	1154.8755664710754	0.021736968789642975	1180.2538852221157
42.0201	0.5595344452402569	22.6708	1.21785	0.022381377809610276	1154.1526556029296	0.022134590282774647	1179.9841822379437
42.4201	0.5697664452402569	22.6909	1.2298	0.022790657809610274	1155.1759308458684	0.02253483045654532	1181.5031501956746
42.8401	0.5803574452402568	22.7179	1.24226	0.023214297809610273	1156.550479679667	0.02294894480645524	1183.3989869467985
43.2501	0.5907814452402569	22.7482	1.25481	0.023631257809610274	1158.0930289264852	0.023356361970513155	1185.4602238605594
43.6701	0.6012624452402568	22.7457	1.26691	0.024050497809610275	1157.9657558863187	0.023765839668605127	1185.8154087618664
44.0801	0.6120054452402568	22.7814	1.28033	0.024480217809610273	1159.7832148998968	0.024185379393371235	1188.1749606125763
44.4801	0.6219504452402569	22.7897	1.29216	0.024878017809610277	1160.2057613932498	0.02457359849346037	1189.0693809880033
44.9101	0.6321074452402569	22.7949	1.30394	0.025284297809610275	1160.470489316796	0.02496993784885979	1189.8121707679459
45.3201	0.6423334452402568	22.8119	1.3167	0.02569333780961027	1161.3359459899284	0.025368811047981502	1191.1745427606909
45.7301	0.6522534452402569	22.8413	1.32798	0.026090137809610274	1162.8326769422868	0.025755596505279532	1193.1711417332292
46.1401	0.6627114452402568	22.8434	1.3407	0.026508457809610274	1162.9395862960266	0.02616319690672601	1193.7673212544803
46.5601	0.6733754452402568	22.8748	1.3533	0.026935017809610273	1164.5381356805183	0.026578655146702043	1195.9049911050433
46.9601	0.6835304452402569	22.8877	1.3661	0.027341217809610276	1165.1948645677774	0.026974122901477042	1197.0527111505642
47.3701	0.6933684452402569	22.8826	1.3778	0.027734737809610274	1164.9352275658377	0.02735709658547523	1197.2444006675548
47.7701	0.7037534452402568	22.92	1.38983	0.028150137809610273	1166.8392322467291	0.027761204821864657	1199.6859174361343
48.1901	0.7144644452402569	22.9238	1.40175	0.028578577809610275	1167.0326872677822	0.028177827590772985	1200.3848217272232
48.5901	0.7248234452402569	22.9418	1.41436	0.028992937809610275	1167.949053156981	0.028580593669576056	1201.8113274199548
49.0001	0.7342754452402568	22.9457	1.42623	0.02937101780961027	1168.147599099641	0.02894795339060084	1202.45728303705
49.4201	0.7448814452402568	22.9546	1.43852	0.029795257809610273	1168.6006911226339	0.02936000365679411	1203.4194499911216
49.8301	0.7553954452402568	22.9785	1.45147	0.030215817809610274	1169.817421386626	0.02976831214680204	1205.1644114617525
50.2401	0.7654224452402568	23.0012	1.46399	0.030616897809610272	1170.973060591338	0.030157552866850717	1206.8246231252695
50.6401	0.7753124452402569	22.9983	1.47491	0.031012497809610275	1170.8254238647446	0.030541326988131758	1207.135644757786
51.0501	0.7860344452402568	23.0211	1.48775	0.031441377809610274	1171.9861539910637	0.030957219931243663	1208.835013446329
51.4701	0.7970844452402568	23.0525	1.50144	0.03188337780961027	1173.5847033755551	0.031385654675272504	1211.0025478648574
51.8801	0.8072244452402568	23.0474	1.51336	0.03228897780961027	1173.3250663736155	0.03177864511923022	1211.2105334052128
52.2901	0.8174174452402568	23.0552	1.52533	0.03269669780961027	1173.722158258935	0.03217353406215334	1212.0989969799712
52.7101	0.8277254452402568	23.0723	1.53782	0.03310901780961027	1174.592705853674	0.0325727197187305	1213.4823166708218
53.1201	0.8380714452402568	23.1005	1.54982	0.03352285780961027	1176.0283457467524	0.032973216788783274	1215.4521767612919
53.5501	0.8485504452402568	23.0942	1.56244	0.03394201780961027	1175.7076176855328	0.03337869889460874	1215.6135065839098
53.9401	0.8587404452402568	23.1114	1.57388	0.034349617809610274	1176.5832562018786	0.033772840608723986	1216.9984413736
54.3601	0.8691134452402568	23.1099	1.58682	0.03476453780961027	1176.5068923777787	0.03417390113449023	1217.407610721113
54.7601	0.8795204452402569	23.149	1.59936	0.03518081780961027	1178.497442725983	0.03457611465619696	1219.9579465476174
55.1801	0.8899694452402568	23.1541	1.61151	0.03559877780961027	1178.7570797279227	0.03497978871842927	1220.719391100662
55.6001	0.9008234452402568	23.1635	1.624	0.036032937809610276	1179.2356263589488	0.035398936584416126	1221.7269503464177
56.0101	0.9116184452402568	23.1803	1.63605	0.03646473780961027	1180.090901188868	0.035815631870811604	1223.1226064922269
56.4301	0.9214084452402569	23.1548	1.64825	0.03685633780961028	1178.7927161791695	0.036193383304741956	1222.238698734177
56.8301	0.9323234452402568	23.1977	1.661	0.03729293780961027	1180.9767215484271	0.03661437518954064	1225.01881297973
57.2401	0.9422144452402569	23.1749	1.67222	0.037688577809610276	1179.8159914221083	0.03699571835025457	1224.281578215843
57.6501	0.9528134452402568	23.1977	1.68429	0.03811253780961027	1180.9767215484271	0.037404196795231714	1225.986741500711
58.0701	0.9636234452402568	23.2143	1.69692	0.03854493780961027	1181.821814535133	0.03782063524146127	1227.3750628784305
58.4801	0.9739824452402568	23.2392	1.70919	0.03895929780961027	1183.0894540151914	0.0382195369605434	1229.1817883895785
58.8901	0.9843724452402568	23.2309	1.72176	0.039374897809610274	1182.6669075218383	0.03861947264597409	1229.2342961483184
59.2901	0.9950024452402568	23.2551	1.73446	0.039800097809610274	1183.8989105506505	0.03902848103326566	1231.0182029872574
59.6901	1.0051354452402568	23.2435	1.74578	0.04020541780961027	1183.3083636442777	0.03941821077396751	1230.8837708022022
60.1001	1.0157554452402568	23.2673	1.75843	0.04063021780961027	1184.520002986663	0.0398265082854382	1232.6473087078514
60.5201	1.026205445240257	23.2608	1.77053	0.04104821780961028	1184.18909308223	0.04022810730137235	1232.7979449028344
60.9401	1.0373054452402568	23.2813	1.78405	0.04149221780961027	1185.2327320115958	0.04065450959266344	1234.4106666833002
61.3501	1.0480054452402567	23.2929	1.7963	0.04192021780961027	1185.8232789179683	0.041065373998293006	1235.5332490539158
61.7701	1.0588654452402568	23.2923	1.80895	0.04235461780961027	1185.7927333883283	0.041482209627516364	1236.0165314124042
62.1701	1.068805445240257	23.3006	1.82046	0.04275221780961028	1186.2152798816812	0.04186358097792092	1236.9286138962707
62.5801	1.0792054452402569	23.3054	1.83291	0.043168217809610276	1186.459644118801	0.042262445669413055	1237.676992458434
62.9801	1.0897354452402568	23.3099	1.84465	0.04358941780961027	1186.6887355911008	0.0426661341462449	1238.4158066967395
63.4001	1.100735445240257	23.3102	1.8572	0.044029417809610276	1186.7040083559207	0.04308766704200916	1238.953894956163
63.8001	1.1112554452402568	23.3369	1.86911	0.04445021780961027	1188.0632844248994	0.04349063961451355	1240.872956189187
64.2101	1.122195445240257	23.3416	1.8827	0.04488781780961028	1188.3025577404123	0.04390952827583942	1241.642866454958
64.6301	1.132695445240257	23.3457	1.89478	0.045307817809610275	1188.5112855262855	0.044311404538994174	1242.360138315576
65.0401	1.1435854452402567	23.3462	1.90681	0.04574341780961027	1188.5367401343187	0.044728037090967156	1242.904472820355
65.4701	1.1547554452402569	23.3408	1.91953	0.04619021780961027	1188.2618303675592	0.04515520170000282	1243.147903127083
65.8701	1.1655354452402569	23.3617	1.93249	0.04662141780961027	1189.3258329833513	0.04556727892545664	1244.7738895546308
66.2901	1.1762454452402569	23.3494	1.94434	0.047049817809610275	1188.6996496257318	0.0459765122364852	1244.62775157097
66.7001	1.186865445240257	23.3628	1.95628	0.04747461780961028	1189.3818331210246	0.04638214131256609	1245.847281078139
67.1101	1.1982954452402568	23.3896	1.9697	0.04793181780961027	1190.7462001116098	0.046818524440424635	1247.8208300328452
67.5301	1.2095254452402568	23.3734	1.98168	0.04838101780961027	1189.9214708113307	0.04724708643674763	1247.4910826826913
67.9301	1.220075445240257	23.3651	1.99297	0.04880301780961028	1189.4989243179778	0.04764953085605315	1247.5500615059805
68.3301	1.2306454452402569	23.3625	2.00506	0.04922581780961027	1189.3665603562044	0.04805257584623189	1247.914101965142
68.7401	1.2415254452402569	23.3852	2.01767	0.049661017809610276	1190.5221995609168	0.048467271863998226	1249.6447437160477
69.1501	1.2523654452402568	23.37	2.0292	0.050094617809610276	1189.748379476704	0.04888027230920042	1249.3483698361927
69.5601	1.263155445240257	23.3915	2.04201	0.05052621780961028	1190.8429276221364	0.049291198449467985	1251.0117167602064
69.9701	1.274745445240257	23.3924	2.05514	0.050989817809610274	1190.888745916596	0.049732403750462846	1251.6119461023984
70.3901	1.286035445240257	23.3848	2.0671	0.05144141780961028	1190.5018358744899	0.05016200163627669	1251.7429382168177
70.8201	1.2975054452402568	23.396	2.07992	0.05190021780961027	1191.072019094436	0.05059825982610843	1252.8889163123695
71.2301	1.3090654452402568	23.3904	2.09287	0.052362617809610275	1190.7869274844631	0.051037748657651524	1253.1396482610123
71.6401	1.3201054452402567	23.4033	2.10482	0.05280421780961027	1191.4436563717225	0.05145728785901578	1254.3569067106532
72.0601	1.3311254452402568	23.387	2.11644	0.05324501780961027	1190.6138361498365	0.05187589156398297	1254.008091060003
72.4701	1.3426154452402568	23.3807	2.12942	0.05370461780961027	1190.293108088617	0.0523121620846637	1254.2173445399294
72.8701	1.353585445240257	23.386	2.14108	0.054143417809610274	1190.5629269337699	0.052728510890577264	1255.0240729153775
73.2801	1.364535445240257	23.4	2.15337	0.054581417809610275	1191.2756559587024	0.05314392782777113	1256.2971702630018
73.6901	1.3759354452402568	23.4025	2.16623	0.05503741780961027	1191.402928998869	0.053576233417200435	1256.9746697817732
74.1001	1.3868054452402567	23.3973	2.1783	0.05547221780961027	1191.1382010753227	0.05398826660464796	1257.2132788067204
74.5101	1.398865445240257	23.4225	2.19151	0.05595461780961028	1192.4211133202011	nan	nan
74.9201	1.409845445240257	23.4009	2.20282	0.056393817809610274	1191.3214742531625	nan	nan
75.3301	1.421945445240257	23.4128	2.21531	0.05687781780961028	1191.9272939243551	nan	nan
75.7501	1.433705445240257	23.4118	2.22828	0.057348217809610275	1191.8763847082885	nan	nan
76.1601	1.4448554452402569	23.3977	2.24021	0.05779421780961028	1191.1585647617494	nan	nan
76.5801	1.4560654452402568	23.3942	2.25269	0.05824261780961027	1190.9803825055162	nan	nan
76.9801	1.4674054452402567	23.4019	2.26491	0.05869621780961027	1191.3723834692291	nan	nan
77.3801	1.4785254452402568	23.3922	2.27636	0.05914101780961027	1190.878564073383	nan	nan
77.7901	1.4902354452402569	23.3989	2.28971	0.05960941780961027	1191.2196558210292	nan	nan
78.2001	1.5011454452402568	23.3824	2.30069	0.060045817809610276	1190.3796537559301	nan	nan
78.6201	1.5135554452402569	23.4038	2.31352	0.06054221780961028	1191.4691109797554	nan	nan
79.0401	1.525765445240257	23.394	2.32674	0.06103061780961028	1190.970200662303	nan	nan
79.4601	1.5377354452402567	23.3882	2.33878	0.06150941780961027	1190.6749272091165	nan	nan
79.8701	1.5499154452402568	23.3965	2.35177	0.06199661780961027	1191.0974737024694	nan	nan
80.2701	1.5614454452402569	23.3896	2.36371	0.06245781780961027	1190.7462001116098	nan	nan
80.6901	1.5731754452402569	23.3946	2.37655	0.06292701780961027	1191.0007461919429	nan	nan
81.1001	1.5843954452402569	23.3763	2.38761	0.06337581780961027	1190.0691075379239	nan	nan
81.5101	1.5967454452402567	23.3773	2.40073	0.06386981780961026	1190.1200167539905	nan	nan
81.9301	1.6086954452402569	23.3669	2.4127	0.06434781780961027	1189.5905609068977	nan	nan
82.3401	1.620125445240257	23.3561	2.42448	0.06480501780961027	1189.0407413733783	nan	nan
82.7401	1.632195445240257	23.3475	2.43644	0.06528781780961028	1188.6029221152053	nan	nan
83.1401	1.6441754452402568	23.3527	2.44887	0.06576701780961028	1188.8676500387517	nan	nan
83.5401	1.6561354452402568	23.3681	2.46165	0.06624541780961027	1189.6516519661775	nan	nan
83.9601	1.6680654452402568	23.3486	2.47385	0.06672261780961027	1188.6589222528787	nan	nan
84.3701	1.6802354452402568	23.3375	2.48576	0.06720941780961028	1188.0938299545392	nan	nan
84.7901	1.6923654452402568	23.3372	2.49808	0.06769461780961027	1188.0785571897193	nan	nan
85.2001	1.704215445240257	23.325	2.51085	0.06816861780961028	1187.4574647537065	nan	nan
85.6001	1.7160654452402568	23.3128	2.52269	0.06864261780961027	1186.836372317694	nan	nan
86.0301	1.729025445240257	23.3082	2.5355	0.06916101780961027	1186.6021899237876	nan	nan
86.4501	1.7417154452402568	23.2901	2.54878	0.06966861780961027	1185.680733112982	nan	nan
86.8701	1.7543054452402569	23.2823	2.56104	0.07017221780961028	1185.2836412276622	nan	nan
87.2801	1.7665554452402568	23.2975	2.57318	0.07066221780961027	1186.057461311875	nan	nan
87.6901	1.7791054452402568	23.2623	2.58552	0.07116421780961027	1184.26545690633	nan	nan
88.1001	1.7912354452402568	23.2492	2.59768	0.07164941780961027	1183.5985461758573	nan	nan
88.5201	1.8036154452402569	23.2354	2.60991	0.07214461780961028	1182.8959989941382	nan	nan
88.9301	1.816475445240257	23.231	2.62297	0.07265901780961027	1182.671998443445	nan	nan
89.3401	1.828435445240257	23.215	2.63459	0.07313741780961028	1181.8574509863795	nan	nan
89.7401	1.8413254452402568	23.2004	2.64717	0.07365301780961027	1181.1141764318068	nan	nan
90.1501	1.8532854452402567	23.1694	2.65915	0.07413141780961027	1179.5359907337418	nan	nan
90.5501	1.8657054452402568	23.1745	2.67106	0.07462821780961028	1179.7956277356816	nan	nan
90.9601	1.8792554452402568	23.1473	2.68355	0.07517021780961027	1178.41089705867	nan	nan
91.3701	1.891445445240257	23.1068	2.69504	0.07565781780961028	1176.349073807972	nan	nan
91.7801	1.9039254452402568	23.1006	2.70764	0.07615701780961028	1176.033436668359	nan	nan
92.1901	1.9167054452402568	23.09	2.71994	0.07666821780961026	1175.493798978053	nan	nan
92.5901	1.9291454452402568	23.065	2.73189	0.07716581780961027	1174.2210685763878	nan	nan
93.0201	1.9420554452402568	23.0206	2.74461	0.07768221780961027	1171.9606993830303	nan	nan
93.4401	1.9553854452402568	23.0182	2.75718	0.07821541780961028	1171.8385172644703	nan	nan
93.8501	1.9679854452402568	22.9756	2.76857	0.07871941780961027	1169.6697846600325	nan	nan
94.2601	1.9807154452402569	22.9505	2.78129	0.07922861780961027	1168.3919633367607	nan	nan
94.6701	1.9933054452402568	22.9295	2.7935	0.07973221780961028	1167.3228697993618	nan	nan
95.0901	2.006785445240257	22.9139	2.80622	0.08027141780961028	1166.5286860287229	nan	nan
95.5001	2.020155445240257	22.8641	2.81824	0.08080621780961028	1163.9934070686056	nan	nan
95.9001	2.032195445240257	22.8411	2.83065	0.08128781780961028	1162.8224950990736	nan	nan
96.3101	2.045275445240257	22.8134	2.84293	0.08181101780961027	1161.4123098140285	nan	nan
96.7301	2.057915445240257	22.773	2.85486	0.08231661780961028	1159.3555774849372	nan	nan
97.1301	2.0704054452402567	22.7516	2.86723	0.08281621780961027	1158.2661202611116	nan	nan
97.5401	2.083865445240257	22.7371	2.88102	0.08335461780961027	1157.527936628146	nan	nan
97.9501	2.0961654452402567	22.6803	2.89215	0.08384661780961027	1154.6362931555623	nan	nan
98.3801	2.1098654452402568	22.6513	2.90549	0.08439461780961027	1153.1599258896306	nan	nan
98.7901	2.122785445240257	22.6249	2.91781	0.08491141780961028	1151.8159225854722	nan	nan
99.2001	2.1362254452402567	22.5797	2.93045	0.08544901780961027	1149.5148260192614	nan	nan
99.6201	2.1487754452402568	22.5436	2.94268	0.08595101780961027	1147.6770033192568	nan	nan
100.03	2.162035445240257	22.5128	2.95502	0.08648141780961029	1146.1089994644049	nan	nan
100.45	2.175285445240257	22.4901	2.96812	0.08701141780961028	1144.953360259693	nan	nan
100.85	2.1873954452402566	22.4583	2.98064	0.08749581780961027	1143.334447188775	nan	nan
101.26	2.200785445240257	22.4242	2.99322	0.08803141780961027	1141.5984429209034	nan	nan
101.66	2.213485445240257	22.384	3.00497	0.08853941780961028	1139.5518924350254	nan	nan
102.06	2.226355445240257	22.3541	3.01743	0.08905421780961027	1138.0297068746338	nan	nan
102.47	2.238815445240257	22.3065	3.02855	0.08955261780961027	1135.6064281898632	nan	nan
102.87	2.2515354452402567	22.2713	3.04093	0.09006141780961027	1133.8144237843183	nan	nan
103.29	2.264645445240257	22.2284	3.05364	0.09058581780961028	1131.6304184150608	nan	nan
103.71	2.278155445240257	22.223	3.0665	0.09112621780961028	1131.355508648301	nan	nan
104.12	2.291745445240257	22.178	3.07913	0.09166981780961027	1129.0645939253036	nan	nan
104.54	2.304625445240257	22.1223	3.09134	0.09218501780961028	1126.2289505903932	nan	nan
104.95	2.317105445240257	22.0834	3.10308	0.09268421780961028	1124.2485820854022	nan	nan
105.35	2.3298354452402568	22.0624	3.11503	0.09319341780961027	1123.1794885480033	nan	nan
105.78	2.343605445240257	21.9978	3.12783	0.09374421780961027	1119.8907531901004	nan	nan
106.2	2.356835445240257	21.9728	3.14056	0.09427341780961028	1118.618022788435	nan	nan
106.62	2.370475445240257	21.946	3.15312	0.09481901780961027	1117.2536557978497	nan	nan
107.03	2.383085445240257	21.894	3.16485	0.09532341780961028	1114.606376562386	nan	nan
107.45	2.3966554452402566	21.8797	3.17814	0.09586621780961027	1113.8783747726334	nan	nan
107.85	2.409525445240257	21.8352	3.18999	0.09638101780961028	1111.6129146576693	nan	nan
108.27	2.422605445240257	21.7694	3.20206	0.09690421780961028	1108.2630882404862	nan	nan
108.68	2.4357854452402568	21.7556	3.21486	0.09743141780961027	1107.560541058767	nan	nan
109.09	2.448065445240257	21.7033	3.22626	0.09792261780961027	1104.8979890584833	nan	nan
109.49	2.460635445240257	21.6692	3.23817	0.09842541780961028	1103.1619847906118	nan	nan
109.91	2.474505445240257	21.6322	3.25143	0.09898021780961028	1101.2783437961473	nan	nan
110.32	2.487955445240257	21.5803	3.26348	0.09951821780961029	1098.6361554822902	nan	nan
110.72	2.5002354452402566	21.5515	3.27479	0.10000941780961027	1097.1699700595716	nan	nan
111.13	2.513075445240257	21.504	3.28706	0.10052301780961027	1094.7517822964076	nan	nan
111.55	2.526725445240257	21.4605	3.2995	0.10106901780961028	1092.53723139751	nan	nan
111.96	2.540125445240257	21.4303	3.3118	0.10160501780961027	1090.9997730722982	nan	nan
112.37	2.552215445240257	21.3895	3.32371	0.10208861780961027	1088.9226770567807	nan	nan
112.79	2.5654554452402567	21.3559	3.33673	0.10261821780961027	1087.2121273969424	nan	nan
113.2	2.579125445240257	21.317	3.34865	0.10316501780961028	1085.2317588919514	nan	nan
113.61	2.591665445240257	21.2738	3.36126	0.10366661780961028	1083.0324807578738	nan	nan
114.02	2.605135445240257	21.233	3.37352	0.10420541780961028	1080.955384742356	nan	nan
114.42	2.617815445240257	21.187	3.38483	0.10471261780961028	1078.6135608032919	nan	nan
114.84	2.6313354452402566	21.1472	3.39723	0.10525341780961027	1076.5873740038408	nan	nan
115.26	2.6442954452402567	21.0962	3.40937	0.10577181780961027	1073.9910039844435	nan	nan
115.65	2.657005445240257	21.0672	3.42212	0.10628021780961028	1072.5146367185118	nan	nan
116.07	2.6704554452402567	21.0244	3.43428	0.10681821780961026	1070.335722270861	nan	nan
116.48	2.6836854452402568	20.9708	3.44642	0.10734741780961027	1067.6069882896904	nan	nan
116.88	2.696065445240257	20.9253	3.45789	0.10784261780961028	1065.2906189586597	nan	nan
117.29	2.7086954452402567	20.8916	3.47004	0.10834781780961027	1063.574978377215	nan	nan
117.7	2.721735445240257	20.8537	3.48186	0.10886941780961028	1061.6455190882903	nan	nan
118.12	2.7357254452402566	20.8244	3.49444	0.10942901780961027	1060.1538790575387	nan	nan
118.52	2.7485554452402567	20.7803	3.50623	0.10994221780961028	1057.908782629001	nan	nan
118.93	2.7615754452402568	20.7163	3.51826	0.11046301780961026	1054.650592800738	nan	nan
119.35	2.774835445240257	20.6865	3.53119	0.11099341780961028	1053.133498161953	nan	nan
119.76	2.788085445240257	20.6338	3.54346	0.11152341780961027	1050.4505824752425	nan	nan
120.17	2.800715445240257	20.612	3.5563	0.11202861780961028	1049.3407615649903	nan	nan
120.58	2.8138254452402567	20.5493	3.56814	0.11255301780961027	1046.1487537176138	nan	nan
120.99	2.826545445240257	20.5059	3.57952	0.11306181780961028	1043.939293740323	nan	nan
121.41	2.8398654452402567	20.4659	3.59233	0.11359461780961028	1041.9029250976587	nan	nan
121.83	2.8536754452402566	20.4217	3.60564	0.11414701780961027	1039.6527377475143	nan	nan
122.23	2.866255445240257	20.3775	3.61693	0.11465021780961028	1037.40255039737	nan	nan
122.64	2.8799854452402567	20.3244	3.62918	0.11519941780961027	1034.699271024233	nan	nan
123.05	2.8923154452402566	20.2774	3.64147	0.11569261780961027	1032.3065378691024	nan	nan
123.46	2.9060254452402567	20.2127	3.65404	0.11624101780961027	1029.0127115895925	nan	nan
123.86	2.918815445240257	20.169	3.66615	0.11675261780961028	1026.7879788474816	nan	nan
124.28	2.931755445240257	20.1456	3.67867	0.11727021780961028	1025.5967031915231	nan	nan
124.68	2.9449854452402566	20.0985	3.69144	0.11779941780961027	1023.1988791147855	nan	nan
125.09	2.957635445240257	20.0449	3.70292	0.11830541780961028	1020.4701451336151	nan	nan
125.51	2.9713754452402568	20.0132	3.71684	0.11885501780961027	1018.8563229843037	nan	nan
125.91	2.983875445240257	19.9541	3.72776	0.11935501780961028	1015.847588314767	nan	nan
126.33	2.9976754452402568	19.9197	3.74078	0.11990701780961027	1014.0963112820752	nan	nan
126.73	3.0101454452402567	19.8558	3.75199	0.12040581780961027	1010.843212375419	nan	nan
127.15	3.023985445240257	19.813	3.76484	0.12095941780961027	1008.6642979277681	nan	nan
127.56	3.0375354452402568	19.7624	3.77744	0.12150141780961027	1006.0882915947974	nan	nan
127.97	3.049975445240257	19.704	3.78868	0.12199901780961028	1003.1151933765074	nan	nan
128.4	3.064185445240257	19.6753	3.80295	0.12256741780961028	1001.6540988753957	nan	nan
128.79	3.076135445240257	19.6091	3.81337	0.12304541780961027	998.2839087717862	nan	nan
129.2	3.089335445240257	19.5765	3.82673	0.12357341780961027	996.6242683280145	nan	nan
129.62	3.102995445240257	19.5142	3.8387	0.12411981780961029	993.4526241670644	nan	nan
130.02	3.115875445240257	19.4601	3.85047	0.12463501780961028	990.698435577861	nan	nan
130.42	3.1288454452402568	19.4135	3.86265	0.12515381780961027	988.3260661091568	nan	nan
130.85	3.143105445240257	19.351	3.87566	0.12572421780961027	985.1442401049936	nan	nan
131.25	3.155995445240257	19.3082	3.88792	0.12623981780961027	982.9653256573428	nan	nan
131.67	3.1688954452402567	19.2666	3.89988	0.12675581780961026	980.8475022689718	nan	nan
132.08	3.182415445240257	19.202	3.91225	0.12729661780961027	977.5587669110686	nan	nan
132.49	3.1956154452402568	19.1544	3.92564	0.12782461780961027	975.1354882262978	nan	nan
132.9	3.208435445240257	19.0894	3.9372	0.12833741780961028	971.8263891819682	nan	nan
133.32	3.221595445240257	19.0442	3.94992	0.1288638178096103	969.5252926157574	nan	nan
133.74	3.235715445240257	18.9987	3.96392	0.1294286178096103	967.2089232847266	nan	nan
134.15	3.2491554452402567	18.9303	3.97525	0.12996621780961026	963.7267329057703	nan	nan
134.56	3.262075445240257	18.8738	3.98685	0.13048301780961027	960.8503621980068	nan	nan
134.96	3.2751254452402567	18.8306	3.99943	0.13100501780961027	958.6510840639293	nan	nan
135.38	3.288635445240257	18.7571	4.01194	0.13154541780961027	954.9092566830334	nan	nan
135.79	3.3023054452402567	18.6946	4.02414	0.13209221780961028	951.7274306788702	nan	nan
136.21	3.315755445240257	18.6578	4.03725	0.13263021780961026	949.8539715276189	nan	nan
136.62	3.328585445240257	18.6028	4.04924	0.13314341780961028	947.053964643955	nan	nan
137.05	3.341515445240257	18.5419	4.0616	0.13366061780961028	943.9535933854984	nan	nan
137.44	3.3549154452402568	18.4765	4.07454	0.13419661780961026	940.6241306547421	nan	nan
137.85	3.368215445240257	18.4198	4.08675	0.13472861780961026	937.7375781037653	nan	nan
138.27	3.382585445240257	18.3635	4.09939	0.13530341780961028	934.8713892392151	nan	nan
138.68	3.395475445240257	18.3085	4.11177	0.13581901780961028	932.0713823555515	nan	nan
139.09	3.4092154452402568	18.2517	4.12408	0.13636861780961027	929.179738882968	nan	nan
139.5	3.4220754452402566	18.1955	4.13641	0.13688301780961026	926.3186409400244	nan	nan
139.91	3.435725445240257	18.1311	4.14914	0.13742901780961028	923.0400874253346	nan	nan
140.32	3.448545445240257	18.077	4.1611	0.13794181780961026	920.285898836131	nan	nan
140.74	3.461955445240257	18.009	4.17286	0.13847821780961028	916.8240721436014	nan	nan
141.14	3.474995445240257	17.9529	4.18525	0.13899981780961027	913.9680651222645	nan	nan
141.56	3.488735445240257	17.891	4.19786	0.13954941780961028	910.8167846477413	nan	nan
141.98	3.5026754452402566	17.8302	4.2107	0.14010701780961027	907.7215043108913	nan	nan
142.4	3.516735445240257	17.776	4.22321	0.1406694178096103	904.962224800081	nan	nan
142.81	3.530425445240257	17.7017	4.23492	0.14121701780961027	901.1796700463316	nan	nan
143.23	3.543855445240257	17.6127	4.24739	0.14175421780961028	896.6487498164034	nan	nan
143.64	3.556815445240257	17.5717	4.25922	0.14227261780961029	894.5614719576723	nan	nan
144.04	3.5695954452402567	17.5196	4.27127	0.14278381780961028	891.909101800602	nan	nan
144.46	3.5834754452402566	17.4587	4.28481	0.14333901780961025	888.8087305421453	nan	nan
144.87	3.597145445240257	17.3786	4.29678	0.14388581780961027	884.7309023352096	nan	nan
145.29	3.610855445240257	17.3071	4.30951	0.14443421780961027	881.090893386447	nan	nan
145.7	3.6241654452402567	17.2544	4.32085	0.14496661780961026	878.4079776997366	nan	nan
146.11	3.637945445240257	17.1727	4.33337	0.14551781780961026	874.2486947470945	nan	nan
146.51	3.6514154452402567	17.094	4.34542	0.14605661780961027	870.2421394426522	nan	nan
146.92	3.6644154452402566	17.041	4.35723	0.14657661780961026	867.5439509911217	nan	nan
147.33	3.678235445240257	16.9779	4.37015	0.14712941780961028	864.3315794573186	nan	nan
147.75	3.691965445240257	16.883	4.38191	0.14767861780961028	859.5002948525972	nan	nan