File: original_data/46NTA5.csv
Specimen name:	AWA_3_03_Rz
Specimen ID:	46NTA5
Material:	42CrMoS4
Specimen type:	Round Tensile Specimen
Gauge diameter:	5.005	mm
Gauge length:	25	mm
Parallel length:	30	mm
Original cross-section:	19.674243628060164	mm²
Cross-section after fracture:	9.734162201644443	mm²
Yield stress at 0.2% plastic strain:	1090.2693151348315	MPa
Yield stress at 1% plastic strain:	1135.3664602381584	MPa
Ultimate tensile strength:	1187.9389338589992	MPa
Uniform elongation:	4.847164614075007	%
Elongation after fracture:	13.099755554594974	%
Reduction of area:	50.52332183301215	%
Slope of linear-elastic region:	207815.34734739337	MPa
Crosshead seperation speed:	0.029967912599107215	mm/s
Strain rate:	0.0009989304199702405	s-1
Test temperature:	RT	Cel
Machine type:	INSTRON 8852TT
Standard:	DIN EN ISO 6892-1
Date:	2022-09-06 00:00:00
Heat treatment batch:	Batch 3
Time	Displacement	Force	Machine Displacement	Engineering Strain	Engineering Stress	True Strain	True Stress
s	mm	kN	mm		MPa		MPa
0	0.000998368386021635	0.164994	0	3.9934735440865394e-05	8.38629444258173	3.993393807063069e-05	8.386629347031626
0.430001	0.0008636623860216349	0.155527	-0.0018692	3.4546495440865394e-05	7.905106947958161	3.454589872433747e-05	7.905380041699297
0.840001	0.000970359086021635	0.163501	-0.001091	3.88143634408654e-05	8.310408424891547	3.8813610182973385e-05	8.310730988104492
1.24	0.000872000386021635	0.155641	-0.00147247	3.48800154408654e-05	7.910901325732228	3.487940714723643e-05	7.9111772580926205
1.66	0.0017515613860216348	0.295713	0.0093689	7.00624554408654e-05	15.0304634623027	7.006000118163597e-05	15.031516533479284
2.08	0.002806078386021635	0.47874	0.0215683	0.0001122431354408654	24.33333697856636	0.00011223683665138096	24.336068228604574
2.48	0.004113338386021635	0.672174	0.033844	0.0001645335354408654	34.16517619215204	0.0001645200012831554	34.17079750937989
2.89	0.005713198386021635	0.909016	0.0460663	0.00022852793544086538	46.20335181290154	0.0002285018269097859	46.213910569501785
3.3	0.007364318386021636	1.16136	0.057991	0.00029457273544086543	59.029461155173635	0.0002945293574110828	59.046849625017714
3.71001	0.008949848386021635	1.41941	0.0698547	0.00035799393544086537	72.14559435340034	0.00035792987090123014	72.17142203864763
4.12001	0.010772418386021634	1.69778	0.0823364	0.00043089673544086533	86.29454997591677	0.00043080392610250767	86.33173401578773
4.54001	0.012704968386021634	2.02088	0.0954971	0.0005081987354408654	102.71703645662612	0.000508069646197069	102.76923712466161
4.94001	0.014893768386021635	2.31852	0.106857	0.0005957507354408654	117.84544523446063	0.0005955733464210323	117.9156517451274
5.35001	0.016727268386021635	2.63343	0.120193	0.0006690907354408654	133.851651417191	0.0006688669940314828	133.94121031707772
5.77001	0.018845768386021634	2.96032	0.13253	0.0007538307354408654	150.46677554495042	0.00075354674776217	150.58020202501888
6.18001	0.020918568386021633	3.28811	0.144508	0.0008367427354408653	167.12764476039987	0.0008363928613942172	167.26748760304446
6.59001	0.023299568386021634	3.65656	0.157272	0.0009319827354408654	185.855175381933	0.0009315487091802915	186.0283891966813
7.02001	0.025527468386021636	4.02389	0.170013	0.0010210987354408653	204.5257787832297	0.0010205777687359156	204.7346197973103
7.44001	0.027689468386021633	4.38717	0.182159	0.0011075787354408652	222.99052928992143	0.001106965822637651	223.23750885836765
7.86001	0.030371168386021635	4.78273	0.195099	0.0012148467354408654	243.0960036084277	0.0012141094062465103	243.39132799481015
8.27001	0.03261206838602164	5.1518	0.207237	0.0013044827354408656	261.85504751259174	0.001303632637049534	262.19663290126
8.67001	0.03492236838602164	5.55965	0.220146	0.0013968947354408656	282.5851964174426	0.0013959199856328432	282.97993819063163
9.08001	0.03720706838602164	5.93102	0.231483	0.0014882827354408656	301.4611444345922	0.001487176340306944	301.9098038512604
9.48001	0.03961426838602164	6.3252	0.244171	0.0015845707354408655	321.49647628530715	0.0015833166278731063	322.00591019317625
9.89001	0.041988068386021635	6.72778	0.256935	0.0016795227354408655	341.9587622877954	0.0016781139143422846	342.533089803641
10.3	0.04439796838602164	7.11086	0.269432	0.0017759187354408656	361.4299047236671	0.0017743436562961301	362.07177486301447
10.71	0.04676056838602164	7.51168	0.281357	0.0018704227354408656	381.8027336657839	0.0018686756729939457	382.51686617928584
11.12	0.04920616838602164	7.91641	0.293419	0.0019682467354408656	402.37429959997604	0.0019663122757485646	403.16627150158905
11.53	0.05176546838602164	8.32527	0.306305	0.0020706187354408655	423.1557846587901	0.0020684779591121486	424.0319789545148
11.95	0.05442166838602164	8.76353	0.319702	0.0021768667354408657	445.4316092488107	0.002174500793986351	446.40125450189834
12.37	0.056833468386021636	9.16571	0.33165	0.0022733387354408655	465.87356410121464	0.002270758610529789	466.9326525203038
12.78	0.059301268386021636	9.56096	0.344231	0.0023720507354408654	485.9632817784054	0.002369241864075035	487.1160113383451
13.18	0.061586668386021635	9.94089	0.355644	0.0024634667354408654	505.2743164073621	0.002460437375394332	506.51904287810424
13.58	0.06383366838602163	10.3241	0.36718	0.002553346735440865	524.7520664670112	0.00255009248397629	526.0919404428406
13.99	0.06646666838602162	10.755	0.380142	0.002658666735440865	546.6537978954782	0.0026551387328411385	548.1071681637453
14.41	0.06889016838602163	11.1599	0.392776	0.002755606735440865	567.2340045684562	0.0027518170115966405	568.797078412016
14.82	0.07132806838602163	11.546	0.404564	0.002853122735440865	586.8586471874654	0.002849060306007955	588.5330269362461
15.24	0.07379066838602164	11.971	0.417519	0.0029516267354408655	608.4604941521868	0.002947279237940449	610.2564424141859
15.66	0.07616106838602163	12.3654	0.429497	0.0030464427354408652	628.5070081354482	0.0030418117317784635	630.4217187445562
16.07	0.07882776838602164	12.7992	0.441856	0.0031531107354408655	650.5561404020274	0.003148150106658363	652.6074159523359
16.49	0.08105886838602164	13.1704	0.45282	0.0032423547354408656	669.4234476803911	0.003237109637911987	671.5939559659927
16.89	0.08359576838602163	13.5842	0.465645	0.0033438307354408652	690.4560224427479	0.0033382525649601797	692.7647905120622
17.3	0.08597146838602163	13.9747	0.478172	0.0034388587354408653	710.3043077126861	0.00343295938156735	712.7469438860851
17.72	0.08833436838602163	14.3905	0.490814	0.003533374735440865	731.4385382254652	0.0035271470324911656	734.0229846769589
18.13	0.09084056838602163	14.7922	0.503212	0.0036336227354408653	751.8560956977677	0.0036270370767271776	754.5880571008748
18.55	0.09336086838602163	15.1961	0.515526	0.0037344347354408653	772.3854744955347	0.003727479045712064	775.2698976406408
18.95	0.09567096838602163	15.6035	0.527832	0.0038268387354408653	793.0927508565405	0.0038195350155957397	796.1277889163156
19.37	0.09827436838602163	16.0115	0.540512	0.003930974735440866	813.8305239426732	0.003923268642624579	817.0296711712224
19.78	0.10057476838602163	16.391	0.552284	0.004022990735440865	833.1197025852889	0.004014920146241402	836.4713354303027
20.19	0.10298436838602162	16.7969	0.563843	0.004119374735440865	853.7507371334782	0.004110913340480424	857.2676563503899
20.59	0.10534636838602163	17.1864	0.576469	0.004213854735440865	873.5481945282049	0.00420500131222065	877.2291997243534
20.99	0.10772236838602163	17.5833	0.588707	0.004308894735440865	893.7217781994945	0.00429963802977429	897.5727312645271
21.4	0.11009636838602163	17.9479	0.599625	0.004403854735440865	912.2536215014647	0.004394186142833991	916.271053932437
21.81	0.11244836838602162	18.3433	0.612144	0.004497934735440865	932.3509633599372	0.00448784925823552	936.5446171436555
22.23	0.11532636838602163	18.7566	0.625664	0.0046130547354408654	953.3581241846884	0.004602447208004665	957.7560173940296
22.64	0.11743436838602163	19.1474	0.637558	0.004697374735440865	973.22165781719	0.004686376499181168	977.7932446446043
23.04	0.11953136838602163	19.4883	0.648804	0.004781254735440865	990.548880476657	0.004769860840660172	995.2849470021217
23.46	0.12229536838602163	19.8953	0.66114	0.004891814735440866	1011.2358256875784	0.004879888687269698	1016.1826040006827
23.87	0.12492736838602163	20.2616	0.673889	0.004997094735440865	1029.8540763774079	0.004984650696354171	1035.0003547607457
24.27	0.12824536838602163	20.6077	0.68589	0.005129814735440865	1047.4456039879726	0.005116702060442082	1052.8188058818828
24.68	0.13186536838602164	20.8822	0.697258	0.005274614735440866	1061.3978557334221	0.005260752678444795	1066.996320503439
25.1	0.13724136838602163	21.0947	0.710274	0.005489654735440865	1072.1987792157827	0.005474641500804318	1078.0847803214385
25.51	0.14521436838602164	21.198	0.723167	0.005808574735440866	1077.4492987250903	0.005791770008153253	1083.7077435003832
25.93	0.15452836838602163	21.2329	0.735085	0.006181134735440865	1079.223191569958	0.006162109878684742	1085.8940155266644
26.33	0.16353236838602164	21.3028	0.746735	0.006541294735440866	1082.7760600472147	0.0065199933091773	1089.858817388463
26.74	0.17223736838602163	21.3818	0.759048	0.006889494735440866	1086.7914621888922	0.006865870610043163	1094.2789062461645
27.15	0.18088536838602162	21.4439	0.771362	0.007235414735440865	1089.9478732395019	0.007209364701968256	1097.8340981424012
27.57	0.18966136838602163	21.5337	0.783501	0.007586454735440865	1094.5122164334596	0.007557822308937152	1102.8156838208192
27.98	0.19800236838602164	21.6091	0.795235	0.007920094735440865	1098.3446382243774	0.00788889541126482	1107.0436318112781
28.39	0.20676336838602163	21.6501	0.807335	0.008270534735440866	1100.4285811080326	0.008236521274024484	1109.5297139119584
28.79	0.21540436838602164	21.7291	0.819527	0.008616174735440865	1104.4439832497103	0.008579267350698756	1113.9600655948962
29.2	0.22410436838602163	21.7855	0.831535	0.008964174735440865	1107.3106754116168	0.008924235027988175	1117.2368017924255
29.6	0.23302536838602164	21.8339	0.843819	0.009321014735440865	1109.7707445718347	0.009277842145138738	1120.1149340349498
30.03	0.24258636838602163	21.8832	0.856911	0.009703454735440865	1112.2765588197421	0.009656678568725232	1123.0694840615415
30.45	0.25203736838602164	21.9221	0.869232	0.010081494735440866	1114.2537631654543	0.010031015454950179	1125.487106612752
30.86	0.26106236838602165	21.9697	0.881821	0.010442494735440866	1116.6731700255032	0.010388348508873324	1128.3340237247025
31.27	0.2706653683860216	22.0094	0.89505	0.010826614735440864	1118.6910366713842	0.010768426552736144	1130.802673533416
31.68	0.2800893683860216	22.0501	0.906227	0.011203574735440864	1120.7597311924765	0.01114127954605945	1133.316246601364
32.08	0.28965036838602165	22.0866	0.918434	0.011586014735440867	1122.614948637682	0.011519410822340152	1135.6215819748243
32.5	0.2990693683860216	22.1076	0.930458	0.011962774735440863	1123.6823340171152	0.011891786330471155	1137.1246926531564
32.9	0.30868836838602165	22.1448	0.942772	0.012347534735440866	1125.5731309749683	0.012271925682460027	1139.4711843069608
33.31	0.3185653683860216	22.1747	0.955688	0.012742614735440866	1127.0928844437806	0.012662110786185411	1141.4549948413044
33.72	0.32831336838602165	22.1993	0.967155	0.013132534735440866	1128.3432501739737	0.013047050603347207	1143.1612571003839
34.13	0.33783736838602163	22.2265	0.980179	0.013513494735440865	1129.7257683797159	0.013423001804442248	1144.992311603207
34.53	0.34740536838602165	22.2377	0.992165	0.013896214735440867	1130.2950405820804	0.013800547598721721	1146.001863180413
34.96	0.3575833683860216	22.266	1.00451	0.014303334735440865	1131.7334694505548	0.01420200711543855	1147.921032095408
35.37	0.3678013683860216	22.3041	1.01754	0.014712054735440865	1133.670011496098	0.014604882330332645	1150.3486267571564
35.7801	0.3775863683860216	22.3284	1.02977	0.015103454735440865	1134.905128863728	0.014990533147389446	1152.046117106541
36.1901	0.3877963683860216	22.3388	1.04189	0.015511854735440865	1135.4337387659234	0.015392775761834183	1153.0464219833789
36.5901	0.39739736838602163	22.3627	1.05391	0.015895894735440865	1136.648524983469	0.01577087809473627	1154.7165702878003
37.0201	0.4072263683860216	22.3854	1.06583	0.016289054735440865	1137.8023177507612	0.016157811385436618	1156.3360419827147
37.4401	0.4174833683860216	22.4021	1.0787	0.016699334735440864	1138.651143266787	0.01656143396163521	1157.6658598550914
37.8601	0.4273383683860216	22.4231	1.09092	0.017093534735440865	1139.7185286462202	0.016949084061951385	1159.20034690426
38.2801	0.43758336838602163	22.4468	1.10387	0.017503334735440867	1140.9231492887232	0.017351915710511163	1160.893109078137
38.6901	0.44750636838602165	22.4637	1.11597	0.017900254735440865	1141.7821403797911	0.017741931731986647	1162.2203315449663
39.1101	0.4573393683860216	22.4886	1.1287	0.018293574735440864	1143.0477544725477	0.018128260380270843	1163.958183995169
39.5201	0.4671013683860216	22.5019	1.14056	0.018684054735440866	1143.7237652128554	0.01851165192972474	1165.0931626443169
39.9201	0.4770813683860216	22.5358	1.15251	0.019083254735440865	1145.446830182512	0.018903453293159626	1167.3056838287882
40.3401	0.48755336838602165	22.5426	1.16528	0.019502134735440865	1145.7924597339475	0.01931440493448755	1168.1378586625312
40.7501	0.4970133683860216	22.5669	1.17735	0.019880534735440866	1147.0275771015777	0.01968549762837675	1169.8310986906542
41.1701	0.5072253683860216	22.5856	1.18993	0.020289014735440866	1147.9780583680251	0.02008593494062287	1171.2694021102168
41.5801	0.5169203683860216	22.5962	1.20208	0.020676814735440866	1148.5168338452631	0.020465951106564656	1172.2645036392166
42.0001	0.5270423683860216	22.6161	1.21568	0.021081694735440863	1149.528308561964	0.02086255041390583	1173.7623134528149
42.4001	0.5367653683860216	22.6495	1.22826	0.021470614735440863	1151.2259595940152	0.02124336808295337	1175.9434886458964
42.8101	0.5465753683860216	22.6492	1.23991	0.021863014735440865	1151.2107112314518	0.021627446335436635	1176.3796479747023
43.2201	0.5562643683860217	22.6651	1.25273	0.022250574735440867	1152.0188744473082	0.02200664248837089	1177.6519565098365
43.6301	0.5658343683860216	22.6884	1.26441	0.022633374735440866	1153.2031639397273	0.02238104026734558	1179.3040432952712
44.0501	0.5759713683860216	22.7023	1.27696	0.023038854735440862	1153.9096714051616	0.022777467416786903	1180.4944287024853
44.4601	0.5857023683860216	22.7152	1.28939	0.023428094735440864	1154.565350995385	0.02315786936248603	1181.6146174167623
44.8601	0.5952893683860216	22.7244	1.30187	0.023811574735440866	1155.032967447327	0.023532500638153108	1182.536121273597
45.2801	0.6049563683860216	22.747	1.31385	0.024198254735440863	1156.1816774270983	0.023910116017757825	1184.1592561779287
45.6901	0.6152113683860216	22.7726	1.3265	0.024608454735440866	1157.4828710325028	0.024310544231492932	1185.966735871354
46.1001	0.6248473683860216	22.7788	1.33875	0.024993894735440864	1157.7980038588114	0.02468665621696492	1186.735885292162
46.5201	0.6346813683860216	22.7989	1.35204	0.025387254735440866	1158.819644150555	0.025070350736325214	1188.238893649038
46.9301	0.6443133683860216	22.8021	1.36358	0.025772534735440864	1158.9822933512303	0.025446021131687927	1188.8522047643858
47.3401	0.6546093683860217	22.8319	1.37636	0.026184374735440868	1160.4969640325214	0.025847433075212776	1190.8838514180904
47.7501	0.6640883683860216	22.8463	1.38924	0.026563534735440864	1161.2288854355613	0.026216850091849507	1192.075229269626
48.1601	0.6742893683860216	22.8715	1.40118	0.026971574735440863	1162.5097478908813	0.02661425260373077	1193.8644664367987
48.5701	0.6836663683860217	22.8781	1.4132	0.027346654735440866	1162.8452118672747	0.02697941511729563	1194.6451383869696
48.9901	0.6937823683860216	22.8892	1.42614	0.027751294735440864	1163.4094012821179	0.027373206571696288	1195.6955184750807
49.4001	0.7037793683860216	22.9004	1.43852	0.028151174735440865	1163.9786734844824	0.027762213356775575	1196.7460405100708
49.8201	0.7135963683860216	22.9195	1.45105	0.028543854735440865	1164.9494859010144	0.028144068711259084	1198.2016348006996
50.2301	0.7232743683860217	22.9273	1.46246	0.028930974735440866	1165.3459433276612	0.028520374655830804	1199.0605373721223
50.6401	0.7329113683860217	22.947	1.475	0.029316454735440867	1166.34725246932	0.028894945758398547	1200.5404189021428
51.0401	0.7429433683860216	22.9443	1.48763	0.029717734735440864	1166.21001720625	0.029284720738466677	1200.8671371433995
51.4501	0.7523933683860217	22.9674	1.49939	0.030095734735440867	1167.3841411236267	0.029651744267388775	1202.517424569244
51.8801	0.7631903683860216	22.9927	1.51275	0.030527614735440866	1168.6700863664678	0.030070918403637053	1204.3467965158977
52.3001	0.7734103683860216	22.9997	1.52519	0.030936414735440863	1169.0258814929455	0.03046752974345618	1205.1913509992758
52.7101	0.7831473683860216	23.0156	1.53748	0.03132589473544087	1169.8340447088021	0.030845250853755255	1206.480142851285
53.1201	0.7930323683860216	23.0227	1.54949	0.031721294735440865	1170.194922622801	0.03122856734487511	1207.3150206612352
53.5301	0.8023783683860216	23.0391	1.56113	0.032095134735440865	1171.0284997762633	0.03159084763177503	1208.6128172556234
53.9501	0.8125663683860216	23.0446	1.57412	0.03250265473544087	1171.3080530899242	0.03198561702208505	1209.3786743283474
54.3601	0.8224583683860216	23.06	1.58621	0.03289833473544086	1172.0908023681754	0.032368767806710184	1210.650637924815
54.7701	0.8320393683860217	23.0663	1.59783	0.03328157473544087	1172.4110179820054	0.03273973260279439	1211.430702897628
55.1701	0.8418463683860217	23.0808	1.61039	0.033673854735440864	1173.1480221725665	0.03311930537840114	1212.6524382543753
55.5801	0.8521063683860216	23.0944	1.6227	0.03408425473544086	1173.8392812754375	0.03351625703682696	1213.8487183568966
55.9901	0.8614783683860217	23.1003	1.63429	0.03445913473544086	1174.139165739183	0.03387871499251908	1214.5989854495476
56.3901	0.8715693683860216	23.1159	1.64603	0.03486277473544087	1174.9320805924765	0.03426883313051578	1215.8934730476149
56.8201	0.8816503683860216	23.1165	1.65883	0.035266014735440866	1174.962577317603	0.03465841276164892	1216.3988248828773
57.2201	0.8920263683860217	23.1362	1.67161	0.035681054735440865	1175.9638864592619	0.03505923421351026	1217.9235182589166
57.6401	0.9020753683860216	23.1441	1.68419	0.036083014735440865	1176.3654266734297	0.035447270680564504	1218.8122376983504
58.0501	0.9115303683860216	23.152	1.69574	0.03646121473544087	1176.7669668875974	0.035812232739101	1219.6733199608595
58.4801	0.9216543683860217	23.1611	1.70911	0.03686617473544087	1177.2295005520186	0.03620287051990322	1220.629449023085
58.8801	0.9322613683860216	23.1786	1.72166	0.03729045473544086	1178.1189883682127	0.03661198138442457	1222.051581176921
59.2901	0.9419453683860216	23.1749	1.73306	0.037677814735440865	1177.930925229932	0.036985346134333345	1222.3127884018918
59.7001	0.9526883683860217	23.1972	1.74548	0.038107534735440866	1179.0643868471393	0.03739937738881564	1223.995623924238
60.1201	0.9627203683860216	23.1973	1.75853	0.03850881473544086	1179.0694696346607	0.03778585224739689	1224.4740374010364
60.5301	0.9724943683860217	23.2105	1.77004	0.038899774735440866	1179.7403975874472	0.038162244264448544	1225.6320332998985
60.9401	0.9829793683860216	23.201	1.78196	0.039319174735440866	1179.2575327729417	0.038565859105705064	1225.6249657621258
61.3601	0.9931303683860216	23.216	1.79447	0.03972521473544086	1180.0199509011084	0.038956461641388	1226.8964968427592
61.7601	1.0035983683860217	23.2347	1.80672	0.04014393473544087	1180.9704321675563	0.03935910236113088	1228.379232120976
62.1801	1.0133383683860218	23.2419	1.81847	0.04053353473544087	1181.3363928690762	0.03973359577519421	1229.2201325836754
62.5801	1.0239783683860217	23.2458	1.83042	0.04095913473544087	1181.5346215823995	0.040142533084629055	1229.929257342381
62.9901	1.0345683683860218	23.2555	1.84293	0.04138273473544087	1182.0276519719473	0.04054938271105559	1230.9431887434584
63.4001	1.0454483683860218	23.257	1.85548	0.041817934735440876	1182.1038937847638	0.0409672013232602	1231.5370372655655
63.8101	1.0555783683860218	23.2633	1.86714	0.04222313473544087	1182.4241093985938	0.04135606122726287	1232.3497618841643
64.2301	1.0664783683860217	23.2682	1.87969	0.04265913473544087	1182.6731659871284	0.04177431026965738	1233.1249799229636
64.6301	1.0768083683860217	23.2766	1.89112	0.043072334735440865	1183.1001201389015	0.0421705261885844	1234.0590045390647
65.0501	1.0873483683860217	23.2849	1.90357	0.043493934735440866	1183.521991503154	0.04257463509411582	1234.998019759551
65.4501	1.0976383683860218	23.2792	1.91499	0.04390553473544087	1183.2322726144505	0.04296900139664142	1235.182718259819
65.8601	1.1087183683860218	23.3032	1.9283	0.04434873473544087	1184.452141619517	0.04339347078538745	1236.9810954550258
66.2701	1.1188083683860217	23.2909	1.94042	0.044752334735440866	1183.8269587544205	0.0437798570746095	1236.8059790814373
66.6901	1.1297683683860218	23.3112	1.95193	0.04519073473544087	1184.858764621206	0.04419939003972619	1238.403402752165
67.0901	1.1404183683860218	23.3053	1.96432	0.045616734735440874	1184.5588801574604	0.044606888111275354	1238.594588372114
67.5001	1.1513783683860217	23.3167	1.97729	0.046055134735440866	1185.138317934867	0.04502607432572722	1239.720022847491
67.9101	1.1618583683860217	23.3171	1.98912	0.04647433473544087	1185.1586490849515	0.04542673774454536	1240.2381088571285
68.3101	1.1723483683860216	23.3244	2.00101	0.046893934735440866	1185.5296925739926	0.04582762277919393	1241.1238446044847
68.7201	1.1832583683860218	23.3234	2.01388	0.04733033473544088	1185.4788646987813	0.04624438808239309	1241.587976186765
69.1401	1.1943783683860218	23.3388	2.02689	0.04777513473544087	1186.2616139770325	0.04666899678411665	1242.9354224162669
69.5701	1.2053583683860218	23.336	2.03933	0.04821433473544087	1186.1192959264415	0.04708808286524951	1243.3072486964045
69.9901	1.2159983683860218	23.3355	2.05091	0.04863993473544087	1186.0938819888358	0.04749402429097569	1243.7854109988787
70.3801	1.2266083683860218	23.3435	2.06306	0.049064334735440876	1186.5005049905249	0.04789865711931764	1244.7153629311497
70.8101	1.2379983683860218	23.3369	2.07669	0.049519934735440876	1186.1650410141315	0.04833285460548543	1244.903856430613
71.2301	1.2492083683860218	23.342	2.08912	0.04996833473544087	1186.424263177708	0.04876000631987047	1245.7079078984207
71.6501	1.2603983683860218	23.3454	2.10114	0.05041593473544087	1186.597077953426	0.049186214050790496	1246.4204787927908
72.0701	1.2716883683860218	23.3504	2.11388	0.050867534735440874	1186.8512173294816	0.04961604659220061	1247.2234128527894
72.4901	1.2828683683860218	23.3522	2.12645	0.051314734735440876	1186.9427075048616	0.05004150922999415	1247.8503576866394
72.9001	1.2939283683860217	23.3535	2.13962	0.051757134735440864	1187.0087837426358	0.05046222714548498	1248.4449572949552
73.3101	1.3047783683860217	23.3429	2.15079	0.05219113473544087	1186.4700082653983	0.05087478482330744	1248.3932243263373
73.7101	1.3155283683860217	23.3436	2.1633	0.05262113473544087	1186.5055877780458	0.051283372336995946	1248.9408581768678
74.1301	1.3268883683860218	23.3576	2.17581	0.05307553473544087	1187.2171780310016	0.051714963471314074	1250.229364602098
74.5501	1.3381183683860218	23.3502	2.18853	0.05352473473544087	1186.8410517544394	0.052141432615288016	1250.3664042227274
74.9601	1.3495783683860216	23.3645	2.20055	0.05398313473544086	1187.5678903699581	0.0525764487913786	1251.6765278032829
75.3701	1.3603083683860218	23.3582	2.21294	0.05441233473544087	1187.2476747561282	nan	nan
75.7801	1.3720483683860218	23.3609	2.22569	0.054881934735440875	1187.3849100191983	nan	nan
76.2001	1.3827083683860217	23.3647	2.23719	0.05530833473544087	1187.5780559450004	nan	nan
76.6101	1.3940783683860218	23.3701	2.24974	0.055763134735440874	1187.8525264711404	nan	nan
77.0201	1.4052683683860216	23.3638	2.26222	0.056210734735440866	1187.5323108573104	nan	nan
77.4301	1.4163183683860217	23.3603	2.27436	0.056652734735440864	1187.3544132940715	nan	nan
77.8401	1.4281583683860217	23.3495	2.28696	0.05712633473544087	1186.8054722417914	nan	nan
78.2601	1.4396283683860218	23.3429	2.29978	0.05758513473544087	1186.4700082653983	nan	nan
78.6701	1.4508983683860217	23.3523	2.31131	0.058035934735440865	1186.9477902923825	nan	nan
79.0701	1.4616283683860218	23.3337	2.32279	0.05846513473544088	1186.002391813456	nan	nan
79.4901	1.4733983683860217	23.3493	2.33578	0.05893593473544087	1186.7953066667492	nan	nan
79.9001	1.4851283683860217	23.3487	2.34908	0.059405134735440866	1186.7648099416226	nan	nan
80.3001	1.4960083683860217	23.3325	2.3605	0.05984033473544087	1185.9413983632026	nan	nan
80.7101	1.5073583683860217	23.3485	2.37279	0.060294334735440866	1186.7546443665804	nan	nan
81.1201	1.5189083683860218	23.3375	2.38528	0.06075633473544087	1186.195537739258	nan	nan
81.5401	1.5304483683860217	23.3374	2.39758	0.06121793473544087	1186.190454951737	nan	nan
81.9601	1.5422583683860218	23.3276	2.41082	0.061690334735440874	1185.6923417746682	nan	nan
82.3701	1.5544683683860216	23.3251	2.42276	0.06217873473544087	1185.5652720866403	nan	nan
82.7801	1.5657283683860217	23.3149	2.4348	0.06262913473544086	1185.046827759487	nan	nan
83.2001	1.5775983683860217	23.3165	2.44786	0.06310393473544088	1185.1281523598248	nan	nan
83.6001	1.5888583683860218	23.3046	2.46009	0.06355433473544086	1184.5233006448127	nan	nan
84.0101	1.6010683683860218	23.3082	2.47272	0.06404273473544088	1184.7062809955728	nan	nan
84.4301	1.6129483683860217	23.2897	2.4849	0.06451793473544087	1183.7659653041671	nan	nan
84.8301	1.6247583683860218	23.2913	2.49761	0.06499033473544087	1183.8472899045048	nan	nan
85.2401	1.6357183683860217	23.2846	2.50937	0.06542873473544086	1183.5067431405905	nan	nan
85.6501	1.6480583683860217	23.286	2.52192	0.06592233473544087	1183.5779021658861	nan	nan
86.0601	1.6589483683860218	23.2595	2.53293	0.06635793473544087	1182.2309634727917	nan	nan
86.4801	1.5796383683860218	23.2649	2.54565	0.06318553473544088	1182.5054339989317	nan	nan
86.8901	1.5915383683860218	23.2563	2.55846	0.06366153473544087	1182.0683142721161	nan	nan
87.2901	1.6029883683860218	23.2482	2.57019	0.06411953473544087	1181.6566084829062	nan	nan
87.7101	1.6153383683860219	23.225	2.58276	0.06461353473544088	1180.4774017780085	nan	nan
88.1401	1.6278483683860216	23.2201	2.59577	0.06511393473544086	1180.2283451894739	nan	nan
88.5501	1.6402383683860218	23.226	2.60839	0.06560953473544087	1180.5282296532196	nan	nan
88.9701	1.6531083683860217	23.213	2.62139	0.06612433473544087	1179.867467275475	nan	nan
89.3801	1.6649183683860218	23.1828	2.63309	0.06659673473544087	1178.3324654440996	nan	nan
89.7901	1.6778783683860217	23.1677	2.6452	0.06711513473544087	1177.5649645284118	nan	nan
90.2001	1.6899583683860218	23.1614	2.65775	0.06759833473544087	1177.2447489145818	nan	nan
90.6101	1.7025283683860217	23.1433	2.67004	0.06810113473544087	1176.3247643732607	nan	nan
91.0101	1.7147383683860218	23.1287	2.68188	0.06858953473544087	1175.5826773951785	nan	nan
91.4201	1.7267383683860218	23.1146	2.69405	0.06906953473544088	1174.8660043547018	nan	nan
91.8301	1.7395783683860218	23.0895	2.7069	0.06958313473544087	1173.5902246869032	nan	nan
92.2501	1.7522983683860218	23.0609	2.71965	0.07009193473544087	1172.1365474558654	nan	nan
92.6801	1.7656283683860217	23.0559	2.73223	0.07062513473544087	1171.88240807981	nan	nan
93.0801	1.7775583683860217	23.025	2.74419	0.07110233473544086	1170.3118267357866	nan	nan
93.4901	1.7902883683860218	23.02	2.75703	0.07161153473544087	1170.057687359731	nan	nan
93.9101	1.8036283683860217	22.984	2.76939	0.07214513473544087	1168.227883852131	nan	nan
94.3201	1.8160783683860218	22.9672	2.78197	0.07264313473544087	1167.3739755485842	nan	nan
94.7201	1.8285083683860217	22.9267	2.79352	0.07314033473544086	1165.3154466025346	nan	nan
95.1301	1.8413583683860217	22.9045	2.80677	0.07365433473544086	1164.187067772848	nan	nan
95.5501	1.8542583683860216	22.8765	2.81916	0.07417033473544087	1162.7638872669368	nan	nan
95.9701	1.8664483683860218	22.8446	2.83138	0.07465793473544087	1161.1424780477023	nan	nan
96.3801	1.8794983683860218	22.8353	2.84385	0.07517993473544088	1160.6697788082392	nan	nan
96.7901	1.8921983683860217	22.7889	2.8559	0.07568793473544087	1158.3113653984437	nan	nan
97.2001	1.9049983683860217	22.762	2.86864	0.07619993473544087	1156.9440955552648	nan	nan
97.6101	1.9181283683860217	22.7437	2.88078	0.07672513473544088	1156.0139454389016	nan	nan
98.0401	1.9311283683860216	22.6893	2.8936	0.07724513473544087	1153.2489090274173	nan	nan
98.4501	1.9445083683860218	22.6654	2.90681	0.07778033473544087	1152.0341228098719	nan	nan
98.8501	1.9569083683860218	22.6396	2.91888	0.07827633473544088	1150.7227636294253	nan	nan
99.2701	1.9696883683860218	22.5955	2.93137	0.07878753473544087	1148.4812543326152	nan	nan
99.6901	1.9825283683860218	22.5813	2.9445	0.07930113473544087	1147.7594985046173	nan	nan
100.1	1.9946283683860218	22.5313	2.95572	0.07978513473544087	1145.2181047440622	nan	nan
100.52	2.0076283683860217	22.5043	2.96803	0.08030513473544086	1143.845752113362	nan	nan
100.93	2.0205783683860217	22.4773	2.98103	0.08082313473544087	1142.473399482662	nan	nan
101.33	2.032888368386022	22.4369	2.99277	0.08131553473544088	1140.4199533241333	nan	nan
101.74	2.045358368386022	22.3935	3.00436	0.08181433473544088	1138.214023539971	nan	nan
102.16	2.0585483683860217	22.3594	3.01732	0.08234193473544087	1136.4807929952724	nan	nan
102.57	2.0711583683860217	22.3252	3.03001	0.08284633473544087	1134.7424796630523	nan	nan
102.98	2.0829483683860217	22.2977	3.04203	0.08331793473544087	1133.344713094747	nan	nan
103.39	2.0951283683860216	22.2589	3.05489	0.08380513473544086	1131.372591536556	nan	nan
103.8	2.1040183683860216	22.2215	3.06656	0.08416073473544086	1129.4716290036604	nan	nan
104.21	2.069688368386022	22.1844	3.07937	0.08278753473544087	1127.5859148333284	nan	nan
104.62	2.081078368386022	22.1624	3.09148	0.08324313473544087	1126.467701578684	nan	nan
105.05	2.0948083683860217	22.1159	3.1049	0.08379233473544087	1124.1042053813674	nan	nan
105.46	2.1070083683860217	22.0773	3.11669	0.08428033473544087	1122.1422493982184	nan	nan
105.86	2.1195483683860217	22.0383	3.12902	0.08478193473544086	1120.159962264985	nan	nan
106.26	2.1315283683860216	22.002	3.14124	0.08526113473544086	1118.314910394822	nan	nan
106.67	2.1448983683860217	21.9623	3.15357	0.08579593473544087	1116.297043748941	nan	nan
107.09	2.157618368386022	21.9387	3.16606	0.08630473473544088	1115.097505893959	nan	nan
107.5	2.1704483683860216	21.8989	3.17905	0.08681793473544086	1113.0745564605568	nan	nan
107.91	2.1831383683860217	21.8423	3.19117	0.08732553473544087	1110.197698723608	nan	nan
108.31	2.1955283683860216	21.8237	3.20308	0.08782113473544087	1109.252300244681	nan	nan
108.73	2.2089583683860217	21.7849	3.21615	0.08835833473544087	1107.2801786864902	nan	nan
109.14	2.2214383683860217	21.7312	3.22784	0.08885753473544086	1104.5507217876536	nan	nan
109.56	2.234058368386022	21.7083	3.24052	0.08936233473544088	1103.3867634453193	nan	nan
110	2.2480783683860217	21.6713	3.25399	0.08992313473544086	1101.5061320625082	nan	nan
110.4	2.260588368386022	21.6264	3.26582	0.09042353473544087	1099.2239604655294	nan	nan
110.82	2.2735083683860218	21.5904	3.27807	0.09094033473544087	1097.3941569579295	nan	nan
111.23	2.2862883683860216	21.5506	3.29113	0.09145153473544086	1095.3712075245273	nan	nan
111.63	2.298728368386022	21.504	3.30283	0.09194913473544088	1093.0026285396896	nan	nan
112.04	2.3111283683860218	21.469	3.3152	0.09244513473544087	1091.223652907301	nan	nan
112.44	2.3234383683860216	21.4275	3.32736	0.09293753473544086	1089.1142960860398	nan	nan
112.85	2.3363383683860217	21.3918	3.34018	0.09345353473544087	1087.2997409410032	nan	nan
113.25	2.348498368386022	21.3373	3.3512	0.09393993473544088	1084.5296217419977	nan	nan
113.67	2.361588368386022	21.3108	3.3642	0.09446353473544088	1083.1826830489033	nan	nan
114.1	2.3744183683860216	21.265	3.37733	0.09497673473544087	1080.8547663642346	nan	nan
114.51	2.3870483683860217	21.2232	3.38924	0.09548193473544087	1078.73016118041	nan	nan
114.91	2.3992383683860217	21.1827	3.40192	0.09596953473544087	1076.6716322343602	nan	nan
115.31	2.4106883683860216	21.1415	3.4145	0.09642753473544087	1074.5775237756627	nan	nan
115.72	2.4207383683860217	21.112	3.42597	0.09682953473544087	1073.078101456935	nan	nan
116.12	2.4298783683860217	21.0538	3.43773	0.09719513473544086	1070.1199191196483	nan	nan
116.53	2.4421483683860217	21.0208	3.45033	0.09768593473544086	1068.4425992376819	nan	nan
116.94	2.4547683683860217	20.9732	3.46226	0.09819073473544088	1066.0231923776328	nan	nan
117.34	2.4671483683860216	20.9354	3.47482	0.09868593473544086	1064.101898694653	nan	nan
117.76	2.4805083683860216	20.8841	3.48663	0.09922033473544087	1061.494428696323	nan	nan
118.17	2.493348368386022	20.8337	3.49977	0.09973393473544087	1058.9327037856833	nan	nan
118.57	2.5060783683860217	20.8181	3.51144	0.10024313473544087	1058.13978893239	nan	nan
118.98	2.5188783683860216	20.7636	3.52361	0.10075513473544087	1055.3696697333844	nan	nan
119.39	2.5318383683860217	20.7225	3.53616	0.10127353473544087	1053.280644062208	nan	nan
119.82	2.5455883683860216	20.6816	3.54974	0.10182353473544087	1051.2017839660734	nan	nan
120.22	2.557818368386022	20.6164	3.56109	0.10231273473544088	1047.887806502309	nan	nan
120.64	2.5719083683860218	20.5832	3.5736	0.10287633473544087	1046.2003210453004	nan	nan
121.04	2.5847183683860218	20.5501	3.58714	0.10338873473544087	1044.5179183758128	nan	nan
121.44	2.5970483683860217	20.4823	3.59807	0.10388193473544087	1041.0717884364994	nan	nan
121.85	2.6097283683860217	20.4485	3.61027	0.10438913473544087	1039.353806254364	nan	nan
122.25	2.6224583683860216	20.4173	3.6225	0.10489833473544087	1037.7679765477774	nan	nan
122.67	2.635918368386022	20.3764	3.63583	0.10543673473544088	1035.689116451643	nan	nan
123.08	2.6489783683860217	20.3137	3.64753	0.10595913473544087	1032.5022086759066	nan	nan
123.49	2.6618483683860217	20.263	3.65901	0.10647393473544087	1029.9252354027033	nan	nan
123.89	2.6745183683860216	20.2292	3.67151	0.10698073473544087	1028.2072532205677	nan	nan
124.31	2.687648368386022	20.1885	3.6846	0.10750593473544087	1026.1385586994757	nan	nan
124.73	2.701318368386022	20.1473	3.69787	0.10805273473544087	1024.0444502407781	nan	nan
125.15	2.714218368386022	20.0874	3.71006	0.10856873473544087	1020.9998605156325	nan	nan
125.56	2.727078368386022	20.0474	3.72208	0.10908313473544087	1018.9667455071882	nan	nan
125.97	2.7389083683860216	19.9926	3.7341	0.10955633473544087	1016.1813779456193	nan	nan
126.38	2.7513183683860216	19.9364	3.74617	0.11005273473544086	1013.3248513587549	nan	nan
126.81	2.763768368386022	19.8918	3.75898	0.11055073473544087	1011.0579281243396	nan	nan
127.22	2.7767983683860216	19.843	3.77186	0.11107193473544086	1008.5775278140375	nan	nan
127.62	2.788918368386022	19.788	3.78401	0.11155673473544088	1005.7819946774265	nan	nan
128.02	2.8004683683860216	19.738	3.79539	0.11201873473544087	1003.240600916871	nan	nan
128.43	2.812978368386022	19.7099	3.80812	0.11251913473544088	1001.8123376234389	nan	nan
128.84	2.825308368386022	19.6476	3.82087	0.11301233473544087	998.6457609977869	nan	nan
129.27	2.8366483683860215	19.6043	3.83289	0.11346593473544087	996.4449140011457	nan	nan
129.69	2.849568368386022	19.5418	3.8456	0.11398273473544088	993.2681718004513	nan	nan
130.1	2.8626183683860216	19.4998	3.85841	0.11450473473544086	991.1334010415848	nan	nan
130.52	2.8747683683860217	19.4453	3.86983	0.11499073473544087	988.3632818425793	nan	nan
130.91	2.8874283683860216	19.3996	3.88132	0.11549713473544086	986.0404479454317	nan	nan
131.34	2.9005883683860216	19.3482	3.8944	0.11602353473544086	983.4278951595805	nan	nan
131.75	2.9133383683860217	19.2802	3.90723	0.11653353473544087	979.9715996452253	nan	nan
132.16	2.9256083683860217	19.2203	3.91968	0.11702433473544087	976.92700992008	nan	nan
132.57	2.9367983683860217	19.1841	3.93122	0.11747193473544087	975.0870408374378	nan	nan
133	2.950108368386022	19.1328	3.94449	0.11800433473544088	972.4795708391077	nan	nan
133.42	2.9632183683860216	19.0869	3.95711	0.11852873473544086	970.146571366918	nan	nan
133.83	2.9758183683860215	19.023	3.96896	0.11903273473544086	966.8986701409281	nan	nan
134.24	2.989278368386022	18.9427	3.98134	0.11957113473544087	962.8171917614758	nan	nan
134.66	3.0022683683860216	18.9029	3.99388	0.12009073473544087	960.7942423280737	nan	nan
135.08	3.016408368386022	18.8566	4.00683	0.12065633473544088	958.4409117057994	nan	nan
135.49	3.0292683683860218	18.7935	4.01907	0.12117073473544088	955.2336727799785	nan	nan
135.9	3.0428783683860217	18.7399	4.03174	0.12171513473544086	952.509298668663	nan	nan
136.31	3.055508368386022	18.6853	4.04337	0.12222033473544087	949.7340966821366	nan	nan
136.72	3.0686983683860216	18.6258	4.0555	0.12274793473544086	946.7098381070756	nan	nan
137.14	3.0826083683860217	18.5613	4.0688	0.12330433473544086	943.431440155959	nan	nan
137.54	3.095438368386022	18.5163	4.08025	0.12381753473544087	941.1441857714592	nan	nan
137.95	3.1084383683860217	18.4602	4.0921	0.12433753473544087	938.2927419721159	nan	nan
138.37	3.122078368386022	18.3962	4.10502	0.12488313473544087	935.0397579586049	nan	nan
138.78	3.1362083683860216	18.335	4.11774	0.12544833473544087	931.929091995685	nan	nan
139.19	3.149128368386022	18.2752	4.1292	0.12596513473544088	928.8895850580607	nan	nan
139.6	3.163088368386022	18.2183	4.14214	0.12652353473544087	925.9974789585485	nan	nan
140.01	3.1761483683860217	18.1477	4.15349	0.12704593473544087	922.4090309686443	nan	nan
140.43	3.189538368386022	18.0956	4.16588	0.12758153473544087	919.7608986701456	nan	nan
140.84	3.203028368386022	18.0262	4.17861	0.12812113473544087	916.2334441304945	nan	nan
141.24	3.2161483683860217	17.9706	4.19032	0.12864593473544086	913.407414268757	nan	nan
141.65	3.229318368386022	17.9251	4.20331	0.1291727347354409	911.0947459466515	nan	nan
142.05	3.242558368386022	17.8559	4.21457	0.12970233473544088	907.5774569820425	nan	nan
142.47	3.257048368386022	17.7884	4.2279	0.13028193473544086	904.1465754052927	nan	nan
142.88	3.2705083683860217	17.7126	4.24013	0.13082033473544086	900.2938224642907	nan	nan
143.3	3.284158368386022	17.655	4.25232	0.13136633473544088	897.3661368521308	nan	nan
143.7	3.2974283683860217	17.5844	4.26431	0.13189713473544087	893.7776888622263	nan	nan
144.11	3.310538368386022	17.5261	4.2772	0.13242153473544088	890.8144237374188	nan	nan
144.53	3.3243483683860218	17.4601	4.2894	0.13297393473544086	887.4597839734857	nan	nan
144.94	3.3384983683860217	17.3826	4.30212	0.13353993473544087	883.5206236446246	nan	nan
145.36	3.3517683683860215	17.3243	4.31446	0.13407073473544087	880.557358519817	nan	nan
145.76	3.3659383683860216	17.2392	4.32668	0.13463753473544085	876.2319063393517	nan	nan
146.18	3.3801383683860218	17.1444	4.33884	0.13520553473544086	871.4134237693386	nan	nan