File: original_data/46NT77.csv
Specimen name:	AWA_1_04_Rz
Specimen ID:	46NT77
Material:	42CrMoS4
Specimen type:	Round Tensile Specimen
Gauge diameter:	5.01	mm
Gauge length:	25	mm
Parallel length:	30	mm
Original cross-section:	19.71357244109229	mm²
Cross-section after fracture:	8.800980378229477	mm²
Yield stress at 0.2% plastic strain:	1139.0926164551984	MPa
Yield stress at 1% plastic strain:	1151.4400996104164	MPa
Ultimate tensile strength:	1203.064541998655	MPa
Uniform elongation:	5.212535570391568	%
Elongation after fracture:	14.447040124678706	%
Reduction of area:	55.355730654459535	%
Slope of linear-elastic region:	199821.25831804346	MPa
Crosshead seperation speed:	0.029937661657082174	mm/s
Strain rate:	0.0009979220552360725	s-1
Test temperature:	RT	Cel
Machine type:	INSTRON 8852TT
Standard:	DIN EN ISO 6892-1
Date:	2022-08-18 00:00:00
Heat treatment batch:	Batch 1
Time	Displacement	Force	Machine Displacement	Engineering Strain	Engineering Stress	True Strain	True Stress
s	mm	kN	mm		MPa		MPa
0	0.001138006149504561	0.188447	0	4.552024598018244e-05	9.559251655838313	4.551920996518886e-05	9.559686795325073
0.440001	0.0011260721495045612	0.188682	-0.000518799	4.504288598018245e-05	9.571172376991326	4.504187157984544e-05	9.571603490217399
0.850001	0.001192227749504561	0.188153	-0.000102997	4.768910998018244e-05	9.544338072778798	4.768797289064371e-05	9.544793233766837
1.26	0.002161276149504561	0.309572	0.0124359	8.645104598018243e-05	15.703495696939608	8.644730930383415e-05	15.704853280568154
1.67	0.0031927461495045613	0.424645	0.0261116	0.00012770984598018244	21.54074312349605	0.0001277016917720671	21.54349408848265
2.08	0.003865976149504561	0.498948	0.0343513	0.00015463904598018245	25.30987224618707	0.00015462709059534674	25.3137861406851
2.48	0.005344716149504561	0.642466	0.0489349	0.00021378864598018242	32.59003419698811	0.00021376579644410984	32.59700157627152
2.88	0.006589446149504561	0.762487	0.0611229	0.0002635778459801825	38.678276211906734	0.00026354311544229904	38.68847094863689
3.29	0.0075093661495045615	0.879005	0.0710831	0.00030037464598018244	44.58882339193596	0.0003003295425479577	44.60221674397699
3.70001	0.00882663614950456	1.05854	0.0849724	0.0003530654459801824	53.6960007204736	0.00035300313304226455	53.71495892291533
4.10001	0.01011663614950456	1.23013	0.0972099	0.0004046654459801824	62.400156221093376	0.0004045835910004262	62.42540740813982
4.50001	0.01102238614950456	1.37597	0.107201	0.00044089544598018243	69.7981050421808	0.000440798280142041	69.82887870883194
4.91001	0.01247750614950456	1.605	0.121243	0.0004991002459801824	81.41598915143511	0.0004989757368790681	81.45662389164731
5.32001	0.013855306149504563	1.79902	0.133129	0.0005542122459801825	91.25793944125532	0.0005540587270922391	91.3085157088366
5.72001	0.01509960614950456	1.98481	0.143791	0.0006039842459801824	100.68241085835508	0.0006038019209061074	100.74322144836083
6.13001	0.01683970614950456	2.24022	0.157974	0.0006735882459801824	113.63845932512645	0.0006733614872398121	113.71500485561914
6.53001	0.01799990614950456	2.43089	0.168438	0.0007199962459801825	123.310475930425	0.0007197371730300888	123.39925901018495
6.94001	0.019825306149504562	2.71779	0.182793	0.0007930122459801825	137.8639010317002	0.0007926979779037833	137.97322879349696
7.34001	0.021159006149504563	2.9409	0.194092	0.0008463602459801825	149.18148442084455	0.0008460022851089561	149.30774569869467
7.75001	0.022616506149504563	3.17558	0.205135	0.0009046602459801826	161.08597310250113	0.0009042512875268497	161.231701178552
8.16001	0.024288006149504562	3.44928	0.21891	0.0009715202459801825	174.9698087602879	0.0009710486256203888	175.13979547193378
8.57001	0.025771806149504563	3.67403	0.229794	0.0010308722459801826	186.37058356513842	0.0010303412620728146	186.56270782720284
8.97001	0.027586206149504564	3.99649	0.244198	0.0011034482459801825	202.7278420459931	0.0011028398944462371	202.9515417277101
9.38001	0.02882520614950456	4.21495	0.254368	0.0011530082459801825	213.80954733572673	0.0011523440424781486	214.0560715068741
9.78001	0.03088630614950456	4.53645	0.268375	0.0012354522459801824	230.1181084025096	0.0012346897028465127	230.40240833637617
10.19	0.03228930614950456	4.77157	0.279015	0.0012915722459801823	242.0449167322824	0.0012907388840343894	242.35753522901436
10.62	0.03421190614950456	5.10151	0.292881	0.0013684762459801824	258.78160923111386	0.001367540735747432	259.1357457162432
11.03	0.03585100614950456	5.36138	0.303997	0.0014340402459801823	271.9638977674275	0.001433012992231589	272.35390494227966
11.43	0.03781420614950456	5.69237	0.316784	0.0015125682459801823	288.75385306290013	0.001511425466840013	289.19061297194753
11.84	0.03946970614950456	5.95685	0.328354	0.0015787882459801824	302.16999063970485	0.0015775432700139936	302.64705306921473
12.25	0.04157530614950456	6.30836	0.342331	0.0016630122459801824	320.000853160964	0.0016616309722864006	320.5330184984948
12.65	0.04322690614950456	6.56502	0.353394	0.0017290762459801824	333.0203097189748	0.0017275831145590235	333.59612722593886
13.06	0.04554660614950456	6.94482	0.36755	0.0018218642459801823	352.28622416116485	0.0018202066642686728	352.92804183731545
13.47	0.047257406149504556	7.20449	0.378387	0.0018902962459801823	365.4583674028802	0.001888511884325586	366.1491919828439
13.88	0.04921060614950456	7.51755	0.390038	0.0019684242459801823	381.33879703761437	0.001966489437573813	382.0894335716361
14.3	0.05118520614950456	7.8356	0.402927	0.0020474082459801825	397.4723517725763	0.0020453151621618797	398.28613994314463
14.71	0.05323940614950456	8.17231	0.415188	0.002129576245980182	414.55246249356054	0.0021273119126301956	415.4352835703994
15.12	0.055183306149504556	8.45792	0.426498	0.002207332245980182	429.04045044467665	0.002204899667173467	429.98748526577305
15.54	0.05743630614950456	8.84087	0.440895	0.0022974522459801826	448.4661532767902	0.002294817137820605	449.496482847882
15.97	0.05930330614950456	9.12818	0.452164	0.0023721322459801823	463.0403762319919	0.0023693231817215666	464.1387692396426
16.38	0.06145660614950456	9.46475	0.464798	0.0024582642459801823	480.11338524675733	0.0024552476571323327	481.293630815726
16.79	0.06351940614950456	9.78411	0.476711	0.0025407762459801826	496.31339166133824	0.0025375539309809253	497.57441293743324
17.2	0.06579530614950456	10.1522	0.490505	0.0026318122459801823	514.9852991047973	0.002628355092521785	516.340643721481
17.6	0.06753450614950456	10.425	0.501003	0.002701380245980182	528.8234809368917	0.002697738076146046	530.252034241905
18	0.06985470614950456	10.7813	0.514435	0.0027941882459801824	546.8973232637802	0.002790291758661573	548.4254573362018
18.4	0.07163340614950456	11.0586	0.524563	0.0028653362459801824	560.9637742243367	0.0028612389948810936	562.5711240593035
18.81	0.07386800614950456	11.4168	0.53849	0.0029547202459801825	579.1339968499093	0.0029503636397062096	580.8451757955371
19.23	0.07643840614950456	11.7656	0.551086	0.0030575362459801824	596.8273906293613	0.003052871488057937	598.6522120088043
19.65	0.07804640614950456	12.0735	0.562637	0.0031218562459801825	612.4460716634591	0.003116993370939269	614.3580402576077
20.08	0.08048680614950456	12.4432	0.577011	0.003219472245980182	631.1996487284345	0.003214300841697805	633.231778479188
20.5	0.08238710614950456	12.7474	0.588791	0.0032954842459801824	646.6306418124636	0.00329006603825465	648.7616029055247
20.91	0.08487930614950456	13.1479	0.60265	0.0033951722459801825	666.9465942455786	0.0033894216611648686	669.2109928119122
21.32	0.08667110614950456	13.4066	0.612732	0.0034668442459801826	680.0695328084921	0.0034608485947970856	682.4272279551757
21.73	0.08921460614950456	13.7975	0.627293	0.0035685842459801825	699.8985111008884	0.0035622319571861215	702.396157901388
22.13	0.09070830614950456	14.0534	0.636734	0.0036283322459801826	712.8794155394256	0.0036217657274173363	715.4659789103229
22.55	0.09331150614950456	14.4456	0.651318	0.0037324602459801823	732.774338246711	0.003725511900484877	735.5093893334913
22.99	0.09511250614950456	14.7284	0.662304	0.0038045002459801826	747.1197848087209	0.0037972814384296203	749.9622022138022
23.41	0.09763300614950456	15.1065	0.67588	0.0039053202459801823	766.2994642468252	0.003897714278928606	769.2921090590321
23.8	0.09936080614950456	15.3892	0.686699	0.003974432245980182	780.639838161536	0.003966555054818255	783.742438306822
24.21	0.10175400614950456	15.7481	0.699837	0.004070160245980182	798.8455693182027	0.0040618995510813966	802.0969987971191
24.62	0.10372400614950456	16.0462	0.711834	0.0041489602459801826	813.9671309169831	0.004140377043140094	817.3442481846922
25.02	0.10583500614950456	16.4049	0.724911	0.004233400245980182	832.1627167790517	0.004224464617011491	835.6855946289597
25.43	0.10762200614950455	16.6867	0.735664	0.004304880245980182	846.4574368680699	0.004295640756121541	850.1013347671062
25.85	0.11039000614950456	17.0661	0.749847	0.004415600245980183	865.7030607210634	0.004405880086269566	869.525659368929
26.27	0.11221800614950456	17.3693	0.761368	0.004488720245980182	881.0833273321008	0.004478675987285432	885.038263901892
26.67	0.11449600614950456	17.7014	0.773483	0.004579840245980182	897.929589012594	0.0045693846886750615	902.0419630824103
27.09	0.11648100614950456	18.0066	0.784985	0.004659240245980183	913.4113085696146	0.004648419583837305	917.6671112996355
27.48	0.11849300614950456	18.3171	0.797085	0.004739720245980183	929.1618784334903	0.004728523138806179	933.5658458004946
27.9	0.12082000614950456	18.6712	0.809849	0.004832800245980182	947.1241225197975	0.004821159755914811	951.7013842120849
28.3	0.12249800614950455	18.9443	0.820831	0.004899920245980182	960.9775222937894	0.004887954707642025	965.6862355112086
28.72	0.12495400614950455	19.297	0.833912	0.004998160245980182	978.8687493179086	0.004985710908348695	983.7612921867817
29.13	0.12708700614950458	19.6267	0.846214	0.005083480245980183	995.5932674632222	0.005070602982712922	1000.6543461714025
29.53	0.12923600614950456	19.9288	0.858395	0.005169440245980182	1010.9177349539689	0.005156124559800033	1016.143613778415
29.94	0.13151100614950456	20.2777	0.871441	0.005260440245980182	1028.6162013807202	0.0052466524622603195	1034.0271754441305
30.36	0.13330900614950458	20.5477	0.882442	0.005332360245980184	1042.3123490884382	0.005318193552045572	1047.8703340226116
30.76	0.13565500614950457	20.8981	0.895348	0.005426200245980183	1060.0869052246767	0.005411531461341921	1065.8391490505671
31.17	0.13826900614950458	21.2511	0.908566	0.005530760245980183	1077.9933501906935	0.005515521752679313	1083.9554729573592
31.57	0.14021800614950458	21.4943	0.9193	0.0056087202459801835	1090.3300284222378	0.0055930499408485615	1096.4453845274497
31.98	0.14278200614950456	21.774	0.930511	0.005711280245980182	1104.5182229179738	0.005695032718391446	1110.8264360258504
32.39	0.14574700614950456	22.0588	0.94397	0.005829880245980182	1118.9651224259671	0.00581295225438383	1125.488555089139
32.79	0.14995700614950458	22.3305	0.9562	0.005998280245980183	1132.7475051377705	0.005980362179048645	1139.5420421215217
33.2	0.15580200614950457	22.4683	0.96825	0.0062320802459801825	1139.7376131160058	0.006212741140863822	1146.8405493803066
33.6	0.1631190061495046	22.498	0.979469	0.006524760245980183	1141.244189363855	0.0065035661388714245	1148.690534081572
34.01	0.17336500614950456	22.4688	0.992016	0.006934600245980182	1139.762976352502	0.006910666489345072	1147.666776968675
34.41	0.18350500614950457	22.4704	1.0036	0.007340200245980183	1139.8441387092882	0.00731339208108934	1148.2108229366213
34.83	0.19528400614950459	22.4552	1.01581	0.007811360245980183	1139.0730963198166	0.007781009522698109	1147.9708066216747
35.24	0.20858300614950456	22.4	1.02916	0.008343320245980182	1136.2729950106832	0.008308707141825763	1145.7532844949164
35.65	0.22084600614950456	22.3353	1.04036	0.008833840245980183	1132.99099220813	0.008795050155494387	1142.999653633431
36.0501	0.23094500614950458	22.3554	1.05111	0.009237800245980183	1134.01059431526	0.00919539273728376	1144.4863576623695
36.4601	0.24329900614950456	22.3643	1.06335	0.009731960245980182	1134.462059924885	0.009684909737030756	1145.5025995926467
36.8601	0.25494900614950455	22.3914	1.0761	0.010197960245980181	1135.836747342956	0.010146311891174464	1147.4199653382827
37.2701	0.26634100614950457	22.4248	1.08821	0.010653640245980183	1137.5310115408738	0.01059729009027856	1149.6498577064763
37.7001	0.27756400614950455	22.4592	1.10105	0.011102560245980182	1139.276002211783	0.011041379251245195	1151.9248826631388
38.1101	0.28873500614950454	22.4841	1.11325	0.011549400245980182	1140.5390913892725	0.011483215035153926	1153.7116338519138
38.5201	0.29886200614950453	22.5076	1.12445	0.01195448024598018	1141.7311635045737	0.011883589859552736	1155.379966144909
38.9201	0.30960700614950454	22.5423	1.13647	0.012384280245980182	1143.4913721173805	0.012308222351748643	1157.6526897285426
39.3301	0.3209710061495045	22.5646	1.14939	0.012838840245980181	1144.622572465092	0.012757121046449387	1159.3181988149142
39.7401	0.33166500614950456	22.5856	1.16174	0.013266600245980182	1145.6878283979145	0.01317936956106935	1160.8872108239548
40.1501	0.34259100614950455	22.6026	1.17432	0.013703640245980182	1146.550178438771	0.01361059444838334	1162.2620896080603
40.5601	0.3531110061495045	22.6199	1.18642	0.014124440245980181	1147.4277464215247	0.014025619775321208	1163.6345210624352
40.9701	0.36325500614950457	22.6388	1.19793	0.014530200245980182	1148.3864767610648	0.01442564844191824	1165.0727622281788
41.3801	0.37448600614950456	22.6695	1.21127	0.014979440245980183	1149.9437794819055	0.01486835637330638	1167.1692936128914
41.8001	0.38604900614950455	22.6857	1.22466	0.015441960245980182	1150.7655483443687	0.015323946535908085	1168.535624194346
42.2101	0.39649900614950456	22.6989	1.23654	0.015859960245980183	1151.4351377878568	0.01573550525269292	1169.6968532989968
42.6301	0.40701000614950456	22.7112	1.24851	0.01628040024598018	1152.0590734056532	0.016149295573650232	1170.8150562277103
43.0501	0.4173600061495045	22.7302	1.26079	0.016694400245980182	1153.0228763924924	0.01655658050961956	1172.2719017837599
43.4701	0.42828000614950457	22.7539	1.2734	0.017131200245980183	1154.2250938023922	0.016986115870577047	1173.9983550132563
43.8801	0.43951900614950457	22.7759	1.28639	0.01758076024598018	1155.3410762082062	0.017428006434002562	1175.6528506713553
44.2901	0.4501370061495045	22.7895	1.29865	0.01800548024598018	1156.0309562408913	0.01784530145959737	1176.8458487872283
44.6901	0.46038000614950453	22.8069	1.31079	0.01841520024598018	1156.913596870944	0.018247693764343993	1178.2183924246197
45.1001	0.4717000061495045	22.8283	1.32347	0.01886800024598018	1157.9991433929633	0.018692207327648903	1179.8482715153466
45.5101	0.48229200614950457	22.842	1.33591	0.019291680245980183	1158.6940960729476	0.01910795493580518	1181.047252077292
45.9301	0.49310100614950453	22.8562	1.34874	0.019724040245980182	1159.4144119894277	0.01953204191280572	1182.2827485132766
46.3401	0.5033590061495046	22.8716	1.36057	0.020134360245980185	1160.1955996734976	0.019934344352460564	1183.5553958331247
46.7301	0.5134710061495046	22.8862	1.37101	0.020538840245980183	1160.936206179174	0.020330762559157476	1184.780489453662
47.1401	0.5241750061495045	22.9163	1.38412	0.02096700024598018	1162.4630730162196	0.020750217647441192	1186.8364365540933
47.5501	0.5357190061495045	22.9394	1.39756	0.021428760245980182	1163.6348545423243	0.02120239250679026	1188.5701068541778
47.9701	0.5472810061495046	22.946	1.41046	0.021891240245980183	1163.9696492640685	0.02165506757264974	1189.4503884951373
48.3701	0.5572480061495045	22.9518	1.42164	0.022289920245980182	1164.2638628074196	0.022045130853498043	1190.2152114546736
48.7901	0.5673290061495045	22.9669	1.43372	0.02269316024598018	1165.029832549592	0.022439500869634577	1191.4680412309872
49.2201	0.5775020061495045	22.9884	1.44576	0.023100080245980183	1166.12045171891	0.02283731233690546	1193.0579277300956
49.6201	0.5881940061495046	23.0134	1.45799	0.023527760245980182	1167.388613543699	0.023255248610187563	1194.8546529570424
50.0401	0.5994960061495045	23.0324	1.47118	0.02397984024598018	1168.3524165305382	0.02369683916373434	1196.3693208299453
50.4501	0.6101180061495045	23.0471	1.48333	0.024404720245980182	1169.098095683514	0.02411168314790445	1197.6296076487783
50.8501	0.6206140061495046	23.0609	1.4956	0.024824560245980183	1169.7981210107976	0.02452143720507209	1198.8378449414645
51.2601	0.6314410061495045	23.0755	1.50736	0.02525764024598018	1170.5387275164742	0.024943937343201415	1200.1037735900727
51.6601	0.6417630061495045	23.0892	1.51903	0.025670520245980183	1171.2336801964584	0.025346564810639034	1201.2998580967155
52.0801	0.6521770061495046	23.1114	1.53151	0.026087080245980183	1172.3598078968707	0.025752616681117016	1202.9432522826385
52.4801	0.6633210061495045	23.1239	1.54449	0.02653284024598018	1172.993888809265	0.026186949411260787	1204.116748270552
52.8901	0.6738820061495046	23.1368	1.55598	0.026955280245980182	1173.648260310856	0.026598385934066823	1205.2842780777423
53.2901	0.6838390061495045	23.1513	1.56759	0.027353560245980183	1174.3837941692334	0.026986136789380995	1206.5073720349444
53.6901	0.6939140061495045	23.1677	1.57989	0.02775656024598018	1175.2157083262948	0.027378329890030115	1207.8356539364759
54.1001	0.7052300061495046	23.1891	1.59266	0.028209200245980184	1176.3012548483139	0.02781864851401816	1209.4837724959277
54.5101	0.7156800061495046	23.1991	1.6049	0.028627200245980183	1176.8085195782296	0.028225097958081438	1210.497252719371
54.9301	0.7262830061495046	23.2114	1.61716	0.029051320245980183	1177.4324551960256	0.02863732951104976	1211.6384225199358
55.3601	0.7373670061495046	23.2235	1.62997	0.029494680245980183	1178.0462455192232	0.029068080154221552	1212.79234284579
55.7701	0.7474360061495046	23.2368	1.64155	0.02989744024598018	1178.7209076100107	0.02945922470714801	1213.9616455119685
56.1701	0.7573360061495046	23.2509	1.65342	0.030293440245980182	1179.4361508791917	0.029843655109812895	1215.1653294397995
56.5801	0.7678630061495045	23.266	1.66572	0.030714520245980183	1180.202120621364	0.03025227071337254	1216.4514625495376
56.9901	0.7779320061495045	23.2892	1.67823	0.03111728024598018	1181.378974794768	0.0306429524411709	1218.1402754301657
57.3901	0.7891240061495045	23.3067	1.69073	0.031564960245980184	1182.2666880721201	0.031077028032884493	1219.5848890812633
57.8001	0.8002000061495046	23.3159	1.70374	0.03200800024598018	1182.7333716236421	0.03150641920566039	1220.5903016735006
58.2301	0.8110970061495045	23.3224	1.71617	0.03244388024598018	1183.0630936980872	0.031928691103199625	1221.4462510334668
58.6501	0.8213400061495045	23.3325	1.72791	0.032853600245980184	1183.575431075302	0.032325457195489175	1222.4601451488138
59.0801	0.8315590061495045	23.3445	1.74022	0.03326236024598018	1184.1841487512006	0.03272113683123984	1223.5729085045425
59.4801	0.8418420061495046	23.3608	1.75188	0.033673680245980185	1185.010990260963	0.03311913657324603	1224.9146714349831
59.9001	0.8522560061495046	23.3731	1.76451	0.03409024024598018	1185.634925878759	0.0335220452433383	1226.053505345991
60.3201	0.8624400061495046	23.3902	1.7757	0.034497600245980184	1186.5023485669144	0.033915898477213074	1227.4338322786925
60.7101	0.8738170061495045	23.4277	1.78958	0.03495268024598018	1188.4045913040975	0.03435570610305967	1229.9425169868043
61.1301	0.8862350061495046	23.4142	1.80398	0.03544940024598018	1187.7197839187115	0.03483553561464163	1229.823737918915
61.5401	0.8951020061495045	23.3897	1.81385	0.03580408024598018	1186.4769853304185	0.03517801422173376	1228.9577025231977
61.9401	0.9043750061495045	23.4332	1.82441	0.03617500024598018	1188.683586905551	0.03553604872840859	1231.6842159542518
62.3501	0.9150340061495046	23.4543	1.83682	0.03660136024598018	1189.7539154856727	0.03594743899138133	1233.3005271504294
62.7701	0.9265040061495046	23.4637	1.84954	0.03706016024598018	1190.2307443317932	0.036389941302344235	1234.3408864464216
63.1801	0.9376130061495045	23.4723	1.86289	0.03750452024598018	1190.6669919995204	0.036818329976820656	1235.322386307187
63.5801	0.9479490061495045	23.4764	1.87467	0.03791796024598018	1190.8749705387859	0.03721674524827028	1236.0305203296084
63.9901	0.9580720061495045	23.4855	1.88649	0.03832288024598018	1191.336581443009	0.037606796341801	1236.9920305863047
64.4101	0.9686060061495045	23.4948	1.89908	0.03874424024598018	1191.8083376418306	0.038012522282598105	1237.984046202588
64.8001	0.9790860061495046	23.5073	1.91114	0.03916344024598018	1192.4424185542246	0.03841600508370879	1239.142565960045
65.2001	0.9896420061495046	23.5161	1.92265	0.039585680245980186	1192.8888115165505	0.03882224939827726	1240.110126578252
65.6101	0.9998960061495046	23.5268	1.93475	0.039995840245980185	1193.43158477756	0.03921671338180158	1241.1638837868302
66.0301	1.0109880061495045	23.5393	1.94811	0.04043952024598018	1194.0656656899541	0.03964323949758678	1242.353108352653
66.4201	1.0216980061495045	23.548	1.96026	0.040867920245980176	1194.5069860049807	0.0400549038175381	1243.3240022422983
66.8401	1.0322280061495046	23.5537	1.97176	0.041289120245980186	1194.7961269010325	0.040459484257489894	1244.1282078540805
67.2301	1.0426380061495046	23.5602	1.98379	0.041705520245980184	1195.1258489754775	0.04085929326078943	1244.9691942664185
67.6401	1.0534980061495045	23.5667	1.99604	0.04213992024598018	1195.4555710499226	0.041276214782752126	1245.831973471579
68.0401	1.0637780061495046	23.5761	2.00827	0.042551120245980185	1195.932399896043	0.0416707096957593	1246.8206632500835
68.4601	1.0745880061495046	23.5815	2.02028	0.042983520245980185	1196.2063228501975	0.042085375554384255	1247.6234815467985
68.8701	1.0857380061495046	23.6027	2.03363	0.04342952024598018	1197.2817240776183	0.042512903563591976	1249.2790949535893
69.2901	1.0973580061495045	23.6057	2.04631	0.04389432024598018	1197.4339034965928	0.042958258518741535	1249.9944507300665
69.7101	1.1086180061495046	23.6082	2.05892	0.044344720245980185	1197.560719679072	0.043389626765623746	1250.666214770815
70.1401	1.1201380061495045	23.6086	2.07224	0.04480552024598018	1197.5810102682685	0.04383076306931469	1251.239250470045
70.5501	1.1301180061495046	23.6154	2.08333	0.045204720245980184	1197.9259502846112	0.04421277077159329	1252.077857742627
70.9501	1.1402480061495046	23.6227	2.09455	0.045609920245980186	1198.2962535374493	0.04460037089379009	1252.950450092349
71.3701	1.1510480061495045	23.6315	2.10671	0.04604192024598018	1198.742646499775	0.04501344155667916	1253.9350598253727
71.7801	1.1625480061495046	23.6489	2.12023	0.04650192024598018	1199.625287129828	0.04545309782433635	1255.4101665570004
72.1801	1.1736380061495046	23.652	2.13256	0.046945520245980185	1199.7825391961017	0.045876896385560355	1256.1069546807057
72.5801	1.1846280061495045	23.6551	2.14508	0.047385120245980177	1199.9397912623756	0.04629669639035109	1256.7990825592794
73.0001	1.1960080061495046	23.6589	2.15702	0.047840320245980186	1200.1325518597432	0.04673120811244545	1257.5472774783389
73.4101	1.2068480061495046	23.6629	2.16976	0.048273920245980186	1200.3354577517098	0.047144926027059414	1258.2803559076378
73.8201	1.2183880061495045	23.6695	2.18281	0.04873552024598018	1200.6702524734537	0.0475851720255203	1259.18554187162
74.2901	1.2306980061495045	23.6686	2.19614	0.04922792024598018	1200.6245986477616	0.04805457964200948	1259.7288506353557
74.7001	1.2413780061495046	23.6702	2.20795	0.049655120245980185	1200.7057610045479	0.04846165330705675	1260.32694994727
75.1201	1.2523380061495046	23.6757	2.21964	0.05009352024598018	1200.9847566060014	0.04887922710414465	1261.1463108261578
75.5401	1.2640680061495047	23.6857	2.23241	0.050562720245980186	1201.492021335917	0.04932594465722009	1262.2427262885021
75.9501	1.2747880061495045	23.69	2.24455	0.05099152024598018	1201.7101451697806	0.04973402359012465	1262.987172367005
76.3501	1.2856380061495045	23.694	2.25661	0.05142552024598018	1201.9130510617467	0.050146881741296376	1263.7220550030304
76.7601	1.2967880061495045	23.6954	2.26882	0.05187152024598018	1201.9840681239348	0.05057097781341402	1264.332809048971
77.1601	1.3082880061495046	23.6992	2.28131	0.05233152024598018	1202.1768287213029	0.05100819798511421	1265.08856977278
77.5701	1.3194080061495046	23.7037	2.29321	0.05277632024598018	1202.4050978497648	0.05143078916839103	1265.863614359283
77.9801	1.3312980061495046	23.7059	2.30613	0.05325192024598018	1202.5166960903462	0.05188244503790013	1266.553019285009
78.3801	1.3424780061495045	23.7067	2.3184	0.053699120245980184	1202.5572772687394	0.052306944704120194	1267.133545103472
78.8001	1.3541280061495045	23.7061	2.33083	0.05416512024598018	1202.5268413849444	0.05274909842411784	1267.6618523475786
79.2101	1.3651280061495046	23.7076	2.34286	0.05460512024598018	1202.6029310944318	0.05316640325698821	1268.2712087550115
79.6101	1.3760980061495045	23.7092	2.35462	0.05504392024598018	1202.6840934512184	0.0535823966264121	1268.8845407722563
80.0201	1.3877880061495045	23.7099	2.36747	0.05551152024598018	1202.7196019823125	0.05402550273836691	1269.4843955179908
80.4201	1.3987680061495045	23.7103	2.37913	0.055950720245980176	1202.739892571509	0.0544415177614269	1270.0340558294577
80.8501	1.4107780061495045	23.7107	2.39141	0.05643112024598018	1202.7601831607055	0.05489635977821901	1270.6332876837243
81.2501	1.4213380061495045	23.7124	2.40347	0.05685352024598018	1202.8464181647912	0.055296116628320145	1271.2324713527278
81.6601	1.4331380061495045	23.7129	2.41578	0.05732552024598018	1202.871781401287	0.05574262565031111	1271.8270320593247
82.0601	1.4444380061495046	23.7147	2.42773	0.05777752024598018	1202.9630890526719	0.0561700280020903	1272.4673132855796
82.4801	1.4561780061495044	23.7167	2.44046	0.05824712024598018	1203.064541998655	nan	nan
82.9101	1.4681280061495046	23.7145	2.4535	0.05872512024598018	1202.9529437580734	nan	nan
83.3101	1.4793880061495046	23.7115	2.46481	0.05917552024598018	1202.8007643390988	nan	nan
83.7201	1.4914980061495045	23.7128	2.47736	0.05965992024598018	1202.866708753988	nan	nan
84.1201	1.5030180061495046	23.7103	2.48899	0.06012072024598018	1202.739892571509	nan	nan
84.5301	1.5145480061495045	23.7079	2.50177	0.06058192024598018	1202.6181490363292	nan	nan
84.9301	1.5258880061495046	23.7075	2.51362	0.061035520245980183	1202.5978584471327	nan	nan
85.3501	1.5379180061495046	23.702	2.52574	0.061516720245980185	1202.3188628456792	nan	nan
85.7901	1.5505780061495045	23.7009	2.53926	0.06202312024598018	1202.2630637253885	nan	nan
86.2001	1.5627680061495046	23.6982	2.55162	0.06251072024598019	1202.1261022483113	nan	nan
86.6101	1.5742680061495045	23.6959	2.56365	0.06297072024598017	1202.0094313604309	nan	nan
87.0101	1.5861180061495046	23.6915	2.5762	0.06344472024598019	1201.7862348792678	nan	nan
87.4201	1.5981180061495046	23.6863	2.58839	0.06392472024598018	1201.522457219712	nan	nan
87.8201	1.6097280061495045	23.6805	2.60006	0.06438912024598017	1201.2282436763608	nan	nan
88.2301	1.6214880061495045	23.6769	2.61198	0.06485952024598018	1201.0456283735914	nan	nan
88.6301	1.6333080061495044	23.6718	2.6243	0.06533232024598018	1200.7869233613344	nan	nan
89.0501	1.6456780061495044	23.6656	2.63685	0.06582712024598018	1200.472419228787	nan	nan
89.4601	1.6580680061495046	23.6565	2.64977	0.06632272024598018	1200.0108083245636	nan	nan
89.8701	1.6697280061495046	23.6492	2.66109	0.06678912024598019	1199.6405050717253	nan	nan
90.2701	1.6816780061495045	23.6428	2.67318	0.06726712024598018	1199.3158556445796	nan	nan
90.6701	1.6935980061495046	23.6358	2.68555	0.06774392024598018	1198.9607703336385	nan	nan
91.0801	1.7063180061495045	23.6232	2.69835	0.06825272024598018	1198.3216167739452	nan	nan
91.5001	1.7183080061495046	23.596	2.71007	0.06873232024598018	1196.941856708575	nan	nan
91.9101	1.7292780061495046	23.5905	2.72129	0.06917112024598018	1196.6628611071214	nan	nan
92.3101	1.7409380061495046	23.591	2.73265	0.06963752024598019	1196.6882243436173	nan	nan
92.7201	1.7539080061495045	23.5826	2.74568	0.07015632024598017	1196.2621219704881	nan	nan
93.1201	1.7665480061495045	23.5688	2.75863	0.07066192024598018	1195.5620966432048	nan	nan
93.5301	1.7794480061495046	23.5503	2.7715	0.07117792024598019	1194.6236568928612	nan	nan
93.9301	1.7924780061495045	23.5308	2.78418	0.07169912024598019	1193.634490669526	nan	nan
94.3401	1.8059980061495045	23.5061	2.79686	0.07223992024598018	1192.3815467866348	nan	nan
94.7501	1.8187280061495046	23.482	2.80962	0.07274912024598018	1191.1590387875385	nan	nan
95.1501	1.8293980061495045	23.4315	2.81913	0.07317592024598019	1188.5973519014653	nan	nan
95.5701	1.8402880061495046	23.4279	2.82967	0.07361152024598018	1188.4147365986958	nan	nan
95.9901	1.8523380061495045	23.4302	2.84169	0.07409352024598018	1188.5314074865764	nan	nan
96.4201	1.8680080061495046	23.4298	2.85764	0.07472032024598019	1188.5111168973797	nan	nan
96.8201	1.8833580061495045	23.384	2.87228	0.07533432024598018	1186.1878444343668	nan	nan
97.2301	1.8951280061495046	23.2877	2.88194	0.07580512024598018	1181.3028850852806	nan	nan
97.6401	1.9048480061495046	23.2772	2.89202	0.07619392024598018	1180.7702571188695	nan	nan
98.0401	1.9178380061495046	23.3179	2.90547	0.07671352024598019	1182.8348245696254	nan	nan
98.4501	1.9331880061495046	23.2785	2.91985	0.07732752024598018	1180.8362015337584	nan	nan
98.8501	1.9469580061495046	23.2077	2.93189	0.07787832024598018	1177.2447672459568	nan	nan
99.2501	1.9578980061495046	23.1636	2.94174	0.07831592024598018	1175.0077297870293	nan	nan
99.6601	1.9694580061495046	23.152	2.95295	0.07877832024598018	1174.4193027003275	nan	nan
100.08	1.9819980061495046	23.1377	2.96545	0.07927992024598018	1173.6939141365483	nan	nan
100.49	1.9948580061495045	23.1118	2.97769	0.07979432024598018	1172.3800984860673	nan	nan
100.9	2.0090680061495045	23.0804	2.99179	0.08036272024598018	1170.7872872341327	nan	nan
101.3	2.0232280061495045	23.0413	3.00455	0.08092912024598017	1168.803882140163	nan	nan
101.71	2.0369380061495046	22.9949	3.01773	0.08147752024598018	1166.4501737933554	nan	nan
102.12	2.0490380061495044	22.91	3.02827	0.08196152024598018	1162.1434962363728	nan	nan
102.53	2.0586380061495047	22.8994	3.03777	0.08234552024598019	1161.6057956226625	nan	nan
102.95	2.0725780061495045	22.9321	3.05198	0.08290312024598018	1163.264551289486	nan	nan
103.36	2.0890880061495047	22.8752	3.06723	0.08356352024598018	1160.378214976267	nan	nan
103.77	2.1018980061495047	22.7768	3.07827	0.08407592024598019	1155.3867300338989	nan	nan
104.17	2.1120080061495043	22.751	3.08787	0.08448032024598018	1154.0779870307167	nan	nan
104.57	2.1235280061495048	22.7612	3.09958	0.08494112024598019	1154.5953970552303	nan	nan
104.98	2.1381780061495044	22.7331	3.11351	0.08552712024598018	1153.169983164168	nan	nan
105.4	2.1535880061495045	22.6828	3.12843	0.08614352024598018	1150.618441572693	nan	nan
105.81	2.1667180061495044	22.6158	3.14041	0.08666872024598017	1147.2197678822592	nan	nan
106.22	2.1795780061495047	22.5801	3.15242	0.08718312024598018	1145.4088327964612	nan	nan
106.62	2.1914180061495045	22.5429	3.16355	0.08765672024598019	1143.5218080011753	nan	nan
107.02	2.2033680061495047	22.5171	3.17543	0.08813472024598018	1142.2130649979933	nan	nan
107.43	2.2160480061495047	22.4881	3.18736	0.0886419202459802	1140.7419972812386	nan	nan
107.83	2.2295080061495045	22.4536	3.19994	0.08918032024598017	1138.9919339630303	nan	nan
108.26	2.2446380061495046	22.3988	3.21331	0.08978552024598019	1136.2121232430934	nan	nan
108.67	2.2560380061495047	22.3325	3.22406	0.09024152024598019	1132.8489580837536	nan	nan
109.07	2.2669480061495046	22.3167	3.23438	0.09067792024598019	1132.0474798104872	nan	nan
109.47	2.2792580061495045	22.3016	3.2467	0.09117032024598018	1131.281510068315	nan	nan
109.88	2.2938880061495044	22.2687	3.26006	0.09175552024598017	1129.612609106893	nan	nan
110.29	2.3093180061495047	22.2212	3.27442	0.09237272024598019	1127.2031016397943	nan	nan
110.71	2.3239880061495044	22.166	3.28791	0.09295952024598017	1124.403000330661	nan	nan
111.11	2.3360380061495047	22.062	3.29781	0.0934415202459802	1119.1274471395398	nan	nan
111.52	2.3454680061495043	22.0632	3.30742	0.09381872024598018	1119.1883189071295	nan	nan
111.92	2.3607780061495047	22.1055	3.32264	0.09443112024598019	1121.3340487146722	nan	nan
112.33	2.3748480061495045	21.9356	3.33327	0.09499392024598018	1112.7156209534082	nan	nan
112.73	2.3844680061495045	21.9556	3.34312	0.09537872024598018	1113.7301504132392	nan	nan
113.15	2.4017580061495045	21.9449	3.36057	0.09607032024598018	1113.1873771522296	nan	nan
113.57	2.4138780061495044	21.8226	3.37019	0.09655512024598017	1106.9835295053633	nan	nan
113.97	2.4241680061495043	21.8408	3.38064	0.09696672024598017	1107.9067513138095	nan	nan
114.37	2.4401480061495047	21.8323	3.39592	0.0976059202459802	1107.4755762933812	nan	nan
114.78	2.4552380061495045	21.735	3.40953	0.09820952024598018	1102.5398904713036	nan	nan
115.19	2.4662980061495046	21.6664	3.41905	0.09865192024598018	1099.060054424083	nan	nan
115.59	2.4769680061495047	21.6689	3.42979	0.09907872024598019	1099.1868706065623	nan	nan
116	2.4904780061495044	21.6607	3.4427	0.09961912024598017	1098.7709135280313	nan	nan
116.4	2.5054580061495044	21.6074	3.45678	0.10021832024598018	1096.0671925175818	nan	nan
116.81	2.5210180061495047	21.5282	3.47021	0.10084072024598019	1092.0496558566513	nan	nan
117.21	2.5319980061495047	21.4595	3.48053	0.10127992024598019	1088.5647471621319	nan	nan
117.62	2.5426780061495045	21.4467	3.49029	0.10170712024598018	1087.9154483078403	nan	nan
118.02	2.5548080061495044	21.4337	3.502	0.10219232024598018	1087.25600415895	nan	nan
118.43	2.5695980061495045	21.3967	3.51596	0.10278392024598018	1085.3791246582628	nan	nan
118.83	2.5845580061495044	21.3437	3.52964	0.10338232024598018	1082.6906215897104	nan	nan
119.24	2.5992080061495044	21.2835	3.54319	0.10396832024598018	1079.6368879156194	nan	nan
119.65	2.6097980061495045	21.1654	3.55157	0.10439192024598018	1073.6460914553177	nan	nan
120.05	2.6203380061495047	21.2293	3.56305	0.10481352024598019	1076.8875130794775	nan	nan
120.46	2.6374180061495047	21.1904	3.57906	0.10549672024598018	1074.9142532801063	nan	nan
120.86	2.6504280061495047	21.0474	3.58874	0.10601712024598019	1067.660367642315	nan	nan
121.27	2.6607880061495046	21.0469	3.59913	0.10643152024598018	1067.6350044058192	nan	nan
121.68	2.6745280061495045	21.0566	3.61255	0.10698112024598018	1068.1270511938371	nan	nan
122.08	2.6901380061495046	20.9886	3.62722	0.10760552024598019	1064.6776510304119	nan	nan
122.49	2.7040280061495046	20.8853	3.63884	0.10816112024598018	1059.4376063703849	nan	nan
122.89	2.7142980061495043	20.8561	3.64789	0.10857192024598017	1057.9563933590318	nan	nan
123.29	2.7259580061495043	20.8539	3.65953	0.10903832024598017	1057.84479511845	nan	nan
123.71	2.7408380061495046	20.8176	3.67354	0.10963352024598018	1056.003424148857	nan	nan
124.11	2.7560380061495047	20.7576	3.68743	0.11024152024598019	1052.9598357693642	nan	nan
124.51	2.7704780061495047	20.6855	3.70004	0.11081912024598019	1049.3024570666735	nan	nan
124.92	2.7815880061495046	20.6075	3.70948	0.11126352024598019	1045.3457921733327	nan	nan
125.32	2.7919980061495044	20.5936	3.72009	0.11167992024598018	1044.6406941987502	nan	nan
125.73	2.8049380061495044	20.58	3.73249	0.11219752024598018	1043.9508141660651	nan	nan
126.14	2.8192080061495046	20.5356	3.74562	0.11276832024598019	1041.6985587652403	nan	nan
126.54	2.8343780061495045	20.479	3.75919	0.11337512024598018	1038.8274403939188	nan	nan
126.95	2.8501680061495045	20.4067	3.77377	0.11400672024598019	1035.1599163966298	nan	nan
127.35	2.8608180061495045	20.3027	3.78205	0.11443272024598018	1029.8843632055089	nan	nan
127.76	2.8711680061495044	20.3451	3.79343	0.11484672024598018	1032.0351656603505	nan	nan
128.16	2.8869480061495048	20.2041	3.80629	0.11547792024598019	1024.8827329685423	nan	nan
128.57	2.9004080061495046	20.2852	3.82075	0.11601632024598019	1028.9966499281568	nan	nan
128.97	2.9125580061495047	20.0968	3.82948	0.11650232024598019	1019.4397824165492	nan	nan
129.38	2.9260980061495045	20.1496	3.84364	0.11704392024598018	1022.1181401905027	nan	nan
129.79	2.9421580061495045	20.0655	3.85847	0.11768632024598018	1017.8520438119135	nan	nan
130.19	2.9544480061495046	19.9871	3.86887	0.11817792024598019	1013.8750883293762	nan	nan
130.59	2.9658480061495047	19.9595	3.8798	0.11863392024598018	1012.4750376748094	nan	nan
131	2.9785580061495045	19.9287	3.89112	0.11914232024598018	1010.9126623066697	nan	nan
131.41	2.9933880061495044	19.8782	3.90549	0.11973552024598018	1008.3509754205966	nan	nan
131.81	3.0082080061495047	19.8178	3.91883	0.12032832024598018	1005.287096451907	nan	nan
132.22	3.0204080061495047	19.7111	3.92882	0.12081632024598019	999.8745817837088	nan	nan
132.63	3.0309680061495046	19.6962	3.93896	0.12123872024598019	999.1187573361348	nan	nan
133.03	3.0462380061495047	19.701	3.95391	0.12184952024598018	999.3622444064941	nan	nan
133.43	3.0628080061495044	19.5943	3.96877	0.12251232024598017	993.9497297382959	nan	nan
133.85	3.0722880061495044	19.5498	3.97652	0.12289152024598017	991.6924016901722	nan	nan
134.25	3.0887880061495046	19.4682	3.99123	0.12355152024598018	987.5531214940618	nan	nan
134.65	3.0984080061495045	19.3957	3.99962	0.12393632024598018	983.8754522021745	nan	nan
135.06	3.1127780061495045	19.4374	4.01383	0.12451112024598018	985.9907461259221	nan	nan
135.46	3.1297680061495043	19.3111	4.02785	0.12519072024598019	979.5839925870894	nan	nan
135.87	3.1412780061495047	19.2262	4.03782	0.12565112024598019	975.2773150301068	nan	nan
136.28	3.1521880061495047	19.2102	4.04824	0.1260875202459802	974.4656914622423	nan	nan
136.68	3.1647380061495047	19.1826	4.06047	0.1265895202459802	973.0656408076757	nan	nan
137.09	3.1802580061495047	19.1281	4.07442	0.1272103202459802	970.301048029636	nan	nan
137.49	3.1962180061495045	19.0561	4.08858	0.12784872024598018	966.6487419742448	nan	nan
137.91	3.2097580061495044	18.9109	4.09996	0.12839032024598018	959.2832580958719	nan	nan
138.33	3.2203780061495046	18.9569	4.11108	0.12881512024598019	961.6166758534831	nan	nan
138.75	3.2386380061495044	18.8644	4.12691	0.12954552024598018	956.9244771017649	nan	nan
139.16	3.2499880061495046	18.76	4.13662	0.1299995202459802	951.6286333214472	nan	nan
139.56	3.2607480061495044	18.7453	4.14665	0.13042992024598019	950.8829541684713	nan	nan
139.97	3.2750280061495047	18.7239	4.16055	0.13100112024598018	949.7974076464524	nan	nan
140.38	3.2915680061495047	18.647	4.17532	0.1316627202459802	945.8965418734022	nan	nan
140.78	3.3064180061495048	18.5205	4.18824	0.1322567202459802	939.4796430399713	nan	nan
141.19	3.3164980061495046	18.4618	4.1964	0.1326599202459802	936.5019990753674	nan	nan
141.59	3.3288080061495045	18.5085	4.20927	0.13315232024598017	938.8709253640727	nan	nan
142.02	3.3472480061495045	18.2926	4.22362	0.13388992024598018	927.9190798451974	nan	nan
142.42	3.3583880061495046	18.3812	4.23621	0.1343355202459802	932.4134453522487	nan	nan
142.83	3.3723780061495043	18.1756	4.2459	0.13489512024598016	921.9840825051863	nan	nan
143.23	3.3845680061495047	18.2357	4.25887	0.1353827202459802	925.0327435319784	nan	nan
143.64	3.4025480061495044	18.134	4.2747	0.13610192024598017	919.873861228738	nan	nan
144.05	3.4129880061495044	17.9929	4.28215	0.13651952024598019	912.7163558896303	nan	nan
144.45	3.4253380061495045	18.0487	4.29504	0.13701352024598018	915.5468930825589	nan	nan
144.85	3.4433980061495046	17.9402	4.31122	0.1377359202459802	910.0430707629758	nan	nan
145.26	3.4545580061495045	17.8073	4.3196	0.13818232024598018	903.3015225023992	nan	nan
145.67	3.4654580061495044	17.8143	4.33027	0.13861832024598017	903.6566078133399	nan	nan
146.07	3.4830180061495044	17.776	4.34659	0.1393207202459802	901.7137838977636	nan	nan
146.48	3.4976380061495047	17.6095	4.35799	0.13990552024598019	893.2678261446708	nan	nan
146.88	3.5083480061495047	17.5761	4.36792	0.14033392024598018	891.573561946753	nan	nan
147.3	3.5211980061495045	17.5468	4.37979	0.14084792024598017	890.0872762881006	nan	nan
147.71	3.5366080061495047	17.4769	4.39347	0.14146432024598019	886.5414958259915	nan	nan
148.11	3.5528780061495047	17.3913	4.40772	0.1421151202459802	882.1993097379151	nan	nan
148.54	3.5667080061495047	17.2288	4.41785	0.1426683202459802	873.9562578767883	nan	nan
148.94	3.5759280061495047	17.2716	4.42777	0.1430371202459802	876.1273509208265	nan	nan
149.35	3.5952080061495044	17.1134	4.4429	0.14380832024598017	868.1024228935636	nan	nan
149.75	3.6045980061495047	17.0808	4.45243	0.14418392024598017	866.4487398740391	nan	nan
150.16	3.6200180061495044	17.0645	4.46746	0.14480072024598017	865.621898364277	nan	nan
150.56	3.6370780061495047	16.9403	4.48208	0.1454831202459802	859.3216704187266	nan	nan
150.97	3.6482880061495044	16.8335	4.49046	0.1459315202459802	853.9040831032293	nan	nan
151.37	3.6594380061495047	16.8277	4.5018	0.1463775202459802	853.6098695598783	nan	nan
151.78	3.6771280061495046	16.7548	4.51736	0.1470851202459802	849.9119096787944	nan	nan
152.19	3.6933480061495048	16.5884	4.52971	0.1477339202459802	841.4710245730008	nan	nan
152.59	3.7015080061495045	16.525	4.53671	0.14806032024598018	838.2549661853366	nan	nan
153	3.7192180061495046	16.5338	4.55455	0.14876872024598017	838.7013591476622	nan	nan