File: original_data/46NT9F.csv
Specimen name:	AWA_2_04_Rz
Specimen ID:	46NT9F
Material:	42CrMoS4
Specimen type:	Round Tensile Specimen
Gauge diameter:	4.99	mm
Gauge length:	25	mm
Parallel length:	30	mm
Original cross-section:	19.556492808412802	mm²
Cross-section after fracture:	8.814130888727863	mm²
Yield stress at 0.2% plastic strain:	1106.555484554111	MPa
Yield stress at 1% plastic strain:	1139.6807488416064	MPa
Ultimate tensile strength:	1192.8007863437151	MPa
Uniform elongation:	5.0265280164062585	%
Elongation after fracture:	14.376390801436681	%
Reduction of area:	54.929899879920164	%
Slope of linear-elastic region:	208809.84306349463	MPa
Crosshead seperation speed:	0.030074472653748394	mm/s
Strain rate:	0.0010024824217916132	s-1
Test temperature:	RT	Cel
Machine type:	INSTRON 8852TT
Standard:	DIN EN ISO 6892-1
Date:	2022-08-23 00:00:00
Heat treatment batch:	Batch 2
Time	Displacement	Force	Machine Displacement	Engineering Strain	Engineering Stress	True Strain	True Stress
s	mm	kN	mm		MPa		MPa
0	0.0009142682753775459	0.150191	0	3.6570731015101835e-05	7.679853513171386	3.6570062322159346e-05	7.680134371028451
0.450001	0.0008916652753775459	0.147732	-0.000492096	3.566661101510184e-05	7.5541152213370655	3.5665974976614496e-05	7.554384651026228
0.870001	0.0008873661753775459	0.152995	3.4332e-05	3.549464701510184e-05	7.823233004958062	3.5494017095055395e-05	7.82351068785209
1.26	0.001764647275377546	0.242537	0.00880432	7.058589101510183e-05	12.401865834331275	7.058339994826831e-05	12.40274123108144
1.68	0.003101018275377546	0.39853	0.0216179	0.00012404073101510184	20.37839831017965	0.0001240330385996515	20.38092606160296
2.1	0.004726608275377546	0.566527	0.0339928	0.00018906433101510182	28.968742276544173	0.00018904646060694753	28.97421923242304
2.51	0.006071908275377545	0.709411	0.045784	0.00024287633101510183	36.27496028811598	0.00024284684133387945	36.28377061737847
2.91	0.007780418275377545	0.881782	0.0583916	0.0003112167310151018	45.0889639895286	0.000311168313133629	45.10299642950628
3.31	0.009307188275377546	1.0813	0.0698776	0.00037228753101510185	55.29110002458349	0.0003722182492067973	55.31168421169875
3.72001	0.010772468275377546	1.34073	0.0827713	0.00043089873101510184	68.5567710496253	0.00043080592081714	68.58631207527307
4.13001	0.012202368275377547	1.58694	0.0951195	0.00048809473101510186	81.14645174605802	0.000487975651528325	81.18605890159584
4.55001	0.013985768275377546	1.8724	0.108059	0.0005594307310151018	95.74313852402676	0.0005592743079795015	95.79670017800093
4.98001	0.015542068275377546	2.16616	0.120464	0.0006216827310151019	110.76423677911015	0.0006214895663599581	110.83309699232979
5.37001	0.017260668275377547	2.45797	0.132267	0.0006904267310151019	125.685623904028	0.0006901884961291135	125.77240061847566
5.79001	0.019154968275377545	2.77947	0.145302	0.0007661987310151018	142.1251769031065	0.0007659053506162125	142.23407303329495
6.19001	0.021122068275377548	3.10583	0.157181	0.0008448827310151019	158.81324071890515	0.000844526018506453	158.94741928344507
6.62001	0.023261268275377545	3.4473	0.169876	0.0009304507310151018	176.27393795870404	0.0009300181300554199	176.4379521731366
7.03001	0.025350868275377546	3.78432	0.181988	0.0010140347310151018	193.507089286074	0.0010135209450990118	193.70331219530772
7.43001	0.027296168275377546	4.12368	0.19392	0.0010918467310151018	210.85989396964254	0.0010912510998921906	211.09012065557548
7.85001	0.029647068275377546	4.52413	0.207024	0.0011858827310151018	231.33646939260052	0.001185180127504692	231.61080731670722
8.27001	0.031784068275377546	4.88564	0.21907	0.0012713627310151018	249.82189024702313	0.001270555233760265	250.1395044876749
8.69001	0.034248268275377546	5.27761	0.232578	0.0013699307310151019	269.86485008854356	0.0013689932320193271	270.2345462399006
9.08001	0.03638626827537754	5.6431	0.244129	0.0014554507310151016	288.5537839163295	0.0014543925891910522	288.9737597320677
9.48001	0.038793668275377544	6.05805	0.256451	0.0015517467310151016	309.77180107641544	0.0015505440161016932	310.25248845609644
9.90001	0.04118636827537754	6.44703	0.26841	0.0016474547310151016	329.66187051834874	0.0016460991660866655	330.20497352656946
10.3	0.043641768275377545	6.83502	0.280716	0.0017456707310151017	349.5013173865058	0.001744148818778844	350.1114316067186
10.72	0.046022068275377546	7.23681	0.293732	0.0018408827310151018	370.04641225275697	0.0018391903830248283	370.72762430274713
11.13	0.048221268275377545	7.60821	0.304562	0.0019288507310151017	389.03754750581373	0.0019269928870626865	389.78794286371266
11.54	0.05094836827537754	8.02876	0.317982	0.0020379347310151017	410.5419145781698	0.0020358609590278337	411.37857220442606
11.97	0.053366168275377546	8.43894	0.330772	0.0021346467310151018	431.5160229736971	0.002132371609826638	432.4371572415185
12.38	0.05572406827537754	8.83241	0.343685	0.002228962731015102	451.6356836845755	0.0022264822787934424	452.6423627915049
12.79	0.058190768275377544	9.2342	0.355469	0.0023276307310151016	472.18077855082663	0.00232492599487672	473.2798410415762
13.2	0.06070606827537754	9.6361	0.368137	0.0024282427310151015	492.73149814749746	0.0024252993135598796	493.9279698262163
13.6	0.06303266827537754	10.0185	0.379539	0.002521306731015102	512.2851064425134	0.002518133569755177	513.5767343295857
14.01	0.06556006827537755	10.4303	0.392506	0.002622402731015102	533.3420517769474	0.0026189702325925394	534.7406894300925
14.42	0.06790996827537756	10.8342	0.404579	0.0027163987310151023	553.9950391994289	0.002712715987674163	555.4999106208988
14.84	0.07046596827537754	11.2348	0.417873	0.002818638731015102	574.4792847093227	0.0028146738175588945	576.0985342713702
15.26	0.07299586827537755	11.6456	0.429779	0.002919834731015102	595.4850961308514	0.002915580293078716	597.2238141963361
15.68	0.07566876827537755	12.0724	0.442581	0.003026750731015102	617.309050158866	0.003022179342999709	619.1774907776966
16.08	0.07791836827537756	12.445	0.454491	0.003116734731015102	636.3615461074093	0.003111887781815145	638.3449162396446
16.5	0.08042166827537756	12.8546	0.467606	0.0032168667310151023	657.3059968334514	0.0032117036848236975	659.4204626267617
16.92	0.08303456827537754	13.267	0.480095	0.0033213827310151016	678.3936225156286	0.003315879122418757	680.6468273782828
17.32	0.08543276827537755	13.6681	0.492508	0.003417310731015102	698.9034349819751	0.0034114849931638986	701.2918051902824
17.74	0.08778626827537755	14.0557	0.5047	0.0035114507310151023	718.722939624099	0.0035052999823918366	721.2466998158393
18.14	0.09024286827537754	14.4487	0.517059	0.0036097147310151017	738.8185673959119	0.003603215346715049	741.4854916621883
18.55	0.09291856827537755	14.86	0.529366	0.003716742731015102	759.8499457738932	0.0037098527097645245	762.6741125365106
18.97	0.09520446827537755	15.2474	0.541061	0.0038081787310151024	779.6592236334361	0.00380094597499441	782.6283053063167
19.37	0.09771176827537754	15.6328	0.553463	0.003908470731015102	799.366233667168	0.003900852503249022	802.4905331948179
19.78	0.10023116827537755	16.0333	0.56649	0.004009246731015102	819.8453657857714	0.004001231118575969	823.1323281384858
20.19	0.10248426827537754	16.4215	0.578136	0.0040993707310151015	839.6955507756385	0.004090991203540281	843.1377741394517
20.6	0.10500426827537755	16.8135	0.590481	0.004200170731015102	859.7400446345459	0.004191374635397539	863.3510996063015
21.01	0.10731826827537755	17.2122	0.603516	0.0042927307310151016	880.1271357099196	0.004283543245999106	883.9052845125817
21.42	0.10985526827537755	17.5996	0.615822	0.004394210731015102	899.9364135694623	0.004384584376890884	903.8909238152005
21.84	0.11236126827537755	17.9815	0.62838	0.004494450731015102	919.4644549080256	0.004484380848448771	923.5969425995294
22.25	0.11481626827537755	18.3843	0.641178	0.004592650731015102	940.0611950263112	0.0045821366899019035	944.3785677608477
22.66	0.11720026827537755	18.7499	0.652508	0.004688010731015102	958.7557535845169	0.004677056231905755	963.2504108457435
23.08	0.11957626827537755	19.1671	0.664875	0.004783050731015102	980.0888220486399	0.004771648288386403	984.7766366053995
23.48	0.12205126827537754	19.5242	0.676395	0.0048820507310151015	998.3487423471498	0.004870172166825562	1003.2227315545337
23.88	0.12447426827537755	19.8931	0.689335	0.004978970731015102	1017.2120428179433	0.004966616646359454	1022.2767118063698
24.29	0.12696926827537755	20.274	0.701843	0.005078770731015102	1036.688950243601	0.005065917276409525	1041.9540557412652
24.7	0.12946326827537755	20.617	0.713413	0.0051785307310151015	1054.2278823701452	0.005165168252898189	1059.687233856492
25.12	0.13266126827537755	20.991	0.726521	0.0053064507310151025	1073.3519657967558	0.005292421131036842	1079.0476551202946
25.55	0.13644126827537756	21.3184	0.739697	0.005457650731015102	1090.0932088819761	0.005442811721534204	1096.0425568803055
25.96	0.14148226827537755	21.5405	0.751572	0.005659290731015102	1101.4500509382601	0.005643337107719937	1107.6834770022112
26.37	0.14893826827537754	21.6561	0.763916	0.005957530731015102	1107.3611312701216	0.005939854813282192	1113.9582692399952
26.78	0.15825126827537755	21.6997	0.775822	0.006330050731015102	1109.590569872796	0.0063101001079282	1116.6143344707468
27.19	0.17003926827537755	21.6442	0.788105	0.006801570731015102	1106.7526377065478	0.00677854439999108	1114.2802940536465
27.61	0.18198826827537756	21.6338	0.801247	0.007279530731015103	1106.2208450123317	0.007253162833802169	1114.2736136488886
28.03	0.19371926827537755	21.6586	0.813549	0.007748770731015102	1107.488966052385	0.007718903198978705	1116.0706441374539
28.44	0.20358526827537754	21.7033	0.825302	0.008143410731015101	1109.7746519592554	0.008110432080007706	1118.812002769029
28.85	0.21389726827537756	21.7625	0.838398	0.008555890731015103	1112.8017796032539	0.008519496540388699	1122.3227900348184
29.26	0.22366526827537755	21.7943	0.850113	0.008946610731015102	1114.4278380336448	0.008906826920005695	1124.3981900883384
29.67	0.23369526827537754	21.8552	0.862743	0.0093478107310151	1117.541893329582	0.009304390329009172	1127.9884634324073
30.09	0.24354326827537756	21.8894	0.875622	0.009741730731015103	1119.2906731509458	0.009694586005732388	1130.194501498519
30.5	0.25291226827537755	21.9405	0.887897	0.010116490731015101	1121.9036161004108	0.010065661559767224	1133.253343633783
30.9	0.26202426827537756	21.9646	0.899441	0.010480970731015102	1123.1359434014305	0.01042642614638548	1134.907498351172
31.33	0.27233126827537757	21.9983	0.912487	0.010893250731015103	1124.8591562663414	0.01083434666039961	1137.1125290926288
31.73	0.28217626827537756	22.032	0.924316	0.011287050731015102	1126.5823691312528	0.011223827266746653	1139.2981614843045
32.16	0.29226226827537755	22.0643	0.93684	0.011690490731015102	1128.2339945180963	0.011622684888326445	1141.4236035734264
32.56	0.30211526827537755	22.0926	0.949203	0.012084610731015102	1129.6810842533187	0.012012174812080948	1143.332840406711
32.96	0.31184326827537756	22.1162	0.960842	0.012473730731015103	1130.8878445978855	0.012396574704958918	1144.9942350583776
33.39	0.32238626827537753	22.1443	0.974266	0.012895450731015102	1132.3247075505267	0.012813012369710976	1146.9265450282555
33.79	0.33255426827537754	22.1714	0.986225	0.013302170731015101	1133.7104365902621	0.013214473709073447	1148.7912463773193
34.2	0.34242226827537753	22.1882	0.998192	0.0136968907310151	1134.5694863270724	0.01360393615382136	1150.1095606080382
34.6	0.35209426827537754	22.2053	1.00929	0.014083770731015102	1135.4438762377545	0.013985515889782824	1151.4352074686221
35.02	0.36250126827537754	22.2298	1.02172	0.014500050731015101	1136.696657103936	0.014395930289660283	1153.1788162977184
35.44	0.37313226827537754	22.2625	1.03472	0.014925290731015102	1138.368736055942	0.014815004593637533	1155.3592204006752
35.8601	0.38344726827537756	22.2812	1.04662	0.015337890731015102	1139.3249402272722	0.015221454367684106	1156.7997816675984
36.2801	0.3942562682753776	22.3052	1.06034	0.015770250731015102	1140.5521541370015	0.01564719241452128	1158.5389475795414
36.6901	0.40454526827537757	22.3119	1.07196	0.016181810731015104	1140.8947513534677	0.01605228071698047	1159.3564942838782
37.1101	0.41523426827537757	22.3367	1.08531	0.016609370731015104	1142.162872393521	0.016472943705096506	1161.133478976306
37.5301	0.42559826827537756	22.3558	1.09753	0.017023930731015102	1143.1395301300136	0.0168806474985429	1162.600258306832
37.9401	0.43554226827537756	22.3741	1.10992	0.017421690731015103	1144.0752807361819	0.017271672946332785	1164.007006450167
38.3401	0.44597426827537756	22.4025	1.12217	0.017838970731015102	1145.5274838626947	0.01768172362313116	1165.9625151188948
38.7601	0.45581526827537755	22.4104	1.13439	0.018232610731015102	1145.931441774647	0.018068389797826025	1166.8247636769552
39.1601	0.4659742682753775	22.437	1.14658	0.0186389707310151	1147.29160385793	0.018467393848046458	1168.6759384821773
39.5701	0.47673126827537754	22.4602	1.15876	0.019069250731015102	1148.4779106373348	0.018889711431950985	1170.3785238743105
39.9801	0.48655226827537756	22.4676	1.17088	0.019462090731015104	1148.8563015928348	0.019275126163500866	1171.215447171333
40.3901	0.49701026827537753	22.4759	1.18321	0.0198804107310151	1149.2807130699491	0.019685376041162213	1172.1288856910137
40.8001	0.5068012682753775	22.5027	1.19536	0.020272050731015102	1150.6511019358134	0.020069308136639066	1173.9771594479546
41.2201	0.5170062682753775	22.5146	1.20752	0.020680250731015103	1151.2595954993874	0.020469317490263438	1175.0679325908018
41.6201	0.5273652682753776	22.5387	1.21967	0.021094610731015102	1152.4919228004067	0.020875199660241497	1176.8032912825204
42.0301	0.5377912682753776	22.5642	1.23257	0.021511650731015103	1153.795837579494	0.02128354072299379	1178.615890652403
42.4401	0.5474662682753776	22.5739	1.24457	0.021898650731015105	1154.2918365346761	0.021662319281905852	1179.5692703046109
42.8601	0.5578822682753776	22.588	1.25721	0.022315290731015104	1155.012824706642	0.022069947854746138	1180.7872716880217
43.2701	0.5686832682753775	22.6111	1.26987	0.022747330731015102	1156.1940180947563	0.022492467930066404	1182.494345813579
43.6801	0.5785092682753775	22.6334	1.28181	0.0231403707310151	1157.334304352546	0.02287669234722724	1184.1154492149856
44.0901	0.5887632682753775	22.6525	1.29413	0.0235505307310151	1158.3109620890386	0.02327749542423093	1185.5897999977883
44.5001	0.5983022682753776	22.662	1.30609	0.023932090731015102	1158.7967342616398	0.023650206772710805	1186.5291628447935
44.9001	0.6082712682753776	22.6754	1.31719	0.024330850731015104	1159.481928694572	0.02403957084991578	1187.693110426949
45.3101	0.6187012682753775	22.703	1.33074	0.0247480507310151	1160.8932246907602	0.024446778210713126	1189.623069108699
45.7301	0.6292662682753776	22.7231	1.34335	0.025170650731015102	1161.9210163401583	0.02485908725075987	1191.1673244194826
46.1301	0.6390332682753775	22.7215	1.35551	0.025561330731015103	1161.8392020795097	0.025240102428031142	1191.537358180123
46.5401	0.6489362682753775	22.7419	1.36742	0.025957450731015103	1162.8823339027795	0.025626274866228815	1193.0677947910287
46.9501	0.6594262682753775	22.7558	1.38022	0.0263770507310151	1163.593095292164	0.026035175077717094	1194.2852493969442
47.3701	0.6698172682753776	22.7755	1.39183	0.026792690731015104	1164.6004333764001	0.026440051496149017	1195.8032126130604
47.7701	0.6798082682753775	22.7922	1.40436	0.027192330731015103	1165.4543697219199	0.02682918773703405	1197.145790395305
48.1701	0.6900132682753776	22.8013	1.41576	0.027600530731015104	1165.919688329359	0.027226502729728236	1198.099690516989
48.5901	0.6998842682753775	22.8024	1.4282	0.0279953707310151	1165.9759356335546	0.027610663842887514	1198.617864215058
49.0001	0.7098232682753776	22.8411	1.441	0.028392930731015103	1167.954818062993	0.027997322339894687	1201.1164783092108
49.4101	0.7202262682753775	22.8476	1.45288	0.0288090507310151	1168.2871884968777	0.02840187182937104	1201.9444333786792
49.8401	0.7307232682753776	22.8622	1.46572	0.029228930731015103	1169.0337436252962	0.028809910951688462	1203.2033499399392
50.2601	0.7413452682753775	22.8792	1.47851	0.0296538107310151	1169.9030201446876	0.029222639658841157	1204.5951028777013
50.6701	0.7514932682753775	22.8887	1.49082	0.030059730731015102	1170.3887923172888	0.029616791561116834	1205.5703642649444
51.0801	0.7613032682753775	22.8944	1.50275	0.0304521307310151	1170.6802556208493	0.029997667800737423	1206.3299638092335
51.4901	0.7717052682753776	22.9158	1.51511	0.030868210731015103	1171.7745213570242	0.030401370221251015	1207.9451042115074
51.9001	0.7815842682753775	22.934	1.5274	0.0312633707310151	1172.7051585719023	0.030784624140049493	1209.3678747025094
52.3201	0.7921382682753776	22.9461	1.53961	0.031685530731015106	1173.3238789180573	0.03119390233942111	1210.5012687409492
52.7501	0.8031622682753775	22.9553	1.55348	0.0321264907310151	1173.7943109167868	0.03162122808626675	1211.504202966573
53.1601	0.8131142682753776	22.9689	1.56547	0.032524570731015105	1174.4897321322999	0.032006842888073525	1212.6895064978878
53.5801	0.8233562682753776	22.9805	1.57745	0.0329342507310151	1175.0828855220022	0.03240353925511368	1213.7833599035087
53.9801	0.8334312682753775	22.9989	1.58989	0.0333372507310151	1176.023749519461	0.03279361384581946	1215.2291481228197
54.3801	0.8435062682753776	23.0121	1.60122	0.0337402507310151	1176.698717169812	0.033183536337667116	1216.4008269219853
54.7901	0.8541712682753776	23.0305	1.61424	0.0341668507310151	1177.639581167271	0.03359612741175363	1217.8758169519483
55.1901	0.8637642682753776	23.0244	1.62507	0.034550570731015105	1177.3276642985484	0.033967101233910134	1218.0050070374764
55.6001	0.8744912682753776	23.0361	1.63819	0.034979650731015104	1177.9259310795412	0.03438176539459591	1219.1293687357095
56.0101	0.8844982682753776	23.0584	1.651	0.035379930731015106	1179.066217337331	0.034768442190811974	1220.781498434006
56.4301	0.8949382682753776	23.0609	1.66248	0.035797530731015104	1179.1940521195945	0.03517169108032437	1221.4062874381762
56.8401	0.9054932682753776	23.0845	1.67524	0.0362197307310151	1180.4008124641614	0.03557921664847051	1223.1546120462847
57.2401	0.9156262682753775	23.0818	1.68663	0.0366250507310151	1180.2627508993169	0.03597029272786704	1223.4899340269317
57.6601	0.9260872682753776	23.0956	1.69958	0.0370434907310151	1180.9683988974111	0.036373867356418205	1224.7155908355892
58.0801	0.9367912682753775	23.1072	1.71221	0.0374716507310151	1181.5615522871133	0.03678664815278077	1225.836614091612
58.4901	0.9469902682753776	23.1082	1.72399	0.037879610731015104	1181.6126862000187	0.03717979606256381	1226.3717147881046
58.8901	0.9574732682753776	23.1355	1.73585	0.038298930731015104	1183.0086420223356	0.03758373050011577	1228.3166080573412
59.3201	0.9681472682753776	23.1375	1.74831	0.0387258907310151	1183.1109098481463	0.03799485703226125	1228.9279336655975
59.7201	0.9782632682753776	23.1404	1.76024	0.039130530731015106	1183.259198195572	0.038384335343597455	1229.56075861332
60.1201	0.9887182682753776	23.1508	1.77276	0.0395487307310151	1183.7909908897877	0.03878670622725971	1230.6084220302896
60.5401	0.9992002682753776	23.1488	1.78563	0.0399680107310151	1183.6887230639772	0.03918995376773085	1230.99840664958
60.9501	1.0093642682753776	23.1678	1.79746	0.04037457073101511	1184.6602674091791	0.03958081247417523	1232.4904171679143
61.3601	1.0202442682753776	23.171	1.81036	0.040809770731015105	1184.8238959304765	0.039999035884445346	1233.1762874800274
61.7701	1.0303742682753776	23.177	1.82228	0.041214970731015106	1185.1306994079087	0.04038827237817826	1233.9758264964332
62.1701	1.0410042682753775	23.1912	1.83393	0.0416401707310151	1185.8568009711648	0.0407965580985265	1235.2360806261395
62.5901	1.0517342682753776	23.2071	1.84753	0.042069370731015104	1186.6698301863605	0.04120851571308818	1236.5922832077813
63.0101	1.0628242682753775	23.2118	1.85943	0.0425129707310151	1186.9101595770157	0.041634116561634904	1237.3692364514577
63.4001	1.0730542682753776	23.2058	1.8717	0.042922170731015105	1186.6033560995834	0.04202655265050289	1237.5349479400852
63.8101	1.0831442682753776	23.2225	1.88383	0.0433257707310151	1187.4572924451033	0.042413467357057116	1238.9047948504517
64.2201	1.0938042682753775	23.2289	1.89617	0.043752170731015096	1187.7845494876976	0.04282207692305546	1239.7527018885453
64.6201	1.1042742682753774	23.2373	1.90825	0.0441709707310151	1188.214074356103	0.04322324112043424	1240.6986434566668
65.0501	1.1150142682753776	23.2401	1.92105	0.04460057073101511	1188.357249312238	0.04363458338312772	1241.3586608639032
65.4701	1.1260242682753776	23.238	1.93421	0.0450409707310151	1188.2498680951367	0.04405609108938467	1241.7697956251423
65.8901	1.1372842682753777	23.2513	1.94627	0.045491370731015106	1188.929949136778	0.044486986127969835	1243.0160022261662
66.3001	1.1484542682753776	23.2537	1.95898	0.0459381707310151	1189.052670527751	0.04491425369586013	1243.6755751146243
66.7201	1.1593842682753777	23.2607	1.97189	0.04637537073101511	1189.4106079180888	0.04533216429835756	1244.569965811692
67.1401	1.1696742682753776	23.2667	1.98338	0.0467869707310151	1189.717411395521	0.045725444835802875	1245.3806851006623
67.5401	1.1808042682753777	23.2649	1.99606	0.047232170731015106	1189.6253703522914	0.046150655855026826	1245.8139589507177
67.9501	1.1910242682753776	23.2637	2.00789	0.0476409707310151	1189.5640096568047	0.046540942022812455	1246.2359938235334
68.3601	1.2024042682753775	23.2843	2.02142	0.0480961707310151	1190.6173682626556	0.046975347653320836	1247.881504481928
68.7701	1.2129242682753776	23.2831	2.03352	0.0485169707310151	1190.5560075671692	0.04737675695227901	1248.3181785399397
69.1701	1.2236942682753775	23.2948	2.04509	0.048947770731015104	1191.154274348162	0.04778753859503262	1249.4586206742244
69.5801	1.2350942682753776	23.2932	2.05738	0.0494037707310151	1191.0724600875133	0.04822216548968585	1249.9159308297028
70.0001	1.2463042682753775	23.2954	2.07033	0.049852170731015104	1191.1849546959054	0.04864936447763499	1250.5681104296223
70.4101	1.2570042682753775	23.292	2.08239	0.0502801707310151	1191.011099392027	0.04905695784446779	1250.8953408119924
70.8101	1.2676242682753776	23.2929	2.0936	0.050704970731015105	1191.0571199136416	0.04946133957702318	1251.44963631783
71.2201	1.2788342682753775	23.3001	2.10621	0.0511533707310151	1191.4252840865606	0.049888009631761876	1252.3707033417454
71.6301	1.2895442682753775	23.3068	2.11852	0.0515817707310151	1191.7678813030266	0.050295478929706414	1253.241378920987
72.0301	1.3002442682753776	23.3126	2.13005	0.052009770731015106	1192.0644579978775	0.0507024020395118	1254.063457154939
72.4301	1.3110142682753776	23.3085	2.14228	0.0524405707310151	1191.8548089549656	0.05111182011655545	1254.356355365069
72.8501	1.3225342682753776	23.3145	2.15501	0.052901370731015106	1192.161612432398	0.05154956374221858	1255.228595862969
73.2801	1.3343442682753774	23.3134	2.16783	0.0533737707310151	1192.105365128202	0.05199812812834441	1255.7325235737678
73.6801	1.3458442682753775	23.3131	2.18007	0.0538337707310151	1192.0900249543304	0.05243472490227938	1256.2647260484518
74.0801	1.3570342682753775	23.3264	2.19244	0.054281370731015105	1192.7701059959718	0.05285936964574972	1257.5153023164112
74.5101	1.3682042682753774	23.3079	2.20455	0.054728170731015095	1191.8241286072225	0.05328307565361786	1257.0504829989818
74.9101	1.3793442682753776	23.3062	2.21698	0.05517377073101511	1191.7372009552832	0.05370546495794396	1257.4898360524119
75.3201	1.3907742682753776	23.3149	2.22891	0.055630970731015104	1192.1820659975601	0.05413866467383364	1258.5043116171116
75.7201	1.4019642682753775	23.327	2.24152	0.0560785707310151	1192.8007863437151	nan	nan
76.1301	1.4127942682753776	23.3112	2.25319	0.056511770731015105	1191.9928705198101	nan	nan
76.5401	1.4243642682753777	23.3009	2.2649	0.056974570731015105	1191.4661912168847	nan	nan
76.9601	1.4362942682753777	23.3172	2.27853	0.05745177073101511	1192.2996739972425	nan	nan
77.3701	1.4476642682753775	23.3077	2.291	0.0579065707310151	1191.8139018246413	nan	nan
77.7801	1.4592242682753775	23.3106	2.30279	0.0583689707310151	1191.962190172067	nan	nan
78.1901	1.4705342682753775	23.3088	2.31533	0.0588213707310151	1191.8701491288375	nan	nan
78.5901	1.4818142682753777	23.3125	2.32715	0.059272570731015106	1192.0593446065873	nan	nan
79.0201	1.4941342682753775	23.3069	2.34038	0.0597653707310151	1191.772994694317	nan	nan
79.4201	1.5055942682753776	23.3016	2.3522	0.060223770731015105	1191.5019849559187	nan	nan
79.8401	1.5172342682753774	23.2955	2.3636	0.060689370731015095	1191.1900680871959	nan	nan
80.2701	1.5290742682753775	23.3013	2.37643	0.0611629707310151	1191.486644782047	nan	nan
80.6801	1.5411342682753775	23.2902	2.38917	0.0616453707310151	1190.919058348797	nan	nan
81.1001	1.5531942682753777	23.2932	2.40131	0.06212777073101511	1191.0724600875133	nan	nan
81.5201	1.5656542682753776	23.2976	2.41422	0.0626261707310151	1191.297449304297	nan	nan
81.9301	1.5775942682753776	23.2917	2.42708	0.0631037707310151	1190.9957592181552	nan	nan
82.3401	1.5895442682753775	23.2665	2.43908	0.0635817707310151	1189.70718461294	nan	nan
82.7501	1.6009642682753775	23.2621	2.45077	0.0640385707310151	1189.4821953961562	nan	nan
83.1601	1.6129042682753776	23.2546	2.46332	0.06451617073101511	1189.0986910493657	nan	nan
83.5801	1.6253542682753777	23.2691	2.47612	0.0650141707310151	1189.840132786494	nan	nan
83.9901	1.6370342682753776	23.2507	2.48804	0.0654813707310151	1188.8992687890347	nan	nan
84.4001	1.6492242682753775	23.2409	2.50018	0.0659689707310151	1188.3981564425624	nan	nan
84.8201	1.6618442682753776	23.231	2.51234	0.0664737707310151	1187.891930704799	nan	nan
85.2201	1.6741642682753775	23.2262	2.52513	0.0669665707310151	1187.646487922853	nan	nan
85.6301	1.6861642682753775	23.2114	2.53659	0.06744657073101509	1186.8897060118536	nan	nan
86.0501	1.6983342682753775	23.194	2.54892	0.0679333707310151	1185.9999759273	nan	nan
86.4601	1.7107942682753776	23.1925	2.56149	0.0684317707310151	1185.923275057942	nan	nan
86.8701	1.7228642682753776	23.1772	2.5735	0.0689145707310151	1185.1409261904898	nan	nan
87.2801	1.7354042682753776	23.1632	2.58553	0.06941617073101511	1184.4250514098146	nan	nan
87.6901	1.7473942682753776	23.1502	2.59749	0.0698957707310151	1183.7603105420446	nan	nan
88.1001	1.7601642682753775	23.1395	2.61026	0.0704065707310151	1183.213177673957	nan	nan
88.5001	1.7725942682753775	23.1217	2.62255	0.0709037707310151	1182.3029940242413	nan	nan
88.9201	1.7856442682753775	23.1002	2.63453	0.0714257707310151	1181.203614896776	nan	nan
89.3301	1.7977342682753776	23.0758	2.64617	0.07190937073101511	1179.9559474218845	nan	nan
89.7501	1.8110142682753776	23.0709	2.65998	0.0724405707310151	1179.7053912486483	nan	nan
90.1601	1.8236642682753776	23.0443	2.67189	0.07294657073101511	1178.3452291653653	nan	nan
90.5701	1.8357842682753776	23.0126	2.68377	0.0734313707310151	1176.7242841262648	nan	nan
90.9801	1.8488542682753775	23.0117	2.69699	0.0739541707310151	1176.67826360465	nan	nan
91.3901	1.8609442682753776	22.9724	2.70852	0.07443777073101511	1174.6687008274687	nan	nan
91.8001	1.8738842682753776	22.9607	2.72063	0.0749553707310151	1174.0704340464758	nan	nan
92.2101	1.8866942682753776	22.9396	2.73298	0.0754677707310151	1172.9915084841723	nan	nan
92.6301	1.9000742682753775	22.8981	2.74522	0.0760029707310151	1170.869451098599	nan	nan
93.0401	1.9130542682753775	22.8753	2.75721	0.0765221707310151	1169.7035978843567	nan	nan
93.4601	1.9260442682753776	22.8357	2.76966	0.0770417707310151	1167.6786949333036	nan	nan
93.8701	1.9384242682753776	22.8047	2.78146	0.0775369707310151	1166.093543633237	nan	nan
94.2801	1.9518442682753776	22.7773	2.79408	0.07807377073101511	1164.6924744196297	nan	nan
94.6901	1.9642642682753775	22.7589	2.80595	0.0785705707310151	1163.7516104221709	nan	nan
95.1001	1.9774442682753774	22.7117	2.81873	0.0790977707310151	1161.3380897330371	nan	nan
95.5101	1.9898842682753775	22.6908	2.82981	0.0795953707310151	1160.2693909533145	nan	nan
95.9201	2.0031842682753775	22.6642	2.84224	0.0801273707310151	1158.9092288700317	nan	nan
96.3601	2.0174842682753775	22.6233	2.85587	0.0806993707310151	1156.8178518322018	nan	nan
96.7701	2.0298742682753774	22.5798	2.86693	0.0811949707310151	1154.5935266208178	nan	nan
97.1701	2.043264268275377	22.5536	2.88019	0.08173057073101508	1153.2538181026969	nan	nan
97.5801	2.056134268275377	22.5258	2.8926	0.08224537073101508	1151.8322953239276	nan	nan
97.9901	2.0694342682753772	22.4847	2.90471	0.08277737073101508	1149.7306915035167	nan	nan
98.4101	2.082634268275377	22.4525	2.91757	0.08330537073101509	1148.0841795079634	nan	nan
98.8101	2.0948842682753774	22.4194	2.92898	0.0837953707310151	1146.3916469907954	nan	nan
99.2201	2.1073642682753775	22.3773	2.94054	0.0842945707310151	1144.2389092574792	nan	nan
99.6401	2.120534268275377	22.3509	2.95345	0.08482137073101509	1142.8889739567771	nan	nan
100.04	2.1337842682753774	22.3119	2.96544	0.08535137073101509	1140.8947513534677	nan	nan
100.45	2.1473342682753773	22.288	2.97848	0.08589337073101509	1139.6726508350291	nan	nan
100.86	2.1599742682753775	22.2458	2.99024	0.0863989707310151	1137.514799710422	nan	nan
101.27	2.1735842682753774	22.2042	3.00254	0.0869433707310151	1135.3876289335585	nan	nan
101.67	2.1861942682753774	22.172	3.01518	0.0874477707310151	1133.7411169380055	nan	nan
102.09	2.199304268275377	22.1387	3.02713	0.08797217073101508	1132.0383576382565	nan	nan
102.49	2.2120642682753773	22.1009	3.0392	0.08848257073101509	1130.105495730433	nan	nan
102.91	2.225134268275377	22.0495	3.05093	0.08900537073101508	1127.4772126070968	nan	nan
103.33	2.238614268275377	22.0198	3.06343	0.08954457073101509	1125.958535393807	nan	nan
103.75	2.2520542682753772	21.988	3.07647	0.09008217073101508	1124.3324769634162	nan	nan
104.15	2.2647342682753773	21.9374	3.08793	0.09058937073101508	1121.745100970404	nan	nan
104.55	2.277394268275377	21.9036	3.09946	0.09109577073101509	1120.0167747142025	nan	nan
104.96	2.2907742682753773	21.8669	3.1122	0.09163097073101509	1118.1401601105752	nan	nan
105.37	2.3043342682753774	21.8328	3.12507	0.0921733707310151	1116.3964936805016	nan	nan
105.8	2.3175342682753772	21.7884	3.13681	0.09270137073101509	1114.126147947503	nan	nan
106.19	2.3301142682753775	21.7488	3.14915	0.0932045707310151	1112.10124499645	nan	nan
106.6	2.342604268275377	21.7211	3.16108	0.09370417073101509	1110.684835608971	nan	nan
107.01	2.3561142682753773	21.6794	3.17353	0.0942445707310151	1108.552551440817	nan	nan
107.42	2.3686942682753775	21.6301	3.18497	0.0947477707310151	1106.031649534582	nan	nan
107.84	2.382264268275377	21.5922	3.19724	0.09529057073101509	1104.093674235468	nan	nan
108.25	2.395954268275377	21.5488	3.20976	0.09583817073101508	1101.8744624153749	nan	nan
108.66	2.4088042682753774	21.5257	3.2217	0.0963521707310151	1100.6932690272606	nan	nan
109.07	2.4218742682753773	21.4658	3.23457	0.09687497073101509	1097.6303476442288	nan	nan
109.47	2.434794268275377	21.4529	3.24702	0.09739177073101508	1096.9707201677493	nan	nan
109.88	2.447684268275377	21.399	3.25866	0.09790737073101509	1094.2146022621494	nan	nan
110.29	2.461104268275377	21.3597	3.27152	0.0984441707310151	1092.2050394849682	nan	nan
110.7	2.4736542682753773	21.3213	3.28282	0.0989461707310151	1090.2414972294016	nan	nan
111.11	2.486924268275377	21.2739	3.29605	0.09947697073101508	1087.817749757687	nan	nan
111.52	2.499944268275377	21.2288	3.30754	0.09999777073101508	1085.5116102856543	nan	nan
111.95	2.5137342682753774	21.1958	3.32074	0.1005493707310151	1083.824191159777	nan	nan
112.34	2.527184268275377	21.1539	3.33277	0.10108737073101509	1081.6816802090418	nan	nan
112.77	2.540944268275377	21.0917	3.34572	0.10163777073101508	1078.5011508263274	nan	nan
113.18	2.5535142682753773	21.0664	3.35735	0.1021405707310151	1077.2074628298212	nan	nan
113.6	2.566914268275377	21.0209	3.36976	0.10267657073101509	1074.8808697926268	nan	nan
114.01	2.5803542682753773	20.9796	3.38267	0.10321417073101509	1072.7690391896347	nan	nan
114.42	2.593084268275377	20.9347	3.39505	0.10372337073101509	1070.4731265001833	nan	nan
114.82	2.605694268275377	20.9036	3.40646	0.10422777073101509	1068.8828618088262	nan	nan
115.24	2.6194242682753774	20.8504	3.41883	0.10477697073101509	1066.16253764226	nan	nan
115.65	2.632874268275377	20.8228	3.43209	0.10531497073101509	1064.7512416460715	nan	nan
116.06	2.6462442682753773	20.7662	3.44389	0.10584977073101509	1061.8570621756273	nan	nan
116.48	2.6602342682753775	20.7163	3.45642	0.1064093707310151	1059.3054799216488	nan	nan
116.88	2.6729042682753774	20.6721	3.46791	0.1069161707310151	1057.0453609712313	nan	nan
117.28	2.6854942682753773	20.6262	3.48016	0.1074197707310151	1054.6983143688747	nan	nan
117.7	2.6990142682753775	20.5919	3.49249	0.1079605707310151	1052.94442115622	nan	nan
118.12	2.7120742682753773	20.5426	3.5046	0.1084829707310151	1050.423519249985	nan	nan
118.53	2.7257242682753775	20.5065	3.51841	0.1090289707310151	1048.577584994101	nan	nan
118.94	2.7389242682753774	20.4518	3.52964	0.1095569707310151	1045.7805599581768	nan	nan
119.36	2.7526642682753772	20.4125	3.54156	0.1101065707310151	1043.7709971809957	nan	nan
119.75	2.7655042682753774	20.367	3.55399	0.1106201707310151	1041.444404143801	nan	nan
120.17	2.779424268275377	20.3184	3.56657	0.11117697073101508	1038.9592959765998	nan	nan
120.58	2.792234268275377	20.2616	3.57851	0.11168937073101509	1036.0548897235744	nan	nan
121	2.8052242682753774	20.2252	3.59161	0.1122089707310151	1034.1936152938188	nan	nan
121.43	2.8190942682753772	20.165	3.60386	0.1127637707310151	1031.115353736915	nan	nan
121.86	2.8324842682753775	20.1285	3.61787	0.11329937073101509	1029.2489659158687	nan	nan
122.26	2.8455342682753773	20.0851	3.6298	0.11382137073101509	1027.0297540957756	nan	nan
122.66	2.8580442682753775	20.0334	3.6416	0.1143217707310151	1024.3861307985676	nan	nan
123.08	2.8717042682753773	19.9858	3.65506	0.11486817073101509	1021.9521565442717	nan	nan
123.49	2.8855342682753773	19.9349	3.66668	0.11542137073101509	1019.3494403773877	nan	nan
123.9	2.898674268275377	19.8844	3.67874	0.11594697073101509	1016.7671777756663	nan	nan
124.32	2.911824268275377	19.8472	3.69172	0.11647297073101509	1014.8649962155864	nan	nan
124.72	2.9247242682753773	19.7924	3.70382	0.1169889707310151	1012.0628577883718	nan	nan
125.13	2.9376142682753774	19.7438	3.71627	0.1175045707310151	1009.5777496211704	nan	nan
125.55	2.9512442682753774	19.6911	3.72932	0.1180497707310151	1006.882992411057	nan	nan
125.96	2.964014268275377	19.6598	3.74091	0.11856057073101509	1005.2825009371188	nan	nan
126.39	2.978444268275377	19.5897	3.75503	0.11913777073101509	1001.698013642452	nan	nan
126.81	2.991804268275377	19.5405	3.7676	0.11967217073101509	999.1822251275074	nan	nan
127.22	3.0047142682753774	19.5064	3.7795	0.12018857073101509	997.438558697434	nan	nan
127.62	3.0183242682753773	19.4465	3.79162	0.12073297073101509	994.3756373144021	nan	nan
128.03	3.0315642682753774	19.3763	3.80414	0.1212625707310151	990.7860366284445	nan	nan
128.45	3.0446642682753775	19.3354	3.81665	0.1217865707310151	988.6946595906148	nan	nan
128.86	3.0577742682753772	19.2917	3.82896	0.12231097073101509	986.4601075966497	nan	nan
129.29	3.071314268275377	19.2223	3.84195	0.12285257073101509	982.9114140410167	nan	nan
129.69	3.085144268275377	19.1914	3.85464	0.12340577073101508	981.3313761322406	nan	nan
130.1	3.098164268275377	19.136	3.86692	0.12392657073101508	978.4985573572826	nan	nan
130.52	3.1116742682753773	19.0766	3.87969	0.12446697073101509	975.4612029307033	nan	nan
130.93	3.1252542682753774	19.0295	3.8919	0.12501017073101509	973.0527956328601	nan	nan
131.35	3.139244268275377	18.9716	3.90482	0.12556977073101508	970.0921420756387	nan	nan
131.76	3.1523042682753775	18.9115	3.91694	0.12609217073101509	967.0189939100256	nan	nan
132.17	3.165944268275377	18.8514	3.92907	0.1266377707310151	963.9458457444126	nan	nan
132.57	3.1788842682753775	18.7967	3.94094	0.1271553707310151	961.1488207084885	nan	nan
132.97	3.1917442682753774	18.7433	3.95276	0.1276697707310151	958.4182697593415	nan	nan
133.38	3.204524268275377	18.7036	3.96452	0.1281809707310151	956.388253416998	nan	nan
133.8	3.2181942682753775	18.6334	3.97709	0.1287277707310151	952.7986527310405	nan	nan
134.21	3.2319442682753774	18.5909	3.98996	0.1292777707310151	950.625461432562	nan	nan
134.62	3.2455242682753775	18.5122	4.00197	0.1298209707310151	946.6012224869089	nan	nan
135.04	3.2590742682753775	18.4647	4.01401	0.1303629707310151	944.1723616239035	nan	nan
135.45	3.273124268275377	18.3829	4.02647	0.13092497073101508	939.9896075482436	nan	nan
135.85	3.2859442682753772	18.3421	4.0382	0.1314377707310151	937.9033439017043	nan	nan
136.26	3.2991242682753774	18.2956	4.0504	0.1319649707310151	935.5256169516043	nan	nan
136.68	3.3124242682753775	18.2182	4.06263	0.1324969707310151	931.5678520927282	nan	nan
137.09	3.3262342682753774	18.1679	4.07558	0.13304937073101508	928.9958162735877	nan	nan
137.51	3.3399442682753775	18.1131	4.08779	0.1335977707310151	926.193677846373	nan	nan
137.93	3.3536742682753773	18.0453	4.09982	0.13414697073101509	922.7267985513886	nan	nan
138.34	3.3678042682753775	17.9808	4.1132	0.1347121707310151	919.4286611689918	nan	nan
138.76	3.380974268275377	17.931	4.12521	0.1352389707310151	916.8821923063041	nan	nan
139.16	3.395144268275377	17.8632	4.13741	0.13580577073101507	913.4153130113197	nan	nan
139.57	3.4085142682753773	17.8004	4.14952	0.1363405707310151	910.204103280862	nan	nan
139.98	3.4222042682753773	17.7313	4.16197	0.13688817073101509	906.6707498991004	nan	nan
140.41	3.4361942682753774	17.6716	4.17485	0.1374477707310151	903.6180552986496	nan	nan
140.81	3.449234268275377	17.6059	4.1861	0.1379693707310151	900.2585572207661	nan	nan
141.23	3.4628842682753773	17.5375	4.19828	0.13851537073101508	896.7609975780385	nan	nan
141.63	3.4763842682753774	17.4838	4.21032	0.1390553707310151	894.0151064550197	nan	nan
142.04	3.490114268275377	17.4128	4.22322	0.1396045707310151	890.384598638738	nan	nan
142.44	3.5038342682753774	17.3476	4.23497	0.14015337073101508	887.0506675173075	nan	nan
142.85	3.5170342682753772	17.277	4.24702	0.14068137073101508	883.4406132661879	nan	nan
143.27	3.5308842682753774	17.2109	4.25887	0.1412353707310151	880.0606616231424	nan	nan
143.67	3.5440842682753773	17.1477	4.27106	0.14176337073101508	876.8289983275229	nan	nan
144.09	3.558174268275377	17.0831	4.2828	0.14232697073101508	873.5257475538356	nan	nan
144.49	3.571594268275377	17.0141	4.29534	0.14286377073101508	869.9975075633644	nan	nan
144.9	3.5855442682753775	16.9305	4.30761	0.1434217707310151	865.7227124444751	nan	nan
145.3	3.598774268275377	16.8743	4.31998	0.1439509707310151	862.848986539193	nan	nan
145.7	3.6124942682753773	16.8038	4.33133	0.14449977073101508	859.2440456793638	nan	nan
146.14	3.6271542682753775	16.7235	4.34434	0.1450861707310151	855.1379924730621	nan	nan
146.56	3.6410342682753774	16.6435	4.35644	0.1456413707310151	851.047279440632	nan	nan
146.97	3.654764268275377	16.5806	4.36842	0.14619057073101507	847.830956318884	nan	nan
147.38	3.6692442682753774	16.4936	4.38118	0.1467697707310151	843.3823058961162	nan	nan
147.79	3.682494268275377	16.4234	4.39331	0.14729977073101508	839.7927052101587	nan	nan
148.2	3.6966342682753774	16.3366	4.40555	0.1478653707310151	835.354281569972	nan	nan