File: original_data/46NTAZ.csv
Specimen name:	AWA_4_04_Rz
Specimen ID:	46NTAZ
Material:	42CrMoS4
Specimen type:	Round Tensile Specimen
Gauge diameter:	4.998	mm
Gauge length:	25	mm
Parallel length:	30	mm
Original cross-section:	19.61924926326091	mm²
Cross-section after fracture:	13.000454092433179	mm²
Yield stress at 0.2% plastic strain:	1081.8509694883146	MPa
Yield stress at 1% plastic strain:	1150.5294376095599	MPa
Ultimate tensile strength:	1201.0551313054405	MPa
Uniform elongation:	5.080753636862774	%
Elongation after fracture:	10.87958564538251	%
Reduction of area:	33.73623058667243	%
Slope of linear-elastic region:	211746.34888895313	MPa
Crosshead seperation speed:	0.029939821002019324	mm/s
Strain rate:	0.000997994033400644	s-1
Test temperature:	RT	Cel
Machine type:	INSTRON 8852TT
Standard:	DIN EN ISO 6892-1
Date:	2022-09-13 00:00:00
Heat treatment batch:	Batch 4
Time	Displacement	Force	Machine Displacement	Engineering Strain	Engineering Stress	True Strain	True Stress
s	mm	kN	mm		MPa		MPa
0	0.0009055853526044518	0.149242	0	3.6223414104178074e-05	7.6069169618773955	3.622275805223101e-05	7.607192510380562
0.460001	0.0010037486526044519	0.148145	-0.000282288	4.014994610417807e-05	7.551002488021647	4.014914011672724e-05	7.551305660364574
0.880001	0.0009216094526044518	0.15024	5.3405e-05	3.686437810417807e-05	7.657785371091649	3.686369862964128e-05	7.658067670587009
1.3	0.0015156693526044518	0.218207	0.00356293	6.062677410417807e-05	11.122087143702046	6.0624936375529734e-05	11.122761439966874
1.72	0.002869565352604452	0.460169	0.0163956	0.00011478261410417807	23.454974949613103	0.00011477602708393152	23.457667172951567
2.13	0.004269905352604452	0.696267	0.0283279	0.00017079621410417807	35.48897262362798	0.00017078163009140375	35.495034005794544
2.55	0.005642305352604452	0.968077	0.0401535	0.00022569221410417806	49.343223433774554	0.0002256667494478025	49.35435981512236
2.96	0.007362145352604452	1.27152	0.0530624	0.0002944858141041781	64.80981932275327	0.0002944424616676282	64.82890489515847
3.37	0.009201455352604452	1.58216	0.0646439	0.00036805821410417806	80.64324882006365	0.000367990497294952	80.67293023020392
3.78001	0.011008085352604452	1.91504	0.0769501	0.0004403234141041781	97.61025889946319	0.00044022650019758707	97.65323898191339
4.19001	0.01296558535260445	2.24464	0.0896835	0.000518623414104178	114.41008623114453	0.0005184889754613175	114.46942198067367
4.60001	0.014976085352604451	2.60239	0.102051	0.0005990434141041781	132.6447289129073	0.0005988640592221143	132.72418886417822
5.00001	0.017073185352604454	2.9542	0.114235	0.0006829274141041782	150.57660771618043	0.0006826943252935718	150.67944060951262
5.41001	0.01907678535260445	3.30277	0.125771	0.0007630714141041781	168.3433425857319	0.0007627804231345945	168.47180057821384
5.81001	0.02127398535260445	3.67054	0.137939	0.000850959414104178	187.08870817363376	0.0008505975534132438	187.2479130711267
6.22001	0.023566785352604452	4.08361	0.150513	0.0009426714141041781	208.14303061264354	0.0009422273784378486	208.33924109764706
6.62001	0.025930885352604453	4.46775	0.162094	0.001037235414104178	227.72278082863892	0.0010366978571353341	227.95898296151267
7.03001	0.02827088535260445	4.86877	0.174294	0.001130835414104178	248.16291055118396	0.001130196501362036	248.44354195890241
7.44001	0.030573885352604455	5.27803	0.186821	0.0012229554141041782	269.02303595702114	0.0012222082132651631	269.3520391353635
7.86001	0.033111185352604454	5.70595	0.199661	0.0013244474141041781	290.83426809225494	0.001323571107290584	291.2194627865626
8.26001	0.035457485352604456	6.10235	0.211349	0.0014182994141041783	311.038914798197	0.0014172945774839887	311.48006110881886
8.67001	0.03801508535260445	6.50948	0.224098	0.001520603414104178	331.7904733587171	0.0015194484673950767	332.2949950852736
9.10001	0.04046058535260445	6.94709	0.236755	0.0016184234141041782	354.09560818461847	0.001617115178259935	354.6686848077359
9.52001	0.04299548535260445	7.37959	0.24971	0.001719819414104178	376.14028452245884	0.0017183422181266215	376.78717788620725
9.93001	0.045481985352604455	7.77822	0.261253	0.0018192794141041783	396.4585951087093	0.0018176265297128657	397.17986406933517
10.35	0.04810528535260445	8.22641	0.274239	0.001924211414104178	419.3029962367016	0.0019223624907541853	420.1098238480283
10.76	0.05071648535260445	8.65048	0.287071	0.002028659414104178	440.9179925247662	0.0020266044633224147	441.81246496114943
11.17	0.05316358535260445	9.05583	0.29834	0.002126543414104178	461.57882386243926	0.002124285521096586	462.5603912704139
11.58	0.05594998535260445	9.49811	0.31134	0.002237999414104178	484.1219902224394	0.002235498823600496	485.2054549529122
11.99	0.05831588535260445	9.9013	0.322823	0.002332635414104178	504.6727256042981	0.002329919043498065	505.8499430765752
12.41	0.060781185352604454	10.3174	0.335312	0.002431247414104178	525.8814882035474	0.0024282967137305897	527.1600362118676
12.82	0.06344278535260445	10.7362	0.348297	0.002537711414104178	547.2278707475649	0.0025344968617490426	548.6165771612768
13.23	0.06574608535260444	11.1252	0.359673	0.002629843414104178	567.0553368641426	0.002626391426712469	568.5466036072274
13.64	0.06857048535260445	11.5469	0.372414	0.0027428194141041777	588.549533422911	0.002739064748946983	590.1638185093453
14.05	0.07093538535260445	11.9532	0.383926	0.002837415414104178	609.2587865930025	0.002833397549427846	610.9875068652599
14.46	0.07328918535260445	12.365	0.396095	0.002931567414104178	630.2483766876213	0.0029272787499800184	632.0959922915108
14.87	0.07587128535260444	12.7794	0.4086	0.003034851414104178	651.3704896920169	0.0030302555487157915	653.3473023437645
15.27	0.07844338535260445	13.1896	0.42086	0.003137735414104178	672.2785272267731	0.0031328229955703947	674.3879593697944
15.68	0.08096548535260445	13.602	0.433212	0.003238619414104178	693.2986995313405	0.0032333863817388037	695.5440301594158
16.09	0.08339828535260445	13.9975	0.445328	0.003335931414104178	713.4574729223598	0.0033303795385952943	715.8375181189089
16.5	0.08593398535260445	14.4211	0.458473	0.003437359414104178	735.0485131459648	0.003431465197398859	737.5751390724503
16.91	0.08831768535260445	14.8009	0.469971	0.003532707414104178	754.4070520433331	0.003526482060527792	757.0721514293391
17.31	0.09072948535260444	15.1925	0.482384	0.0036291794141041778	774.3670410696876	0.003622609832490007	777.1773579940984
17.73	0.09339588535260444	15.6056	0.495338	0.003735835414104178	795.4228926191947	0.0037288745121198162	798.3944616306306
18.14	0.09604108535260444	16.0343	0.507614	0.0038416434141041777	817.2738816273617	0.003834283146370653	820.4135564522348
18.57	0.09853528535260445	16.4297	0.5205	0.003941411414104178	837.4275579833896	0.003933664401573586	840.7282045189107
18.97	0.10097858535260444	16.8288	0.532265	0.004039143414104177	857.7698246340998	0.004031007973793307	861.234479972088
19.37	0.10337758535260444	17.2143	0.544258	0.004135103414104177	877.4188945259783	0.004126577369949537	881.0471123923322
19.79	0.10621858535260445	17.651	0.557846	0.004248743414104178	899.6776463334577	0.004239742988464803	903.5001458081337
20.2	0.10865558535260444	18.0259	0.569992	0.004346223414104178	918.786430516247	0.0043368058624502406	922.7796816131179
20.6	0.11118658535260445	18.388	0.581863	0.004447463414104178	937.2427942201359	0.004437602674735699	941.4111472575627
21.02	0.11427558535260444	18.7708	0.594879	0.004571023414104178	956.7542441672466	0.0045606080138760954	961.1275902188786
21.42	0.11745258535260444	19.1266	0.60746	0.0046981034141041775	974.8894946666767	0.004687101770708184	979.4696263299446
21.82	0.12109458535260445	19.4371	0.619125	0.004843783414104178	990.7157883149993	0.004832090040134172	995.5146010185306
22.23	0.12525858535260445	19.7164	0.630882	0.0050103434141041785	1004.9518070460023	0.004997833412409836	1009.9869607139274
22.65	0.13068758535260447	20.0038	0.643845	0.0052275034141041786	1019.6006856113092	0.005213887449187055	1024.9306516763654
23.07	0.13677758535260445	20.2505	0.656242	0.005471103414104178	1032.1750709351134	0.00545619129359664	1037.8222074896596
23.48	0.14293058535260447	20.4612	0.668419	0.0057172234141041785	1042.9145236620104	0.005700942118713714	1048.8770989956001
23.89	0.14954958535260446	20.654	0.681274	0.005981983414104179	1052.7416071254452	0.005964162386067879	1059.0390899586068
24.3	0.15625158535260447	20.8228	0.693321	0.006250063414104179	1061.3454021909422	0.006230612770861943	1067.9788782589037
24.72	0.16378858535260446	20.9801	0.705841	0.006551543414104178	1069.3630382324272	0.006530175332051906	1076.3690166028452
25.12	0.17108258535260445	21.1115	0.717201	0.006843303414104178	1076.0605422111378	0.006819994293793968	1083.424350993434
25.54	0.17893858535260446	21.2534	0.730225	0.007157543414104179	1083.2932348639458	0.007132049775840988	1091.04695322269
25.95	0.18725958535260445	21.3724	0.743309	0.007490383414104178	1089.3587065037216	0.007462469794739506	1097.518420890927
26.36	0.19540558535260447	21.4905	0.754761	0.007816223414104179	1095.3783048285748	0.007785834985659039	1103.9400263820776
26.77	0.20378558535260446	21.5937	0.767395	0.00815142341410418	1100.6384449397078	0.008118380008012462	1109.6102149302526
27.19	0.21304058535260445	21.6928	0.779755	0.008521623414104179	1105.6896066161935	0.008485519346479283	1115.1118770566657
27.6	0.22141858535260445	21.7647	0.791573	0.008856743414104178	1109.354374775016	0.008817752514627639	1119.1796418277122
28	0.22986158535260445	21.8497	0.802925	0.009194463414104178	1113.6868545177126	0.009152451656066561	1123.9266075563444
28.41	0.23908158535260446	21.9156	0.816437	0.009563263414104179	1117.0458005770508	0.009517824874657002	1127.7284038135879
28.82	0.24775858535260445	21.9765	0.82785	0.009910343414104178	1120.1498948868184	0.009861558016049767	1131.2509650204195
29.23	0.2575205853526044	22.0539	0.840729	0.010300823414104177	1124.0949999701681	0.01024813147062174	1135.6741040655384
29.64	0.26661258535260446	22.1114	0.852348	0.010664503414104179	1127.025795090228	0.010608038688323957	1139.0449655297512
30.06	0.2764425853526044	22.1642	0.864853	0.011057703414104177	1129.7170295656915	0.010997013992279798	1142.2091054204916
30.47	0.2863075853526044	22.2129	0.877586	0.011452303414104177	1132.1992856065074	0.011387222202547828	1145.165575350505
30.87	0.2954945853526044	22.2609	0.889259	0.011819783414104177	1134.6458624023833	0.011750475376882	1148.057130747689
31.27	0.3052355853526044	22.2975	0.900436	0.012209423414104177	1136.5113772092386	0.012135489588632106	1150.387525828533
31.68	0.31518158535260443	22.3449	0.913147	0.012607263414104177	1138.927371795166	0.012528453561822927	1153.2861291809209
32.08	0.32482258535260444	22.3843	0.924324	0.012992903414104178	1140.935603581781	0.012909219727796429	1155.7596696808316
32.49	0.33502258535260443	22.4178	0.93721	0.013400903414104177	1142.6431103039026	0.013311905527702325	1157.9555602618768
32.89	0.34456758535260446	22.4491	0.949738	0.013782703414104178	1144.2384822562135	0.013688585768434703	1160.0091818921558
33.3	0.35422158535260445	22.4967	0.961754	0.014168863414104178	1146.6646709121237	0.014069423270654916	1162.9116060160563
33.71	0.36397758535260444	22.5078	0.972969	0.014559103414104178	1147.23044179617	0.014454137250246	1163.9330884380888
34.12	0.3742545853526044	22.5365	0.985405	0.014970183414104176	1148.6932908387041	0.014859236115573788	1165.8894400891106
34.53	0.3843215853526044	22.5678	0.997696	0.015372863414104177	1150.288662791015	0.015255898153458248	1167.9718932908938
34.93	0.3944665853526044	22.599	1.00969	0.015778663414104176	1151.8789377083344	0.015655474452950693	1170.05404776023
35.34	0.4046765853526044	22.6155	1.02153	0.016187063414104176	1152.7199484819166	0.01605744974230433	1171.3790993866962
35.7401	0.41511558535260445	22.6387	1.03402	0.016604623414104177	1153.9024605999234	0.016468273938977845	1173.0625764147933
36.1601	0.42558958535260444	22.6691	1.04592	0.017023583414104176	1155.4519592373115	0.016880305995300136	1175.121892046378
36.6001	0.43646058535260446	22.6994	1.059	0.01745842341410418	1156.9963608397081	0.017307775990278874	1177.1956931958255
37.0201	0.44645258535260446	22.716	1.07119	0.017858103414104178	1157.842468648282	0.017700520804040356	1178.5193391906446
37.4301	0.45668158535260445	22.7365	1.08348	0.018267263414104177	1158.8873608215206	0.018102421406206937	1180.0570615089232
37.8301	0.4668195853526044	22.768	1.09541	0.018672783414104176	1160.492926843814	0.018500587278579145	1182.1625599203685
38.2501	0.47738358535260444	22.7813	1.10745	0.01909534341410418	1161.1708324976717	0.01891531553003555	1183.3437883066558
38.6601	0.4882145853526044	22.8097	1.11966	0.019528583414104177	1162.6183904352315	0.019340347337835625	1185.3226806516175
39.0801	0.49881758535260445	22.8259	1.13165	0.019952703414104177	1163.4441101038396	0.019756257019236476	1186.657965371628
39.4901	0.5087935853526044	22.8327	1.14367	0.020351743414104177	1163.7907084832552	0.020147414334712847	1187.4758783700252
39.8901	0.5192105853526044	22.864	1.15608	0.02076842341410418	1165.386080435566	0.020555699954109392	1189.589311994955
40.3001	0.5294815853526045	22.8811	1.16863	0.02117926341410418	1166.2576734190968	0.020958100082373195	1190.9581518931602
40.7001	0.5393325853526044	22.8952	1.18107	0.021573303414104177	1166.9763553528853	0.02134389326289442	1192.1518903439985
41.1201	0.5503105853526045	22.925	1.1935	0.022012423414104178	1168.495271780325	0.021773647690118712	1194.2166844601322
41.5601	0.5610425853526044	22.9314	1.20608	0.02244170341410418	1168.8214820197752	0.022193593533535474	1195.0518270632967
41.9801	0.5718675853526044	22.9493	1.21912	0.022874703414104178	1169.733851283237	0.022616999912150652	1196.491166204779
42.4101	0.5825645853526045	22.9767	1.23189	0.02330258341410418	1171.1304388708832	0.023035223698516637	1198.4208036114683
42.8101	0.5925375853526045	22.9885	1.24374	0.02370150341410418	1171.7318889998692	0.02342498355060202	1199.5036963674142
43.2201	0.6032425853526044	23.0043	1.25611	0.024129703414104177	1172.5372205285116	0.023843182086509544	1200.8301959018627
43.6201	0.6133855853526045	23.0163	1.26824	0.02453542341410418	1173.1488647274807	0.024239264393950733	1201.9325688513452
44.0401	0.6239775853526044	23.0432	1.28128	0.024959103414104174	1174.5199671401692	0.02465271268618981	1203.834932461951
44.4501	0.6340285853526044	23.0511	1.29299	0.025361143414104177	1174.922632904491	0.02504488557310807	1204.7200142980585
44.8501	0.6440125853526044	23.0673	1.30492	0.025760503414104175	1175.7483525730988	0.02543429202851175	1206.0362220236855
45.2701	0.6548025853526044	23.0822	1.31819	0.026192103414104176	1176.5078107868187	0.025854964518635167	1207.3230250344484
45.6801	0.6654195853526045	23.0859	1.33064	0.02661678341410418	1176.6964010815007	0.026268719553293816	1208.0162743332428
46.1001	0.6757505853526045	23.1102	1.34303	0.02703002341410418	1177.934980584413	0.0266711646126909	1209.774590689902
46.5201	0.6864995853526045	23.123	1.35552	0.02745998341410418	1178.587401063313	0.027089721047473463	1210.9513915485838
46.9401	0.6971195853526044	23.1479	1.36826	0.027884783414104178	1179.8565627761739	0.027503082360772025	1212.756607488897
47.3601	0.7078925853526045	23.1545	1.38072	0.02831570341410418	1180.1929670856068	0.02792222437447058	1213.6109611130144
47.7701	0.7181915853526044	23.1614	1.39288	0.028727663414104175	1180.544662500014	0.028322760417755694	1214.458952209632
48.1901	0.7287675853526044	23.1784	1.40524	0.029150703414104178	1181.4111584485534	0.028733902312998987	1215.8501247386002
48.6001	0.7391835853526044	23.1904	1.41798	0.029567343414104177	1182.0228026475224	0.029138659055992607	1216.9720767767037
49.0001	0.7491075853526045	23.1894	1.42972	0.02996430341410418	1181.9718322976082	0.029524144761470358	1217.3887949074983
49.4101	0.7595645853526044	23.215	1.44131	0.030382583414104176	1183.2766732554087	0.029930173482576122	1219.227675482555
49.8201	0.7700745853526044	23.2347	1.45445	0.030802983414104177	1184.2807891487162	0.030338094062455124	1220.7601706545063
50.2201	0.7802395853526044	23.2431	1.46632	0.031209583414104177	1184.7089400879943	0.03073246605786475	1221.6832125751055
50.6401	0.7907565853526044	23.2475	1.47794	0.03163026341410417	1184.9332096276164	0.031140330979107757	1222.4129591762578
51.0601	0.8018445853526044	23.256	1.49047	0.032073783414104176	1185.3664576018862	0.03157016005998811	1223.385644629353
51.4701	0.8120025853526044	23.2722	1.50275	0.03248010341410418	1186.1921772704943	0.03196377536626643	1224.7198218572414
51.8701	0.8222455853526044	23.2892	1.51491	0.03288982341410417	1187.0586732190336	0.03236052754131503	1226.1008233633884
52.2801	0.8327765853526045	23.2866	1.52747	0.033311063414104176	1186.9261503092569	0.032768271056015416	1226.463922570067
52.6901	0.8435485853526045	23.3066	1.54053	0.03374194341410418	1187.9455573075386	0.033185173771927805	1228.029149081246
53.0901	0.8537685853526045	23.3146	1.55256	0.03415074341410418	1188.3533201068512	0.03358055212780608	1228.9364694271192
53.5101	0.8643445853526044	23.3294	1.56483	0.03457378341410418	1189.1076812855797	0.0339895384383667	1230.219632714395
53.9201	0.8749655853526044	23.3403	1.57755	0.034998623414104174	1189.6632580996431	0.03440009668176597	1231.299834459469
54.3201	0.8852075853526045	23.3477	1.58918	0.03540830341410418	1190.0404386890075	0.034795844976498035	1232.1777516171614
54.7301	0.8953745853526044	23.351	1.60104	0.035814983414104176	1190.2086408437237	0.035188540450532546	1232.8359435748653
55.1301	0.9056185853526044	23.3572	1.61328	0.03622474341410418	1190.524657013191	0.035584054107955294	1233.651107241658
55.5501	0.9166945853526044	23.3677	1.6259	0.03666778341410418	1191.059845687289	0.03601151477078493	1234.733370142187
55.9601	0.9272065853526045	23.3802	1.63842	0.03708826341410418	1191.696975061215	0.036417039814490335	1235.8949463820763
56.3801	0.9378545853526045	23.3836	1.65097	0.03751418341410418	1191.870274250923	0.036827643789854654	1236.5823143249909
56.7901	0.9482705853526044	23.402	1.66321	0.03793082341410418	1192.808128689342	0.037229138413153395	1238.0523231855657
57.1901	0.9583985853526045	23.4019	1.67485	0.03833594341410418	1192.8030316543507	0.03761937728959603	1238.5302611800237
57.6001	0.9693385853526044	23.419	1.68843	0.038773543414104175	1193.6746246378814	0.03804073207060224	1239.9576195185928
58.0001	0.9796045853526044	23.425	1.69988	0.03918418341410418	1193.9804467373658	0.038435966295094805	1240.7655955551768
58.4101	0.9907115853526044	23.4377	1.71248	0.03962846341410418	1194.6277701812749	0.03886340260826335	1241.9690330653764
58.8301	1.0012355853526045	23.4395	1.72475	0.04004942341410418	1194.71951681112	0.039268234537684174	1242.5673446009826
59.2501	1.0126055853526046	23.4461	1.73712	0.04050422341410418	1195.0559211205532	0.03970542586696077	1243.4607331419681
59.6601	1.0229555853526044	23.4474	1.74966	0.04091822341410418	1195.1221825754412	0.04010323074899264	1244.0244590492148
60.0601	1.0331855853526046	23.453	1.76132	0.041327423414104184	1195.4076165349602	0.040496267954656655	1244.8107332559455
60.4801	1.0437855853526046	23.4512	1.77392	0.041751423414104184	1195.3158699051148	0.040903357687722776	1245.2220089031214
60.8901	1.0551255853526045	23.461	1.78765	0.042205023414104176	1195.8153793342728	0.041338683491056114	1246.2847954180218
61.3001	1.0654055853526045	23.4712	1.79925	0.04261622341410418	1196.3352769033966	0.041733153766104925	1247.3185683420859
61.7001	1.0760255853526046	23.4825	1.81135	0.043041023414104186	1196.9112418574257	0.042140507377557805	1248.4275266428156
62.1201	1.0870155853526045	23.4774	1.82381	0.04348062341410418	1196.6512930728636	0.04256187852141592	1248.6824373049656
62.5401	1.0983455853526045	23.4991	1.83672	0.04393382341410418	1197.7573496659993	0.042996099916989404	1250.3794095591709
62.9501	1.1093455853526046	23.4981	1.84895	0.04437382341410419	1197.7063793160853	0.04341749377356919	1250.8531906938033
63.3501	1.1202055853526045	23.5013	1.86067	0.04480822341410418	1197.8694844358104	0.04383335031122216	1251.543887915348
63.7601	1.1306855853526045	23.5034	1.87309	0.045227423414104184	1197.9765221706298	0.04423449180013149	1252.1579135789968
64.1801	1.1415755853526046	23.5049	1.88547	0.045663023414104185	1198.0529776955009	0.044651156391012276	1252.7596988673479
64.6001	1.1524855853526046	23.5143	1.89767	0.04609942341410418	1198.5320989846934	0.045068412190773996	1253.7837376911837
65.0101	1.1636255853526045	23.5255	1.91049	0.04654502341410418	1199.1029669037312	0.04549428482997014	1254.9152425741872
65.4101	1.1741255853526045	23.523	1.92207	0.046965023414104176	1198.9755410289458	0.04589552484911498	1255.2854553863085
65.8401	1.1853055853526044	23.5181	1.93508	0.04741222341410418	1198.725786314367	0.04632257303966763	1255.5600411073515
66.2401	1.1951455853526045	23.4454	1.94442	0.04780582341410418	1195.020241875613	0.04669828573002545	1252.1491685349986
66.6601	1.2074155853526045	23.5368	1.9595	0.04829662341410418	1199.6789318577603	0.04716658346014096	1257.6193734475294
67.0801	1.2187555853526046	23.5242	1.97186	0.048750223414104184	1199.036705448843	0.04759919182819938	1257.4900127211854
67.4901	1.2300055853526046	23.5345	1.98399	0.04920022341410418	1199.5617000529578	0.04802818194813441	1258.580403694566
67.9001	1.2407855853526046	23.5345	1.99578	0.04963142341410418	1199.5617000529578	0.0484390772257222	1259.0976546996287
68.3001	1.2514355853526045	23.536	2.00784	0.05005742341410418	1199.638155577829	0.0488448516398586	1259.6889506753034
68.7201	1.2625855853526045	23.5393	2.02063	0.05050342341410418	1199.8063577325454	0.049269500140163194	1260.4006862320464
69.1401	1.2739755853526045	23.5357	2.03288	0.05095902341410418	1199.6228644728546	0.049703102946462026	1260.7544741116217
69.5601	1.2852255853526044	23.5443	2.04568	0.05140902341410418	1200.0612094821158	0.05013119165105513	1261.7551842987402
69.9701	1.2964855853526045	23.5319	2.05746	0.05185942341410418	1199.4291771431813	0.05055947745314926	1261.63088269588
70.3701	1.3073555853526044	23.5415	2.06945	0.052294223414104175	1199.9184925023565	0.0509727552637731	1262.6672982279897
70.8001	1.3191855853526044	23.5556	2.08227	0.052767423414104175	1200.637174436145	0.05142233830442515	1263.9917045863308
71.2001	1.3301955853526046	23.5529	2.09473	0.05320782341410418	1200.499554491377	0.05184057684458177	1264.375522795465
71.6201	1.3417955853526045	23.5528	2.10683	0.053671823414104175	1200.4944574563856	0.052281038650931394	1264.9271839865955
72.0401	1.3526655853526046	23.5487	2.11855	0.05410662341410419	1200.285479021738	0.052693605737212657	1265.2288734245847
72.4801	1.3651055853526046	23.5478	2.13219	0.05460422341410418	1200.2396057068152	0.05316555286072141	1265.7777572872865
72.8901	1.3768355853526046	23.553	2.14445	0.055073423414104185	1200.5046515263684	0.05361036015954399	1266.6205525104817
73.2901	1.3881055853526045	23.5605	2.15664	0.05552422341410418	1200.886929150724	0.054037537748349455	1267.5652432999664
73.7101	1.3999855853526046	23.5548	2.16904	0.05599942341410419	1200.5963981562136	0.05448763927454958	1267.8291042060118
74.1201	1.4114755853526046	23.5638	2.18166	0.056459023414104186	1201.0551313054405	nan	nan
74.5201	1.4231955853526046	23.5588	2.19315	0.056927823414104184	1200.8002795558702	nan	nan
74.9401	1.4353455853526045	23.5468	2.2058	0.05741382341410418	1200.188635356901	nan	nan
75.3401	1.4469355853526045	23.5496	2.21729	0.05787742341410418	1200.3313523366605	nan	nan
75.7401	1.4578155853526045	23.5451	2.22898	0.058312623414104175	1200.1019857620472	nan	nan
76.1501	1.4698655853526046	23.5434	2.24125	0.058794623414104186	1200.015336167193	nan	nan
76.5501	1.4815955853526046	23.5522	2.25334	0.05926382341410418	1200.463875246437	nan	nan
76.9701	1.4936255853526046	23.5473	2.26557	0.05974502341410418	1200.214120531858	nan	nan
77.3901	1.5055655853526047	23.5314	2.27856	0.060222623414104184	1199.4036919682242	nan	nan
77.8201	1.5183355853526046	23.5534	2.29095	0.06073342341410418	1200.5250396663341	nan	nan
78.2201	1.5303455853526045	23.5423	2.30352	0.061213823414104175	1199.9592687822876	nan	nan
78.6301	1.5424555853526045	23.5399	2.31593	0.06169822341410418	1199.8369399424937	nan	nan
79.0301	1.5543555853526045	23.5269	2.32767	0.06217422341410418	1199.1743253936108	nan	nan
79.4501	1.5662555853526046	23.5247	2.3402	0.06265022341410419	1199.0621906237998	nan	nan
79.8901	1.5792755853526046	23.5108	2.35301	0.06317102341410419	1198.3537027599941	nan	nan
80.3001	1.5909855853526045	23.5042	2.36555	0.06363942341410418	1198.0172984505612	nan	nan
80.7001	1.6028755853526044	23.4978	2.37687	0.06411502341410417	1197.6910882111113	nan	nan
81.1101	1.6153055853526046	23.5038	2.38988	0.06461222341410418	1197.9969103105955	nan	nan
81.5201	1.6270855853526045	23.4971	2.40186	0.06508342341410418	1197.655408966171	nan	nan
81.9201	1.6392055853526046	23.5056	2.41396	0.06556822341410419	1198.088656940441	nan	nan
82.3201	1.6517655853526045	23.496	2.4269	0.06607062341410418	1197.5993415812657	nan	nan
82.7301	1.6639755853526046	23.4685	2.43855	0.06655902341410419	1196.1976569586284	nan	nan
83.1401	1.6760555853526045	23.4605	2.45036	0.06704222341410418	1195.7898941593157	nan	nan
83.5401	1.6880655853526045	23.4543	2.46261	0.06752262341410419	1195.4738779898485	nan	nan
83.9501	1.7006155853526046	23.4458	2.47537	0.06802462341410419	1195.0406300155787	nan	nan
84.3501	1.7130855853526046	23.4518	2.48727	0.06852342341410418	1195.3464521150634	nan	nan
84.7601	1.7245155853526046	23.4314	2.49908	0.06898062341410419	1194.3066569768162	nan	nan
85.1701	1.7373355853526045	23.4287	2.51154	0.06949342341410418	1194.169037032048	nan	nan
85.5701	1.7496755853526045	23.4102	2.52325	0.06998702341410418	1193.2260855586376	nan	nan
85.9701	1.7621855853526045	23.4026	2.53551	0.07048742341410418	1192.8387108992904	nan	nan
86.3801	1.7749155853526046	23.3773	2.54788	0.07099662341410419	1191.5491610464644	nan	nan
86.8001	1.7873155853526046	23.3655	2.55992	0.07149262341410419	1190.947710917478	nan	nan
87.2201	1.8005555853526045	23.3571	2.57293	0.07202222341410418	1190.5195599781996	nan	nan
87.6301	1.8128555853526045	23.3174	2.58471	0.07251422341410418	1188.4960370866106	nan	nan
88.0401	1.8254555853526044	23.3094	2.59698	0.07301822341410417	1188.0882742872982	nan	nan
88.4401	1.8379655853526045	23.2964	2.6093	0.07351862341410417	1187.4256597384149	nan	nan
88.8601	1.8508655853526046	23.2727	2.62125	0.07403462341410419	1186.2176624454512	nan	nan
89.2801	1.8635255853526045	23.2444	2.63285	0.07454102341410418	1184.7752015428825	nan	nan
89.7001	1.8768055853526044	23.2346	2.64676	0.07507222341410417	1184.2756921137247	nan	nan
90.1101	1.8906855853526046	23.2122	2.65964	0.07562742341410418	1183.1339562756493	nan	nan
90.5201	1.9029355853526047	23.197	2.67152	0.07611742341410418	1182.3592069569552	nan	nan
90.9201	1.9153855853526045	23.1707	2.68323	0.07661542341410418	1181.018686754215	nan	nan
91.3401	1.9282355853526045	23.1428	2.69601	0.07712942341410418	1179.5966139916122	nan	nan
91.7501	1.9414555853526045	23.1153	2.70877	0.07765822341410418	1178.194929368975	nan	nan
92.1501	1.9542655853526045	23.0831	2.7207	0.07817062341410418	1176.5536841017415	nan	nan
92.5701	1.9669855853526046	23.0654	2.73286	0.07867942341410418	1175.6515089082623	nan	nan
92.9901	1.9801855853526045	23.0378	2.74589	0.07920742341410418	1174.2447272506333	nan	nan
93.4001	1.9936855853526045	23.0148	2.75804	0.07974742341410418	1173.0724092026096	nan	nan
93.8101	2.0067255853526045	22.981	2.77003	0.08026902341410418	1171.3496113755136	nan	nan
94.2101	2.0193655853526047	22.9455	2.78247	0.08077462341410419	1169.5401639535637	nan	nan
94.6201	2.0324455853526047	22.9158	2.7949	0.08129782341410419	1168.0263445611154	nan	nan
95.0301	2.0449055853526046	22.898	2.80708	0.08179622341410418	1167.1190723326447	nan	nan
95.4301	2.0573255853526047	22.8632	2.81898	0.08229302341410419	1165.3453041556347	nan	nan
95.8301	2.0703655853526044	22.8461	2.83089	0.08281462341410417	1164.4737111721038	nan	nan
96.2401	2.0833555853526047	22.8023	2.84357	0.08333422341410418	1162.2412098458672	nan	nan
96.6501	2.0960955853526047	22.7653	2.85486	0.08384382341410418	1160.3553068990461	nan	nan
97.0501	2.1091555853526045	22.7557	2.86771	0.08436622341410419	1159.865991539871	nan	nan
97.4601	2.1224355853526045	22.7067	2.88027	0.08489742341410418	1157.368444394081	nan	nan
97.8601	2.1354455853526044	22.6871	2.89243	0.08541782341410417	1156.369425535765	nan	nan
98.2701	2.1481755853526043	22.6488	2.90402	0.08592702341410417	1154.4172611340557	nan	nan
98.6701	2.1605655853526047	22.6047	2.91642	0.08642262341410419	1152.1694687028446	nan	nan
99.1001	2.1745655853526045	22.5756	2.92949	0.08698262341410418	1150.686231520345	nan	nan
99.5001	2.1875355853526046	22.5499	2.94131	0.08750142341410419	1149.376293527553	nan	nan
99.9201	2.2005255853526045	22.498	2.95308	0.08802102341410417	1146.730932367012	nan	nan
100.33	2.2133155853526048	22.4621	2.96534	0.08853262341410419	1144.9010968050964	nan	nan
100.73	2.2261755853526046	22.432	2.97758	0.08904702341410418	1143.3668892726828	nan	nan
101.14	2.2393055853526045	22.3968	2.98953	0.08957222341410417	1141.572732955707	nan	nan
101.54	2.2524855853526047	22.3632	3.00181	0.0900994234141042	1139.860129198594	nan	nan
101.96	2.2658155853526045	22.3272	3.01466	0.09063262341410418	1138.025196601687	nan	nan
102.37	2.2788255853526045	22.2939	3.02654	0.09115302341410418	1136.327883949548	nan	nan
102.79	2.2919155853526045	22.2515	3.03884	0.09167662341410418	1134.166741113191	nan	nan
103.21	2.3054255853526047	22.2243	3.05231	0.09221702341410419	1132.780347595528	nan	nan
103.63	2.3185455853526045	22.1747	3.0646	0.09274182341410418	1130.2522182397895	nan	nan
104.07	2.3327755853526044	22.1382	3.07809	0.09331102341410417	1128.3918004679256	nan	nan
104.49	2.3458355853526047	22.1034	3.08971	0.0938334234141042	1126.6180322909154	nan	nan
104.9	2.3594555853526047	22.0662	3.10345	0.09437822341410419	1124.7219352741115	nan	nan
105.31	2.3728355853526044	22.0346	3.11614	0.09491342341410418	1123.1112722168266	nan	nan
105.71	2.3850955853526044	21.9699	3.12708	0.09540382341410418	1119.8134905773854	nan	nan
106.11	2.3982555853526044	21.9415	3.13999	0.09593022341410418	1118.3659326398256	nan	nan
106.52	2.4116855853526045	21.9034	3.15304	0.09646742341410418	1116.4239623080991	nan	nan
106.94	2.4251355853526047	21.8505	3.16472	0.09700542341410419	1113.7276307976442	nan	nan
107.36	2.4384455853526044	21.8258	3.17771	0.09753782341410418	1112.4686631547663	nan	nan
107.78	2.4517855853526047	21.7873	3.19047	0.09807142341410419	1110.5063046830742	nan	nan
108.22	2.4659855853526045	21.7169	3.20302	0.09863942341410419	1106.9179920491226	nan	nan
108.64	2.4795455853526045	21.6955	3.21585	0.09918182341410418	1105.8272265609614	nan	nan
109.06	2.4933455853526048	21.6423	3.2286	0.0997338234141042	1103.1156039455323	nan	nan
109.48	2.5066555853526045	21.6172	3.24177	0.10026622341410418	1101.836248162689	nan	nan
109.89	2.5192055853526045	21.5575	3.25292	0.10076822341410419	1098.7933182728182	nan	nan
110.31	2.5329255853526047	21.5375	3.26608	0.10131702341410419	1097.7739112745364	nan	nan
110.72	2.5466355853526044	21.4788	3.27962	0.10186542341410418	1094.78195173458	nan	nan
111.12	2.5593855853526044	21.4305	3.29091	0.10237542341410417	1092.3200838337298	nan	nan
111.54	2.5725655853526046	21.3918	3.30363	0.10290262341410418	1090.3475312920548	nan	nan
111.96	2.5859955853526047	21.3451	3.31575	0.10343982341410418	1087.9672159510671	nan	nan
112.4	2.6004855853526045	21.3135	3.32957	0.10401942341410418	1086.3565528937822	nan	nan
112.82	2.6138155853526044	21.2511	3.34186	0.10455262341410418	1083.1760030591436	nan	nan
113.24	2.6275955853526045	21.1992	3.35413	0.10510382341410418	1080.5306418986027	nan	nan
113.65	2.6408455853526047	21.1463	3.36608	0.10563382341410418	1077.8343103881477	nan	nan
114.07	2.6545255853526046	21.1168	3.37927	0.10618102341410418	1076.3306850656825	nan	nan
114.49	2.6681655853526047	21.0625	3.39221	0.10672662341410419	1073.5629950653476	nan	nan
114.9	2.6816755853526044	21.0178	3.40451	0.10726702341410417	1071.2846204241885	nan	nan
115.3	2.6940055853526044	20.9543	3.41607	0.10776022341410417	1068.048003204644	nan	nan
115.71	2.7071955853526046	20.9143	3.42845	0.10828782341410419	1066.0091892080807	nan	nan
116.11	2.7202755853526046	20.8753	3.44038	0.10881102341410419	1064.0213455614314	nan	nan
116.54	2.7347055853526046	20.8115	3.45319	0.10938822341410419	1060.769437236913	nan	nan
116.94	2.7480455853526045	20.7581	3.46561	0.10992182341410418	1058.047620551501	nan	nan
117.36	2.7616155853526045	20.7061	3.47797	0.11046462341410418	1055.397162355969	nan	nan
117.79	2.7755455853526048	20.6548	3.49057	0.11102182341410419	1052.7823834053768	nan	nan
118.19	2.7886455853526044	20.5838	3.5027	0.11154582341410418	1049.1634885614767	nan	nan
118.6	2.8028955853526045	20.5236	3.51601	0.11211582341410418	1046.0950734966489	nan	nan
119	2.8160755853526047	20.4294	3.52747	0.11264302341410419	1041.2936665347427	nan	nan
119.42	2.8317955853526047	20.2747	3.54065	0.11327182341410419	1033.4085534030341	nan	nan
119.62	2.8405555853526043	20.136	3.54652	0.11362222341410418	1026.338965869951	nan	nan