File: original_data/46NTAR.csv
Specimen name:	AWA_3_14_Rz
Specimen ID:	46NTAR
Material:	42CrMoS4
Specimen type:	Round Tensile Specimen
Gauge diameter:	5.008	mm
Gauge length:	25	mm
Parallel length:	30	mm
Original cross-section:	19.69783620349046	mm²
Cross-section after fracture:	10.12793001389401	mm²
Yield stress at 0.2% plastic strain:	1090.1475559439107	MPa
Yield stress at 1% plastic strain:	1134.938412609495	MPa
Ultimate tensile strength:	1187.7243651693223	MPa
Uniform elongation:	4.902860932870663	%
Elongation after fracture:	13.21183296834719	%
Reduction of area:	48.58354029718585	%
Slope of linear-elastic region:	215228.21414192926	MPa
Crosshead seperation speed:	0.029734720660579972	mm/s
Strain rate:	0.0009911573553526658	s-1
Test temperature:	RT	Cel
Machine type:	INSTRON 8852TT
Standard:	DIN EN ISO 6892-1
Date:	2022-09-06 00:00:00
Heat treatment batch:	Batch 3
Time	Displacement	Force	Machine Displacement	Engineering Strain	Engineering Stress	True Strain	True Stress
s	mm	kN	mm		MPa		MPa
0	0.0010179387354554913	0.16843	0	4.0717549418219657e-05	8.550685377826127	4.071672048123167e-05	8.551033540780558
0.450001	0.0008259767354554914	0.168833	0.000450134	3.3039069418219653e-05	8.571144477792071	3.30385236402842e-05	8.571427660429467
0.860001	0.0008377667354554913	0.166413	0.00025177	3.351066941821965e-05	8.44828834400154	3.3510107948318445e-05	8.448571451799387
1.27	0.0015233457354554914	0.301718	0.0111694	6.093382941821965e-05	15.317316931822972	6.0931973027813186e-05	15.318250274600041
1.68	0.0021473087354554913	0.458886	0.0228043	8.589234941821966e-05	23.296264384546223	8.588866088161399e-05	23.29826535542688
2.08	0.002699998735455491	0.615282	0.0354385	0.00010799994941821964	31.236019715250347	0.00010799411784356822	31.239393203799622
2.51	0.0036392987354554917	0.820792	0.0486145	0.00014557194941821965	41.66914535793304	0.00014556135485005082	41.67521121665338
2.92	0.004754198735455491	1.03214	0.0609283	0.00019016794941821964	52.39864873163605	0.00019014986978586686	52.40861327521763
3.34	0.005896008735455491	1.26977	0.0727692	0.00023584034941821964	64.46241033190216	0.00023581254345481193	64.47761316927918
3.75001	0.007267818735455491	1.53893	0.0855331	0.00029071274941821964	78.12685536126557	0.00029067050065490987	78.14956783419105
4.16001	0.00865961873545549	1.80661	0.0970078	0.00034638474941821963	91.71616523442654	0.0003463247720707271	91.74793431533887
4.56001	0.010126528735455491	2.09564	0.109016	0.0004050611494182196	106.38935050280558	0.00040497913429747903	106.4324446954061
4.97001	0.011833738735455492	2.40416	0.121178	0.00047334954941821966	122.05198455117534	0.0004732375548605996	122.10975780306823
5.37001	0.013465338735455492	2.72343	0.13308	0.0005386135494182196	138.2603638219617	0.0005384685492042183	138.33483272726372
5.78001	0.01531983873545549	3.0626	0.145363	0.0006127935494182196	155.47900634168676	0.0006126058681204742	155.5742828738429
6.20001	0.017247938735455492	3.41524	0.158463	0.0006899175494182196	173.38148031684915	0.0006896796657128049	173.50109924286383
6.62001	0.019170038735455492	3.78052	0.169861	0.0007668015494182197	191.92564913957864	0.0007665077073129148	192.07281802471198
7.03001	0.021292938735455492	4.14976	0.182968	0.0008517175494182197	210.67085527214715	0.0008513550438465712	210.8502873367334
7.43001	0.02347463873545549	4.52684	0.194611	0.0009389855494182196	229.8140746645991	0.0009385449782589045	230.0298667597621
7.86001	0.02590033873545549	4.93109	0.206993	0.0010360135494182196	250.33663337733563	0.0010354772577526622	250.59598552143032
8.27001	0.028168938735455493	5.33744	0.219421	0.0011267575494182196	270.9658027846837	0.0011261232345653347	271.27111554860556
8.67001	0.030391338735455492	5.70956	0.231544	0.0012156535494182196	289.8572178698625	0.0012149152409331979	290.2095838255905
9.07001	0.03265693873545549	6.11271	0.243019	0.0013062775494182197	310.3239328854215	0.0013054251111666345	310.72930207199687
9.48001	0.03492653873545549	6.51202	0.255119	0.0013970615494182195	330.59570263083356	0.0013960865668999742	331.057565175382
9.88001	0.03735563873545549	6.90984	0.267151	0.0014942255494182198	350.7918295500688	0.0014931103052345488	351.31599166430965
10.3	0.03959693873545549	7.32771	0.28022	0.0015838775494182197	372.00583476785783	0.0015826245382753515	372.5950464577992
10.73	0.04200263873545549	7.73641	0.292297	0.0016801055494182196	392.7543066191761	0.0016786957509422366	393.4141753092849
11.14	0.044459038735455494	8.13753	0.30397	0.0017783615494182197	413.11796462994386	0.0017767821367519483	413.85263773361567
11.54	0.04694973873545549	8.55074	0.316803	0.0018779895494182197	434.09539563968997	0.0018762283317319832	434.9106222561519
11.95	0.04918253873545549	8.9386	0.32885	0.0019673015494182195	453.78588326448147	0.0019653689459856972	454.6786169357318
12.35	0.051648238735455494	9.35299	0.34082	0.00206592954941822	474.8232193311998	0.0020637984515939505	475.8041706507661
12.75	0.05391053873545549	9.74617	0.352692	0.0021564215494182196	494.78378738234085	0.002154099809636262	495.8507498037549
13.16	0.05668533873545549	10.1627	0.36451	0.0022674135494182195	515.9297648235681	0.0022648468464354383	517.0995909628773
13.56	0.05899483873545549	10.5785	0.376915	0.0023597935494182195	537.0386823566686	0.0023570136091513676	538.3059827750819
13.97	0.06134053873545549	10.9653	0.388145	0.0024536215494182197	556.67535696418	0.0024506163348333465	558.0412276160573
14.39	0.06390283873545549	11.3899	0.401024	0.0025561135494182197	578.2310240747006	0.0025528522475027084	579.709048230032
14.8	0.0664220387354555	11.7984	0.413567	0.0026568815494182204	598.969342526532	0.0026533582788628987	600.5607331213579
15.21	0.0685632387354555	12.1835	0.425049	0.00274252954941822	618.5197132384054	0.002738775677090954	620.2160218288593
15.61	0.0711046387354555	12.5935	0.437248	0.00284418554941822	639.334182186388	0.002840148506619346	641.1525672286116
16.02	0.07344743873545549	13.0104	0.449127	0.0029378975494182198	660.4989434166661	0.002933590362400205	662.4394216439233
16.43	0.07588123873545549	13.4165	0.460907	0.0030352495494182195	681.1154210746556	0.003030652479325404	683.1827763495742
16.84	0.0785275387354555	13.8402	0.473839	0.00314110154941822	702.6253978874854	0.0031361785962496507	704.8324156134504
17.26	0.08090283873545549	14.2337	0.485657	0.00323611354941822	722.6022113778054	0.003230888603277319	724.9406341848847
17.67	0.0833300387354555	14.6504	0.498619	0.0033332015494182197	743.7568192085964	0.003327658746571322	746.235910590773
18.07	0.0855173387354555	15.0216	0.510071	0.00342069354941822	762.6015286561358	0.003414856285112688	765.2101547859863
18.49	0.0879895387354555	15.4218	0.522697	0.0035195815494182196	782.9184810292642	0.0035134023169073473	785.6740264697933
18.91	0.0905599387354555	15.854	0.53598	0.00362239754941822	804.859977320284	0.0036158524685763922	807.7755001297538
19.32	0.0929817387354555	16.259	0.548698	0.00371926954941822	825.4206112810961	0.0037123701682414104	828.490573026096
19.73	0.0954459387354555	16.6643	0.560219	0.00381783754941822	845.9964753411383	0.003810568104140814	849.2263524513712
20.14	0.0978664387354555	17.0623	0.57209	0.00391465754941822	866.2017403199117	0.003907015215806737	869.5926235019742
20.57	0.1003632387354555	17.486	0.584724	0.0040145295494182194	887.7117171327416	0.00400649282759116	891.2754620525358
20.96	0.10263093873545549	17.86	0.597481	0.0041052375494182195	906.6985741730964	0.004096834052798683	910.4207872057957
21.36	0.1048339387354555	18.2379	0.609581	0.00419335754941822	925.8834225034444	0.004184589927618921	929.7659827430804
21.78	0.1073989387354555	18.6471	0.622215	0.00429595754941822	946.6572778534796	0.004286756266586125	950.7240773329859
22.18	0.1097799387354555	19.0169	0.633934	0.00439119754941822	965.4309135046113	0.004381584373421642	969.6703113661254
22.6	0.1122349387354555	19.4297	0.647194	0.00448939754941822	986.3875300454094	0.004479350263856194	990.815815805572
23	0.1146529387354555	19.7927	0.658882	0.00458611754941822	1004.8159501139892	0.004575633354608908	1009.4241541767423
23.41	0.1171909387354555	20.1689	0.670471	0.00468763754941822	1023.9144945486992	0.004676684791556057	1028.7142345807392
23.83	0.1200969387354555	20.5309	0.683746	0.00480387754941822	1042.2921476198446	0.004792375750444044	1047.2991914677305
24.24	0.12366693873545549	20.8775	0.695869	0.004946677549418219	1059.8879889305051	0.004934482938699952	1065.1309130502457
24.65	0.1284419387354555	21.1071	0.707954	0.00513767754941822	1071.5440915413753	0.005124524714897455	1077.0493395636993
25.06	0.1364489387354555	21.2363	0.720169	0.0054579575494182195	1078.1031876098616	0.005443116874472363	1083.9874290417288
25.47	0.1456499387354555	21.2691	0.732735	0.00582599754941822	1079.7683451257003	0.005809092054828923	1086.059072858342
25.87	0.1550039387354555	21.303	0.744041	0.0062001575494182205	1081.4893463387164	0.006181015653699508	1088.1947506740337
26.29	0.1645469387354555	21.3794	0.756851	0.00658187754941822	1085.367944942682	0.00656031157140939	1092.5117038523583
26.71	0.1734999387354555	21.467	0.769592	0.00693999754941822	1089.8151339179094	0.006916026608037548	1097.3784482766187
27.12	0.1824729387354555	21.5373	0.782654	0.00729891754941822	1093.3840538375268	0.007272409359962741	1101.3645738963355
27.53	0.1907069387354555	21.6019	0.79435	0.007628277549418219	1096.66360187177	0.0075993293635585124	1105.0292562051925
27.95	0.1998809387354555	21.6674	0.806427	0.00799523754941822	1099.9888402037038	0.007963444984660615	1108.7835122828415
28.36	0.2090609387354555	21.7442	0.818909	0.00836243754941822	1103.887745606643	0.008327666083520398	1113.1189379408465
28.78	0.2181139387354555	21.7905	0.831558	0.00872455754941822	1106.238257587842	0.00868671852376728	1115.8896969295354
29.19	0.2270379387354555	21.848	0.843536	0.00908151754941822	1109.157359940303	0.009040528543599274	1119.2301919696674
29.6	0.2364749387354555	21.9022	0.856079	0.00945899754941822	1111.9089312012316	0.009414541352930147	1122.4264750566401
30.01	0.2454079387354555	21.942	0.868828	0.009816317549418219	1113.9294576991088	0.009768450501482367	1124.8641429835343
30.41	0.2542809387354555	21.9728	0.88002	0.010171237549418219	1115.4930812200791	0.010119858610662658	1126.839026333901
30.83	0.2643659387354555	22.0277	0.893234	0.01057463754941822	1118.2801893792116	0.010519117132310222	1130.1055970605914
31.24	0.2740869387354555	22.0539	0.905632	0.010963477549418219	1119.6102847119848	0.010903814311048777	1131.8851069325226
31.66	0.2840409387354555	22.094	0.918083	0.01136163754941822	1121.6460413090927	0.011297578896349053	1134.3897770891865
32.08	0.29394493873545546	22.1164	0.930801	0.011757797549418218	1122.7832220516163	0.011689211736398445	1135.9846798683827
32.49	0.30371093873545546	22.1657	0.943245	0.012148437549418219	1125.2860350251178	0.012075237529566563	1138.956502146853
32.89	0.3133289387354555	22.1779	0.955223	0.012533157549418219	1125.905392393814	0.012455267659303009	1140.0165420624253
33.31	0.3233039387354555	22.2038	0.967903	0.012932157549418219	1127.2202576273573	0.012849251206872681	1141.79764759189
33.73	0.33323093873545545	22.2441	0.979942	0.013329237549418218	1129.2661676239516	0.013241184849830738	1144.3184246287324
34.14	0.34351493873545547	22.258	0.992874	0.01374059754941822	1129.9718288882857	0.013647051484047395	1145.4983170312198
34.57	0.3535959387354555	22.2875	1.00616	0.014143837549418219	1131.4694553125917	0.014044746735646017	1147.4727754806618
34.97	0.36300093873545547	22.3127	1.01791	0.014520037549418219	1132.748783647931	0.014415631246313492	1149.196338520557
35.38	0.37327793873545545	22.3359	1.0306	0.014931117549418218	1133.9265779884022	0.01482074570752062	1150.8573690167566
35.8001	0.3839369387354555	22.369	1.0432	0.015357477549418219	1135.606965603471	0.015240745117749083	1153.0470240826894
36.2201	0.39405193873545546	22.3818	1.05589	0.01576207754941822	1136.2567831706276	0.015639146092557198	1154.1665507030157
36.6301	0.4038379387354555	22.4067	1.06741	0.01615351754941822	1137.5208814067369	0.01602443769205733	1155.8958449273703
37.0401	0.4138609387354555	22.418	1.08028	0.01655443754941822	1138.0945484777421	0.016418906562209616	1156.9350636058502
37.4501	0.4236829387354555	22.4447	1.0927	0.01694731754941822	1139.4500273092328	0.016805313905014455	1158.7606487537355
37.8701	0.4338929387354555	22.4643	1.10497	0.01735571754941822	1140.4450604589415	0.017206827345677193	1160.238302808896
38.2801	0.4436129387354555	22.4788	1.11758	0.01774451754941822	1141.1811819217357	0.017588921552168665	1161.4308914314117
38.6801	0.4534789387354555	22.4998	1.12946	0.01813915754941822	1142.247288867852	0.017976605789504857	1162.9666924010219
39.1001	0.4636219387354555	22.5289	1.14239	0.01854487754941822	1143.7246084931844	0.018375018109113267	1164.9348413079467
39.5101	0.4735249387354555	22.553	1.15506	0.01894099754941822	1144.9480931313462	0.01876385025743094	1166.6345521575581
39.9101	0.4832139387354555	22.5527	1.16662	0.01932855754941822	1144.932863032116	0.01914413362446761	1167.0627637654525
40.3201	0.49346993873545547	22.5809	1.17894	0.019738797549418218	1146.3644923597578	0.01954651366798058	1168.9923489922887
40.7201	0.5030029387354555	22.5921	1.19099	0.020120117549418223	1146.9330827310196	0.019920382666095086	1170.0095111768842
41.1501	0.5133249387354555	22.6146	1.20333	0.02053299754941822	1148.075340173287	0.02032503743331553	1171.6487683196126
41.5601	0.5232349387354556	22.6233	1.21554	0.02092939754941822	1148.5170130509637	0.020713386497137307	1172.5547822093777
41.9601	0.5328349387354555	22.6464	1.22727	0.02131339754941822	1149.6897306916917	0.021089443649055684	1174.1935249804073
42.3701	0.5425439387354555	22.6642	1.23948	0.021701757549418218	1150.5933832460187	0.02146962683439194	1175.5632818871886
42.7701	0.5521649387354556	22.6708	1.251	0.022086597549418222	1150.9284454290837	0.02184622160614326	1176.3485388114534
43.1701	0.5618669387354556	22.7068	1.26347	0.02247467754941822	1152.7560573367116	0.022225843395313513	1178.6638780184928
43.5801	0.5721229387354555	22.7248	1.27544	0.02288491754941822	1153.6698632905252	0.022626985577337715	1180.0715029911773
43.9801	0.5819579387354555	22.7377	1.28743	0.023278317549418222	1154.3247575574253	0.023011510133442752	1181.1954958190022
44.3901	0.5917329387354555	22.7561	1.29958	0.02366931754941822	1155.2588703102126	0.023393542382877063	1182.6030593633673
44.8201	0.6015859387354555	22.7576	1.31157	0.02406343754941822	1155.335020806364	0.023778475430302412	1183.1363529281937
45.2201	0.6116599387354555	22.791	1.3241	0.02446639754941822	1157.030638520663	0.024171889280853277	1185.3390100995666
45.6201	0.6214669387354556	22.8071	1.33638	0.024858677549418222	1157.847987179352	0.024554727523119272	1186.6305569438864
46.0501	0.6314949387354555	22.8244	1.34892	0.02525979754941822	1158.7262562349622	0.024946041498375468	1187.9954468826527
46.4501	0.6411639387354555	22.8334	1.36053	0.02564655754941822	1159.183159211869	0.0253232015804272	1188.9122168149127
46.8501	0.6505249387354555	22.8487	1.37283	0.02602099754941822	1159.9598942726109	0.02568821198693931	1190.1432078389018
47.2601	0.6607819387354555	22.8643	1.38502	0.026431277549418222	1160.7518594325827	0.026088006915613235	1191.4320139952486
47.6801	0.6709169387354555	22.8646	1.39748	0.026836677549418222	1160.7670895318129	0.026482889623699334	1191.9182216235547
48.0901	0.6805879387354555	22.8972	1.4094	0.027223517549418222	1162.422093648165	0.026859548502048185	1194.0673119144271
48.5001	0.6908559387354555	22.9067	1.42229	0.027634237549418218	1162.9043801237888	0.027259303671913846	1195.0403560113887
48.9201	0.7009229387354555	22.92	1.43398	0.02803691754941822	1163.5795811896623	0.02765107840120516	1196.2027659696635
49.3501	0.7115139387354555	22.9376	1.44731	0.02846055754941822	1164.4730803445025	0.028063079885400667	1197.6146334623954
49.7701	0.7216699387354555	22.96	1.45968	0.02886679754941822	1165.6102610870266	0.028458000027081588	1199.2576965153503
50.1901	0.7319719387354555	22.959	1.47188	0.02927887754941822	1165.5594940895924	0.028858438159806758	1199.6857677936034
50.6201	0.7425839387354555	22.9816	1.48468	0.02970335754941822	1166.7068282316031	0.029270758381688928	1201.361938305914
51.0401	0.7528599387354555	22.9925	1.49689	0.03011439754941822	1167.260188503635	0.029669861656178766	1202.4115258638424
51.4401	0.7630359387354555	23.0114	1.50926	0.03052143754941822	1168.2196847551395	0.030064924188200146	1203.8754289073945
51.8501	0.7735609387354555	23.0286	1.52152	0.03094243754941822	1169.0928771110061	0.030473371807329785	1205.2674604504832
52.2501	0.7835719387354555	23.0344	1.53329	0.03134287754941822	1169.387325696124	0.030861717689541886	1206.0392894532592
52.6801	0.7940059387354556	23.0558	1.54572	0.03176023754941822	1170.4737394412139	0.031266312111060464	1207.6482634512226
53.1001	0.8044969387354556	23.0574	1.55827	0.03217987754941822	1170.5549666371085	0.031672951821886036	1208.223282128354
53.5301	0.8155029387354555	23.082	1.57162	0.03262011754941822	1171.8038347739873	0.03209937569607829	1210.028213609174
53.9501	0.8259959387354555	23.0925	1.58395	0.03303983754941822	1172.3368882470454	0.032505754301366305	1211.0707085879183
54.3601	0.8357089387354555	23.0939	1.59595	0.03342835754941822	1172.4079620434532	0.032881777513820605	1211.5996345924266
54.7701	0.8465229387354555	23.1152	1.60902	0.03386091754941822	1173.4892990887995	0.03330025789924411	1213.22472349037
55.1901	0.8570779387354556	23.1237	1.62095	0.03428311754941822	1173.9208185669895	0.033708546682520185	1214.166483983631
55.6001	0.8674209387354556	23.1402	1.63303	0.03469683754941822	1174.758474024652	0.034108473230377474	1215.518877957688
56.0301	0.8776789387354555	23.1461	1.64598	0.03510715754941822	1175.0579993095134	0.03450495522224394	1216.3109456209766
56.4201	0.8878339387354556	23.153	1.65766	0.03551335754941822	1175.4082915918086	0.03489730138345384	1217.1509865176592
56.8401	0.8984039387354555	23.1632	1.67051	0.03593615754941822	1175.9261149656365	0.035305517951407295	1218.184381099517
57.2401	0.9085809387354555	23.1752	1.68286	0.03634323754941822	1176.5353189348457	0.035698399342014235	1219.2944215161751
57.6701	0.9195399387354555	23.1862	1.69566	0.03678159754941822	1177.093755906621	0.03612129718117132	1220.3891447143114
58.0901	0.9295149387354555	23.1979	1.70782	0.03718059754941822	1177.6877297766	0.03650606794108735	1221.4748632963117
58.4801	0.9397059387354555	23.2086	1.71926	0.03758823754941822	1178.230936649145	0.036899017746722954	1222.5185609839866
58.8801	0.9500179387354555	23.2181	1.73225	0.03800071754941822	1178.7132231247688	0.03729647602420762	1223.5051713884975
59.3001	0.9607349387354556	23.2268	1.74432	0.03842939754941822	1179.1548960024454	0.037709376995902634	1224.4691082732663
59.7201	0.9716229387354556	23.2393	1.75648	0.038864917549418225	1179.7894834703718	0.03812869168156426	1225.6419044711186
60.1301	0.9823159387354555	23.2415	1.76939	0.039292637549418225	1179.9011708647267	0.03854032553963251	1226.2625999156487
60.5401	0.9924169387354556	23.2491	1.78133	0.03969667754941822	1180.287000045226	0.03892901441085711	1227.1404725017917
60.9601	1.0031379387354553	23.2492	1.79413	0.04012551754941821	1180.2920767449693	0.039341395822198685	1227.6519071838388
61.3701	1.0136479387354553	23.2591	1.80657	0.04054591754941821	1180.794670019567	0.039745496151187894	1228.671073352973
61.7701	1.0240879387354553	23.2755	1.81879	0.04096351754941821	1181.6272487774863	0.04014674343699034	1230.0308573196537
62.1801	1.0340379387354555	23.2661	1.83021	0.04136151754941822	1181.1500390016058	0.04052900845146973	1230.0041970682666
62.5801	1.0444479387354555	23.2869	1.84272	0.04177791754941822	1182.2059925482351	0.04092878966489211	1231.5960970313433
62.9901	1.0555779387354554	23.2928	1.85532	0.04222311754941822	1182.5055178330963	0.04135604473749002	1232.4345873153989
63.4001	1.0661479387354553	23.296	1.86739	0.04264591754941821	1182.6679722248855	0.04176163376843447	1233.1039330567257
63.8101	1.0767379387354554	23.3069	1.87984	0.043069517549418214	1183.221332496917	0.04216782533099928	1234.182104441739
64.2301	1.0874079387354554	23.3102	1.89203	0.04349631754941821	1183.3888635884496	0.042576918587270474	1234.861921383538
64.6201	1.0972679387354554	23.3191	1.90311	0.043890717549418215	1183.8406898656133	0.04295480730465891	1235.8003072080135
65.0501	1.1089079387354555	23.3191	1.91647	0.04435631754941822	1183.8406898656133	0.043400731565428306	1236.3515034332147
65.4701	1.1195779387354554	23.3267	1.92944	0.04478311754941822	1184.2265190461123	0.04380932086183164	1237.2598744536926
65.8901	1.1306479387354553	23.3365	1.94209	0.04522591754941821	1184.7240356209668	0.044233051093796334	1238.3042671747746
66.3001	1.1410679387354554	23.3373	1.9536	0.04564271754941822	1184.764649218914	0.04463173707389491	1238.8405274657484
66.7201	1.1524679387354555	23.3482	1.96665	0.04609871754941822	1185.3180094909455	0.04506773743184749	1239.9596496167073
67.1301	1.1634879387354553	23.3512	1.97884	0.046539517549418215	1185.4703104832479	0.04548902382442716	1240.6415268022974
67.5401	1.1739779387354554	23.3559	1.99094	0.046959117549418214	1185.7089153711881	0.04588988389529966	1241.388759707497
67.9501	1.1851679387354555	23.3669	2.00392	0.04740671754941822	1186.2673523429635	0.046317316389960776	1242.5043936535824
68.3701	1.1960079387354554	23.3451	2.01601	0.04784031754941822	1185.1606317988999	0.046731205538997914	1241.8590927712285
68.7801	1.2069279387354555	23.3654	2.02818	0.04827711754941822	1186.1912018468124	0.04714797608725885	1243.4570939344567
69.1901	1.2179679387354554	23.3711	2.04049	0.048718717549418214	1186.4805737321867	0.047569150034423	1244.2843856817167
69.6001	1.2279879387354553	23.3569	2.05244	0.049119517549418214	1185.7596823686224	0.04795125767091357	1244.0036258961204
70.0201	1.2395379387354555	23.3744	2.06523	0.04958151754941822	1186.6481048237192	0.04839153001055271	1245.4839186580205
70.4301	1.2511079387354553	23.3841	2.07812	0.05004431754941821	1187.14054469883	0.04883237046865581	1246.5501830935275
70.8401	1.2620779387354555	23.3794	2.08968	0.05048311754941822	1186.9019398108899	0.04925017030221263	1246.8204499579956
71.2501	1.2730879387354554	23.3805	2.10322	0.05092351754941822	1186.9577835080672	0.04966931812357366	1247.4018490269589
71.6601	1.2842679387354554	23.3922	2.11524	0.051370717549418216	1187.5517573780464	0.05009475810174512	1248.5571432816294
72.0601	1.2946779387354554	23.3837	2.12634	0.05178711754941822	1187.1202378998564	0.050490734094123524	1248.5977732052695
72.4801	1.3060679387354555	23.3846	2.13897	0.05224271754941822	1187.165928197547	0.050923807807737816	1249.1867024686642
72.8801	1.3165779387354555	23.3875	2.15156	0.05266311754941822	1187.313152490106	0.05132325561065602	1249.8407646076628
73.2901	1.3282779387354555	23.3917	2.16376	0.05313111754941822	1187.5263738793292	0.051767743490720095	1250.6209772429463
73.6901	1.3388979387354554	23.3825	2.17546	0.053555917549418214	1187.0593175029355	0.05217103073621981	1250.6333684373915
74.0901	1.3498279387354555	23.3893	2.18836	0.05399311754941822	1187.4045330854874	0.05258592025858938	1251.516205619084
74.5101	1.3615679387354553	23.3956	2.20074	0.05446271754941821	1187.7243651693223	nan	nan
74.9301	1.3733479387354555	23.3874	2.21323	0.05493391754941822	1187.3080757903624	nan	nan
75.3501	1.3851079387354555	23.3866	2.22559	0.05540431754941822	1187.2674621924155	nan	nan
75.7501	1.3961279387354555	23.3881	2.23794	0.05584511754941822	1187.3436126885665	nan	nan
76.1701	1.4074879387354555	23.3799	2.24972	0.05629951754941822	1186.9273233096067	nan	nan
76.5901	1.4184779387354554	23.3839	2.2618	0.05673911754941821	1187.1303912993433	nan	nan
76.9801	1.4297079387354554	23.3824	2.2737	0.057188317549418215	1187.0542408031922	nan	nan
77.3901	1.4410879387354554	23.3784	2.28603	0.05764351754941822	1186.8511728134556	nan	nan
77.8101	1.4529279387354554	23.3841	2.29906	0.058117117549418215	1187.14054469883	nan	nan
78.2201	1.4644779387354554	23.3794	2.31108	0.05857911754941822	1186.9019398108899	nan	nan
78.6401	1.4762379387354554	23.3772	2.32382	0.059049517549418215	1186.7902524165345	nan	nan
79.0401	1.4874879387354554	23.3757	2.33537	0.059499517549418214	1186.7141019203834	nan	nan
79.4601	1.4993179387354554	23.3669	2.34824	0.059972717549418214	1186.2673523429635	nan	nan
79.8701	1.5116979387354554	23.3774	2.36134	0.060467917549418215	1186.8004058160216	nan	nan
80.2901	1.5234979387354555	23.3666	2.3741	0.060939917549418215	1186.252122243733	nan	nan
80.7001	1.5345779387354554	23.3619	2.38587	0.06138311754941822	1186.0135173557928	nan	nan
81.1001	1.5462479387354555	23.3519	2.39794	0.061849917549418224	1185.505847381452	nan	nan
81.5001	1.5573779387354554	23.3592	2.40952	0.062295117549418216	1185.8764464627209	nan	nan
81.9101	1.5697279387354555	23.351	2.42237	0.06278911754941822	1185.4601570837613	nan	nan
82.3101	1.5814079387354554	23.3526	2.43516	0.06325631754941821	1185.5413842796556	nan	nan
82.7301	1.5937279387354555	23.3394	2.44685	0.06374911754941821	1184.8712599135256	nan	nan
83.1501	1.6060379387354553	23.3336	2.46012	0.06424151754941822	1184.576811328408	nan	nan
83.5601	1.6177679387354553	23.323	2.47264	0.0647107175494182	1184.0386811556064	nan	nan
83.9801	1.6299479387354554	23.3139	2.48478	0.06519791754941821	1183.576701478956	nan	nan
84.4001	1.6418179387354555	23.3105	2.49723	0.06567271754941822	1183.40409368768	nan	nan
84.8201	1.6543079387354553	23.2977	2.50964	0.06617231754941821	1182.7542761205234	nan	nan
85.2301	1.6664579387354554	23.2917	2.52226	0.06665831754941821	1182.4496741359187	nan	nan
85.6401	1.6787279387354554	23.2796	2.53416	0.06714911754941821	1181.835393466966	nan	nan
86.0501	1.6913779387354555	23.2647	2.5471	0.06765511754941822	1181.078965205198	nan	nan
86.4601	1.7034879387354553	23.2538	2.55963	0.06813951754941822	1180.5256049331663	nan	nan
86.8701	1.7161379387354554	23.238	2.57167	0.06864551754941822	1179.7234863737074	nan	nan
87.2801	1.7279179387354555	23.2133	2.58378	0.06911671754941823	1178.469541537085	nan	nan
87.6801	1.7399379387354554	23.2084	2.59607	0.06959751754941822	1178.220783249658	nan	nan
88.0901	1.7526979387354553	23.1877	2.60896	0.07010791754941821	1177.169906402772	nan	nan
88.5001	1.7650579387354555	23.1728	2.62156	0.07060231754941822	1176.413478141004	nan	nan
88.9001	1.7770879387354555	23.1524	2.63284	0.07108351754941822	1175.3778313933483	nan	nan
89.3001	1.7893279387354555	23.1376	2.6447	0.07157311754941822	1174.6264798313234	nan	nan
89.7201	1.8023179387354553	23.1166	2.65739	0.0720927175494182	1173.5603728852072	nan	nan
90.1301	1.8154079387354554	23.0912	2.67029	0.07261631754941822	1172.270891150381	nan	nan
90.5401	1.8283079387354555	23.0595	2.68244	0.07313231754941822	1170.6615773317199	nan	nan
90.9601	1.8412179387354555	23.0496	2.69537	0.07364871754941822	1170.1589840571223	nan	nan
91.3801	1.8538079387354554	23.014	2.70823	0.07415231754941821	1168.3516789484681	nan	nan
91.7901	1.8662179387354554	22.9964	2.71986	0.07464871754941821	1167.458179793628	nan	nan
92.2001	1.8792579387354553	22.9698	2.73217	0.07517031754941822	1166.1077776618808	nan	nan
92.6201	1.8921579387354555	22.944	2.74497	0.07568631754941822	1164.7979891280809	nan	nan
93.0201	1.9047379387354555	22.9051	2.75683	0.07618951754941822	1162.8231529278944	nan	nan
93.4201	1.9172379387354554	22.8865	2.76842	0.07668951754941822	1161.87888677562	nan	nan
93.8401	1.9306879387354554	22.8529	2.78197	0.07722751754941821	1160.1731156618341	nan	nan
94.2501	1.9431479387354553	22.8267	2.79379	0.07772591754941821	1158.8430203290604	nan	nan
94.6601	1.9560979387354553	22.7936	2.8063	0.07824391754941822	1157.1626327139918	nan	nan
95.0901	1.9694779387354555	22.7694	2.81909	0.07877911754941821	1155.9340713760864	nan	nan
95.5001	1.9822779387354554	22.722	2.83228	0.07929111754941821	1153.52771569771	nan	nan
95.9101	1.9946179387354555	22.6867	2.84379	0.07978471754941822	1151.735640688286	nan	nan
96.3201	2.0077279387354556	22.6737	2.85661	0.08030911754941822	1151.0756697216427	nan	nan
96.7301	2.020157938735456	22.6285	2.86813	0.08080631754941824	1148.7810014376212	nan	nan
97.1401	2.033377938735456	22.6005	2.88123	0.08133511754941823	1147.3595255094663	nan	nan
97.5501	2.0461779387354557	22.5707	2.89368	0.08184711754941823	1145.8466689859297	nan	nan
97.9501	2.059007938735456	22.5395	2.90579	0.08236031754941824	1144.2627386659858	nan	nan
98.3701	2.0721279387354556	22.498	2.91805	0.08288511754941823	1142.1559082724705	nan	nan
98.7801	2.0853179387354555	22.4649	2.93089	0.08341271754941822	1140.4755206574018	nan	nan
99.1801	2.0977879387354554	22.4309	2.94263	0.08391151754941822	1138.7494427446422	nan	nan
99.5901	2.1103379387354555	22.3924	2.95457	0.08441351754941823	1136.794913343429	nan	nan
100	2.1234279387354555	22.3552	2.96698	0.08493711754941823	1134.9063810388805	nan	nan
100.43	2.1367679387354555	22.3156	2.97993	0.08547071754941822	1132.8960079404899	nan	nan
100.83	2.149437938735456	22.2954	2.99179	0.08597751754941824	1131.8705145923211	nan	nan
101.25	2.1628479387354558	22.2487	3.00411	0.08651391754941823	1129.4996958121485	nan	nan
101.64	2.175597938735456	22.2139	3.01662	0.08702391754941824	1127.7330043014415	nan	nan
102.05	2.1881179387354557	22.1733	3.02827	0.08752471754941822	1125.671864205617	nan	nan
102.46	2.2016879387354558	22.1402	3.04118	0.08806751754941823	1123.9914765905482	nan	nan
102.88	2.2149979387354555	22.1006	3.05402	0.08859991754941822	1121.9811034921577	nan	nan
103.29	2.2271579387354556	22.0573	3.06568	0.08908631754941823	1119.782892503261	nan	nan
103.7	2.2402879387354555	22.0376	3.07854	0.08961151754941822	1118.7827826538091	nan	nan
104.11	2.2527979387354558	21.9809	3.09014	0.09011191754941823	1115.9042938992952	nan	nan
104.52	2.266157938735456	21.9528	3.103	0.09064631754941824	1114.477741271397	nan	nan
104.94	2.2796879387354556	21.9076	3.11572	0.09118751754941823	1112.1830729873755	nan	nan
105.34	2.2927579387354555	21.885	3.1282	0.09171031754941822	1111.035738845365	nan	nan
105.76	2.3058479387354556	21.8414	3.14085	0.09223391754941822	1108.822297757238	nan	nan
106.17	2.3180579387354556	21.7819	3.15212	0.09272231754941823	1105.8016614099088	nan	nan
106.59	2.3313379387354556	21.7626	3.16533	0.09325351754941823	1104.8218583594305	nan	nan
106.99	2.3439379387354555	21.7178	3.17709	0.09375751754941822	1102.5474968743827	nan	nan
107.41	2.3572979387354556	21.6823	3.18955	0.09429191754941822	1100.745268465472	nan	nan
107.83	2.3705879387354556	21.6391	3.2029	0.09482351754941823	1098.5521341763185	nan	nan
108.23	2.3834079387354556	21.6057	3.21525	0.09533631754941822	1096.8565164620195	nan	nan
108.65	2.3966179387354556	21.5591	3.22755	0.09586471754941822	1094.4907743815904	nan	nan
109.06	2.4103679387354555	21.5267	3.24017	0.09641471754941822	1092.8459236647254	nan	nan
109.46	2.4230979387354554	21.4783	3.25216	0.09692391754941822	1090.3888009889147	nan	nan
109.87	2.4356079387354557	21.4378	3.26419	0.09742431754941823	1088.3327375928336	nan	nan
110.3	2.4488579387354554	21.3979	3.27625	0.09795431754941822	1086.3071343952129	nan	nan
110.71	2.462337938735456	21.3601	3.28914	0.09849351754941824	1084.3881418922035	nan	nan
111.14	2.4755679387354554	21.3208	3.30172	0.09902271754941822	1082.3929988930433	nan	nan
111.54	2.4886579387354555	21.2671	3.31429	0.09954631754941821	1079.666811130832	nan	nan
111.95	2.5013579387354556	21.2369	3.32627	0.10005431754941822	1078.133647808322	nan	nan
112.37	2.514667938735456	21.1907	3.33944	0.10058671754941823	1075.7882125268666	nan	nan
112.77	2.5274579387354557	21.148	3.35097	0.10109831754941823	1073.6204617364301	nan	nan
113.19	2.5408779387354556	21.1075	3.36394	0.10163511754941823	1071.564398340349	nan	nan
113.59	2.5536279387354557	21.0652	3.3757	0.10214511754941823	1069.4169543488865	nan	nan
114	2.5668879387354555	21.0139	3.38816	0.10267551754941823	1066.8126073805167	nan	nan
114.4	2.5794479387354556	20.9786	3.39955	0.10317791754941823	1065.020532371093	nan	nan
114.82	2.5927479387354557	20.9345	3.41199	0.10370991754941823	1062.781707784249	nan	nan
115.24	2.605437938735456	20.895	3.42469	0.10421751754941823	1060.776411385602	nan	nan
115.64	2.6187379387354555	20.8523	3.43744	0.10474951754941822	1058.6086605951657	nan	nan
116.04	2.631667938735456	20.8143	3.44939	0.10526671754941823	1056.6795146926697	nan	nan
116.46	2.6450579387354556	20.7568	3.46182	0.10580231754941823	1053.7604123402086	nan	nan
116.87	2.6580279387354557	20.7264	3.47401	0.10632111754941823	1052.2170956182122	nan	nan
117.28	2.6713779387354557	20.6751	3.4862	0.10685511754941823	1049.6127486498426	nan	nan
117.7	2.684887938735456	20.6348	3.49914	0.10739551754941823	1047.566838653248	nan	nan
118.1	2.6976779387354557	20.5903	3.51089	0.10790711754941823	1045.3077072674305	nan	nan
118.51	2.7102179387354557	20.5283	3.52258	0.10840871754941822	1042.1601534265162	nan	nan
118.93	2.7234379387354557	20.5059	3.53521	0.10893751754941823	1041.022972683992	nan	nan
119.34	2.7368379387354556	20.4517	3.54765	0.10947351754941823	1038.2714014230635	nan	nan
119.76	2.7502679387354556	20.3962	3.56047	0.11001071754941823	1035.453833065471	nan	nan
120.17	2.7632779387354556	20.3577	3.57301	0.11053111754941822	1033.499303664258	nan	nan
120.57	2.7761179387354558	20.3149	3.58431	0.11104471754941823	1031.3264761740784	nan	nan
120.98	2.789417938735456	20.2594	3.59727	0.11157671754941824	1028.5089078164854	nan	nan
121.4	2.8027279387354556	20.2071	3.60915	0.11210911754941823	1025.853793850682	nan	nan
121.81	2.8157079387354558	20.17	3.62144	0.11262831754941822	1023.9703382458765	nan	nan
122.23	2.8291679387354556	20.1209	3.6345	0.11316671754941822	1021.4776786718619	nan	nan
122.65	2.8425179387354556	20.0727	3.64688	0.11370071754941823	1019.0307093955383	nan	nan
123.05	2.855027938735456	20.029	3.65864	0.11420111754941824	1016.812191607668	nan	nan
123.45	2.8678579387354555	19.9889	3.67062	0.11471431754941822	1014.7764350105604	nan	nan
123.86	2.8814579387354557	19.9372	3.68307	0.11525831754941823	1012.1517812432172	nan	nan
124.27	2.8942279387354555	19.8875	3.69481	0.11576911754941822	1009.6286614707421	nan	nan
124.68	2.9081579387354557	19.8302	3.70795	0.11632631754941823	1006.7197125177681	nan	nan
125.1	2.921187938735456	19.7818	3.72037	0.11684751754941823	1004.2625898419574	nan	nan
125.51	2.9340779387354554	19.7317	3.73238	0.11736311754941822	1001.7191632705088	nan	nan
125.92	2.947557938735456	19.687	3.74425	0.11790231754941823	999.4498784852044	nan	nan
126.34	2.9611679387354557	19.6338	3.7571	0.11844671754941823	996.74907422171	nan	nan
126.74	2.9739179387354557	19.584	3.76836	0.11895671754941822	994.2208777494917	nan	nan
127.15	2.9866879387354555	19.5341	3.78033	0.11946751754941821	991.6876045775298	nan	nan
127.55	2.9996979387354554	19.4872	3.79307	0.11998791754941822	989.3066323978704	nan	nan
127.96	3.0135979387354555	19.427	3.80576	0.12054391754941822	986.2504591523374	nan	nan
128.37	3.025927938735456	19.3757	3.817	0.12103711754941823	983.6461121839676	nan	nan
128.78	3.039757938735456	19.3226	3.82995	0.12159031754941824	980.9503846202169	nan	nan
129.21	3.0535479387354556	19.2638	3.84286	0.12214191754941822	977.9652851710915	nan	nan
129.6	3.0664479387354557	19.2139	3.85406	0.12265791754941822	975.4320119991297	nan	nan
130.01	3.079337938735456	19.1704	3.86649	0.12317351754941823	973.2236476107463	nan	nan
130.42	3.0925479387354557	19.1021	3.87856	0.12370191754941823	969.7562616859968	nan	nan
130.84	3.1063679387354557	19.0619	3.89191	0.12425471754941823	967.715428389146	nan	nan
131.24	3.1197079387354556	19.0045	3.90399	0.12478831754941823	964.8014027364284	nan	nan
131.65	3.1324079387354558	18.9429	3.91521	0.12529631754941822	961.6741556944877	nan	nan
132.06	3.146177938735456	18.8905	3.92859	0.12584711754941824	959.0139650289406	nan	nan
132.47	3.1599579387354555	18.8329	3.94132	0.12639831754941822	956.089785976736	nan	nan
132.89	3.1734379387354554	18.7752	3.95332	0.1269375175494182	953.1605302247884	nan	nan
133.3	3.1866279387354557	18.7209	3.96593	0.12746511754941822	950.4038822641166	nan	nan
133.71	3.1997879387354558	18.6582	3.97799	0.12799151754941823	947.2207915249983	nan	nan
134.12	3.2131379387354557	18.6079	3.99014	0.12852551754941824	944.6672115540629	nan	nan
134.53	3.226707938735456	18.5478	4.0026	0.12906831754941822	941.6161150082731	nan	nan
134.94	3.2397779387354557	18.4857	4.01462	0.12959111754941824	938.4634844676153	nan	nan
135.35	3.2534079387354558	18.4331	4.02742	0.13013631754941823	935.7931404025813	nan	nan
135.78	3.267037938735456	18.3595	4.03948	0.13068151754941823	932.0566893914314	nan	nan
136.2	3.2808179387354555	18.3154	4.0521	0.13123271754941823	929.8178648045874	nan	nan
136.62	3.2946779387354557	18.245	4.06488	0.13178711754941821	926.2438681852265	nan	nan
137.04	3.3081479387354555	18.1764	4.0775	0.13232591754941822	922.7612521612471	nan	nan
137.43	3.3208079387354554	18.1231	4.08952	0.1328323175494182	920.0553711980093	nan	nan
137.83	3.3340779387354558	18.0565	4.10127	0.13336311754941824	916.6742891688979	nan	nan
138.25	3.3476879387354557	17.9895	4.1134	0.13390751754941824	913.272900340813	nan	nan
138.65	3.360857938735456	17.9196	4.12542	0.13443431754941823	909.724287220169	nan	nan
139.06	3.3743079387354555	17.8497	4.13697	0.1349723175494182	906.175674099525	nan	nan
139.47	3.3889079387354557	17.7407	4.14943	0.13555631754941821	900.6420713792079	nan	nan
139.89	3.4046379387354557	17.6005	4.16243	0.13618551754941824	893.5245383389465	nan	nan