File: original_data/46NT79.csv
Specimen name:	AWA_1_05_Rz
Specimen ID:	46NT79
Material:	42CrMoS4
Specimen type:	Round Tensile Specimen
Gauge diameter:	5.015	mm
Gauge length:	25	mm
Parallel length:	30	mm
Original cross-section:	19.752940524032585	mm²
Cross-section after fracture:	8.719666339227071	mm²
Yield stress at 0.2% plastic strain:	1131.103874548778	MPa
Yield stress at 1% plastic strain:	1143.104213932002	MPa
Ultimate tensile strength:	1197.1837798645006	MPa
Uniform elongation:	5.565130184472215	%
Elongation after fracture:	14.534422157542112	%
Reduction of area:	55.85636311404768	%
Slope of linear-elastic region:	199824.73421938933	MPa
Crosshead seperation speed:	0.029905242191204235	mm/s
Strain rate:	0.0009968414063734744	s-1
Test temperature:	RT	Cel
Machine type:	INSTRON 8852TT
Standard:	DIN EN ISO 6892-1
Date:	2022-08-18 00:00:00
Heat treatment batch:	Batch 1
Time	Displacement	Force	Machine Displacement	Engineering Strain	Engineering Stress	True Strain	True Stress
s	mm	kN	mm		MPa		MPa
0	0.0005322329935573761	0.0883106	0	2.1289319742295045e-05	4.470757145881959	2.1289093127861358e-05	4.470852325260327
0.440001	0.0005543496935573761	0.0870675	-0.000457764	2.2173987742295046e-05	4.40782474356507	2.2173741903170042e-05	4.407922482616904
0.850001	0.00048459449355737615	0.0869783	-0.000751495	1.9383779742295045e-05	4.403308960211625	1.9383591879168294e-05	4.4033943129826465
1.25	0.0005793848935573762	0.0924673	0.000991821	2.3175395742295048e-05	4.681191637644981	2.317512719692387e-05	4.6813001261137295
1.66	0.0005188072935573761	0.141721	0.015358	2.0752291742295046e-05	7.174678616967126	2.0752076416537978e-05	7.174827507990943
2.06	0.0004912748935573761	0.203314	0.0283661	1.9650995742295045e-05	10.292847272669922	1.965080266390571e-05	10.293049537367853
2.47	0.0005384593535573761	0.278067	0.0402527	2.1538374142295046e-05	14.077245849127495	2.1538142194754994e-05	14.077549050115485
2.88	0.0007233379935573761	0.361306	0.0520363	2.8933519742295045e-05	18.29125134864928	2.8933101176104877e-05	18.291780578931288
3.28	0.0009291979935573761	0.470027	0.0640869	3.7167919742295045e-05	23.795292626337712	3.716722903238376e-05	23.796177047864294
3.68001	0.0013350819935573762	0.575806	0.0758324	5.3403279742295047e-05	29.150394053960763	5.340185383796929e-05	29.151950780609027
4.09001	0.0013078089935573763	0.675379	0.0888138	5.231235974229505e-05	34.19131441105157	5.231099149846107e-05	34.193103039391104
4.51001	0.0010036879935573762	0.780396	0.102814	4.0147519742295047e-05	39.507839303749456	4.0146713852138484e-05	39.50942544550788
4.92001	0.0010155249935573762	0.873287	0.113361	4.062099974229505e-05	44.2104809123233	4.062017473186741e-05	44.21227678625704
5.33001	0.0008525359935573761	0.984935	0.125031	3.4101439742295045e-05	49.86270265946837	3.410085830137358e-05	49.8644030494185
5.74001	0.0007252189935573762	1.14573	0.140751	2.9008759742295047e-05	58.00300965853857	2.900833899638761e-05	58.004692253910086
6.15001	0.0009913649935573761	1.27232	0.151127	3.965459974229505e-05	64.41167574275946	3.9653813519455916e-05	64.41422996197977
6.55001	0.0015001459935573762	1.41667	0.161098	6.000583974229505e-05	71.7194484677558	6.000403946381051e-05	71.72375205348695
6.96001	0.002623462993557376	1.63829	0.175941	0.00010493851974229505	82.93904383536012	0.00010493301408095252	82.94774733584904
7.36001	0.0034789729935573764	1.80243	0.186642	0.00013915891974229506	91.2486927101845	0.0001391492380380806	91.26139077968995
7.77001	0.004651512993557376	2.04242	0.20015	0.00018606051974229504	103.39827619665397	0.00018604321263059162	103.41751453366358
8.19001	0.005935062993557376	2.26716	0.212296	0.00023740251974229502	114.77582273088102	0.00023737434422326152	114.80307080040282
8.58001	0.007208462993557376	2.47535	0.222889	0.000288338519742295	125.31551932677287	0.00028829695818032784	125.35165261811629
8.98001	0.008699522993557376	2.73421	0.235252	0.00034798091974229503	138.42040361906624	0.0003479203884240332	138.4685712784287
9.39001	0.010248922993557376	2.97276	0.246895	0.000409956919742295	150.49708656709447	0.0004098729103635602	150.5587838891337
9.80001	0.012071332993557376	3.26331	0.260239	0.000482853319742295	165.20628895883453	0.0004827367835898368	165.28605936390062
10.2	0.013588532993557376	3.51839	0.272041	0.0005435413197422951	178.11980933771966	0.0005433936546648153	178.21662481395933
10.62	0.015598132993557376	3.83142	0.285912	0.000623925319742295	193.96707013512597	0.000623730759263161	194.0880911013795
11.06	0.017217732993557375	4.08597	0.29739	0.000688709319742295	206.85375906583474	0.0006884722683121896	206.9962211775271
11.46	0.019065732993557377	4.3781	0.310043	0.000762629319742295	221.64294954836453	0.0007623386657673566	221.81198096020427
11.87	0.020603432993557377	4.64134	0.321587	0.0008241373197422951	234.9695729784167	0.0008237979050515797	235.16322017251215
12.27	0.022425832993557375	4.92958	0.333397	0.000897033319742295	249.56183075640732	0.0008966312257970048	249.78569603393169
12.69	0.024302132993557376	5.23574	0.346367	0.0009720853197422951	265.06129523500016	0.0009716131507754985	265.31895742893
13.1	0.026238532993557377	5.52263	0.358532	0.0010495413197422951	279.5852087582021	0.0010489909363177311	279.8786449871826
13.51	0.028247332993557375	5.84172	0.372272	0.001129893319742295	295.7392593215486	0.0011292554707077005	296.07341313504156
13.91	0.029679532993557377	6.09989	0.382572	0.001187181319742295	308.809212105839	0.0011864771772408583	309.1758246338154
14.31	0.03171073299355738	6.44277	0.395714	0.0012684293197422953	326.16764031468375	0.001267625542890278	326.58136091281006
14.72	0.033492532993557374	6.71766	0.407928	0.001339701319742295	340.0840493508752	0.0013388047206232111	340.53966040061385
15.14	0.035497632993557376	7.03282	0.420574	0.001419905319742295	356.03914219472586	0.001418898207407216	356.54468406676466
15.55	0.037254532993557375	7.31325	0.431862	0.001490181319742295	370.23601580242047	0.001489072101380389	370.7877345970651
15.95	0.03917423299355738	7.63068	0.444458	0.0015669693197422952	386.30602824506394	0.0015657429043207688	386.9113579393554
16.36	0.04124483299355738	7.9602	0.456566	0.001649793319742295	402.98810145837047	0.0016484339057061723	403.65294853609214
16.77	0.04306673299355738	8.2654	0.46981	0.0017226693197422952	418.4389655780024	0.001721187226809601	419.1597975461883
17.17	0.04480433299355738	8.54365	0.480396	0.0017921733197422951	432.5254758705568	0.0017905692933146526	433.3006364885209
17.57	0.04686413299355738	8.84802	0.49255	0.001874565319742295	447.93432092983727	0.001872810514828681	448.7740030733747
18	0.048956432993557376	9.18766	0.505955	0.001958257319742295	465.1287229271892	0.00195634243336313	466.03956465348375
18.4	0.05106333299355738	9.54411	0.519257	0.002042533319742295	483.174137460095	0.0020404501846607004	484.16103673509497
18.81	0.05278023299355738	9.81344	0.52985	0.0021112093197422953	496.80906941730495	0.0021089838490856556	497.8579373547913
19.21	0.05482843299355738	10.1319	0.541275	0.002193137319742295	512.9312259950834	0.002190735904538659	514.0561546092745
19.63	0.056941432993557375	10.4564	0.554337	0.002277657319742295	529.3591598313238	0.0022750673902116277	530.5648585964863
20.06	0.05912173299355738	10.819	0.56786	0.002364869319742295	547.7159204138225	0.0023620774170827713	549.0111969899435
20.46	0.06157023299355738	11.1798	0.580921	0.002462809319742295	565.9815553232694	0.00245978157502262	567.3754599725218
20.87	0.06321103299355739	11.4479	0.591652	0.0025284413197422958	579.554218070561	0.002525250189913186	581.0195869025616
21.28	0.06522433299355739	11.7787	0.603611	0.0026089733197422952	596.3010917624819	0.002605575856827831	597.8568254014234
21.68	0.06730423299355738	12.1049	0.615311	0.002692169319742295	612.8150887343821	0.002688551922894686	614.4648907149481
22.09	0.06948683299355739	12.4351	0.627872	0.0027794733197422953	629.5315872019524	0.00277561772646821	631.2813534525153
22.49	0.07144753299355738	12.7289	0.638695	0.0028579013197422955	644.4053220589245	0.002853825283857771	646.2469688792856
22.89	0.07341643299355738	13.0496	0.651207	0.002936657319742295	660.6408794742783	0.00293235376495391	662.5809553487074
23.31	0.07562833299355738	13.4097	0.664097	0.0030251333197422953	678.8710766219831	0.0030205668111546718	680.9247521356815
23.71	0.07753573299355739	13.6903	0.674709	0.0031014293197422953	693.0765565432438	0.0030966298088315808	695.226084496533
24.11	0.07968543299355739	14.0234	0.687405	0.0031874173197422957	709.939868595175	0.003182348273744375	712.2027432283109
24.52	0.08184253299355738	14.3512	0.700089	0.0032737013197422955	726.5348661653434	0.0032683544258214066	728.9133243155477
24.92	0.08378923299355738	14.6712	0.711819	0.003351569319742295	742.7349858189549	0.0033459653292406103	745.224313610125
25.33	0.08600573299355738	15.0023	0.72419	0.003440229319742295	759.497047123051	0.0034343252678427547	762.1098911328213
25.74	0.08799073299355738	15.3173	0.735851	0.003519629319742295	775.4440399070749	0.0035134499196884813	778.1733154857512
26.14	0.09021843299355738	15.6618	0.748795	0.003608737319742295	792.884481221666	0.0036022414504539736	795.745793039295
26.55	0.09202993299355738	15.9383	0.758965	0.0036811973197422953	806.8823971098647	0.003674438295345393	809.8526904274528
26.95	0.09419363299355739	16.2865	0.771984	0.0037677453197422954	824.5101523079508	0.0037606651459667394	827.616696575389
27.36	0.09628093299355739	16.6006	0.784355	0.0038512373197422956	840.4115822554488	0.0038438402910218965	843.6482067049748
27.76	0.09840603299355738	16.9324	0.796444	0.003936241319742295	857.2090813212874	0.003928514591419853	860.5832631268427
28.17	0.10052483299355738	17.2597	0.80864	0.004020993319742296	873.7787662044967	0.004012930731951419	877.2922247863378
28.58	0.10245223299355738	17.5521	0.819817	0.004098089319742295	888.5816255379843	0.004089715022986964	892.2231124073207
28.99	0.10461523299355738	17.899	0.832726	0.004184609319742295	906.1435677499777	0.004175878191262368	909.9354245686089
29.42	0.10696923299355739	18.2366	0.845577	0.004278769319742295	923.2346939845378	0.004269641414500943	927.1850022680806
29.82	0.10889323299355738	18.5419	0.856514	0.004355729319742295	938.6906206415615	0.004346270587294392	942.779302900057
30.23	0.11109123299355739	18.8631	0.869411	0.004443649319742295	954.951490743874	0.004433805461101268	959.194960286105
30.63	0.11318423299355738	19.1777	0.880955	0.004527369319742295	970.8782333783311	0.004517151611216524	975.2737577053338
31.04	0.11540523299355739	19.5078	0.893421	0.004616209319742296	987.5896693085097	0.0046055873019282345	992.1485899440529
31.45	0.11749323299355738	19.8205	0.905045	0.004699729319742295	1003.4202237325231	0.004688720072083491	1008.1360271780213
31.85	0.11950323299355738	20.1253	0.917046	0.004780129319742295	1018.8508377025881	0.004768740779628384	1023.7210764643343
32.26	0.12170023299355738	20.4447	0.929443	0.0048680093197422955	1035.020582131849	0.004856198875766209	1040.059071971792
32.66	0.12380123299355739	20.7513	0.940903	0.004952049319742295	1050.5423217749658	0.004939828253120341	1055.744659164872
33.07	0.12646223299355736	21.1174	0.954498	0.0050584893197422945	1069.0762711661757	0.005045738145683859	1074.4841820658598
33.48	0.12872923299355737	21.4145	0.967052	0.005149169319742295	1084.1170697570756	0.005135957680637666	1089.6993721116776
33.88	0.13068123299355736	21.6465	0.976719	0.005227249319742294	1095.862156505944	0.005213634676164782	1101.590501218071
34.28	0.13348923299355736	21.9532	0.989502	0.005339569319742294	1111.3889586864523	0.0053253643626148895	1117.3232970725546
34.69	0.13654723299355737	22.1802	1.00087	0.005461889319742294	1122.880918565733	0.00544702729420402	1129.0139698621895
35.1	0.14151123299355736	22.3817	1.01442	0.005660449319742295	1133.0819314101163	0.005644489175891007	1139.495684257979
35.5	0.14937823299355737	22.4307	1.02632	0.005975129319742295	1135.5625747320757	0.005957349025764622	1142.3477079667593
35.9101	0.16180223299355737	22.3759	1.03933	0.006472089319742295	1132.7883042413948	0.006451235280766779	1140.1198113268044
36.3101	0.17289123299355738	22.3573	1.05077	0.006915649319742295	1131.8466722865285	0.0068918458980496726	1139.6741269557792
36.7201	0.18505123299355736	22.3395	1.0629	0.007402049319742294	1130.9455406307964	0.0073747885935164905	1139.316855300488
37.1301	0.19711023299355737	22.3287	1.07584	0.007884409319742295	1130.398786592487	0.007853489779785588	1139.3113133205222
37.5301	0.20843923299355738	22.3305	1.08753	0.008337569319742295	1130.4899122655386	0.008303003784127813	1139.915450274322
37.9301	0.21953323299355737	22.3461	1.09903	0.008781329319742294	1131.279668098652	0.00874299768578473	1141.2138074169552
38.3401	0.23162023299355736	22.3583	1.11172	0.009264809319742294	1131.8972976604462	0.00922215423230071	1142.3841102928018
38.7501	0.24333223299355736	22.362	1.12372	0.009733289319742294	1132.084611543941	0.00968622600009836	1143.1035186025263
39.1501	0.25490823299355736	22.3557	1.13627	0.010196329319742294	1131.7656716882605	0.01014469742785286	1143.3055271895732
39.5601	0.26773223299355736	22.332	1.14904	0.010709289319742294	1130.5658503264149	0.010652351032538941	1142.673407112581
39.9601	0.27982023299355735	22.3106	1.16109	0.011192809319742293	1129.4824673245798	0.011130633348525036	1142.1245492113358
40.3701	0.28982823299355737	22.3424	1.17249	0.011593129319742294	1131.0923542151575	0.01152644389632392	1144.2052541501455
40.7701	0.2993632329935574	22.3732	1.18371	0.011974529319742295	1132.6516157318174	0.011903401892156619	1146.2145857134515
41.1801	0.3092992329935574	22.404	1.19674	0.012371969319742295	1134.2108772484776	0.01229606194849955	1148.2432994239139
41.5901	0.31915523299355736	22.4431	1.20816	0.012766209319742294	1136.1903293686532	0.012685408225349646	1150.6951729404404
41.9901	0.33090423299355737	22.4787	1.22165	0.013236169319742294	1137.9925926801175	0.013149336612980353	1153.055255321444
42.3901	0.34209123299355737	22.4886	1.23501	0.013683649319742294	1138.4937838819012	0.01359087357280966	1154.0725335732477
42.8001	0.3517422329935574	22.5009	1.24622	0.014069689319742295	1139.1164759810868	0.013971629947175043	1155.1434908971403
43.2101	0.3612222329935574	22.5218	1.25748	0.014448889319742295	1140.1745462959632	0.014345498846784861	1156.648802120581
43.6201	0.3715542329935574	22.5499	1.26948	0.014862169319742295	1141.5971193030462	0.014752809499288583	1158.563728985058
44.0201	0.38212223299355735	22.5734	1.28213	0.015284889319742295	1142.786815590108	0.01516925224348313	1160.2541855824636
44.4201	0.3931272329935574	22.5947	1.29484	0.015725089319742296	1143.8651360545516	0.01560273116433778	1161.8525174887486
44.8301	0.40400823299355737	22.6101	1.30672	0.016160329319742296	1144.6447668128817	0.016031141155043168	1163.1426031986975
45.2401	0.41504423299355736	22.6226	1.31963	0.016601769319742294	1145.277583986851	0.01646546645777755	1164.2912182432724
45.6401	0.4251452329935574	22.6384	1.33147	0.017005809319742295	1146.0774648947481	0.016862829262244236	1165.5674397284017
46.0501	0.43513623299355736	22.6581	1.34259	0.017405449319742295	1147.0747847609236	0.017255709515382155	1167.040136793034
46.4501	0.44568023299355736	22.6807	1.35455	0.017827209319742295	1148.2189182114598	0.017670168279344152	1168.6884572113036
46.8601	0.45747723299355736	22.7098	1.36799	0.018299089319742293	1149.6921165924603	0.018133675880776925	1170.7304353241893
47.2701	0.46921623299355736	22.719	1.38142	0.018768649319742294	1150.1578700325015	0.018594691486109812	1171.7447797574832
47.6701	0.4790162329935574	22.7209	1.3917	0.019160649319742297	1150.254058242945	0.018979395710241855	1172.2936728815484
48.0701	0.48866323299355735	22.7396	1.40271	0.019546529319742295	1151.2007527352025	0.019357949343300346	1173.7027320014506
48.4901	0.49908023299355736	22.7692	1.41431	0.019963209319742294	1152.6992638031618	0.019766557351296857	1175.7108404891771
48.9001	0.5103542329935574	22.7888	1.4278	0.020414169319742298	1153.6915211319454	0.020208593233544944	1177.243175187084
49.3201	0.5214632329935575	22.8024	1.4404	0.0208585293197423	1154.3800262172238	0.0206439686807502	1178.4586958402006
49.7301	0.5316082329935574	22.8174	1.4523	0.021264329319742297	1155.1394068259867	0.021041398251282227	1179.7026715829463
50.1301	0.5417472329935574	22.833	1.46421	0.021669889319742296	1155.9291626591005	0.021438435024788965	1180.9780196753854
50.5401	0.5526222329935574	22.8532	1.47637	0.022104889319742294	1156.9517952122349	0.02186411794358714	1182.5260865936784
50.9401	0.5632572329935575	22.8756	1.4886	0.022530289319742297	1158.0858035879874	0.02228023130266705	1184.177811799911
51.3601	0.5741192329935574	22.8864	1.50173	0.022964769319742295	1158.6325576262968	0.02270504778384025	1185.2402870385279
51.7701	0.5843332329935574	22.8988	1.51335	0.023373329319742297	1159.2603122628745	0.0231043561930422	1186.356085308702
52.1801	0.5946942329935574	22.9144	1.52602	0.023787769319742295	1160.050068095988	0.023509248613025585	1187.6450715152068
52.5801	0.6046262329935574	22.9329	1.5373	0.0241850493197423	1160.9866375134625	0.023897222517139306	1189.0651566012873
53.0001	0.6153732329935574	22.9557	1.54977	0.024614929319742296	1162.140896038782	0.024316863292998637	1190.7469120543585
53.4301	0.6270992329935574	22.9775	1.56393	0.025083969319742296	1163.2445291901845	0.024774530522559454	1192.423319271749
53.8301	0.6376102329935575	22.9879	1.57563	0.025504409319742297	1163.7710330789268	0.025184598199009117	1193.452325861031
54.2301	0.6476982329935574	23.0009	1.58718	0.0259079293197423	1164.429162939855	0.02557800521680261	1194.5971113911476
54.6401	0.6576682329935575	23.0137	1.59901	0.0263067293197423	1165.0771677259993	0.02596665852199267	1195.7265374139793
55.0601	0.6680402329935574	23.0279	1.61129	0.026721609319742295	1165.7960480356282	0.026370822456643794	1196.9479945777357
55.4701	0.6786202329935574	23.0474	1.62304	0.027144809319742298	1166.7832428270203	0.026782923265293024	1198.4553514710306
55.8701	0.6889912329935575	23.0677	1.63517	0.027559649319742297	1167.810937917546	0.027186718569179463	1199.9953978383128
56.2801	0.6993532329935574	23.0819	1.64744	0.0279741293197423	1168.5298182271754	0.027590000684924294	1201.2184224762373
56.6901	0.7102532329935575	23.096	1.66017	0.028410129319742298	1169.2436359994124	0.02801404595243847	1202.4619989044413
57.0901	0.7203132329935574	23.1075	1.67162	0.0288125293197423	1169.8258277994642	0.028405253003792052	1203.531468761928
57.5401	0.7314572329935575	23.1296	1.68471	0.0292582893197423	1170.9446485630417	0.028838435383070144	1205.2044858681033
57.9301	0.7419752329935574	23.1452	1.69682	0.029679009319742294	1171.7344043961552	0.029247112234117082	1206.5103207044915
58.3501	0.7527072329935575	23.1551	1.70991	0.0301082893197423	1172.235595597939	0.029663931977105713	1207.529604061102
58.7601	0.7628252329935574	23.1674	1.72107	0.030513009319742296	1172.8582876971245	0.03005674554791706	1208.6457235603639
59.1701	0.7733542329935574	23.1812	1.73362	0.030934169319742296	1173.5569178571866	0.030465351705982757	1209.8599262605355
59.5701	0.7834822329935575	23.1958	1.74551	0.0313392893197423	1174.2960483163824	0.030858238501392136	1211.0976519215997
59.9901	0.7946042329935574	23.2233	1.7587	0.031784169319742296	1175.6882460991148	0.031289506930852584	1213.0565203803599
60.4101	0.8060392329935574	23.2304	1.77208	0.03224156931974229	1176.0476862539292	0.03173271846540345	1213.9653092536078
60.8201	0.8164362329935574	23.2372	1.78421	0.03265744931974229	1176.3919387965686	0.03213552751501719	1214.809898917971
61.2301	0.8267502329935574	23.2433	1.79631	0.0330700093197423	1176.7007535774658	0.03253496065781614	1215.6142584648203
61.6301	0.8363052329935574	23.2568	1.80731	0.0334522093197423	1177.3841961253522	0.032904857483420515	1216.770298703894
62.0301	0.8462192329935574	23.2729	1.81894	0.033848769319742296	1178.1992646454246	0.033288507478231644	1218.0798597670976
62.4401	0.8563822329935574	23.2891	1.83102	0.034255289319742296	1179.019395702889	0.03368164050607674	1219.407046216279
62.8501	0.8675412329935575	23.3105	1.84376	0.034701649319742296	1180.102778704724	0.03411312363517337	1221.0542914925886
63.2501	0.8784342329935574	23.3213	1.85701	0.0351373693197423	1180.6495327430334	0.03453414189071153	1222.1344514122065
63.6601	0.8890732329935574	23.3272	1.86914	0.035562929319742295	1180.948222449147	0.03494517192366321	1222.9462006143813
64.0701	0.8999762329935574	23.3363	1.88185	0.0359990493197423	1181.4089133517966	0.035366226191833994	1223.9385110903313
64.4701	0.9100322329935574	23.3476	1.89346	0.0364012893197423	1181.9809800770645	0.035754413741846715	1225.0066117032823
64.8801	0.9199502329935574	23.3593	1.90495	0.036798009319742295	1182.5732969518997	0.036137126590633145	1226.089640154414
65.2801	0.9301062329935574	23.3687	1.91666	0.0372042493197423	1183.0491754667246	0.03652887158850192	1227.063631948304
65.7001	0.9408202329935574	23.3841	1.92928	0.0376328093197423	1183.8288062250544	0.03694197391314966	1228.37960995694
66.1201	0.9522682329935575	23.4033	1.94251	0.0380907293197423	1184.8008134042714	0.03738318874634357	1229.930740485464
66.5301	0.9636812329935575	23.4106	1.95556	0.0385472493197423	1185.1703786338692	0.03782286095888132	1230.8554367054423
66.9401	0.9743132329935574	23.4147	1.9679	0.038972529319742294	1185.3779426669312	0.038232272229294206	1231.5751192924938
67.3401	0.9845412329935574	23.4189	1.97966	0.0393816493197423	1185.590569237385	0.03862596836587109	1232.2810812718853
67.7501	0.9951752329935575	23.4274	1.99202	0.0398070093197423	1186.0208849156838	0.03903512797163043	1233.2328293349315
68.1601	1.0050322329935573	23.4386	2.0028	0.04020128931974229	1186.5878891035604	0.03941424184822446	1234.290252136715
68.5601	1.0154222329935574	23.451	2.01464	0.0406168893197423	1187.2156437401377	0.03981370010920335	1235.4366501405975
68.9701	1.0264122329935572	23.4664	2.02729	0.04105648931974229	1187.995274498468	0.04023605263678575	1236.7701897978186
69.3701	1.0388322329935573	23.4938	2.04256	0.041553289319742295	1189.3824097438082	0.04071314634345991	1238.805161127705
69.7701	1.0491122329935574	23.4554	2.05308	0.041964489319742296	1187.438395385375	0.04110786340280496	1237.2686412463768
70.1801	1.0578922329935574	23.4673	2.06304	0.0423156893197423	1188.0408373349937	0.04144486224482523	1238.3136043068278
70.5901	1.0694322329935573	23.5072	2.07628	0.04277728931974229	1190.0607897543034	0.04188762428207699	1240.968364465704
70.9901	1.0809722329935574	23.5135	2.08915	0.0432388893197423	1190.3797296099838	0.042330190367864014	1241.8504269870548
71.4001	1.0917122329935574	23.507	2.10174	0.04366848931974229	1190.0506646795197	0.04274190006851039	1242.0183794200295
71.8001	1.1016722329935573	23.5041	2.11269	0.04406688931974229	1189.903851095159	0.04312355763767563	1242.3392124025045
72.2101	1.1118722329935573	23.5174	2.12388	0.04447488931974229	1190.577168568262	0.043514260863594154	1243.5279563669476
72.6201	1.1224322329935572	23.5321	2.13564	0.04489728931974229	1191.32136156485	0.04391859285391467	1244.8084614078164
73.0201	1.1335822329935572	23.5429	2.14848	0.04534328931974229	1191.8681156031591	0.04434533799638886	1245.9113363999293
73.4201	1.1444522329935574	23.5503	2.16122	0.045778089319742296	1192.2427433701491	0.044761191433408315	1246.8213381669625
73.8301	1.1559022329935573	23.5528	2.1737	0.046236089319742296	1192.369306804943	0.04519904698141891	1247.4998005764955
74.2401	1.1668522329935573	23.5562	2.18523	0.04667408931974229	1192.5414330762626	0.045617602933666505	1248.2022184411576
74.6401	1.1774622329935573	23.5602	2.19723	0.047098489319742295	1192.7439345719326	0.04602299558245937	1248.9203720355563
75.0501	1.1885922329935572	23.5652	2.20969	0.04754368931974229	1192.9970614415204	0.04644808012553196	1249.7165430900616
75.4501	1.1991422329935573	23.5703	2.22149	0.047965689319742294	1193.2552508484998	0.04685084616419189	1250.49056148985
75.8601	1.2096722329935574	23.5753	2.23311	0.0483868893197423	1193.5083777180876	0.04725268697089559	1251.2585354929179
76.2601	1.2202622329935573	23.5827	2.24507	0.048810489319742294	1193.8830054850773	0.04765665467567631	1252.1570191733285
76.6701	1.2318222329935573	23.5916	2.25769	0.049272889319742295	1194.3335713129434	0.04809743792785236	1253.1818371830987
77.0701	1.2430222329935574	23.5977	2.26986	0.0497208893197423	1194.6423860938403	0.048524309137631005	1254.0410679494848
77.4801	1.2543322329935573	23.6016	2.28287	0.05017328931974229	1194.8398250521188	0.04895518799962421	1254.7888692852089
77.8901	1.2659422329935572	23.6005	2.29571	0.05063768931974229	1194.7841371408094	0.04939730298501457	1255.2852450815021
78.2901	1.2768422329935574	23.6024	2.307	0.051073689319742294	1194.8803253512526	0.04981220296670171	1255.907271862515
78.7001	1.2876522329935574	23.6062	2.31896	0.05150608931974229	1195.0727017721395	0.050223507223014496	1256.6262230932011
79.1101	1.2987722329935574	23.6086	2.33128	0.051950889319742295	1195.1942026695415	0.05064643006968711	1257.2856044080245
79.5101	1.3097922329935574	23.6135	2.34315	0.05239168931974229	1195.4422670017375	0.05106537326926082	1258.0735068541808
79.9101	1.3205122329935572	23.6139	2.355	0.052820489319742286	1195.4625171513044	0.05147274313941537	1258.6074322706472
80.3201	1.3311722329935574	23.6153	2.36637	0.053246889319742294	1195.5333926747892	0.05187766846151165	1259.1918269125995
80.7301	1.3427822329935573	23.6215	2.37877	0.05371128931974229	1195.8472699930776	0.05231849354501697	1260.0777686938998
81.1301	1.3539622329935572	23.6267	2.39079	0.05415848931974229	1196.110521937449	0.05274280818839899	1260.8900608650297
81.5401	1.3653722329935574	23.6289	2.40304	0.054614889319742295	1196.2218977600676	0.05317566646681736	1261.5534243080856
81.9401	1.3765922329935574	23.6286	2.41529	0.055063689319742294	1196.2067101478922	0.053601134129346036	1262.0742647976667
82.3501	1.3886222329935574	23.6292	2.42781	0.055544889319742295	1196.2370853722427	0.054057116364240425	1262.681941879415
82.7601	1.3997022329935573	23.6288	2.43985	0.05598808931974229	1196.2168352226756	0.0544769061671863	1263.1907302389022
83.1601	1.4109222329935573	23.6292	2.45132	0.05643688931974229	1196.2370853722427	0.05490182067188197	1263.748985359567
83.5601	1.4220422329935574	23.63	2.4639	0.056881689319742294	1196.2775856713768	0.05532276998928649	1264.3238756397075
83.9701	1.4337122329935572	23.6306	2.47668	0.05734848931974229	1196.3079608957273	0.05576434916292732	1264.9144152142785
84.3701	1.4449622329935574	23.6304	2.48861	0.0577984893197423	1196.2978358209439	0.05618985151461635	1265.4420435078716
84.7801	1.4562422329935574	23.6319	2.49995	0.058249689319742295	1196.3737738818202	0.05661630683958753	1266.0621745207238
85.1901	1.4681022329935574	23.6327	2.51308	0.058724089319742295	1196.4142741809542	0.05706449378713289	1266.6726128813712
85.5901	1.4792522329935573	23.6251	2.52408	0.0591700893197423	1196.0295213391807	0.057485666866591775	1266.7986949458686
86.0001	1.4903222329935573	23.6258	2.53656	0.05961288931974229	1196.0649591009233	0.05790364266771038	1267.3658471270287
86.4101	1.5021422329935572	23.6256	2.54879	0.060085689319742286	1196.0548340261396	0.058349743837570446	1267.9206131928102
86.8101	1.5136422329935573	23.6265	2.56135	0.06054568931974229	1196.1003968626653	0.05878357690431473	1268.5191198863326
87.2201	1.5265322329935573	23.6428	2.57435	0.06106128931974229	1196.9255904575214	0.05926962358057622	1270.0114102306513
87.6201	1.5399222329935573	23.643	2.58826	0.0615968893197423	1196.9357155323048	nan	nan
88.0301	1.5503322329935574	23.5737	2.59821	0.062013289319742294	1193.4273771198193	nan	nan
88.4301	1.5599622329935574	23.6139	2.60986	0.0623984893197423	1195.4625171513044	nan	nan
88.8401	1.5726622329935573	23.6295	2.6235	0.0629064893197423	1196.252272984418	nan	nan
89.2401	1.5858522329935574	23.6156	2.63625	0.0634340893197423	1195.5485802869644	nan	nan
89.6501	1.5970522329935573	23.5919	2.6478	0.06388208931974229	1194.3487589251185	nan	nan
90.0501	1.6077622329935572	23.587	2.65848	0.06431048931974229	1194.1006945929228	nan	nan
90.4601	1.6189722329935574	23.5895	2.6699	0.0647588893197423	1194.2272580277165	nan	nan
90.8701	1.6311322329935574	23.5916	2.68192	0.0652452893197423	1194.3335713129434	nan	nan
91.2701	1.6433622329935573	23.5939	2.69431	0.0657344893197423	1194.4500096729537	nan	nan
91.6801	1.6565222329935574	23.5846	2.7081	0.06626088931974229	1193.9791936955205	nan	nan
92.0801	1.6682322329935573	23.5728	2.72031	0.06672928931974229	1193.3818142832936	nan	nan
92.4901	1.6808922329935574	23.5562	2.73259	0.06723568931974229	1192.5414330762626	nan	nan
92.9001	1.6926522329935574	23.5457	2.74482	0.0677060893197423	1192.0098666501285	nan	nan
93.3001	1.7050522329935573	23.5356	2.75683	0.0682020893197423	1191.4985503735613	nan	nan
93.7001	1.7169922329935574	23.5255	2.76823	0.06867968931974229	1190.9872340969941	nan	nan
94.1101	1.7289422329935573	23.5133	2.78022	0.0691576893197423	1190.3696045352003	nan	nan
94.5201	1.7415622329935574	23.5003	2.79259	0.0696624893197423	1189.7114746742723	nan	nan
94.9201	1.7537922329935574	23.4874	2.80456	0.07015168931974229	1189.0584073507362	nan	nan
95.3401	1.7665122329935574	23.4711	2.81696	0.0706604893197423	1188.2332137558801	nan	nan
95.7501	1.7787022329935573	23.4554	2.82963	0.0711480893197423	1187.438395385375	nan	nan
96.1501	1.7908922329935573	23.4342	2.8415	0.07163568931974229	1186.3651374583233	nan	nan
96.5701	1.8035122329935573	23.4197	2.85333	0.07214048931974229	1185.6310695365187	nan	nan
96.9801	1.8167622329935573	23.4002	2.86645	0.07267048931974229	1184.643874745127	nan	nan
97.3901	1.8293122329935574	23.3806	2.87884	0.0731724893197423	1183.6516174163432	nan	nan
97.7901	1.8419522329935574	23.3406	2.89101	0.07367808931974229	1181.6266024596416	nan	nan
98.2001	1.8529222329935573	23.3037	2.90141	0.0741168893197423	1179.7585261620848	nan	nan
98.6001	1.8642422329935573	23.3133	2.91266	0.0745696893197423	1180.244529751693	nan	nan
99.0101	1.8784222329935574	23.3111	2.92697	0.0751368893197423	1180.1331539290745	nan	nan
99.4101	1.8934722329935574	23.2641	2.94081	0.07573888931974229	1177.7537613549503	nan	nan
99.8301	1.9060822329935574	23.1904	2.95246	0.0762432893197423	1174.022671297228	nan	nan
100.26	1.9184422329935573	23.1754	2.96461	0.07673768931974229	1173.2632906884648	nan	nan
100.66	1.9304122329935574	23.1613	2.97624	0.07721648931974229	1172.5494729162276	nan	nan
101.07	1.9433022329935574	23.1411	2.98862	0.07773208931974229	1171.5268403630935	nan	nan
101.5	1.9580822329935572	23.1079	3.00294	0.07832328931974229	1169.8460779490313	nan	nan
101.91	1.9719322329935574	23.0716	3.01619	0.07887728931974229	1168.0083768758245	nan	nan
102.32	1.9856422329935572	23.0113	3.02835	0.0794256893197423	1164.9556668285973	nan	nan
102.72	1.9965222329935572	22.9773	3.03843	0.07986088931974229	1163.2344041154008	nan	nan
103.13	2.0081122329935575	22.9653	3.04928	0.0803244893197423	1162.6268996283904	nan	nan
103.53	2.0208522329935574	22.9428	3.06173	0.0808340893197423	1161.487828715246	nan	nan
103.95	2.0347422329935574	22.9098	3.0753	0.08138968931974229	1159.8171913759672	nan	nan
104.36	2.0492522329935574	22.8709	3.08867	0.0819700893197423	1157.847864330575	nan	nan
104.77	2.0632722329935573	22.8291	3.10175	0.0825308893197423	1155.7317237008222	nan	nan
105.17	2.0757622329935574	22.7466	3.11225	0.0830304893197423	1151.5551303526256	nan	nan
105.58	2.0856822329935576	22.7577	3.12204	0.0834272893197423	1152.11707200311	nan	nan
105.98	2.1019222329935574	22.7544	3.13852	0.08407688931974229	1151.9500082691823	nan	nan
106.4	2.1142122329935575	22.6274	3.14795	0.0845684893197423	1145.5205857816552	nan	nan
106.81	2.1248722329935577	22.6521	3.15904	0.0849948893197423	1146.7710325174182	nan	nan
107.21	2.1393422329935574	22.636	3.17285	0.0855736893197423	1145.9559639973459	nan	nan
107.62	2.1548122329935575	22.5759	3.18682	0.0861924893197423	1142.913379024902	nan	nan
108.02	2.1671022329935576	22.4991	3.19791	0.08668408931974231	1139.025350308035	nan	nan
108.43	2.1780422329935574	22.477	3.20879	0.08712168931974229	1137.9065295444577	nan	nan
108.85	2.1905822329935574	22.4623	3.22055	0.0876232893197423	1137.16233654787	nan	nan
109.26	2.2047422329935573	22.4331	3.23313	0.08818968931974229	1135.6840756294778	nan	nan
109.67	2.2187722329935577	22.3895	3.24674	0.08875088931974232	1133.4768093266732	nan	nan
110.07	2.2328922329935574	22.3425	3.25993	0.08931568931974229	1131.0974167525492	nan	nan
110.48	2.2457022329935574	22.2485	3.27074	0.0898280893197423	1126.3386316043006	nan	nan
110.88	2.2553022329935577	22.2352	3.27984	0.09021208931974231	1125.6653141311974	nan	nan
111.29	2.2704622329935575	22.2692	3.29515	0.0908184893197423	1127.3865768443936	nan	nan
111.72	2.2862822329935577	22.1453	3.30874	0.09145128931974231	1121.1140930160109	nan	nan
112.13	2.2967322329935573	22.1066	3.31789	0.0918692893197423	1119.1548910454023	nan	nan
112.53	2.3081122329935577	22.1108	3.32927	0.09232448931974231	1119.367517615856	nan	nan
112.96	2.3244322329935576	22.0899	3.34525	0.0929772893197423	1118.3094473009796	nan	nan
113.36	2.3397922329935574	22.0153	3.35848	0.0935916893197423	1114.5327944067312	nan	nan
113.77	2.3527622329935576	21.9363	3.36982	0.09411048931974231	1110.533389867246	nan	nan
114.17	2.3626422329935575	21.9118	3.37925	0.09450568931974229	1109.2930682062663	nan	nan
114.58	2.3748922329935573	21.9063	3.39171	0.0949956893197423	1109.01462864972	nan	nan
114.99	2.3878222329935577	21.8745	3.40381	0.0955128893197423	1107.404741759142	nan	nan
115.4	2.4034122329935577	21.839	3.41763	0.09613648931974231	1105.6075409850696	nan	nan
115.81	2.4193522329935577	21.7748	3.43224	0.09677408931974231	1102.3573919795638	nan	nan
116.22	2.4316722329935576	21.6808	3.44321	0.09726688931974231	1097.5986068313157	nan	nan
116.62	2.4415622329935576	21.6555	3.45245	0.09766248931974231	1096.3177848712019	nan	nan
117.03	2.4530922329935576	21.6673	3.4641	0.0981236893197423	1096.9151642834288	nan	nan
117.43	2.4680722329935576	21.6441	3.47795	0.09872288931974231	1095.740655608542	nan	nan
117.84	2.4847922329935574	21.5719	3.49277	0.0993916893197423	1092.0855036116957	nan	nan
118.25	2.4964222329935577	21.4764	3.50293	0.0998568893197423	1087.250780402571	nan	nan
118.65	2.5070622329935577	21.4609	3.51226	0.1002824893197423	1086.4660871068493	nan	nan
119.05	2.5188622329935577	21.454	3.52351	0.1007544893197423	1086.1167720268184	nan	nan
119.46	2.5336822329935575	21.4282	3.53766	0.1013472893197423	1084.810637379746	nan	nan
119.87	2.5497122329935573	21.3711	3.55215	0.10198848931974229	1081.9199285290545	nan	nan
120.27	2.5631522329935574	21.2589	3.56405	0.1025260893197423	1076.2397615755071	nan	nan
120.68	2.5721022329935574	21.2287	3.57246	0.1028840893197423	1074.7108752831975	nan	nan
121.08	2.5888122329935577	21.2603	3.58937	0.10355248931974231	1076.3106370989915	nan	nan
121.49	2.5998422329935575	21.1233	3.59757	0.1039936893197423	1069.3749608722892	nan	nan
121.89	2.6122622329935576	21.1889	3.61089	0.10449048931974231	1072.6959854012796	nan	nan
122.3	2.6289922329935576	21.0477	3.62513	0.1051596893197423	1065.5476826041233	nan	nan
122.71	2.6386622329935574	21.0067	3.63375	0.1055464893197423	1063.4720422735043	nan	nan
123.11	2.6524422329935575	21.0429	3.64828	0.1060976893197423	1065.304680809319	nan	nan
123.52	2.6689522329935573	20.9514	3.66266	0.10675808931974229	1060.6724590958645	nan	nan
123.92	2.6799222329935577	20.8719	3.67151	0.1071968893197423	1056.6477418694205	nan	nan
124.33	2.6911122329935577	20.8681	3.68251	0.10764448931974231	1056.455365448534	nan	nan
124.74	2.7066022329935575	20.8658	3.69847	0.1082640893197423	1056.3389270885236	nan	nan
125.14	2.7215322329935576	20.7314	3.71081	0.1088612893197423	1049.5348768340068	nan	nan
125.54	2.7306922329935577	20.6879	3.71875	0.1092276893197423	1047.3326730685937	nan	nan
125.95	2.7475022329935577	20.7021	3.73479	0.10990008931974231	1048.0515533782232	nan	nan
126.36	2.7594722329935575	20.5954	3.74512	0.1103788893197423	1042.649825981222	nan	nan
126.76	2.7705022329935574	20.5844	3.75617	0.1108200893197423	1042.0929468681288	nan	nan
127.18	2.7844922329935575	20.5705	3.7692	0.1113796893197423	1041.3892541706753	nan	nan
127.6	2.8004622329935573	20.5089	3.78357	0.11201848931974229	1038.2707311373551	nan	nan
128.01	2.8154822329935576	20.4376	3.79766	0.1126192893197423	1034.6611419770345	nan	nan
128.42	2.8269322329935576	20.3352	3.8068	0.1130772893197423	1029.477103687879	nan	nan
128.83	2.8373622329935575	20.3677	3.81736	0.1134944893197423	1031.122428340199	nan	nan
129.27	2.8549622329935573	20.3271	3.83379	0.11419848931974229	1029.067038159147	nan	nan
129.68	2.8688222329935575	20.2009	3.84514	0.1147528893197423	1022.678115970754	nan	nan
130.08	2.8795322329935575	20.1806	3.85503	0.11518128931974231	1021.6504208802278	nan	nan
130.49	2.8934622329935573	20.1781	3.86877	0.11573848931974229	1021.5238574454341	nan	nan
130.89	2.9094922329935575	20.1096	3.8835	0.1163796893197423	1018.0560193320828	nan	nan
131.3	2.9232422329935575	20.0211	3.89552	0.11692968931974229	1013.575673740381	nan	nan
131.7	2.9337122329935577	19.9515	3.90419	0.1173484893197423	1010.0521477157204	nan	nan
132.13	2.9450722329935575	19.9711	3.91522	0.1178028893197423	1011.0444050445041	nan	nan
132.53	2.9642222329935577	19.9106	3.9336	0.11856888931974231	1007.9815699224931	nan	nan
132.94	2.9738322329935576	19.8092	3.94063	0.1189532893197423	1002.848157007255	nan	nan
133.34	2.9899822329935577	19.7904	3.95675	0.11959928931974231	1001.8963999776054	nan	nan
133.75	3.0020422329935577	19.7057	3.96693	0.12008168931974231	997.6084308067901	nan	nan
134.15	3.0130822329935576	19.6904	3.97745	0.12052328931974231	996.8338625858518	nan	nan
134.58	3.0284222329935577	19.6546	3.99211	0.12113688931974231	995.0214741996039	nan	nan
134.98	3.0438822329935578	19.5877	4.00595	0.1217552893197423	991.6346366845208	nan	nan
135.39	3.0575122329935573	19.4714	4.01789	0.1223004893197423	985.7469056979112	nan	nan
135.79	3.0673422329935573	19.4468	4.02641	0.1226936893197423	984.5015214995399	nan	nan
136.2	3.0810522329935575	19.4623	4.0402	0.1232420893197423	985.2862147952617	nan	nan
136.61	3.0989222329935577	19.3746	4.05593	0.1239568893197423	980.846369502694	nan	nan
137.02	3.1113822329935577	19.2558	4.06671	0.12445528931974231	974.8320750812906	nan	nan
137.43	3.1222922329935576	19.2322	4.07667	0.1248916893197423	973.6373162568366	nan	nan
137.84	3.1347922329935574	19.2196	4.08847	0.1253916893197423	972.9994365454756	nan	nan
138.24	3.1504322329935577	19.1637	4.10274	0.12601728931974232	970.1694781434853	nan	nan
138.65	3.1668922329935576	19.0635	4.11724	0.1266756893197423	965.0968156769484	nan	nan
139.05	3.1784322329935577	18.9689	4.1266	0.1271372893197423	960.3076553043495	nan	nan
139.47	3.1889922329935576	18.9561	4.13657	0.1275596893197423	959.6596505182049	nan	nan
139.88	3.2033922329935574	18.9419	4.1501	0.12813568931974229	958.940770208576	nan	nan
140.29	3.2206722329935573	18.8569	4.16634	0.1288268893197423	954.6376134255853	nan	nan
140.69	3.2340922329935577	18.7309	4.17655	0.12936368931974232	948.2588163119758	nan	nan
141.11	3.2446322329935575	18.7002	4.18596	0.12978528931974231	946.7046173327074	nan	nan
141.52	3.2576522329935576	18.707	4.19928	0.1303060893197423	947.0488698753468	nan	nan
141.92	3.2746622329935575	18.6233	4.21459	0.1309864893197423	942.811526078449	nan	nan
142.35	3.2888922329935575	18.4805	4.22583	0.1315556893197423	935.5822226830248	nan	nan
142.75	3.2988122329935576	18.4649	4.23522	0.1319524893197423	934.7924668499114	nan	nan
143.16	3.3129122329935576	18.4651	4.24884	0.1325164893197423	934.8025919246948	nan	nan
143.56	3.3303022329935574	18.3696	4.26408	0.1332120893197423	929.96786871557	nan	nan
143.97	3.3429222329935575	18.2295	4.27353	0.1337168893197423	922.8752538297233	nan	nan
144.37	3.3528822329935575	18.2289	4.28351	0.1341152893197423	922.8448786053727	nan	nan
144.78	3.3678222329935577	18.2102	4.29795	0.13471288931974232	921.8981841131149	nan	nan
145.19	3.3857222329935577	18.109	4.31319	0.1354288893197423	916.7748962726603	nan	nan
145.59	3.3972322329935576	17.9699	4.32262	0.1358892893197423	909.7329067607309	nan	nan
146	3.4077222329935575	18.0093	4.33305	0.1363088893197423	911.7275464930818	nan	nan
146.4	3.4252322329935576	17.9342	4.34915	0.1370092893197423	907.9255809118749	nan	nan
146.82	3.4388122329935573	17.781	4.35923	0.1375524893197423	900.1697736277084	nan	nan
147.24	3.4493722329935577	17.7941	4.36965	0.1379748893197423	900.8329660260281	nan	nan
147.65	3.4686122329935576	17.7064	4.38745	0.13874448931974231	896.3931207334601	nan	nan
148.06	3.4777722329935576	17.5878	4.39378	0.1391108893197423	890.3889513868406	nan	nan
148.46	3.4938022329935574	17.4905	4.40773	0.13975208931974228	885.4631025046642	nan	nan
148.87	3.5080022329935576	17.5541	4.42293	0.1403200893197423	888.6828762858194	nan	nan
149.27	3.5208822329935576	17.379	4.43264	0.14083528931974232	879.818373312859	nan	nan
149.68	3.5327022329935573	17.4052	4.44503	0.14130808931974229	881.1447581094984	nan	nan
150.09	3.5514822329935574	17.3062	4.46063	0.1420592893197423	876.1328460916624	nan	nan
150.49	3.5625022329935576	17.1516	4.46891	0.1425000893197423	868.3061632840112	nan	nan
150.89	3.5746422329935577	17.1994	4.48169	0.14298568931974232	870.7260561572696	nan	nan
151.3	3.5922822329935578	17.0733	4.49677	0.14369128931974232	864.3421965062681	nan	nan
151.71	3.6054122329935576	16.9776	4.50761	0.1442164893197423	859.4973482223598	nan	nan
152.11	3.6178422329935573	16.9329	4.51905	0.1447136893197423	857.2343940082461	nan	nan
152.52	3.6318522329935576	16.8709	4.53151	0.1452740893197423	854.0956208253588	nan	nan
152.93	3.6476722329935574	16.7765	4.54506	0.1459068893197423	849.3165855275435	nan	nan
153.33	3.6595722329935576	16.6749	4.55493	0.1463828893197423	844.1730475375218	nan	nan
153.74	3.6705522329935576	16.6446	4.56528	0.1468220893197423	842.6390987078206	nan	nan
154.14	3.6845522329935574	16.593	4.57804	0.14738208931974228	840.0268294136756	nan	nan
154.54	3.7011922329935576	16.5018	4.59277	0.1480476893197423	835.4097953123962	nan	nan
154.95	3.7186022329935575	16.3487	4.60637	0.1487440893197423	827.6590505656216	nan	nan
155.36	3.7292522329935576	16.3784	4.61639	0.1491700893197423	829.1626241709723	nan	nan