File: original_data/46NTAJ.csv
Specimen name:	AWA_3_10_Rz
Specimen ID:	46NTAJ
Material:	42CrMoS4
Specimen type:	Round Tensile Specimen
Gauge diameter:	5.005	mm
Gauge length:	25	mm
Parallel length:	30	mm
Original cross-section:	19.674243628060164	mm²
Cross-section after fracture:	10.009821052684138	mm²
Yield stress at 0.2% plastic strain:	1082.6551017869408	MPa
Yield stress at 1% plastic strain:	1127.0550004870347	MPa
Ultimate tensile strength:	1182.291956923045	MPa
Uniform elongation:	5.200818538703827	%
Elongation after fracture:	13.533600370421366	%
Reduction of area:	49.12220646486381	%
Slope of linear-elastic region:	212446.85529570933	MPa
Crosshead seperation speed:	0.02995686455964125	mm/s
Strain rate:	0.0009985621519880417	s-1
Test temperature:	RT	Cel
Machine type:	INSTRON 8852TT
Standard:	DIN EN ISO 6892-1
Date:	2022-09-06 00:00:00
Heat treatment batch:	Batch 3
Time	Displacement	Force	Machine Displacement	Engineering Strain	Engineering Stress	True Strain	True Stress
s	mm	kN	mm		MPa		MPa
0	0.0008851069374262132	0.146276	0	3.540427749704853e-05	7.434898274380191	3.5403650780401715e-05	7.4351615015818595
0.440001	0.0009529158374262133	0.151191	1.5258e-05	3.811663349704853e-05	7.684717281042793	3.811590707664957e-05	7.685010196594923
0.880001	0.0007913731374262133	0.14431	-0.0002594	3.165492549704853e-05	7.334970671715151	3.1654424490478696e-05	7.335202859665287
1.3	0.0018019919374262132	0.320385	0.0111542	7.207967749704853e-05	16.28448879951118	7.207707988198535e-05	16.285662580212055
1.7	0.002936896937426213	0.530729	0.0237579	0.00011747587749704852	26.975827382916712	0.00011746897774657588	26.97899639190973
2.11	0.0042456469374262135	0.77173	0.0362396	0.00016982587749704854	39.22539613666921	0.00016981145871524075	39.2320576239883
2.52	0.005615826937426213	1.02611	0.0480041	0.0002246330774970485	52.154991032871145	0.00022460785126503441	52.16670676901369
2.92	0.006908036937426213	1.29954	0.0599289	0.0002763214774970485	66.05285695184469	0.00027628330774879937	66.07110877487052
3.33	0.008417876937426214	1.58571	0.0715103	0.00033671507749704856	80.59827000100778	0.0003366584016974409	80.6254086537373
3.73001	0.010246696937426213	1.90833	0.0842285	0.0004098678774970485	96.9963591016158	0.0004097839046029923	97.03611479344572
4.13001	0.011942606937426213	2.22286	0.0960159	0.0004777042774970485	112.98325069176592	0.00047759021313325634	113.03722327390689
4.54001	0.013841106937426214	2.5536	0.108902	0.0005536442774970485	129.79406213908814	0.0005534910730487228	129.86592187884455
4.96001	0.015932506937426216	2.90171	0.121048	0.0006373002774970486	147.48775377882734	0.0006370972879142056	147.58174776523802
5.37001	0.017683106937426214	3.24041	0.132828	0.0007073242774970485	164.70315511282996	0.0007070742415776919	164.81965365302165
5.77001	0.019942406937426212	3.6043	0.144722	0.0007976962774970485	183.19891062340045	0.0007973782869169492	183.34504771244627
6.19001	0.022116206937426212	3.97484	0.157547	0.0008846482774970485	202.03267150412483	0.0008842572068326832	202.2113993589691
6.60001	0.024451506937426214	4.35876	0.17025	0.0009780602774970486	221.5465093551738	0.0009775822881867794	221.76319519559226
7.02001	0.02666140693742621	4.74727	0.182075	0.0010664562774970485	241.2936471534418	0.0010658880169820005	241.55097627816878
7.44001	0.028869906937426214	5.13572	0.194374	0.0011547962774970486	261.03773527919714	0.0011541300131596096	261.3391806841838
7.86001	0.031423006937426216	5.56266	0.207466	0.0012569202774970487	282.73818832182803	0.0012561310144962483	283.09356768395253
8.29001	0.03372950693742622	5.97027	0.220284	0.0013491802774970487	303.4561385366282	0.001348270951590876	303.86555557382724
8.69001	0.03606440693742621	6.35143	0.231995	0.0014425762774970484	322.8296914520945	0.0014415367639371126	323.29539790665496
9.10001	0.038546506937426214	6.77437	0.245659	0.0015418602774970485	344.326832993881	0.001540672831366681	344.8577368601506
9.50001	0.04080090693742622	7.1626	0.256874	0.0016320362774970487	364.05973898708993	0.0016307059535195295	364.653897688293
9.92001	0.04340780693742621	7.61743	0.270485	0.0017363122774970486	387.1777814693586	0.0017348066299322843	387.85004300489794
10.35	0.04584860693742622	8.0066	0.282097	0.0018339442774970489	406.958465665266	0.0018322646549331655	407.7048048145518
10.75	0.04816000693742622	8.41458	0.293732	0.0019264002774970488	427.6952221938943	0.0019245471480135539	428.51913438861277
11.15	0.050592206937426214	8.82429	0.306038	0.0020236882774970484	448.5199109466377	0.002021643378735218	449.42757543264446
11.56	0.05311590693742622	9.24921	0.318497	0.002124636277497049	470.1176916813422	0.0021223824296812913	471.1165207837816
11.97	0.05564940693742622	9.64916	0.32975	0.002225976277497049	490.4463003720253	0.002223502462724822	491.5380222020396
12.38	0.05825860693742622	10.0845	0.342178	0.0023303442774970486	512.5737075664296	0.002327633236227403	513.7681807726525
12.78	0.06048780693742622	10.4904	0.354584	0.0024195122774970487	533.2047421146186	0.0024165899704226075	534.4948375345846
13.19	0.0631531069374262	10.9188	0.366959	0.002526124277497048	554.9794038550577	0.002522938988726784	556.3813508006468
13.59	0.06547750693742621	11.3107	0.378738	0.0026191002774970484	574.8988481502915	0.0026156764113614986	576.4045658830147
13.99	0.06785690693742621	11.7096	0.390259	0.0027142762774970486	595.1740875720029	0.002710599281727156	596.7895544788805
14.43	0.07080190693742622	12.1854	0.404236	0.0028320762774970486	619.3579905974485	0.0028280735051332286	621.1120596698978
14.85	0.07332750693742622	12.6075	0.416428	0.002933100277497049	640.8124367240578	0.002928807131647609	642.6920038600366
15.28	0.07579480693742621	13.0434	0.429634	0.0030317922774970485	662.9683075285801	0.003027205663392426	664.9782897235705
15.68	0.07833290693742621	13.44	0.44072	0.0031333162774970485	683.126642837306	0.003128417671969306	685.2670946669001
16.08	0.08075080693742621	13.8641	0.453087	0.0032300322774970486	704.6827447143374	0.003224826929190236	706.9588927251599
16.51	0.08324720693742621	14.2803	0.465462	0.0033298882774970484	725.837306377201	0.003324356476311737	728.2542635150764
16.91	0.08566970693742622	14.6851	0.47876	0.003426788277497049	746.412430262658	0.0034209302176201406	748.97022762886
17.33	0.08820330693742622	15.0942	0.490967	0.0035281322774970486	767.2061140115227	0.0035219230192504664	769.9129186658599
17.74	0.09090060693742621	15.538	0.504227	0.0036360242774970486	789.7635250302129	0.0036294299212161125	792.6351243807045
18.14	0.09314680693742622	15.907	0.515747	0.0037258722774970486	808.5190109831121	0.003718948408355078	811.5314495519635
18.57	0.09574590693742621	16.3492	0.528893	0.0038298362774970484	830.9950974014645	0.003822521125814342	834.1776725719149
18.97	0.09815370693742621	16.7477	0.541138	0.003926148277497049	851.2500056730914	0.003918461071519601	854.5921394165842
19.39	0.10088450693742622	17.1584	0.55307	0.004035380277497049	872.1250140222941	0.004027259968863388	875.6443701033915
19.8	0.10310810693742621	17.555	0.565399	0.004124324277497048	892.2833493310198	0.004115842565014929	895.9634152110722
20.2	0.10563310693742621	17.9427	0.577309	0.004225324277497049	911.9893165503668	0.004216422660873956	915.8427671504049
20.63	0.10820510693742622	18.3647	0.59008	0.004328204277497048	933.438679889455	0.004318864541189701	937.4787931765337
21.03	0.11079910693742621	18.7836	0.602806	0.004431964277497049	954.7304768153884	0.004422172045705713	958.961808183272
21.45	0.11332310693742621	19.1747	0.616478	0.004532924277497049	974.6092588104533	0.004522681517683134	979.0270887807885
21.86	0.11568810693742622	19.537	0.627701	0.004627524277497049	993.0241979994381	0.004616850204049732	997.6194415838227
22.26	0.11834710693742621	19.9361	0.639847	0.004733884277497049	1013.3096029961916	0.004722714683825715	1018.1064933940521
22.67	0.12134410693742621	20.317	0.652893	0.004853764277497049	1032.6699406641033	0.004842022742101614	1037.6822771325437
23.07	0.12456410693742621	20.6511	0.664749	0.004982564277497049	1049.6515337721346	0.004970192382928888	1054.8814900081275
23.5	0.1293691069374262	20.92	0.67675	0.005174764277497048	1063.3191494164018	0.005161421196570012	1068.8215753663803
23.9	0.13649210693742622	21.0767	0.68927	0.005459684277497049	1071.2838774619827	0.0054448342278267	1077.132749204498
24.31	0.14628510693742622	21.1306	0.702309	0.005851404277497049	1074.0234999358615	0.005834351301721307	1080.3080456375187
24.71	0.15602910693742622	21.1715	0.713974	0.006241164277497049	1076.1023600319959	0.0062217688698453484	1082.818491640358
25.13	0.16588210693742622	21.2295	0.726357	0.006635284277497049	1079.0503767942403	0.006613367673954151	1086.2101827940103
25.56	0.1753841069374262	21.2917	0.738838	0.007015364277497048	1082.211870632371	0.006990871095202005	1089.8039811302888
25.96	0.18470110693742622	21.3775	0.751312	0.007388044277497049	1086.5729023254844	0.00736088635894627	1094.6005510385935
26.38	0.19343710693742622	21.4422	0.763542	0.007737484277497049	1089.861465851643	0.00770770346641782	1098.29425180832
26.8	0.2024721069374262	21.5077	0.776398	0.008098884277497049	1093.1906916779708	0.00806626431938118	1102.0443165831075
27.21	0.21192810693742622	21.5714	0.788597	0.008477124277497049	1096.4284273289186	0.008441395237165642	1105.7229873687666
27.62	0.2206531069374262	21.6299	0.800003	0.008826124277497049	1099.4018580287682	0.008787401722538423	1109.1053154586411
28.02	0.22994010693742623	21.6718	0.811974	0.00919760427749705	1101.5315460001136	0.009155563899166604	1111.6629972594021
28.42	0.23917610693742622	21.7258	0.824387	0.009567044277497048	1104.2762512615136	0.009521569916151981	1114.840911051921
28.83	0.2487381069374262	21.7711	0.836929	0.009949524277497047	1106.578754008577	0.009900353641453741	1117.5886861865479
29.25	0.2584161069374262	21.8046	0.849617	0.010336644277497049	1108.2814878281492	0.010283586483180222	1119.737399327164
29.66	0.2679301069374262	21.861	0.861557	0.010717204277497047	1111.1481799900555	0.0106601820941975	1123.056582017578
30.06	0.2772591069374262	21.8861	0.872849	0.01109036427749705	1112.4239596578543	0.011029317129639126	1124.7611466014757
30.47	0.2875731069374262	21.932	0.886192	0.011502924277497049	1114.7569591300444	0.011437268652128775	1127.5799240187303
30.88	0.2969941069374262	21.9602	0.897728	0.011879764277497049	1116.1903052109976	0.011809753804333094	1129.4503829257317
31.28	0.3067341069374262	21.9842	0.909302	0.012269364277497048	1117.4101742160642	0.012194705682942354	1131.1200866909026
31.69	0.3170471069374262	22.0206	0.921761	0.012681884277497049	1119.2603088737487	0.012602142658030889	1133.4546385872811
32.09	0.3267071069374262	22.0461	0.933617	0.013068284277497049	1120.5564196916318	0.012983630968568026	1135.2001695331362
32.51	0.3368321069374262	22.0714	0.945801	0.013473284277497048	1121.842364934473	0.013383326698155805	1136.9572660317745
32.92	0.3466891069374262	22.0985	0.957954	0.013867564277497049	1123.219800352694	0.013772289417722234	1138.7961231318423
33.33	0.3571011069374262	22.1313	0.971062	0.014284044277497047	1124.8869546596184	0.014182988503626148	1140.954889727155
33.73	0.3666981069374262	22.155	0.98304	0.014667924277497048	1126.0915753021216	0.014561390763048772	1142.6090012581803
34.13	0.3766301069374262	22.1686	0.994614	0.015065204277497048	1126.7828344049929	0.014952851097892095	1143.758047981681
34.57	0.3872551069374262	22.1967	1.00734	0.015490204277497048	1128.211097698425	0.015371455785472249	1145.6873180699129
34.98	0.3971581069374262	22.2179	1.01901	0.015886324277497046	1129.2886486529005	0.015761457342990132	1147.228894328297
35.38	0.40707810693742624	22.2392	1.03102	0.01628312427749705	1130.371282394897	0.01615197596369358	1148.7772584658467
35.7901	0.4176611069374262	22.2738	1.04386	0.016706444277497047	1132.1299268772016	0.016568426704677043	1151.0437924154623
36.1901	0.4274761069374262	22.277	1.05511	0.017099044277497047	1132.292576077877	0.01695450099455943	1151.6536969713136
36.6001	0.43726810693742624	22.3083	1.06706	0.01749072427749705	1133.8834885719846	0.01733952210386825	1153.7159320334038
37.0001	0.4470331069374262	22.3242	1.07932	0.017881324277497047	1134.6916517878415	0.017723334002112914	1154.9814411684288
37.4401	0.4576931069374262	22.3475	1.09233	0.018307724277497047	1135.8759412802601	0.018142155630227832	1156.6712448266615
37.8501	0.4682951069374262	22.3656	1.10451	0.018731804277497047	1136.7959258215812	0.01855852458152417	1158.0901646075272
38.2501	0.47794610693742623	22.3763	1.11643	0.019117844277497048	1137.3397840863402	0.018937394538776874	1159.083268969105
38.6701	0.48835310693742623	22.4073	1.12892	0.01953412427749705	1138.9154482178844	0.019345782053866778	1161.163164124934
39.0801	0.49826410693742623	22.4203	1.14065	0.01993056427749705	1139.576210595629	0.019734550741275548	1162.2886075100116
39.4901	0.5086391069374262	22.4409	1.15293	0.02034556427749705	1140.6232648249777	0.020141358427661855	1163.8298887758829
39.8901	0.5185141069374262	22.4685	1.16533	0.020740564277497046	1142.0261141808044	0.02052840726348039	1165.7123802085516
40.3101	0.5289071069374262	22.4802	1.17773	0.021156284277497047	1142.6208003207744	0.020935597279996734	1166.794410793742
40.7201	0.5387231069374262	22.4982	1.18948	0.021548924277497047	1143.5357020745744	0.02132002867341685	1168.177666327194
41.1201	0.5482921069374261	22.5101	1.20182	0.021931684277497046	1144.1405537895866	0.021694644417626793	1169.2334831843805
41.5401	0.5585641069374262	22.535	1.21413	0.02234256427749705	1145.4061678823432	0.02209662571326092	1170.997478812096
41.9501	0.5689021069374262	22.5557	1.22709	0.022756084277497046	1146.458304899213	0.02250102674880776	1172.547206706136
42.3601	0.5785841069374261	22.5693	1.23853	0.023143364277497046	1147.1495640020842	0.02287961818437348	1173.6984642425562
42.7701	0.5889441069374262	22.5822	1.25141	0.023557764277497048	1147.8052435923075	0.023284562511497093	1174.8449689573304
43.1701	0.5987581069374261	22.6	1.2632	0.023950324277497045	1148.7099797710653	0.02366801399284086	1176.2219562873793
43.5701	0.6088641069374262	22.6191	1.27543	0.02435456427749705	1149.6807921875973	0.02406272086241562	1177.6807669395337
43.9801	0.6186451069374261	22.645	1.28727	0.024745804277497046	1150.9972341555651	0.024444586007489284	1179.4795864359191
44.3801	0.6281491069374262	22.651	1.29955	0.025125964277497047	1151.3022014068317	0.024815497017816844	1180.2297793919834
44.8001	0.6385751069374261	22.6727	1.31242	0.025543004277497047	1152.405166298913	0.02522223258766685	1181.841056391096
45.2301	0.6493451069374262	22.6894	1.32527	0.02597380427749705	1153.2539918149382	0.025642214529355747	1183.2083852805815
45.6301	0.6590411069374261	22.7083	1.33728	0.026361644277497046	1154.2146386564284	0.026020164444794547	1184.6416343805688
46.0401	0.6686241069374261	22.7244	1.34975	0.026744964277497046	1155.032967447327	0.02639356931608251	1185.9242829010373
46.4401	0.6781721069374261	22.7373	1.36129	0.027126884277497047	1155.6886470375507	0.02676547178377602	1187.0388792265553
46.8601	0.6887011069374261	22.7548	1.37379	0.027548044277497047	1156.5781348537448	0.027175424716033514	1188.4396005230808
47.2801	0.6989381069374262	22.7627	1.38642	0.027957524277497047	1156.9796750679125	0.02757384738311923	1189.3259624221942
47.7201	0.7101171069374261	22.7878	1.39935	0.028404684277497046	1158.2554547357115	0.02800875131705435	1191.1553352401681
48.1301	0.7202591069374261	22.7826	1.41162	0.028810364277497044	1157.9911497846138	0.02840314859267571	1191.3532966400262
48.5401	0.7297461069374261	22.805	1.42364	0.029189844277497046	1159.1296941893427	0.028771933787860096	1192.9645094601522
48.9401	0.7395981069374261	22.8235	1.43579	0.029583924277497044	1160.070009880748	0.029154763616792458	1194.3894332096554
49.3401	0.7494901069374261	22.8381	1.44806	0.029979604277497046	1160.8120968588303	0.029539000373155818	1195.6127841631896
49.7801	0.7601471069374262	22.8463	1.46094	0.030405884277497047	1161.2288854355613	0.02995278702468299	1196.537076545802
50.2001	0.7705831069374262	22.8685	1.47392	0.030823324277497045	1162.357264265248	0.030357826895042433	1198.1849791480001
50.6201	0.7810381069374261	22.8862	1.48575	0.031241524277497046	1163.2569176564846	0.03076343975055138	1199.5988368904161
51.0501	0.7917571069374262	22.8958	1.49883	0.031670284277497046	1163.7448652585115	0.031179124031765672	1200.600995967726
51.4501	0.8019061069374261	22.9099	1.5114	0.03207624427749704	1164.461538298988	0.03157254444422358	1201.8130910532163
51.8701	0.8121541069374262	22.9154	1.52359	0.032486164277497044	1164.7410916126491	0.03196964554776776	1202.5790620555288
52.2901	0.8221771069374262	22.9207	1.53577	0.03288708427749705	1165.010479351268	0.03235787562222649	1203.3242771698606
52.7101	0.8326121069374262	22.9389	1.54884	0.03330448427749705	1165.93554668011	0.032761903992132	1204.7664287630926
53.1201	0.8429041069374261	22.9646	1.56148	0.033716164277497046	1167.2418230730357	0.03316023577051186	1206.5967401313312
53.5201	0.8524501069374262	22.9623	1.57335	0.03409800427749705	1167.12491896005	0.03352955329444284	1206.9215494391233
53.9501	0.8633621069374262	22.9749	1.58616	0.03453448427749705	1167.76535018771	0.03395155189389676	1208.0935243135734
54.3601	0.8730831069374262	22.9872	1.59805	0.034923324277497045	1168.3905330528066	0.03432734114939019	1209.1946145213676
54.7601	0.8831461069374261	23.0015	1.6102	0.03532584427749705	1169.1173716683254	0.03471620255910457	1210.4174298819974
55.1601	0.8935291069374262	23.013	1.62332	0.035741164277497045	1169.7018922332531	0.03511727119073411	1211.508399719261
55.5801	0.9045631069374261	23.0314	1.63577	0.03618252427749705	1170.6371251371377	0.03554331005414793	1212.9937313375517
56.0201	0.9153451069374262	23.0348	1.64891	0.036613804277497046	1170.8099399128555	0.0359594435645003	1213.677745898973
56.4401	0.9252921069374261	23.0451	1.6611	0.03701168427749704	1171.3334670275299	0.03634319656819248	1214.6864914928187
56.8601	0.9360841069374262	23.0554	1.67431	0.037443364277497046	1171.8569941422043	0.036759382984506116	1215.7352624550035
57.2701	0.9459791069374262	23.0608	1.68618	0.03783916427749705	1172.1314646683443	0.03714082502852002	1216.483939714753
57.6801	0.9563951069374261	23.0773	1.69878	0.038255804277497044	1172.9701246093275	0.0375421939561497	1217.8430401197331
58.0901	0.9665021069374261	23.0832	1.71135	0.038660084277497044	1173.2700090730732	0.03793150197515427	1218.628726504098
58.4901	0.9765071069374262	23.0865	1.7233	0.03906028427749705	1173.4377410612697	0.038316731875198407	1219.2725528090668
58.8901	0.9865931069374262	23.0905	1.73531	0.039463724277497045	1173.6410525621143	0.03870493042706127	1219.9572994611772
59.3001	0.9972881069374262	23.1046	1.74783	0.03989152427749705	1174.357725602591	0.03911640413395497	1221.204645323933
59.7001	1.0069151069374263	23.1157	1.75901	0.04027660427749705	1174.9219150174342	0.03948664344212699	1222.2437800455505
60.1201	1.0179451069374263	23.1211	1.77232	0.040717804277497056	1175.196385543574	0.03991067149794193	1223.0478019577595
60.5301	1.0281551069374262	23.1242	1.78387	0.041126204277497046	1175.3539519567285	0.040303015980583876	1223.6917986832643
60.9301	1.0378251069374262	23.131	1.79647	0.04151300427749705	1175.699581508164	0.04067446774511282	1224.506403264364
61.3401	1.0485951069374262	23.1332	1.80882	0.04194380427749705	1175.8114028336283	0.04108801124106683	1225.1294061813314
61.7601	1.0593951069374263	23.1512	1.82163	0.042375804277497056	1176.7263045874286	0.041502535006436345	1226.5910281588078
62.1701	1.0693051069374262	23.1571	1.83354	0.04277220427749705	1177.026189051174	0.04188274782888238	1227.3701936492346
62.5701	1.0799251069374263	23.1671	1.84585	0.04319700427749705	1177.5344678032852	0.04229004051961839	1228.4004292458837
62.9901	1.0904751069374263	23.1688	1.8577	0.043619004277497056	1177.620875191144	0.04269448442269611	1228.9875251833764
63.4001	1.1013351069374262	23.1789	1.87086	0.04405340427749705	1178.1342367307761	0.043110641674657016	1230.0350605546375
63.8201	1.1122251069374263	23.1871	1.88318	0.04448900427749705	1178.5510253075074	0.04352777469961431	1230.9835869136616
64.2301	1.1225451069374264	23.1856	1.89511	0.04490180427749706	1178.4747834946909	0.04392291380301319	1231.3904275691352
64.6301	1.1326951069374263	23.1911	1.9072	0.04530780427749705	1178.7543368083518	0.044311391593416745	1232.1611075917153
65.0501	1.1434551069374264	23.2053	1.91934	0.04573820427749706	1179.4760926363497	0.0447230515992867	1233.423211101775
65.4701	1.1543551069374263	23.2009	1.93189	0.04617420427749705	1179.2524499854208	0.04513989506226372	1233.7034935057866
65.9101	1.1656251069374264	23.2043	1.9453	0.04662500427749706	1179.4252647611384	0.0455707056294023	1234.4159727756146
66.3201	1.1764251069374263	23.2062	1.95759	0.04705700427749705	1179.5218377240396	0.04598337575253033	1235.026601887221
66.7301	1.1868251069374263	23.2181	1.96921	0.04747300427749705	1180.1266894390517	0.04638060090926795	1236.1508488147804
67.1301	1.1973551069374262	23.2207	1.98163	0.04789420427749705	1180.2588419146007	0.046782630686152266	1236.7863999895806
67.5301	1.2080851069374263	23.2159	1.99361	0.048323404277497053	1180.0148681135875	0.04719213016201412	1237.0372036388978
67.9501	1.2189051069374264	23.221	2.00604	0.04875620427749706	1180.2740902771639	0.047604894660204136	1237.8197749261544
68.3601	1.2299251069374262	23.2252	2.01794	0.04919700427749705	1180.4875673530507	0.04802511376203046	1238.5640192536507
68.7801	1.2406751069374262	23.2319	2.03078	0.04962700427749705	1180.828114116965	0.04843486703744924	1239.4290759872365
69.1901	1.2513751069374264	23.2357	2.0425	0.05005500427749705	1181.0212600427674	0.04884254782357204	1240.137284266023
69.5901	1.2618151069374264	23.2364	2.05446	0.05047260427749706	1181.056839555415	0.04924016221702348	1240.6678540475268
70.0101	1.2731551069374263	23.2403	2.06711	0.05092620427749705	1181.2550682687386	0.0496718746603715	1241.4119051792209
70.4501	1.2847951069374264	23.2389	2.08054	0.05139180427749705	1181.183909243443	0.050114814316234955	1241.8870815230107
70.8701	1.2958651069374263	23.2445	2.09263	0.05183460427749705	1181.468545344625	0.05053588168657725	1242.7094998588739
71.2801	1.3071851069374263	23.251	2.10513	0.05228740427749705	1181.7989265334973	0.05096627498615644	1243.5921247798663
71.6801	1.3178251069374263	23.2435	2.1169	0.052713004277497054	1181.417717469414	0.051370645459501416	1243.69379466389
72.1001	1.3292551069374263	23.2511	2.12883	0.05317020427749705	1181.8040093210184	0.05180485758040734	1244.640769912582
72.5101	1.3399451069374262	23.245	2.1412	0.053597804277497045	1181.4939592822307	0.05221078742568231	1244.8194412668845
72.9301	1.3511451069374263	23.25	2.15421	0.05404580427749705	1181.7480986582862	0.05263590674370048	1245.6166251036761
73.3401	1.3628651069374262	23.2585	2.16621	0.05451460427749705	1182.1801355975806	0.0530805703215829	1246.6262178744005
73.7401	1.3738351069374262	23.2456	2.17807	0.054953404277497044	1181.5244560073572	0.05349659939104436	1246.4532471020793
74.1601	1.3856651069374262	23.252	2.19061	0.055426604277497044	1181.8497544087083	0.05394504943891456	1247.355673061777
74.5701	1.3966151069374262	23.2468	2.20251	0.055864604277497044	1181.5854494576106	0.0543599614174315	1247.5942530116085
74.9701	1.4080551069374263	23.251	2.21436	0.056322204277497054	1181.7989265334973	0.054793256432158384	1248.3604470886437
75.4101	1.4205951069374263	23.2577	2.22797	0.05682380427749705	1182.1394732974118	0.055267998837453786	1249.3131353567674
75.8201	1.4323851069374263	23.2554	2.23986	0.05729540427749705	1182.0225691844262	0.05571414208795173	1249.7470301509736
76.2301	1.4438551069374264	23.2514	2.25217	0.05775420427749706	1181.8192576835818	nan	nan
76.6301	1.4551651069374263	23.2406	2.26362	0.05820660427749705	1181.2703166313017	nan	nan
77.0301	1.4663451069374263	23.2455	2.27577	0.05865380427749705	1181.519373219836	nan	nan
77.4401	1.4783251069374264	23.2422	2.28778	0.059133004277497056	1181.3516412316394	nan	nan
77.8601	1.4900351069374262	23.2365	2.30106	0.05960140427749705	1181.0619223429362	nan	nan
78.2701	1.5016751069374263	23.2386	2.3127	0.06006700427749705	1181.1686608808795	nan	nan
78.6701	1.5135251069374263	23.235	2.32464	0.06054100427749705	1180.9856805301195	nan	nan
79.0901	1.5255651069374263	23.2258	2.33697	0.061022604277497054	1180.5180640781773	nan	nan
79.5001	1.5377651069374263	23.2245	2.35004	0.06151060427749705	1180.4519878404028	nan	nan
79.9001	1.5492951069374263	23.2166	2.36195	0.06197180427749705	1180.050447626235	nan	nan
80.3401	1.5619951069374263	23.2096	2.37538	0.06247980427749705	1179.6946524997572	nan	nan
80.7601	1.5746051069374263	23.2219	2.3884	0.06298420427749706	1180.319835364854	nan	nan
81.1801	1.5869551069374264	23.2087	2.40038	0.06347820427749705	1179.6489074120673	nan	nan
81.5901	1.5982751069374264	23.1998	2.41251	0.06393100427749705	1179.1965393226883	nan	nan
82.0001	1.6109051069374263	23.1896	2.42456	0.06443620427749705	1178.678094995535	nan	nan
82.4001	1.6228451069374263	23.191	2.43745	0.06491380427749706	1178.7492540208307	nan	nan
82.8101	1.6347051069374263	23.1755	2.44888	0.06538820427749706	1177.9614219550585	nan	nan
83.2101	1.6468051069374263	23.1757	2.46162	0.06587220427749706	1177.9715875301008	nan	nan
83.6201	1.6596851069374263	23.1577	2.47389	0.06638740427749705	1177.0566857763006	nan	nan
84.0201	1.6710151069374262	23.1452	2.48538	0.06684060427749705	1176.421337336162	nan	nan
84.4501	1.6838251069374264	23.1445	2.49828	0.06735300427749706	1176.385757823514	nan	nan
84.8501	1.6960351069374262	23.1237	2.51008	0.06784140427749705	1175.328538019123	nan	nan
85.2701	1.7086051069374262	23.102	2.52259	0.06834420427749704	1174.225573127042	nan	nan
85.6901	1.7212051069374263	23.101	2.53545	0.06884820427749705	1174.174745251831	nan	nan
86.1101	1.7340251069374262	23.0841	2.54765	0.06936100427749704	1173.315754160763	nan	nan
86.5201	1.7470351069374264	23.0675	2.56031	0.06988140427749706	1172.4720114322588	nan	nan
86.9201	1.7593951069374263	23.0485	2.57278	0.07037580427749705	1171.5062818032477	nan	nan
87.3601	1.7728751069374262	23.0429	2.58539	0.07091500427749704	1171.2216457020654	nan	nan
87.7701	1.7851551069374263	23.0131	2.59737	0.07140620427749705	1169.7069750207745	nan	nan
88.1701	1.7972751069374262	22.993	2.60867	0.07189100427749705	1168.6853347290312	nan	nan
88.5801	1.8104251069374262	22.9729	2.62163	0.07241700427749705	1167.6636944372876	nan	nan
88.9801	1.8227551069374264	22.9461	2.63345	0.07291020427749706	1166.3015073816302	nan	nan
89.4101	1.8355651069374264	22.9356	2.64683	0.07342260427749706	1165.7678146919136	nan	nan
89.8101	1.8480951069374263	22.9108	2.65803	0.07392380427749705	1164.507283386678	nan	nan
90.2301	1.8612951069374262	22.8896	2.67096	0.07445180427749705	1163.4297324322024	nan	nan
90.6501	1.8751351069374262	22.8626	2.68372	0.07500540427749705	1162.0573798015025	nan	nan
91.0601	1.8882051069374264	22.8258	2.69593	0.07552820427749705	1160.1869139937337	nan	nan
91.4701	1.9007251069374262	22.8036	2.70824	0.07602900427749705	1159.058535164047	nan	nan
91.8701	1.9133551069374262	22.777	2.72009	0.07653420427749705	1157.7065136834315	nan	nan
92.2801	1.9262251069374263	22.7443	2.73249	0.07704900427749706	1156.0444421640282	nan	nan
92.6801	1.9385951069374263	22.7147	2.74458	0.07754380427749705	1154.5399370577795	nan	nan
93.1001	1.9519351069374262	22.6853	2.75768	0.07807740427749704	1153.045597526573	nan	nan
93.5301	1.9658051069374263	22.6462	2.77062	0.07863220427749705	1151.0582276058185	nan	nan
93.9301	1.9778951069374262	22.6252	2.78145	0.07911580427749705	1149.9908422263852	nan	nan
94.3301	1.9909451069374262	22.596	2.79403	0.07963780427749705	1148.5066682702209	nan	nan
94.7401	2.0042051069374263	22.5658	2.80724	0.08016820427749705	1146.9716664388452	nan	nan
95.1601	2.017325106937426	22.5301	2.81922	0.08069300427749704	1145.1571112938088	nan	nan
95.5701	2.0305051069374263	22.4999	2.83201	0.08122020427749704	1143.6221094624332	nan	nan
95.9701	2.0428451069374263	22.4718	2.84336	0.08171380427749705	1142.193846169001	nan	nan
96.3901	2.0558151069374264	22.4377	2.85617	0.08223260427749705	1140.4606156243021	nan	nan
96.8001	2.0690151069374263	22.3927	2.86813	0.08276060427749705	1138.1733612398023	nan	nan
97.2201	2.0823051069374263	22.376	2.8812	0.08329220427749705	1137.3245357237768	nan	nan
97.6301	2.095705106937426	22.3272	2.89381	0.08382820427749704	1134.8441354134748	nan	nan
98.0301	2.108645106937426	22.2912	2.90547	0.08434580427749705	1133.0143319058748	nan	nan
98.4401	2.1212751069374263	22.2645	2.91717	0.08485100427749705	1131.657227637738	nan	nan
98.8501	2.1339651069374264	22.2329	2.92966	0.08535860427749706	1130.0510667810672	nan	nan
99.2501	2.147495106937426	22.19	2.94238	0.08589980427749705	1127.8705509345104	nan	nan
99.6601	2.160025106937426	22.161	2.95438	0.08640100427749704	1126.3965425533884	nan	nan
100.06	2.172845106937426	22.1106	2.96638	0.08691380427749705	1123.8348176427485	nan	nan
100.48	2.1856751069374263	22.078	2.97858	0.08742700427749706	1122.1778289108663	nan	nan
100.9	2.1991251069374265	22.0516	2.99126	0.08796500427749705	1120.835973005293	nan	nan
101.32	2.2126651069374264	22.0023	3.00414	0.08850660427749706	1118.3301587573856	nan	nan
101.73	2.2260351069374265	21.9796	3.01679	0.08904140427749706	1117.1763659900932	nan	nan
102.14	2.2390551069374265	21.9319	3.02888	0.08956220427749706	1114.751876342523	nan	nan
102.54	2.2518551069374264	21.9022	3.04048	0.09007420427749706	1113.2422884487532	nan	nan
102.96	2.265365106937426	21.8665	3.05356	0.09061460427749704	1111.4277333037166	nan	nan
103.38	2.2787651069374264	21.8249	3.06547	0.09115060427749705	1109.3132936949344	nan	nan
103.79	2.2918351069374263	21.7878	3.07911	0.09167340427749705	1107.4275795246024	nan	nan
104.19	2.3043751069374263	21.7493	3.09076	0.09217500427749706	1105.4707063289748	nan	nan
104.6	2.317025106937426	21.7073	3.10287	0.09268100427749705	1103.3359355701082	nan	nan
105.02	2.3303551069374264	21.6695	3.11583	0.09321420427749706	1101.4146418871283	nan	nan
105.44	2.344015106937426	21.6355	3.12833	0.09376060427749705	1099.6864941299505	nan	nan
105.86	2.357565106937426	21.5967	3.14088	0.09430260427749705	1097.7143725717592	nan	nan
106.27	2.3708251069374264	21.5482	3.15335	0.09483300427749705	1095.2492206240206	nan	nan
106.68	2.3835451069374263	21.514	3.16588	0.09534180427749706	1093.5109072918008	nan	nan
107.08	2.396345106937426	21.4747	3.17774	0.09585380427749705	1091.513371796004	nan	nan
107.5	2.409625106937426	21.4389	3.19084	0.09638500427749705	1089.6937338634466	nan	nan
107.92	2.423105106937426	21.3979	3.20284	0.09692420427749704	1087.6097909797911	nan	nan
108.34	2.436595106937426	21.3601	3.21568	0.09746380427749704	1085.688497296811	nan	nan
108.76	2.449685106937426	21.3185	3.2281	0.09798740427749704	1083.574057688029	nan	nan
109.17	2.4634951069374265	21.2727	3.24049	0.09853980427749706	1081.2461410033602	nan	nan
109.59	2.4771151069374264	21.2288	3.25338	0.09908460427749706	1079.0147972815923	nan	nan
110	2.489815106937426	21.1896	3.26503	0.09959260427749704	1077.0223445733168	nan	nan
110.4	2.502635106937426	21.1566	3.2775	0.10010540427749705	1075.3450246913505	nan	nan
110.81	2.516105106937426	21.1104	3.28962	0.10064420427749704	1072.996776856597	nan	nan
111.21	2.5288851069374263	21.0754	3.30248	0.10115540427749706	1071.2178012242082	nan	nan
111.65	2.5429951069374264	21.0311	3.31562	0.10171980427749705	1068.966126352356	nan	nan
112.06	2.555505106937426	20.9927	3.32728	0.10222020427749705	1067.0143359442495	nan	nan
112.46	2.5682051069374263	20.9534	3.33918	0.10272820427749706	1065.0168004484528	nan	nan
112.87	2.5819651069374263	20.9053	3.35179	0.10327860427749705	1062.5719796507985	nan	nan
113.27	2.595085106937426	20.8702	3.3634	0.10380340427749704	1060.7879212308887	nan	nan
113.68	2.6079951069374263	20.8301	3.37582	0.10431980427749706	1058.7497234349235	nan	nan
114.09	2.621265106937426	20.776	3.38764	0.10485060427749705	1055.9999353860023	nan	nan
114.49	2.6339851069374265	20.7441	3.40058	0.10535940427749706	1054.3785261667679	nan	nan
114.9	2.646885106937426	20.6971	3.4118	0.10587540427749705	1051.9896160318456	nan	nan
115.3	2.6592451069374263	20.6508	3.42358	0.10636980427749705	1049.6362854095714	nan	nan
115.72	2.6727451069374264	20.6114	3.43706	0.10690980427749705	1047.6336671262538	nan	nan
116.14	2.686185106937426	20.565	3.44933	0.10744740427749705	1045.2752537164583	nan	nan
116.56	2.6997051069374263	20.5238	3.46193	0.10798820427749706	1043.1811452577606	nan	nan
116.97	2.7135451069374263	20.4905	3.47428	0.10854180427749706	1041.4885770132305	nan	nan
117.39	2.7270951069374263	20.4283	3.48742	0.10908380427749705	1038.3270831750997	nan	nan
117.8	2.7398551069374264	20.3904	3.49953	0.10959420427749705	1036.4007067045986	nan	nan
118.21	2.7533551069374265	20.3387	3.51224	0.11013420427749705	1033.7729055561842	nan	nan
118.61	2.7663451069374263	20.2983	3.52403	0.11065380427749705	1031.7194593976556	nan	nan
119.02	2.779195106937426	20.2533	3.5364	0.11116780427749705	1029.4322050131555	nan	nan
119.42	2.7917151069374264	20.2107	3.54835	0.11166860427749706	1027.2669375291623	nan	nan
119.83	2.805175106937426	20.1643	3.56069	0.11220700427749705	1024.9085241193668	nan	nan
120.23	2.8180851069374264	20.1164	3.57293	0.11272340427749705	1022.4738688967545	nan	nan
120.64	2.831065106937426	20.072	3.58485	0.11324260427749705	1020.2171112373815	nan	nan
121.04	2.844215106937426	20.0271	3.59752	0.11376860427749705	1017.9349396404027	nan	nan
121.46	2.8577851069374263	19.9683	3.61008	0.11431140427749704	1014.9462605779894	nan	nan
121.89	2.871735106937426	19.9233	3.62314	0.11486940427749705	1012.6590061934896	nan	nan
122.32	2.885285106937426	19.8688	3.63535	0.11541140427749705	1009.8888869944841	nan	nan
122.73	2.898775106937426	19.8175	3.64767	0.11595100427749705	1007.2814169961542	nan	nan
123.13	2.9117551069374263	19.7789	3.6599	0.11647020427749705	1005.3194610130055	nan	nan
123.56	2.925075106937426	19.7339	3.67316	0.11700300427749705	1003.0322066285054	nan	nan
123.97	2.9388151069374264	19.6741	3.68497	0.11755260427749706	999.9926996908811	nan	nan
124.38	2.9517651069374264	19.6372	3.69708	0.11807060427749706	998.1171510955912	nan	nan
124.8	2.965745106937426	19.5816	3.7094	0.11862980427749704	995.2911212338537	nan	nan
125.21	2.979365106937426	19.5331	3.72213	0.11917460427749704	992.8259692861149	nan	nan
125.61	2.9920751069374263	19.4809	3.73415	0.11968300427749705	990.1727542000948	nan	nan
126.03	3.005685106937426	19.4279	3.74635	0.12022740427749705	987.4788768139061	nan	nan
126.44	3.0188751069374264	19.3709	3.75871	0.12075500427749705	984.5816879268727	nan	nan
126.85	3.0323551069374264	19.3298	3.77164	0.12129420427749706	982.4926622556962	nan	nan
127.25	3.0452951069374263	19.286	3.78384	0.12181180427749705	980.2664013214497	nan	nan
127.67	3.058625106937426	19.2231	3.79603	0.12234500427749705	977.0693279706709	nan	nan
128.08	3.071635106937426	19.1719	3.80809	0.12286540427749705	974.4669407598623	nan	nan
128.49	3.0853751069374264	19.1204	3.82085	0.12341500427749706	971.8493051864901	nan	nan
128.89	3.0985651069374263	19.0662	3.83277	0.12394260427749705	969.0944343500478	nan	nan
129.3	3.111705106937426	19.0162	3.84541	0.12446820427749705	966.5530405894925	nan	nan
129.7	3.1246651069374263	18.9668	3.85712	0.12498660427749705	964.0421435540636	nan	nan
130.11	3.1384351069374263	18.9031	3.8698	0.12553740427749704	960.8044079031159	nan	nan
130.51	3.151275106937426	18.8503	3.88128	0.12605100427749705	958.1206960919694	nan	nan
130.93	3.165105106937426	18.802	3.89452	0.12660420427749705	955.665709719273	nan	nan
131.35	3.178325106937426	18.7418	3.9075	0.12713300427749705	952.6058716315644	nan	nan
131.77	3.1921751069374262	18.6909	3.92042	0.12768700427749705	950.0187327833186	nan	nan
132.18	3.2058851069374263	18.625	3.93243	0.12823540427749705	946.6691758069067	nan	nan
132.59	3.2189751069374264	18.5684	3.94464	0.12875900427749706	943.7923180699579	nan	nan
132.99	3.2321251069374264	18.5157	3.95709	0.12928500427749706	941.1136890463324	nan	nan
133.4	3.245985106937426	18.4622	3.96962	0.12983940427749704	938.3943977225381	nan	nan
133.8	3.2589451069374262	18.4125	3.98126	0.13035780427749705	935.8682523245459	nan	nan
134.21	3.2725051069374262	18.3421	3.99352	0.13090020427749705	932.2899699096838	nan	nan
134.61	3.285095106937426	18.2767	4.00478	0.13140380427749704	928.9658268708773	nan	nan
135.02	3.2984651069374262	18.2372	4.01742	0.13193860427749704	926.9581258000386	nan	nan
135.44	3.3122351069374263	18.171	4.03016	0.13248940427749706	923.5933204610631	nan	nan
135.85	3.3257551069374265	18.1087	4.04253	0.13303020427749707	920.4267438354109	nan	nan
136.25	3.3391551069374263	18.0467	4.05455	0.13356620427749705	917.2754155723222	nan	nan
136.67	3.3529951069374264	17.9812	4.06744	0.13411980427749706	913.9461897459946	nan	nan
137.1	3.3672151069374263	17.9109	4.07959	0.13468860427749704	910.3729901186537	nan	nan
137.5	3.380005106937426	17.8628	4.09189	0.13520020427749704	907.9281693209992	nan	nan
137.92	3.3940151069374265	17.7979	4.1047	0.13576060427749706	904.6294402197982	nan	nan
138.34	3.4083051069374264	17.7271	4.11739	0.13633220427749707	901.0308266548517	nan	nan
138.76	3.4212651069374265	17.6602	4.12949	0.13685060427749707	897.6304418032286	nan	nan
139.19	3.435935106937426	17.6018	4.14311	0.13743740427749704	894.6620938908998	nan	nan
139.59	3.449615106937426	17.5278	4.15474	0.13798460427749704	890.9008311252777	nan	nan
140.01	3.4634051069374263	17.451	4.16695	0.13853620427749705	886.9972503090645	nan	nan
140.42	3.4777251069374264	17.3727	4.17977	0.13910900427749706	883.0174276800345	nan	nan
140.62	3.4855951069374265	17.2811	4.18605	0.13942380427749707	878.361594310697	nan	nan