File: original_data/46NTC3.csv
Specimen name:	AWA_5_10_Rz
Specimen ID:	46NTC3
Material:	42CrMoS4
Specimen type:	Round Tensile Specimen
Gauge diameter:	4.927	mm
Gauge length:	25	mm
Parallel length:	30	mm
Original cross-section:	19.065798812468813	mm²
Cross-section after fracture:	10.297858760526683	mm²
Yield stress at 0.2% plastic strain:	1075.1098155421125	MPa
Yield stress at 1% plastic strain:	1130.3128430826273	MPa
Ultimate tensile strength:	1183.9892061190249	MPa
Uniform elongation:	4.76276246693239	%
Elongation after fracture:	12.40630205775525	%
Reduction of area:	45.98779279160335	%
Slope of linear-elastic region:	211676.3546389107	MPa
Crosshead seperation speed:	0.029804949134021118	mm/s
Strain rate:	0.0009934983044673706	s-1
Test temperature:	RT	Cel
Machine type:	INSTRON 8852TT
Standard:	DIN EN ISO 6892-1
Date:	2022-09-13 00:00:00
Heat treatment batch:	Batch 5
Time	Displacement	Force	Machine Displacement	Engineering Strain	Engineering Stress	True Strain	True Stress
s	mm	kN	mm		MPa		MPa
0	0.001097096639656363	0.175703	0	4.3883865586254514e-05	9.215611773113448	4.388290271763175e-05	9.216016189781795
0.440001	0.001150835339656363	0.184909	0.000457764	4.6033413586254516e-05	9.69846591893499	4.603235408126449e-05	9.69891237242779
0.860001	0.001569999639656363	0.266358	0.00590515	6.279998558625452e-05	13.970461065906399	6.279801374968497e-05	13.971338410659971
1.26	0.002783396639656363	0.457174	0.0176086	0.00011133586558625452	23.978748779254584	0.00011132966820871041	23.981418474005597
1.69	0.0042306966396563625	0.667206	0.0303268	0.0001692278655862545	34.99491453584704	0.00016921354816626608	35.000836650540315
2.1	0.005589996639656363	0.873685	0.0430985	0.00022359986558625453	45.82472565632131	0.00022357487086204053	45.83497205881859
2.51	0.006884496639656363	1.07396	0.0546646	0.0002753798655862545	56.329137350261064	0.000275341955510781	56.344649260533174
2.93	0.008451456639656362	1.29899	0.0680771	0.0003380582655862545	68.13194730401096	0.0003380011367657235	68.15497987194757
3.34	0.010316036639656363	1.55468	0.0810013	0.00041264146558625455	81.54287241210461	0.0004125563525100406	81.57652038248486
3.75001	0.012131196639656363	1.83863	0.0930099	0.00048524786558625454	96.43603281901606	0.0004851301709133388	96.4828281981071
4.17001	0.014152196639656363	2.14163	0.10524	0.0005660878655862545	112.32836457916459	0.0005659276982934148	112.391952303314
4.58001	0.016199696639656362	2.45454	0.118034	0.0006479878655862545	128.7404752427556	0.0006477780120994274	128.82389750852272
4.99001	0.018158496639656362	2.765	0.129959	0.0007263398655862545	145.02408355383054	0.000726076208448244	145.1294203271858
5.40001	0.020412796639656363	3.11715	0.142372	0.0008165118655862545	163.49432985527048	0.0008161787011157952	163.6278249155534
5.80001	0.02242629663965636	3.45407	0.154083	0.0008970518655862544	181.16576357351877	0.0008966497550194747	181.32827865971274
6.21001	0.02466269663965636	3.80971	0.166855	0.0009865078655862543	199.81906016486934	0.000986021586487578	200.01618323941602
6.63001	0.02689199663965636	4.17289	0.178749	0.0010756798655862543	218.86782930233048	0.0010751017365502962	219.10326101953555
7.03001	0.02913999663965636	4.55753	0.190887	0.0011655998655862544	239.0421741479527	0.0011649210814720942	239.32080167400898
7.45001	0.03166849663965636	4.94583	0.203484	0.0012667398655862544	259.4084857732519	0.0012659382275493002	259.7370888436523
7.85001	0.03395179663965636	5.33311	0.215843	0.0013580718655862546	279.72129845995266	0.0013571505200649099	280.1011800855964
8.28001	0.036253696639656365	5.74359	0.228439	0.0014501478655862545	301.25094975007073	0.001449097416585095	301.6878081718566
8.69001	0.03881869663965636	6.16316	0.240974	0.0015527478655862545	323.25737099299323	0.0015515435990729701	323.75930818583765
9.09001	0.04114899663965636	6.54274	0.252876	0.0016459598655862546	343.1663191432149	0.0016446067582168216	343.7311571317456
9.51001	0.04382409663965636	6.95906	0.265053	0.0017529638655862545	365.00227808177937	0.0017514292176223922	365.64211388611335
9.91001	0.046039796639656363	7.34806	0.276337	0.0018415918655862546	385.40530466494033	0.0018398982143107499	386.1150639389651
10.33	0.04875599663965636	7.79681	0.289703	0.0019502398655862542	408.94221515129885	0.0019483406167458217	409.73975056200806
10.75	0.05125519663965636	8.19364	0.302055	0.0020502078655862542	429.75592476311317	0.0020481090576122954	430.6370137403448
11.15	0.053624996639656364	8.58705	0.313797	0.0021449998655862544	450.390255580803	0.0021427026378235334	451.3563426184852
11.58	0.05621379663965636	9.01486	0.326271	0.0022485518655862543	472.82886432769794	0.0022460276560092945	473.892044552685
12.01	0.05895589663965636	9.45913	0.33976	0.0023582358655862543	496.13079908374135	0.002355459591270483	497.3007925281626
12.42	0.06153649663965636	9.87659	0.352165	0.002461459865586254	518.0265509536807	0.002458435435243961	519.3016525181613
12.83	0.06398749663965636	10.2756	0.363892	0.0025594998655862544	538.9546014342644	0.0025562299242264516	540.3340556641925
13.23	0.06664329663965636	10.6749	0.375641	0.0026657318655862543	559.8978623973908	0.0026621851041417873	561.3903999706572
13.64	0.06903399663965636	11.0652	0.387764	0.0027613598655862543	580.369073902295	0.002757554315485082	581.9716817701963
14.05	0.07170879663965636	11.5059	0.400368	0.0028683518655862545	603.4837623732436	0.0028642459938898897	605.214766148898
14.47	0.07420849663965637	11.9198	0.41288	0.0029683398655862545	625.1927924574861	0.0029639430435000527	627.0485771470148
14.87	0.07678459663965637	12.3071	0.424927	0.0030713838655862546	645.5066541429829	0.0030666768018316397	647.4892528656462
15.28	0.07924859663965636	12.6981	0.436951	0.0031699438655862543	666.0145806057488	0.003164930186124974	668.1258094399311
15.69	0.08180369663965636	13.1165	0.449089	0.0032721478655862546	687.9596354191024	0.0032668060394171476	690.2107410717484
16.12	0.08449219663965636	13.5232	0.46151	0.0033796878655862543	709.291025936767	0.003373989555947705	711.6882082102948
16.54	0.08702489663965636	13.9298	0.474266	0.0034809958655862543	730.6171714604515	0.0034749512230003053	733.1604468136316
16.95	0.08978489663965636	14.3569	0.486633	0.0035913958655862544	753.0185407500866	0.003584962202739989	755.7229284240462
17.35	0.09244439663965637	14.7811	0.49881	0.0036977758655862545	775.2678052142945	0.0036909558997098393	778.134571793782
17.76	0.09451659663965636	15.1382	0.509727	0.0037806638655862547	793.9976787177567	0.00377353511790368	796.9995170510442
18.18	0.09721479663965636	15.5542	0.522942	0.0038885918655862544	815.8168536755843	0.003881050835241988	818.9892324565953
18.58	0.09978259663965636	15.9353	0.534439	0.0039913038655862544	835.8055257343058	0.003983359743566711	839.1414795600475
18.99	0.10246109663965636	16.3557	0.547043	0.004098443865586254	857.8554804272643	0.004090068121738165	861.3713529585809
19.4	0.10487809663965636	16.725	0.558731	0.004195123865586254	877.2252431963167	0.004186348866374386	880.9053117495442
19.81	0.10742109663965636	17.1206	0.570747	0.004296843865586254	897.9744393821738	0.004287638791075299	901.8328953434863
20.22	0.10999809663965636	17.5243	0.582581	0.004399923865586255	919.1484800804312	0.004390272500400233	923.1926634139545
20.63	0.11272209663965636	17.9262	0.595192	0.004508883865586255	940.2281108870441	0.0044987493010269775	944.4674902461933
21.04	0.11521609663965636	18.2901	0.606163	0.0046086438655862545	959.3146439811629	0.004598056582661971	963.7357835303138
21.45	0.11818009663965637	18.6947	0.619057	0.004727203865586255	980.5358896252426	0.004716065725107174	985.1710826730251
21.87	0.12143609663965636	19.0445	0.631844	0.004857443865586255	998.8828785681467	0.004845684549901866	1003.7348960790866
22.28	0.12494709663965636	19.355	0.643517	0.004997883865586254	1015.1685848768137	0.004985435902440385	1020.2422795680195
22.69	0.1300230966396564	19.6349	0.657097	0.005200923865586255	1029.849323027525	0.005187445773215096	1035.205490949617
23.11	0.13642609663965638	19.8352	0.669594	0.005457043865586255	1040.35504596996	0.0054422081500048606	1046.0323090916022
23.51	0.14413609663965637	19.999	0.68203	0.005765443865586255	1048.9463461096045	0.005748887300917722	1054.9939873861113
23.92	0.15124809663965638	20.1172	0.693146	0.006049923865586255	1055.1459289942566	0.006031696555145488	1061.529481531755
24.34	0.1595250966396564	20.2474	0.706512	0.006381003865586255	1061.9749111565382	0.006360731453610603	1068.7513771697836
24.75	0.16794709663965637	20.3691	0.718956	0.006717883865586255	1068.3580688304987	0.006695419436598298	1075.535174263764
25.15	0.1759810966396564	20.4805	0.731178	0.007039243865586255	1074.2009921244942	0.007014584045182316	1081.762554868713
25.55	0.18410209663965638	20.5685	0.742401	0.007364083865586255	1078.8165868271115	0.007337101386514961	1086.7610826480918
25.97	0.19269209663965636	20.6564	0.754967	0.0077076838655862545	1083.4269365357486	0.007678131427064911	1091.777648854027
26.39	0.20134209663965638	20.7435	0.76812	0.008053683865586254	1087.9953262925437	0.008021426034191386	1096.7576966977392
26.82	0.20996309663965637	20.8173	0.779495	0.008398523865586255	1091.866131849966	0.0083634524923831	1101.036195616333
27.23	0.2195260966396564	20.8973	0.792503	0.008781043865586256	1096.062127034164	0.008742714716435297	1105.6866966510586
27.63	0.22841709663965637	20.9568	0.805573	0.009136683865586255	1099.1828984524109	0.009095196880395489	1109.2257851060292
28.05	0.2378440966396564	21.0241	0.817612	0.009513763865586255	1102.7127794011171	0.009468793017170655	1113.2037283959037
28.46	0.24663409663965638	21.0647	0.829262	0.009865363865586256	1104.8422469570971	0.009817018864139871	1115.7419177374009
28.86	0.25570509663965635	21.1174	0.841728	0.010228203865586254	1107.6063587846875	0.010176249752944134	1118.935182425157
29.26	0.26510109663965636	21.1668	0.853828	0.010604043865586254	1110.1973858109295	0.010548215317879436	1121.9699675895279
29.67	0.27510609663965635	21.2	0.866257	0.011004243865586254	1111.9387238123716	0.010944137720509428	1124.1747686927915
30.1	0.2846840966396563	21.2471	0.878471	0.011387363865586253	1114.4091159770678	0.011323015879535013	1127.099298075825
30.51	0.2946970966396564	21.2838	0.891266	0.011787883865586254	1116.3340287678184	0.011718947972596627	1129.4932446541354
30.93	0.3043070966396563	21.3186	0.903687	0.012172283865586253	1118.1592866729443	0.012098797349823063	1131.7698389172688
31.35	0.31463609663965636	21.3569	0.91642	0.012585443865586254	1120.168119367379	0.0125069054410538	1134.2659323536966
31.76	0.32413809663965637	21.3764	0.928169	0.012965523865586255	1121.1908931935272	0.012882190991025996	1135.727720477106
32.17	0.33474309663965635	21.4276	0.94165	0.013389723865586255	1123.8763301114138	0.013300873753262795	1138.924723830674
32.59	0.34473209663965637	21.4418	0.953354	0.013789283865586255	1124.6211192566088	0.01369507673548618	1140.1288391112714
32.99	0.35438209663965636	21.4794	0.965347	0.014175283865586254	1126.5932369931816	0.014075754002538514	1142.5630159286095
33.4	0.36417609663965633	21.4953	0.977425	0.014567043865586254	1127.427191036041	0.014461963724211454	1143.8504723831177
33.81	0.37439109663965636	21.5232	0.989891	0.014975643865586254	1128.89054435653	0.014864616014296917	1145.7964071120414
34.23	0.38421709663965636	21.5503	1.00235	0.015368683865586255	1130.311937725177	0.0152517818753198	1147.6833445655734
34.62	0.39340409663965636	21.5648	1.01338	0.015736163865586253	1131.072461852313	0.015613634198620783	1148.871203455873
35.04	0.40365109663965637	21.5973	1.02679	0.016146043865586254	1132.7770848958928	0.016017082788307945	1151.0669533985529
35.46	0.41397009663965634	21.6235	1.03951	0.016558803865586252	1134.1512733187176	0.016423201764344964	1152.931461807507
35.8701	0.42442409663965636	21.64	1.0524	0.016976963865586253	1135.0166973254584	0.016834465743596837	1154.2858347827898
36.2801	0.4344630966396563	21.6638	1.06454	0.017378523865586252	1136.2650058927572	0.01722924434314546	1156.011614415295
36.6901	0.44410209663965633	21.6732	1.07696	0.017764083865586252	1136.7580353269004	0.017608146542085142	1156.9515004013265
37.1001	0.45442309663965635	21.7061	1.0888	0.018176923865586253	1138.4836383464017	0.018013698573397234	1159.1777687628398
37.5101	0.46455909663965633	21.7206	1.10136	0.018582363865586253	1139.2441624735377	0.018411821226179494	1160.414012032366
37.9201	0.47436709663965637	21.7447	1.11401	0.018974683865586255	1140.5082060227771	0.018796909835389286	1162.1489886781662
38.3301	0.4841410966396563	21.7423	1.12511	0.019365643865586254	1140.3823261672512	0.01918051604626133	1162.466564166415
38.7301	0.49396609663965635	21.7699	1.13828	0.019758643865586255	1141.8299445057994	0.019565975635194306	1164.3909557343518
39.1501	0.5045400966396564	21.7953	1.15079	0.020181603865586255	1143.1621729767821	0.019980654453881516	1166.2330191059223
39.5601	0.5142230966396564	21.8169	1.16361	0.020568923865586255	1144.2950916765155	0.020360240296822516	1167.8320102969737
39.9701	0.5247000966396564	21.8306	1.17618	0.020988003865586257	1145.0136558518095	0.020770789716428678	1169.0452068869763
40.3801	0.5346620966396564	21.8535	1.18789	0.021386483865586253	1146.2147594732858	0.0211610021945514	1170.7282629332578
40.7801	0.5446050966396564	21.8723	1.20011	0.021784203865586257	1147.2008183415724	0.02155031866958868	1172.1916748430924
41.1801	0.5541770966396564	21.8817	1.21135	0.022167083865586256	1147.6938477757153	0.021924965567268435	1173.134873551377
41.6201	0.5647640966396564	21.904	1.22443	0.022590563865586256	1148.8634814333107	0.022339176030327108	1174.8169552834697
42.0301	0.5750550966396564	21.9181	1.23714	0.023002203865586254	1149.6030255845253	0.022741641283479896	1176.0464287435152
42.4501	0.5851370966396564	21.9256	1.24933	0.023405483865586257	1149.9964001330438	0.023135775851717028	1176.91262232184
42.8701	0.5949670966396564	21.9462	1.26195	0.023798683865586256	1151.076868892975	0.02351990950192423	1178.4709834007476
43.2801	0.6052790966396564	21.9734	1.27495	0.024211163865586256	1152.5035072556022	0.023922720070471346	1180.4069585254304
43.6901	0.6152600966396564	21.9845	1.28676	0.02461040386558626	1153.0857015874094	0.02431244654674572	1181.4636063951084
44.1101	0.6257990966396564	22.0082	1.30015	0.025031963865586256	1154.328765160728	0.024723796363261146	1183.223881099238
44.5201	0.6357560966396564	22.0216	1.31266	0.025430243865586254	1155.031594354081	0.02511227463270416	1184.4043294709622
44.9301	0.6459620966396564	22.0306	1.32436	0.025838483865586258	1155.5036438123034	0.02551031122329899	1185.3601060695737
45.3401	0.6556280966396564	22.0497	1.33649	0.026225123865586255	1156.5054376625305	0.025887141652062007	1186.8349360164543
45.7401	0.6654160966396564	22.0644	1.34777	0.026616643865586254	1157.2764517776268	0.026268583622798804	1188.0792669486211
46.1501	0.6756540966396564	22.073	1.36066	0.027026163865586254	1157.7275212599282	0.026667406635142086	1189.016454961198
46.5701	0.6853680966396564	22.0866	1.37265	0.027414723865586254	1158.4408404412418	0.027045670139293942	1190.199176196556
46.9701	0.6956210966396564	22.098	1.38486	0.027824843865586257	1159.03876975499	0.027444767170980912	1191.2888425575836
47.3901	0.7057320966396564	22.1339	1.39729	0.028229283865586256	1160.9217225938987	0.02783818094327568	1193.6937114467273
47.8001	0.7154190966396564	22.1281	1.40917	0.028616763865586255	1160.6175129430442	0.028214951975809976	1193.8306302491994
48.2001	0.7253470966396564	22.1427	1.421	0.029013883865586253	1161.3832820641603	0.028600949341633142	1195.0795217334032
48.6201	0.7356160966396564	22.158	1.43373	0.029424643865586256	1162.1857661431382	0.029000047978700486	1196.3826684175535
49.0301	0.7459130966396564	22.1735	1.44634	0.02983652386558626	1162.9987402100764	0.029400074951428955	1197.698579878001
49.4401	0.7558870966396564	22.1912	1.45782	0.030235483865586256	1163.92710414458	0.029787401223025808	1199.119003322662
49.8601	0.7659350966396564	22.1986	1.47025	0.030637403865586256	1164.3152336991184	0.03017744954428654	1199.9868297408127
50.2801	0.7763840966396564	22.2107	1.48286	0.031055363865586254	1164.9498779707283	0.030582902783748176	1201.1278203162794
50.7001	0.7865850966396564	22.2225	1.49541	0.031463403865586256	1165.5687872603974	0.030978574340009887	1202.241548747093
51.1001	0.7961260966396564	22.2334	1.50664	0.03184504386558626	1166.1404916042443	0.03134850449250041	1203.2762867128176
51.5201	0.8064350966396564	22.2485	1.51939	0.03225740386558626	1166.9324856952617	0.03174805830916221	1204.5746981702061
51.9301	0.8168340966396564	22.2537	1.53254	0.03267336386558626	1167.2052253822344	0.03215093864987535	1205.3417464169618
52.3401	0.8267490966396565	22.2794	1.54458	0.033069963865586256	1168.553188835158	0.03253491665870999	1207.1972005649523
52.7501	0.8371650966396564	22.2799	1.55669	0.03348660386558626	1168.5794138050594	0.032938138145264834	1207.7111697206285
53.1601	0.8474240966396565	22.2911	1.5691	0.03389696386558626	1169.166853130847	0.033335123021989446	1208.7980597042642
53.5901	0.8578450966396564	22.3076	1.5818	0.03431380386558625	1170.0322771375877	0.03373821540710608	1210.1805352116924
53.9901	0.8673630966396564	22.3152	1.59359	0.03469452386558625	1170.4308966800866	0.03410623712958454	1211.0384393579734
54.4101	0.8780290966396564	22.327	1.60674	0.03512116386558626	1171.0498059697557	0.03451848640237835	1212.1784380999823
54.8201	0.8883890966396564	22.3413	1.61868	0.035535563865586255	1171.7998401089308	0.034918745894917905	1213.4404081648056
55.2301	0.8988000966396564	22.346	1.63022	0.03595200386558626	1172.0463548260025	0.035320814449030624	1214.1837699053533
55.6501	0.9092530966396564	22.3588	1.64294	0.03637012386558625	1172.717714055474	0.03572434245278885	1215.3696025750387
56.0601	0.9194250966396564	22.3588	1.65447	0.03677700386558626	1172.717714055474	0.03611686645630187	1215.8467579585338
56.4601	0.9302960966396564	22.3795	1.66708	0.03721184386558626	1173.8034278093853	0.03653619369313557	1217.482817693918
56.8801	0.9410920966396564	22.3877	1.67974	0.03764368386558626	1174.2335173157653	0.0369524540066503	1218.4359926259754
57.2901	0.9515080966396564	22.4044	1.69166	0.038060323865586256	1175.1094313104666	0.03735389853250144	1219.834476843648
57.6901	0.9614360966396565	22.3924	1.70294	0.038457443865586256	1174.480032032837	0.03773638503082333	1219.6475319359918
58.1001	0.9724940966396564	22.4171	1.716	0.03889976386558625	1175.7755455459583	0.03816223380159651	1221.512936626627
58.5101	0.9826000966396564	22.4066	1.72731	0.03930400386558626	1175.2248211780322	0.03855126206857872	1221.4158620925466
58.9301	0.9936570966396564	22.4421	1.74076	0.039746283865586256	1177.0867940410199	0.03897672556917959	1223.8716198914071
59.3301	1.0038970966396563	22.4437	1.75292	0.04015588386558625	1177.170713944704	0.03937059025344202	1224.4410444238367
59.7401	1.0147070966396563	22.4413	1.76518	0.04058828386558625	1177.0448340891778	0.03978621079241092	1224.8190639377112
60.1601	1.0257970966396563	22.4608	1.77791	0.041031883865586254	1178.067607915326	0.04021241727675591	1226.405941189117
60.5701	1.0356970966396564	22.4588	1.78922	0.041427883865586254	1177.962708035721	0.04059273675366422	1226.7632103022163
60.9901	1.0466970966396565	22.4656	1.80244	0.04186788386558626	1178.319367626378	0.04101514437658331	1227.65310606673
61.3901	1.0570670966396565	22.4733	1.81434	0.04228268386558626	1178.723232162857	0.04141319623703851	1228.562813953421
61.8101	1.0682170966396565	22.4803	1.82666	0.04272868386558626	1179.0903817414742	0.04184101165685345	1229.471361911859
62.2101	1.0788270966396565	22.4828	1.839	0.04315308386558626	1179.2215065909804	0.04224793789056606	1230.108551161004
62.6201	1.0895070966396565	22.4866	1.85134	0.04358028386558626	1179.4208163622297	0.04265738167727532	1230.8203103362773
63.0301	1.0999970966396564	22.4916	1.86346	0.04399988386558626	1179.683066061242	0.043059378220580806	1231.5889839661354
63.4401	1.1108070966396564	22.4987	1.87547	0.04443228386558626	1180.0554606338399	0.043473468764539835	1232.4880198378578
63.8501	1.1210170966396564	22.5042	1.88715	0.044840683865586255	1180.3439353027534	0.04386441816321528	1233.271364558326
64.2601	1.1328070966396564	22.5144	1.90135	0.04531228386558626	1180.8789246887384	0.044315677009131006	1234.3872457351226
64.6801	1.1435370966396563	22.5117	1.91345	0.045741483865586255	1180.737309851272	0.04472618774075431	1234.7459864593295
65.0901	1.1542170966396563	22.5256	1.92538	0.04616868386558625	1181.4663640145263	0.04513461828670057	1236.0131110725365
65.5101	1.1651270966396563	22.5246	1.938	0.046605083865586254	1181.4139140747236	0.045551672449988014	1236.4738086201467
65.9201	1.1766470966396565	22.5357	1.95041	0.04706588386558626	1181.996108406531	0.045991856236784014	1237.6277999743677
66.3401	1.1873870966396565	22.5269	1.96247	0.04749548386558626	1181.5345489362694	0.04640206145935956	1237.6521040419047
66.7401	1.1980870966396564	22.5424	1.97442	0.04792348386558626	1182.3475230032077	0.046810571654736254	1239.0097354453678
67.1401	1.2089270966396564	22.5331	1.98685	0.04835708386558626	1181.8597385630449	0.04722425674332438	1239.0110290580978
67.5601	1.2191870966396563	22.5398	1.99848	0.04876748386558625	1182.2111531597213	0.04761564980747897	1239.8646164971542
67.9501	1.2301570966396564	22.5448	2.01057	0.04920628386558626	1182.4734028587336	0.04803395818973582	1240.6585247833061
68.3701	1.2416270966396563	22.5474	2.02325	0.049665083865586254	1182.6097727022202	0.04847114554133963	1241.344186243738
68.8001	1.2533170966396565	22.5473	2.03631	0.05013268386558626	1182.6045277082399	0.04891652177224645	1241.891666633848
69.2101	1.2643270966396565	22.5635	2.04852	0.05057308386558626	1183.4542167330399	0.04933580943567548	1243.3051460869615
69.6101	1.2751870966396563	22.5561	2.05975	0.051007483865586255	1183.0660871785017	0.049749212578868496	1243.4113115321813
70.0301	1.2866170966396564	22.5598	2.07309	0.05146468386558625	1183.2601519557707	0.05018412916347197	1244.15626160692
70.4401	1.2977270966396564	22.5564	2.08506	0.05190908386558626	1183.0818221604422	0.050606688399904586	1244.494515686819
70.8501	1.3081070966396564	22.559	2.09654	0.052324283865586255	1183.2181920039286	0.05100132143990439	1245.1292365572679
71.2601	1.3197970966396564	22.5668	2.10955	0.05279188386558625	1183.627301534388	0.051445572464962556	1246.1132165771287
71.6801	1.3312670966396565	22.5737	2.12249	0.05325068386558626	1183.9892061190249	nan	nan
72.0901	1.3426770966396564	22.5596	2.13458	0.05370708386558626	1183.2496619678102	nan	nan
72.5001	1.3542070966396564	22.5611	2.14734	0.05416828386558626	1183.3283368775137	nan	nan
72.9101	1.3650270966396565	22.5669	2.15913	0.05460108386558626	1183.6325465283683	nan	nan
73.3301	1.3768270966396563	22.5543	2.17171	0.05507308386558625	1182.9716772868574	nan	nan
73.7501	1.3883470966396565	22.5614	2.18431	0.05553388386558626	1183.3440718594545	nan	nan
74.1501	1.3990970966396563	22.5609	2.19612	0.055963883865586254	1183.3178468895535	nan	nan
74.5601	1.4110370966396564	22.5652	2.20953	0.056441483865586256	1183.543381630704	nan	nan
74.9601	1.4224370966396565	22.5652	2.22128	0.05689748386558626	1183.543381630704	nan	nan
75.3701	1.4333070966396564	22.5582	2.23232	0.05733228386558625	1183.1762320520868	nan	nan
75.7701	1.4446970966396564	22.5508	2.24496	0.057787883865586254	1182.7881024975484	nan	nan
76.1701	1.4561670966396565	22.5532	2.25735	0.05824668386558626	1182.9139823530745	nan	nan
76.5901	1.4681270966396565	22.5465	2.26998	0.05872508386558626	1182.5625677563978	nan	nan
77.0001	1.4802570966396564	22.5403	2.28259	0.05921028386558626	1182.2373781296224	nan	nan
77.4101	1.4913170966396565	22.5381	2.29403	0.05965268386558626	1182.121988262057	nan	nan
77.8301	1.5033670966396564	22.5288	2.30673	0.06013468386558626	1181.634203821894	nan	nan
78.2401	1.5151570966396564	22.521	2.31934	0.06060628386558625	1181.2250942914347	nan	nan
78.6501	1.5269470966396563	22.5234	2.33138	0.061077883865586255	1181.3509741469607	nan	nan
79.0701	1.5392670966396564	22.5229	2.34397	0.061570683865586257	1181.3247491770596	nan	nan
79.4701	1.5509370966396565	22.5166	2.3559	0.06203748386558626	1180.994314556304	nan	nan
79.9001	1.5633570966396564	22.5034	2.36856	0.06253428386558625	1180.3019753509113	nan	nan
80.3201	1.5753470966396563	22.5028	2.38128	0.06301388386558625	1180.2705053870297	nan	nan
80.7201	1.5878470966396565	22.4891	2.39427	0.06351388386558626	1179.5519412117362	nan	nan
81.1301	1.5998270966396564	22.4805	2.40599	0.06399308386558626	1179.1008717294349	nan	nan
81.5501	1.6121270966396564	22.468	2.41812	0.06448508386558625	1178.4452474819038	nan	nan
81.9501	1.6239470966396563	22.4648	2.43	0.06495788386558625	1178.2774076745359	nan	nan
82.3501	1.6356170966396564	22.4404	2.44117	0.06542468386558625	1176.9976291433559	nan	nan
82.7701	1.6481570966396564	22.4353	2.45441	0.06592628386558626	1176.7301344503633	nan	nan
83.1801	1.6615070966396563	22.4349	2.46752	0.06646028386558625	1176.7091544744421	nan	nan
83.5901	1.6736770966396564	22.4003	2.47916	0.06694708386558626	1174.894386557277	nan	nan
83.9901	1.6857570966396564	22.3939	2.49127	0.06743028386558626	1174.5587069425408	nan	nan
84.4101	1.6986670966396564	22.3632	2.50383	0.06794668386558626	1172.948493790605	nan	nan
84.8201	1.7110270966396564	22.3474	2.51604	0.06844108386558626	1172.119784741726	nan	nan
85.2501	1.7239370966396563	22.3378	2.52942	0.06895748386558626	1171.6162653196225	nan	nan
85.6501	1.7360970966396565	22.3076	2.54082	0.06944388386558625	1170.0322771375877	nan	nan
86.0601	1.7492570966396563	22.2874	2.55421	0.06997028386558625	1168.972788353578	nan	nan
86.4701	1.7610370966396565	22.2656	2.56617	0.07044148386558625	1167.8293796658838	nan	nan
86.8901	1.7741870966396565	22.2428	2.57863	0.07096748386558625	1166.6335210383875	nan	nan
87.3001	1.7875170966396563	22.2258	2.59164	0.07150068386558625	1165.7418720617457	nan	nan
87.7101	1.8002770966396564	22.1974	2.60354	0.07201108386558626	1164.2522937713552	nan	nan
88.1301	1.8132270966396564	22.1756	2.61601	0.07252908386558626	1163.1088850836616	nan	nan
88.5301	1.8262270966396563	22.136	2.62844	0.07304908386558626	1161.0318674674838	nan	nan
88.9401	1.8395370966396565	22.118	2.64117	0.07358148386558626	1160.0877685510393	nan	nan
89.3601	1.8523270966396563	22.0792	2.65332	0.07409308386558626	1158.0527108867034	nan	nan
89.7701	1.8644470966396565	22.0684	2.66535	0.07457788386558625	1157.4862515368368	nan	nan
90.1801	1.8780770966396565	22.03	2.6786	0.07512308386558626	1155.4721738484218	nan	nan
90.6001	1.8910870966396565	21.996	2.69051	0.07564348386558625	1153.688875895138	nan	nan
91.0401	1.9052270966396565	21.9664	2.70409	0.07620908386558627	1152.1363576769847	nan	nan
91.4501	1.9180370966396565	21.929	2.71564	0.07672148386558626	1150.1747299283725	nan	nan
91.8601	1.9308070966396564	21.8994	2.72859	0.07723228386558625	1148.6222117102193	nan	nan
92.2601	1.9437170966396564	21.8707	2.74123	0.07774868386558625	1147.1168984378885	nan	nan
92.6701	1.9569270966396564	21.844	2.75271	0.07827708386558625	1145.7164850451625	nan	nan
93.0901	1.9695970966396563	21.7992	2.76533	0.07878388386558625	1143.3667277420118	nan	nan
93.4901	1.9818670966396563	21.7897	2.77763	0.07927468386558625	1142.8684533138883	nan	nan
93.9001	1.9951070966396565	21.7354	2.78945	0.07980428386558626	1140.020421582614	nan	nan
94.3001	2.0078970966396565	21.7184	2.80198	0.08031588386558626	1139.128772605972	nan	nan
94.7101	2.0212370966396564	21.6755	2.8143	0.08084948386558626	1136.8786701884462	nan	nan
95.1101	2.0340070966396566	21.644	2.82636	0.08136028386558626	1135.2264970846684	nan	nan
95.5401	2.0477170966396563	21.607	2.83913	0.08190868386558625	1133.285849311977	nan	nan
95.9501	2.0608970966396565	21.5665	2.85165	0.08243588386558626	1131.161626749977	nan	nan
96.3701	2.073937096639656	21.5259	2.86422	0.08295748386558625	1129.0321591939967	nan	nan
96.7701	2.0867970966396565	21.5061	2.87598	0.08347188386558627	1127.9936503859076	nan	nan
97.1901	2.0997570966396566	21.4648	2.88857	0.08399028386558627	1125.8274678720657	nan	nan
97.6001	2.1124370966396566	21.44	2.90124	0.08449748386558627	1124.5267093649643	nan	nan
98.0201	2.1259170966396566	21.3936	2.91383	0.08503668386558626	1122.0930321581297	nan	nan
98.4301	2.1392670966396565	21.3646	2.92679	0.08557068386558626	1120.571983903858	nan	nan
98.8401	2.1519270966396564	21.315	2.93819	0.08607708386558625	1117.9704668896557	nan	nan
99.2501	2.1654970966396565	21.2869	2.95102	0.08661988386558626	1116.496623581206	nan	nan
99.6701	2.1792170966396562	21.2433	2.96413	0.08716868386558625	1114.2098062058187	nan	nan
100.07	2.1916070966396566	21.212	2.97563	0.08766428386558626	1112.568123090001	nan	nan
100.48	2.2046470966396563	21.1835	2.98845	0.08818588386558625	1111.0732998056308	nan	nan
100.9	2.2182970966396565	21.127	3.00106	0.08873188386558625	1108.109878206791	nan	nan
101.3	2.2300670966396563	21.0888	3.01252	0.08920268386558625	1106.1062905063368	nan	nan
101.7	2.2427770966396565	21.066	3.02428	0.08971108386558627	1104.9104318788404	nan	nan
102.12	2.2567170966396564	21.0305	3.0375	0.09026868386558626	1103.0484590158528	nan	nan
102.53	2.2700570966396563	20.985	3.05064	0.09080228386558625	1100.6619867548404	nan	nan
102.94	2.2827970966396562	20.9412	3.06218	0.09131188386558625	1098.364679391492	nan	nan
103.36	2.2959570966396563	20.8977	3.07433	0.09183828386558625	1096.0831070100846	nan	nan
103.78	2.3093670966396562	20.859	3.0871	0.09237468386558625	1094.053294339729	nan	nan
104.18	2.3224670966396563	20.8279	3.0994	0.09289868386558625	1092.4221012118724	nan	nan
104.59	2.3353470966396563	20.774	3.11147	0.09341388386558626	1089.595049456519	nan	nan
105.01	2.3481970966396566	20.7557	3.12432	0.09392788386558626	1088.635215558134	nan	nan
105.43	2.362037096639656	20.7045	3.13704	0.09448148386558625	1085.9497786402474	nan	nan
105.84	2.3746970966396566	20.6709	3.14915	0.09498788386558626	1084.1874606628844	nan	nan
106.25	2.3883770966396565	20.6326	3.1618	0.09553508386558626	1082.1786279684497	nan	nan
106.66	2.4014470966396564	20.5851	3.17355	0.09605788386558625	1079.6872558278326	nan	nan
107.08	2.4146770966396565	20.5334	3.18579	0.09658708386558626	1076.9755939400447	nan	nan
107.48	2.4275470966396564	20.5086	3.19773	0.09710188386558626	1075.6748354329436	nan	nan
107.91	2.4413770966396564	20.4575	3.21152	0.09765508386558626	1072.9946435090374	nan	nan
108.33	2.4553570966396565	20.4269	3.22424	0.09821428386558625	1071.3896753510817	nan	nan
108.73	2.4677470966396564	20.3617	3.23582	0.09870988386558625	1067.9699392759605	nan	nan
109.14	2.480727096639656	20.3446	3.24877	0.09922908386558625	1067.0730453053384	nan	nan
109.54	2.4934470966396565	20.3005	3.26035	0.09973788386558625	1064.7600029600494	nan	nan
109.97	2.5071870966396563	20.2544	3.27329	0.10028748386558625	1062.3420607351557	nan	nan
110.38	2.5204470966396566	20.2148	3.28556	0.10081788386558627	1060.2650431189777	nan	nan
110.8	2.5339770966396564	20.1595	3.29797	0.10135908386558626	1057.364561447901	nan	nan
111.21	2.5477370966396564	20.1269	3.3115	0.10190948386558625	1055.6546934103405	nan	nan
111.63	2.560517096639656	20.0667	3.32255	0.10242068386558625	1052.497207034232	nan	nan
112.03	2.574007096639656	20.0413	3.33538	0.10296028386558626	1051.164978563249	nan	nan
112.44	2.5863670966396564	19.9793	3.34731	0.10345468386558626	1047.913082295496	nan	nan
112.86	2.5999170966396563	19.9383	3.36022	0.10399668386558625	1045.7626347635949	nan	nan
113.27	2.6129970966396563	19.9122	3.37309	0.10451988386558625	1044.39369133475	nan	nan
113.69	2.6260770966396563	19.8554	3.38457	0.10504308386558625	1041.4145347539697	nan	nan
114.08	2.6393670966396563	19.8144	3.39727	0.10557468386558626	1039.2640872220684	nan	nan
114.49	2.6525470966396565	19.7711	3.4098	0.10610188386558626	1036.9930048286217	nan	nan
114.89	2.6654770966396564	19.7323	3.422	0.10661908386558626	1034.9579471642858	nan	nan
115.31	2.6792270966396563	19.6714	3.43409	0.10716908386558625	1031.7637458303152	nan	nan
115.72	2.692227096639656	19.633	3.44631	0.10768908386558625	1029.7496681419004	nan	nan
116.14	2.7054870966396565	19.59	3.45921	0.10821948386558626	1027.4943207303943	nan	nan
116.55	2.718597096639656	19.5369	3.47112	0.10874388386558625	1024.709228926883	nan	nan
116.96	2.7314670966396566	19.5045	3.48376	0.10925868386558626	1023.009850877283	nan	nan
117.38	2.7450170966396565	19.4552	3.4963	0.10980068386558627	1020.4240688450212	nan	nan
117.79	2.7586970966396565	19.398	3.50889	0.11034788386558626	1017.4239322883199	nan	nan
118.18	2.7716270966396563	19.3502	3.52087	0.11086508386558626	1014.9168251657619	nan	nan
118.61	2.7846670966396565	19.312	3.53243	0.11138668386558626	1012.9132374653075	nan	nan
119	2.7975070966396562	19.2437	3.54394	0.11190028386558624	1009.3309065767987	nan	nan
119.41	2.8112770966396563	19.2101	3.55718	0.11245108386558625	1007.5685885994359	nan	nan
119.82	2.8240970966396564	19.1559	3.5694	0.11296388386558626	1004.7258018621417	nan	nan
120.23	2.8373170966396564	19.1258	3.58205	0.11349268386558625	1003.1470586740876	nan	nan
120.64	2.8506570966396563	19.0595	3.59438	0.11402628386558625	999.6696276651837	nan	nan
121.04	2.8635470966396563	19.0193	3.60562	0.11454188386558625	997.5611400851245	nan	nan
121.46	2.8771770966396564	18.9527	3.61849	0.11508708386558625	994.0679740942799	nan	nan
121.88	2.8905970966396564	18.916	3.6311	0.11562388386558625	992.1430613035292	nan	nan
122.3	2.9043670966396564	18.8622	3.64397	0.11617468386558626	989.3212545421563	nan	nan
122.71	2.9181470966396565	18.7955	3.65617	0.11672588386558626	985.8228435573316	nan	nan
123.12	2.9313970966396563	18.7618	3.66862	0.11725588386558625	984.0552805859883	nan	nan
123.53	2.9448670966396566	18.6912	3.68108	0.11779468386558627	980.3523148359337	nan	nan
123.93	2.9578570966396565	18.6639	3.69279	0.11831428386558626	978.9204314793265	nan	nan
124.35	2.9718870966396564	18.5953	3.70598	0.11887548386558626	975.3223656088771	nan	nan
124.76	2.9843770966396566	18.5367	3.71691	0.11937508386558626	972.2487991364522	nan	nan
125.18	2.998217096639656	18.4949	3.73026	0.11992868386558625	970.0563916527091	nan	nan
125.58	3.0110770966396565	18.4337	3.74194	0.12044308386558626	966.8464553367978	nan	nan
126	3.0246270966396565	18.3716	3.75411	0.12098508386558626	963.5893140750644	nan	nan
126.42	3.0388370966396563	18.3254	3.76713	0.12155348386558625	961.1661268561901	nan	nan
126.83	3.0527470966396564	18.2729	3.78004	0.12210988386558626	958.4125050165605	nan	nan
127.23	3.0660270966396563	18.2136	3.79179	0.12264108386558625	955.302223586274	nan	nan
127.65	3.0795870966396564	18.1529	3.80407	0.12318348386558625	952.118512240264	nan	nan
128.06	3.0921870966396563	18.1105	3.81596	0.12368748386558626	949.8946347926393	nan	nan
128.48	3.1056770966396563	18.0453	3.82864	0.12422708386558626	946.4748987175183	nan	nan
128.9	3.1198470966396563	17.9851	3.84135	0.12479388386558625	943.3174123414095	nan	nan
129.32	3.1338270966396564	17.9143	3.85365	0.12535308386558625	939.6039566033946	nan	nan
129.74	3.148167096639656	17.8557	3.86674	0.12592668386558625	936.5303901309697	nan	nan
130.17	3.1619970966396562	17.782	3.87903	0.12647988386558626	932.6648295675278	nan	nan
130.59	3.1760570966396564	17.7209	3.89169	0.12704228386558625	929.4601382455969	nan	nan
131	3.1899270966396562	17.6488	3.90359	0.12759708386558624	925.678497585839	nan	nan
131.41	3.2041070966396563	17.5553	3.91588	0.12816428386558626	920.7744282143077	nan	nan
131.63	3.2108370966396564	17.5185	3.92136	0.12843348386558626	918.8442704295769	nan	nan