File: original_data/46NT97.csv
Specimen name:	AWA_1_14_Rz
Specimen ID:	46NT97
Material:	42CrMoS4
Specimen type:	Round Tensile Specimen
Gauge diameter:	4.984	mm
Gauge length:	25	mm
Parallel length:	30	mm
Original cross-section:	19.509491440722446	mm²
Cross-section after fracture:	8.761587751596574	mm²
Yield stress at 0.2% plastic strain:	1135.106772729417	MPa
Yield stress at 1% plastic strain:	1149.360649368586	MPa
Ultimate tensile strength:	1203.2297239179459	MPa
Uniform elongation:	5.393134167293369	%
Elongation after fracture:	14.47568454212653	%
Reduction of area:	55.09063996763963	%
Slope of linear-elastic region:	198468.05669024208	MPa
Crosshead seperation speed:	0.030114542405053273	mm/s
Strain rate:	0.0010038180801684425	s-1
Test temperature:	RT	Cel
Machine type:	INSTRON 8852TT
Standard:	DIN EN ISO 6892-1
Date:	2022-08-18 00:00:00
Heat treatment batch:	Batch 1
Time	Displacement	Force	Machine Displacement	Engineering Strain	Engineering Stress	True Strain	True Stress
s	mm	kN	mm		MPa		MPa
0	0.0011225854602676623	0.183969	0	4.490341841070649e-05	9.429717866248364	4.490241028236636e-05	9.430141292815208
0.440001	0.0010997877602676623	0.177301	-0.000392914	4.399151041070649e-05	9.087935507632814	4.399054281256236e-05	9.08833529964231
0.840001	0.0011196992602676623	0.181542	0.000324249	4.478797041070649e-05	9.305316878791865	4.478696745943122e-05	9.305733645048894
1.25	0.002731525460267662	0.355522	0.0118713	0.00010926101841070648	18.22302754944774	0.00010925504986047726	18.22501861599632
1.67	0.004585015460267662	0.559426	0.0248222	0.00018340061841070647	28.674555751479094	0.00018338380257328695	28.679814682736566
2.09	0.0061218354602676625	0.765719	0.0371895	0.0002448734184107065	39.248537171076826	0.000244843441808645	39.258148094541525
2.52	0.008254405460267662	1.01552	0.0505714	0.00033017621841070646	52.05261260066935	0.0003301217222383219	52.069799135456236
2.92	0.010139325460267662	1.25003	0.0624619	0.0004055730184107065	64.07291567789379	0.0004054907959048138	64.09890192370365
3.33	0.011910285460267664	1.4924	0.0742264	0.00047641141841070657	76.49609957976104	0.00047629797052150294	76.53254319506472
3.73001	0.013842085460267661	1.75849	0.0863762	0.0005536834184107065	90.13510194988876	0.0005535301923034271	90.18500826125518
4.14001	0.015934385460267663	2.04212	0.0990868	0.0006373754184107065	104.6731538956189	0.0006371723809682735	104.7398699908795
4.55001	0.018225685460267663	2.31895	0.111271	0.0007290274184107065	118.86265754522039	0.0007287618070063934	118.949311681596
4.95001	0.020226585460267663	2.61799	0.123951	0.0008090634184107065	134.1905814385008	0.0008087363030294678	134.29915012903797
5.36001	0.022534685460267663	2.91624	0.135941	0.0009013874184107065	149.47801222090752	0.0009009814127323141	149.61274982045248
5.77001	0.024634185460267664	3.21204	0.148418	0.0009853674184107065	164.6398631025031	0.000984882262614286	164.8020938593759
6.18001	0.027015085460267662	3.54536	0.161957	0.0010806034184107065	181.72488046509088	0.0010800199868044552	181.92125299213174
6.59001	0.02918488546026766	3.85608	0.173264	0.0011673954184107064	197.65148731407461	0.001166714542228775	197.8822247548071
6.99001	0.03152198546026766	4.20681	0.185577	0.0012608794184107064	215.6288908289564	0.0012600851775148093	215.90077285941737
7.40001	0.03386308546026766	4.56355	0.198204	0.0013545234184107063	233.9143495290931	0.0013536068791211125	234.23119199343256
7.81001	0.03608338546026766	4.92184	0.210274	0.0014433354184107065	252.27925673790614	0.0014422948110223246	252.6433803244863
8.21001	0.03833548546026766	5.28474	0.221893	0.0015334194184107063	270.88045918865345	0.0015322449313551673	271.29583254484135
8.61001	0.04044518546026766	5.6268	0.233715	0.0016178074184107064	288.41346362597125	0.0016165001777084657	288.88006106699487
9.03001	0.04295358546026766	6.02611	0.246624	0.0017181434184107064	308.88093717407787	0.0017166690984948354	309.41163892335607
9.44001	0.04539218546026766	6.42171	0.259804	0.0018156874184107063	329.15824687238495	0.0018140410505684155	329.7558953598973
9.86001	0.04774498546026766	6.7973	0.271717	0.0019097994184107065	348.40990195223117	0.0019079780700727732	349.0752949803481
10.27	0.05037648546026766	7.17637	0.284199	0.0020150594184107067	367.8399317483314	0.0020130319094247145	368.5811510672685
10.68	0.05278028546026766	7.59021	0.296818	0.0021112114184107062	389.05217099390114	0.0021089859433326102	389.87354237966093
11.08	0.055069885460267656	7.98175	0.309113	0.0022027954184107063	409.1213768565785	0.002200372821587533	410.02258755109204
11.48	0.05767568546026766	8.35138	0.320446	0.0023070274184107064	428.06753960628845	0.002304370316542598	429.05510315709176
11.89	0.05992268546026766	8.74044	0.332848	0.0023969074184107065	448.00962785508347	0.002394039417798217	449.08346545560875
12.31	0.06248948546026766	9.14003	0.344704	0.0024995794184107063	468.49145339185424	0.0024964606657417025	469.66248498645376
12.73	0.06512518546026767	9.54897	0.357689	0.002605007418410707	489.452532835802	0.002601620267679081	490.7275603147992
13.14	0.06753958546026767	9.94678	0.370422	0.0027015834184107067	509.84312073035085	0.0026979407011888316	511.22050445130674
13.55	0.06989498546026766	10.3354	0.382473	0.0027957994184107065	529.7626558541023	0.002791898440426532	531.2437659792348
13.95	0.07236688546026766	10.7146	0.394764	0.0028946754184107065	549.1993490735109	0.0028904939129788644	550.7891029290812
14.35	0.07463498546026767	11.0756	0.406296	0.002985399418410707	567.7031630297517	0.0029809519629889992	569.3979837224907
14.79	0.07738548546026766	11.4945	0.419315	0.0030954194184107066	589.1747632133231	0.0030906384712065804	590.9985062162111
15.2	0.08013188546026767	11.936	0.432404	0.0032052754184107067	611.8047739104984	0.00320014947361256	613.76577671318
15.61	0.08231758546026767	12.3108	0.444115	0.003292703418410707	631.0159358794709	0.003287294340916207	633.0936842086129
16.01	0.08475548546026766	12.6833	0.456268	0.0033902194184107066	650.109206512988	0.0033844855802167145	652.3132193689959
16.42	0.08747348546026766	13.0957	0.469177	0.0034989394184107066	671.2476355311424	0.0034928323711966498	673.5962903426172
16.82	0.09005238546026767	13.4883	0.481339	0.0036020954184107067	691.3711739223338	0.003595623409914049	693.8615588603407
17.22	0.09238528546026767	13.8602	0.493599	0.0036954114184107067	710.4336902944278	0.003688600160743915	713.0590350655655
17.63	0.09468988546026767	14.2469	0.505413	0.003787595418410707	730.2548117816253	0.0037804405397169408	733.0207215610019
18.05	0.09706598546026766	14.6164	0.517506	0.0038826394184107065	749.1943111080269	0.003875121427465967	752.1031624723839
18.46	0.09996318546026767	15.0393	0.53133	0.003998527418410707	770.8709397010857	0.003990554553731416	773.9532882895365
18.86	0.10236958546026767	15.4141	0.5429	0.0040947834184107065	790.0821016700581	0.00408642260882052	793.3173167591597
19.28	0.10497358546026767	15.8344	0.555729	0.004198943418410706	811.62546179695	0.004190152455407726	815.0334311879768
19.69	0.10734158546026766	16.2042	0.56728	0.004293663418410707	830.5803382540632	0.004284471946301446	834.146570668476
20.11	0.10989258546026767	16.6052	0.579941	0.004395703418410707	851.1344363051784	0.004386070532695604	854.8757708563722
20.52	0.11238858546026767	16.9938	0.592133	0.0044955434184107065	871.0529462868824	0.0044854686461965314	874.9688026266496
20.92	0.11522858546026767	17.3662	0.604366	0.004609143418410707	890.1410912101624	0.004598553843663343	894.2438791621706
21.33	0.11734958546026766	17.7379	0.616375	0.004693983418410707	909.193356161782	0.004683001032260471	913.4610946997346
21.73	0.11978058546026767	18.1219	0.629135	0.004791223418410707	928.8760834725756	0.004779782038405677	933.326536316511
22.15	0.12220058546026767	18.4933	0.640888	0.004888023418410707	947.9129712934838	0.0048761158192588555	952.5463920957817
22.56	0.12464658546026766	18.8909	0.654091	0.004985863418410706	968.2927951965343	0.004973475161770919	973.1205708224154
22.97	0.12713258546026768	19.2532	0.666046	0.005085303418410707	986.8632433858586	0.005072416932312753	991.8817424109525
23.37	0.12959758546026767	19.6328	0.677937	0.005183903418410707	1006.3204394462159	0.005170513246720588	1011.5371074122777
23.78	0.13221658546026765	20.0368	0.690845	0.005288663418410706	1027.0283088044466	0.005274727551180921	1032.459915850893
24.18	0.13456058546026767	20.39	0.702038	0.005382423418410707	1045.132317362187	0.005367989945693817	1050.7576620224952
24.6	0.13746758546026766	20.7966	0.714863	0.005498703418410706	1065.9734551865845	0.005483640740340613	1071.834927068554
25.01	0.13979758546026766	21.143	0.726357	0.005591903418410707	1083.728915448196	0.00557632676825989	1089.7890228751212
25.42	0.14240858546026766	21.5037	0.738754	0.005696343418410707	1102.217352273725	0.005680180604484727	1108.4959608340075
25.83	0.14538858546026767	21.8306	0.75095	0.0058155434184107065	1118.9732990390858	0.005798698422768018	1125.4807368436898
26.23	0.14939658546026766	22.1385	0.763241	0.005975863418410706	1134.7553608593807	0.005958078763885428	1141.5365039091857
26.63	0.15517458546026766	22.3584	0.775452	0.006206983418410706	1146.0267976709522	0.006187799439001742	1153.14016700115
27.04	0.16665058546026768	22.3078	0.788383	0.006666023418410707	1143.4331882909364	0.006643903730130589	1151.0553407014718
27.44	0.17908858546026768	22.1945	0.800659	0.007163543418410707	1137.6257585922049	0.0071380071223094785	1145.7751901077827
27.86	0.19064858546026767	22.1479	0.812595	0.007625943418410707	1135.2371776216764	0.007597012900470827	1143.8944321046956
28.29	0.20272458546026767	22.1548	0.825821	0.008108983418410707	1135.5908516280422	0.008076282275441824	1144.799339013993
28.69	0.21400158546026768	22.1488	0.837585	0.008560063418410707	1135.283309013811	0.008523633821031421	1145.0014061368324
29.1	0.22568858546026765	22.1489	0.849972	0.009027543418410706	1135.288434724048	0.008987038737657169	1145.5373003609388
29.5	0.23717658546026768	22.1309	0.861908	0.009487063418410708	1134.3658068813547	0.009442343848040864	1145.127607230915
29.91	0.24835658546026768	22.151	0.874012	0.009934263418410708	1135.396074639029	0.009885243010654625	1146.6753983287226
30.32	0.2597255854602677	22.1818	0.885994	0.010389023418410708	1136.9747933920821	0.010335428394987254	1148.7868511467752
30.72	0.27041858546026765	22.2055	0.898952	0.010816743418410706	1138.1895867182952	0.010758660916289664	1150.501091439334
31.13	0.2814255854602677	22.2175	0.910412	0.011257023418410707	1138.8046719467575	0.011194134650412019	1151.6242228078574
31.53	0.29214458546026767	22.2384	0.92268	0.011685783418410707	1139.8759453863292	0.011618031959788605	1153.1962888079702
31.94	0.30329458546026766	22.2565	0.935162	0.012131783418410707	1140.8036989392601	0.012058783156465974	1154.643682337713
32.34	0.31363958546026766	22.2834	0.9473	0.012545583418410706	1142.182514993063	0.012467539645316387	1156.5118610139587
32.75	0.32444958546026764	22.2958	0.959717	0.012977983418410706	1142.818103062474	0.012894490991277456	1157.6495774542784
33.15	0.3345185854602677	22.3139	0.971062	0.013380743418410708	1143.7458566154048	0.013292011923745862	1159.050026458646
33.56	0.3444235854602677	22.3394	0.98354	0.013776943418410707	1145.0529127258872	0.013682904065602892	1160.828241915598
33.97	0.35499358546026766	22.3524	0.996449	0.014199743418410706	1145.719255056721	0.014099871389606153	1161.988174508059
34.37	0.36498158546026765	22.3749	1.00799	0.014599263418410707	1146.8725398600882	0.014493720167940535	1163.6160341768473
34.77	0.37496958546026765	22.3856	1.01923	0.014998783418410705	1147.420990855467	0.014887413890481252	1164.6309097870462
35.18	0.38545758546026765	22.4083	1.0311	0.015418303418410707	1148.5845270793081	0.015300649189464648	1166.2937518195088
35.59	0.39562158546026766	22.4149	1.04315	0.015824863418410707	1148.9228239549623	0.015700955772218174	1167.1043707223441
36.0001	0.40680058546026765	22.4464	1.05638	0.016272023418410705	1150.537422679676	0.016141052905493565	1169.2589945652774
36.4001	0.41750858546026764	22.4667	1.06829	0.016700343418410705	1151.5779418578247	0.016562426076447315	1170.8096889599171
36.8101	0.42741258546026767	22.481	1.07984	0.017096503418410708	1152.3109184217421	0.016952002848214433	1172.0114059776115
37.2101	0.43775358546026766	22.4959	1.0919	0.017510143418410708	1153.0746492470828	0.01735860724650615	1173.2651517275328
37.6101	0.44868158546026765	22.5161	1.10418	0.017947263418410707	1154.1100427149945	0.017788112678800396	1174.8231596654339
38.0201	0.4587135854602677	22.5288	1.11621	0.018348543418410707	1154.761007915117	0.018182240097662734	1175.9491904067354
38.4301	0.4699255854602677	22.5523	1.12979	0.01879702341841071	1155.9655498208556	0.018622542464411886	1177.6942613317142
38.8401	0.4802455854602677	22.565	1.14167	0.019209823418410706	1156.6165150209783	0.019027644151175967	1178.8349140373489
39.2401	0.49047958546026765	22.5875	1.15342	0.019619183418410707	1157.769799824345	0.0194292079940763	1180.4842978833956
39.6401	0.5012275854602677	22.6082	1.16534	0.020049103418410708	1158.8308218434427	0.01985076674374292	1182.0643408350238
40.0501	0.5120185854602677	22.6159	1.17742	0.020480743418410708	1159.225501531706	0.02027383333804653	1182.9673015926553
40.4601	0.5225775854602677	22.6374	1.19067	0.020903103418410708	1160.3275292327007	0.020687631073030167	1184.5819755754808
40.8601	0.5329125854602677	22.6596	1.20219	0.021316503418410706	1161.4654369053562	0.021092484698235436	1186.2238188615152
41.2701	0.5435325854602676	22.6708	1.21462	0.021741303418410705	1162.039516451921	0.021508331968635865	1187.3037701632852
41.6701	0.5534835854602677	22.6732	1.22633	0.022139343418410708	1162.1625334976134	0.021897826341165105	1187.8920489347272
42.0801	0.5639775854602677	22.6837	1.2383	0.022559103418410706	1162.7007330725178	0.02230841011849057	1188.9302191545626
42.4801	0.5741765854602676	22.7185	1.25077	0.022967063418410705	1164.4844802350585	0.022707290379249987	1191.2292691423722
42.9001	0.5849295854602676	22.7353	1.26387	0.023397183418410704	1165.3455995549057	0.023127665204503118	1192.6114042935296
43.3201	0.5962875854602677	22.7617	1.27681	0.02385150341841071	1166.6987870575228	0.02357149990849307	1194.5263071652812
43.7301	0.6066355854602676	22.7547	1.28893	0.024265423418410707	1166.3399873409198	0.023975695587178807	1194.641720983571
44.1401	0.6172425854602677	22.7935	1.3008	0.024689703418410706	1168.328762912948	0.024389838386605783	1197.1744535644675
44.5401	0.6272305854602677	22.7958	1.31269	0.025089223418410706	1168.446654248403	0.02477965603945452	1197.762073409336
44.9501	0.6382515854602676	22.8119	1.32592	0.025530063418410704	1169.2718935965902	0.02520961396447852	1199.1234791934764
45.3501	0.6486785854602677	22.8446	1.33804	0.025947143418410708	1170.9480008441496	0.025616228285472557	1201.330756557554
45.7601	0.6587205854602677	22.85	1.34949	0.026348823418410706	1171.2247891969578	0.026007672805775487	1202.0851843507735
46.1701	0.6693865854602676	22.8592	1.36198	0.026775463418410705	1171.696354538779	0.026423273564946642	1203.0690674172172
46.5701	0.6797425854602677	22.8876	1.37428	0.027189703418410708	1173.1520562461396	0.026826629972644865	1205.0497127201709
46.9701	0.6902605854602677	22.883	1.38636	0.027610423418410707	1172.916273575229	0.027236129661090767	1205.3009885229856
47.3901	0.7012165854602677	22.914	1.3993	0.028048663418410707	1174.5052437487568	0.027662503868220157	1207.4485460138242
47.8001	0.7113025854602677	22.9126	1.41098	0.02845210341841071	1174.4334838054363	0.028054859671516094	1207.8485867447127
48.2201	0.7219935854602677	22.932	1.42311	0.028879743418410708	1175.4278715914502	0.028470582596154134	1209.3739269298599
48.6301	0.7332285854602677	22.9522	1.43574	0.029329143418410707	1176.4632650593617	0.028907272972933388	1210.9679248867794
49.0301	0.7435905854602677	22.9635	1.44801	0.029743623418410706	1177.0424703161636	0.029309861955968703	1212.0519783007235
49.4401	0.7535275854602677	22.979	1.45964	0.030141103418410708	1177.8369554029275	0.02969578646888418	1213.3382608857532
49.8401	0.7637655854602676	22.9915	1.47117	0.030550623418410704	1178.4776691825757	0.030093245244554402	1214.480896660779
50.2801	0.7750385854602677	23.0095	1.48525	0.03100154341841071	1179.4002970252693	0.030530702044770028	1215.9635265411848
50.6901	0.7860915854602677	23.0333	1.4984	0.031443663418410706	1180.6202160617195	0.030959435865486013	1217.7432407605356
51.1001	0.7964045854602677	23.0533	1.51067	0.031856183418410705	1181.6453581091566	0.03135930019555804	1219.2880693725956
51.5001	0.8066905854602676	23.0551	1.52167	0.032267623418410704	1181.7376208934259	0.03175795845829042	1219.8694854237835
51.9001	0.8172365854602677	23.0558	1.53401	0.032689463418410704	1181.7735008650864	0.03216652869789218	1220.4050424904628
52.3101	0.8281455854602676	23.0809	1.54698	0.03312582341841071	1183.06005413462	0.03258898661004933	1222.2498925812588
52.7201	0.8384795854602677	23.0917	1.55847	0.03353918341841071	1183.613630840236	0.03298901274311373	1223.3110655015178
53.1501	0.8498245854602676	23.1114	1.57198	0.033992983418410706	1184.6233957569616	0.033427990200941296	1224.8922792059893
53.5701	0.8606335854602677	23.1126	1.58484	0.034425343418410706	1184.6849042798078	0.03384604877322081	1225.4680889522472
53.9801	0.8707145854602677	23.1102	1.59656	0.034828583418410705	1184.5618872341154	0.034235793115251184	1225.818499737919
54.3901	0.8815785854602677	23.1368	1.60946	0.035263143418410706	1185.9253261572067	0.03465563925129401	1227.7447810170138
54.7901	0.8919795854602677	23.1379	1.62079	0.035679183418410705	1185.9817089698156	0.03505742736504831	1228.2965678950297
55.2101	0.9032105854602677	23.1695	1.63447	0.03612842341841071	1187.6014334047666	0.03549109698336446	1230.5076008431254
55.6201	0.9136875854602676	23.1805	1.64607	0.036547503418410704	1188.165261530857	0.035895482444964724	1231.5897354882927
56.0301	0.9248385854602676	23.1942	1.659	0.036993543418410706	1188.8674838333513	0.03632570301625302	1232.847904715277
56.4301	0.9350265854602676	23.2025	1.67079	0.03740106341841071	1189.2929177830379	0.03671860801504104	1233.773737624108
56.8301	0.9454925854602677	23.2149	1.68349	0.037819703418410705	1189.928505852449	0.03712207352807851	1234.9312490329012
57.2601	0.9566705854602676	23.2203	1.69545	0.03826682341841071	1190.2052942052571	0.03755280702702777	1235.7506700302672
57.6601	0.9670655854602677	23.2285	1.7073	0.03868262341841071	1190.6256024447061	0.037953201948712836	1236.682124256393
58.0801	0.9781705854602677	23.2527	1.7207	0.03912682341841071	1191.8660243221052	0.03838076763087232	1238.4999557941594
58.4901	0.9888955854602677	23.2549	1.7326	0.039555823418410706	1191.978789947323	0.038793529056233365	1239.1284924809704
58.8901	0.9995275854602677	23.2672	1.7448	0.039981103418410706	1192.6092523064972	0.03920254319821902	1240.2910861607168
59.3001	1.0100825854602677	23.2696	1.75671	0.04040330341841071	1192.7322693521896	0.039608429729966504	1240.9225931277558
59.7001	1.0210225854602677	23.2839	1.76947	0.04084090341841071	1193.465245916107	0.04002894742319156	1242.2074447577966
60.1301	1.0325625854602676	23.2995	1.78241	0.041302503418410706	1194.264856713108	0.0404723366787506	1243.590985039989
60.5301	1.0432325854602678	23.3066	1.79384	0.04172930341841071	1194.6287821399483	0.0408821239941164	1244.4798090622328
60.9401	1.0537025854602677	23.2992	1.80588	0.04214810341841071	1194.2494795823966	0.041284067029982545	1244.5848301552187
61.3501	1.0648225854602678	23.3189	1.81836	0.04259290341841071	1195.259244499122	0.04171078670910879	1246.1688060600356
61.7501	1.0751325854602676	23.3219	1.8302	0.043005303418410704	1195.4130158062376	0.042106260778872695	1246.8221152613023
62.1501	1.0856125854602676	23.3286	1.84184	0.043424503418410705	1195.7564383921292	0.04250809553436453	1247.6815679386748
62.5601	1.0964425854602677	23.3244	1.85389	0.04385770341841071	1195.5411585621673	0.04292318076318597	1247.97484811889
62.9601	1.1073425854602676	23.3417	1.8666	0.044293703418410706	1196.4279064332004	0.043340775009377684	1249.4221292822626
63.3801	1.1186025854602677	23.3529	1.87918	0.04474410341841071	1197.0019859797653	0.04377197831791009	1250.5607666324868
63.7801	1.1295225854602677	23.3638	1.89056	0.04518090341841071	1197.5606883956186	0.04418998375344613	1251.6675621957065
64.1801	1.1401625854602677	23.3615	1.90295	0.04560650341841071	1197.4427970601632	0.04459710310425797	1252.053976077639
64.5901	1.1514325854602676	23.3681	1.91536	0.0460573034184107	1197.7810939358174	0.0450281475249782	1252.947661208055
64.9901	1.1622925854602677	23.3734	1.92694	0.04649170341841071	1198.0527565783884	0.04544333493977322	1253.7522700168402
65.4101	1.1735125854602677	23.3876	1.94011	0.04694050341841071	1198.7806074320688	0.04587210450337319	1255.0519726331584
65.8401	1.1847025854602677	23.3909	1.95265	0.04738810341841071	1198.9497558698959	0.04629954459596775	1255.7657108945368
66.2401	1.1956825854602677	23.3919	1.96452	0.04782730341841071	1199.0010129722677	0.04671878550551792	1256.3459982186741
66.6501	1.2070325854602677	23.3999	1.97658	0.048281303418410706	1199.4110697912424	0.04715196917321386	1257.3201995752338
67.0501	1.2183325854602676	23.4228	1.98888	0.0487333034184107	1200.5848574355582	0.04758305821334393	1259.0933235725147
67.4701	1.2297425854602677	23.4162	2.00248	0.04918970341841071	1200.2465605599039	0.04801815521710694	1259.2863329028132
67.8801	1.2405225854602677	23.4269	2.0141	0.04962090341841071	1200.7950115552828	0.04842905461380549	1260.3795448489768
68.2801	1.2512425854602676	23.4093	2.02522	0.0500497034184107	1199.8928865535383	0.04883749963805355	1259.9471696594037
68.6901	1.2630125854602676	23.4212	2.03845	0.0505205034184107	1200.502846071763	0.04928575888342517	1261.1528542105432
69.1001	1.2737625854602677	23.4242	2.0501	0.0509505034184107	1200.6566173788788	0.049694996036450265	1261.830676466979
69.5001	1.2848025854602676	23.4338	2.06231	0.0513921034184107	1201.1486855616488	0.05011509883516484	1262.878243030921
69.9101	1.2961325854602677	23.433	2.07456	0.051845303418410704	1201.1076798797512	0.05054605352011012	1263.3794719813004
70.3101	1.3072525854602677	23.433	2.08651	0.052290103418410706	1201.1076798797512	0.05096884000540975	1263.9137246773107
70.7201	1.3184325854602676	23.4492	2.0988	0.05273730341841071	1201.9380449381752	0.051393727591457584	1265.325016304211
71.1301	1.3305325854602676	23.4569	2.11152	0.053221303418410706	1202.3327246264387	0.05185337576018262	1266.3224393736668
71.5301	1.3411125854602677	23.4523	2.1224	0.053644503418410705	1202.0969419555279	0.05225510994213038	1266.5828354675223
71.9401	1.3524525854602676	23.4459	2.13502	0.0540981034184107	1201.768896500348	0.05268552303482137	1266.7823145482532
72.3401	1.3640725854602678	23.4542	2.14718	0.05456290341841071	1202.1943304500346	0.05312637152210383	1267.789543592541
72.7601	1.3750525854602678	23.4462	2.15873	0.05500210341841071	1201.7842736310597	0.053542760687569024	1267.884936535935
73.1801	1.3871225854602676	23.4611	2.17146	0.055484903418410704	1202.5480044564003	0.05400028542651116	1269.2712643396662
73.5901	1.3986325854602677	23.4553	2.18389	0.05594530341841071	1202.2507132626438	0.054436387937317476	1269.5109942011231
74.0001	1.4105825854602676	23.4625	2.19649	0.0564233034184107	1202.619764399721	0.05488896047282254	1270.475544263424
74.4001	1.4218825854602677	23.4637	2.20874	0.05687530341841071	1202.6812729225671	0.05531672776082438	1271.0841352356786
74.8001	1.4327325854602677	23.4528	2.22001	0.05730930341841071	1202.1225705067138	0.05572728794056727	1271.015377646003
75.2101	1.4446425854602676	23.4558	2.23276	0.0577857034184107	1202.2763418138295	0.056177764166473236	1271.7507259288552
75.6301	1.4565025854602676	23.4549	2.2454	0.0582601034184107	1202.2302104216947	0.056626147662156956	1272.2722668136003
76.0401	1.4679525854602677	23.4707	2.25705	0.05871810341841071	1203.0400726391701	0.05705883988890413	1273.6803040408893
76.4501	1.4797925854602676	23.4652	2.26966	0.05919170341841071	1202.758158576125	0.05750607329456197	1273.9514627826366
76.8501	1.4912125854602676	23.4613	2.282	0.0596485034184107	1202.558255876875	0.057937252583687475	1274.2890561133847
77.2601	1.5026825854602677	23.4744	2.29409	0.06010730341841071	1203.2297239179459	nan	nan
77.6601	1.5139225854602676	23.4564	2.30575	0.060556903418410704	1202.3070960752525	nan	nan
78.0801	1.5265125854602677	23.4657	2.31928	0.06106050341841071	1202.7837871273107	nan	nan
78.4901	1.5380725854602677	23.4697	2.33127	0.061522903418410706	1202.9888155367983	nan	nan
78.8901	1.5496425854602676	23.4386	2.34259	0.061985703418410705	1201.3947196530337	nan	nan
79.3001	1.5613225854602677	23.4517	2.35493	0.062452903418410706	1202.0661876941047	nan	nan
79.7001	1.5736425854602676	23.4501	2.36779	0.0629457034184107	1201.9841763303098	nan	nan
80.1101	1.5852125854602677	23.4521	2.37995	0.0634085034184107	1202.0866905350538	nan	nan
80.5101	1.5972525854602677	23.4425	2.39161	0.06389010341841071	1201.5946223522837	nan	nan
80.9501	1.6094825854602677	23.4339	2.40419	0.06437930341841071	1201.1538112718858	nan	nan
81.3601	1.6219625854602677	23.4351	2.41755	0.06487850341841071	1201.2153197947318	nan	nan
81.7601	1.6331525854602678	23.4368	2.42949	0.0653261034184107	1201.3024568687642	nan	nan
82.1801	1.6461625854602677	23.4429	2.44196	0.06584650341841071	1201.6151251932326	nan	nan
82.5901	1.6582125854602676	23.4173	2.45405	0.0663285034184107	1200.302943372513	nan	nan
82.9901	1.6698325854602676	23.4015	2.46615	0.06679330341841071	1199.4930811550375	nan	nan
83.4301	1.6826725854602678	23.4073	2.47889	0.06730690341841071	1199.7903723487943	nan	nan
83.8401	1.6953425854602677	23.4026	2.49148	0.06781370341841071	1199.5494639676465	nan	nan
84.2401	1.7072525854602676	23.3984	2.50378	0.0682901034184107	1199.3341841376848	nan	nan
84.6501	1.7191925854602677	23.3926	2.51563	0.06876770341841071	1199.0368929439283	nan	nan
85.0501	1.7310325854602677	23.3829	2.5275	0.06924130341841071	1198.539699050921	nan	nan
85.4901	1.7443225854602677	23.3609	2.54022	0.0697729034184107	1197.4120427987402	nan	nan
85.9001	1.7571425854602676	23.3619	2.5532	0.0702857034184107	1197.463299901112	nan	nan
86.3101	1.7690625854602677	23.3366	2.56444	0.07076250341841071	1196.1664952111041	nan	nan
86.7101	1.7809825854602677	23.3205	2.57632	0.07123930341841071	1195.341255862917	nan	nan
87.1101	1.7935025854602678	23.3309	2.58887	0.07174010341841071	1195.8743297275844	nan	nan
87.5301	1.8061725854602677	23.2996	2.6012	0.07224690341841071	1194.2699824233453	nan	nan
87.9401	1.8190925854602678	23.281	2.61412	0.07276370341841071	1193.3166003192287	nan	nan
88.3601	1.8325425854602677	23.2718	2.62677	0.0733017034184107	1192.8450349774075	nan	nan
88.7701	1.8447225854602676	23.2447	2.63843	0.0737889034184107	1191.4559675031303	nan	nan
89.1801	1.8575325854602676	23.2225	2.65073	0.07430130341841071	1190.318059830475	nan	nan
89.5801	1.8695825854602677	23.1929	2.66215	0.0747833034184107	1188.800849600268	nan	nan
89.9801	1.8820225854602677	23.1827	2.67429	0.0752809034184107	1188.278027156075	nan	nan
90.3901	1.8948425854602677	23.1551	2.68675	0.07579370341841071	1186.8633311306119	nan	nan
90.7901	1.9073925854602676	23.1356	2.69855	0.0762957034184107	1185.8638176343604	nan	nan
91.2201	1.9212325854602677	23.1038	2.71092	0.0768493034184107	1184.2338417789354	nan	nan
91.6201	1.9340825854602677	23.0893	2.72421	0.0773633034184107	1183.4906137945436	nan	nan
92.0301	1.9466225854602677	23.0694	2.73593	0.07786490341841071	1182.4705974573435	nan	nan
92.4301	1.9593725854602677	23.0109	2.74743	0.0783749034184107	1179.4720569685896	nan	nan
92.8501	1.9726025854602676	22.9887	2.75998	0.0789041034184107	1178.3341492959346	nan	nan
93.2901	1.9863325854602676	22.9695	2.77348	0.0794533034184107	1177.350012930395	nan	nan
93.7001	1.9995225854602676	22.9133	2.78489	0.0799809034184107	1174.4693637770965	nan	nan
94.1001	2.0123825854602675	22.9246	2.79747	0.0804953034184107	1175.0485690338985	nan	nan
94.5101	2.0249425854602676	22.8537	2.80866	0.0809977034184107	1171.4144404757337	nan	nan
94.9201	2.0385625854602676	22.8339	2.82173	0.0815425034184107	1170.399549848771	nan	nan
95.3201	2.0512925854602675	22.7958	2.8335	0.0820517034184107	1168.446654248403	nan	nan
95.7201	2.0638725854602673	22.7646	2.84531	0.0825549034184107	1166.8474326544012	nan	nan
96.1601	2.0780625854602675	22.7348	2.8587	0.0831225034184107	1165.3199710037197	nan	nan
96.5701	2.0909825854602673	22.7137	2.87047	0.0836393034184107	1164.2384461436736	nan	nan
96.9701	2.1034125854602674	22.664	2.88244	0.0841365034184107	1161.6909681557922	nan	nan
97.3901	2.1165625854602674	22.6272	2.89436	0.0846625034184107	1159.8047067885077	nan	nan
97.8001	2.1304425854602673	22.5917	2.90715	0.08521770341841069	1157.985079654307	nan	nan
98.2001	2.1428425854602673	22.5446	2.91882	0.0857137034184107	1155.5708701325923	nan	nan
98.6401	2.1572525854602675	22.5081	2.93198	0.0862901034184107	1153.6999858960194	nan	nan
99.0501	2.1703825854602674	22.4935	2.94435	0.08681530341841069	1152.9516322013903	nan	nan
99.4501	2.1830525854602674	22.4459	2.95627	0.0873221034184107	1150.51179412849	nan	nan
99.8601	2.1964925854602675	22.4087	2.96874	0.0878597034184107	1148.6050299202568	nan	nan
100.26	2.2091525854602674	22.3607	2.97991	0.0883661034184107	1146.1446890064078	nan	nan
100.7	2.2236125854602675	22.3329	2.99419	0.0889445034184107	1144.7197415604699	nan	nan
101.11	2.2362425854602677	22.2857	3.00583	0.0894497034184107	1142.3004063285182	nan	nan
101.52	2.2497725854602675	22.2461	3.01842	0.0899909034184107	1140.2706250745928	nan	nan
101.92	2.2625925854602675	22.2002	3.03011	0.0905037034184107	1137.9179240757244	nan	nan
102.32	2.2755525854602676	22.1777	3.04218	0.0910221034184107	1136.7646392723577	nan	nan
102.73	2.2886225854602675	22.1416	3.05466	0.0915449034184107	1134.9142578767337	nan	nan
103.13	2.3016525854602676	22.0947	3.06617	0.0920661034184107	1132.5102997754934	nan	nan
103.57	2.3158725854602675	22.0525	3.07904	0.0926349034184107	1130.347250055401	nan	nan
103.99	2.3291125854602672	22.0042	3.09204	0.09316450341841069	1127.8715320108404	nan	nan
104.42	2.3435825854602674	21.9673	3.10487	0.0937433034184107	1125.9801449333188	nan	nan
104.82	2.3564625854602674	21.9142	3.11655	0.0942585034184107	1123.258392797373	nan	nan
105.22	2.3690725854602674	21.8751	3.12878	0.0947629034184107	1121.2542400946334	nan	nan
105.63	2.3822125854602674	21.8475	3.14104	0.09528850341841069	1119.8395440691702	nan	nan
106.05	2.3957125854602674	21.7901	3.15335	0.0958285034184107	1116.8973863930253	nan	nan
106.46	2.4093525854602675	21.7529	3.16568	0.0963741034184107	1114.9906221847923	nan	nan
106.86	2.4223425854602674	21.727	3.1784	0.09689370341841069	1113.6630632333613	nan	nan
107.27	2.4356625854602676	21.6649	3.18996	0.0974265034184107	1110.4799971760688	nan	nan
107.68	2.4491125854602673	21.6328	3.20296	0.09796450341841069	1108.834644189932	nan	nan
108.08	2.4621125854602672	21.5897	3.21426	0.0984845034184107	1106.625463077705	nan	nan
108.5	2.4760525854602675	21.5608	3.22719	0.0990421034184107	1105.1441328191584	nan	nan
108.91	2.4886725854602676	21.5189	3.23892	0.0995469034184107	1102.9964602297773	nan	nan
109.31	2.5015125854602673	21.4774	3.25041	0.10006050341841069	1100.8692904813454	nan	nan
109.72	2.5150025854602673	21.4191	3.26302	0.10060010341841069	1097.881001413066	nan	nan
110.13	2.5279125854602675	21.3807	3.2753	0.1011165034184107	1095.9127286819867	nan	nan
110.53	2.5414225854602672	21.3565	3.28785	0.10165690341841069	1094.6723068045878	nan	nan
110.93	2.5548725854602674	21.2985	3.29984	0.1021949034184107	1091.69939486702	nan	nan
111.37	2.5683025854602675	21.2594	3.31253	0.1027321034184107	1089.6952421642802	nan	nan
111.78	2.5824825854602675	21.2206	3.32563	0.1032993034184107	1087.7064665922524	nan	nan
112.18	2.5953725854602676	21.1732	3.33619	0.10381490341841071	1085.2768799398261	nan	nan
112.6	2.6088025854602677	21.1229	3.34867	0.10435210341841071	1082.6986476905217	nan	nan
113.01	2.6221925854602675	21.086	3.36145	0.1048877034184107	1080.8072606130002	nan	nan
113.41	2.6351025854602677	21.0254	3.3728	0.10540410341841071	1077.7010802092657	nan	nan
113.85	2.6492625854602676	20.9807	3.38584	0.1059705034184107	1075.4098877332433	nan	nan
114.26	2.6632125854602675	20.961	3.39869	0.1065285034184107	1074.400122816518	nan	nan
114.67	2.6762625854602673	20.892	3.41085	0.10705050341841069	1070.8633827528597	nan	nan
115.07	2.6900625854602676	20.8667	3.42379	0.1076025034184107	1069.5665780628517	nan	nan
115.47	2.7028425854602673	20.7982	3.43465	0.1081137034184107	1066.0554665503794	nan	nan
115.9	2.7168325854602675	20.7668	3.44755	0.1086733034184107	1064.445993535903	nan	nan
116.3	2.7299225854602676	20.7318	3.46027	0.1091969034184107	1062.651994952888	nan	nan
116.71	2.7430625854602675	20.6856	3.47239	0.1097225034184107	1060.2839168233083	nan	nan
117.12	2.7566025854602674	20.6125	3.48418	0.1102641034184107	1056.5370226399252	nan	nan
117.52	2.7696625854602672	20.5855	3.49589	0.11078650341841069	1055.153080875885	nan	nan
117.92	2.7827425854602676	20.5472	3.50888	0.1113097034184107	1053.1899338550431	nan	nan
118.33	2.7963325854602674	20.4884	3.52066	0.1118533034184107	1050.1760162355777	nan	nan
118.73	2.8090325854602676	20.4492	3.53187	0.1123613034184107	1048.166737822601	nan	nan
119.15	2.8229725854602674	20.3939	3.54481	0.1129189034184107	1045.332220061437	nan	nan
119.55	2.8365625854602676	20.3632	3.55739	0.1134625034184107	1043.7586270186212	nan	nan
119.95	2.8493825854602672	20.2924	3.5685	0.1139753034184107	1040.1296241706937	nan	nan
120.36	2.8625425854602673	20.2684	3.58078	0.11450170341841069	1038.899453713769	nan	nan
120.76	2.8760925854602672	20.1935	3.59312	0.11504370341841069	1035.0602967461168	nan	nan
121.18	2.8897825854602672	20.1459	3.60581	0.11559130341841069	1032.6204586732165	nan	nan
121.61	2.9044225854602677	20.1057	3.61844	0.1161769034184107	1030.5599231578674	nan	nan
122.02	2.9174825854602675	20.0497	3.63053	0.1166993034184107	1027.6895254250437	nan	nan
122.42	2.9307025854602675	20.0061	3.64245	0.1172281034184107	1025.4547157616305	nan	nan
122.82	2.9436625854602676	19.9634	3.65447	0.1177465034184107	1023.2660374903523	nan	nan
123.23	2.9575425854602675	19.9058	3.66674	0.1183017034184107	1020.3136283937332	nan	nan
123.63	2.9709725854602675	19.8569	3.67934	0.1188389034184107	1017.8071560877493	nan	nan
124.05	2.9843725854602674	19.7979	3.69194	0.1193749034184107	1014.7829870478096	nan	nan
124.46	2.9975325854602675	19.7601	3.70373	0.1199013034184107	1012.8454685781536	nan	nan
124.87	3.0116125854602673	19.706	3.71662	0.1204645034184107	1010.072459339836	nan	nan
125.27	3.0250625854602675	19.642	3.72858	0.1210025034184107	1006.792004788037	nan	nan
125.68	3.0383225854602673	19.5918	3.74055	0.12153290341841069	1004.2188982489697	nan	nan
126.08	3.0508625854602673	19.5281	3.75211	0.1220345034184107	1000.9538208278823	nan	nan
126.5	3.0648325854602674	19.4938	3.76498	0.1225933034184107	999.1957022165276	nan	nan
126.91	3.0788525854602673	19.443	3.77773	0.1231541034184107	996.5918414160373	nan	nan
127.32	3.0915425854602674	19.3892	3.78896	0.12366170341841069	993.8342093084311	nan	nan
127.72	3.1054225854602673	19.3182	3.80141	0.12421690341841068	990.1949550400294	nan	nan
128.14	3.1198425854602676	19.2771	3.81502	0.1247937034184107	988.0882881325462	nan	nan
128.56	3.1333025854602674	19.2132	3.82712	0.1253321034184107	984.8129592909843	nan	nan
128.98	3.1472025854602674	19.1709	3.84007	0.1258881034184107	982.6447838606546	nan	nan
129.39	3.1608025854602673	19.0968	3.85209	0.12643210341841069	978.8466325749001	nan	nan
129.8	3.1741925854602675	19.0353	3.86443	0.1269677034184107	975.6943207790307	nan	nan
130.2	3.1873525854602676	18.9882	3.87622	0.1274941034184107	973.2801112573162	nan	nan
130.62	3.2013125854602675	18.9362	3.88884	0.1280525034184107	970.6147419339796	nan	nan
131.03	3.2154025854602675	18.8782	3.90146	0.1286161034184107	967.6418299964118	nan	nan
131.43	3.2286425854602676	18.8084	3.91331	0.1291457034184107	964.064084250856	nan	nan
131.86	3.2427225854602675	18.7582	3.92604	0.1297089034184107	961.4909777117887	nan	nan
132.26	3.2559225854602674	18.6905	3.93774	0.13023690341841068	958.020871881214	nan	nan
132.68	3.2700025854602672	18.641	3.95091	0.1308001034184107	955.4836453138071	nan	nan
133.09	3.2842525854602673	18.561	3.96378	0.13137010341841068	951.3830771240584	nan	nan
133.49	3.2971625854602675	18.513	3.97562	0.1318865034184107	948.9227362102092	nan	nan
133.91	3.3110025854602676	18.4536	3.98748	0.1324401034184107	945.878064329321	nan	nan
134.33	3.3254725854602674	18.401	4.00046	0.1330189034184107	943.1819407445611	nan	nan
134.76	3.3393325854602676	18.3367	4.01291	0.1335733034184107	939.8861090620507	nan	nan
135.16	3.3526825854602675	18.2713	4.02527	0.1341073034184107	936.533894566931	nan	nan
135.57	3.3667025854602675	18.2008	4.03706	0.1346681034184107	932.9202688497151	nan	nan
135.97	3.3801225854602674	18.1491	4.04964	0.1352049034184107	930.2702766570901	nan	nan
136.39	3.3943825854602676	18.0822	4.06198	0.1357753034184107	926.8411765084128	nan	nan
136.82	3.4089025854602673	18.026	4.07536	0.1363561034184107	923.9605273551143	nan	nan
137.22	3.4220425854602676	17.9409	4.08691	0.13688170341841072	919.5985479432691	nan	nan
137.64	3.4361525854602673	17.8807	4.09975	0.13744610341841068	916.5128703804834	nan	nan
138.05	3.4499225854602673	17.8267	4.11208	0.1379969034184107	913.7449868524028	nan	nan
138.45	3.4636725854602672	17.7625	4.12486	0.1385469034184107	910.4542808801297	nan	nan
138.88	3.4779725854602677	17.6825	4.13778	0.1391189034184107	906.353712690381	nan	nan
139.3	3.4917325854602677	17.6299	4.14994	0.13966930341841072	903.6575891056212	nan	nan
139.7	3.5055025854602673	17.5444	4.16148	0.14022010341841068	899.2751068528273	nan	nan
140.11	3.5196325854602675	17.4798	4.17453	0.1407853034184107	895.9638980396054	nan	nan
140.51	3.5332825854602676	17.4249	4.187	0.14133130341841071	893.1498831193904	nan	nan
140.93	3.5472225854602675	17.3422	4.19904	0.1418889034184107	888.9109207532376	nan	nan
141.34	3.5613025854602673	17.2826	4.21175	0.1424521034184107	885.8559974518749	nan	nan
141.74	3.5749325854602674	17.205	4.2236	0.1429973034184107	881.8784463078188	nan	nan
142.16	3.5893525854602673	17.1441	4.23637	0.1435741034184107	878.7568887733728	nan	nan
142.56	3.6021325854602675	17.0619	4.24716	0.1440853034184107	874.5435549584059	nan	nan
142.96	3.6155825854602672	16.9983	4.25927	0.14462330341841068	871.2836032475557	nan	nan
143.44	3.6325225854602676	16.916	4.27447	0.1453009034184107	867.0651437223518	nan	nan
143.77	3.6439625854602675	16.8526	4.28406	0.1457585034184107	863.815443431976	nan	nan
144.18	3.6572725854602672	16.7745	4.2961	0.1462909034184107	859.8122637367339	nan	nan
144.59	3.6718425854602676	16.697	4.30866	0.14687370341841072	855.8398383029149	nan	nan
144.99	3.6862725854602676	16.631	4.32168	0.14745090341841072	852.4568695463722	nan	nan
145.4	3.6998425854602672	16.5524	4.33362	0.1479937034184107	848.4280612999441	nan	nan
145.8	3.7132825854602673	16.4694	4.34527	0.1485313034184107	844.1737218030801	nan	nan
146.21	3.7275125854602673	16.3797	4.35749	0.1491005034184107	839.5759597203242	nan	nan