File: original_data/46NTB5.csv
Specimen name:	AWA_4_07_Rz
Specimen ID:	46NTB5
Material:	42CrMoS4
Specimen type:	Round Tensile Specimen
Gauge diameter:	5.004	mm
Gauge length:	25	mm
Parallel length:	30	mm
Original cross-section:	19.666382577842715	mm²
Cross-section after fracture:	12.65764193127713	mm²
Yield stress at 0.2% plastic strain:	1081.7008049995425	MPa
Yield stress at 1% plastic strain:	1149.5965567820929	MPa
Ultimate tensile strength:	1199.4630891894092	MPa
Uniform elongation:	4.83482971454074	%
Elongation after fracture:	11.064687025085208	%
Reduction of area:	35.63817910499736	%
Slope of linear-elastic region:	209730.3983377688	MPa
Crosshead seperation speed:	0.029925920907495355	mm/s
Strain rate:	0.0009975306969165119	s-1
Test temperature:	RT	Cel
Machine type:	INSTRON 8852TT
Standard:	DIN EN ISO 6892-1
Date:	2022-09-13 00:00:00
Heat treatment batch:	Batch 4
Time	Displacement	Force	Machine Displacement	Engineering Strain	Engineering Stress	True Strain	True Stress
s	mm	kN	mm		MPa		MPa
0	0.0008294550809135292	0.137024	0	3.317820323654117e-05	6.967422679673646	3.31776528521501e-05	6.967653846239347
0.450001	0.0007112290809135292	0.134312	-0.000205994	2.8449163236541168e-05	6.8295223825922955	2.844875856675192e-05	6.829716676789386
0.850001	0.0008030739809135292	0.147112	0.000366211	3.2122959236541166e-05	7.4803792419733	3.212244330539609e-05	7.480619533890764
1.28	0.0013454140809135292	0.246822	0.00758362	5.381656323654117e-05	12.550452480167042	5.381511517715532e-05	12.551127902386588
1.68	0.0024287950809135294	0.41736	0.0185852	9.715180323654118e-05	21.22200147119186	9.714708430563591e-05	21.224063226903073
2.1	0.003815255080913529	0.647819	0.0318298	0.00015261020323654117	32.94042498338614	0.00015259855948409213	32.94545202833755
2.51	0.005221525080913529	0.886117	0.0447388	0.00020886100323654115	45.05744747375915	0.00020883919481370133	45.06685821744179
2.92	0.006838775080913529	1.13543	0.0569916	0.00027355100323654116	57.73456280054477	0.0002735135949827629	57.75035614812028
3.32	0.00853796508091353	1.4075	0.0685883	0.00034151860323654114	71.56883043584085	0.0003414602990325922	71.59327252284658
3.73001	0.010623105080913528	1.70933	0.081604	0.0004249242032365411	86.91634026919776	0.00042483394851404487	86.95327312583488
4.13001	0.012371555080913529	1.99401	0.0930252	0.0004948622032365412	101.3918036073684	0.000494739799316867	101.44197857869167
4.55001	0.014607255080913529	2.32117	0.105705	0.0005842902032365412	118.02729814760976	0.0005841195721778069	118.09626034163188
4.97001	0.01684215508091353	2.65482	0.118851	0.0006736862032365413	134.99279745483412	0.000673459378553108	135.08374024001574
5.40001	0.01904785508091353	3.02675	0.132278	0.0007619142032365411	153.9047655571448	0.0007616240939594778	154.02202778396855
5.80001	0.02113195508091353	3.3612	0.14373	0.0008452782032365412	170.9109434180805	0.0008449211568042108	171.05541071324637
6.21001	0.02340815508091353	3.73327	0.155594	0.0009363262032365412	189.83003026729065	0.000935888123292864	190.0077730987911
6.61001	0.02559175508091353	4.09008	0.168777	0.0010236702032365413	207.97317370445754	0.001023146610187899	208.1860696454513
7.03001	0.027981555080913528	4.47434	0.180756	0.001119262203236541	227.51210001584383	0.0011186362962892088	227.76674571017054
7.46001	0.03037125508091353	4.88713	0.19371	0.0012148502032365413	248.50172524895981	0.001214112869834382	248.80361762038314
7.86001	0.032771355080913535	5.27989	0.205833	0.0013108542032365415	268.4728611935288	0.001309995783958562	268.82478997207926
8.26001	0.03518015508091353	5.6864	0.218552	0.0014072062032365411	289.14315978001093	0.0014062170164718562	289.5500438280768
8.67001	0.037454855080913535	6.07415	0.230156	0.0014981942032365413	308.8595462819629	0.0014970730299851095	309.3222778638168
9.08001	0.040064355080913536	6.49934	0.242828	0.0016025742032365414	330.4796890976042	0.0016012914514852213	331.0093073220457
9.48001	0.042351455080913536	6.88984	0.254929	0.0016940582032365413	350.33590812793875	0.001692624905137184	350.9293975469912
9.90001	0.04494385508091353	7.3075	0.267143	0.0017977542032365412	371.5731640567723	0.0017961401772740677	372.2411612742653
10.33	0.047360955080913536	7.72822	0.279755	0.0018944382032365413	392.96601545355173	0.0018926460182824988	393.71046528580064
10.73	0.049821255080913535	8.13328	0.291313	0.0019928502032365413	413.5625841614321	0.001990867111502969	414.3867524413292
11.15	0.05232245508091353	8.55316	0.304604	0.002092898203236541	434.9127230768146	0.0020907111427901828	435.8229511335067
11.57	0.05480585508091353	8.99672	0.317047	0.0021922342032365412	457.4669471820519	0.002189834763950993	458.46982187051464
11.98	0.057459755080913534	9.40845	0.329178	0.0022983902032365413	478.40267333150047	0.0022957529446665003	479.50222934908777
12.39	0.05983455508091353	9.81899	0.341621	0.002393382203236541	499.27789013230336	0.002390522625849983	500.4728529490155
12.79	0.062272855080913535	10.2155	0.352821	0.002490914203236541	519.4397067973941	0.002487817018600547	520.7335865407808
13.19	0.06465075508091353	10.6142	0.365097	0.0025860302032365413	539.7128810032697	0.002582692180710108	541.1085948146199
13.6	0.06714145508091353	11.0344	0.377609	0.002685658203236541	561.0792913401366	0.0026820582672689016	562.5861585415904
14.02	0.06958625508091354	11.4515	0.390686	0.0027834502032365416	582.2880722813724	0.0027795835790948545	583.9088421345061
14.44	0.07217555508091353	11.867	0.402962	0.0028870222032365413	603.4154961151854	0.0028828627583189375	605.1575700502469
14.87	0.07461455508091354	12.2656	0.41568	0.0029845822032365417	623.6835855018469	0.002980137179934731	625.5450204315865
15.27	0.07709775508091353	12.6775	0.427223	0.0030839102032365413	644.6279558439591	0.003079164706120456	646.6159305742777
15.68	0.07958905508091353	13.0897	0.439804	0.0031835622032365413	665.5875806437131	0.003178505398677748	667.7065201083941
16.08	0.08190545508091353	13.4819	0.45105	0.0032762182032365413	685.530241600684	0.0032708630935298936	687.7761882570854
16.49	0.08433815508091354	13.8693	0.462822	0.0033735262032365417	705.2288312353874	0.003367848629094815	707.6079391768378
16.89	0.08677915508091354	14.2733	0.475365	0.0034711662032365417	725.7715008596002	0.003465155610991714	728.2907743646563
17.31	0.08914315508091353	14.6644	0.487206	0.0035657262032365413	745.6582288052183	0.003559384073286249	748.3170418903279
17.72	0.09173845508091354	15.0808	0.500114	0.0036695382032365413	766.8314160119564	0.003662821873461954	769.6453331884543
18.12	0.09406915508091353	15.4654	0.512054	0.003762766203236541	786.3876307086701	0.003755704706783179	789.3466235081439
18.55	0.09660775508091353	15.8861	0.524834	0.003864310203236541	807.7794651416067	0.003856862936097772	810.9009755707183
18.95	0.09892245508091353	16.2669	0.537132	0.003956898203236542	827.1424567081915	0.003949090271557702	830.4153752089608
19.36	0.10136045508091353	16.6768	0.54937	0.004054418203236541	847.9851306660254	0.004046221198340679	851.4232170158716
19.76	0.10384845508091353	17.063	0.561241	0.0041539382032365416	867.6227024701616	0.004145334420097779	871.2267535599477
20.18	0.10632045508091353	17.461	0.573822	0.0042528182032365415	887.8602829415397	0.004243800529878197	891.6361913147643
20.61	0.10900345508091354	17.8426	0.585472	0.004360138203236542	907.263953061836	0.0043506603405348366	911.2197492840003
21.01	0.11148845508091353	18.2192	0.597511	0.004459538203236541	926.4133822214364	0.004449623927210791	930.5447580914426
21.43	0.11436745508091353	18.5885	0.60968	0.004574698203236542	945.1916195784211	0.004564266075203367	949.5155859822208
21.84	0.11768245508091353	18.9691	0.622688	0.004707298203236541	964.5444415065783	0.004696253521892857	969.084839823024
22.24	0.12113545508091353	19.2909	0.634262	0.004845418203236541	980.9073897369537	0.00483371694754948	985.6602962588744
22.67	0.12531245508091352	19.6177	0.647141	0.00501249820323654	997.524578928025	0.0049999774568332345	1002.524669087586
23.07	0.12978645508091352	19.8865	0.658714	0.005191458203236541	1011.192572975026	0.005178029041999624	1016.4421369530492
23.47	0.13493445508091353	20.1317	0.671135	0.005397378203236542	1023.6605496875433	0.005382864557835874	1029.18563282594
23.88	0.14111745508091353	20.3751	0.683716	0.005644698203236541	1036.0369996542101	0.0056288265932883845	1041.8851158446448
24.3	0.14749445508091352	20.5879	0.69561	0.005899778203236541	1046.8574949414196	0.005882442662293246	1053.03372197197
24.72	0.15446445508091353	20.7778	0.708374	0.006178578203236541	1056.5135666286424	0.006159569048446768	1063.041318322838
25.14	0.16157645508091353	20.948	0.720963	0.006463058203236541	1065.1679289307242	0.006442262198333481	1072.0521712516245
25.57	0.16857245508091354	21.071	0.73243	0.006742898203236541	1071.4222565638386	0.006720266543504154	1078.6467477725305
25.97	0.17611845508091353	21.2209	0.745094	0.007044738203236541	1079.0444005654958	0.007020039962313212	1086.6459858771482
26.39	0.18390145508091355	21.3451	0.757874	0.007356058203236542	1085.359746029177	0.007329134362031463	1093.3437154924177
26.81	0.19242745508091352	21.4559	0.770119	0.007697098203236541	1090.993725718194	0.007667626676412265	1099.3912115641617
27.23	0.20103745508091353	21.5763	0.783073	0.008041498203236542	1097.1158480517463	0.008009337654180219	1105.9383031725968
27.66	0.21015745508091352	21.6978	0.796501	0.00840629820323654	1103.293903396652	0.008371162051151782	1112.568520954417
28.06	0.21834445508091352	21.7705	0.808319	0.008733778203236542	1106.9905669651675	0.008695859385469488	1116.6587770501164
28.47	0.22698845508091353	21.8438	0.820427	0.009079538203236542	1110.7177394489668	0.009038567009185353	1120.802543597306
28.87	0.23590345508091354	21.9181	0.832001	0.009436138203236542	1114.4957601249048	0.009391895950722104	1125.0122961443647
29.29	0.24491045508091353	21.9981	0.84536	0.009796418203236542	1118.5636154960362	0.00974874440057511	1129.5215324603596
29.71	0.25371745508091353	22.0567	0.857567	0.010148698203236542	1121.5433195553896	0.010097545960291053	1132.9255242274135
30.14	0.2638804550809135	22.1166	0.870514	0.01055521820323654	1124.589126264524	0.010499900805237427	1136.4594098812331
30.54	0.2728184550809135	22.1698	0.882164	0.01091273820323654	1127.2942500863264	0.010853623952413512	1139.5961171155325
30.95	0.28240245508091355	22.2186	0.895119	0.011296098203236541	1129.7756418627166	0.01123277371943142	1142.5376984608226
31.35	0.2914434550809135	22.2745	0.906265	0.011657738203236541	1132.6180558032945	0.01159031030513502	1145.821820582108
31.76	0.30144045508091355	22.3128	0.918785	0.012057618203236541	1134.5655415622236	0.011985504227974512	1148.2456996889293
32.16	0.3107014550809135	22.35	0.930672	0.012428058203236541	1136.4570943097997	0.012351463847695629	1150.581049223363
32.6	0.32114245508091355	22.3902	0.943634	0.012845698203236541	1138.5011916337933	0.012763892048672247	1153.1260343455463
33.01	0.33060545508091355	22.4292	0.955688	0.013224218203236542	1140.4842711272197	0.0131375415474765	1155.5662839859651
33.41	0.34028245508091354	22.4649	0.967964	0.013611298203236541	1142.299551586587	0.013519496572018692	1157.8477314206555
33.82	0.3503704550809135	22.504	0.98053	0.01401481820323654	1144.2877158992274	0.013917518674872863	1160.3247002097517
34.22	0.3596984550809135	22.5203	0.991943	0.014387938203236542	1145.1165414310954	0.014285414057611866	1161.59240746471
34.64	0.37027545508091353	22.5618	1.0052	0.014811018203236541	1147.22674140487	0.014702406196105543	1164.2183375550574
35.08	0.38133545508091354	22.5942	1.01836	0.015253418203236542	1148.874222830178	0.015138254437244416	1166.398481813925
35.5	0.3914034550809135	22.6257	1.03048	0.01565613820323654	1150.4759408825607	0.015534845219938963	1168.4879512125167
35.9101	0.40146045508091355	22.646	1.04333	0.016058418203236544	1151.5081591829855	0.015930845734862295	1169.999558767585
36.3201	0.4119934550809135	22.672	1.05577	0.01647973820323654	1152.830212178603	0.016345420983751278	1171.8285522680878
36.7201	0.42132445508091354	22.6909	1.0665	0.016852978203236543	1153.7912430100328	0.01671254241073715	1173.236061679566
37.1201	0.43115845508091355	22.7228	1.07897	0.017246338203236542	1155.4133003392715	0.01709930819127783	1175.3399488814403
37.5601	0.44219445508091354	22.7388	1.09228	0.01768777820323654	1156.2268714134977	0.017533169910303924	1176.6779558676817
37.9701	0.4523534550809135	22.7646	1.10435	0.01809413820323654	1157.5387547706875	0.017932387529953672	1178.4834209751107
38.3701	0.46188545508091355	22.7808	1.11643	0.018475418203236543	1158.3624954833415	0.018306821099634885	1179.763727018341
38.8001	0.47288145508091356	22.8175	1.12961	0.018915258203236543	1160.2286241348481	0.01873858905845259	1182.1746481351447
39.2001	0.48311245508091355	22.8283	1.14159	0.01932449820323654	1160.7777846099507	0.019140151243875494	1183.2092328230026
39.6201	0.4937944550809135	22.856	1.15437	0.01975177820323654	1162.186279532205	0.019559242977910004	1185.1415251563699
40.0401	0.5038294550809135	22.8725	1.16724	0.02015317820323654	1163.0252747025008	0.01995279073014227	1186.4639303184483
40.4601	0.5144794550809135	22.8913	1.17944	0.020579178203236542	1163.9812207147168	0.020370287914278626	1187.9349976810256
40.8701	0.5248524550809135	22.909	1.19183	0.02099409820323654	1164.8812337155796	0.02077675875763051	1189.3368647313118
41.2701	0.5347274550809135	22.924	1.20399	0.021389098203236537	1165.6439565976666	0.021163561788148773	1190.5760296553433
41.7001	0.5453384550809135	22.9447	1.21695	0.02181353820323654	1166.696514174947	0.021579027193823597	1192.146293158485
42.1001	0.5551964550809135	22.9627	1.22891	0.022207858203236543	1167.6117816334513	0.02196485486234501	1193.5419385163955
42.5201	0.5658284550809135	22.9914	1.24101	0.02263313820323654	1169.0711247478446	0.02238080897015006	1195.5308730836757
42.9501	0.5764134550809135	22.9933	1.2541	0.02305653820323654	1169.1677363129093	0.02279475250315904	1196.1246968911996
43.3501	0.5866454550809135	23.018	1.26657	0.023465818203236538	1170.423686658746	0.023194728593500934	1197.888636110642
43.7601	0.5972664550809135	23.0288	1.27915	0.023890658203236537	1170.9728471338485	0.02360974181762045	1198.9481591899942
44.1601	0.6072224550809134	23.0474	1.29102	0.02428889820323654	1171.9186235076368	0.02399861397853318	1200.3832356564908
44.5801	0.6172244550809135	23.0582	1.30279	0.02468897820323654	1172.4677839827393	0.0243891306451026	1201.4148155454861
45.0001	0.6281834550809134	23.0691	1.31582	0.025127338203236538	1173.022029277056	0.02481683726756817	1202.4969505265472
45.4101	0.6384054550809135	23.098	1.32849	0.02553621820323654	1174.491542029877	0.02521561551097262	1204.483614325008
45.8201	0.6486454550809134	23.116	1.34013	0.025945818203236538	1175.4068094883817	0.02561493658537043	1205.9037008822136
46.2201	0.6586054550809135	23.1198	1.35217	0.02634421820323654	1175.6000326185106	0.026003185807397532	1206.5702963975446
46.6401	0.6694934550809135	23.1361	1.36556	0.02677973820323654	1176.4288581503783	0.026427436866544307	1207.933314986378
47.0601	0.6795304550809135	23.137	1.3771	0.02718121820323654	1176.4746215233035	0.026818369326930876	1208.4526349214984
47.4801	0.6903224550809135	23.1698	1.3895	0.02761289820323654	1178.1424422254674	0.02723853794908548	1210.674369551552
47.9101	0.7018814550809135	23.1845	1.40392	0.02807525820323654	1178.8899106499127	0.027688372722278743	1211.9875492845997
48.3101	0.7116904550809134	23.198	1.41502	0.02846761820323654	1179.5763612437913	0.02806994512639621	1213.1560907372427
48.7301	0.7219174550809134	23.1976	1.42804	0.028876698203236538	1179.5560219669358	0.02846762285309353	1213.617705227085
49.1401	0.7320224550809135	23.2204	1.43957	0.02928089820323654	1180.715360747708	0.0288604013321589	1215.2877670327596
49.5401	0.7419404550809134	23.2345	1.45171	0.029677618203236538	1181.4323202568698	0.029245761213621484	1216.494417590417
49.9501	0.7527694550809135	23.2474	1.46435	0.03011077820323654	1182.0882619354647	0.02966634811190773	1217.681859407253
50.3501	0.7628544550809134	23.2553	1.47645	0.030514178203236538	1182.489962653364	0.030057879820673185	1218.5726720973073
50.7901	0.7741344550809135	23.272	1.49002	0.03096537820323654	1183.3391274620876	0.030495623678770442	1219.9816710866392
51.2101	0.7846884550809134	23.2841	1.50275	0.03138753820323654	1183.9543905869712	0.030905020152611384	1221.1158042524094
51.6301	0.7953084550809135	23.2838	1.51518	0.03181233820323654	1183.9391361293294	0.031316807697638414	1221.6030083399232
52.0501	0.8058194550809135	23.3086	1.52746	0.032232778203236535	1185.2001712943802	0.03172420189893097	1223.40246554215
52.4901	0.8168194550809135	23.3175	1.54086	0.03267277820323654	1185.6527202044185	0.032150371517482575	1224.3912885577215
52.9001	0.8271734550809134	23.3203	1.55283	0.033086938203236535	1185.7950951424082	0.032551347489915256	1225.0294241770862
53.3001	0.8373454550809135	23.3415	1.56548	0.03349381820323654	1186.873076815758	0.03294511870257749	1226.6259878809408
53.7201	0.8476984550809135	23.3475	1.57748	0.03390793820323654	1187.1781659685928	0.033345737502726513	1227.4329298564876
54.1301	0.8586964550809135	23.3614	1.59058	0.03434785820323654	1187.884955839327	0.03377113943550352	1228.6862598642542
54.5301	0.8689764550809135	23.362	1.60248	0.03475905820323654	1187.9154647546104	0.03416860561006681	1229.2062875345405
54.9701	0.8802494550809135	23.3874	1.61577	0.03520997820323654	1189.2070088349444	0.034604283631526934	1231.0789616951588
55.3901	0.8908214550809135	23.3831	1.62849	0.03563285820323654	1188.9883616087461	0.035012697054741644	1231.3554153032492
55.8101	0.9017184550809135	23.3948	1.64175	0.03606873820323654	1189.583285456774	0.03543349125327651	1232.4900535508605
56.2201	0.9117484550809135	23.3931	1.65343	0.03646993820323654	1189.4968435301378	0.035820649292427786	1232.8777199066267
56.6401	0.9221344550809135	23.406	1.66568	0.03688537820323654	1190.1527852087324	0.03622139102952652	1234.0520208107919
57.0501	0.9329444550809135	23.4198	1.67844	0.03731777820323654	1190.8544902602525	0.03663832223024155	1235.294534000113
57.4501	0.9434474550809134	23.4308	1.69053	0.03773789820323654	1191.4138203737834	0.037043246310609304	1236.3752738449784
57.8701	0.9544134550809135	23.4414	1.70304	0.03817653820323654	1191.952811210458	0.03746584562283088	1237.4574432440895
58.2801	0.9646614550809135	23.4393	1.71475	0.03858645820323654	1191.846030006966	0.03786061383281219	1237.8351470285231
58.6801	0.9747984550809135	23.4422	1.7268	0.038991938203236536	1191.9934897641695	0.03825095289857231	1238.471626255714
59.0901	0.9856344550809135	23.459	1.73962	0.03942537820323654	1192.847739392107	0.03866803949890242	1239.8762126565166
59.5101	0.9964604550809135	23.4631	1.75166	0.03985841820323654	1193.0562169798775	0.03908456754284636	1240.6095506162326
59.9301	1.0072494550809137	23.4784	1.76515	0.04028997820323655	1193.8341943196065	0.03949949948418046	1241.9337479870221
60.3501	1.0182794550809136	23.4774	1.77812	0.040731178203236545	1193.783346127467	0.03992352208986328	1242.4075483346408
60.7701	1.0291694550809136	23.4879	1.79048	0.04116677820323655	1194.3172521449283	0.040341986409899944	1243.4834455682774
61.2001	1.0401894550809136	23.4947	1.80312	0.041607578203236545	1194.6630198514745	0.040765267986442845	1244.3700548764596
61.6001	1.0506094550809135	23.4981	1.81518	0.04202437820323654	1194.8359037047476	0.04116533864602144	1245.0481396128419
62.0101	1.0617394550809136	23.5116	1.82737	0.04246957820323655	1195.522354298626	0.04159249268539962	1246.2956844182288
62.4101	1.0719194550809137	23.5138	1.8395	0.04287677820323655	1195.634220321332	0.04198302733584232	1246.8991635982495
62.8301	1.0830294550809136	23.5166	1.85262	0.04332117820323655	1195.7765952593215	0.04240906553164926	1247.57904623381
63.2401	1.0932794550809135	23.5266	1.8643	0.04373117820323654	1196.285077180713	0.04280196416115969	1248.6000330727754
63.6601	1.1038794550809137	23.5167	1.87638	0.04415517820323655	1195.7816800785354	0.0432081165406008	1248.5816332545687
64.0701	1.1149594550809137	23.5244	1.88893	0.04459837820323655	1196.173211158007	0.04363248446595225	1249.5205964258118
64.4701	1.1256094550809135	23.5484	1.90193	0.04502437820323654	1197.3935677693462	0.044040213568820596	1251.3054686227158
64.8801	1.1364394550809136	23.5389	1.91405	0.045457578203236544	1196.9105099440244	0.04445466345667855	1251.3191630520805
65.2801	1.1464494550809137	23.5298	1.9255	0.045857978203236546	1196.4477913955584	0.04483758032799029	1251.3144681346862
65.7001	1.1577294550809136	23.5429	1.9373	0.046309178203236545	1197.1139027125807	0.04526890342338786	1252.5512637628697
66.1301	1.1696394550809135	23.5565	1.95161	0.04678557820323654	1197.8054381256732	0.045724114547268706	1253.8454581233639
66.5301	1.1801694550809136	23.5588	1.96306	0.047206778203236544	1197.9223889675934	0.046126408284771686	1254.4724454882778
66.9501	1.1912894550809137	23.5525	1.97598	0.047651578203236546	1197.6020453571166	0.046551067074063146	1254.6696728778072
67.3701	1.2027394550809136	23.5654	1.98963	0.048109578203236546	1198.2579870357117	0.04698813978713553	1255.905673370659
67.8001	1.2137594550809137	23.5533	2.00157	0.048550378203236544	1197.642723910828	0.04740861808658285	1255.788731109053
68.2101	1.2246794550809137	23.5578	2.01423	0.048987178203236545	1197.8715407754542	0.047825106463613175	1256.551887408007
68.6101	1.2355094550809136	23.5716	2.02611	0.04942037820323655	1198.5732458269742	0.048237990991055475	1257.8071889400242
69.0101	1.2461794550809135	23.5679	2.03796	0.049847178203236545	1198.3851075160596	0.048644609008447394	1258.1212235265175
69.4201	1.2572694550809136	23.5815	2.0503	0.05029077820323655	1199.0766429291518	0.04906705745307823	1259.3791404273832
69.8201	1.2680294550809137	23.5836	2.06223	0.050721178203236544	1199.1834241326442	0.04947676478930576	1260.0074202864434
70.2401	1.2791594550809136	23.5795	2.07429	0.051166378203236544	1198.9749465448735	0.049900384031258724	1260.322152115994
70.6801	1.2909794550809135	23.5695	2.08795	0.05163917820323654	1198.4664646234821	0.050350068983371334	1260.3542879607771
71.0901	1.3026794550809135	23.5786	2.10078	0.05210717820323654	1198.9291831719484	0.050794989547387946	1261.40199977255
71.4901	1.3133394550809137	23.5724	2.11271	0.05253357820323654	1198.6139243806854	0.051200189346485445	1261.5814027126264
71.9001	1.3242694550809135	23.5738	2.12479	0.05297077820323654	1198.6851118496804	0.05161548177269507	1262.1803950449917
72.3001	1.3350394550809135	23.5768	2.13692	0.05340157820323654	1198.8376564260977	0.05202452626541867	1262.8574792887207
72.7101	1.3465194550809136	23.5786	2.1496	0.053860778203236544	1198.9291831719484	0.05246035240341482	1263.5044419881601
73.1101	1.3575494550809135	23.5831	2.16116	0.05430197820323654	1199.1580000365745	nan	nan
73.5201	1.3686394550809136	23.5779	2.17289	0.05474557820323654	1198.8935894374508	nan	nan
73.9301	1.3805494550809136	23.5881	2.1866	0.055221978203236544	1199.4122409972701	nan	nan
74.3301	1.3915594550809136	23.5767	2.19866	0.055662378203236544	1198.8325716068837	nan	nan
74.7501	1.4033094550809135	23.5734	2.21078	0.05613237820323654	1198.6647725728246	nan	nan
75.1801	1.4145394550809136	23.5721	2.22359	0.056581578203236546	1198.5986699230439	nan	nan
75.5801	1.4259594550809136	23.5795	2.23547	0.057038378203236546	1198.9749465448735	nan	nan
75.9801	1.4367294550809135	23.5708	2.24742	0.05746917820323654	1198.5325672732629	nan	nan
76.4101	1.4492294550809135	23.5791	2.26093	0.05796917820323654	1198.954607268018	nan	nan
76.8101	1.4600994550809137	23.5727	2.27289	0.05840397820323655	1198.6291788383273	nan	nan
77.2201	1.4716694550809135	23.5701	2.28438	0.05886677820323654	1198.4969735387656	nan	nan
77.6201	1.4827794550809137	23.56	2.29636	0.059311178203236545	1197.9834067981603	nan	nan
78.0401	1.4955494550809136	23.5708	2.31041	0.059821978203236544	1198.5325672732629	nan	nan
78.4501	1.5067794550809135	23.5575	2.3226	0.06027117820323654	1197.8562863178124	nan	nan
78.8701	1.5189294550809136	23.5558	2.33505	0.06075717820323654	1197.769844391176	nan	nan
79.2801	1.5307794550809135	23.547	2.34761	0.06123117820323654	1197.3223803003514	nan	nan
79.6801	1.5422094550809136	23.5483	2.36001	0.06168837820323654	1197.3884829501324	nan	nan
80.1001	1.5534494550809135	23.5486	2.37186	0.06213797820323654	1197.403737407774	nan	nan
80.5201	1.5655594550809135	23.5364	2.3839	0.06262237820323655	1196.7833894636765	nan	nan
80.9601	1.5787194550809136	23.5436	2.39793	0.06314877820323654	1197.1494964470785	nan	nan
81.3701	1.5901494550809137	23.5197	2.40954	0.06360597820323655	1195.934224654953	nan	nan
81.7701	1.6022494550809137	23.5337	2.42219	0.06408997820323654	1196.646099344901	nan	nan
82.1901	1.6144994550809135	23.5214	2.43488	0.06457997820323653	1196.0206665815895	nan	nan
82.6101	1.6269194550809136	23.5152	2.44772	0.06507677820323654	1195.7054077903267	nan	nan
83.0401	1.6398594550809136	23.4974	2.46112	0.06559437820323655	1194.8003099702498	nan	nan
83.4501	1.6512794550809136	23.4923	2.47266	0.06605117820323654	1194.5409841903404	nan	nan
83.8501	1.6629994550809135	23.4794	2.48461	0.06651997820323655	1193.8850425117453	nan	nan
84.2501	1.6749994550809135	23.4744	2.49676	0.06699997820323654	1193.6308015510497	nan	nan
84.6701	1.6877094550809135	23.4775	2.50964	0.06750837820323655	1193.788430946681	nan	nan
85.1101	1.7005494550809135	23.4559	2.52253	0.06802197820323654	1192.6901099964757	nan	nan
85.5301	1.7136294550809137	23.4407	2.53557	0.06854517820323655	1191.9172174759608	nan	nan
85.9401	1.7258494550809136	23.4361	2.54714	0.06903397820323655	1191.6833157921205	nan	nan
86.3401	1.7384894550809136	23.43	2.55994	0.06953957820323654	1191.3731418200719	nan	nan
86.7501	1.7502894550809136	23.3918	2.57098	0.07001157820323654	1189.4307408803568	nan	nan
87.1501	1.7621394550809135	23.3976	2.58346	0.07048557820323655	1189.725660394764	nan	nan
87.5601	1.7748194550809135	23.3749	2.59569	0.07099277820323655	1188.5714064332053	nan	nan
87.9801	1.7872694550809136	23.3674	2.60821	0.07149077820323654	1188.1900449921618	nan	nan
88.3901	1.7996794550809136	23.3446	2.61984	0.07198717820323655	1187.0307062113893	nan	nan
88.7901	1.8125494550809136	23.3251	2.63242	0.07250197820323655	1186.0391664646759	nan	nan
89.2101	1.8247894550809136	23.2995	2.64466	0.07299157820323654	1184.737452745914	nan	nan
89.6201	1.8379994550809136	23.2748	2.65711	0.07351997820323654	1183.4815024000773	nan	nan
90.0201	1.8501994550809135	23.2592	2.66914	0.07400797820323654	1182.6882706027068	nan	nan
90.4301	1.8627894550809136	23.2344	2.68137	0.07451157820323655	1181.427235437656	nan	nan
90.8401	1.8758094550809137	23.2091	2.69408	0.07503237820323655	1180.1407761765356	nan	nan
91.2401	1.8882194550809135	23.1976	2.70609	0.07552877820323654	1179.5560219669358	nan	nan
91.6501	1.9001494550809135	23.1744	2.71761	0.07600597820323654	1178.3763439093075	nan	nan
92.0501	1.9125794550809136	23.1431	2.72995	0.07650317820323654	1176.7847954953525	nan	nan
92.4701	1.9254994550809137	23.1239	2.74258	0.07701997820323654	1175.8085102062807	nan	nan
92.9101	1.9394494550809136	23.0942	2.75545	0.07757797820323654	1174.2983188997484	nan	nan
93.3301	1.9526494550809137	23.055	2.76819	0.07810597820323655	1172.305069767894	nan	nan
93.7501	1.9661294550809136	23.0493	2.78093	0.07864517820323655	1172.015235072701	nan	nan
94.1701	1.9791694550809136	23.0027	2.79305	0.07916677820323655	1169.645709319017	nan	nan
94.6001	1.9931194550809135	22.968	2.80651	0.07972477820323653	1167.8812770517889	nan	nan
95.0001	2.005279455080913	22.944	2.81824	0.08021117820323653	1166.6609204404494	nan	nan
95.4101	2.0176694550809136	22.9194	2.8297	0.08070677820323655	1165.4100549138263	nan	nan
95.8101	2.0304794550809135	22.8842	2.84205	0.08121917820323654	1163.6201985505288	nan	nan
96.2301	2.0436294550809135	22.8693	2.85519	0.08174517820323654	1162.8625604876556	nan	nan
96.6601	2.0580594550809135	22.8278	2.86861	0.08232237820323654	1160.7523605138813	nan	nan
97.0601	2.0703294550809135	22.7797	2.88	0.08281317820323654	1158.3065624719884	nan	nan
97.4801	2.0833994550809134	22.7532	2.89237	0.08333597820323653	1156.9590853803013	nan	nan
97.9001	2.096589455080913	22.7392	2.90495	0.08386357820323653	1156.2472106903533	nan	nan
98.3201	2.1101294550809135	22.6878	2.91768	0.08440517820323654	1153.6336136144014	nan	nan
98.7301	2.1226994550809133	22.6693	2.92992	0.08490797820323653	1152.6929220598274	nan	nan
99.1501	2.135839455080913	22.6261	2.94264	0.08543357820323653	1150.4962801594165	nan	nan
99.5601	2.149049455080913	22.5879	2.95471	0.08596197820323653	1148.5538792197015	nan	nan
99.9601	2.1616894550809134	22.5546	2.96638	0.08646757820323653	1146.8606344214681	nan	nan
100.38	2.1749894550809135	22.5142	2.97901	0.08699957820323653	1144.8063674590464	nan	nan
100.8	2.1881794550809133	22.4769	2.99114	0.08752717820323654	1142.9097298922568	nan	nan
101.23	2.2013094550809136	22.447	3.00423	0.08805237820323654	1141.3893689472964	nan	nan
101.63	2.2143894550809136	22.4066	3.01659	0.08857557820323654	1139.335101984875	nan	nan
102.04	2.2275994550809135	22.3783	3.02894	0.08910397820323654	1137.8960981473374	nan	nan
102.45	2.2400394550809133	22.3351	3.04108	0.08960157820323653	1135.6994562469267	nan	nan
102.86	2.2534194550809135	22.3006	3.05328	0.09013677820323654	1133.945193618126	nan	nan
103.28	2.266659455080913	22.2783	3.06587	0.09066637820323653	1132.8112789334234	nan	nan
103.71	2.280359455080913	22.2251	3.07833	0.09121437820323652	1130.106155111621	nan	nan
104.12	2.293239455080913	22.1943	3.09089	0.09172957820323653	1128.5400307937355	nan	nan
104.52	2.3066694550809133	22.1517	3.10307	0.09226677820323653	1126.373897808608	nan	nan
104.92	2.3193594550809133	22.1055	3.11472	0.09277437820323653	1124.0247113317798	nan	nan
105.35	2.332489455080913	22.0717	3.12753	0.09329957820323653	1122.306042437477	nan	nan
105.75	2.3455194550809133	22.031	3.13987	0.09382077820323653	1120.2365210174137	nan	nan
106.17	2.3586594550809132	22.0077	3.15207	0.09434637820323653	1119.0517581405718	nan	nan
106.59	2.3717894550809135	21.9539	3.16434	0.09487157820323654	1116.316125403486	nan	nan
107	2.3849594550809132	21.9214	3.17724	0.09539837820323653	1114.6635591589638	nan	nan
107.4	2.3978794550809135	21.8748	3.18893	0.09591517820323654	1112.2940334052798	nan	nan
107.82	2.411249455080913	21.8344	3.20121	0.09644997820323653	1110.2397664428586	nan	nan
108.25	2.4246994550809133	21.8007	3.21445	0.09698797820323653	1108.5261823677697	nan	nan
108.66	2.4383394550809134	21.7357	3.22686	0.09753357820323653	1105.2210498787256	nan	nan
109.06	2.451179455080913	21.7038	3.23849	0.09804717820323652	1103.598992549487	nan	nan
109.46	2.463659455080913	21.6644	3.25004	0.09854637820323653	1101.5955737792049	nan	nan
109.88	2.477819455080913	21.6357	3.26359	0.09911277820323652	1100.1362306648114	nan	nan
110.31	2.4909994550809134	21.5734	3.27557	0.09963997820323653	1096.9683882945428	nan	nan
110.71	2.5032594550809133	21.5377	3.28752	0.10013037820323653	1095.1531078351757	nan	nan
111.13	2.5167794550809135	21.499	3.29956	0.10067117820323654	1093.1852827993907	nan	nan
111.54	2.5310194550809135	21.473	3.31361	0.10124077820323654	1091.863229803773	nan	nan
111.94	2.5436494550809132	21.4149	3.32469	0.10174597820323653	1088.908949840489	nan	nan
112.36	2.5568094550809133	21.3633	3.33674	0.10227237820323654	1086.2851831261094	nan	nan
112.8	2.5712394550809132	21.3223	3.35056	0.10284957820323654	1084.2004072484046	nan	nan
113.21	2.5840594550809133	21.2756	3.36214	0.10336237820323653	1081.8257966755068	nan	nan
113.61	2.5964394550809136	21.2305	3.37372	0.10385757820323654	1079.5325432100315	nan	nan
114.02	2.6101094550809134	21.183	3.3868	0.10440437820323653	1077.1172540834223	nan	nan
114.43	2.6232194550809136	21.1412	3.39872	0.10492877820323654	1074.9917996520062	nan	nan
114.83	2.6359094550809132	21.1001	3.41085	0.10543637820323654	1072.9019389550876	nan	nan
115.23	2.6488094550809134	21.04	3.42247	0.10595237820323654	1069.845962607525	nan	nan
115.67	2.6632094550809136	21.0032	3.43607	0.10652837820323655	1067.9747491368048	nan	nan
116.09	2.6764094550809134	20.9562	3.44857	0.10705637820323653	1065.5848841062652	nan	nan
116.51	2.6907794550809134	20.8918	3.46155	0.10763117820323653	1062.3102605325043	nan	nan
116.94	2.7049994550809133	20.8412	3.47459	0.10819997820323653	1059.737342010264	nan	nan
117.34	2.7174194550809134	20.7956	3.48602	0.10869677820323653	1057.418664448719	nan	nan
117.76	2.730809455080913	20.7441	3.49873	0.10923237820323653	1054.7999825535533	nan	nan
118.18	2.7443094550809133	20.6808	3.51007	0.10977237820323653	1051.581291991146	nan	nan
118.6	2.7587794550809135	20.6435	3.52357	0.11035117820323653	1049.6846544243558	nan	nan
119.01	2.7717094550809134	20.5845	3.53551	0.11086837820323653	1046.6846110881463	nan	nan
119.42	2.785709455080913	20.5234	3.5484	0.11142837820323653	1043.5777865484447	nan	nan
119.82	2.798049455080913	20.4811	3.55952	0.11192197820323653	1041.4269080209594	nan	nan
120.24	2.8120294550809133	20.4279	3.57228	0.11248117820323653	1038.7217841991571	nan	nan
120.65	2.826049455080913	20.3593	3.58467	0.11304197820323653	1035.2335982184118	nan	nan
121.05	2.8394194550809133	20.2908	3.59674	0.11357677820323653	1031.7504970568807	nan	nan
121.47	2.853429455080913	20.2247	3.60937	0.11413717820323653	1028.3894315564833	nan	nan
121.9	2.8670894550809134	20.1416	3.62159	0.11468357820323653	1024.163946789721	nan	nan
122.3	2.8806494550809134	20.0776	3.63366	0.11522597820323653	1020.9096624928158	nan	nan
122.5	2.8877594550809134	20.0082	3.63941	0.11551037820323654	1017.3807979583594	nan	nan