File: original_data/46NT95.csv
Specimen name:	AWA_1_13_Rz
Specimen ID:	46NT95
Material:	42CrMoS4
Specimen type:	Round Tensile Specimen
Gauge diameter:	4.988	mm
Gauge length:	25	mm
Parallel length:	30	mm
Original cross-section:	19.540819402664045	mm²
Cross-section after fracture:	8.972702777917807	mm²
Yield stress at 0.2% plastic strain:	1133.3374954926353	MPa
Yield stress at 1% plastic strain:	1144.9666137670347	MPa
Ultimate tensile strength:	1199.4379312878068	MPa
Uniform elongation:	5.3608161538646515	%
Elongation after fracture:	14.841479445546113	%
Reduction of area:	54.08225933097495	%
Slope of linear-elastic region:	202404.18965807394	MPa
Crosshead seperation speed:	0.02992631464894041	mm/s
Strain rate:	0.000997543821631347	s-1
Test temperature:	RT	Cel
Machine type:	INSTRON 8852TT
Standard:	DIN EN ISO 6892-1
Date:	2022-08-18 00:00:00
Heat treatment batch:	Batch 1
Time	Displacement	Force	Machine Displacement	Engineering Strain	Engineering Stress	True Strain	True Stress
s	mm	kN	mm		MPa		MPa
0	0.0011955133017924838	0.196235	0	4.7820532071699355e-05	10.042311735056863	4.781938870655867e-05	10.042791963747264
0.430001	0.001095210301792484	0.198092	0.000946045	4.380841207169936e-05	10.137343573882763	4.380745251128445e-05	10.137787674807361
0.830001	0.001166002701792484	0.198816	0.000488281	4.6640108071699356e-05	10.174394220791731	4.663902045562651e-05	10.174868755637752
1.25	0.0023661433017924836	0.316658	0.00835037	9.464573207169935e-05	16.204949929419506	9.464125344691641e-05	16.20648365876876
1.65	0.004256763301792484	0.509683	0.0202522	0.00017027053207169934	26.08299014986617	0.0001702560376898783	26.08743131447701
2.06	0.006245963301792484	0.735713	0.0327301	0.00024983853207169936	37.65005882505104	0.0002498073276229426	37.6594652604803
2.46	0.008204523301792485	0.973179	0.0455093	0.0003281809320716994	49.802363961632246	0.0003281270924886599	49.81870814785655
2.86	0.010130913301792483	1.2172	0.0569916	0.0004052365320716993	62.290120742534285	0.000405154445923688	62.31536297504632
3.27	0.012214413301792484	1.46622	0.0686798	0.0004885765320716993	75.03370098185887	0.0004884572174191481	75.0703606872731
3.68001	0.014435413301792484	1.75975	0.0813179	0.0005774165320716994	90.05507720725822	0.0005772498912903603	90.1070764976347
4.09001	0.016644913301792484	2.05452	0.0932083	0.0006657965320716994	105.13991034172817	0.0006655749878908233	105.20991212941603
4.50001	0.018793013301792484	2.3795	0.105312	0.0007517205320716994	121.77073801089412	0.0007514381317078015	121.86227557486244
4.89001	0.020747913301792487	2.68041	0.116531	0.0008299165320716995	137.16978519511693	0.0008295723417663107	137.2836246675511
5.30001	0.02310671330179248	3.035	0.129715	0.0009242685320716992	155.31590244297695	0.0009238416589219563	155.4594560441353
5.71001	0.02530141330179248	3.37791	0.141533	0.0010120565320716993	172.8642965473332	0.0010115447481333943	173.0392449878159
6.11001	0.027371913301792485	3.7154	0.153419	0.0010948765320716995	190.1353225491389	0.0010942775918986634	190.34349725171583
6.52001	0.029792113301792482	4.08467	0.166	0.0011916845320716993	209.03268772051226	0.0011909750396644574	209.28178874116614
6.94001	0.031936713301792485	4.44752	0.178207	0.0012774685320716993	227.60150986266515	0.0012766532633927536	227.89226362936674
7.34001	0.03418121330179248	4.80188	0.191025	0.0013672485320716994	245.73585687739117	0.0013663146988886026	246.07183886698417
7.74001	0.03640741330179248	5.16969	0.202835	0.0014562965320716991	264.55850665582653	0.0014552371606582491	264.94378229159946
8.15001	0.03846701330179248	5.51613	0.214249	0.0015386805320716992	282.28754825132734	0.001537497976076913	282.72189860626787
8.57001	0.041010513301792485	5.92568	0.227192	0.0016404205320716995	303.246239468962	0.0016390765119487242	303.7436908264604
8.97001	0.043122613301792484	6.28835	0.239265	0.0017249045320716994	321.8058501243144	0.0017234185927396336	322.360934493641
9.37001	0.04548751330179248	6.66578	0.251041	0.0018195005320716991	341.12080269731365	0.001817847246111377	341.74147217932216
9.77001	0.04783181330179248	7.04189	0.262646	0.0019132725320716991	360.3682043671087	0.0019114445574183979	361.0576869539563
10.18	0.05027791330179248	7.44765	0.276176	0.002011116532071699	381.1329426126647	0.0020090969445162687	381.8994453744702
10.59	0.05281301330179248	7.83775	0.288338	0.0021125205320716993	401.0962815065709	0.0021102922981473555	401.9436056365912
11.01	0.05533181330179248	8.25574	0.300545	0.0022132725320716993	422.48688910529904	0.0022108268523932987	423.4219677321162
11.42	0.05782011330179248	8.63322	0.31295	0.002312804532071699	441.80440042463175	0.002310134116310462	442.8262076442231
11.83	0.060323813301792484	9.0378	0.325298	0.0024129525320716995	462.5087522567174	0.002410046036662097	463.6247639215806
12.24	0.06290571330179248	9.45445	0.338116	0.0025162285320716993	483.83078545370785	0.0025130681294788203	485.0482142807611
12.64	0.06512451330179249	9.82436	0.349998	0.0026049805320716994	502.76090257814997	0.0026015934511969224	504.0705849416529
13.05	0.06777361330179249	10.2244	0.362049	0.0027109445320716995	523.2329202431544	0.0027072765495796207	524.6513756672874
13.46	0.07021201330179248	10.6199	0.374748	0.0028084805320716996	543.4726037410777	0.0028045441191258324	544.9989359683988
13.87	0.07254031330179249	10.9966	0.386253	0.0029016125320716997	562.750198617608	0.0028974109799838905	564.3830816463427
14.28	0.0750023133017925	11.4109	0.398678	0.0030000925320717	583.9519707369244	0.0029956012350999804	585.7038806834208
14.69	0.07749721330179249	11.7937	0.4105	0.0030998885320716995	603.5417326661408	0.003095093783850586	605.4126447618592
15.09	0.07985701330179248	12.1869	0.423195	0.0031942805320716995	623.6637138327235	0.003189189656255708	625.6558706923789
15.51	0.08270551330179249	12.5899	0.435513	0.0033082205320716994	644.2872092806707	0.003302760409406658	646.4186534549642
15.92	0.08487861330179249	12.9776	0.447559	0.0033951445320716993	664.1277283505693	0.003389394041031096	666.3825379760759
16.34	0.08743251330179248	13.3804	0.459835	0.0034973005320716993	684.7409888131824	0.0034911991978939408	687.13573383769
16.74	0.0900332133017925	13.7914	0.472702	0.0036013285320716996	705.7738836744884	0.0035948592757662832	708.3156072989564
17.15	0.0924043133017925	14.1682	0.484356	0.0036961725320717	725.0565960436858	0.003689358471844819	727.7365303181798
17.56	0.09491261330179249	14.5641	0.4963	0.0037965045320716997	745.3167495122769	0.003789315997199698	748.1463479296293
17.96	0.09732081330179249	14.9542	0.509014	0.0038928325320716993	765.2800884061833	0.0038852750664595875	768.2591956304776
18.37	0.09980151330179249	15.341	0.521275	0.0039920605320717	785.0745500420788	0.003984113401688471	788.2086151680359
18.78	0.1025005133017925	15.7459	0.532848	0.004100020532071699	805.7952778506989	0.004091638351487188	809.0990550345331
19.19	0.10482751330179249	16.1124	0.545094	0.0041931005320717	824.5508884751968	0.004184333983504697	828.0083132443823
19.59	0.1074395133017925	16.5124	0.557312	0.0042975805320717	845.0208591431342	0.004288372305493782	848.6524043365823
20.01	0.10991751330179249	16.9003	0.569572	0.004396700532071699	864.871613198367	0.0043870632820299914	868.6741946802899
20.44	0.1124645133017925	17.309	0.582451	0.0044985805320716995	885.7868057283322	0.004488492162915474	889.7715890081475
20.87	0.11523651330179249	17.7265	0.595856	0.004609460532071699	907.152337612992	0.004598869502357984	911.3338205097957
21.27	0.11763451330179249	18.1038	0.607738	0.0047053805320716995	926.4606374455242	0.004694344833662441	930.8199872926909
21.68	0.12001451330179248	18.4896	0.620163	0.0048005805320717	946.2039241547501	0.004789094490459558	950.7462522924172
22.1	0.12265151330179248	18.8854	0.632229	0.0049060605320716995	966.4589601306745	0.004894065034858013	971.2004662908387
22.51	0.12527151330179248	19.2711	0.644855	0.005010860532071699	986.1971293472334	0.004998347952223189	991.138825619522
22.92	0.1277855133017925	19.6564	0.657501	0.0051114205320717	1005.9148285931243	0.0050984015669023625	1011.0564823015105
23.33	0.1303915133017925	20.0402	0.669537	0.0052156605320717	1025.5557654490103	0.005202106084515707	1030.9047161783012
23.74	0.13267751330179248	20.4186	0.681957	0.005307100532071699	1044.9203577008795	0.005293067501947961	1050.4658550872064
24.17	0.1354085133017925	20.8174	0.695171	0.0054163405320717	1065.3289184568132	0.00540172491139227	1071.099102657839
24.58	0.13809451330179248	21.1731	0.706837	0.005523780532071699	1083.531839873277	0.0055085804054737595	1089.517031956249
24.99	0.14117551330179248	21.5309	0.71954	0.005647020532071699	1101.842228635747	0.005631135884191941	1108.0643543239569
25.39	0.1444865133017925	21.8312	0.7318	0.005779460532071699	1117.2100591147014	0.005762823521237803	1123.6669305573885
25.79	0.1496195133017925	22.0633	0.744064	0.0059847805320716995	1129.0877595947723	0.005966942867353747	1135.8451020373955
26.2	0.15626851330179248	22.1268	0.755875	0.0062507405320716995	1132.3373674383072	0.006231285682858943	1139.4153145169332
26.61	0.16523351330179248	22.1892	0.768513	0.006609340532071699	1135.5306828625055	0.006587594605836118	1143.0357918301597
27.02	0.1747435133017925	22.1728	0.780972	0.0069897405320716996	1134.69141406512	0.006965425533653583	1142.6226126334047
27.42	0.18557351330179248	22.1482	0.792419	0.007422940532071699	1133.4325108690418	0.007395526089264629	1141.8459129943394
27.83	0.1969105133017925	22.1464	0.805004	0.0078764205320717	1133.3403960010362	0.007845563454844202	1142.267061565925
28.24	0.20783551330179248	22.1397	0.816975	0.0083134205320717	1132.9975239923483	0.008279054387039941	1142.4166088710926
28.66	0.2202595133017925	22.136	0.829796	0.0088103805320717	1132.8081767636697	0.008771795595876722	1142.7886478707999
29.09	0.2324355133017925	22.127	0.842762	0.0092974205320717	1132.347602423641	0.009254465559491925	1142.875514271857
29.51	0.2444845133017925	22.1323	0.854767	0.0097793805320717	1132.6188295349914	0.009731871875982488	1143.6951400668036
29.92	0.25613151330179246	22.1339	0.867268	0.010245260532071698	1132.7007094176631	0.010193133584171215	1144.3055232905097
30.33	0.2679795133017925	22.1241	0.879295	0.0107191805320717	1132.1991951362986	0.010662137391519251	1144.3354427072309
30.74	0.27992751330179244	22.0982	0.891651	0.011197100532071697	1130.8737645355495	0.011134877052776703	1143.5362717661365
31.16	0.29087151330179245	22.1562	0.903492	0.011634860532071698	1133.8419102824005	0.011567696006856957	1147.034002773954
31.57	0.30187451330179244	22.2063	0.91647	0.012074980532071698	1136.4057741085599	0.012002659555492448	1150.1278517074545
31.98	0.31273051330179247	22.2206	0.928082	0.012509220532071699	1137.1375755599388	0.012431626655433745	1151.3622802679233
32.39	0.32360751330179244	22.2549	0.940384	0.012944300532071698	1138.8928755447141	0.01286123908758014	1153.6350471996002
32.8	0.33470051330179246	22.2808	0.952877	0.013388020532071698	1140.2183061454632	0.013299192924154457	1155.4835722391829
33.2	0.3448265133017925	22.2915	0.964733	0.013793060532071699	1140.7658778608306	0.01369880202585082	1156.500530667087
33.62	0.35577051330179243	22.3235	0.977051	0.014230820532071697	1142.4034755142657	0.014130512925200856	1158.6608143495241
34.03	0.36678751330179243	22.3246	0.989742	0.014671500532071698	1142.4597679336023	0.01456491531348226	1159.2213670267106
34.44	0.37722351330179243	22.3492	1.00136	0.015088940532071698	1143.7186711296806	0.014976234794776899	1160.9761741437765
34.84	0.3877385133017925	22.375	1.0146	0.0155095405320717	1145.0389842377626	0.015390496905122432	1162.7980127746005
35.25	0.39830851330179246	22.3794	1.02598	0.0159323405320717	1145.26415391511	0.015806752974317297	1163.5108924144606
35.65	0.4085775133017925	22.413	1.038	0.0163431005320717	1146.9836314512165	0.016210989523452006	1165.7289002486646
36.0801	0.4194745133017925	22.4254	1.05134	0.016778980532071698	1147.6182005419228	0.016639768504053014	1166.8740639870668
36.5001	0.43054551330179247	22.4499	1.0645	0.017221820532071698	1148.8719862453338	0.01707520590089716	1168.6576534067758
36.9001	0.4406365133017925	22.4634	1.07527	0.017625460532071698	1149.5628477553769	0.017471933467678384	1169.824422357625
37.3101	0.45114851330179245	22.4756	1.08784	0.0180459405320717	1150.1871818607488	0.017885045334122277	1170.9433913453588
37.7201	0.46137551330179244	22.4887	1.0996	0.018455020532071698	1150.8575734001238	0.018286793247158838	1172.0966735467132
38.1501	0.47265551330179245	22.5078	1.11268	0.018906220532071697	1151.835014499518	0.018729719124300707	1173.611861300208
38.5601	0.48275151330179245	22.5135	1.12506	0.019310060532071696	1152.126711581536	0.019125987183815585	1174.3743481227923
38.9801	0.49351451330179247	22.5485	1.13675	0.0197405805320717	1153.9178340149806	0.019548262136410765	1176.696841944747
39.3901	0.5044135133017925	22.5677	1.14923	0.0201765405320717	1154.9003926070413	0.019975691272757282	1178.2022871889828
39.7901	0.5148765133017925	22.5884	1.16143	0.0205950605320717	1155.9597135891074	0.020385849867329105	1179.7667738631114
40.2001	0.5252135133017924	22.598	1.173	0.0210085405320717	1156.4509928851378	0.020790904017348937	1180.7463404425198
40.6001	0.5349175133017925	22.6114	1.18479	0.0213967005320717	1157.1367369025138	0.02117100488750835	1181.8956451366755
41.0101	0.5456555133017925	22.6254	1.19734	0.0218262205320717	1157.8531858758913	0.02159143870498261	1183.1247448545803
41.4301	0.5566355133017925	22.6499	1.20987	0.0222654205320717	1159.1069715793026	0.02202116504203693	1184.914975743172
41.8401	0.5665885133017925	22.6655	1.22148	0.0226635405320717	1159.9053004353523	0.022410537986144112	1186.1928612251336
42.2401	0.5767405133017924	22.6837	1.23368	0.023069620532071698	1160.8366841007435	0.0228075399149024	1187.616745902656
42.6501	0.5872485133017925	22.7017	1.24614	0.0234899405320717	1161.7578327808005	0.023218297572686987	1189.04745518549
43.0501	0.5978235133017925	22.7147	1.25885	0.0239129405320717	1162.4231068275087	0.023631503991346295	1190.220061454181
43.4601	0.6083355133017925	22.7336	1.27025	0.0243334205320717	1163.3903129415685	0.02404207960754158	1191.6995786693142
43.8701	0.6185385133017924	22.7518	1.28338	0.0247415405320717	1164.3216966069597	0.02444042521534173	1193.1288090559312
44.2901	0.6290645133017925	22.7657	1.29564	0.0251625805320717	1165.0330280876706	0.02485121516555875	1194.34826547945
44.7001	0.6396535133017924	22.7923	1.30801	0.025586140532071696	1166.3942811370885	0.025264293571189065	1196.2378091300666
45.1101	0.6500965133017924	22.7876	1.32064	0.026003860532071696	1166.1537589817403	0.025671509443323016	1196.4782586892525
45.5201	0.6599245133017925	22.8026	1.33232	0.0263969805320717	1166.921382881788	0.026054592510667517	1197.7245839081768
45.9201	0.6701685133017925	22.8286	1.34471	0.0268067405320717	1168.251930975204	0.0264537345940725	1199.5689573649481
46.3201	0.6805545133017925	22.8409	1.35685	0.0272221805320717	1168.881382573243	0.026858246917540147	1200.7008825902292
46.7501	0.6917445133017924	22.8622	1.37048	0.027669780532071697	1169.9714085113105	0.02729389026576504	1202.3442606136175
47.1601	0.7020465133017925	22.8742	1.3825	0.0280818605320717	1170.5855076313485	0.027694794730378072	1203.4577265975163
47.5701	0.7127135133017924	22.8792	1.39465	0.028508540532071698	1170.841382264698	0.028109733948125368	1204.220361267618
47.9801	0.7226295133017925	22.9024	1.40693	0.0289051805320717	1172.0286405634383	0.028495305406945698	1205.9063400076832
48.3801	0.7329005133017925	22.9138	1.41948	0.0293160205320717	1172.6120347274746	0.02889452392169435	1206.9883532136996
48.7901	0.7438025133017925	22.9359	1.43215	0.0297521005320717	1173.7430006068782	0.02931809417860699	1208.6643203597496
49.1901	0.7540165133017924	22.9443	1.4439	0.030160660532071698	1174.1728699909047	0.02971477117685634	1209.5866993286686
49.6001	0.7641615133017925	22.961	1.45575	0.0305664605320717	1175.0274912662912	0.030108612749665652	1210.9439227021815
50.0101	0.7750435133017924	22.9732	1.46848	0.0310017405320717	1175.651825371663	0.03053089323133358	1212.099078217892
50.4101	0.7848165133017925	22.9823	1.48022	0.0313926605320717	1176.1175172043588	0.03090998658465147	1213.0389751677783
50.8201	0.7954145133017925	22.9982	1.49246	0.031816580532071696	1176.9311985384095	0.03132091922059354	1214.3771247974144
51.2201	0.8055625133017925	23.0159	1.50458	0.0322225005320717	1177.8369947404656	0.03171424511152004	1215.7898479301841
51.6501	0.8164305133017925	23.0162	1.51799	0.0326572205320717	1177.8523472184665	0.032135305962656256	1216.3177310757983
52.0501	0.8269225133017925	23.0497	1.52947	0.0330769005320717	1179.5667072619065	0.03254163125059597	1218.5831179089519
52.4601	0.8371625133017925	23.0548	1.54156	0.0334865005320717	1179.8276993879226	0.03293803815991485	1219.3360002712293
52.8601	0.8473135133017925	23.0636	1.55388	0.0338925405320717	1180.2780387426174	0.03333084470110141	1220.2806600098156
53.2801	0.8582155133017925	23.0804	1.56619	0.034328620532071696	1181.1377775106707	0.033752540421725125	1221.684608070929
53.6901	0.8691545133017925	23.0951	1.57906	0.0347661805320717	1181.8900489327173	0.0341754886658538	1222.9798517429713
54.1001	0.8791905133017924	23.1123	1.59078	0.035167620532071696	1182.7702576714387	0.03456336580938998	1224.3654732698485
54.5001	0.8894955133017924	23.1196	1.6026	0.0355798205320717	1183.1438346361283	0.03496148293103426	1225.2398799361088
54.9001	0.8999755133017925	23.1316	1.61513	0.0359990205320717	1183.7579337561665	0.035366198404481186	1226.3720599184576
55.3101	0.9107455133017924	23.1415	1.62757	0.036429820532071694	1184.264565530198	0.035781942479905085	1227.4071111149551
55.7301	0.9213355133017924	23.1459	1.64	0.0368534205320717	1184.4897352075454	0.03619056972147466	1228.1422335350712
56.1601	0.9320825133017925	23.1579	1.65252	0.0372833005320717	1185.1038343275836	0.03660508434993627	1229.2884167445293
56.5601	0.9421955133017924	23.172	1.66431	0.037687820532071696	1185.8254007936282	0.036994988576571804	1230.5165756811105
56.9701	0.9533105133017925	23.1759	1.67682	0.0381324205320717	1186.0249830076407	0.03742334937391186	1231.2509864212311
57.3701	0.9638555133017924	23.1952	1.68986	0.0385542205320717	1187.0126590923687	0.037829573401610396	1232.7770069253768
57.7701	0.9738165133017924	23.1989	1.70132	0.0389526605320717	1187.202006321047	0.038213148549800735	1233.4466830562653
58.1801	0.9842495133017924	23.2063	1.71376	0.0393699805320717	1187.580700778404	0.03861474163969263	1234.3357298483138
58.5901	0.9953885133017925	23.2282	1.72662	0.039815540532071696	1188.7014316724735	0.03904333254926411	1236.0302217057606
58.9901	1.0058055133017925	23.2301	1.73818	0.0402322205320717	1188.7986640331462	0.039443977201154744	1236.62667405276
59.4001	1.0162755133017924	23.2393	1.75035	0.040651020532071695	1189.2694733585088	0.03984649858956314	1237.6144911381714
59.8001	1.0266555133017925	23.2506	1.76241	0.0410662205320717	1189.847750029878	0.04024540003238691	1238.7103001321943
60.2101	1.0379755133017925	23.2582	1.77529	0.0415190205320717	1190.2366794725688	0.040680244184939846	1239.654140605615
60.6101	1.0482655133017924	23.2657	1.78765	0.041930620532071694	1190.6204914225927	0.041075358131773314	1240.5439474461423
61.0301	1.0590055133017924	23.2785	1.79978	0.042360220532071696	1191.2755304839668	0.04148758467676365	1241.7382246697282
61.4501	1.0700855133017924	23.2778	1.81226	0.042803420532071694	1191.2397080352978	0.04191268321382435	1242.228842212835
61.8601	1.0807355133017924	23.2872	1.82449	0.0432294205320717	1191.7207523459942	0.04232111398973168	1243.238149905956
62.2701	1.0916455133017924	23.3032	1.8372	0.04366582053207169	1192.539551172712	0.042739342943225726	1244.612769191617
62.6801	1.1026055133017925	23.3059	1.84953	0.0441042205320717	1192.6777234747206	0.04315931257380826	1245.2798448145388
63.0901	1.1132755133017924	23.3149	1.86122	0.0445310205320717	1193.1382978147492	0.04356800050317899	1246.2699638523388
63.4801	1.1239255133017925	23.3178	1.87396	0.0449570205320717	1193.2867051020914	0.04397575589352377	1246.9333200040144
63.8901	1.1347655133017924	23.3298	1.8861	0.0453906205320717	1193.9008042221296	0.044390615123348465	1248.0927025795115
64.3001	1.1456955133017925	23.3333	1.89842	0.045827820532071704	1194.0799164654743	0.044808744571506125	1248.8019965782053
64.7001	1.1563755133017926	23.3359	1.911	0.0462550205320717	1194.2129712748156	0.04521714140699704	1249.4513167807986
65.1101	1.1671755133017925	23.3478	1.92276	0.0466870205320717	1194.821952902187	0.04562995743119555	1250.6046299495015
65.5401	1.1782055133017924	23.353	1.93525	0.04712822053207169	1195.0880625208702	0.046051389081779706	1251.4104362866
65.9401	1.1895555133017925	23.358	1.9477	0.0475822205320717	1195.3439371542192	0.04648486188853017	1252.2210559835662
66.3501	1.2003755133017924	23.3753	1.95998	0.0480150205320717	1196.2292633856075	0.04689791836491088	1253.6662360281325
66.7601	1.2112055133017925	23.3601	1.97202	0.0484482205320717	1195.4514045002259	0.04731118581237221	1253.3688977808276
67.1801	1.2225755133017924	23.3659	1.98479	0.0489030205320717	1195.7482190749113	0.047744875695329266	1254.2239187835198
67.5901	1.2335055133017925	23.3732	1.99653	0.049340220532071696	1196.121796039601	0.04816160526964242	1255.1387092394125
68.0001	1.2447955133017925	23.3771	2.00888	0.0497918205320717	1196.3213782536134	0.04859187835216696	1255.888397618298
68.4101	1.2554155133017924	23.3968	2.02143	0.050216620532071696	1197.3295243090092	0.048996448160066305	1257.4553666830807
68.8001	1.2666255133017925	23.3899	2.03307	0.0506650205320717	1196.9764173149874	0.04942331657382589	1257.621252074657
69.2101	1.2771555133017924	23.3955	2.04472	0.0510862205320717	1197.2629969043385	0.04982412519228577	1258.4266383990825
69.6201	1.2884155133017925	23.4011	2.05783	0.0515366205320717	1197.5495764936895	0.0502525424986069	1259.267234585788
70.0201	1.2995555133017924	23.4078	2.06996	0.051982220532071695	1197.8924485023776	0.05067621353778794	1260.1615579341317
70.4301	1.3101855133017926	23.3998	2.081	0.0524074205320717	1197.4830490890188	0.05108032121584262	1260.2400468226544
70.8401	1.3218555133017924	23.4105	2.09418	0.0528742205320717	1198.0306208043862	0.051523777329784665	1261.3755560529721
71.2401	1.3326055133017924	23.4066	2.10578	0.0533042205320717	1197.831038590374	0.051932099813379234	1261.680488431556
71.6401	1.3437055133017926	23.4073	2.1173	0.053748220532071705	1197.8668610390425	0.0523535416322144	1262.2500732542294
72.0701	1.3554555133017925	23.4139	2.13036	0.0542182205320717	1198.2046155550636	0.05279946904228365	1263.169137643774
72.4801	1.3664755133017925	23.4083	2.14231	0.0546590205320717	1197.9180359657125	0.05321751139945479	1263.3950624893014
72.8801	1.3774255133017925	23.4147	2.15438	0.0550970205320717	1198.2455554963994	0.05363272528937159	1264.2653154700483
73.2801	1.3887455133017925	23.4157	2.16684	0.0555498205320717	1198.2967304230694	0.05406178807537338	1264.8618987422392
73.6901	1.4000955133017925	23.4168	2.17888	0.0560038205320717	1198.353022842406	0.0544918032056232	1265.4653704677378
74.1001	1.4114655133017924	23.4268	2.19093	0.05645862053207169	1198.8647721091045	0.05492239074951131	1266.551023346881
74.5101	1.4222855133017924	23.419	2.20232	0.0568914205320717	1198.4656076810797	0.05533197742246272	1266.6480185608889
74.9201	1.4336655133017924	23.4329	2.21505	0.05734662053207169	1199.1769391617906	0.055762581733039294	1267.945684042713
75.3401	1.4455055133017924	23.413	2.22688	0.0578202205320717	1198.1585581210607	0.05621039511467904	1267.4363501840094
75.7401	1.4566155133017924	23.4184	2.23969	0.058264620532071695	1198.4349027250778	0.05663041608728782	1268.2612575647445
76.1501	1.4683655133017925	23.4306	2.25169	0.0587346205320717	1199.05923683045	0.057074440816825237	1269.485526101162
76.5601	1.4795755133017925	23.4186	2.26326	0.0591830205320717	1198.445137710412	0.05749787560768373	1269.372740902089
76.9701	1.4917955133017924	23.438	2.27638	0.05967182053207169	1199.4379312878068	nan	nan
77.3801	1.5029055133017926	23.4179	2.28828	0.060116220532071704	1198.409315261743	nan	nan
77.7901	1.5146355133017924	23.422	2.30071	0.06058542053207169	1198.6191324610893	nan	nan
78.2001	1.5259555133017924	23.4212	2.31217	0.061038220532071696	1198.5781925197534	nan	nan
78.6101	1.5380155133017925	23.4186	2.32464	0.061520620532071704	1198.445137710412	nan	nan
79.0201	1.5494355133017925	23.4299	2.33663	0.0619774205320717	1199.023414381781	nan	nan
79.4301	1.5612255133017925	23.4221	2.34922	0.0624490205320717	1198.6242499537564	nan	nan
79.8301	1.5727155133017925	23.4226	2.36129	0.0629086205320717	1198.6498374170912	nan	nan
80.2301	1.5839055133017925	23.4177	2.37268	0.0633562205320717	1198.399080276409	nan	nan
80.6401	1.5953355133017924	23.4073	2.38492	0.06381342053207169	1197.8668610390425	nan	nan
81.0401	1.6071955133017926	23.4164	2.39776	0.0642878205320717	1198.332552871738	nan	nan
81.4501	1.6192455133017924	23.4063	2.40996	0.0647698205320717	1197.815686112373	nan	nan
81.8701	1.6310855133017925	23.3896	2.42223	0.0652434205320717	1196.9610648369865	nan	nan
82.2801	1.6431055133017924	23.4143	2.43536	0.06572422053207169	1198.2250855257314	nan	nan
82.6801	1.6543455133017924	23.3941	2.44706	0.0661738205320717	1197.191352007001	nan	nan
83.0901	1.6665655133017925	23.395	2.45933	0.0666626205320717	1197.2374094410036	nan	nan
83.4901	1.6783955133017925	23.3907	2.47141	0.0671358205320717	1197.0173572563233	nan	nan
83.9101	1.6908155133017924	23.3907	2.48424	0.0676326205320717	1197.0173572563233	nan	nan
84.3401	1.7029155133017924	23.3743	2.49669	0.0681166205320717	1196.178088458938	nan	nan
84.7401	1.7144955133017925	23.3743	2.50859	0.0685798205320717	1196.178088458938	nan	nan
85.1501	1.7269655133017925	23.365	2.5219	0.0690786205320717	1195.7021616409083	nan	nan
85.5501	1.7385255133017925	23.3642	2.53329	0.0695410205320717	1195.6612216995725	nan	nan
85.9801	1.7511055133017925	23.3596	2.54617	0.0700442205320717	1195.425817036891	nan	nan
86.3801	1.7629855133017924	23.3511	2.55862	0.07051942053207169	1194.9908301601972	nan	nan
86.7801	1.7748655133017925	23.3555	2.57041	0.0709946205320717	1195.2159998375448	nan	nan
87.1901	1.7876555133017924	23.3274	2.58323	0.0715062205320717	1193.7779843981223	nan	nan
87.6001	1.7992855133017924	23.3194	2.59531	0.0719714205320717	1193.3685849847634	nan	nan
88.0101	1.8117055133017925	23.3123	2.60781	0.0724682205320717	1193.0052430054075	nan	nan
88.4301	1.8245555133017926	23.3119	2.62126	0.0729822205320717	1192.9847730347396	nan	nan
88.8301	1.8365255133017924	23.2929	2.63261	0.0734610205320717	1192.0124494280124	nan	nan
89.2301	1.8486255133017924	23.2929	2.64472	0.07394502053207169	1192.0124494280124	nan	nan
89.6501	1.8611955133017926	23.2641	2.65743	0.0744478205320717	1190.5386115399208	nan	nan
90.0501	1.8735055133017924	23.2486	2.66896	0.0749402205320717	1189.7454001765384	nan	nan
90.4601	1.8855755133017924	23.2455	2.68205	0.0754230205320717	1189.5867579038618	nan	nan
90.8601	1.8975155133017925	23.2343	2.69265	0.0759006205320717	1189.0135987251597	nan	nan
91.2601	1.9098755133017924	23.1967	2.7049	0.0763950205320717	1187.0894214823736	nan	nan
91.6701	1.9227955133017924	23.1811	2.71774	0.0769118205320717	1186.291092626324	nan	nan
92.0701	1.9348555133017924	23.1658	2.72962	0.07739422053207169	1185.5081162482752	nan	nan
92.4901	1.9482455133017924	23.1561	2.74259	0.0779298205320717	1185.0117194595778	nan	nan
92.9001	1.9605955133017925	23.1289	2.75484	0.0784238205320717	1183.6197614541582	nan	nan
93.3101	1.9736755133017925	23.1178	2.76793	0.0789470205320717	1183.0517197681227	nan	nan
93.7101	1.9860055133017924	23.0701	2.77915	0.0794402205320717	1180.610675765971	nan	nan
94.1201	1.9985555133017925	23.0669	2.79169	0.0799422205320717	1180.4469160006279	nan	nan
94.5201	2.0113455133017926	23.0269	2.80381	0.0804538205320717	1178.399918933834	nan	nan
94.9301	2.0238355133017927	23.0127	2.81614	0.0809534205320717	1177.6732349751219	nan	nan
95.3301	2.0365655133017926	22.9748	2.82795	0.0814626205320717	1175.733705254335	nan	nan
95.7601	2.049955513301793	22.9498	2.84106	0.08199822053207172	1174.454332087589	nan	nan
96.1601	2.0627355133017926	22.9159	2.8532	0.0825094205320717	1172.7195020734814	nan	nan
96.5701	2.0752855133017927	22.8867	2.86535	0.08301142053207171	1171.2251942147218	nan	nan
96.9701	2.0880455133017928	22.8533	2.87751	0.08352182053207172	1169.515951663949	nan	nan
97.3801	2.1007155133017927	22.8368	2.88942	0.0840286205320717	1168.6715653738966	nan	nan
97.7901	2.1140355133017925	22.7929	2.90236	0.0845614205320717	1166.4249860930902	nan	nan
98.2001	2.1267855133017926	22.7509	2.91451	0.0850714205320717	1164.275639172957	nan	nan
98.6101	2.1395255133017925	22.7386	2.9269	0.0855810205320717	1163.646187574918	nan	nan
99.0301	2.152715513301793	22.6881	2.93962	0.08610862053207172	1161.0618537780906	nan	nan
99.4401	2.1655855133017927	22.6699	2.95158	0.08662342053207171	1160.1304701126994	nan	nan
99.8501	2.1791455133017927	22.6202	2.9641	0.08716582053207171	1157.5870762572083	nan	nan
100.25	2.1915455133017927	22.5842	2.97644	0.08766182053207171	1155.744778897094	nan	nan
100.65	2.2044955133017927	22.5651	2.9883	0.08817982053207171	1154.7673377977	nan	nan
101.06	2.217595513301793	22.5204	3.00055	0.08870382053207171	1152.4798185755578	nan	nan
101.47	2.2303155133017927	22.479	3.01203	0.08921262053207171	1150.3611766114263	nan	nan
101.87	2.2430555133017926	22.4559	3.02468	0.08972222053207171	1149.179035805353	nan	nan
102.29	2.256365513301793	22.4105	3.03741	0.09025462053207171	1146.855694134542	nan	nan
102.71	2.2698955133017926	22.3859	3.05029	0.0907958205320717	1145.5967909384638	nan	nan
103.12	2.2834355133017925	22.3406	3.06255	0.0913374205320717	1143.2785667603198	nan	nan
103.53	2.295955513301793	22.3099	3.07466	0.09183822053207172	1141.7074965115555	nan	nan
103.93	2.3091255133017925	22.2664	3.08675	0.0923650205320717	1139.4813872014176	nan	nan
104.33	2.3212855133017927	22.2262	3.09835	0.09285142053207171	1137.4241551492896	nan	nan
104.74	2.334995513301793	22.193	3.11191	0.09339982053207171	1135.725147583851	nan	nan
105.15	2.3481755133017925	22.1592	3.12371	0.0939270205320717	1133.99543506241	nan	nan
105.55	2.3601155133017926	22.1104	3.13574	0.0944046205320717	1131.4980986409216	nan	nan
105.96	2.373845513301793	22.0946	3.14804	0.09495382053207171	1130.6895347995383	nan	nan
106.36	2.3867055133017927	22.0277	3.16002	0.09546822053207171	1127.2659322053257	nan	nan
106.77	2.3995055133017926	22.0047	3.1725	0.09598022053207171	1126.0889088919193	nan	nan
107.17	2.412625513301793	21.9579	3.1846	0.09650502053207172	1123.6939223237705	nan	nan
107.61	2.4267655133017927	21.9256	3.19827	0.0970706205320717	1122.0409721923345	nan	nan
108.02	2.4399155133017927	21.8733	3.21099	0.0975966205320717	1119.3645235275017	nan	nan
108.43	2.4528455133017926	21.8469	3.22297	0.0981138205320717	1118.013505463418	nan	nan
108.83	2.4653755133017925	21.7961	3.23491	0.0986150205320717	1115.4138191885897	nan	nan
109.23	2.4786155133017926	21.7766	3.24711	0.09914462053207171	1114.4159081185278	nan	nan
109.66	2.4924855133017925	21.7291	3.26071	0.0996994205320717	1111.9850991017101	nan	nan
110.06	2.5056555133017926	21.6712	3.27281	0.1002262205320717	1109.022070847526	nan	nan
110.47	2.5184655133017926	21.6606	3.28502	0.10073862053207171	1108.479616624826	nan	nan
110.87	2.531185513301793	21.5991	3.29708	0.10124742053207171	1105.3323586346305	nan	nan
111.28	2.5450555133017927	21.5572	3.30992	0.1018022205320717	1103.1881292071641	nan	nan
111.69	2.5575255133017927	21.5239	3.3216	0.10230102053207171	1101.4840041490584	nan	nan
112.1	2.5709555133017927	21.4845	3.33428	0.10283822053207171	1099.4677120382664	nan	nan
112.54	2.5852555133017927	21.4392	3.34792	0.1034102205320717	1097.1494878601225	nan	nan
112.95	2.5979655133017925	21.4036	3.35976	0.1039186205320717	1095.3276604706762	nan	nan
113.37	2.6113355133017926	21.3621	3.37225	0.1044534205320717	1093.2039010138776	nan	nan
113.78	2.6251755133017927	21.3219	3.38493	0.10500702053207171	1091.1466689617496	nan	nan
114.18	2.637875513301793	21.2748	3.39736	0.10551502053207171	1088.7363299156	nan	nan
114.59	2.6509755133017925	21.2344	3.409	0.1060390205320717	1086.6688628781385	nan	nan
115	2.6643455133017926	21.1864	3.42137	0.1065738205320717	1084.2124663979857	nan	nan
115.4	2.6776455133017927	21.1461	3.43372	0.10710582053207171	1082.150116853191	nan	nan
115.8	2.690485513301793	21.106	3.44588	0.10761942053207171	1080.0980022937304	nan	nan
116.21	2.703365513301793	21.0661	3.45763	0.10813462053207172	1078.0561227196035	nan	nan
116.61	2.7166855133017926	21.0175	3.46988	0.1086674205320717	1075.569021283449	nan	nan
117.02	2.7299655133017926	20.9739	3.48223	0.1091986205320717	1073.337794480644	nan	nan
117.42	2.742605513301793	20.9191	3.49386	0.10970422053207171	1070.5334084991364	nan	nan
117.83	2.7557755133017925	20.9031	3.50607	0.1102310205320717	1069.7146096724189	nan	nan
118.25	2.770005513301793	20.8495	3.51955	0.11080022053207171	1066.9716336029153	nan	nan
118.66	2.7834355133017925	20.7881	3.53196	0.1113374205320717	1063.8294931053867	nan	nan
119.06	2.7959955133017926	20.7504	3.5433	0.1118398205320717	1061.9001983699336	nan	nan
119.47	2.8090655133017925	20.7185	3.5555	0.1123626205320717	1060.2677182091657	nan	nan
119.87	2.8220355133017927	20.6638	3.5676	0.1128814205320717	1057.4684497203252	nan	nan
120.28	2.8352955133017925	20.6206	3.57991	0.1134118205320717	1055.2576928881879	nan	nan
120.68	2.8484555133017926	20.5699	3.59188	0.1139382205320717	1052.663124106027	nan	nan
121.11	2.8621555133017926	20.5315	3.60429	0.1144862205320717	1050.6980069219048	nan	nan
121.51	2.8753155133017927	20.4943	3.61713	0.1150126205320717	1048.7942996497866	nan	nan
121.92	2.8889355133017927	20.4191	3.62929	0.1155574205320717	1044.9459451642142	nan	nan
122.32	2.9017655133017928	20.398	3.64135	0.1160706205320717	1043.8661542114808	nan	nan
122.73	2.9149755133017927	20.3462	3.65319	0.1165990205320717	1041.2152930099828	nan	nan
123.14	2.9287155133017926	20.3072	3.66649	0.1171486205320717	1039.219470869859	nan	nan
123.54	2.9423355133017925	20.2586	3.67873	0.1176934205320717	1036.7323694337044	nan	nan
123.96	2.955535513301793	20.1966	3.69046	0.11822142053207171	1033.559523980174	nan	nan
124.37	2.9690055133017927	20.1704	3.70226	0.1187602205320717	1032.2187409014243	nan	nan
124.79	2.982175513301793	20.1094	3.71505	0.11928702053207171	1029.0970703745638	nan	nan
125.19	2.9959555133017925	20.064	3.72742	0.1198382205320717	1026.7737287037528	nan	nan
125.6	3.0100555133017926	20.019	3.74007	0.1204022205320717	1024.4708570036098	nan	nan
126.01	3.0226555133017925	19.9515	3.75202	0.1209062205320717	1021.0165494533953	nan	nan
126.42	3.0366255133017925	19.8986	3.76439	0.1214650205320717	1018.3093958325604	nan	nan
126.83	3.0492555133017927	19.8679	3.77655	0.12197022053207171	1016.7383255837962	nan	nan
127.24	3.0633955133017925	19.8133	3.78954	0.1225358205320717	1013.9441745876229	nan	nan
127.66	3.0773155133017926	19.7592	3.80197	0.1230926205320717	1011.1756110547843	nan	nan
128.06	3.0898055133017928	19.7135	3.81311	0.12359222053207171	1008.8369169059723	nan	nan
128.47	3.1036055133017926	19.6754	3.82637	0.1241442205320717	1006.8871521998514	nan	nan
128.88	3.1175155133017927	19.6142	3.83807	0.1247006205320717	1003.7552466876568	nan	nan
129.28	3.1301755133017926	19.5574	3.84965	0.1252070205320717	1000.8485108528098	nan	nan
129.69	3.1436955133017928	19.5098	3.86176	0.1257478205320717	998.4125843433251	nan	nan
130.08	3.1566355133017927	19.448	3.8735	0.1262654205320717	995.2499738751287	nan	nan
130.5	3.1708755133017927	19.4043	3.88676	0.1268350205320717	993.0136295796565	nan	nan
130.9	3.184105513301793	19.3285	3.89876	0.12736422053207172	989.1345701380824	nan	nan
131.31	3.196715513301793	19.2918	3.91006	0.1278686205320717	987.256450329299	nan	nan
131.72	3.2113055133017925	19.2479	3.9231	0.1284522205320717	985.009871048493	nan	nan
132.12	3.2245455133017926	19.1911	3.93512	0.12898182053207172	982.1031352136457	nan	nan
132.52	3.2378955133017926	19.1407	3.94717	0.1295158205320717	979.5239189094857	nan	nan
132.93	3.251285513301793	19.0818	3.95904	0.13005142053207172	976.5097157286319	nan	nan
133.34	3.2648055133017926	19.0255	3.97125	0.1305922205320717	973.6285673571196	nan	nan
133.74	3.2779155133017928	18.968	3.98372	0.1311166205320717	970.6860090736036	nan	nan
134.15	3.291485513301793	18.9026	3.99545	0.13165942053207172	967.3391688693957	nan	nan
134.55	3.3047255133017925	18.8692	4.00728	0.1321890205320717	965.629926318623	nan	nan
134.96	3.318675513301793	18.7989	4.01951	0.1327470205320717	962.032328973733	nan	nan
135.37	3.3325455133017927	18.7525	4.03247	0.1333018205320717	959.6578123762522	nan	nan
135.78	3.3463655133017927	18.683	4.04446	0.1338546205320717	956.1011549726979	nan	nan
136.19	3.3603455133017928	18.626	4.05755	0.1344138205320717	953.1841841525169	nan	nan
136.6	3.3730155133017927	18.5583	4.06818	0.1349206205320717	949.7196416169684	nan	nan
137.02	3.3870955133017926	18.5253	4.08204	0.1354838205320717	948.0308690368637	nan	nan
137.43	3.400755513301793	18.4493	4.09362	0.1360302205320717	944.1415746099553	nan	nan
137.84	3.4144155133017926	18.3824	4.10611	0.1365766205320717	940.7179720157429	nan	nan
138.25	3.4277055133017926	18.3254	4.11835	0.1371082205320717	937.8010011955616	nan	nan
138.67	3.442105513301793	18.2644	4.1307	0.13768422053207172	934.6793306687011	nan	nan
139.08	3.455605513301793	18.2026	4.14293	0.13822422053207173	931.5167202005048	nan	nan
139.49	3.469555513301793	18.141	4.15504	0.1387822205320717	928.3643447176424	nan	nan
139.89	3.4832855133017926	18.0838	4.16759	0.1393314205320717	925.4371389121274	nan	nan
140.29	3.4965155133017927	18.0237	4.1791	0.1398606205320717	922.3615258192698	nan	nan
140.7	3.5097755133017925	17.9613	4.19149	0.1403910205320717	919.1682103950716	nan	nan
141.11	3.5234155133017926	17.9082	4.20403	0.1409366205320717	916.4508217889028	nan	nan
141.52	3.5375855133017926	17.8472	4.21638	0.1415034205320717	913.3291512620423	nan	nan
141.92	3.5502755133017927	17.7599	4.22773	0.1420110205320717	908.8615801637648	nan	nan
142.35	3.5650855133017925	17.7142	4.24137	0.1426034205320717	906.522886014953	nan	nan
142.78	3.5797355133017925	17.6363	4.25502	0.1431894205320717	902.5363592273721	nan	nan
143.19	3.593745513301793	17.569	4.26744	0.14374982053207172	899.0922866624916	nan	nan
143.61	3.607445513301793	17.5055	4.27937	0.1442978205320717	895.8426788189565	nan	nan
144.01	3.6209155133017927	17.4414	4.29173	0.14483662053207172	892.5623660194196	nan	nan
144.43	3.6352255133017928	17.3636	4.30454	0.14540902053207172	888.5809567245058	nan	nan
144.83	3.648865513301793	17.3007	4.3163	0.14595462053207173	885.3620538369724	nan	nan
145.25	3.6626055133017927	17.2263	4.32886	0.1465042205320717	881.554639292736	nan	nan
145.66	3.6766055133017925	17.151	4.34066	0.1470642205320717	877.7011673144967	nan	nan
146.08	3.690615513301793	17.0898	4.35388	0.1476246205320717	874.5692618023023	nan	nan
146.49	3.7046055133017926	17.0219	4.3661	0.1481842205320717	871.0944842814198	nan	nan
146.91	3.7188555133017926	16.9301	4.37898	0.1487542205320717	866.3966260131282	nan	nan
147.31	3.7329555133017926	16.8667	4.39133	0.1493182205320717	863.1521356622601	nan	nan
147.74	3.747285513301793	16.7977	4.40412	0.14989142053207172	859.6210657220408	nan	nan
148.14	3.7600655133017926	16.7284	4.41596	0.1504026205320717	856.0746433038207	nan	nan
148.55	3.7749855133017927	16.6599	4.42922	0.15099942053207172	852.5691608269364	nan	nan
148.98	3.7899655133017927	16.5716	4.44215	0.1515986205320717	848.0504148019891	nan	nan
149.39	3.8037155133017926	16.4874	4.45338	0.1521486205320717	843.7414859763883	nan	nan
149.8	3.8176355133017927	16.4254	4.46616	0.1527054205320717	840.5686405228579	nan	nan