File: original_data/46NT9Z.csv
Specimen name:	AWA_2_14_Rz
Specimen ID:	46NT9Z
Material:	42CrMoS4
Specimen type:	Round Tensile Specimen
Gauge diameter:	4.995	mm
Gauge length:	25	mm
Parallel length:	30	mm
Original cross-section:	19.59570381172042	mm²
Cross-section after fracture:	9.410626853010825	mm²
Yield stress at 0.2% plastic strain:	1106.0144753956063	MPa
Yield stress at 1% plastic strain:	1138.089092522478	MPa
Ultimate tensile strength:	1191.5417901976366	MPa
Uniform elongation:	4.960800775977732	%
Elongation after fracture:	14.109564896076632	%
Reduction of area:	51.97607116626135	%
Slope of linear-elastic region:	208149.984605333	MPa
Crosshead seperation speed:	0.030028062657001205	mm/s
Strain rate:	0.0010009354219000402	s-1
Test temperature:	RT	Cel
Machine type:	INSTRON 8852TT
Standard:	DIN EN ISO 6892-1
Date:	2022-08-23 00:00:00
Heat treatment batch:	Batch 2
Time	Displacement	Force	Machine Displacement	Engineering Strain	Engineering Stress	True Strain	True Stress
s	mm	kN	mm		MPa		MPa
0	0.0003003968702424109	0.0494465	0	1.2015874809696435e-05	2.5233337100362516	1.2015802619544551e-05	2.523364030098214
0.450001	0.0006297348702424109	0.0480596	-0.000114441	2.5189394809696433e-05	2.4525579923929546	2.518907756229906e-05	2.4526197708445188
0.870001	0.0003417595702424109	0.0488072	-0.000366211	1.3670382809696434e-05	2.490709212026763	1.3670289370918006e-05	2.4907432609751594
1.31	0.0005432968702424109	0.0904793	0.0067215	2.1731874809696436e-05	4.617302898091533	2.173163867592367e-05	4.617403240740073
1.7	0.0008747848702424109	0.154353	0.0185471	3.4991394809696435e-05	7.876879620301244	3.499078262509456e-05	7.877155243305906
2.11	0.001320656870242411	0.248139	0.0315628	5.282627480969644e-05	12.662928690093038	5.282487955110751e-05	12.663597625443915
2.51	0.002005846870242411	0.361736	0.0433044	8.023387480969645e-05	18.459964667543172	8.023065624442276e-05	18.4614457820373
2.93	0.002642636870242411	0.518652	0.0559769	0.00010570547480969643	26.46763826312726	0.00010569988837967471	26.470436037396954
3.35	0.003270826870242411	0.689062	0.0689926	0.00013083307480969643	35.163932187414666	0.00013082451690946375	35.16853279278515
3.77001	0.003708166870242411	0.865812	0.0811996	0.00014832667480969643	44.18376641731785	0.0001483156754961021	44.190320048471094
4.19001	0.005076786870242411	1.09559	0.0944748	0.00020307147480969642	55.909704010973826	0.00020305085858885803	55.92105767702351
4.59001	0.006413416870242411	1.31709	0.105682	0.00025653667480969643	67.21320206994726	0.0002565037749035444	67.2304447213096
5.01001	0.008035036870242412	1.58756	0.117767	0.00032140147480969646	81.0157172844418	0.0003213498364197702	81.04175585545978
5.41001	0.009862546870242411	1.87844	0.130051	0.0003945018748096964	95.85978733136817	0.0003944240794047183	95.89760419718925
5.82001	0.011755296870242411	2.20133	0.143333	0.00047021187480969647	112.33737870049652	0.0004701013598483356	112.39020106994649
6.23001	0.01364129687024241	2.51039	0.154922	0.0005456518748096964	128.1092031253558	0.0005455030609567078	128.17910615222152
6.66001	0.015874896870242412	2.88364	0.16777	0.0006349958748096965	147.15674556558983	0.0006347943502362414	147.2501894919744
7.07001	0.018067396870242412	3.21766	0.179962	0.0007226958748096964	164.20231857533383	0.0007224348558965548	164.3209869136024
7.48001	0.02031239687024241	3.57158	0.192711	0.0008124958748096964	182.2634203045974	0.0008121659787171178	182.41150858172358
7.88001	0.02269989687024241	3.96642	0.205055	0.0009079958748096965	202.41273485811914	0.0009075838959199446	202.59652478637926
8.29001	0.02481759687024241	4.32547	0.216927	0.0009927038748096964	220.73562866432417	0.0009922114701658431	220.9547537782078
8.69001	0.027384796870242412	4.70698	0.22921	0.0010953918748096965	240.20469207054967	0.0010947923708846275	240.46781033853495
9.09001	0.02980959687024241	5.10272	0.241089	0.0011923838748096965	260.39993505862253	0.0011916735497547023	260.71043174218795
9.50001	0.03219749687024241	5.49538	0.25367	0.0012878998748096964	280.4380007373427	0.0012870712431525939	280.79917680338417
9.91001	0.034644196870242415	5.89195	0.265274	0.0013857678748096967	300.6755999483905	0.001384808584641677	301.09226653553816
10.32	0.03721829687024241	6.29568	0.277328	0.0014887318748096963	321.2785853720896	0.0014876248121224005	321.7568830428268
10.72	0.039827896870242414	6.73346	0.289589	0.0015931158748096967	343.6191965696399	0.0015918482118917733	344.16662176658434
11.13	0.042279596870242415	7.13544	0.301392	0.0016911838748096967	364.13287670393396	0.0016897554336381846	364.74869235330374
11.53	0.04487199687024242	7.54462	0.313484	0.0017948798748096968	385.01398431463707	0.0017932710027942446	385.70503816660374
11.93	0.04728559687024241	7.95087	0.326027	0.0018914238748096964	405.74556935507934	0.0018896373849909744	406.5130062120558
12.35	0.050020196870242416	8.38396	0.338768	0.0020008078748096968	427.8468423770243	0.0019988089246331746	428.7028817084647
12.76	0.05249439687024241	8.80138	0.351059	0.0020997758748096964	449.14845032184	0.002097574426607503	450.091561402034
13.18	0.055043896870242415	9.23197	0.363022	0.0022017558748096966	471.12214435892076	0.002199335562317385	472.159440308016
13.6	0.057669596870242416	9.6476	0.375366	0.0023067838748096967	492.3324057505737	0.0023041273334805322	493.46811020520533
14.01	0.06040969687024241	10.0853	0.388077	0.0024163878748096963	514.6689344206083	0.002413473104162378	515.9125741932835
14.42	0.06271459687024242	10.4868	0.399818	0.002508583874809697	535.1581193898085	0.002505442630567667	536.5006084185833
14.83	0.06537029687024241	10.8922	0.411682	0.0026148118748096968	555.8463275753968	0.002611399201943266	557.2997611533103
15.24	0.06791469687024242	11.3465	0.42495	0.002716587874809697	579.0299807049302	0.0027129046190529126	580.6029665296644
15.66	0.07054139687024241	11.7688	0.437141	0.0028216558748096966	600.580622828201	0.0028176824764921025	602.2752546709011
16.08	0.07324989687024241	12.2161	0.450325	0.0029299958748096964	623.4070548001143	0.002925711803064799	625.2336348990059
16.51	0.07572169687024241	12.6201	0.463051	0.0030288678748096962	644.0238187541787	0.0030242900958371327	645.9744818094155
16.91	0.07824269687024242	13.0506	0.475647	0.0031297078748096967	665.9929199478042	0.0031248205337634947	668.0772832339323
17.33	0.08063969687024242	13.4331	0.487061	0.0032255878748096967	685.5125046320361	0.0032203968260346235	687.7236854550076
17.72	0.08317909687024241	13.8593	0.499596	0.0033271638748096966	707.262169971695	0.0033216411117861387	709.6153471136445
18.14	0.08592169687024241	14.2966	0.512497	0.0034368678748096966	729.5782860041514	0.003430975341793864	732.0857501774778
18.53	0.08819819687024241	14.6777	0.523766	0.0035279278748096966	749.0264264568591	0.0035217193351665976	751.6689376657254
18.94	0.09081219687024242	15.0986	0.536423	0.0036324878748096967	770.5056243486059	0.0036259063241826837	773.3044766865249
19.36	0.09345809687024241	15.5212	0.549667	0.0037383238748096965	792.0715759500605	0.0037313537078733287	795.0325960329927
19.77	0.09564689687024241	15.9083	0.561279	0.0038258758748096968	811.8259059664425	0.0038185758251700276	814.9318511146251
20.18	0.09823759687024242	16.3225	0.573578	0.003929503874809697	832.9631921787532	0.003921803540196657	836.2363242699935
20.59	0.10054439687024241	16.7165	0.585152	0.004021775874809697	853.0696401933604	0.004013710152668367	856.5004950918228
21.01	0.10294439687024241	17.0984	0.597229	0.004117775874809697	872.5586059212249	0.004109321037867419	876.1516066980448
21.41	0.10568939687024241	17.5382	0.610252	0.004227575874809697	895.0023009385454	0.004218664781973662	898.7859910738923
21.82	0.10809939687024242	17.9235	0.622154	0.004323975874809697	914.6647740858251	0.004314654352159355	918.6197625025105
22.23	0.11067939687024242	18.3491	0.634842	0.004427175874809697	936.3838204691167	0.004417404760044363	940.5293563286598
22.65	0.11295739687024241	18.7308	0.646698	0.004518295874809696	955.8625798781919	0.004508119019185632	960.1814498297406
23.05	0.11584339687024242	19.1567	0.660057	0.004633735874809697	977.5969357396673	0.004623033170332633	982.1268617319082
23.47	0.11824039687024242	19.5607	0.67202	0.004729615874809696	998.2136996937318	0.004718466383035992	1002.9348670542558
23.87	0.12044339687024241	19.9224	0.683861	0.004817735874809697	1016.6718272238929	0.004806167725310472	1021.5698835588178
24.28	0.12296039687024242	20.3047	0.69593	0.004918415874809697	1036.1812055893354	0.004906359981887684	1041.2775756800854
24.69	0.1255953968702424	20.6899	0.708359	0.005023815874809696	1055.8385755772206	0.0050112386181307735	1061.1429141744418
25.11	0.1285643968702424	21.0635	0.720444	0.005142575874809696	1074.9039790753357	0.00512939799103193	1080.4317543458653
25.53	0.1318763968702424	21.3957	0.732971	0.005275055874809697	1091.8566745840985	0.005261191503085897	1097.6162795498135
25.93	0.1364213968702424	21.6579	0.745522	0.005456855874809696	1105.2371585166622	0.005442021179516718	1111.2682783981718
26.33	0.1433553968702424	21.7331	0.757263	0.005734215874809696	1109.074734381379	0.005717837839260709	1115.434408329619
26.74	0.1540143968702424	21.6882	0.769615	0.006160575874809696	1106.7834158132168	0.006141677105738347	1113.6018390233153
27.15	0.16599439687024242	21.6559	0.782234	0.006639775874809697	1105.1350953287706	0.006617829654735275	1112.47294467314
27.55	0.17654239687024242	21.6649	0.794456	0.007061695874809697	1105.594379674282	0.007036878865448272	1113.4017509444407
27.96	0.1868783968702424	21.6778	0.806091	0.007475135874809696	1106.2526872361818	0.007447335501721762	1114.5220763851457
28.38	0.19760239687024242	21.7411	0.819778	0.007904095874809697	1109.4829871329446	0.007873022141456815	1118.2524470347137
28.78	0.2068563968702424	21.7707	0.831451	0.008274255874809696	1110.9935223137375	0.008240211883215207	1120.1861669926175
29.19	0.21664439687024242	21.8153	0.843475	0.008665775874809697	1113.2695314037157	0.008628443559670126	1122.9168756511147
29.6	0.22565639687024241	21.8506	0.855461	0.009026255874809697	1115.070946669999	0.0089857627126064	1125.135862353209
30	0.2350783968702424	21.8994	0.867912	0.009403135874809697	1117.5612884545496	0.00935920159129127	1128.0698690983152
30.4	0.2439413968702424	21.9321	0.879181	0.009757655874809696	1119.230021576574	0.009710357383431746	1130.1510829718738
30.83	0.25417939687024244	21.9714	0.892387	0.010167175874809697	1121.2355632186402	0.01011583782426206	1132.6353623869754
31.24	0.2636883968702424	22.0074	0.904655	0.010547535874809697	1123.0727006006857	0.010492298689599045	1134.918350200291
31.64	0.2728723968702424	22.0244	0.916718	0.010914895874809696	1123.9402376977625	0.010855758329782604	1136.2079283617425
32.06	0.2831073968702424	22.0565	0.929192	0.011324295874809695	1125.5783518634196	0.011260656036506252	1138.3247341502015
32.47	0.2930763968702424	22.095	0.942177	0.011723055874809696	1127.5430682303293	0.011654873210730334	1140.7613186204476
32.88	0.3027393968702424	22.1145	0.954483	0.012109575874809698	1128.5381843122705	0.012036841559926731	1142.20430308282
33.31	0.3125703968702424	22.1363	0.966202	0.012502815874809696	1129.6506730602869	0.012425301105613056	1143.7744874284144
33.71	0.32291839687024243	22.1719	0.978561	0.012916735874809697	1131.467397804754	0.012834026305688003	1146.0822633331563
34.12	0.3328843968702424	22.1905	0.990402	0.013315375874809696	1132.416585452144	0.01322750541682409	1147.4951379343079
34.54	0.3430023968702424	22.2126	1.00312	0.013720095874809697	1133.544383678344	0.013626827491862642	1149.096721300763
34.93	0.35275339687024243	22.2321	1.01493	0.014110135874809698	1134.5394997602853	0.014011514531934574	1150.5480062572415
35.35	0.3630983968702424	22.2518	1.02715	0.014523935874809697	1135.5448221610156	0.014419473770617988	1152.0374023410545
35.7601	0.3728693968702424	22.278	1.03931	0.014914775874809695	1136.881849922393	0.014804644313161653	1153.8381879101244
36.1701	0.3827263968702424	22.2935	1.05143	0.015309055874809695	1137.6728396285514	0.015193054693131569	1155.0895366976783
36.5801	0.3928713968702424	22.3224	1.06416	0.015714855874809697	1139.1476526935821	0.01559265609915374	1157.0491938757896
36.9901	0.4034553968702424	22.3442	1.07652	0.016138215874809694	1140.2601414415988	0.016009379150650965	1158.6619057576245
37.3901	0.4130363968702424	22.358	1.08779	0.016521455874809698	1140.9643774380495	0.0163864614629213	1159.814770054622
37.8001	0.4226033968702424	22.3691	1.09956	0.016904135874809698	1141.5308281308467	0.016762850946825184	1160.8274203548544
38.2101	0.4334833968702424	22.4014	1.11309	0.017339335874809694	1143.179148615293	0.01719072500682188	1163.0011158382124
38.6301	0.4437793968702424	22.4116	1.12535	0.017751175874809698	1143.6996708735392	0.01759546376732836	1164.0016848791772
39.0401	0.4536513968702424	22.4388	1.13773	0.018146055874809698	1145.0877302288623	0.01798338119144355	1165.8665561631542
39.4501	0.4639263968702424	22.4558	1.14996	0.018557055874809696	1145.9552673259393	0.018386974629493315	1167.2208232517391
39.8601	0.4735013968702424	22.4665	1.16164	0.018940055874809694	1146.5013053811583	0.018762926087095354	1168.2161041656195
40.2701	0.4835863968702424	22.4851	1.17438	0.019343455874809696	1147.4504930285484	0.019158749340280404	1169.6461510089748
40.6801	0.4934023968702424	22.5008	1.18645	0.019736095874809696	1148.2516890534962	0.01954386428541901	1170.913694477068
41.1001	0.5035393968702424	22.5266	1.19935	0.020141575874809695	1149.568304177295	0.019941417541632513	1172.7224213991583
41.5101	0.5141523968702424	22.5499	1.2126	0.020566095874809696	1150.75734031623	0.02035746929857978	1174.4239261058146
41.9301	0.5244273968702424	22.5696	1.22501	0.020977095874809698	1151.7626627169604	0.020760105899376054	1175.9232985178003
42.3601	0.5343603968702424	22.5782	1.23782	0.021374415874809694	1152.2015344248935	0.02114918682176045	1176.829169193285
42.7601	0.5445163968702424	22.605	1.24947	0.021780655874809696	1153.5691811426384	0.021546846315129653	1178.6946745048922
43.1701	0.5545483968702424	22.6196	1.26193	0.022181935874809697	1154.3142424142454	0.0219394953849074	1179.9191669188576
43.5801	0.5643093968702424	22.6223	1.27402	0.022572375874809696	1154.452027717899	0.022321389681451295	1180.5107528169838
43.9801	0.5741703968702424	22.6485	1.28661	0.022966815874809695	1155.7890554792764	0.022707048393325165	1182.3338499065892
44.3901	0.5841373968702425	22.6595	1.29901	0.023365495874809697	1156.3504030126792	0.02309670163073449	1183.3691035841066
44.7901	0.5937673968702424	22.6776	1.31081	0.023750695874809696	1157.2740748630965	0.02347303591610497	1184.7601394589717
45.2001	0.6034383968702424	22.695	1.3233	0.024137535874809695	1158.1620245977517	0.02385082997596007	1186.1172020153222
45.6301	0.6137183968702424	22.7176	1.33581	0.0245487358748097	1159.3153386209246	0.024252257965391332	1187.7750646643453
46.0401	0.6243153968702424	22.7383	1.34853	0.024972615874809697	1160.3716926156005	0.024665896013788987	1189.3492091672924
46.4401	0.6338893968702424	22.7375	1.36018	0.025355575874809695	1160.330867340444	0.02503945572583358	1189.7517246871782
46.8501	0.6441623968702425	22.7628	1.37299	0.025766495874809697	1161.6219666672703	0.02544013398009954	1191.5528942794908
47.2501	0.6537633968702424	22.7751	1.38525	0.026150535874809696	1162.2496552728026	0.02581445711163173	1192.6431065784993
47.6701	0.6639653968702424	22.7934	1.39762	0.026558615874809694	1163.1835334420089	0.026212058501023018	1194.076078098599
48.0901	0.6741653968702425	22.8066	1.40981	0.0269666158748097	1163.857150482092	0.02660942396706204	1195.2424391922932
48.5101	0.6840843968702424	22.8261	1.42249	0.027363375874809696	1164.8522665640335	0.02699569102885509	1196.7265569726492
48.9201	0.6939543968702424	22.8343	1.4348	0.027758175874809696	1165.270725634388	0.02737990188443251	1197.6165153783147
49.3301	0.7039013968702424	22.8481	1.44698	0.028156055874809696	1165.9749616308388	0.027766960837401294	1198.8042177991458
49.7301	0.7138073968702424	22.8605	1.45905	0.028552295874809695	1166.6077533957657	0.02815227556086732	1199.9170831405686
50.1501	0.7238973968702425	22.8814	1.4711	0.0289558958748097	1167.6743137092308	0.028544594781558737	1201.4853695526851
50.5501	0.7339583968702424	22.8807	1.48314	0.029358335874809696	1167.6385915934688	0.0289356332332397	1201.9185175458597
50.9701	0.7447113968702425	22.9189	1.4965	0.0297884558748097	1169.587998482195	0.02935339850182462	1204.4282189666887
51.3901	0.7543903968702425	22.9172	1.50838	0.0301756158748097	1169.501244772487	0.02972928855725633	1204.7916650998534
51.8101	0.7646373968702425	22.9463	1.52134	0.030585495874809698	1170.986264156307	0.03012708333615437	1206.8014597081187
52.2101	0.7740453968702424	22.9436	1.53273	0.030961815874809697	1170.8484788526537	0.030492168340059023	1207.1000738721905
52.6301	0.7844823968702425	22.9637	1.54567	0.0313792958748097	1171.8742138909624	0.030897028625609356	1208.646801576707
53.0501	0.7945373968702424	22.9826	1.55798	0.0317814958748097	1172.8387110165363	0.031286915838184555	1210.1132796725256
53.4501	0.8043203968702424	22.9936	1.57	0.0321728158748097	1173.4000585499389	0.0316661102830047	1211.1516425811571
53.8601	0.8145863968702424	23.0079	1.58253	0.032583455874809694	1174.1298103433624	0.03206387152100886	1212.387017209984
54.2701	0.8248283968702425	23.0161	1.59414	0.0329931358748097	1174.5482694137172	0.03246054527012884	1213.3003000580065
54.6801	0.8346083968702425	23.0205	1.60609	0.0333843358748097	1174.7728084270782	0.03283917890316235	1213.991818440201
55.0801	0.8442573968702424	23.0357	1.61877	0.033770295874809696	1175.5484886550528	0.03321260041557075	1215.247108932119
55.4901	0.8544843968702425	23.0455	1.63062	0.0341793758748097	1176.048598275721	0.0336082386759449	1216.2452053632298
55.8901	0.8642753968702425	23.0596	1.64278	0.0345710158748097	1176.7681437503552	0.033986863382183506	1217.4502139289189
56.3001	0.8747163968702424	23.0728	1.65498	0.0349886558748097	1177.4417607904386	0.03439046614983525	1218.6388653713652
56.7201	0.8846853968702424	23.0833	1.66701	0.035387415874809695	1177.9775925268686	0.0347756715338928	1219.6631754848243
57.1301	0.8946313968702424	23.1032	1.67911	0.0357852558748097	1178.993121246388	0.035159840377291904	1221.1836917648307
57.5301	0.9046263968702424	23.1065	1.69144	0.0361850558748097	1179.161525506409	0.03554575324746645	1221.8295511922843
57.9501	0.9148703968702424	23.1153	1.70361	0.0365948158748097	1179.610603533131	0.035941125675501305	1222.7782363733993
58.3501	0.9250333968702424	23.1234	1.71549	0.0370013358748097	1180.0239594440914	0.03633321745756324	1223.686422307805
58.7501	0.9350183968702425	23.1298	1.72713	0.0374007358748097	1180.3505616453438	0.03671829228020676	1224.4965412411245
59.1701	0.9453183968702424	23.1386	1.73956	0.0378127358748097	1180.799639672066	0.03711535986965895	1225.4489045680562
59.5801	0.9560123968702424	23.15	1.75246	0.038240495874809696	1181.381399843047	0.03752744950157358	1226.558010390322
60.0001	0.9657523968702424	23.1465	1.76387	0.03863009587480969	1181.202789264237	0.0379026293573793	1226.832766261107
60.4101	0.9755153968702425	23.1667	1.77583	0.0390206158748097	1182.2336274619402	0.03827855395566772	1228.3651117134154
60.8201	0.9864283968702424	23.1903	1.7891	0.039457135874809694	1183.4379730790588	0.03869859213606259	1230.1330459822486
61.2501	0.9968053968702424	23.1853	1.80096	0.03987221587480969	1183.1828151093305	0.03909783625307969	1230.3589357327348
61.6601	1.0071703968702423	23.1906	1.81282	0.040286815874809694	1183.4532825572426	0.039496459626737174	1231.1308470480653
62.0601	1.0175303968702425	23.1938	1.82534	0.0407012158748097	1183.6165836578687	0.03989473198501616	1231.7912177423323
62.4601	1.0274903968702425	23.2086	1.83709	0.041099615874809696	1184.3718512482653	0.04027747753760458	1233.0490793875063
62.8801	1.0377903968702424	23.2165	1.84969	0.0415116158748097	1184.7750008404362	0.040673134680996294	1233.9569255734016
63.3001	1.0483903968702424	23.2176	1.86178	0.04193561587480969	1184.8311355937767	0.041080152434450366	1234.5177589725517
63.7101	1.0582803968702423	23.2223	1.87401	0.042331215874809695	1185.0709840853212	0.04145975834548287	1235.23647973961
64.1201	1.0688203968702423	23.2392	1.88705	0.042752815874809696	1185.9334180230037	0.04186415452264002	1236.6354110835248
64.5401	1.0793103968702424	23.2416	1.89917	0.043172415874809696	1186.0558938484733	0.04226647000286244	1237.2607921484687
64.9401	1.0893903968702423	23.2585	1.91121	0.043575615874809695	1186.918327786156	0.04265290861344988	1238.639024912537
65.3501	1.0996803968702424	23.2581	1.92318	0.0439872158748097	1186.8979151485776	0.043047244054830354	1239.1062499635798
65.7701	1.1103903968702424	23.2582	1.93594	0.044415615874809695	1186.903018307972	0.043457509736810805	1239.620046849791
66.1601	1.1206903968702424	23.2734	1.94768	0.0448276158748097	1187.6786985359468	0.04385191092388148	1240.9195030166102
66.5701	1.1311003968702424	23.2682	1.95953	0.045244015874809695	1187.4133342474292	0.044250366172193335	1241.1366819920806
66.9701	1.1414203968702423	23.2805	1.9724	0.04565681587480969	1188.0410228529613	0.04464521991092158	1242.2831930850793
67.3801	1.1517603968702423	23.2716	1.98409	0.04607041587480969	1187.5868416668445	0.04504068256887478	1242.299461349888
67.7801	1.1618303968702424	23.2901	1.9964	0.046473215874809695	1188.53092615484	0.04542566857238124	1243.7657804599214
68.1901	1.1720203968702425	23.2906	2.00921	0.0468808158748097	1188.556441951813	0.04581509147836751	1244.276937663775
68.6001	1.1825803968702424	23.2907	2.02093	0.0473032158748097	1188.5615451112076	0.046218494426078144	1244.7843284601004
69.0101	1.1927903968702425	23.3004	2.0331	0.047711615874809696	1189.0565515724809	0.046608372339097155	1245.788361014533
69.4201	1.2040203968702423	23.3029	2.04568	0.04816081587480969	1189.1841305573453	0.047037024388786215	1246.4562085103632
69.8401	1.2149103968702424	23.3139	2.05866	0.048596415874809694	1189.7454780907478	0.047452523140545294	1247.5628441292201
70.2601	1.2256003968702425	23.3155	2.0706	0.0490240158748097	1189.8271286410609	0.04786022321769047	1248.1572326838395
70.6701	1.2365003968702424	23.3178	2.08329	0.04946001587480969	1189.944501307136	0.048275761291535456	1248.7991752319297
71.0701	1.2468903968702425	23.3095	2.09531	0.0498756158748097	1189.5209390773869	0.048671696080755285	1248.8490285098535
71.5001	1.2580603968702424	23.3192	2.10823	0.0503224158748097	1190.01594553866	0.04909717977323198	1249.9004228477113
71.9201	1.2682803968702425	23.3264	2.12016	0.0507312158748097	1190.383373015069	0.049486317869453	1250.7729688852805
72.3101	1.2787303968702424	23.3179	2.13187	0.051149215874809695	1189.9496044665307	0.0498840569598375	1250.8145936655337
72.7101	1.2895403968702424	23.3302	2.144	0.051581615874809694	1190.577293072063	0.05029533166943515	1251.989193672577
73.1201	1.3001303968702425	23.3299	2.15611	0.0520052158748097	1190.561983593879	0.05069807235912972	1252.4774165630201
73.5301	1.3109903968702423	23.3356	2.16844	0.05243961587480969	1190.8528636793696	0.05111091283811603	1253.3007304141329
73.9401	1.3221203968702424	23.3374	2.18082	0.0528848158748097	1190.9447205484719	0.051533840535075245	1253.9276128117544
74.3601	1.3332703968702424	23.3286	2.19303	0.053330815874809694	1190.49564252175	0.05195734893558564	1253.9857464328404
74.7601	1.3437303968702423	23.3326	2.20525	0.05374921587480969	1190.6997688975325	0.05235448620535676	1254.698947818092
75.1801	1.3550903968702424	23.3405	2.21809	0.054203615874809694	1191.1029184897036	0.052785615403500324	1255.6650035508842
75.5901	1.3655003968702424	23.3281	2.22961	0.0546200158748097	1190.4701267247767	0.053180527523359666	1255.4936239449708
75.9901	1.3760503968702424	23.3309	2.24187	0.0550420158748097	1190.6130151878249	0.05358059160876999	1256.1467556705481
76.3901	1.3867703968702425	23.33	2.25369	0.055470815874809704	1190.5670867532738	nan	nan
76.8001	1.3984103968702424	23.3304	2.26679	0.05593641587480969	1190.5874993908521	nan	nan
77.2101	1.4091503968702423	23.332	2.27914	0.056366015874809695	1190.6691499411652	nan	nan
77.6101	1.4197003968702424	23.3311	2.29037	0.056788015874809694	1190.6232215066138	nan	nan
78.0301	1.4312603968702424	23.3343	2.30285	0.057250415874809696	1190.7865226072402	nan	nan
78.4401	1.4426603968702425	23.336	2.31584	0.0577064158748097	1190.8732763169478	nan	nan
78.8601	1.4536303968702424	23.3311	2.3282	0.0581452158748097	1190.6232215066138	nan	nan
79.2701	1.4651803968702424	23.3159	2.34059	0.058607215874809694	1189.847541278639	nan	nan
79.6801	1.4764003968702424	23.3103	2.35252	0.05905601587480969	1189.5617643525434	nan	nan
80.1001	1.4875903968702424	23.317	2.36534	0.0595036158748097	1189.9036760319796	nan	nan
80.5101	1.4983903968702423	23.3183	2.3782	0.059935615874809695	1189.9700171041088	nan	nan
80.9401	1.5102803968702425	23.3076	2.39073	0.0604112158748097	1189.42397904889	nan	nan
81.3601	1.5219803968702423	23.3185	2.40357	0.06087921587480969	1189.980223422898	nan	nan
81.7901	1.5342503968702423	23.3211	2.41655	0.0613700158748097	1190.112905567157	nan	nan
82.1901	1.5456303968702425	23.3067	2.42801	0.0618252158748097	1189.378050614339	nan	nan
82.6001	1.5571403968702424	23.3054	2.44046	0.0622856158748097	1189.3117095422092	nan	nan
83.0001	1.5681703968702425	23.2913	2.45234	0.0627268158748097	1188.592164067575	nan	nan
83.4101	1.5798103968702424	23.2971	2.46548	0.0631924158748097	1188.88814731246	nan	nan
83.8201	1.5907003968702425	23.2873	2.47717	0.06362801587480969	1188.388037691792	nan	nan
84.2201	1.6021003968702423	23.2783	2.48866	0.06408401587480969	1187.928753346281	nan	nan
84.6301	1.6139103968702424	23.2834	2.50169	0.0645564158748097	1188.1890144754038	nan	nan
85.0301	1.6254903968702423	23.277	2.51367	0.0650196158748097	1187.8624122741514	nan	nan
85.4401	1.6371603968702424	23.2762	2.5256	0.06548641587480969	1187.821586998995	nan	nan
85.8501	1.6492803968702423	23.2603	2.53813	0.0659712158748097	1187.0101846552582	nan	nan
86.2501	1.6608703968702425	23.2582	2.54993	0.0664348158748097	1186.903018307972	nan	nan
86.6501	1.6724303968702423	23.243	2.56212	0.06689721587480969	1186.1273380799973	nan	nan
87.0601	1.6842103968702424	23.2433	2.57446	0.0673684158748097	1186.1426475581814	nan	nan
87.4701	1.6957503968702423	23.2365	2.58637	0.06783001587480969	1185.7956327193504	nan	nan
87.8701	1.7077203968702424	23.2111	2.59821	0.06830881587480969	1184.4994302331295	nan	nan
88.2701	1.7188403968702424	23.2049	2.61066	0.0687536158748097	1184.183034350666	nan	nan
88.6801	1.7310303968702425	23.208	2.62269	0.0692412158748097	1184.3412322918978	nan	nan
89.1001	1.7437703968702425	23.1814	2.63496	0.0697508158748097	1182.9837918929422	nan	nan
89.5101	1.7556503968702424	23.1701	2.64705	0.0702260158748097	1182.4071348813557	nan	nan
89.9101	1.7678703968702425	23.1706	2.65886	0.0707148158748097	1182.4326506783284	nan	nan
90.3401	1.7808903968702423	23.1375	2.67168	0.0712356158748097	1180.7435049187256	nan	nan
90.7401	1.7927103968702425	23.123	2.68311	0.0717084158748097	1180.003546806513	nan	nan
91.1501	1.8044403968702425	23.11	2.69575	0.0721776158748097	1179.3401360852188	nan	nan
91.5501	1.8166703968702425	23.0958	2.70824	0.07266681587480969	1178.6154874511897	nan	nan
91.9601	1.8291003968702424	23.0656	2.72023	0.0731640158748097	1177.0743333140294	nan	nan
92.3601	1.8410703968702424	23.0549	2.73219	0.0736428158748097	1176.5282952588107	nan	nan
92.7701	1.8536803968702424	23.0314	2.74441	0.0741472158748097	1175.3290528010866	nan	nan
93.1701	1.8655903968702423	23.0121	2.75673	0.07462361587480969	1174.3441430379344	nan	nan
93.5901	1.8784903968702424	22.9835	2.76923	0.0751396158748097	1172.8846394510872	nan	nan
94.0201	1.8922703968702423	22.9522	2.78207	0.07569081587480969	1171.2873505605867	nan	nan
94.4201	1.9040603968702423	22.9317	2.7938	0.0761624158748097	1170.2412028846998	nan	nan
94.8301	1.9161203968702425	22.9039	2.8054	0.0766448158748097	1168.8225245730093	nan	nan
95.2401	1.9287703968702423	22.8827	2.81749	0.0771508158748097	1167.7406547813603	nan	nan
95.6401	1.9411103968702423	22.8633	2.83023	0.07764441587480969	1166.7506418588137	nan	nan
96.0501	1.9542203968702425	22.8354	2.84258	0.0781688158748097	1165.3268603877286	nan	nan
96.4501	1.9667703968702424	22.8017	2.8541	0.07867081587480969	1163.6070956717583	nan	nan
96.8501	1.9795103968702423	22.776	2.86555	0.07918041587480969	1162.2955837073537	nan	nan
97.2601	1.9931803968702424	22.7417	2.87853	0.0797272158748097	1160.545200035016	nan	nan
97.6701	2.0060903968702424	22.7118	2.8905	0.0802436158748097	1159.0193553760394	nan	nan
98.0701	2.018660396870242	22.6752	2.90224	0.08074641587480968	1157.1515990376267	nan	nan
98.4901	2.031740396870242	22.6483	2.91371	0.08126961587480969	1155.7788491604872	nan	nan
98.9001	2.0450503968702423	22.6043	2.92648	0.08180201587480969	1153.5334590268762	nan	nan
99.3001	2.057170396870242	22.578	2.93857	0.08228681587480968	1152.1913281061043	nan	nan
99.7101	2.0702203968702424	22.5435	2.95081	0.08280881587480969	1150.4307381149774	nan	nan
100.13	2.084010396870242	22.5152	2.96375	0.08336041587480969	1148.986544006314	nan	nan
100.54	2.097360396870242	22.4763	2.97617	0.08389441587480968	1147.0014150018262	nan	nan
100.94	2.1100703968702423	22.4246	2.98771	0.08440281587480969	1144.3630815948334	nan	nan
101.35	2.1228903968702424	22.4013	2.99964	0.0849156158748097	1143.1740454558983	nan	nan
101.75	2.1357603968702423	22.3725	3.0118	0.08543041587480969	1141.7043355502622	nan	nan
102.16	2.149160396870242	22.3375	3.02475	0.08596641587480969	1139.9182297621626	nan	nan
102.57	2.162110396870242	22.2929	3.03638	0.08648441587480969	1137.642220672184	nan	nan
102.97	2.174760396870242	22.2611	3.04842	0.08699041587480968	1136.0194159847106	nan	nan
103.39	2.187940396870242	22.2317	3.06098	0.08751761587480969	1134.519087122707	nan	nan
103.81	2.201220396870242	22.1896	3.07361	0.08804881587480969	1132.3706570175927	nan	nan
104.22	2.2150703968702423	22.1531	3.08578	0.0886028158748097	1130.5080038385745	nan	nan
104.63	2.2279403968702423	22.1203	3.09817	0.0891176158748097	1128.8341675571555	nan	nan
105.03	2.2406403968702424	22.0766	3.11003	0.0896256158748097	1126.6040869017284	nan	nan
105.44	2.254300396870242	22.0519	3.12275	0.09017201587480969	1125.3436065312694	nan	nan
105.84	2.267430396870242	21.9989	3.13519	0.09069721587480968	1122.638932052147	nan	nan
106.25	2.2797503968702424	21.9603	3.14686	0.0911900158748097	1120.6691125258428	nan	nan
106.65	2.292310396870242	21.9251	3.15917	0.09169241587480968	1118.8728004189543	nan	nan
107.06	2.3057703968702423	21.8946	3.17126	0.09223081587480969	1117.3163368036103	nan	nan
107.46	2.318630396870242	21.8621	3.18396	0.09274521587480969	1115.6578100003749	nan	nan
107.87	2.331780396870242	21.8157	3.19536	0.09327121587480969	1113.2899440412941	nan	nan
108.27	2.3441303968702423	21.7639	3.20688	0.0937652158748097	1110.6465074749067	nan	nan
108.68	2.357670396870242	21.7433	3.21931	0.09430681587480969	1109.5952566396254	nan	nan
109.09	2.371000396870242	21.7027	3.23144	0.09484001587480968	1107.5233739254297	nan	nan
109.49	2.3839203968702423	21.6653	3.24368	0.0953568158748097	1105.6147923118601	nan	nan
109.9	2.3977003968702424	21.6175	3.25671	0.0959080158748097	1103.1754821212555	nan	nan
110.3	2.410380396870242	21.5743	3.2682	0.09641521587480968	1100.970917262801	nan	nan
110.71	2.422330396870242	21.5371	3.2793	0.09689321587480969	1099.072541968021	nan	nan
111.12	2.436020396870242	21.5045	3.2924	0.09744081587480968	1097.4089120053911	nan	nan
111.52	2.4490803968702424	21.472	3.30434	0.09796321587480969	1095.7503852021557	nan	nan
111.92	2.4623703968702424	21.4301	3.31585	0.0984948158748097	1093.6121614158305	nan	nan
112.33	2.4751603968702423	21.3731	3.32794	0.09900641587480968	1090.7033605609256	nan	nan
112.74	2.488700396870242	21.3476	3.34097	0.09954801587480969	1089.4020549153101	nan	nan
113.14	2.5016703968702423	21.2999	3.3529	0.10006681587480969	1086.9678478841001	nan	nan
113.55	2.5141403968702423	21.2524	3.36456	0.1005656158748097	1084.543847171679	nan	nan
113.95	2.526910396870242	21.218	3.37696	0.10107641587480969	1082.7883603399468	nan	nan
114.36	2.540270396870242	21.1759	3.38952	0.10161081587480968	1080.6399302348327	nan	nan
114.77	2.5529103968702422	21.1451	3.40186	0.10211641587480969	1079.068157141305	nan	nan
115.17	2.566030396870242	21.1019	3.41312	0.10264121587480968	1076.8635922828507	nan	nan
115.57	2.5792203968702423	21.0508	3.42561	0.1031688158748097	1074.2558778322252	nan	nan
115.98	2.592530396870242	21.0173	3.43824	0.10370121587480968	1072.546319435044	nan	nan
116.39	2.605430396870242	20.9755	3.44968	0.10421721587480968	1070.4131988081137	nan	nan
116.79	2.618380396870242	20.9385	3.46169	0.10473521587480969	1068.5250298321225	nan	nan
117.2	2.631980396870242	20.9009	3.47518	0.10527921587480968	1066.6062418997642	nan	nan
117.6	2.644740396870242	20.844	3.48711	0.10578961587480969	1063.7025442042536	nan	nan
118.01	2.6579803968702422	20.8081	3.49894	0.10631921587480969	1061.8705099816027	nan	nan
118.41	2.670970396870242	20.7597	3.51137	0.10683881587480969	1059.4005808346305	nan	nan
118.85	2.6847603968702423	20.7178	3.52489	0.10739041587480969	1057.2623570483058	nan	nan
119.26	2.698010396870242	20.6781	3.5368	0.10792041587480967	1055.2364027686615	nan	nan
119.66	2.711360396870242	20.6371	3.54958	0.10845441587480968	1053.1441074168874	nan	nan
120.07	2.723900396870242	20.5843	3.561	0.10895601587480969	1050.4496392565543	nan	nan
120.47	2.736580396870242	20.5401	3.57254	0.10946321587480969	1048.1940428041542	nan	nan
120.88	2.7501303968702424	20.4927	3.5849	0.1100052158748097	1045.775145251128	nan	nan
121.29	2.763450396870242	20.453	3.59726	0.11053801587480969	1043.7491909714834	nan	nan
121.69	2.776230396870242	20.3931	3.60983	0.11104921587480968	1040.692398494136	nan	nan
122.11	2.7894203968702422	20.3686	3.62162	0.11157681587480969	1039.4421244424661	nan	nan
122.53	2.8032603968702423	20.3123	3.63462	0.1121304158748097	1036.5690457033227	nan	nan
122.96	2.8175103968702424	20.2632	3.64758	0.1127004158748097	1034.0633944405888	nan	nan
123.36	2.830410396870242	20.2145	3.65935	0.11321641587480968	1031.5781558154329	nan	nan
123.77	2.843750396870242	20.1656	3.67109	0.11375001587480968	1029.0827108714882	nan	nan
124.17	2.856580396870242	20.1295	3.68363	0.11426321587480968	1027.240470330048	nan	nan
124.58	2.870150396870242	20.0839	3.69617	0.1148060158748097	1024.913429646124	nan	nan
124.99	2.883210396870242	20.0447	3.70848	0.11532841587480969	1022.9129911634523	nan	nan
125.4	2.8968803968702423	19.9943	3.72104	0.1158752158748097	1020.3409988285889	nan	nan
125.82	2.9103103968702424	19.9336	3.73359	0.1164124158748097	1017.2433810760846	nan	nan
126.23	2.9231803968702423	19.8925	3.74596	0.1169272158748097	1015.1459825649163	nan	nan
126.65	2.937450396870242	19.8383	3.75877	0.11749801587480968	1012.380070173059	nan	nan
127.07	2.951010396870242	19.7892	3.77144	0.11804041587480968	1009.8744189103251	nan	nan
127.48	2.9641903968702423	19.7375	3.78317	0.1185676158748097	1007.2360855033321	nan	nan
127.88	2.977170396870242	19.6859	3.79587	0.11908681587480968	1004.6028552557339	nan	nan
128.29	2.990440396870242	19.6535	3.80774	0.11961761587480968	1002.949431611893	nan	nan
128.69	3.004230396870242	19.5851	3.81985	0.12016921587480969	999.458870586007	nan	nan
129.13	3.0184103968702423	19.5368	3.83408	0.1207364158748097	996.9940445984294	nan	nan
129.54	3.0310403968702424	19.4903	3.84566	0.1212416158748097	994.6210754799542	nan	nan
129.95	3.043940396870242	19.4483	3.85784	0.12175761587480968	992.4777485342345	nan	nan
130.35	3.056830396870242	19.387	3.86922	0.12227321587480969	989.3495118253629	nan	nan
130.75	3.070430396870242	19.3317	3.88185	0.12281721587480968	986.5274646801655	nan	nan
131.16	3.0839103968702424	19.2855	3.89409	0.1233564158748097	984.169805039874	nan	nan
131.57	3.097950396870242	19.2273	3.90665	0.12391801587480968	981.199766272234	nan	nan
131.97	3.1109603968702424	19.1793	3.92001	0.1244384158748097	978.7502497628403	nan	nan
132.38	3.124190396870242	19.1282	3.93168	0.12496761587480969	976.1425353122148	nan	nan
132.79	3.137750396870242	19.07	3.94408	0.12551001587480967	973.1724965445748	nan	nan
133.19	3.150720396870242	19.0132	3.95589	0.12602881587480969	970.2739020084588	nan	nan
133.59	3.163380396870242	18.9622	3.96769	0.12653521587480968	967.6712907172279	nan	nan
134.01	3.1773703968702423	18.9162	3.98085	0.1270948158748097	965.3238373957255	nan	nan
134.42	3.190220396870242	18.8477	3.99236	0.12760881587480968	961.8281732104448	nan	nan
134.84	3.2039403968702422	18.8039	4.00518	0.1281576158748097	959.5929893956228	nan	nan
135.25	3.2177803968702423	18.7425	4.01732	0.1287112158748097	956.4596495273568	nan	nan
135.65	3.2313403968702423	18.6905	4.02985	0.12925361587480969	953.8060066421801	nan	nan
136.06	3.2444803968702423	18.6231	4.04153	0.1297792158748097	950.3664772102397	nan	nan
136.47	3.257660396870242	18.5725	4.05363	0.13030641587480968	947.7842785565871	nan	nan
136.87	3.270970396870242	18.5061	4.06597	0.1308388158748097	944.3957807185922	nan	nan
137.28	3.284180396870242	18.4546	4.07736	0.13136721587480968	941.7676536303885	nan	nan
137.68	3.2971703968702424	18.4112	4.08978	0.1318868158748097	939.552882453145	nan	nan
138.09	3.310960396870242	18.346	4.10271	0.13243841587480967	936.2256225278851	nan	nan
138.49	3.323980396870242	18.2903	4.1144	0.1329592158748097	933.3831627451093	nan	nan
138.9	3.337750396870242	18.2323	4.12663	0.13351001587480968	930.4233302962585	nan	nan
139.3	3.3511203968702423	18.1625	4.1389	0.13404481587480968	926.8613250388483	nan	nan
139.71	3.3651503968702423	18.1051	4.15192	0.1346060158748097	923.9321115463649	nan	nan
140.12	3.3778403968702424	18.0393	4.16354	0.1351136158748097	920.5742326647377	nan	nan
140.52	3.391370396870242	17.9911	4.17608	0.13565481587480968	918.1145098365547	nan	nan
140.92	3.4041203968702423	17.9232	4.18763	0.1361648158748097	914.6494646076414	nan	nan
141.33	3.417800396870242	17.8658	4.20084	0.1367120158748097	911.720251115158	nan	nan
141.74	3.431010396870242	17.8093	4.21272	0.13724041587480967	908.8369660572257	nan	nan
142.14	3.444700396870242	17.7493	4.2251	0.13778801587480968	905.7750704204836	nan	nan
142.55	3.459010396870242	17.6758	4.23779	0.13836041587480968	902.0242482654743	nan	nan
142.95	3.472080396870242	17.6147	4.24927	0.13888321587480967	898.9062178753918	nan	nan
143.36	3.485390396870242	17.543	4.26135	0.1394156158748097	895.2472525894848	nan	nan
143.76	3.4987003968702424	17.488	4.2733	0.1399480158748097	892.440514922471	nan	nan
144.2	3.5132603968702423	17.402	4.28625	0.1405304158748097	888.0517978431405	nan	nan
144.61	3.527000396870242	17.3477	4.29914	0.14108001587480967	885.2807822918888	nan	nan
145.01	3.5404503968702423	17.2881	4.31162	0.14161801587480968	882.2392992927248	nan	nan
145.42	3.554050396870242	17.2154	4.3233	0.1421620158748097	878.5293024128721	nan	nan
145.82	3.567590396870242	17.1457	4.33569	0.14270361587480968	874.9724003148566	nan	nan
146.23	3.5812603968702423	17.0868	4.34851	0.1432504158748097	871.9666394314546	nan	nan
146.64	3.5949603968702424	17.0153	4.35995	0.14379841587480968	868.3178804643368	nan	nan
147.04	3.608420396870242	16.9537	4.37225	0.14433681587480968	865.1743342772814	nan	nan
147.46	3.622180396870242	16.8727	4.38416	0.14488721587480968	861.0407751676793	nan	nan
147.66	3.6289203968702424	16.8342	4.38984	0.1451568158748097	859.0760588007698	nan	nan