File: original_data/46NT9P.csv
Specimen name:	AWA_2_09_Rz
Specimen ID:	46NT9P
Material:	42CrMoS4
Specimen type:	Round Tensile Specimen
Gauge diameter:	5.014	mm
Gauge length:	25	mm
Parallel length:	30	mm
Original cross-section:	19.745063765851878	mm²
Cross-section after fracture:	9.503288128328458	mm²
Yield stress at 0.2% plastic strain:	1105.7658840600573	MPa
Yield stress at 1% plastic strain:	1137.036261165777	MPa
Ultimate tensile strength:	1191.0673107408604	MPa
Uniform elongation:	4.942097395562412	%
Elongation after fracture:	14.121919350023635	%
Reduction of area:	51.87005602502064	%
Slope of linear-elastic region:	214398.40196820133	MPa
Crosshead seperation speed:	0.02982033132604466	mm/s
Strain rate:	0.0009940110442014885	s-1
Test temperature:	RT	Cel
Machine type:	INSTRON 8852TT
Standard:	DIN EN ISO 6892-1
Date:	2022-08-23 00:00:00
Heat treatment batch:	Batch 2
Time	Displacement	Force	Machine Displacement	Engineering Strain	Engineering Stress	True Strain	True Stress
s	mm	kN	mm		MPa		MPa
0	0.001637310970842273	0.271562	0	6.549243883369092e-05	13.753412155075093	6.549029429755316e-05	13.754312899579414
0.450001	0.001705119770842273	0.275667	0.000473023	6.820479083369092e-05	13.961312218031555	6.820246499259018e-05	13.962264446411147
0.860001	0.001644671560842273	0.272837	0.000236512	6.578686243369092e-05	13.817985256236966	6.578469857290408e-05	13.818894298132129
1.26	0.001923853970842273	0.331652	0.00358582	7.695415883369092e-05	16.796704428657044	7.695119801430277e-05	16.79799700491753
1.69	0.003052110970842273	0.526975	0.0160446	0.00012208443883369094	26.688949007669326	0.0001220769871350405	26.692207313031986
2.09	0.004564550970842273	0.741476	0.0290298	0.0001825820388336909	37.55247431929526	0.00018256537276183443	37.55933072661973
2.5	0.006039480970842274	0.961424	0.0403748	0.00024157923883369096	48.69186604819863	0.0002415500632681173	48.70362899213595
2.91	0.007613740970842273	1.2182	0.0524292	0.0003045496388336909	61.69643281207414	0.0003045032730059416	61.71522243840438
3.31	0.009186040970842272	1.4995	0.0645142	0.0003674416388336909	75.94303152331733	0.00036737414868671166	75.97093615527827
3.71001	0.010992390970842272	1.78677	0.0765915	0.0004396956388336909	90.4919842847067	0.0004395990010327632	90.5317732155461
4.15001	0.012806710970842272	2.11167	0.0897522	0.0005122684388336909	106.9467298278383	0.0005121372741494018	107.00151526216557
4.57001	0.014652910970842273	2.43959	0.102127	0.0005861164388336909	123.55442499097683	0.0005859447396809141	123.62684227055468
4.98001	0.016397910970842273	2.77423	0.114929	0.0006559164388336909	140.50245838141558	0.0006557014196643496	140.5946162535645
5.38001	0.018210510970842274	3.09461	0.126656	0.000728420438833691	156.7282859502321	0.0007281552694277958	156.8424500370616
5.79001	0.019825710970842274	3.41639	0.13871	0.0007930284388336909	173.02501731640285	0.000792714157926199	173.16223107576445
6.19001	0.021905610970842274	3.77094	0.150658	0.000876224438833691	190.98140399635764	0.0008758407782988134	191.14874656990202
6.62001	0.023827710970842273	4.14005	0.163254	0.0009531084388336909	209.67519016879618	0.0009526545193856583	209.8750333619601
7.02001	0.025679710970842273	4.49652	0.175301	0.0010271884388336908	227.72881634226533	0.0010266612417789162	227.9627367496014
7.43001	0.027844310970842275	4.87683	0.187843	0.001113772438833691	246.98983289353762	0.0011131526544674274	247.2649233620866
7.83001	0.030080310970842274	5.25202	0.199898	0.001203212438833691	265.99154412877164	0.0012024891588620556	266.31158846329197
8.25001	0.03230621097084227	5.65247	0.212158	0.0012922484388336907	286.2725624505539	0.0012914142044346902	286.6424977224616
8.67001	0.03458861097084227	6.06544	0.224876	0.001383544438833691	307.1876633029609	0.00138258822310295	307.61267108620206
9.08001	0.03728211097084227	6.48356	0.236618	0.0014912844388336908	328.3635888384924	0.001490173578463691	328.8532723488068
9.49001	0.03948971097084227	6.86713	0.248772	0.0015795884388336908	347.7897099464609	0.0015783422012047047	348.33907455143765
9.89001	0.04183441097084227	7.27325	0.261032	0.0016733764388336908	368.3578886475277	0.0016719779044462985	368.974290059449
10.3	0.044243010970842274	7.67162	0.2733	0.001769720438833691	388.53356418466933	0.00176815632870435	389.2211599743798
10.7	0.04681691097084227	8.09354	0.285255	0.001872676438833691	409.90194288444803	0.0018709251663483841	410.6695565951199
11.12	0.04968491097084227	8.51912	0.297791	0.001987396438833691	431.4556843687383	0.0019854241792067015	432.31315785936727
11.55	0.05182541097084227	8.94076	0.310608	0.0020730164388336907	452.80988230904603	0.0020708707051715026	453.748564638739
11.96	0.05448991097084227	9.37695	0.323196	0.002179596438833691	474.9009732861424	0.0021772245643763097	475.9360657563155
12.36	0.05680851097084227	9.77699	0.334671	0.0022723404388336906	495.16122692441365	0.002269762577745374	496.28640180409644
12.76	0.059222510970842274	10.2019	0.347496	0.002368900438833691	516.6810358771131	0.002366099017508956	517.9050018097395
13.18	0.06165251097084227	10.6006	0.359558	0.002466100438833691	536.8734244522026	0.002463064603239191	538.1974082398424
13.59	0.06390831097084228	10.9971	0.371033	0.0025563324388336913	556.9543927743068	0.002553070578814671	558.3781533555068
13.99	0.06623281097084227	11.379	0.382576	0.0026493124388336908	576.2959357811457	0.0026458091967254634	577.8227237722599
14.42	0.06880041097084227	11.8286	0.396004	0.002752016438833691	599.0661838457562	0.002748236574837745	600.7148238316491
14.83	0.07136511097084228	12.2417	0.408272	0.002854604438833691	619.9878686222032	0.0028505377928549117	621.7576887439952
15.24	0.07385771097084227	12.6343	0.419647	0.002954308438833691	639.8713192231064	0.0029499530456658075	641.7616964612549
15.65	0.07626811097084227	13.0544	0.432495	0.0030507244388336906	661.1475229863246	0.0030460804217131245	663.1645018923732
16.05	0.07847281097084227	13.4472	0.445068	0.003138912438833691	681.0411027011356	0.0031339963379713237	683.1788310897613
16.48	0.08122991097084227	13.8869	0.457245	0.003249196438833691	703.3099596273128	0.0032439292065156596	705.5951518435301
16.89	0.08367631097084227	14.2917	0.469536	0.003347052438833691	723.8112861765884	0.0033414635262696358	726.2339205072411
17.29	0.08605401097084227	14.6903	0.481255	0.003442160438833691	743.998610194724	0.003436249764366697	746.5595727772836
17.69	0.08829951097084227	15.052	0.493019	0.0035319804388336904	762.3171126968806	0.003525757644144954	765.0096018271141
18.1	0.09078351097084227	15.4639	0.504898	0.0036313404388336906	783.1780227898813	0.00362476304051481	786.0220088148441
18.5	0.09327341097084227	15.8889	0.518158	0.0037309364388336905	804.7023898438391	0.003723993758585799	807.704683312524
18.92	0.09573001097084227	16.3078	0.531265	0.003829200438833691	825.9178189236109	0.003821887712817543	829.0804237982736
19.36	0.09827311097084226	16.7234	0.543732	0.0039309244388336904	846.9661176239048	0.003923218542956746	850.2954774345367
19.78	0.10086251097084227	17.1396	0.556206	0.004034500438833691	868.0448036659219	0.004026383666029798	871.5469308072395
20.19	0.10314331097084227	17.5247	0.568123	0.004125732438833691	887.5484124952847	0.00411724494150877	891.2101997717518
20.59	0.10564931097084226	17.9289	0.580917	0.0042259724388336905	908.019351702837	0.004217068094833607	911.8566164570607
21.02	0.10812031097084226	18.3329	0.59375	0.004324812438833691	928.4801617964816	0.004315487314127541	932.4956643494295
21.42	0.11051831097084228	18.7302	0.605827	0.004420732438833691	948.6016465742169	0.004410989703982163	952.7951606447587
21.83	0.11294831097084226	19.1204	0.617737	0.00451793243883369	968.3635478082273	0.004507757217869079	972.7385488934541
22.23	0.11537531097084228	19.5017	0.629692	0.004615012438833691	987.6747034733429	0.004604395919975133	992.2328345153938
22.64	0.11795431097084227	19.896	0.642609	0.004718172438833691	1007.6442515424619	0.004707076750478411	1012.3984908782387
23.04	0.12065531097084227	20.2799	0.654434	0.004826212438833691	1027.0870856883782	0.004814603611708351	1032.044026157093
23.45	0.12323331097084227	20.6354	0.666573	0.0049293324388336906	1045.091585659395	0.004917223057494624	1050.243189514138
23.85	0.12612431097084228	20.9571	0.678337	0.005044972438833692	1061.3842653800025	0.005032289205203017	1066.7389197458565
24.29	0.13007731097084227	21.3144	0.691833	0.005203092438833691	1079.4799273761885	0.005189603123906631	1085.0965612241923
24.7	0.13470831097084227	21.5831	0.704414	0.005388332438833691	1093.0883919112441	0.005373867314265815	1098.9783155518921
25.1	0.14058731097084226	21.7637	0.717072	0.005623492438833691	1102.2349817699376	0.005607739634818749	1108.4333918557388
25.51	0.14801831097084228	21.8534	0.72876	0.005920732438833691	1106.7778893575612	0.0059032737806629315	1113.3308251096644
25.91	0.15871531097084227	21.8554	0.740791	0.006348612438833691	1106.8791804966386	0.00632854488816932	1113.9063274302255
26.33	0.17103831097084227	21.8545	0.75354	0.006841532438833691	1106.8335994840538	0.006818235353925225	1114.406037459315
26.77	0.18314931097084228	21.8364	0.766708	0.007325972438833691	1105.916914675403	0.007299267848162239	1114.0188315119549
27.18	0.19447831097084228	21.8546	0.779396	0.007779132438833691	1106.8386640410079	0.007749030996041804	1115.4489085970047
27.59	0.20472831097084226	21.9054	0.791237	0.00818913243883369	1109.411458973575	0.008155783436341445	1118.4965763402693
27.99	0.21465931097084226	21.9602	0.803352	0.00858637243883369	1112.186836184297	0.008549719205767924	1121.7364865813436
28.39	0.22504531097084227	22.0189	0.816284	0.009001812438833691	1115.15973111622	0.008961537642240969	1125.1981898550684
28.8	0.23490231097084227	22.0396	0.82785	0.009396092438833692	1116.2080944056715	0.0093522237443838	1126.6960888416816
29.2	0.24464431097084227	22.089	0.840439	0.009785772438833691	1118.7099855408846	0.009738201859199639	1129.6574268844388
29.64	0.2556663109708423	22.1317	0.853607	0.010226652438833693	1120.872551360188	0.010174714032660376	1132.3353253711775
30.05	0.2650623109708423	22.1561	0.864655	0.010602492438833693	1122.108303256933	0.010546680168724953	1134.0054480577671
30.45	0.2752213109708423	22.1913	0.877296	0.011008852438833691	1123.891027304696	0.010948696121496937	1136.2637777816226
30.86	0.2856803109708423	22.2218	0.889633	0.01142721243883369	1125.4357171756274	0.011362415015490939	1138.2963102020444
31.26	0.2957073109708423	22.2463	0.90136	0.011828292438833692	1126.676533629326	0.011758884966307226	1140.0031931530652
31.7	0.3066223109708423	22.2736	0.914497	0.012264892438833693	1128.059157677733	0.012190288036119594	1141.8946819112919
32.11	0.3170673109708423	22.3077	0.927101	0.012682692438833692	1129.7861715990036	0.012602940698389678	1144.1149021350411
32.51	0.3270813109708423	22.3296	0.938675	0.013083252438833692	1130.8953095719016	0.012998405935855386	1145.6910983889238
32.92	0.3376223109708423	22.3522	0.951439	0.01350489243883369	1132.039899443477	0.01341451416894595	1147.3279765219293
33.32	0.3476213109708423	22.3776	0.963219	0.013904852438833692	1133.3262969097607	0.013809066879565039	1149.0850318333407
33.74	0.3581493109708423	22.3996	0.975563	0.014325972438833691	1134.4404994396125	0.0142243253411623	1150.692462768081
34.18	0.3691043109708423	22.4101	0.988739	0.01476417243883369	1134.972277919769	0.014656243073273472	1151.7292043442724
34.59	0.3792763109708423	22.4443	1.00082	0.015171052438833692	1136.7043563979935	0.015057122865360028	1153.9493577963583
35	0.3898723109708423	22.4704	1.01357	0.015594892438833692	1138.0262057629543	0.015474541728644617	1155.7736020344014
35.4	0.4000863109708423	22.4868	1.02568	0.016003452438833693	1138.8567931033892	0.015876747220234952	1157.082433626462
35.8101	0.4103953109708423	22.4978	1.03821	0.016415812438833693	1139.4138943683154	0.016282529641986357	1158.1182991484666
36.2101	0.42073731097084227	22.5237	1.05032	0.01682949243883369	1140.7256146193681	0.016689445624741412	1159.9234477253888
36.6101	0.4308403109708423	22.5496	1.0621	0.01723361243883369	1142.0373348704213	0.017086798100530494	1161.7187636902568
37.0401	0.4420403109708423	22.5531	1.07478	0.01768161243883369	1142.2145943638068	0.017527111290742102	1162.4107901433272
37.4401	0.45207031097084227	22.5856	1.08685	0.018082812438833692	1143.8605753738152	0.01792126299149024	1164.5447916144763
37.8501	0.46167431097084227	22.5907	1.09847	0.01846697243883369	1144.1188677784626	0.018298528509288117	1165.247279376477
38.2501	0.4722733109708423	22.6307	1.11111	0.01889093243883369	1146.1446905600117	0.018714714595301312	1167.796432474509
38.6701	0.4836313109708423	22.6487	1.12444	0.019345252438833692	1147.0563108117087	0.01916051181045711	1169.2464047059186
39.1001	0.4939643109708423	22.6574	1.13633	0.019758572438833694	1147.4969272666956	0.0195659055923899	1170.1698284274337
39.5001	0.5042973109708423	22.683	1.14868	0.020171892438833692	1148.793453846887	0.019971135096799316	1171.9667918323225
39.9101	0.5140553109708423	22.6984	1.15963	0.020562212438833695	1149.5733956177833	0.02035366411302597	1173.2111679925074
40.3101	0.5243753109708423	22.7118	1.17235	0.020975012438833693	1150.2520462496022	0.02075806526779857	1174.3785972274816
40.7201	0.5350293109708423	22.72	1.18482	0.02140117243883369	1150.6673399198198	0.021175383105070823	1175.2929700811778
41.1201	0.5450353109708423	22.7479	1.19698	0.021801412438833694	1152.0803513099502	0.021567160218198735	1177.1973302115348
41.5401	0.5552853109708423	22.769	1.20887	0.02221141243883369	1153.1489728272172	0.02196833187476434	1178.7620402661
41.9801	0.5667023109708423	22.8053	1.22302	0.022668092438833692	1154.987407001473	0.022414989006886755	1181.168768309071
42.4001	0.5769163109708423	22.798	1.23489	0.02307665243883369	1154.6176943438404	0.02281441323266556	1181.2624055759409
42.8301	0.5880323109708423	22.8224	1.24789	0.02352129243883369	1155.853446240585	0.023248929458100743	1183.0406131660436
43.2301	0.5973043109708422	22.8366	1.25895	0.02389217243883369	1156.5726133280352	0.023611220720143194	1184.2056456437012
43.6301	0.6075283109708423	22.8433	1.27103	0.02430113243883369	1156.9119386439445	0.024010558033140686	1185.0262088849986
44.0401	0.6180763109708423	22.8746	1.28458	0.02472305243883369	1158.4971449705067	0.02442238333913483	1187.1387306358517
44.4601	0.6290643109708423	22.8842	1.29662	0.02516257243883369	1158.9833424380784	0.02485120727096911	1188.1463447475783
44.8701	0.6390223109708423	22.885	1.30882	0.02556089243883369	1159.0238588937093	0.025239675059855336	1188.6495430849334
45.2801	0.6493283109708423	22.9154	1.32093	0.02597313243883369	1160.5634842076865	0.025641559698910233	1190.7069532866872
45.6801	0.6591893109708423	22.9365	1.33252	0.026367572438833694	1161.6321057249536	0.026025940327252348	1192.2615244199312
46.0801	0.6690033109708423	22.9587	1.34441	0.026760132438833694	1162.7564373687133	0.026408342263431177	1193.8719536268065
46.4901	0.6795003109708423	22.9723	1.35812	0.02718001243883369	1163.4452171144399	0.026817195468716668	1195.0676725875119
46.9101	0.6900933109708423	22.9781	1.3695	0.02760373243883369	1163.7389614177646	0.027229618437374235	1195.8625003373868
47.3201	0.7001153109708423	23.0082	1.38142	0.028004612438833693	1165.26339306088	0.027619653831111743	1197.8961427727104
47.7201	0.7101933109708423	23.0105	1.39339	0.02840773243883369	1165.3798778708192	0.02801171528334695	1198.4856776309741
48.1301	0.7210003109708423	23.0306	1.40674	0.02884001243883369	1166.3978538185474	0.02843196608438781	1200.0367824313032
48.5301	0.7307763109708423	23.0399	1.41904	0.029231052438833692	1166.8688576152576	0.02881197240329393	1200.9776623814512
48.9501	0.7409903109708423	23.0544	1.43077	0.029639612438833694	1167.6032183735692	0.0292088501793799	1202.2105252484967
49.3901	0.7517013109708423	23.065	1.44376	0.03006805243883369	1168.1400614106797	0.029624870387961112	1203.2637580330784
49.8001	0.7618153109708423	23.0875	1.45602	0.03047261243883369	1169.279586725301	0.030017544031431635	1204.9105904042208
50.2001	0.7720733109708423	23.0915	1.46814	0.030882932438833693	1169.482169003456	0.03041565100180748	1205.5992078172105
50.6101	0.7825383109708423	23.1132	1.48026	0.03130153243883369	1170.5811778624463	0.03082162826803051	1207.2221625735958
51.0101	0.7925383109708423	23.1275	1.49243	0.03170153243883369	1171.30540950685	0.031209412476229183	1208.437585942113
51.4201	0.8023363109708423	23.1267	1.50403	0.03209345243883369	1171.2648930512191	0.03158921764833497	1208.854827189634
51.8201	0.8128043109708423	23.1567	1.51646	0.03251217243883369	1172.784260137381	0.03199483507056373	1210.9140242365174
52.2501	0.8239403109708423	23.1607	1.52911	0.03295761243883369	1172.9868424155354	0.03242615583852366	1211.645688163718
52.6501	0.8338353109708423	23.173	1.54124	0.03335341243883369	1173.609782920862	0.03280925402662354	1212.7536740528717
53.0601	0.8440543109708423	23.1861	1.55325	0.03376217243883369	1174.273239881819	0.03320474231795881	1213.919255497017
53.4601	0.8538613109708423	23.192	1.56521	0.03415445243883369	1174.5720487420976	0.033584138663039866	1214.6889139168431
53.8801	0.8646643109708423	23.2104	1.57738	0.034586572438833695	1175.5039272216104	0.03400189999815924	1216.160578952594
54.3101	0.8755513109708423	23.2289	1.59064	0.03502205243883369	1176.4408702580765	0.03442273319453486	1217.642244107442
54.7201	0.8853463109708423	23.24	1.60233	0.03541385243883369	1177.0030360799565	0.03480120422447964	1218.6852479197512
55.1201	0.8954153109708423	23.2488	1.61459	0.03581661243883369	1177.4487170918972	0.035190113147852684	1219.6209414585796
55.5201	0.9059643109708423	23.2672	1.6268	0.03623857243883369	1178.38059557141	0.035597399603264177	1221.0834261445405
55.9301	0.9169603109708423	23.2825	1.63964	0.03667841243883369	1179.1554727853522	0.03602176778569467	1222.4050235456814
56.3301	0.9267753109708423	23.2807	1.65128	0.03707101243883369	1179.0643107601827	0.036400405628801966	1222.7734184905582
56.7501	0.9375623109708423	23.2851	1.66415	0.03750249243883369	1179.287151266153	0.036816375470513696	1223.5133587397254
57.1901	0.9483503109708423	23.3043	1.67733	0.037934012438833695	1180.2595462012966	0.03723221089135556	1225.0315265079487
57.6001	0.9585173109708423	23.3115	1.68926	0.03834069243883369	1180.6241943019754	0.03762395096721871	1225.8901434215531
58.0101	0.9689883109708423	23.3154	1.70184	0.03875953243883369	1180.8217120231764	0.0380272439818363	1226.5898094748177
58.4101	0.9795683109708423	23.3318	1.71387	0.03918273243883369	1181.6522993636115	0.03843457003030678	1227.9526652453085
58.8201	0.9897253109708423	23.3283	1.72587	0.03958901243883369	1181.4750398702258	0.03882545470167495	1228.2484699198196
59.2201	0.9996993109708423	23.3413	1.73755	0.039987972438833695	1182.1334322742293	0.03920914812374667	1229.4045513830351
59.6201	1.0100773109708423	23.3649	1.74937	0.04040309243883369	1183.328667715343	0.03960822694360679	1231.138805262568
60.0401	1.0214173109708422	23.3722	1.76313	0.04085669243883369	1183.6983803729759	0.04004411679308909	1232.06038104022
60.4401	1.0315373109708423	23.3647	1.77505	0.041261492438833695	1183.3185386014354	0.040432951594149245	1232.1440275346704
60.8401	1.0416473109708424	23.3886	1.78689	0.041665892438833695	1184.5289677134108	0.04082125126125934	1233.8834242728406
61.2501	1.0520973109708422	23.3835	1.79894	0.04208389243883369	1184.2706753087634	0.041222451068107714	1234.1093950269224
61.6501	1.0627273109708424	23.3916	1.81164	0.0425090924388337	1184.6809044220272	0.04163039641665427	1235.040614498624
62.0701	1.0738273109708423	23.4002	1.82394	0.04295309243883369	1185.1164563200603	0.0420562013148952	1236.020873019159
62.5001	1.0845973109708422	23.3944	1.83636	0.04338389243883369	1184.8227120167357	0.042469173916392586	1236.224933113957
62.9001	1.0949273109708424	23.4133	1.84839	0.043797092438833694	1185.7799132810173	0.042865114669390976	1237.7136257550983
63.3101	1.1058073109708424	23.4173	1.86081	0.0442322924388337	1185.9824955591723	0.04328196704652097	1238.4412201300834
63.7101	1.1162573109708422	23.4252	1.87253	0.04465029243883369	1186.3825955585282	0.043682181025617176	1239.3549253945591
64.1201	1.1269673109708422	23.4311	1.88495	0.04507869243883369	1186.6814044188068	0.04409218635080676	1240.1754504714854
64.5201	1.1370673109708422	23.4268	1.89663	0.04548269243883369	1186.4636284697901	0.04447868541077353	1240.4271887733441
64.9301	1.1484873109708422	23.4568	1.90947	0.04593949243883369	1187.9829955559521	0.04491551735275728	1242.5583313977577
65.3401	1.1586073109708424	23.4295	1.92122	0.046344292438833694	1186.6003715075449	0.04530246295542995	1241.5925261327193
65.7401	1.1692073109708423	23.4481	1.93318	0.046768292438833695	1187.542379100965	0.04570760122545212	1243.0817083702673
66.1501	1.1801973109708424	23.4493	1.94556	0.04720789243883369	1187.6031537844115	0.04612747229144882	1243.6673957282856
66.5501	1.1905873109708422	23.4672	1.9573	0.04762349243883369	1188.5097094791545	0.04652425840841534	1245.1106926420155
66.9701	1.2022273109708423	23.4754	1.97047	0.04808909243883369	1188.9250031493723	0.046968594154662424	1246.0993275286633
67.3901	1.2135273109708422	23.469	1.98293	0.048541092438833686	1188.6008715043245	0.0473997622359602	1246.2968562808942
67.8001	1.2240373109708422	23.459	1.99533	0.04896149243883369	1188.0944158089371	0.04780061991180809	1246.265291565187
68.2101	1.2354273109708422	23.4711	2.00797	0.04941709243883369	1188.7072272003556	0.04823485995833022	1247.4496821296254
68.6101	1.2460673109708422	23.4757	2.01942	0.049842692438833686	1188.940196820234	0.04864033622086524	1248.2001773785114
69.0201	1.2567673109708424	23.4882	2.03172	0.0502706924388337	1189.573266439468	0.049047933266822163	1249.373938250105
69.4201	1.2674273109708423	23.493	2.04384	0.05069709243883369	1189.8163651732539	0.04945384144773166	1250.1365954236794
69.8401	1.2788373109708422	23.4871	2.05707	0.051153492438833686	1189.5175563129753	0.0498881254167796	1250.365533635691
70.3201	1.2922173109708424	23.4804	2.07167	0.05168869243883369	1189.1782309970658	0.05039715078768481	1250.6452988340295
70.6701	1.3017973109708423	23.4923	2.08205	0.05207189243883369	1189.7809132745767	0.05076145080071145	1251.7350570163878
71.0901	1.3131073109708422	23.4878	2.0945	0.05252429243883369	1189.5530082116525	0.0511913670100238	1252.0334382864555
71.5101	1.3246173109708423	23.5006	2.10744	0.05298469243883369	1190.2012715017481	0.051628695951049214	1253.2637198125772
71.9201	1.3356273109708423	23.5005	2.11874	0.05342509243883369	1190.1962069447943	0.052046848211429665	1253.7825493211692
72.3201	1.3467673109708422	23.4992	2.13149	0.05387069243883369	1190.1303677043938	0.05246975989742941	1254.2435147051133
72.7301	1.3582173109708422	23.4896	2.14371	0.05432869243883369	1189.644170236822	0.05290425391207589	1254.2759824732698
73.1401	1.3689773109708423	23.514	2.15607	0.054759092438833694	1190.879922133567	0.05331239245335474	1256.0914258732303
73.5401	1.3802973109708423	23.5035	2.16741	0.05521189243883369	1190.3481436534105	nan	nan
73.9501	1.3916273109708424	23.4922	2.18069	0.05566509243883369	1189.775848717623	nan	nan
74.3501	1.4024873109708422	23.4887	2.1918	0.05609949243883369	1189.5985892242372	nan	nan
74.7601	1.4134073109708423	23.4925	2.2041	0.056536292438833693	1189.7910423884844	nan	nan
75.1701	1.4253673109708422	23.5176	2.21664	0.05701469243883369	1191.0622461839066	nan	nan
75.5701	1.4371373109708423	23.5052	2.22952	0.05748549243883369	1190.4342411216262	nan	nan
75.9701	1.4480573109708423	23.503	2.24017	0.05792229243883369	1190.322820868641	nan	nan
76.3801	1.4591873109708422	23.4969	2.25256	0.058367492438833685	1190.0138828944548	nan	nan
76.7801	1.4705573109708423	23.4997	2.26438	0.05882229243883369	1190.1556904891634	nan	nan
77.1901	1.4825173109708423	23.5029	2.27708	0.059300692438833694	1190.3177563116872	nan	nan
77.6001	1.4938173109708424	23.5039	2.28896	0.059752692438833695	1190.368401881226	nan	nan
78.0001	1.5050273109708423	23.4976	2.3009	0.06020109243883369	1190.049334793132	nan	nan
78.4101	1.5171173109708422	23.49	2.31326	0.06068469243883369	1189.6644284646377	nan	nan
78.8101	1.5281073109708423	23.4845	2.32496	0.06112429243883369	1189.3858778321746	nan	nan
79.2301	1.5402073109708423	23.483	2.33793	0.061608292438833694	1189.3099094778665	nan	nan
79.6701	1.5532673109708424	23.4961	2.35126	0.06213069243883369	1189.9733664388239	nan	nan
80.0801	1.5647873109708423	23.4808	2.36366	0.06259149243883369	1189.1984892248813	nan	nan
80.4801	1.5762873109708424	23.4778	2.37553	0.06305149243883369	1189.0465525162651	nan	nan
80.8901	1.5880673109708423	23.4659	2.3875	0.0635226924388337	1188.4438702387545	nan	nan
81.2901	1.5995473109708422	23.4531	2.39946	0.06398189243883369	1187.7956069486586	nan	nan
81.7101	1.6123073109708423	23.4554	2.41293	0.0644922924388337	1187.9120917585979	nan	nan
82.1401	1.6248773109708423	23.4467	2.42561	0.0649950924388337	1187.471475303611	nan	nan
82.5701	1.6372673109708422	23.4462	2.43803	0.0654906924388337	1187.4461525188415	nan	nan
82.9801	1.6490873109708424	23.443	2.45044	0.06596349243883369	1187.2840866963177	nan	nan
83.3901	1.6612173109708424	23.4219	2.46262	0.0664486924388337	1186.2154651790506	nan	nan
83.7901	1.6734973109708422	23.4194	2.47504	0.06693989243883369	1186.0888512552035	nan	nan
84.1901	1.6850173109708424	23.4052	2.4865	0.06740069243883369	1185.3696841677538	nan	nan
84.6001	1.6967973109708423	23.3941	2.49927	0.0678718924388337	1184.807518345874	nan	nan
85.0201	1.7102173109708423	23.3826	2.51254	0.06840869243883368	1184.2250942961784	nan	nan
85.4301	1.7223673109708424	23.3792	2.52423	0.0688946924388337	1184.052899359747	nan	nan
85.8401	1.7339573109708424	23.3645	2.53568	0.0693582924388337	1183.3084094875278	nan	nan
86.2501	1.7465673109708424	23.3549	2.54781	0.0698626924388337	1182.822212019956	nan	nan
86.6601	1.7593473109708424	23.3374	2.56039	0.0703738924388337	1181.9359145530282	nan	nan
87.0801	1.7724173109708423	23.3177	2.57317	0.07089669243883369	1180.9381968331152	nan	nan
87.5001	1.7855473109708424	23.3095	2.58656	0.07142189243883369	1180.5229031628978	nan	nan
87.9101	1.7975973109708423	23.2775	2.59762	0.07190389243883369	1178.9022449376587	nan	nan
88.3101	1.8093573109708423	23.2674	2.60918	0.0723742924388337	1178.3907246853175	nan	nan
88.7201	1.8226773109708423	23.2326	2.62255	0.0729070924388337	1176.62825886537	nan	nan
89.1201	1.8346073109708423	23.2183	2.63384	0.0733842924388337	1175.904027220966	nan	nan
89.5601	1.8481773109708424	23.2087	2.64707	0.07392709243883369	1175.4178297533945	nan	nan
89.9701	1.8604373109708423	23.1779	2.65876	0.0744174924388337	1173.8579462116018	nan	nan
90.4301	1.8751073109708423	23.1541	2.67278	0.07500429243883369	1172.65258165658	nan	nan
90.8001	1.8868773109708423	23.1339	2.68445	0.0754750924388337	1171.629541151898	nan	nan
91.2001	1.8996373109708422	23.0973	2.6961	0.0759854924388337	1169.7759133067805	nan	nan
91.6201	1.9119973109708424	23.082	2.70793	0.0764798924388337	1169.0010360928381	nan	nan
92.0401	1.9258173109708423	23.0534	2.72158	0.07703269243883369	1167.5525728040307	nan	nan
92.4501	1.9382073109708422	23.03	2.73355	0.07752829243883369	1166.3674664768243	nan	nan
92.8501	1.9508273109708423	22.9966	2.74599	0.07803309243883369	1164.6759044542312	nan	nan
93.2701	1.9635273109708422	22.9508	2.75729	0.07854109243883368	1162.3563373693573	nan	nan
93.6801	1.9765473109708422	22.9393	2.77067	0.07906189243883369	1161.7739133196621	nan	nan
94.1001	1.9897673109708423	22.8969	2.78329	0.0795906924388337	1159.62654117122	nan	nan
94.5201	2.002867310970842	22.8867	2.79647	0.08011469243883368	1159.1099563619252	nan	nan
94.9301	2.015727310970842	22.8469	2.80779	0.08062909243883368	1157.094262694284	nan	nan
95.3301	2.0285773109708423	22.8162	2.82037	0.08114309243883369	1155.5394437094449	nan	nan
95.7401	2.041877310970842	22.7662	2.83302	0.08167509243883368	1153.007165232509	nan	nan
96.1501	2.054327310970842	22.7512	2.84512	0.0821730924388337	1152.247481689428	nan	nan
96.5501	2.066847310970842	22.7025	2.85676	0.08267389243883368	1149.781042452892	nan	nan
96.9601	2.0796873109708423	22.6635	2.86984	0.0831874924388337	1147.8058652408818	nan	nan
97.3701	2.092517310970842	22.6376	2.88206	0.08370069243883367	1146.4941449898288	nan	nan
97.7701	2.104877310970842	22.5978	2.89348	0.08419509243883368	1144.4784513221875	nan	nan
98.1701	2.117657310970842	22.5747	2.90583	0.08470629243883368	1143.3085386658431	nan	nan
98.6001	2.131367310970842	22.5372	2.91901	0.08525469243883368	1141.409329808141	nan	nan
99.0001	2.144527310970842	22.5058	2.9313	0.08578109243883368	1139.8190589246249	nan	nan
99.4201	2.157787310970842	22.4467	2.94317	0.08631149243883368	1136.8259057648863	nan	nan
99.8401	2.170817310970842	22.4176	2.95582	0.08683269243883368	1135.3521196913096	nan	nan
100.26	2.184027310970842	22.3863	2.96913	0.08736109243883368	1133.7669133647473	nan	nan
100.69	2.197427310970842	22.3598	2.98177	0.08789709243883369	1132.4248057719713	nan	nan
101.09	2.210097310970842	22.3133	2.9935	0.08840389243883369	1130.0697867884207	nan	nan
101.5	2.223417310970842	22.2705	3.00639	0.08893669243883368	1127.902156412163	nan	nan
101.9	2.235697310970842	22.2267	3.0183	0.08942789243883369	1125.683880466367	nan	nan
102.32	2.2486173109708423	22.2095	3.03032	0.08994469243883368	1124.812776670301	nan	nan
102.73	2.2615573109708422	22.1655	3.04234	0.09046229243883369	1122.5843716105971	nan	nan
103.14	2.275227310970842	22.1423	3.05457	0.09100909243883368	1121.4093943972987	nan	nan
103.54	2.288077310970842	22.0888	3.06651	0.09152309243883368	1118.6998564269768	nan	nan
103.94	2.300637310970842	22.059	3.07869	0.09202549243883368	1117.1906184547229	nan	nan
104.35	2.313187310970842	22.0191	3.09083	0.09252749243883368	1115.1698602301278	nan	nan
104.76	2.326667310970842	21.98	3.10394	0.09306669243883368	1113.1896184611637	nan	nan
105.16	2.339237310970842	21.935	3.11521	0.09356949243883368	1110.910567831921	nan	nan
105.57	2.351757310970842	21.8957	3.12706	0.09407029243883368	1108.9201969490493	nan	nan
105.98	2.3651373109708422	21.8522	3.13884	0.09460549243883369	1106.7171146741148	nan	nan
106.38	2.377827310970842	21.8218	3.1511	0.09511309243883367	1105.1774893601375	nan	nan
106.78	2.390547310970842	21.7751	3.16315	0.09562189243883369	1102.812341262679	nan	nan
107.21	2.404227310970842	21.7515	3.17622	0.09616909243883369	1101.6171058215652	nan	nan
107.62	2.417797310970842	21.6936	3.18868	0.09671189243883369	1098.684727345273	nan	nan
108.02	2.4300773109708422	21.6542	3.20007	0.09720309243883368	1096.6892919054474	nan	nan
108.42	2.442567310970842	21.6244	3.21182	0.09770269243883367	1095.1800539331934	nan	nan
108.83	2.455077310970842	21.5973	3.22414	0.09820309243883368	1093.8075589986938	nan	nan
109.23	2.467757310970842	21.5388	3.23605	0.09871029243883368	1090.8447931806784	nan	nan
109.65	2.480977310970842	21.5159	3.24805	0.09923909243883369	1089.6850096382416	nan	nan
110.09	2.494947310970842	21.4696	3.26109	0.09979789243883369	1087.3401197685987	nan	nan
110.5	2.508557310970842	21.4143	3.27377	0.10034229243883369	1084.5394197731073	nan	nan
110.91	2.521487310970842	21.3765	3.28584	0.10085949243883369	1082.6250172445434	nan	nan
111.31	2.5343373109708422	21.347	3.29765	0.10137349243883369	1081.1309729431512	nan	nan
111.71	2.546987310970842	21.3019	3.30901	0.10187949243883368	1078.8468577569547	nan	nan
112.12	2.560407310970842	21.2546	3.32178	0.10241629243883368	1076.4513223177728	nan	nan
112.52	2.573127310970842	21.2166	3.33337	0.10292509243883367	1074.5267906753013	nan	nan
112.93	2.585627310970842	21.1757	3.34502	0.10342509243883369	1072.4553868811677	nan	nan
113.34	2.599127310970842	21.1389	3.35804	0.10396509243883369	1070.5916299221424	nan	nan
113.74	2.611697310970842	21.087	3.36991	0.10446789243883367	1067.9631248630828	nan	nan
114.15	2.624047310970842	21.0361	3.38073	0.10496189243883368	1065.3852653735619	nan	nan
114.55	2.6368373109708423	21.0197	3.39302	0.1054734924388337	1064.5546780331267	nan	nan
114.96	2.6506573109708422	20.9822	3.40566	0.10602629243883369	1062.6554691754243	nan	nan
115.36	2.6635473109708423	20.9217	3.41746	0.10654189243883369	1059.5914122183317	nan	nan
115.79	2.676817310970842	20.8803	3.42979	0.10707269243883369	1057.4946856394283	nan	nan
116.19	2.689487310970842	20.8423	3.44169	0.10757949243883369	1055.570153996957	nan	nan
116.6	2.702677310970842	20.7841	3.45451	0.10810709243883368	1052.622581849803	nan	nan
117.01	2.715147310970842	20.751	3.46651	0.10860589243883367	1050.9462134980713	nan	nan
117.42	2.7286873109708423	20.7149	3.47987	0.10914749243883369	1049.1179084377234	nan	nan
117.84	2.741777310970842	20.6598	3.49174	0.10967109243883368	1046.3273375561396	nan	nan
118.27	2.755427310970842	20.6214	3.50457	0.11021709243883368	1044.3825476858526	nan	nan
118.67	2.769097310970842	20.5732	3.51714	0.11076389243883368	1041.9414312340862	nan	nan
119.08	2.781667310970842	20.5224	3.52848	0.11126669243883368	1039.368636301519	nan	nan
119.49	2.794627310970842	20.4778	3.54078	0.11178509243883368	1037.1098439000918	nan	nan
119.89	2.807507310970842	20.4303	3.55285	0.11230029243883369	1034.7041793470023	nan	nan
120.29	2.820227310970842	20.3911	3.56488	0.11280909243883368	1032.7188730210846	nan	nan
120.71	2.8338973109708423	20.331	3.57756	0.11335589243883369	1029.675074291807	nan	nan
121.12	2.846667310970842	20.3048	3.59016	0.11386669243883368	1028.3481603698924	nan	nan
121.53	2.860137310970842	20.2477	3.60305	0.11440549243883368	1025.4562983492312	nan	nan
121.93	2.8731373109708422	20.1983	3.61482	0.1149254924388337	1022.9544072140183	nan	nan
122.34	2.8858873109708423	20.1597	3.62651	0.11543549243883369	1020.9994882298236	nan	nan
122.74	2.898537310970842	20.1021	3.63815	0.11594149243883368	1018.082303424393	nan	nan
123.15	2.911687310970842	20.0714	3.6504	0.11646749243883368	1016.5274844395543	nan	nan
123.56	2.924937310970842	20.0102	3.66243	0.11699749243883367	1013.4279755837842	nan	nan
123.96	2.9379473109708423	19.9796	3.67504	0.11751789243883369	1011.8782211558994	nan	nan
124.37	2.950777310970842	19.9224	3.68713	0.11803109243883368	1008.9812945782843	nan	nan
124.78	2.963477310970842	19.8588	3.69978	0.11853909243883369	1005.7602363556214	nan	nan
125.19	2.977067310970842	19.8291	3.71212	0.11908269243883368	1004.2560629403214	nan	nan
125.6	2.990177310970842	19.7769	3.72419	0.11960709243883368	1001.6123642104	nan	nan
126	3.003277310970842	19.7273	3.73618	0.12013109243883369	999.100343961279	nan	nan
126.43	3.016827310970842	19.682	3.74871	0.12067309243883369	996.8060996611749	nan	nan
126.83	3.030257310970842	19.6046	3.76053	0.12121029243883369	992.8861325788777	nan	nan
127.25	3.043517310970842	19.5607	3.7728	0.12174069243883368	990.6627920761276	nan	nan
127.67	3.057537310970842	19.5114	3.78635	0.12230149243883368	988.1659654978683	nan	nan
128.08	3.069907310970842	19.4598	3.798	0.12279629243883368	985.5526541096705	nan	nan
128.48	3.082677310970842	19.4065	3.80978	0.12330709243883367	982.8532452532563	nan	nan
128.91	3.096897310970842	19.3646	3.82407	0.12387589243883369	980.7311958895837	nan	nan
129.31	3.109697310970842	19.3044	3.83595	0.12438789243883369	977.6823326033526	nan	nan
129.73	3.123317310970842	19.2535	3.84829	0.12493269243883369	975.1044731138314	nan	nan
130.15	3.136807310970842	19.2071	3.86108	0.12547229243883368	972.7545186872347	nan	nan
130.57	3.150647310970842	19.1467	3.87392	0.1260258924388337	969.6955262870957	nan	nan
131	3.163927310970842	19.0815	3.88622	0.12655709243883367	966.3934351531708	nan	nan
131.4	3.1768273109708423	19.0382	3.8977	0.1270730924388337	964.2004819921441	nan	nan
131.82	3.190397310970842	18.9729	3.91088	0.12761589243883367	960.8933263012652	nan	nan
132.24	3.204137310970842	18.9237	3.92351	0.12816549243883368	958.4015642799601	nan	nan
132.65	3.2176373109708423	18.8647	3.93585	0.1287054924388337	955.4134756771754	nan	nan
133.06	3.230507310970842	18.8189	3.94783	0.12922029243883368	953.0939085923017	nan	nan
133.47	3.244307310970842	18.7537	3.96097	0.12977229243883368	949.7918174583768	nan	nan
133.87	3.257127310970842	18.7015	3.97276	0.13028509243883368	947.1481187284555	nan	nan
134.27	3.270077310970842	18.6517	3.98528	0.13080309243883367	944.6259693654271	nan	nan
134.68	3.283087310970842	18.5845	3.99686	0.13132349243883368	941.2225870924248	nan	nan
135.08	3.296247310970842	18.5275	4.00911	0.1318498924388337	938.3357896287175	nan	nan
135.51	3.310607310970842	18.4703	4.0226	0.1324242924388337	935.4388630511025	nan	nan
135.91	3.323207310970842	18.4128	4.03483	0.13292829243883367	932.5267428026258	nan	nan
136.32	3.336017310970842	18.351	4.0463	0.1334406924388337	929.3968466051326	nan	nan
136.72	3.349337310970842	18.3165	4.0592	0.1339734924388337	927.6495744560466	nan	nan
137.13	3.363127310970842	18.2379	4.0715	0.13452509243883368	923.6688326903029	nan	nan
137.53	3.375547310970842	18.1688	4.08308	0.13502189243883367	920.169223835177	nan	nan
137.95	3.389647310970842	18.1143	4.0957	0.13558589243883368	917.4090402953165	nan	nan
138.36	3.402537310970842	18.0497	4.10714	0.13610149243883368	914.137336503115	nan	nan
138.77	3.416287310970842	18.0011	4.12041	0.13665149243883368	911.675961823533	nan	nan
139.17	3.429377310970842	17.9407	4.13193	0.1371750924388337	908.616969423394	nan	nan
139.58	3.442697310970842	17.8771	4.14407	0.13770789243883366	905.395911200731	nan	nan
139.98	3.455787310970842	17.8081	4.15562	0.13823149243883368	901.9013669025591	nan	nan
140.4	3.469087310970842	17.744	4.16814	0.13876349243883368	898.6549858951269	nan	nan
140.81	3.483047310970842	17.6907	4.18072	0.13932189243883367	895.9555770387129	nan	nan
141.22	3.4961073109708423	17.6177	4.19241	0.1398442924388337	892.258450462386	nan	nan
141.62	3.5087873109708423	17.5523	4.20392	0.14035149243883369	888.9462302145533	nan	nan
142.02	3.522047310970842	17.4962	4.21596	0.14088189243883367	886.105013763431	nan	nan
142.43	3.536177310970842	17.4286	4.22845	0.1414470924388337	882.6813732626131	nan	nan
142.85	3.5501973109708422	17.3634	4.24115	0.1420078924388337	879.3792821286883	nan	nan
143.26	3.563397310970842	17.2842	4.25304	0.1425358924388337	875.3681530212212	nan	nan
143.67	3.5775173109708422	17.2185	4.26527	0.1431006924388337	872.0407391025271	nan	nan
144.07	3.590517310970842	17.1628	4.27785	0.14362069243883369	869.2197808792201	nan	nan
144.47	3.602977310970842	17.0963	4.2892	0.1441190924388337	865.851850504895	nan	nan
144.89	3.617637310970842	17.0018	4.30223	0.14470549243883368	861.0658441834855	nan	nan
145.3	3.630777310970842	16.9399	4.31387	0.1452310924388337	857.9308834290387	nan	nan