File: original_data/46NT9X.csv
Specimen name:	AWA_2_13_Rz
Specimen ID:	46NT9X
Material:	42CrMoS4
Specimen type:	Round Tensile Specimen
Gauge diameter:	4.999	mm
Gauge length:	25	mm
Parallel length:	30	mm
Original cross-section:	19.627100888700394	mm²
Cross-section after fracture:	9.119302253854462	mm²
Yield stress at 0.2% plastic strain:	1100.9558023634127	MPa
Yield stress at 1% plastic strain:	1133.4248897242016	MPa
Ultimate tensile strength:	1187.9135962164924	MPa
Uniform elongation:	5.08922890015456	%
Elongation after fracture:	14.307246429304483	%
Reduction of area:	53.53719173520641	%
Slope of linear-elastic region:	212193.1095109207	MPa
Crosshead seperation speed:	0.029944175703831302	mm/s
Strain rate:	0.0009981391901277101	s-1
Test temperature:	RT	Cel
Machine type:	INSTRON 8852TT
Standard:	DIN EN ISO 6892-1
Date:	2022-08-23 00:00:00
Heat treatment batch:	Batch 2
Time	Displacement	Force	Machine Displacement	Engineering Strain	Engineering Stress	True Strain	True Stress
s	mm	kN	mm		MPa		MPa
0	0.0011807531859228354	0.194668	0	4.723012743691342e-05	9.918326761751818	4.722901212966301e-05	9.918795205588737
0.430001	0.0012815871859228353	0.196711	0.000259399	5.126348743691341e-05	10.02241752949104	5.1262173509335316e-05	10.022931313566152
0.840001	0.0012053749859228353	0.194708	0.000160217	4.821499943691341e-05	9.92036476014123	4.8213837131243375e-05	9.920843070522555
1.27	0.0016046721859228354	0.311524	0.0103226	6.418688743691342e-05	15.872135256580297	6.418482754680876e-05	15.873154039539395
1.67	0.0018668531859228354	0.461764	0.022644	7.467412743691342e-05	23.526857207212107	7.467133946302909e-05	23.528614054745386
2.07	0.0015835671859228354	0.595756	0.034523	6.334268743691341e-05	30.353744212064722	6.334068137370462e-05	30.35566689979689
2.49	0.0009959561859228354	0.72632	0.0468674	3.9838247436913414e-05	37.005974754944724	3.9837453915014074e-05	37.00744900812366
2.89	0.0009872271859228353	0.884712	0.0590363	3.948908743691341e-05	45.076040777338726	3.9488307763407084e-05	45.07782078905429
3.29	0.0014635171859228354	1.08737	0.0715713	5.8540687436913416e-05	55.4014577173756	5.853897399776401e-05	55.40470095679538
3.70001	0.0020836331859228354	1.30472	0.084343	8.334532743691342e-05	66.47543146584354	8.334185440809305e-05	66.48097188244557
4.10001	0.0029643631859228355	1.54194	0.0961304	0.00011857452743691342	78.56178091425195	0.0001185674980334091	78.57109634029847
4.52001	0.004031203185922835	1.81155	0.108444	0.0001612481274369134	92.29839955848678	0.00016123512835496245	92.313282502581
4.92001	0.005523053185922836	2.09881	0.120903	0.00022092212743691345	106.93428499204971	0.00022089772773732272	106.9579091417861
5.35001	0.007250323185922836	2.42863	0.133461	0.00029001292743691343	123.7386007119471	0.0002899708818169677	123.77448650577654
5.77001	0.009114123185922836	2.75897	0.146423	0.00036456492743691346	140.56941041090684	0.00036449848979043607	140.62065708781313
6.17001	0.011097193185922836	3.10306	0.158493	0.00044388772743691345	158.100782056227	0.0004437892384238784	158.1709610530799
6.59001	0.013013653185922836	3.43422	0.170097	0.0005205461274369134	174.97337072216968	0.0005204106903003232	175.0644524327037
7.00001	0.015198853185922836	3.82402	0.18338	0.0006079541274369134	194.8336650269905	0.0006077693981938053	194.9521149578073
7.40001	0.017241853185922834	4.15532	0.194725	0.0006896741274369134	211.71338668729612	0.0006894364115272911	211.8593999325264
7.81001	0.019593653185922835	4.55317	0.207306	0.0007837461274369134	231.98382816798613	0.0007834391588206262	232.16564459494077
8.21001	0.021917053185922835	4.9498	0.220009	0.0008766821274369134	252.19211069779908	0.0008762980661106486	252.4132030139284
8.62001	0.024349553185922836	5.36239	0.232147	0.0009739821274369134	273.21355458498743	0.0009735081146062549	273.4796597041267
9.03001	0.026574653185922836	5.75013	0.244675	0.0010629861274369134	292.9688919727535	0.0010624215577344635	293.2803138406911
9.43001	0.029074753185922834	6.15566	0.256737	0.0011629901274369135	313.6306291442106	0.0011623143782941983	313.99537846956713
9.85001	0.031299553185922833	6.5422	0.268158	0.0012519821274369132	333.32482658029437	0.00125119905134315	333.7421433058039
10.27	0.03394855318592283	6.96805	0.281105	0.0013579421274369132	355.0218669335728	0.0013570209578619532	355.50396608284325
10.69	0.03650005318592283	7.39702	0.293732	0.0014600021274369132	376.87787116122547	0.0014589373605794404	377.42811365490473
11.12	0.03892815318592283	7.80759	0.305603	0.0015571261274369133	397.7963961297485	0.001555915063571723	398.41581529156235
11.52	0.04172995318592283	8.26416	0.318634	0.0016691981274369132	421.0586192460954	0.0016678065645567295	421.76144950488214
11.94	0.044199553185922835	8.68704	0.331085	0.0017679821274369134	442.60433821896	0.0017664210866928042	443.3868547784572
12.35	0.04647175318592283	9.07715	0.342949	0.0018588701274369131	462.4804270112988	0.0018571445664265231	463.34011806159435
12.75	0.04901655318592283	9.48672	0.355545	0.001960662127436913	483.3480020200865	0.0019587425381490044	484.2956841420195
13.16	0.05135825318592283	9.90453	0.367989	0.0020543301274369135	504.6354046970931	0.002052222876799485	505.6720924123337
13.58	0.05398185318592283	10.3231	0.380341	0.002159274127436913	525.9615293434987	0.0021569462454795185	527.0972244658373
14	0.05645655318592283	10.7416	0.393311	0.0022582621274369135	547.2840874927226	0.002255716085884519	548.5199984204563
14.41	0.05886495318592283	11.1331	0.404587	0.0023545981274369133	567.2309967290935	0.002351830404997321	568.566597771816
14.83	0.06151445318592283	11.5791	0.417343	0.002460578127436913	589.9546787710383	0.0024575558617416756	591.4063083498014
15.22	0.06386075318592284	11.9757	0.429184	0.0025544301274369133	610.161432802059	0.0025511731161583766	611.7200475486087
15.63	0.06636165318592284	12.3799	0.441612	0.0026544661274369137	630.7554065270683	0.0026509492544646513	632.4297253883921
16.04	0.06875805318592285	12.7881	0.453735	0.002750322127436914	651.5531800910187	0.002746546911989533	653.345161219425
16.45	0.07138005318592285	13.198	0.465813	0.0028552021274369137	672.4375685865191	0.002851133779972388	674.3575137629158
16.86	0.07410595318592283	13.6399	0.479057	0.0029642381274369136	694.9523557935491	0.0029598534363075085	697.0123600633444
17.26	0.07635535318592283	14.0212	0.490578	0.0030542141274369134	714.3795754406199	0.003049559490565741	716.561443632283
17.67	0.07873845318592283	14.4158	0.50248	0.0031495381274369134	734.4844295521701	0.003144588721733805	736.7977162670534
18.07	0.08125535318592284	14.8155	0.515114	0.0032502141274369134	754.8491284583704	0.0032449435986433694	757.3025497597691
18.5	0.08394105318592283	15.2427	0.527618	0.0033576421274369135	776.6149512572915	0.003352017833170793	779.2225463344303
18.91	0.08617415318592284	15.6346	0.539124	0.0034469661274369135	796.5822404775565	0.003441038956295315	799.3280324782005
19.32	0.08883055318592284	16.0576	0.552299	0.0035532221274369134	818.1340734455894	0.003546924347558255	821.0410855385662
19.73	0.09114855318592284	16.4433	0.563736	0.0036459421274369136	837.7854729154953	0.003639311791432482	840.8399902649526
20.13	0.09374185318592283	16.8618	0.576538	0.003749674127436913	859.1080310647194	0.0037426616236753115	862.3294062214761
20.56	0.09651485318592284	17.2926	0.589607	0.0038605941274369136	881.0572737186876	0.0038531611582381573	884.4586782555416
20.96	0.09884905318592284	17.6898	0.601311	0.0039539621274369136	901.2945977255498	0.0039461657634457074	904.8582824306201
21.37	0.10126075318592284	18.0817	0.613411	0.004050430127436913	921.2618869458147	0.004042249218687405	924.9933938479594
21.78	0.10376975318592284	18.4781	0.625542	0.004150790127436913	941.4584509848886	0.004142199362200249	945.3662474286288
22.18	0.10615775318592284	18.8597	0.637367	0.004246310127436914	960.9009556198798	0.00423731999353337	964.9812390791923
22.58	0.10845775318592284	19.2385	0.649002	0.004338310127436913	980.2008003676123	0.004328926788822748	984.4532154267689
22.99	0.11100875318592283	19.6389	0.660995	0.0044403501274369135	1000.6011642456272	0.00443052085899733	1005.0441837527986
23.39	0.11348975318592285	20.0184	0.673729	0.004539590127436914	1019.9366739651746	0.004529317266161354	1024.5667684209177
23.81	0.11620375318592284	20.4138	0.686134	0.004648150127436914	1040.082288044513	0.004637380836260381	1044.916746664232
24.23	0.11903875318592284	20.792	0.698349	0.004761550127436914	1059.3515628164043	0.0047502498047997934	1064.3957183853333
24.64	0.12215775318592284	21.129	0.710754	0.004886310127436914	1076.5216992472012	0.004874410860701905	1081.7819181286386
25.06	0.12656975318592284	21.433	0.724152	0.005062790127436914	1092.010487006733	0.005050017298129661	1097.5391069194084
25.47	0.13156075318592284	21.5954	0.735878	0.005262430127436914	1100.2847604677463	0.005248631928881709	1106.0749321399915
25.88	0.13933575318592284	21.6417	0.748108	0.005573430127436913	1102.6437436034907	0.005557956034967895	1108.7892514639202
26.3	0.15073775318592283	21.6243	0.760971	0.0060295101274369135	1101.7572143040966	0.006011405370011317	1108.40027058572
26.72	0.16248375318592284	21.6048	0.773476	0.0064993501274369135	1100.763690089258	0.006478320421829391	1107.9179387187176
27.13	0.17368575318592283	21.6084	0.785759	0.0069474301274369136	1100.9471099443049	0.006923407932253087	1108.5958630646464
27.54	0.18505975318592283	21.642	0.797768	0.0074023901274369135	1102.6590285914112	0.007375126897014398	1110.8213408985855
27.95	0.19548375318592284	21.6926	0.810493	0.007819350127436914	1105.2370965540174	0.00778893744462904	1113.879332385805
28.35	0.20496775318592284	21.7406	0.822182	0.008198710127436913	1107.682694621312	0.008165283283941406	1116.7642639476906
28.76	0.21522475318592285	21.7939	0.834236	0.008608990127436914	1110.3983274752038	0.0085721440923444	1119.9577357139603
29.18	0.22519875318592283	21.8338	0.846733	0.009007950127436914	1112.4312308686422	0.008967620554937435	1122.45195591651
29.6	0.23530275318592284	21.8634	0.85955	0.009412110127436913	1113.939349676807	0.009368092204382367	1124.4238695112506
30.03	0.24543975318592284	21.9107	0.872414	0.009817590127436914	1116.3492827722869	0.00976971070811081	1127.3091424696033
30.43	0.25459275318592284	21.9443	0.883888	0.010183710127436914	1118.061201419393	0.010132205528250698	1129.447212599382
30.84	0.2647397531859228	21.9725	0.896767	0.010589590127436911	1119.4979902839286	0.010533913137319776	1131.3530151495247
31.26	0.2745947531859228	22.0052	0.909187	0.010983790127436912	1121.1640539672728	0.01092390640577757	1133.4786846344757
31.67	0.2843897531859228	22.0238	0.920815	0.011375590127436911	1122.1117232183499	0.011311374635931848	1134.8764062588737
32.08	0.29452575318592283	22.0587	0.934074	0.011781030127436913	1123.8898768131116	0.011712174061313358	1137.1304573117682
32.49	0.3042237531859228	22.0821	0.945885	0.012168950127436913	1125.0821058709178	0.012095503697455233	1138.7731739065327
32.9	0.3147457531859228	22.1032	0.958344	0.012589830127436911	1126.1571500213327	0.012511237176589932	1140.3352772368999
33.31	0.32482775318592283	22.1429	0.970413	0.012993110127436914	1128.1798634228242	0.012909423789750967	1142.8384286318337
33.73	0.3349287531859228	22.1544	0.982346	0.013397150127436912	1128.76578795978	0.013308201866490583	1143.8880326797916
34.13	0.34445475318592284	22.1709	0.994431	0.013778190127436913	1129.6064622954125	0.013684133831448082	1145.1703949021
34.54	0.3548797531859228	22.2016	1.00687	0.014195190127436912	1131.1706260592862	0.014095381838879593	1147.2278081627696
34.97	0.3655057531859228	22.2276	1.0202	0.014620230127436913	1132.4953250124042	0.014514384969450402	1149.052667282332
35.36	0.3755277531859228	22.243	1.03183	0.015021110127436912	1133.279954392328	0.01490941043258227	1150.3030773924718
35.7801	0.3861627531859228	22.2741	1.04474	0.015446510127436912	1134.864498140096	0.015328427216677204	1152.3941941038854
36.1901	0.3959547531859228	22.2911	1.05628	0.015838190127436914	1135.7306474555958	0.01571407478720764	1153.7185653835545
36.6001	0.4064657531859228	22.3056	1.06891	0.01625863012743691	1136.4694218717577	0.016127873974144672	1154.9468578531128
37.0101	0.4166577531859228	22.3346	1.08102	0.016666310127436912	1137.9469707040814	0.01652895125682472	1156.912347826413
37.4201	0.4266537531859228	22.354	1.09341	0.01706615012743691	1138.9353999229463	0.016922159324223737	1158.3726424434838
37.8401	0.4372147531859228	22.371	1.10638	0.01748859012743691	1139.8015492384466	0.017337424637771055	1159.7350713596952
38.2501	0.44708075318592283	22.3796	1.11757	0.01788323012743691	1140.23971889217	0.01772520636985381	1160.6308881855628
38.6601	0.45766375318592284	22.4003	1.1309	0.018306550127436913	1141.294383058691	0.01814100258905079	1162.187545892317
39.0601	0.46740475318592284	22.4251	1.14274	0.018696190127436913	1142.5579420601266	0.018523564671125786	1163.919422576496
39.4801	0.4778667531859228	22.4423	1.15558	0.019114670127436912	1143.4342813675735	0.01893427992840961	1165.2906504683176
39.8801	0.4877047531859228	22.4579	1.16743	0.019508190127436913	1144.2291007394442	0.019320344474785343	1166.5509395860156
40.3101	0.4979627531859228	22.4688	1.18038	0.019918510127436912	1144.7844553005593	0.019722732072716676	1167.5868560671959
40.7201	0.5086097531859228	22.4882	1.19276	0.020344390127436912	1145.772884519424	0.020140207689346577	1169.082935079526
41.1201	0.5182047531859229	22.5122	1.20479	0.020728190127436916	1146.9956835530713	0.02051628447195236	1170.770828157109
41.5301	0.5280947531859228	22.5234	1.21704	0.02112379012743691	1147.5663231021065	0.0209037758364345	1171.8072732686296
41.9501	0.5384437531859229	22.5454	1.22963	0.021537750127436913	1148.6872222162833	0.021309090175114034	1173.4273605829574
42.3601	0.5488887531859228	22.5706	1.2423	0.021955550127436912	1149.9711612016129	0.021717997809672304	1175.2194106764816
42.7801	0.5589627531859228	22.5957	1.25439	0.022358510127436913	1151.250005190969	0.02211222295643718	1176.9902400912429
43.2201	0.5693867531859228	22.6042	1.26707	0.02277547012743691	1151.683079848719	0.02251998108847446	1177.913203430088
43.6101	0.5794507531859228	22.6145	1.27855	0.02317803012743691	1152.2078644339927	0.022913499323512266	1178.9137730289135
44.0201	0.5895917531859228	22.6424	1.29194	0.023583670127436913	1153.6293683106076	0.02330987180327917	1180.8361827821684
44.4301	0.5991317531859228	22.6541	1.30352	0.023965270127436912	1154.2254828395105	0.023682610150984277	1181.8868083237305
44.8401	0.6098357531859228	22.6708	1.31638	0.02439343012743691	1155.07634716709	0.024100661936721248	1183.2526213335655
45.2601	0.6201447531859228	22.705	1.32872	0.02480579012743691	1156.8188357900376	0.024503121591683233	1185.5146410461114
45.6801	0.6303357531859228	22.6913	1.34094	0.025213430127436914	1156.120821341664	0.024900815429228774	1185.270592889437
46.0801	0.6400067531859228	22.7235	1.35331	0.025600270127436913	1157.7614100451406	0.025278070569020254	1187.4004148854185
46.5001	0.6507557531859228	22.7363	1.36555	0.026030230127436913	1158.4135695297525	0.025697210376350168	1188.5673413273576
46.9001	0.6605907531859229	22.7598	1.37728	0.026423630127436915	1159.610893583532	0.026080556392000815	1190.25202292733
47.3301	0.6709037531859228	22.7634	1.38959	0.02683615012743691	1159.7943134385791	0.026482375985914294	1190.9187277509645
47.7401	0.6813117531859229	22.7863	1.40315	0.027252470127436913	1160.9610675165175	0.026887733380522486	1192.6001243281285
48.1401	0.6913517531859228	22.8029	1.41471	0.02765407012743691	1161.8068368481236	0.02727860274343102	1193.935524588857
48.5401	0.7013607531859228	22.8174	1.42715	0.028054430127436913	1162.5456112642853	0.027668113226081828	1195.1601658854574
48.9501	0.7117027531859228	22.8364	1.43912	0.028468110127436913	1163.5136604992563	0.028070423434195028	1196.6366955211263
49.3601	0.7215307531859229	22.8482	1.45172	0.028861230127436913	1164.1148700241326	0.028452588794978667	1197.7126571826705
49.7701	0.7315267531859229	22.8494	1.46381	0.029261070127436915	1164.176009975815	0.02884113713827278	1198.2410458443971
50.1801	0.7415827531859228	22.8823	1.47626	0.029663310127436913	1165.8522636511066	0.029231865432108952	1200.4353009105637
50.5801	0.7514117531859228	22.8912	1.48817	0.03005647012743691	1166.3057182927507	0.029613626105132462	1201.3607512740755
51.0101	0.7622097531859228	22.9071	1.5013	0.030488390127436912	1167.115822652542	0.03003285503303121	1202.699305177477
51.4101	0.7725167531859228	22.9316	1.51341	0.030900670127436913	1168.3640966660569	0.030432857161155732	1204.4673302058757
51.8301	0.7829887531859228	22.9326	1.52564	0.03131955012743691	1168.4150466257925	0.030839098940424824	1205.0092802482404
52.2501	0.7932307531859228	22.946	1.539	0.03172923012743691	1169.0977760862454	0.031236258725793234	1206.1923484651606
52.6601	0.8033657531859228	22.9617	1.55168	0.03213463012743691	1169.8976904540896	0.03162911410062779	1207.4919200237746
53.0701	0.8139747531859228	22.969	1.56351	0.03255899012743691	1170.2696251601574	0.03204017751634473	1208.3724223321863
53.4901	0.8239117531859228	22.9889	1.57662	0.03295647012743691	1171.2835293588898	0.032425049973176745	1209.884900004965
53.9001	0.8342387531859228	22.9982	1.58862	0.03336955012743691	1171.7573639844281	0.03282487071922901	1210.8583800790998
54.3001	0.8438197531859228	23.0089	1.6005	0.03375279012743691	1172.302528553596	0.03319566638712702	1211.871009765729
54.7101	0.8539807531859228	23.0133	1.61239	0.034159230127436914	1172.526708376431	0.03358875855086778	1212.5793180384278
55.1101	0.8644507531859228	23.0266	1.62495	0.03457803012743691	1173.2043428409106	0.033993643224980205	1213.7714379533036
55.5201	0.8747627531859228	23.044	1.63653	0.03499051012743691	1174.090872140305	0.03439225771629899	1215.1729106924615
55.9301	0.8850757531859228	23.0441	1.64877	0.03540303012743691	1174.0959671362784	0.03479075200971547	1215.6625220333062
56.3301	0.8950827531859228	23.0709	1.66122	0.03580331012743691	1175.4614260571848	0.03517727072318576	1217.5468360371494
56.7601	0.9057277531859228	23.0881	1.67397	0.03622911012743691	1176.3377653646319	0.03558826815916369	1218.9554358130904
57.1701	0.9162877531859228	23.0857	1.68623	0.03665151012743691	1176.215485461267	0.035995816960304565	1219.3255592386988
57.5801	0.9262167531859228	23.0991	1.69814	0.037048670127436914	1176.89821492172	0.036378861730843315	1220.500728659924
57.9901	0.9371287531859228	23.1022	1.71069	0.03748515012743691	1177.0561597968997	0.0367996598901012	1221.1782866553108
58.4201	0.9471447531859228	23.1053	1.72254	0.03788579012743691	1177.214104672079	0.0371857499111243	1221.813791176744
58.8301	0.9581567531859229	23.1295	1.73585	0.03832627012743692	1178.4470936976734	0.03761006110268395	1223.6125753416234
59.2401	0.9682297531859229	23.1393	1.74702	0.03872919012743691	1178.9464033030793	0.03799803341518501	1224.606042706662
59.6601	0.9786097531859228	23.1329	1.75951	0.03914439012743691	1178.6203235607732	0.0383976727478869	1224.7566973183618
60.0701	0.9896077531859228	23.1597	1.77264	0.03958431012743691	1179.9857824816795	0.03882093145068314	1226.6947056414006
60.4801	0.9998567531859228	23.1584	1.78516	0.039994270127436914	1179.9195475340236	0.039215203645254895	1227.1095686467427
60.8901	1.010510753185923	23.1612	1.79689	0.04042043012743692	1180.0622074212824	0.03962489120024904	1227.7608294223833
61.2901	1.020600753185923	23.173	1.80937	0.04082403012743692	1180.663416946159	0.040012736081296685	1228.8628558499317
61.7101	1.031110753185923	23.1702	1.82163	0.04124443012743692	1180.5207570589002	0.04041656526726071	1229.210662937405
62.1201	1.041250753185923	23.1876	1.83392	0.04165003012743692	1181.4072863582942	0.04080602331505559	1230.6129354278908
62.5401	1.051920753185923	23.1961	1.84583	0.04207683012743692	1181.8403610160447	0.04121567394068166	1231.5684571242657
62.9501	1.063110753185923	23.2176	1.85902	0.04252443012743692	1182.9357851503535	0.041645108591243	1233.2394552912244
63.3501	1.073550753185923	23.2116	1.87141	0.04294203012743692	1182.6300853919417	0.042045594538670336	1233.414622148456
63.7501	1.0839707531859228	23.2169	1.88315	0.043358830127436916	1182.9001201785386	0.042445153407178075	1234.1892855470846
64.1601	1.094300753185923	23.2116	1.8949	0.04377203012743692	1182.6300853919417	0.04284110366910633	1234.3962051193312
64.5601	1.1044807531859229	23.2267	1.90699	0.044179230127436915	1183.3994297839447	0.04323115109302249	1235.681105525047
64.9801	1.1153207531859228	23.2306	1.91933	0.044612830127436914	1183.5981346269123	0.0436463192799173	1236.401797146174
65.3901	1.125840753185923	23.2344	1.93167	0.04503363012743691	1183.7917444739066	0.044049066839077895	1237.102184042458
65.7901	1.1366407531859228	23.2495	1.94422	0.045465630127436915	1184.5610888659096	0.044462365245217184	1238.417905195641
66.2001	1.146760753185923	23.2523	1.95617	0.04587043012743692	1184.7037487531686	0.04484948619889682	1239.0466192820634
66.6101	1.157680753185923	23.2514	1.96829	0.04630723012743692	1184.6578937894067	0.045267041566822264	1239.5161194993975
67.0201	1.1683307531859228	23.2694	1.98034	0.046733230127436916	1185.574993064642	0.04567410489309024	1240.9807420488664
67.4301	1.179500753185923	23.2756	1.99335	0.04718003012743692	1185.890882815001	0.046100865652728105	1241.8412503940656
67.8401	1.189980753185923	23.2596	2.00475	0.04759923012743692	1185.075683459236	0.04650109875943233	1241.4843736346415
68.2601	1.200850753185923	23.2694	2.01694	0.04803403012743692	1185.574993064642	0.046916056867308716	1242.5229379998448
68.6701	1.212100753185923	23.2629	2.02952	0.04848403012743692	1185.2438183263625	0.04734534008259951	1242.7092153224564
69.0801	1.222540753185923	23.2681	2.04191	0.04890163012743692	1185.5087581169864	0.0477435501146711	1243.4820689192604
69.4901	1.2337507531859229	23.2818	2.05423	0.04935003012743691	1186.2067725653599	0.04817095357186313	1244.7461125288303
69.9001	1.244160753185923	23.283	2.06644	0.049766430127436916	1186.2679125170423	0.048567691926638595	1245.3042316977421
70.3001	1.254890753185923	23.2867	2.07819	0.05019563012743692	1186.4564273680628	0.04897646122214115	1246.0113553585502
70.7201	1.2659807531859228	23.29	2.09019	0.050639230127436916	1186.6245622351894	0.04939876952917208	1246.7143165170862
71.1201	1.276640753185923	23.2967	2.1026	0.051065630127436916	1186.965926965416	0.049804535356633255	1247.579089965702
71.5401	1.288260753185923	23.2997	2.11553	0.05153043012743692	1187.1187768446218	0.05024665547314761	1248.2915180277819
71.9501	1.299760753185923	23.2939	2.12837	0.05199043012743692	1186.8232670781572	0.05068401743710456	1248.5267192188005
72.3701	1.3110307531859229	23.3041	2.14091	0.052441230127436914	1187.342956667457	0.0511124466566504	1249.6086818982465
72.7801	1.3217407531859229	23.291	2.15276	0.052869630127436916	1186.6755121949245	0.0515194174408709	1249.414607605957
73.1901	1.333150753185923	23.3088	2.16525	0.05332603012743692	1187.582421478213	0.05195280548335544	1250.9114774647749
73.6001	1.344030753185923	23.3082	2.17776	0.05376123012743692	1187.5518515023718	0.05236588757482576	1251.3960998792545
74.0001	1.354730753185923	23.3059	2.18983	0.05418923012743692	1187.4346665949806	0.05277196922992297	1251.7808370043924
74.4101	1.3658007531859229	23.3023	2.20147	0.05463203012743691	1187.2512467399335	0.05319191947876879	1252.1131926206667
74.8201	1.376900753185923	23.3095	2.21329	0.05507603012743692	1187.6180864500277	0.053612830802870576	1253.0273759592383
75.2201	1.388050753185923	23.3109	2.22601	0.05552203012743692	1187.6894163936572	0.05403545983398475	1253.6323439527036
75.6301	1.3996907531859228	23.2994	2.23903	0.05598763012743691	1187.103491856701	0.05447647132098891	1253.5666030817629
76.0601	1.4111807531859228	23.301	2.25104	0.056447230127436916	1187.1850117922777	nan	nan
76.4601	1.421840753185923	23.2979	2.26313	0.05687363012743692	1187.0270669170982	nan	nan
76.8501	1.4327007531859228	23.302	2.27558	0.05730803012743691	1187.235961752013	nan	nan
77.2601	1.4436207531859229	23.3059	2.28776	0.05774483012743691	1187.4346665949806	nan	nan
77.6801	1.4557807531859228	23.3121	2.30064	0.05823123012743691	1187.7505563453396	nan	nan
78.0901	1.467660753185923	23.2963	2.31338	0.05870643012743692	1186.9455469815216	nan	nan
78.4901	1.478650753185923	23.308	2.32561	0.05914603012743692	1187.5416615104248	nan	nan
78.9001	1.490100753185923	23.3037	2.3371	0.05960403012743692	1187.322576683563	nan	nan
79.3001	1.501720753185923	23.3026	2.34894	0.06006883012743692	1187.2665317278543	nan	nan
79.7301	1.513860753185923	23.2848	2.36226	0.060554430127436915	1186.3596224445657	nan	nan
80.1401	1.525310753185923	23.2976	2.37463	0.061012430127436915	1187.0117819291775	nan	nan
80.5401	1.536530753185923	23.2809	2.38651	0.061461230127436914	1186.160917601598	nan	nan
80.9401	1.5476007531859228	23.2798	2.39853	0.061904030127436914	1186.1048726458894	nan	nan
81.3501	1.5596707531859229	23.2773	2.41113	0.06238683012743691	1185.9774977465509	nan	nan
81.7601	1.570970753185923	23.2904	2.42281	0.06283883012743692	1186.6449422190835	nan	nan
82.1601	1.582560753185923	23.2875	2.43536	0.06330243012743691	1186.497187335851	nan	nan
82.5701	1.594120753185923	23.2657	2.44694	0.06376483012743692	1185.3864782136216	nan	nan
82.9701	1.606160753185923	23.2574	2.45924	0.06424643012743692	1184.9635935478186	nan	nan
83.3901	1.6183707531859228	23.2667	2.47158	0.06473483012743692	1185.437428173357	nan	nan
83.8001	1.629770753185923	23.248	2.48329	0.06519083012743691	1184.4846639263067	nan	nan
84.2001	1.641030753185923	23.2483	2.49561	0.06564123012743692	1184.4999489142272	nan	nan
84.6201	1.6537207531859228	23.2464	2.50833	0.06614883012743691	1184.4031439907303	nan	nan
85.0301	1.6659307531859229	23.2367	2.521	0.06663723012743691	1183.9089293812976	nan	nan
85.4401	1.6775807531859228	23.2299	2.5331	0.06710323012743691	1183.5624696550976	nan	nan
85.8501	1.6898607531859229	23.2243	2.54513	0.06759443012743692	1183.2771498805798	nan	nan
86.2601	1.7018207531859229	23.2027	2.55703	0.06807283012743691	1182.1766307502974	nan	nan
86.6701	1.714070753185923	23.1953	2.56848	0.06856283012743691	1181.7996010482561	nan	nan
87.0801	1.7260907531859229	23.1966	2.58086	0.06904363012743692	1181.865835995912	nan	nan
87.5001	1.738850753185923	23.1751	2.59348	0.06955403012743692	1180.7704118616032	nan	nan
87.9101	1.751430753185923	23.166	2.60629	0.07005723012743692	1180.306767228012	nan	nan
88.3201	1.763560753185923	23.1438	2.61787	0.07054243012743693	1179.175678121888	nan	nan
88.7301	1.775460753185923	23.1443	2.63	0.07101843012743692	1179.2011531017558	nan	nan
89.1501	1.7883507531859228	23.1277	2.64302	0.07153403012743692	1178.3553837701497	nan	nan
89.5501	1.8001107531859228	23.1218	2.65506	0.07200443012743692	1178.0547790077114	nan	nan
89.9801	1.812340753185923	23.0777	2.66663	0.07249363012743693	1175.8078857833848	nan	nan
90.4001	1.8255607531859228	23.0847	2.67934	0.07302243012743691	1176.1645355015319	nan	nan
90.7901	1.8380107531859229	23.0651	2.69136	0.07352043012743692	1175.16591629072	nan	nan
91.1901	1.850390753185923	23.0318	2.70319	0.07401563012743692	1173.4692826315343	nan	nan
91.6001	1.8631907531859229	23.0113	2.71576	0.07452763012743692	1172.4248084569606	nan	nan
92.0001	1.875500753185923	22.9942	2.72792	0.07502003012743691	1171.553564145487	nan	nan
92.4101	1.8874207531859228	22.9682	2.73932	0.07549683012743691	1170.228865192369	nan	nan
92.8101	1.8997207531859228	22.9448	2.75134	0.07598883012743692	1169.036636134563	nan	nan
93.2201	1.912450753185923	22.9265	2.76381	0.07649803012743692	1168.1042518714069	nan	nan
93.6201	1.9250807531859229	22.9022	2.77595	0.07700323012743691	1166.8661678498393	nan	nan
94.0301	1.937100753185923	22.8738	2.78767	0.07748403012743692	1165.4191889933566	nan	nan
94.4501	1.950100753185923	22.8428	2.79933	0.07800403012743691	1163.8397402415621	nan	nan
94.8601	1.9631107531859229	22.817	2.81171	0.07852443012743691	1162.5252312803914	nan	nan
95.2701	1.975700753185923	22.7873	2.82417	0.07902803012743692	1161.0120174762528	nan	nan
95.6901	1.989130753185923	22.7525	2.83697	0.07956523012743692	1159.2389588774643	nan	nan
96.1001	2.002210753185923	22.7145	2.84894	0.08008843012743691	1157.302860407523	nan	nan
96.5101	2.0143907531859226	22.6917	2.86147	0.0805756301274369	1156.141201325558	nan	nan
96.9201	2.027290753185923	22.6666	2.87392	0.0810916301274369	1154.8623573362017	nan	nan
97.3401	2.0404407531859228	22.6231	2.88641	0.0816176301274369	1152.6460340877163	nan	nan
97.7401	2.0527707531859227	22.6002	2.89811	0.0821108301274369	1151.4792800097778	nan	nan
98.1701	2.0658507531859227	22.5633	2.91092	0.0826340301274369	1149.5992264955453	nan	nan
98.5801	2.079080753185923	22.5304	2.92337	0.08316323012743691	1147.9229728202538	nan	nan
98.9901	2.091760753185923	22.4963	2.93571	0.08367043012743691	1146.18557919328	nan	nan
99.4101	2.104790753185923	22.4515	2.94795	0.08419163012743691	1143.9030209971384	nan	nan
99.8101	2.117390753185923	22.4329	2.9602	0.08469563012743692	1142.9553517460618	nan	nan
100.23	2.1302307531859226	22.3923	2.97225	0.0852092301274369	1140.8867833808085	nan	nan
100.63	2.1427607531859225	22.3632	2.98414	0.0857104301274369	1139.4041395525112	nan	nan
101.04	2.1560807531859227	22.3355	2.99786	0.08624323012743691	1137.9928256678434	nan	nan
101.44	2.168570753185923	22.3052	3.00967	0.08674283012743692	1136.4490418878638	nan	nan
101.86	2.1811607531859227	22.2681	3.02113	0.08724643012743691	1134.558798381684	nan	nan
102.26	2.1942207531859226	22.2206	3.03333	0.0877688301274369	1132.1386752942572	nan	nan
102.66	2.207000753185923	22.1994	3.04586	0.08828003012743692	1131.0585361478688	nan	nan
103.07	2.219620753185923	22.1585	3.05801	0.08878483012743692	1128.974682794695	nan	nan
103.47	2.2319307531859227	22.1094	3.0692	0.08927723012743691	1126.4730397716917	nan	nan
103.88	2.244970753185923	22.0759	3.0817	0.08979883012743692	1124.766216120559	nan	nan
104.28	2.2577307531859225	22.0489	3.09473	0.0903092301274369	1123.3905672077058	nan	nan
104.7	2.270460753185923	21.9974	3.10644	0.09081843012743691	1120.7666442813374	nan	nan
105.11	2.2831007531859226	21.9793	3.11849	0.09132403012743691	1119.8444500101286	nan	nan
105.53	2.2964007531859227	21.9411	3.13172	0.09185603012743691	1117.89816154824	nan	nan
105.92	2.308900753185923	21.8915	3.14323	0.09235603012743691	1115.371043545369	nan	nan
106.32	2.3217407531859227	21.8734	3.15523	0.0928696301274369	1114.4488492741602	nan	nan
106.73	2.3345007531859228	21.8223	3.16685	0.09338003012743691	1111.8453063316863	nan	nan
107.13	2.3472807531859226	21.7783	3.17856	0.0938912301274369	1109.603508103333	nan	nan
107.54	2.3599807531859227	21.749	3.19132	0.09439923012743691	1108.1106742830887	nan	nan
107.96	2.3733207531859226	21.7062	3.20423	0.0949328301274369	1105.9300160064176	nan	nan
108.37	2.3859207531859226	21.6784	3.21588	0.09543683012743691	1104.5136071257764	nan	nan
108.78	2.399190753185923	21.6193	3.22888	0.09596763012743692	1101.5024645054198	nan	nan
109.18	2.4112107531859226	21.6001	3.2407	0.09644843012743691	1100.5242252785022	nan	nan
109.59	2.4241007531859227	21.5727	3.25317	0.0969640301274369	1099.1281963817548	nan	nan
110	2.4371307531859228	21.5109	3.26581	0.09748523012743691	1095.979488870113	nan	nan
110.42	2.4498007531859227	21.4766	3.27805	0.0979920301274369	1094.2319052511923	nan	nan
110.83	2.462910753185923	21.454	3.29047	0.09851643012743691	1093.0804361611745	nan	nan
111.25	2.476450753185923	21.3917	3.30303	0.09905803012743691	1089.9062536696651	nan	nan
111.68	2.490160753185923	21.3485	3.31633	0.09960643012743692	1087.7052154091	nan	nan
112.1	2.503040753185923	21.3114	3.32851	0.10012163012743691	1085.8149719029202	nan	nan
112.53	2.5163707531859227	21.2792	3.34131	0.10065483012743691	1084.1743831994436	nan	nan
112.94	2.529400753185923	21.2338	3.35311	0.10117603012743691	1081.8612550274609	nan	nan
113.35	2.5420507531859227	21.2015	3.36651	0.1016820301274369	1080.2155713280106	nan	nan
113.76	2.555500753185923	21.1629	3.37894	0.10222003012743691	1078.248902882228	nan	nan
114.18	2.5686807531859226	21.1217	3.39175	0.1027472301274369	1076.1497645411334	nan	nan
114.58	2.5819907531859227	21.0692	3.40385	0.1032796301274369	1073.47489165503	nan	nan
115	2.594950753185923	21.0261	3.41612	0.10379803012743691	1071.2789483904385	nan	nan
115.41	2.607150753185923	20.9941	3.42828	0.10428603012743691	1069.648549678909	nan	nan
115.82	2.6205507531859227	20.9529	3.44117	0.1048220301274369	1067.5494113378145	nan	nan
116.25	2.6335107531859228	20.9125	3.45388	0.10534043012743691	1065.4910329645081	nan	nan
116.66	2.646610753185923	20.862	3.46623	0.10586443012743692	1062.9180599978754	nan	nan
117.06	2.6590607531859227	20.8303	3.478	0.1063624301274369	1061.3029462742666	nan	nan
117.47	2.6714607531859227	20.78	3.48969	0.10685843012743691	1058.7401632995807	nan	nan
117.88	2.6850707531859226	20.7389	3.50246	0.1074028301274369	1056.64611995446	nan	nan
118.31	2.698870753185923	20.7002	3.5157	0.10795483012743691	1054.6743565127035	nan	nan
118.72	2.7121107531859225	20.6567	3.52766	0.1084844301274369	1052.4580332642179	nan	nan
119.13	2.7248607531859226	20.5985	3.53976	0.1089944301274369	1049.4927456076234	nan	nan
119.52	2.737300753185923	20.5703	3.5511	0.10949203012743691	1048.0559567430878	nan	nan
119.94	2.7496207531859227	20.5208	3.5631	0.10998483012743691	1045.5339337361904	nan	nan
120.34	2.7626307531859227	20.4774	3.57576	0.1105052301274369	1043.3227054836782	nan	nan
120.74	2.7754207531859225	20.4374	3.58768	0.1110168301274369	1041.2847070942662	nan	nan
121.14	2.788340753185923	20.3974	3.60022	0.11153363012743692	1039.2467087048542	nan	nan
121.55	2.800760753185923	20.3427	3.61104	0.11203043012743691	1036.459745907333	nan	nan
121.96	2.8139507531859227	20.2981	3.62383	0.11255803012743691	1034.1873777031387	nan	nan
122.38	2.826660753185923	20.2517	3.63605	0.11306643012743692	1031.8232995714206	nan	nan
122.77	2.839540753185923	20.2242	3.64803	0.11358163012743691	1030.4221756786997	nan	nan
123.2	2.8539307531859226	20.156	3.661	0.1141572301274369	1026.947388424752	nan	nan
123.61	2.8662707531859226	20.1201	3.67252	0.1146508301274369	1025.118284870255	nan	nan
124.02	2.879600753185923	20.0739	3.68591	0.11518403012743691	1022.7643967304837	nan	nan
124.43	2.8917407531859225	20.0318	3.6972	0.1156696301274369	1020.6194034256275	nan	nan
124.83	2.904800753185923	19.9973	3.70935	0.11619203012743691	1018.8616298147596	nan	nan
125.26	2.918290753185923	19.9403	3.72248	0.11673163012743691	1015.9574821098473	nan	nan
125.67	2.9315407531859226	19.891	3.7347	0.1172616301274369	1013.445649094897	nan	nan
126.08	2.9450407531859226	19.8438	3.74661	0.1178016301274369	1011.0408109953909	nan	nan
126.49	2.9577007531859225	19.7867	3.75842	0.1183080301274369	1008.131568294505	nan	nan
126.9	2.970840753185923	19.733	3.771	0.11883363012743692	1005.3955554567192	nan	nan
127.31	2.983380753185923	19.7011	3.78265	0.11933523012743691	1003.7702517411631	nan	nan
127.74	2.997820753185923	19.6465	3.79584	0.11991283012743692	1000.9883839396156	nan	nan
128.16	3.010970753185923	19.5861	3.80804	0.12043883012743692	997.9110063716032	nan	nan
128.59	3.024390753185923	19.5598	3.82104	0.12097563012743691	996.5710224305649	nan	nan
129.01	3.0383907531859227	19.4947	3.83334	0.1215356301274369	993.2541800517968	nan	nan
129.4	3.0510607531859226	19.4436	3.84474	0.1220424301274369	990.6506371093227	nan	nan
129.8	3.0643507531859226	19.3975	3.85681	0.12257403012743691	988.3018439655253	nan	nan
130.22	3.0780207531859225	19.3489	3.86999	0.1231208301274369	985.8256759223897	nan	nan
130.65	3.0932707531859225	19.2743	3.88279	0.1237308301274369	982.0248089261361	nan	nan
131.06	3.1058907531859226	19.2343	3.8942	0.12423563012743691	979.986810536724	nan	nan
131.46	3.119350753185923	19.1797	3.90694	0.12477403012743692	977.2049427351766	nan	nan
131.86	3.132160753185923	19.1184	3.91824	0.1252864301274369	974.0817102034025	nan	nan
132.28	3.1460407531859227	19.0752	3.93092	0.1258416301274369	971.8806719428372	nan	nan
132.68	3.1590007531859228	19.0228	3.94278	0.1263600301274369	969.2108940527075	nan	nan
133.08	3.172500753185923	18.9582	3.95526	0.12690003012743692	965.9195266538071	nan	nan
133.49	3.1852107531859226	18.9138	3.96717	0.1274084301274369	963.6573484415596	nan	nan
133.89	3.1993107531859226	18.8719	3.97939	0.1279724301274369	961.5225451286506	nan	nan
134.3	3.2130707531859226	18.8047	3.99151	0.1285228301274369	958.0987078344382	nan	nan
134.7	3.2260407531859228	18.7458	4.00375	0.1290416301274369	955.0977552060289	nan	nan
135.11	3.2399907531859227	18.6869	4.016	0.12959963012743692	952.0968025776197	nan	nan
135.51	3.2527907531859226	18.6255	4.0277	0.1301116301274369	948.968475049872	nan	nan
135.92	3.2655507531859227	18.5811	4.03903	0.1306220301274369	946.7062968376244	nan	nan
136.33	3.279940753185923	18.5266	4.05267	0.1311976301274369	943.9295240320505	nan	nan
136.73	3.292970753185923	18.4506	4.06413	0.1317188301274369	940.0573270921677	nan	nan
137.13	3.306310753185923	18.4127	4.07554	0.13225243012743693	938.1263236181998	nan	nan
137.54	3.3200507531859227	18.3418	4.08862	0.1328020301274369	934.5139714729667	nan	nan
137.96	3.3341307531859226	18.2832	4.10125	0.1333652301274369	931.5283038324781	nan	nan
138.35	3.3470807531859226	18.2281	4.11293	0.13388323012743691	928.720961051063	nan	nan
138.76	3.3604607531859227	18.171	4.12497	0.1344184301274369	925.8117183501771	nan	nan
139.16	3.3736807531859228	18.1237	4.13741	0.13494723012743692	923.4017852546974	nan	nan
139.57	3.387800753185923	18.0522	4.14995	0.13551203012743693	919.7588631336232	nan	nan
139.98	3.4007007531859226	17.9962	4.16207	0.13602803012743692	916.9056653884463	nan	nan
140.39	3.4146507531859225	17.9237	4.17372	0.1365860301274369	913.2117933076369	nan	nan
140.8	3.4279607531859226	17.8666	4.18634	0.1371184301274369	910.3025506067511	nan	nan
141.22	3.442370753185923	17.8096	4.19931	0.1376948301274369	907.3984029018388	nan	nan
141.64	3.4567907531859228	17.7324	4.21162	0.1382716301274369	903.4650660102734	nan	nan
142.05	3.4704107531859227	17.671	4.22388	0.1388164301274369	900.336738482526	nan	nan
142.45	3.483920753185923	17.5978	4.23605	0.1393568301274369	896.6072014299018	nan	nan
142.86	3.497200753185923	17.5426	4.24796	0.13988803012743692	893.7947636525131	nan	nan
143.26	3.5105107531859225	17.4797	4.26035	0.1404204301274369	890.5900111851627	nan	nan
143.7	3.5249407531859225	17.3976	4.27315	0.1409976301274369	886.4070194908945	nan	nan
144.11	3.5390707531859227	17.3432	4.28522	0.1415628301274369	883.635341681294	nan	nan
144.52	3.552580753185923	17.2675	4.29758	0.14210323012743692	879.7784297293315	nan	nan
144.93	3.5669107531859225	17.2123	4.30966	0.14267643012743692	876.9659919519428	nan	nan
145.34	3.580300753185923	17.1341	4.32182	0.1432120301274369	872.9817051006421	nan	nan
145.75	3.594130753185923	17.0723	4.3343	0.14376523012743692	869.8329975890005	nan	nan
146.16	3.6077107531859225	16.9984	4.34609	0.1443084301274369	866.0677955645618	nan	nan
146.56	3.6208307531859227	16.9307	4.3583	0.1448332301274369	862.6184832904818	nan	nan
146.96	3.634540753185923	16.8694	4.3704	0.1453816301274369	859.4952507587076	nan	nan
147.37	3.648840753185923	16.7776	4.38318	0.14595363012743692	854.8180444550069	nan	nan
147.78	3.662410753185923	16.7205	4.39499	0.1464964301274369	851.9088017541212	nan	nan
147.98	3.6698307531859227	16.636	4.40125	0.14679323012743692	847.6035301564882	nan	nan