File: original_data/46NT71.csv
Specimen name:	AWA_1_01_Rz
Specimen ID:	46NT71
Material:	42CrMoS4
Specimen type:	Round Tensile Specimen
Gauge diameter:	5.003	mm
Gauge length:	25	mm
Parallel length:	30	mm
Original cross-section:	19.6585230984216	mm²
Cross-section after fracture:	8.764211177811863	mm²
Yield stress at 0.2% plastic strain:	1132.3284914867481	MPa
Yield stress at 1% plastic strain:	1146.282708320003	MPa
Ultimate tensile strength:	1198.7319638417841	MPa
Uniform elongation:	5.208216723513033	%
Elongation after fracture:	14.602290209541668	%
Reduction of area:	55.41775374511452	%
Slope of linear-elastic region:	201875.5901734028	MPa
Crosshead seperation speed:	0.02983036920390606	mm/s
Strain rate:	0.000994345640130202	s-1
Test temperature:	RT	Cel
Machine type:	INSTRON 8852TT
Standard:	DIN EN ISO 6892-1
Date:	2022-08-18 00:00:00
Heat treatment batch:	Batch 1
Time	Displacement	Force	Machine Displacement	Engineering Strain	Engineering Stress	True Strain	True Stress
s	mm	kN	mm		MPa		MPa
0	0.0007143817674338952	0.117967	0	2.857527069735581e-05	6.0008068464447195	2.8574862432169385e-05	6.00097832112476
0.430001	0.0006413187674338952	0.117352	4.5776e-05	2.5652750697355808e-05	5.9695227058752085	2.5652421671253546e-05	5.969675840552965
0.840001	0.0006380759674338952	0.11493	-1.5259e-05	2.552303869735581e-05	5.846319147404712	2.5522712990195747e-05	5.846468363234548
1.27	0.0020630417674338953	0.239763	0.0132065	8.252167069735581e-05	12.196389260760427	8.251826597168456e-05	12.197395727178701
1.66	0.003183051767433895	0.360597	0.0244751	0.00012732207069735582	18.343036157632444	0.00012731396593052634	18.34537163097891
2.08	0.004029911767433896	0.451421	0.0334702	0.00016119647069735583	22.963118731754825	0.00016118347994228575	22.96682030545059
2.49	0.005554011767433895	0.618347	0.0484848	0.00022216047069735582	31.454397510138875	0.00022213579671429248	31.46138543389523
2.91	0.0067621017674338955	0.775788	0.0619659	0.00027048407069735583	39.46318836445494	0.00027044749647606034	39.47386252828645
3.31	0.007830381767433895	0.901297	0.0719986	0.0003132152706973558	45.84764559817649	0.00031316622903450797	45.86200578090336
3.71001	0.008960731767433896	1.03469	0.0827332	0.0003584292706973558	52.6331502534428	0.0003583650502714404	52.65201551510264
4.13001	0.010426881767433897	1.20954	0.0956268	0.00041707527069735585	61.52751119422165	0.0004169883189827286	61.55317279760832
4.57001	0.012171681767433896	1.45085	0.111855	0.00048686727069735585	73.80259405735774	0.00048674878928275033	73.83852612489683
4.98001	0.013508081767433896	1.62305	0.124435	0.0005403232706973558	82.56215341682083	0.0005401773486399014	82.60676366959082
5.40001	0.014742381767433897	1.78625	0.133911	0.0005896952706973559	90.86389608502276	0.0005895214687646973	90.91747809482123
5.79001	0.016482081767433893	2.01925	0.14872	0.0006592832706973557	102.71626153656108	0.0006590660389547232	102.7839806494207
6.21001	0.017605881767433895	2.19463	0.159431	0.0007042352706973558	111.63758279360309	0.0007039874133989006	111.71620191694174
6.61001	0.019123481767433895	2.42108	0.17128	0.0007649392706973558	123.15675943094578	0.0007646468537647964	123.25096687268635
7.01001	0.021152581767433894	2.69014	0.18573	0.0008461032706973558	136.84344375880372	0.0008457455271029043	136.95922744414153
7.42001	0.022253081767433895	2.87753	0.196068	0.0008901232706973558	146.3756959560731	0.0008897273459092365	146.50598836930808
7.84001	0.023754981767433896	3.09627	0.206909	0.0009501992706973558	157.50267629456874	0.0009497481171381695	157.65233522271672
8.25001	0.025658581767433894	3.40354	0.221672	0.0010263432706973557	173.13304681943646	0.001025816940542232	173.31074075697492
8.66001	0.026927881767433895	3.62387	0.232262	0.0010771152706973558	184.3409081067216	0.0010765355982562594	184.53946451385758
9.07001	0.028937581767433895	3.86582	0.243858	0.0011575032706973559	196.64854682345845	0.001156833880284509	196.8761681595845
9.49001	0.030889381767433895	4.22574	0.25972	0.0012355752706973558	214.9571449922038	0.001234812575752649	215.22274072481588
9.91001	0.032204281767433895	4.43173	0.269089	0.0012881712706973559	225.4355516847462	0.0012873422899224755	225.7259512858203
10.33	0.033910481767433893	4.71327	0.281097	0.0013564192706973558	239.75707515781957	0.0013555001651129194	240.08228627484968
10.75	0.036025581767433895	5.05589	0.295448	0.0014410232706973559	257.1856479089185	0.0014399859930386396	257.55625841244466
11.16	0.037684981767433894	5.33217	0.306839	0.0015073992706973558	271.2396029602104	0.0015062642848580586	271.64846933989685
11.57	0.03967478176743389	5.64773	0.31955	0.0015869912706973556	287.29167352625086	0.00158573333076802	287.74760290428105
11.98	0.041643181767433896	5.94873	0.331306	0.001665727270697356	302.60309842287336	0.001664341485706884	303.10715265611384
12.38	0.0433791817674339	6.24794	0.34288	0.001735167270697356	317.82346866645605	0.001733663607122619	318.37494554714556
12.78	0.045379281767433895	6.58569	0.355988	0.0018151712706973558	335.00431171906143	0.0018135258381866337	335.6124019212536
13.19	0.047349081767433895	6.8838	0.367905	0.0018939632706973558	350.16872658926786	0.001892171983659934	350.8319332959748
13.59	0.04934408176743389	7.21231	0.37999	0.0019737632706973555	366.87954450551183	0.0019718179592751804	367.603677875227
14	0.0517770817674339	7.58418	0.394577	0.002071083270697356	385.7960215032095	0.0020689415343733376	386.5950371892464
14.4	0.0530142817674339	7.80961	0.403084	0.002120571270697356	397.26331224887593	0.0021183260330043456	398.10573741573296
14.81	0.05584868176743389	8.26569	0.419434	0.0022339472706973556	420.4634274211402	0.0022314557204645043	421.4027205472557
15.22	0.0575758817674339	8.53024	0.42981	0.0023030352706973557	433.9206947181551	0.002300387349692732	434.92002938277653
15.63	0.059228481767433894	8.79374	0.439003	0.0023691392706973557	447.32455006785614	0.002366337284912366	448.38432422616887
16.03	0.061506481767433896	9.1492	0.452141	0.002460259270697356	465.406274631821	0.0024572377875975693	466.5512947336246
16.43	0.0634238817674339	9.48946	0.464569	0.0025369552706973556	482.71479767276696	0.002533742632074367	483.9394235229665
16.84	0.0659589817674339	9.87362	0.478058	0.002638359270697356	502.2564487966424	0.0026348849106084156	503.58158175459255
17.25	0.0678089817674339	10.1737	0.488495	0.002712359270697356	517.5210746537138	0.002708687462301261	518.9247777383321
17.66	0.06998198176743389	10.5421	0.501778	0.0027992792706973556	536.2610378826696	0.0027953685848477556	537.7621822896973
18.06	0.0720370817674339	10.8716	0.513901	0.002881483270697356	553.0222156349523	0.0028773397555158014	554.6157398976284
18.47	0.0744433817674339	11.218	0.526321	0.002977735270697356	570.6430713963808	0.0029733105985183758	572.342295397057
18.88	0.0765416817674339	11.5818	0.53891	0.0030616672706973557	589.149039427581	0.003056989912037883	590.9528177591592
19.28	0.0784133817674339	11.8752	0.548927	0.0031365352706973558	604.073863562694	0.0031316266054014007	605.9685625418648
19.68	0.0809922817674339	12.3015	0.563995	0.003239691270697356	625.7591141720966	0.003234454777631799	627.7863805118392
20.09	0.08267218176743389	12.5658	0.573463	0.0033068872706973557	639.2036643387986	0.003301431543328425	641.3174387997838
20.5	0.08505338176743389	12.9519	0.586418	0.0034021352706973557	658.8440003939013	0.003396361101128438	661.0854768055287
20.9	0.0874640817674339	13.3016	0.599571	0.0034985632706973557	676.6327222754591	0.0034924575349422993	678.999964665364
21.3	0.0890109817674339	13.5828	0.609482	0.003560439270697356	690.9369504513071	0.003554115911642949	693.3969895032698
21.71	0.0915597817674339	13.9656	0.623032	0.003662391270697356	710.4094203862807	0.0036557010456265515	713.0112176461246
22.12	0.09377898176743389	14.3231	0.635139	0.0037511592706973556	728.5949167335981	0.003744141217841016	731.3279923100863
22.52	0.09578708176743389	14.6252	0.646561	0.0038314832706973557	743.9622970035969	0.0038241618340196853	746.8127760985957
22.94	0.0986013817674339	15.0872	0.661583	0.003944055270697356	767.4635538216685	0.003936297875082985	770.490472496187
23.33	0.10008178176743389	15.3393	0.67128	0.004003271270697355	780.2875080291054	0.003995279501975861	783.4112105928824
23.74	0.1023503817674339	15.6937	0.682655	0.004094015270697356	798.3153119605439	0.0040856575933859995	801.583627038542
24.14	0.1047073817674339	16.0523	0.695313	0.004188295270697356	816.5567636812377	0.004179548775491503	819.9767445128198
24.55	0.10660038176743389	16.3513	0.706398	0.0042640152706973555	831.7664515353576	0.004254950117747497	835.3131163863582
24.96	0.1089833817674339	16.7353	0.719887	0.004359335270697356	851.2999636958328	0.004349860893374866	855.0110656535155
25.36	0.1106313817674339	17.01	0.731117	0.0044252552706973555	865.2735464835478	0.0044154926194782985	869.1026028057191
25.77	0.11291538176743389	17.3641	0.74482	0.004516615270697356	883.286089858611	0.004506445972985193	887.2755533004611
26.17	0.11471938176743389	17.6486	0.756432	0.004588775270697356	897.7581841545879	0.004578278939409689	901.8777947091027
26.58	0.1167933817674339	17.9743	0.769142	0.004671735270697356	914.326061526116	0.00466085658388312	918.5975508366653
26.98	0.11871938176743389	18.2701	0.781448	0.004748775270697355	929.3729701122319	0.004737535407089792	933.7863534899554
27.4	0.1208033817674339	18.5968	0.794472	0.004832135270697356	945.9917160050114	0.004820497978649272	950.5628759417067
27.79	0.1226253817674339	18.8907	0.80661	0.004905015270697356	960.9419744007499	0.004893024876022261	965.6554094594396
28.2	0.1240553817674339	19.1177	0.815964	0.004962215270697356	972.4891287247808	0.004949944058688994	977.3148291299261
28.61	0.1267063817674339	19.5139	0.831558	0.005068255270697356	992.643236844521	0.0050554548971090026	997.6742061615803
29.02	0.1282093817674339	19.7492	0.842072	0.005128375270697356	1004.612599894937	0.005115269941174459	1009.7646303088693
29.43	0.1303663817674339	20.1028	0.855286	0.0052146552706973555	1022.5997090093747	0.005201106038539019	1027.932213971774
29.83	0.1318343817674339	20.3451	0.866005	0.0052733752706973554	1034.9251517085495	0.00525951971633728	1040.382700410592
30.24	0.1343363817674339	20.7204	0.881271	0.005373455270697356	1054.016107734139	0.00535906977014347	1059.679816143643
30.64	0.1359583817674339	20.9539	0.892097	0.005438335270697357	1065.8939074463028	0.00542360092151977	1071.6905958779894
31.04	0.1383653817674339	21.2866	0.904884	0.0055346152706973566	1082.8178644665895	0.005519355566103941	1088.8108447546504
31.45	0.14026538176743392	21.5241	0.91539	0.005610615270697356	1094.8991382637585	0.005594934394407338	1101.0421960887745
31.87	0.1432753817674339	21.8531	0.929344	0.005731015270697356	1111.6348817554156	0.005714655478399728	1118.0056782381957
32.28	0.1468823817674339	22.0894	0.94162	0.005875295270697356	1123.655113327083	0.005858103030230655	1130.2569189003084
32.68	0.1512423817674339	22.2575	0.953239	0.006049695270697356	1132.2061117494159	0.0060314693348959315	1139.055613709121
33.09	0.1600223817674339	22.3336	0.967384	0.006400895270697356	1136.0772062166352	0.006380496541045296	1143.3491174330543
33.49	0.17007738176743392	22.2996	0.980072	0.006803095270697357	1134.347676494093	0.006780058639313242	1142.0647518073768
33.9	0.1801583817674339	22.2858	0.991966	0.007206335270697356	1133.645690900826	0.00718049371103944	1141.8151218276384
34.3	0.1898953817674339	22.269	1.00285	0.007595815270697356	1132.791099743805	0.00756711232244695	1141.395571677749
34.71	0.20143738176743392	22.24	1.01485	0.008057495270697356	1131.3159126275193	0.008025206981542427	1140.43148524318
35.13	0.2141553817674339	22.2147	1.02757	0.008566215270697355	1130.028939039863	0.008529733441418809	1139.709010193796
35.54	0.2269873817674339	22.2064	1.04057	0.009079495270697357	1129.6067303134776	0.00903852446294557	1139.8629892791068
35.9501	0.2381293817674339	22.2117	1.05266	0.009525175270697355	1129.8763334761093	0.009480096816111824	1140.638603586682
36.3501	0.2488423817674339	22.2164	1.06373	0.009953695270697355	1130.11541552599	0.00990448353555958	1141.3642399928533
36.7501	0.2613383817674339	22.2269	1.07684	0.010453535270697357	1130.649534999128	0.010399274885186254	1142.468819792039
37.1601	0.27398538176743387	22.2862	1.09102	0.010959415270697355	1133.6660383093265	0.010899796077974318	1146.0903552014447
37.5701	0.28246938176743386	22.2691	1.10065	0.011298775270697354	1132.7961865959303	0.011235420880754661	1145.5953961357807
37.9801	0.2917443817674339	22.329	1.11194	0.011669775270697355	1135.8432110188794	0.011602208593850773	1149.098246034217
38.3901	0.30372538176743386	22.3712	1.1256	0.012149015270697354	1137.9898626156817	0.012075808316511172	1151.8153188344984
38.8001	0.31537938176743385	22.381	1.13908	0.012615175270697354	1138.4883741239437	0.012536266882910155	1152.8506045071686
39.2001	0.3252313817674339	22.3952	1.15104	0.013009255270697356	1139.2107071257112	0.012925361721054896	1154.0309900218213
39.6101	0.33461438176743385	22.4111	1.16187	0.013384575270697354	1140.0195166136061	0.01329579317286361	1155.278193643785
40.0101	0.34379938176743385	22.4294	1.17216	0.013751975270697355	1140.9504105525036	0.013658274924696965	1156.6407323835138
40.4201	0.3537023817674339	22.4531	1.18442	0.014148095270697356	1142.1559945061579	0.014048945067464244	1158.3153263304291
40.8301	0.36376038176743386	22.4823	1.19675	0.014550415270697354	1143.641355326694	0.014445573746574306	1160.2818119674407
41.2301	0.3751703817674339	22.5114	1.20998	0.015006815270697355	1145.1216292951049	0.014895327023619231	1162.3062580484163
41.6501	0.3870733817674339	22.5251	1.22353	0.015482935270697355	1145.818528036247	0.015364297633886392	1163.559162137798
42.0701	0.3982813817674339	22.5367	1.23643	0.015931255270697355	1146.4086028827614	0.015805684731964253	1164.6723309798103
42.4801	0.4086133817674339	22.5474	1.24925	0.016344535270697357	1146.9528960601497	0.01621240119005578	1165.6993081236333
42.8801	0.4180993817674339	22.5617	1.26034	0.016723975270697355	1147.6803159140422	0.016585669481250204	1166.8740931360549
43.2901	0.4274313817674339	22.5782	1.27123	0.017097255270697356	1148.5196465146878	0.016952742062247943	1168.1561800945606
43.7001	0.4374193817674339	22.6012	1.28246	0.017496775270697356	1149.6896225034661	0.017345469062462975	1169.8054834594623
44.1001	0.4474803817674339	22.624	1.29472	0.017899215270697356	1150.8494247879944	0.017740910546198255	1171.448726386433
44.5101	0.45839838176743386	22.6497	1.30727	0.018335935270697355	1152.1567457841513	0.018169859046159167	1173.2826172965467
44.9101	0.4697463817674339	22.665	1.32066	0.018789855270697355	1152.9350341592951	0.018615506545807972	1174.5985165876648
45.3401	0.4809183817674339	22.6773	1.33389	0.019236735270697355	1153.5607169706852	0.019054048426699895	1175.751459101726
45.7601	0.49156538176743386	22.6903	1.34552	0.019662615270697355	1154.2220077469515	0.019471803237481208	1176.9170310222516
46.1701	0.5019143817674339	22.7065	1.35828	0.020076575270697353	1155.0460777912215	0.019877698273084672	1178.2354473131206
46.5801	0.5117923817674339	22.7218	1.36987	0.020471695270697355	1155.8243661663655	0.02026496674464451	1179.4860503769703
46.9901	0.5216903817674339	22.7396	1.38203	0.020867615270697356	1156.7298258446374	0.02065286894485181	1180.868018822504
47.3901	0.5325123817674339	22.7678	1.39451	0.021300495270697356	1158.1643181439224	0.0210768105432433	1182.8337917252375
47.8001	0.5432933817674339	22.7835	1.40678	0.021731735270697355	1158.9629539275668	0.02149896737460192	1184.1492300308662
48.2101	0.5541023817674339	22.7981	1.41965	0.022164095270697355	1159.705634337835	0.021922041779851405	1185.4094605032633
48.6101	0.5634743817674339	22.8057	1.43015	0.022538975270697356	1160.0922350993442	0.022288725832515382	1186.2395252979761
49.0201	0.5736463817674339	22.8247	1.44218	0.022945855270697355	1161.0587370031178	0.022686558169662408	1187.7002227431701
49.4201	0.5836813817674339	22.8454	1.45351	0.023347255270697354	1162.1117153930184	0.02307887733750843	1189.243834265367
49.8301	0.5948363817674339	22.8667	1.46713	0.02379345527069736	1163.1952148956698	0.0235148024351516	1190.8716482123791
50.2301	0.6053683817674339	22.8795	1.47917	0.024214735270697355	1163.8463319676855	0.023926207045628915	1192.0285627920553
50.6401	0.6154673817674339	22.8918	1.4917	0.024618695270697356	1164.4720147790756	0.02432053876553617	1193.1397964621765
51.0501	0.6258423817674339	22.9045	1.50388	0.025033695270697355	1165.1180449989665	0.02472548548487864	1194.2852550918612
51.4501	0.6354123817674339	22.9177	1.51553	0.025416495270697354	1165.7895094794828	0.025098866907371373	1195.4197930337969
51.8501	0.6448333817674339	22.9315	1.52632	0.025793335270697354	1166.4914950727498	0.02546629884790582	1196.5792012955783
52.2601	0.6548793817674339	22.9632	1.53877	0.026195175270697355	1168.104027196414	0.025857957965948936	1198.7027169232315
52.6701	0.6665403817674339	22.9813	1.55249	0.026661615270697357	1169.0247474310615	0.02631238811439	1200.1928354889926
53.0701	0.6770793817674339	22.9904	1.56556	0.027083175270697354	1169.487650974448	0.02672291624608584	1201.161090002705
53.4801	0.6872943817674338	23.0002	1.57686	0.027491775270697353	1169.98616248271	0.027120662753487977	1202.1511591315102
53.8801	0.6971823817674339	23.0118	1.58858	0.027887295270697353	1170.576237329224	0.02750552607193944	1203.2204424964862
54.2901	0.7073523817674339	23.0246	1.60085	0.028294095270697355	1171.22735440124	0.027901211012167814	1204.3661727503156
54.7001	0.7168393817674339	23.0379	1.61258	0.028673575270697357	1171.9039057338816	0.028270181326810796	1205.5065805849663
55.1001	0.7261543817674339	23.0514	1.62364	0.029046175270697354	1172.5906307707733	0.028632329771927666	1206.6499037529188
55.5101	0.7361863817674339	23.0713	1.63556	0.029447455270697354	1173.6029143436729	0.02902220710662453	1208.1625336693683
55.9301	0.7475423817674339	23.1024	1.64858	0.029901695270697356	1175.1849253545863	0.029463356201956288	1210.3249468792565
56.3401	0.7587493817674339	23.1159	1.66161	0.030349975270697355	1175.8716503914782	0.02989852634498683	1211.5593259023735
56.7501	0.7702883817674339	23.1234	1.6752	0.030811535270697354	1176.2531643008624	0.030346390333669614	1212.495330159988
57.1601	0.7803883817674339	23.1271	1.6873	0.031215535270697356	1176.4413778294918	0.030738237764715324	1213.164625153036
57.5701	0.7905073817674338	23.1373	1.69941	0.03162029527069735	1176.9602367462544	0.031130668416929044	1214.1760669540408
57.9901	0.8003633817674339	23.148	1.71066	0.03201453527069736	1177.5045299236428	0.031512751524813615	1215.2017902282892
58.4001	0.8097083817674339	23.1615	1.72184	0.03238833527069736	1178.1912549605345	0.03187489014554427	1216.3509083391998
58.8001	0.8191703817674338	23.1768	1.73303	0.03276681527069735	1178.9695433356783	0.03224142919626708	1217.6006205719368
59.2101	0.8295853817674339	23.2004	1.7459	0.033183415270697354	1180.1700404372075	0.03264473030148069	1219.332112979071
59.6101	0.8401873817674339	23.2186	1.75758	0.033607495270697355	1181.09584752398	0.0330551056362942	1220.7895206338824
60.0101	0.8511053817674339	23.2315	1.77048	0.034044215270697356	1181.7520514481212	0.03347753655564873	1221.9838726842092
60.4201	0.8619253817674338	23.2409	1.78355	0.03447701527069735	1182.2302155478828	0.03389599975527702	1222.989984742807
60.8301	0.8729533817674339	23.2474	1.79655	0.034918135270697356	1182.5608609360156	0.03432232723223642	1223.8536810440116
61.2301	0.8830123817674339	23.2557	1.80836	0.035320495270697354	1182.983069662401	0.034711036049790485	1224.766617579727
61.6401	0.8929453817674339	23.2637	1.82022	0.03571781527069735	1183.3900178324109	0.0350947276530333	1225.6581238825363
62.0401	0.9025123817674339	23.2736	1.83157	0.03610049527069736	1183.8936161927982	0.0354641422898331	1226.632762085175
62.4501	0.9127463817674338	23.2864	1.84409	0.036509855270697354	1184.544733264814	0.03585916106913816	1227.7922900379792
62.8601	0.9226583817674339	23.2981	1.85563	0.03690633527069735	1185.1398949634536	0.03624160238182897	1228.879065269654
63.2701	0.9330933817674338	23.3151	1.86853	0.03732373527069735	1186.0046598247247	0.036644064974153887	1230.2707837778364
63.6801	0.9437723817674338	23.3284	1.88115	0.03775089527069735	1186.6812111573659	0.03705577065427404	1231.4794892794719
64.0901	0.9549513817674339	23.3462	1.89448	0.038198055270697355	1187.586670835638	0.03748657123518337	1232.950172126961
64.4901	0.9661293817674339	23.3537	1.90779	0.03864517527069736	1187.9681847450224	0.03791714779515928	1233.877423460506
64.9001	0.9768933817674339	23.3575	1.91998	0.039075735270697354	1188.161485125777	0.038331601925142574	1234.5897687773906
65.3001	0.9874493817674339	23.3598	1.93263	0.03949797527069736	1188.2784827246549	0.03873788052249675	1235.213076850015
65.7101	0.9975143817674339	23.3664	1.9446	0.039900575270697354	1188.614214964913	0.03912510788199044	1236.0406059169413
66.1101	1.007274381767434	23.3738	1.95583	0.04029097527069735	1188.990642022172	0.039500457935192836	1236.8962345769778
66.5201	1.017004381767434	23.3824	1.96723	0.04068017527069736	1189.4281113049328	0.039874514062243745	1237.814255344712
66.9201	1.026714381767434	23.3926	1.97935	0.04106857527069736	1189.9469702216954	0.04024766188270553	1238.8163969363834
67.3501	1.037604381767434	23.4039	1.99179	0.041504175270697365	1190.5217845118345	0.0406659906121476	1239.933409319797
67.7601	1.047934381767434	23.4171	2.00389	0.04191737527069736	1191.1932489923508	0.04106264582127733	1241.1249434302845
68.1601	1.059004381767434	23.4388	2.01724	0.04236017527069736	1192.2970959035026	0.04148754125475436	1242.8030098607185
68.5701	1.070934381767434	23.4425	2.0313	0.04283737527069736	1192.4853094321322	0.041945243699500506	1243.5682501370702
68.9701	1.081994381767434	23.4453	2.04363	0.04327977527069736	1192.6277412916356	0.04236938095997704	1244.244401916337
69.3701	1.092634381767434	23.448	2.05588	0.04370537527069736	1192.765086299014	0.042777242037272706	1244.895332005498
69.7801	1.102774381767434	23.4514	2.06808	0.044110975270697364	1192.938039271268	0.04316578196320776	1245.5596996210372
70.1801	1.112934381767434	23.4543	2.07969	0.04451737527069736	1193.0855579828967	0.0435549368887582	1246.1985954976706
70.6101	1.123864381767434	23.4591	2.09207	0.044954575270697364	1193.3297268849026	0.04397341583150469	1246.9753579149108
71.0201	1.133724381767434	23.4657	2.10336	0.04534897527069736	1193.6654591251609	0.044350777296137824	1247.7969645125133
71.4201	1.143724381767434	23.4741	2.11517	0.045748975270697365	1194.0927547036713	0.044733351440763985	1248.7212746095286
71.8301	1.154244381767434	23.4866	2.12745	0.04616977527069736	1194.7286112193117	0.045135661526245686	1249.8889627087797
72.2401	1.164964381767434	23.4942	2.14005	0.04659857527069736	1195.1152119808212	0.04554545366199724	1250.805878143465
72.6501	1.176144381767434	23.5012	2.15259	0.04704577527069736	1195.4712916295798	0.045972651344053816	1251.7131653581555
73.0701	1.187934381767434	23.5125	2.16609	0.047517375270697354	1196.0461059197187	0.04642296004718104	1252.8790775757623
73.4801	1.199304381767434	23.5157	2.17863	0.04797217527069736	1196.208885187723	0.046857035232164564	1253.5936274883138
73.8901	1.2109743817674339	23.517	2.19202	0.048438975270697356	1196.2750142653495	0.04730236773060507	1254.2213500983019
74.2901	1.221764381767434	23.5179	2.20409	0.04887057527069736	1196.3207959344757	0.04771394265141836	1254.7856814400918
74.6901	1.2322943817674339	23.5156	2.21563	0.049291775270697356	1196.2037983355976	0.0481154368499483	1255.1668071411104
75.1101	1.243044381767434	23.5191	2.22841	0.049721775270697356	1196.3818381599772	0.04852515312443759	1255.8680670549113
75.5501	1.254444381767434	23.5245	2.24054	0.05017777527069736	1196.6565281747337	0.04895945961976503	1256.7020905216984
75.9601	1.264694381767434	23.5281	2.25243	0.05058777527069736	1196.839654851238	0.04934979351980448	1257.3851103459115
76.3701	1.275584381767434	23.5338	2.26441	0.051023375270697356	1197.12960542237	0.04976433262816976	1258.2111985274976
76.7701	1.286014381767434	23.5389	2.27588	0.05144057527069736	1197.3890348807515	0.050161200317975774	1258.9834156578427
77.1801	1.296824381767434	23.5478	2.28825	0.05187297527069736	1197.8417647198874	0.05057236108473853	1259.9773809594108
77.5801	1.307724381767434	23.5517	2.30051	0.05230897527069736	1198.0401519527672	0.05098677392211461	1260.708404634567
78.0001	1.319304381767434	23.5536	2.31328	0.05277217527069736	1198.1368021431447	0.05142685197550127	1261.3650874641155
78.4101	1.330904381767434	23.5519	2.32718	0.05323617527069736	1198.0503256570175	0.05186749600940412	1261.8299427768106
78.8301	1.342224381767434	23.557	2.33894	0.05368897527069736	1198.309755115399	0.052297316695587154	1262.645777924425
79.2301	1.353594381767434	23.5604	2.35194	0.054143775270697365	1198.4827080876532	0.05272884999151982	1263.373086500168
79.6601	1.365324381767434	23.5607	2.36522	0.05461297527069736	1198.4979686440286	0.05317385153816318	1263.951508567566
80.0601	1.376244381767434	23.5611	2.3766	0.055049775270697356	1198.518316052529	0.05358794616644391	1264.4964800090352
80.4701	1.387824381767434	23.5607	2.38974	0.05551297527069736	1198.4979686440286	0.054026881239393545	1265.0301567393456
80.8801	1.398694381767434	23.5605	2.40137	0.05594777527069736	1198.4877949397783	0.054438728825037204	1265.5405207557426
81.2801	1.409424381767434	23.5609	2.41261	0.056376975270697356	1198.5081423482789	0.05484510573824289	1266.076406251177
81.6901	1.420914381767434	23.5614	2.42504	0.056836575270697354	1198.5335766089042	0.05528008308081097	1266.6541204502944
82.0901	1.431854381767434	23.5611	2.43723	0.057274175270697364	1198.518316052529	0.055694063290823624	1267.1624641512624
82.5001	1.442664381767434	23.5615	2.44914	0.05770657527069736	1198.5386634610295	0.05610295590690426	1267.7022250588843
82.9101	1.454204381767434	23.5653	2.46114	0.058168175270697356	1198.7319638417841	nan	nan
83.3501	1.466474381767434	23.565	2.47433	0.058658975270697356	1198.7167032854088	nan	nan
83.7601	1.478164381767434	23.564	2.48752	0.059126575270697354	1198.6658347641576	nan	nan
84.1601	1.488714381767434	23.5623	2.49889	0.05954857527069736	1198.5793582780304	nan	nan
84.5801	1.500484381767434	23.5625	2.51147	0.06001937527069736	1198.5895319822807	nan	nan
84.9901	1.512364381767434	23.561	2.52335	0.060494575270697355	1198.5132292004039	nan	nan
85.4101	1.524194381767434	23.5605	2.53624	0.060967775270697355	1198.4877949397783	nan	nan
85.8301	1.536104381767434	23.5572	2.54923	0.061444175270697364	1198.3199288196492	nan	nan
86.2401	1.547424381767434	23.5535	2.56149	0.06189697527069736	1198.1317152910194	nan	nan
86.6501	1.559124381767434	23.5515	2.57377	0.06236497527069736	1198.029978248517	nan	nan
87.0501	1.570524381767434	23.5513	2.58535	0.06282097527069735	1198.019804544267	nan	nan
87.4501	1.5817043817674339	23.548	2.598	0.06326817527069735	1197.8519384241376	nan	nan
87.8601	1.5936343817674339	23.5436	2.61006	0.06374537527069736	1197.6281169306324	nan	nan
88.2701	1.605064381767434	23.5397	2.62254	0.06420257527069735	1197.4297296977525	nan	nan
88.6801	1.616744381767434	23.5325	2.63476	0.06466977527069737	1197.0634763447435	nan	nan
89.0801	1.627864381767434	23.5312	2.64614	0.06511457527069736	1196.9973472671168	nan	nan
89.4801	1.638704381767434	23.5284	2.65757	0.06554817527069737	1196.8549154076136	nan	nan
89.8901	1.650764381767434	23.5232	2.67093	0.06603057527069736	1196.5903990971071	nan	nan
90.3001	1.662334381767434	23.5199	2.68269	0.06649337527069736	1196.4225329769781	nan	nan
90.7001	1.674804381767434	23.5137	2.69561	0.06699217527069737	1196.1071481452202	nan	nan
91.1101	1.686694381767434	23.5061	2.70789	0.06746777527069736	1195.7205473837107	nan	nan
91.5101	1.698664381767434	23.4986	2.71992	0.06794657527069736	1195.3390334743265	nan	nan
91.9201	1.711134381767434	23.489	2.73313	0.06844537527069736	1194.8506956703147	nan	nan
92.3201	1.723204381767434	23.4791	2.74522	0.06892817527069736	1194.3470973099274	nan	nan
92.7301	1.734884381767434	23.4671	2.75731	0.06939537527069736	1193.7366750549124	nan	nan
93.1401	1.747304381767434	23.4568	2.77021	0.06989217527069737	1193.212729286025	nan	nan
93.5501	1.759024381767434	23.4446	2.78159	0.07036097527069736	1192.59213332676	nan	nan
93.9601	1.770724381767434	23.4202	2.79346	0.07082897527069737	1191.3509414082296	nan	nan
94.3801	1.7819143817674339	23.41	2.80527	0.07127657527069736	1190.832082491467	nan	nan
94.7901	1.793204381767434	23.4051	2.8164	0.07172817527069736	1190.582826737336	nan	nan
95.1901	1.805054381767434	23.3988	2.82732	0.07220217527069736	1190.2623550534533	nan	nan
95.6101	1.818024381767434	23.3882	2.84084	0.07272097527069736	1189.72314872819	nan	nan
96.0201	1.831604381767434	23.3692	2.85509	0.07326417527069735	1188.7566468244165	nan	nan
96.4201	1.844624381767434	23.3488	2.86781	0.07378497527069736	1187.7189289908913	nan	nan
96.8301	1.857994381767434	23.3247	2.88062	0.07431977527069736	1186.4929976287365	nan	nan
97.2401	1.871474381767434	23.2959	2.89387	0.07485897527069736	1185.0279842167006	nan	nan
97.6401	1.881814381767434	23.2035	2.90305	0.07527257527069736	1180.3277328530864	nan	nan
98.0501	1.889864381767434	23.2072	2.91128	0.07559457527069736	1180.515946381716	nan	nan
98.4501	1.903764381767434	23.2869	2.92702	0.07615057527069735	1184.5701675254395	nan	nan
98.8601	1.921634381767434	23.2173	2.94393	0.07686537527069735	1181.0297184463536	nan	nan
99.2601	1.932434381767434	23.1263	2.95365	0.07729737527069737	1176.4006830124908	nan	nan
99.6701	1.942574381767434	23.1161	2.96364	0.07770297527069736	1175.8818240957282	nan	nan
100.07	1.953294381767434	23.1155	2.97453	0.07813177527069735	1175.8513029829776	nan	nan
100.48	1.965884381767434	23.1081	2.98784	0.07863537527069736	1175.4748759257184	nan	nan
100.9	1.980454381767434	23.0844	3.00147	0.07921817527069736	1174.269291972064	nan	nan
101.31	1.995064381767434	23.0476	3.0156	0.07980257527069737	1172.3973303900184	nan	nan
101.72	2.010064381767434	22.9953	3.0304	0.08040257527069736	1169.7369067285788	nan	nan
102.12	2.021744381767434	22.9099	3.04044	0.08086977527069736	1165.3927350137233	nan	nan
102.52	2.030664381767434	22.8834	3.04915	0.08122657527069736	1164.0447192005654	nan	nan
102.93	2.040844381767434	22.9104	3.0599	0.08163377527069736	1165.4181692743487	nan	nan
103.35	2.056054381767434	22.9063	3.07584	0.08224217527069737	1165.209608337219	nan	nan
103.77	2.072144381767434	22.8503	3.09166	0.08288577527069735	1162.3609711471493	nan	nan
104.18	2.086564381767434	22.7673	3.10413	0.08346257527069736	1158.1388838832966	nan	nan
104.58	2.096954381767434	22.7252	3.1142	0.08387817527069735	1155.9973191386196	nan	nan
105	2.108074381767434	22.7116	3.12498	0.08432297527069736	1155.305507249603	nan	nan
105.41	2.119544381767434	22.6982	3.13659	0.08478177527069736	1154.6238690648363	nan	nan
105.83	2.132744381767434	22.6721	3.14993	0.08530977527069736	1153.2962006601788	nan	nan
106.24	2.146754381767434	22.6365	3.16338	0.08587017527069736	1151.4852813036348	nan	nan
106.64	2.160804381767434	22.5976	3.17683	0.08643217527069735	1149.5064958269616	nan	nan
107.05	2.174964381767434	22.5535	3.19005	0.08699857527069735	1147.263194039782	nan	nan
107.45	2.187674381767434	22.4607	3.20147	0.08750697527069735	1142.5425952676674	nan	nan
107.86	2.196754381767434	22.417	3.21015	0.08787017527069736	1140.3196408889883	nan	nan
108.27	2.206114381767434	22.435	3.22013	0.08824457527069736	1141.2352742715104	nan	nan
108.69	2.222884381767434	22.4639	3.23804	0.08891537527069737	1142.7053745356711	nan	nan
109.1	2.240624381767434	22.3412	3.25352	0.08962497527069736	1136.4638069781445	nan	nan
109.51	2.250454381767434	22.2535	3.26166	0.09001817527069736	1132.002637664411	nan	nan
109.93	2.259874381767434	22.2545	3.27094	0.09039497527069736	1132.0535061856622	nan	nan
110.34	2.272434381767434	22.291	3.285	0.09089737527069737	1133.9102072113324	nan	nan
110.75	2.288164381767434	22.2449	3.29974	0.09152657527069737	1131.5651683816504	nan	nan
111.15	2.303764381767434	22.1746	3.31459	0.09215057527069735	1127.9891113376884	nan	nan
111.56	2.316114381767434	22.079	3.32497	0.09264457527069736	1123.12608070607	nan	nan
111.96	2.326004381767434	22.0566	3.33463	0.09304017527069736	1121.9866258300422	nan	nan
112.37	2.336354381767434	22.0499	3.34499	0.09345417527069737	1121.645806737659	nan	nan
112.77	2.348494381767434	22.0445	3.35771	0.09393977527069737	1121.3711167229023	nan	nan
113.2	2.364574381767434	22.0058	3.3735	0.09458297527069735	1119.4025049504794	nan	nan
113.6	2.379784381767434	21.9482	3.38776	0.09519137527069736	1116.4724781264083	nan	nan
114.01	2.393734381767434	21.8669	3.40012	0.09574937527069735	1112.3368673486827	nan	nan
114.42	2.405034381767434	21.8169	3.41125	0.09620137527069735	1109.7934412861207	nan	nan
114.83	2.415584381767434	21.8012	3.4216	0.09662337527069736	1108.9948055024763	nan	nan
115.24	2.427364381767434	21.7799	3.43333	0.09709457527069736	1107.911305999825	nan	nan
115.64	2.440004381767434	21.7508	3.44587	0.09760017527069736	1106.4310320314141	nan	nan
116.06	2.453764381767434	21.7119	3.45922	0.09815057527069737	1104.452246554741	nan	nan
116.47	2.467924381767434	21.6698	3.47247	0.09871697527069737	1102.3106818100637	nan	nan
116.88	2.482944381767434	21.6194	3.48734	0.09931777527069735	1099.7469083390013	nan	nan
117.28	2.495104381767434	21.5161	3.49819	0.09980417527069736	1094.4921900937486	nan	nan
117.69	2.503634381767434	21.4806	3.50577	0.10014537527069736	1092.6863575893294	nan	nan
118.09	2.513774381767434	21.5233	3.51695	0.10055097527069735	1094.8584434467573	nan	nan
118.5	2.530264381767434	21.5096	3.53308	0.10121057527069736	1094.1615447056154	nan	nan
118.91	2.547434381767434	21.4297	3.54959	0.10189737527069737	1090.0971498576416	nan	nan
119.31	2.559024381767434	21.291	3.55818	0.10236097527069736	1083.041685960095	nan	nan
119.72	2.567794381767434	21.2822	3.56734	0.10271177527069736	1082.594042973084	nan	nan
120.12	2.579514381767434	21.339	3.58002	0.10318057527069736	1085.4833749801544	nan	nan
120.53	2.596754381767434	21.2835	3.59706	0.10387017527069736	1082.6601720507108	nan	nan
120.94	2.611654381767434	21.1458	3.60929	0.10446617527069735	1075.6555766744154	nan	nan
121.34	2.621234381767434	21.1103	3.618	0.10484937527069736	1073.8497441699963	nan	nan
121.75	2.6311043817674338	21.1078	3.62801	0.10524417527069735	1073.7225728668682	nan	nan
122.15	2.643724381767434	21.1091	3.64055	0.10574897527069735	1073.788701944495	nan	nan
122.56	2.659144381767434	21.0561	3.65453	0.10636577527069736	1071.0926703181794	nan	nan
122.99	2.675124381767434	20.9964	3.66994	0.10700497527069736	1068.0558195994804	nan	nan
123.4	2.689134381767434	20.9146	3.68244	0.10756537527069736	1063.8947745611292	nan	nan
123.8	2.699554381767434	20.855	3.69172	0.10798217527069737	1060.8630106945554	nan	nan
124.23	2.710964381767434	20.8424	3.7027	0.10843857527069735	1060.22206732679	nan	nan
124.63	2.7220743817674338	20.8254	3.71409	0.10888297527069735	1059.3573024655188	nan	nan
125.04	2.736074381767434	20.7866	3.72726	0.10944297527069737	1057.3836038409709	nan	nan
125.44	2.750144381767434	20.7397	3.74054	0.11000577527069735	1054.9978701942878	nan	nan
125.85	2.765504381767434	20.6829	3.75457	0.11062017527069737	1052.1085381872176	nan	nan
126.25	2.780014381767434	20.6152	3.76742	0.11120057527069736	1048.6647392985087	nan	nan
126.66	2.789114381767434	20.5096	3.7748	0.11156457527069737	1043.293023454378	nan	nan
127.07	2.798164381767434	20.5239	3.78424	0.11192657527069735	1044.0204433082708	nan	nan
127.47	2.810964381767434	20.5555	3.79768	0.11243857527069735	1045.62788857981	nan	nan
127.88	2.828714381767434	20.4789	3.81462	0.11314857527069735	1041.731359851965	nan	nan
128.28	2.844744381767434	20.3763	3.8278	0.11378977527069736	1036.5122495715882	nan	nan
128.69	2.853804381767434	20.2787	3.8354	0.11415217527069736	1031.5474818974674	nan	nan
129.1	2.862914381767434	20.2963	3.84441	0.11451657527069736	1032.4427678714892	nan	nan
129.5	2.876024381767434	20.313	3.8584	0.11504097527069736	1033.2922721763848	nan	nan
129.9	2.892314381767434	20.2473	3.87295	0.11569257527069736	1029.9502103301784	nan	nan
130.31	2.909104381767434	20.1553	3.88829	0.11636417527069735	1025.2703063750646	nan	nan
130.71	2.920024381767434	20.0488	3.89704	0.11680097527069735	1019.8528088618078	nan	nan
131.13	2.928984381767434	20.0291	3.90606	0.11715937527069736	1018.8506989931584	nan	nan
131.56	2.939854381767434	20.0479	3.91685	0.11759417527069736	1019.8070271926816	nan	nan
131.97	2.955964381767434	20.0231	3.93272	0.11823857527069735	1018.545487865651	nan	nan
132.37	2.973244381767434	19.9404	3.94866	0.11892977527069735	1014.3386611581739	nan	nan
132.78	2.987014381767434	19.8071	3.95982	0.11948057527069736	1007.5578872753838	nan	nan
133.19	2.995934381767434	19.7586	3.96753	0.11983737527069736	1005.0907639946989	nan	nan
133.6	3.005414381767434	19.7849	3.97759	0.12021657527069736	1006.4286061036064	nan	nan
134	3.020404381767434	19.7739	3.99253	0.12081617527069737	1005.8690523698428	nan	nan
134.43	3.039154381767434	19.6829	4.00962	0.12156617527069737	1001.2400169359802	nan	nan
134.84	3.052544381767434	19.5508	4.02055	0.12210177527069735	994.5202852786916	nan	nan
135.24	3.060664381767434	19.5031	4.02755	0.12242657527069736	992.0938568150076	nan	nan
135.64	3.070344381767434	19.5519	4.03854	0.12281377527069737	994.5762406520681	nan	nan
136.06	3.088094381767434	19.5158	4.05537	0.12352377527069736	992.7398870348983	nan	nan
136.47	3.105794381767434	19.3807	4.07096	0.12423177527069736	985.8675498138563	nan	nan
136.89	3.116374381767434	19.2885	4.08037	0.12465497527069737	981.1774721544921	nan	nan
137.3	3.125454381767434	19.2766	4.08881	0.12501817527069736	980.5721367516023	nan	nan
137.7	3.136254381767434	19.2809	4.09963	0.12545017527069738	980.7908713929826	nan	nan
138.11	3.152374381767434	19.2463	4.11508	0.12609497527069735	979.03082055769	nan	nan
138.51	3.169854381767434	19.158	4.13112	0.12679417527069736	974.5391301312056	nan	nan
138.92	3.183334381767434	19.0171	4.14178	0.12733337527069735	967.3717554869062	nan	nan
139.32	3.191834381767434	18.9759	4.14933	0.12767337527069736	965.2759724113552	nan	nan
139.73	3.202024381767434	18.9966	4.16017	0.12808097527069737	966.328950801256	nan	nan
140.14	3.216754381767434	18.9875	4.17572	0.12867017527069735	965.8660472578697	nan	nan
140.54	3.235674381767434	18.8844	4.19211	0.12942697527069735	960.621502716867	nan	nan
140.95	3.248294381767434	18.7117	4.20159	0.12993177527069735	951.8365090967784	nan	nan
141.35	3.255954381767434	18.6951	4.20824	0.13023817527069736	950.9920916440078	nan	nan
141.78	3.2689843817674338	18.7576	4.22295	0.13075937527069736	954.1713742222101	nan	nan
142.18	3.287224381767434	18.6646	4.23991	0.13148897527069736	949.440601745845	nan	nan
142.59	3.301714381767434	18.4822	4.25089	0.13206857527069737	940.1621834696193	nan	nan
142.99	3.308564381767434	18.4426	4.25658	0.13234257527069737	938.1477900280704	nan	nan
143.41	3.322324381767434	18.5432	4.27274	0.13289297527069738	943.2651632659448	nan	nan
143.82	3.342294381767434	18.3987	4.28972	0.13369177527069737	935.9146619451411	nan	nan
144.22	3.352254381767434	18.2451	4.29674	0.13409017527069736	928.1012570809512	nan	nan
144.63	3.360814381767434	18.259	4.30565	0.13443257527069735	928.8083295263432	nan	nan
145.03	3.375824381767434	18.2805	4.32151	0.13503297527069735	929.9020027332449	nan	nan
145.44	3.394094381767434	18.1706	4.33746	0.13576377527069736	924.3115522477337	nan	nan
145.85	3.407794381767434	18.0123	4.34766	0.13631177527069738	916.259065333663	nan	nan
146.25	3.415204381767434	17.9724	4.35449	0.13660817527069735	914.2294113357386	nan	nan
146.67	3.426644381767434	18.0344	4.36707	0.13706577527069735	917.3832596533153	nan	nan
147.08	3.444054381767434	17.9512	4.38284	0.13776217527069737	913.1509986852125	nan	nan
147.49	3.462144381767434	17.831	4.39797	0.13848577527069736	907.0366024308137	nan	nan
147.89	3.4720743817674338	17.7011	4.40583	0.13888297527069735	900.4287815202779	nan	nan
148.29	3.480424381767434	17.6984	4.41413	0.13921697527069735	900.2914365128995	nan	nan
148.7	3.493364381767434	17.7174	4.42707	0.13973457527069735	901.2579384166731	nan	nan
149.11	3.512004381767434	17.6171	4.44419	0.14048017527069734	896.1558257351741	nan	nan
149.52	3.528934381767434	17.4875	4.45837	0.14115737527069736	889.5632653810136	nan	nan
149.92	3.5385743817674338	17.3817	4.46606	0.14154297527069734	884.1813758326325	nan	nan
150.32	3.547274381767434	17.3731	4.47456	0.14189097527069736	883.7439065498721	nan	nan
150.73	3.560024381767434	17.3808	4.48748	0.14240097527069737	884.1355941635065	nan	nan
151.14	3.577924381767434	17.2883	4.50352	0.14311697527069736	879.4302559477671	nan	nan
151.54	3.595574381767434	17.1575	4.51842	0.14382297527069737	872.7766533681053	nan	nan
151.94	3.604694381767434	17.0138	4.52399	0.14418777527069737	865.4668468643024	nan	nan
152.35	3.612804381767434	17.0582	4.53398	0.14451217527069735	867.7254092078574	nan	nan
152.76	3.629174381767434	17.0363	4.54993	0.14516697527069736	866.6113885924552	nan	nan
153.16	3.647904381767434	16.9096	4.5659	0.14591617527069736	860.1663469499236	nan	nan
153.57	3.660834381767434	16.76	4.57604	0.14643337527069736	852.5564161707384	nan	nan
153.98	3.670184381767434	16.7324	4.58431	0.14680737527069737	851.1524449842042	nan	nan
154.4	3.681534381767434	16.7101	4.59512	0.14726137527069738	850.0180769603018	nan	nan
154.8	3.695024381767434	16.656	4.60802	0.14780097527069735	847.2660899606097	nan	nan
155.22	3.711914381767434	16.5664	4.62271	0.14847657527069735	842.7082704564989	nan	nan
155.63	3.730254381767434	16.4599	4.63883	0.14921017527069735	837.2907729432421	nan	nan
156.03	3.741954381767434	16.2473	4.64648	0.14967817527069735	826.476125325229	nan	nan
156.44	3.748904381767434	16.3127	4.65463	0.14995617527069738	829.8029266150598	nan	nan
156.64	3.757264381767434	16.3491	4.66341	0.15029057527069736	831.654540788605	nan	nan