File: original_data/46NT89.csv
Specimen name:	AWA_1_10_Rz
Specimen ID:	46NT89
Material:	42CrMoS4
Specimen type:	Round Tensile Specimen
Gauge diameter:	4.99	mm
Gauge length:	25	mm
Parallel length:	30	mm
Original cross-section:	19.556492808412802	mm²
Cross-section after fracture:	8.584116041002634	mm²
Yield stress at 0.2% plastic strain:	1127.6752760079194	MPa
Yield stress at 1% plastic strain:	1140.536590244724	MPa
Ultimate tensile strength:	1195.4290694670512	MPa
Uniform elongation:	5.416173582086973	%
Elongation after fracture:	14.60621321857002	%
Reduction of area:	56.10605579897269	%
Slope of linear-elastic region:	200874.12774578255	MPa
Crosshead seperation speed:	0.02993522265461398	mm/s
Strain rate:	0.0009978407551537994	s-1
Test temperature:	RT	Cel
Machine type:	INSTRON 8852TT
Standard:	DIN EN ISO 6892-1
Date:	2022-08-18 00:00:00
Heat treatment batch:	Batch 1
Time	Displacement	Force	Machine Displacement	Engineering Strain	Engineering Stress	True Strain	True Stress
s	mm	kN	mm		MPa		MPa
0	0.0008273832350324939	0.135918	0	3.3095329401299756e-05	6.950019174272949	3.309478176288024e-05	6.950249187446866
0.420001	0.0012130632350324938	0.136461	0.000175476	4.852252940129975e-05	6.977784888980569	4.85213522215013e-05	6.978123468753001
0.840001	0.000839933535032494	0.147878	0.00175476	3.359734140129976e-05	7.561580772621251	3.3596777023369877e-05	7.561834821632003
1.25	0.001230380235032494	0.298941	0.0130882	4.921520940129976e-05	15.286023057846126	4.921399837269211e-05	15.286775362671833
1.66	0.001609834235032494	0.466083	0.0257149	6.439336940129976e-05	23.832647528676546	6.439129623732555e-05	23.83418219315267
2.08	0.002160843235032494	0.655016	0.0385132	8.643372940129975e-05	33.49353109562803	8.642999422175367e-05	33.49642606643144
2.49	0.002964273235032494	0.879349	0.0506973	0.00011857092940129975	44.96455517942983	0.00011856390042434021	44.96988666852757
2.89	0.004344973235032494	1.13016	0.0631065	0.00017379892940129975	57.78950300914019	0.0001737838281170498	57.79954676289381
3.29	0.005664003235032493	1.39409	0.0749969	0.00022656012940129973	71.28527664225618	0.000226534468530995	71.30142704375666
3.70001	0.007383783235032494	1.66938	0.0870171	0.00029535132940129976	85.36193152597725	0.000295307721783561	85.38714328593372
4.42001	0.010677123235032494	2.21908	0.108425	0.00042708492940129973	113.47024345006264	0.0004269937545914516	113.51870488097565
4.73001	0.012182183235032494	2.46618	0.117664	0.0004872873294012998	126.10543332898115	0.0004871686434851196	126.16688290881102
5.14001	0.014373783235032495	2.80511	0.1297	0.0005749513294012998	143.43625043000037	0.0005747861082121344	143.51871929286943
5.54001	0.016429683235032494	3.12233	0.141804	0.0006571873294012998	159.65695028184388	0.000656971476373675	159.76187480661994
5.95001	0.018874383235032495	3.50094	0.154434	0.0007549753294012998	179.01676104694843	0.0007546904788884405	179.15191428508822
6.37001	0.021201683235032496	3.86945	0.166451	0.0008480673294012998	197.86011929170868	0.0008477079234896688	198.02791799467144
6.77001	0.023766483235032495	4.25196	0.178963	0.0009506593294012998	217.41935231714422	0.0009502077390041027	217.6260440528169
7.18001	0.025936683235032496	4.61296	0.190075	0.0010374673294012999	235.87869487598508	0.0010369295321041758	236.12341131562073
7.60001	0.028603683235032495	5.03035	0.203609	0.0011441473294012997	257.22147878356014	0.0011434932916751662	257.515778051575
8.00001	0.031181383235032493	5.42337	0.215149	0.0012472553294012997	277.31812923363117	0.0012464781526311606	277.66401574825744
8.40001	0.03360498323503249	5.81902	0.227268	0.0013441993294012996	297.5492618746434	0.0013432967022659551	297.9492273929191
8.80001	0.036086683235032495	6.20165	0.238979	0.0014434673294012998	317.1146309696275	0.0014424265318868227	317.5723755791073
9.21001	0.038808083235032494	6.6306	0.251965	0.0015523233294012998	339.0485229103887	0.001551119720973713	339.5748358423016
9.64001	0.0414253832350325	7.04826	0.264664	0.0016570153294012998	360.40511297444823	0.00165564399417372	361.0023097714415
10.06	0.04404528323503249	7.46317	0.276993	0.0017618113294012997	381.6210847780179	0.0017602611602910733	382.29342912871823
10.48	0.0468412832350325	7.9023	0.289383	0.0018736513294013	404.0755199521559	0.0018718982342004334	404.83261658729276
10.88	0.0493148832350325	8.2911	0.300671	0.0019725953294013	423.9563852897662	0.0019706523179982985	424.7926796752586
11.28	0.0520688832350325	8.7286	0.314724	0.0020827553294013	446.32747218586843	0.0020805894013976463	447.2570631072218
11.7	0.0547806832350325	9.15478	0.326897	0.0021912273294013	468.11972318788173	0.002188830092086033	469.1454799187628
12.11	0.057303483235032496	9.56791	0.338406	0.0022921393294013	489.2446766264798	0.0022895163853860474	490.3660935914756
12.52	0.0600524832350325	9.98533	0.350903	0.0024020993294013	510.58899455144206	0.0023992189006024523	511.8154800328538
12.93	0.06244988323503249	10.3884	0.363438	0.0024979953294012995	531.1995408262122	0.0024948805251677184	532.5264747981762
13.34	0.0650416832350325	10.7794	0.374897	0.0026016673294013	551.1929007722143	0.0025982888514700293	552.6269213343513
13.76	0.0678780832350325	11.2112	0.387486	0.0027151233294013	573.2725243647559	0.0027114440403654422	574.8290299697635
14.15	0.0704059832350325	11.6225	0.400631	0.0028162393294013	594.3039027427371	0.0028122811571199605	595.977604767258
14.56	0.0730120832350325	12.0285	0.412064	0.0029204833294013	615.0642713823199	0.0029162270029691	616.8605563334023
14.96	0.0755098832350325	12.432	0.424484	0.0030203953294012996	635.6968052396393	0.0030158430994808375	637.6168609011004
15.37	0.0781021832350325	12.8301	0.436886	0.0031240873294013	656.0532159672697	0.0031192175084417207	658.102783506686
15.78	0.0805745832350325	13.2164	0.44854	0.0032229833294013	675.8062465226166	0.003217800651434548	677.9843587890642
16.18	0.08312158323503249	13.6151	0.460152	0.0033248633294012996	696.1933375979902	0.003319348192657951	698.5080852963433
16.59	0.08568658323503249	14.0339	0.472507	0.0034274633294012996	717.6082203227618	0.00342160296393825	720.0677961827951
17.01	0.0883883832350325	14.4695	0.485477	0.0035355353294013	739.8821527843437	0.003529300016825262	742.4980322751062
17.42	0.0907668832350325	14.8432	0.496681	0.0036306753294013	758.9908960370828	0.0036241003373627613	761.7465455585649
17.83	0.09358118323503249	15.2496	0.509022	0.0037432473294012995	779.7717182418278	0.003736258813516349	782.6905966436791
18.24	0.09599568323503249	15.6464	0.520679	0.0038398273294012997	800.0616548826812	0.0038324740100815465	803.1337534903058
18.65	0.09853658323503249	16.0454	0.532986	0.0039414633294013	820.4640861319265	0.0039337161130532	823.6979152405062
19.06	0.10126138323503249	16.4607	0.546398	0.004050455329401299	841.7000001615293	0.004042274318984605	845.1092684129407
19.46	0.1036033832350325	16.8415	0.557575	0.0041441353294013	861.1717941958965	0.004135572050692173	864.7406066529077
19.87	0.1062103832350325	17.2402	0.570011	0.0042484153294013	881.5588852712701	0.0042394162917589505	885.3041135532266
20.27	0.1087743832350325	17.6369	0.582401	0.0043509753294013	901.8437085208329	0.004341537203042773	905.7676082475829
20.67	0.11118238323503249	18.0101	0.593998	0.004447295329401299	920.9268848171195	0.004437435334259459	925.0225186506867
21.08	0.1137313832350325	18.3953	0.605965	0.0045492553294013	940.6236680682704	0.004538938744062898	944.9028053031909
21.48	0.1161823832350325	18.7846	0.617737	0.0046472953294013	960.5301003623335	0.004636529992709602	964.9939674114967
21.89	0.11868838323503249	19.1936	0.630699	0.004747535329401299	981.4438707406323	0.0047363013254052	986.1033101907979
22.3	0.1212623832350325	19.5701	0.642632	0.0048504953294012994	1000.6957889495064	0.004838769578776567	1005.5496591999575
22.7	0.12372938323503249	19.9335	0.654308	0.0049491753294013	1019.2778528993204	0.004936968420700915	1024.3224377026947
23.11	0.1263093832350325	20.3368	0.667038	0.005052375329401299	1039.9001599740586	0.005039654908735652	1045.1541258873522
23.52	0.12885038323503248	20.7001	0.679127	0.005154015329401299	1058.4771105325817	0.005140778853579264	1063.9325177860871
23.92	0.13148538323503248	21.0582	0.69096	0.005259415329401299	1076.7881647439972	0.005245632908460741	1082.4514409241697
24.33	0.13425638323503247	21.4514	0.703583	0.005370255329401299	1096.894019298391	0.005355886926622145	1102.7846202513165
24.75	0.13722838323503248	21.7778	0.715683	0.005489135329401299	1113.584128470706	0.005474124930423687	1119.696742452555
25.15	0.14128438323503248	22.0663	0.727718	0.005651375329401299	1128.336262343907	0.005635466218605371	1134.7129140601864
25.57	0.1477383832350325	22.1913	0.740074	0.0059095353294013	1134.728001457079	0.005892142514161932	1141.4337166709504
25.99	0.15805038323503248	22.1558	0.752934	0.006322015329401299	1132.9127475489383	0.006302115218985481	1140.0750393058167
26.4	0.1706033832350325	22.0733	0.765556	0.0068241353294013	1128.6941997342446	0.006800956309333779	1136.3965616987416
26.81	0.18189138323503248	22.0476	0.777355	0.0072756553294012994	1127.3800581725766	0.007249315432012772	1135.5824869010808
27.21	0.1929753832350325	22.0361	0.788696	0.0077190153294013	1126.792018174165	0.007689376156351955	1135.4897430354983
27.61	0.20444138323503247	22.0519	0.801403	0.008177655329401299	1127.5999339980697	0.008144399486256435	1136.8210576077615
28.02	0.21574438323503248	22.053	0.812927	0.008629775329401299	1127.6561813022656	0.008592751669713156	1137.387600795715
28.44	0.22814338323503247	22.0521	0.825539	0.009125735329401299	1127.6101607806506	0.009084347412971455	1137.9004326626784
28.85	0.23952938323503248	22.0628	0.837875	0.009581175329401299	1128.1572936487382	0.009535566958832837	1138.9663664783297
29.26	0.2507163832350325	22.054	0.849354	0.010028655329401299	1127.7073152151709	0.009978702063970127	1139.0167031919084
29.67	0.26331238323503253	22.0445	0.862236	0.0105324953294013	1127.22154304257	0.010477415018317825	1139.0939986798662
30.08	0.2748353832350325	22.0388	0.874428	0.010993415329401299	1126.9300797390092	0.010933426989826137	1139.3188901527756
30.49	0.2859783832350325	22.094	0.886852	0.0114391353294013	1129.752671731386	0.011374203130490033	1142.676065432074
30.89	0.2964413832350325	22.1238	0.899002	0.0118576553294013	1131.2764623359662	0.011787904183050686	1144.6907487086105
31.31	0.3071453832350325	22.1509	0.911438	0.0122858153294013	1132.662191375702	0.012210957205321329	1146.5778698895388
31.72	0.3176113832350325	22.1833	0.924221	0.012704455329401301	1134.3189301538362	0.012624430802730938	1148.7298343312698
32.12	0.3283583832350325	22.2098	0.936115	0.013134335329401302	1135.6739788458287	0.013048827855876948	1150.5903017088654
32.53	0.33913438323503253	22.2211	0.948936	0.0135653753294013	1136.2517920616592	0.013474189347993633	1151.6654740896806
32.95	0.3496743832350325	22.2512	0.961426	0.013986975329401302	1137.7909228401113	0.013890060243696212	1153.7051764078926
33.35	0.3601303832350325	22.2645	0.973228	0.0144052153294013	1138.4710038817527	0.014302445982364718	1154.870923838949
33.75	0.3704473832350325	22.2775	0.985023	0.0148178953294013	1139.1357447495227	0.014709182928658901	1156.0153389812008
34.15	0.3810643832350325	22.3054	0.997677	0.0152425753294013	1140.5623809195824	0.015127574412393468	1157.9474889286303
34.56	0.3907463832350325	22.3028	1.00904	0.0156298553294013	1140.4294327460289	0.015508967156563865	1158.2541797932404
34.98	0.4017213832350325	22.3224	1.02185	0.016068855329401298	1141.4316574389738	0.015941117853445312	1159.7731576107594
35.39	0.4127233832350325	22.3565	1.03483	0.0165089353294013	1143.1753238690474	0.01637414433725236	1162.0479313609687
35.8101	0.4230663832350325	22.3627	1.04776	0.0169226553294013	1143.4923541290607	0.016781062384172984	1162.8432811097925
36.2101	0.4337583832350325	22.3949	1.0602	0.0173503353294013	1145.138866124614	0.01720153693037698	1165.0074094506065
36.6301	0.4445413832350325	22.4079	1.07213	0.017781655329401302	1145.8036069923837	0.017625411164026262	1166.177891807107
37.0401	0.4545563832350325	22.4174	1.0841	0.0181822553294013	1146.289379164985	0.018018934843962445	1167.1315053383435
37.4401	0.4649163832350325	22.447	1.09665	0.018596655329401298	1147.802942986984	0.018425851867257786	1169.1482387037852
37.8501	0.4755363832350325	22.4549	1.10863	0.0190214553294013	1148.2069008989363	0.018842809298026862	1170.0474671732957
38.2701	0.4865663832350325	22.4634	1.12105	0.0194626553294013	1148.6415391586322	0.01927567998324076	1170.9971535323098
38.6601	0.4963953832350325	22.5074	1.13311	0.0198558153294013	1150.8914313264688	0.019661259784069	1173.7433190510776
39.0801	0.5069773832350325	22.5004	1.14553	0.0202790953294013	1150.533493936131	0.020076212740230907	1173.8652723393309
39.4801	0.5176843832350325	22.5314	1.15788	0.0207073753294013	1152.1186452361978	0.020495892157457063	1175.9759984471052
39.8801	0.5278773832350325	22.5498	1.1704	0.021115095329401302	1153.0595092336566	0.020895260869750115	1177.4064706915979
40.3001	0.5388003832350325	22.5597	1.18267	0.021552015329401302	1153.56573497142	0.021323054516970925	1178.4274013749962
40.7101	0.5488563832350325	22.585	1.19499	0.0219542553294013	1154.8594229679259	0.021716730828093937	1180.2135016093287
41.1201	0.5595563832350325	22.5956	1.2076	0.0223822553294013	1155.401442444723	0.02213544859204505	1181.2619325374794
41.5401	0.5701263832350325	22.6004	1.21948	0.0228050553294013	1155.6468852266687	0.02254890705995117	1182.0014763855131
41.9401	0.5804723832350325	22.6363	1.2319	0.023218895329401298	1157.4825926999715	0.022953438009366816	1184.3580598654762
42.3601	0.5912073832350325	22.6401	1.24489	0.0236482953294013	1157.676901569012	0.02337300602849269	1185.0539868333422
42.7701	0.6016983832350326	22.6633	1.25711	0.024067935329401303	1158.8632083484167	0.023782867511828717	1186.754653102569
43.1801	0.6123003832350326	22.6898	1.26975	0.024492015329401304	1160.2182570404095	0.024196894942094056	1188.6343403772944
43.5901	0.6222753832350325	22.6886	1.2813	0.0248910153294013	1160.1568963449229	0.02458628042940647	1189.034379436355
43.9901	0.6326463832350325	22.7079	1.29372	0.0253058553294013	1161.1437808639964	0.024990963522623845	1190.5275173991747
44.4001	0.6433703832350325	22.7337	1.30637	0.0257348153294013	1162.4630358169552	0.02540924874962188	1192.3788073709597
44.8201	0.6538363832350325	22.738	1.31899	0.026153455329401297	1162.6829116424485	0.025817302162466447	1193.0910872343477
45.2301	0.6641283832350325	22.7548	1.33144	0.0265651353294013	1163.5419613792587	0.026218409267349415	1194.4516110447357
45.6301	0.6741423832350325	22.7667	1.34337	0.0269656953294013	1164.1504549428328	0.026608527593405203	1195.5425814284051
46.0401	0.6852163832350325	22.7908	1.35543	0.027408655329401302	1165.3827822438523	0.02703976351369647	1197.3243572491926
46.4501	0.6953653832350325	22.8119	1.36759	0.0278146153294013	1166.4617078061558	0.027434815487927484	1198.9063915052604
46.8601	0.7058773832350325	22.8126	1.37993	0.0282350953294013	1166.4975015451894	0.027843832841624977	1199.4336697028261
47.2601	0.7163713832350325	22.8443	1.39255	0.028654855329401298	1168.1184465842898	0.028251983025540012	1201.5907116787675
47.6601	0.7264373832350325	22.8452	1.40482	0.0290574953294013	1168.1644671059046	0.02864333024665184	1202.108400652807
48.0701	0.7363013832350325	22.857	1.41683	0.0294520553294013	1168.7678472781881	0.029026675570170492	1203.1904625834507
48.4901	0.7472623832350325	22.8931	1.4298	0.029890495329401297	1170.6137815340724	0.029452481375507884	1205.6040073035492
48.9001	0.7578213832350325	22.8998	1.44202	0.030312855329401298	1170.9563787505383	0.029862499159220318	1206.451410056643
49.3201	0.7685103832350325	22.9039	1.45451	0.0307404153294013	1171.1660277934504	0.030277393827126402	1207.1681579075062
49.7201	0.7788783832350326	22.9291	1.46657	0.031155135329401302	1172.4546023986659	0.030679664451804773	1208.9825842039756
50.1301	0.7893383832350325	22.9427	1.4788	0.0315735353294013	1173.1500236141787	0.03108534069191301	1210.190517331449
50.5501	0.7998383832350325	22.9531	1.49136	0.0319935353294013	1173.681816308395	0.03149240282405419	1211.2320469639333
50.9501	0.8103663832350325	22.9694	1.50393	0.0324146553294013	1174.5152990887525	0.031900384160058304	1212.5868076878232
51.3601	0.8208273832350325	22.9771	1.51566	0.0328330953294013	1174.909030218124	0.03230560431400091	1213.4849304106501
51.7701	0.8313313832350325	23.0034	1.52806	0.0332532553294013	1176.2538521275353	0.03271232497759562	1215.3681218045242
52.1901	0.8422383832350325	22.9992	1.54082	0.033689535329401304	1176.0390896933327	0.03313447503269226	1215.6593001543133
52.6001	0.8527703832350325	23.0145	1.55334	0.0341108153294013	1176.821438560785	0.033541941842236606	1216.9637773272125
53.0001	0.8628203832350325	23.0316	1.56506	0.0345128153294013	1177.695828471467	0.03393060607201945	1218.3414271137087
53.4001	0.8731553832350325	23.0349	1.57716	0.0349262153294013	1177.8645703840548	0.034330134639302165	1219.002921998161
53.8101	0.8838463832350325	23.0546	1.58964	0.0353538553294013	1178.8719084682907	0.03474325749368593	1220.5495753721739
54.2101	0.8942393832350325	23.0664	1.60123	0.0357695753294013	1179.475288640574	0.03514470146310779	1221.6646188267705
54.6301	0.9045213832350325	23.0648	1.61292	0.0361808553294013	1179.3934743799257	0.03554169938286108	1222.0649390529059
55.0501	0.9154353832350325	23.0784	1.62563	0.0366174153294013	1180.0888955954385	0.035962927065877295	1223.300700811071
55.4601	0.9263713832350325	23.0975	1.63866	0.0370548553294013	1181.0655533319311	0.036384825948047025	1224.829766545185
55.8701	0.9367993832350325	23.1122	1.65038	0.0374719753294013	1181.8172218516404	0.03678696102719538	1226.1022476327266
56.2901	0.9477983832350325	23.1237	1.66303	0.0379119353294013	1182.405261850052	0.03721094042139903	1227.232533670455
56.6901	0.9581153832350325	23.1261	1.67518	0.038324615329401304	1182.5279832410251	0.037608467384599414	1227.8479133149901
57.1001	0.9691883832350325	23.1352	1.68739	0.038767535329401304	1182.993301848464	0.03803494822857443	1228.8550364723194
57.5001	0.9793813832350325	23.1475	1.69914	0.039175255329401304	1183.6222489772001	0.03842737482190062	1229.9909527944421
57.9201	0.9905043832350325	23.1663	1.71207	0.0396201753294013	1184.583566539821	0.03885543041624302	1231.5169751384562
58.3201	1.0009573832350325	23.1698	1.72407	0.0400382953294013	1184.7625352349899	0.03925753490746891	1232.1984075159387
58.7301	1.0109673832350325	23.1694	1.73506	0.0404386953294013	1184.7420816698277	0.039642446643326834	1232.6515057543945
59.1401	1.0221673832350324	23.1917	1.74873	0.0408866953294013	1185.8823679276177	0.04007294156634993	1234.3691790015832
59.5601	1.0335473832350326	23.201	1.76115	0.0413418953294013	1186.3579133176377	0.04051016542284062	1235.4041979932224
59.9801	1.0442173832350325	23.206	1.77418	0.0417686953294013	1186.6135828821646	0.04091993723993551	1236.1768840992988
60.4001	1.0553173832350324	23.2139	1.78644	0.0422126953294013	1187.017540794117	0.041346044698196215	1237.1247505943143
60.8001	1.0656573832350325	23.2228	1.79776	0.0426262953294013	1187.4726326189748	0.04174281395210886	1238.0901917525728
61.2101	1.0761373832350325	23.229	1.80973	0.0430454953294013	1187.7896628789883	0.042144794750355624	1238.918657264757
61.6101	1.0871273832350326	23.2499	1.82245	0.0434850953294013	1188.8583616587107	0.042566164088023	1240.5559808485955
62.0201	1.0985573832350326	23.243	1.83457	0.043942295329401304	1188.5055376596636	0.04300421525986924	1240.7311989961333
62.4301	1.1086473832350325	23.2543	1.84576	0.0443458953294013	1189.0833508754943	0.04339075195229569	1241.8143166913528
62.8401	1.1197673832350326	23.2563	1.85872	0.0447906953294013	1189.185618701305	0.04381657380493074	1242.4500694386606
63.2501	1.1300073832350326	23.264	1.87053	0.045200295329401306	1189.5793498306764	0.04420853722206966	1243.3486877607802
63.6601	1.1411873832350325	23.2719	1.88313	0.0456474953294013	1189.9833077426288	0.04463630629145598	1244.3030652248758
64.0601	1.1520373832350326	23.279	1.89513	0.046081495329401305	1190.346358524257	0.045051274012576664	1245.1992986849625
64.4701	1.1629473832350326	23.2935	1.90704	0.0465178953294013	1191.087800261385	0.045468362929140825	1246.4946978820708
64.8701	1.1737873832350325	23.2894	1.91912	0.0469514953294013	1190.878151218473	0.045882603527197904	1246.791661173293
65.2801	1.1846473832350326	23.2918	1.93102	0.0473858953294013	1191.0008726094459	0.04629743640767561	1247.4375152961427
65.7001	1.1960573832350325	23.3032	1.94336	0.0478422953294013	1191.5837992165673	0.04673309301945031	1248.5919032484164
66.1101	1.2067573832350325	23.3068	1.9554	0.048270295329401296	1191.7678813030266	0.047141468035043814	1249.2948688976185
66.5101	1.2174473832350325	23.3093	1.96736	0.0486978953294013	1191.89571608529	0.04754929492324509	1249.9385289107731
66.9201	1.2293173832350326	23.3178	1.98041	0.0491726953294013	1192.3303543449856	0.048001944395735074	1250.9604515911888
67.3201	1.2397273832350324	23.3306	1.99244	0.0495890953294013	1192.9848684301746	0.04839874979529683	1252.143908797292
67.7201	1.2507273832350325	23.3335	2.00416	0.0500290953294013	1193.1331567776	0.048817873623046654	1252.8245292186962
68.1301	1.2616573832350324	23.3331	2.01634	0.0504662953294013	1193.112703212438	0.04923415638020745	1253.3246812540172
68.5401	1.2727473832350324	23.3303	2.02913	0.050909895329401295	1192.969528256303	0.04965635589742043	1253.7034820709966
68.9401	1.2838073832350325	23.3429	2.041	0.051352295329401304	1193.6138155589106	0.05007723585092591	1254.908624724745
69.3401	1.2944673832350324	23.329	2.05348	0.0517786953294013	1192.9030541695258	0.05048272652909709	1254.670017968882
69.7601	1.3055073832350326	23.3481	2.06514	0.052220295329401305	1193.8797119060184	0.05090249859975407	1256.2244630495313
70.1601	1.3171073832350324	23.3428	2.07756	0.0526842953294013	1193.60870216762	0.05134337369649227	1256.4931355403623
70.5701	1.3282373832350325	23.3457	2.08996	0.0531294953294013	1193.7569905150458	0.05176620311152194	1257.180696967055
70.9701	1.3389373832350324	23.3507	2.10161	0.053557495329401295	1194.0126600795725	0.05217252831102851	1257.9609875450303
71.3801	1.3507273832350326	23.3421	2.11387	0.054029095329401304	1193.5729084285863	0.05262005441501989	1258.0605728806652
71.7901	1.3620073832350326	23.3644	2.12636	0.0544802953294013	1194.7131946863763	0.053048034493160284	1259.8015223668224
72.2101	1.3736873832350325	23.3685	2.13963	0.0549474953294013	1194.9228437292882	0.0534909982293056	1260.5808611040982
72.6101	1.3844473832350326	23.358	2.15179	0.0553778953294013	1194.3859376437817	0.053898897416675126	1260.528517081528
73.0101	1.3956573832350325	23.3596	2.16336	0.0558262953294013	1194.4677519044303	0.05432367869432359	1261.150461383693
73.4201	1.4071273832350326	23.3595	2.17582	0.056285095329401305	1194.4626385131398	0.05475812548462597	1261.6930819892602
73.8301	1.4184573832350325	23.363	2.18823	0.0567382953294013	1194.6416072083086	0.05518708430160141	1262.4235355308842
74.2301	1.4296773832350325	23.3684	2.20023	0.0571870953294013	1194.9177303379977	0.055611697212469786	1263.2516044936287
74.6501	1.4413073832350325	23.3675	2.21269	0.0576522953294013	1194.871709816383	0.05605163606509164	1263.7588065114635
75.0501	1.4526773832350326	23.3551	2.22478	0.0581070953294013	1194.237649296356	0.05648155263217688	1263.6313302299795
75.4701	1.4645673832350325	23.3657	2.23751	0.0585826953294013	1194.7796687731532	0.05693093355714989	1264.7730820946538
75.8701	1.4759673832350324	23.3685	2.24974	0.05903869532940129	1194.9228437292882	0.057361605450680704	1265.4695294423634
76.2901	1.4877473832350325	23.3598	2.2618	0.0595098953294013	1194.4779786870115	0.05780643830450108	1265.5612381719504
76.6901	1.4995173832350326	23.3784	2.27425	0.059980695329401305	1195.4290694670512	nan	nan
77.1001	1.5111473832350326	23.3474	2.28664	0.060445895329401304	1193.8439181669848	nan	nan
77.5101	1.5225273832350326	23.3638	2.29927	0.0609010953294013	1194.6825143386332	nan	nan
77.9101	1.5340173832350326	23.3519	2.31065	0.061360695329401305	1194.0740207750591	nan	nan
78.3101	1.5451973832350325	23.3476	2.32287	0.0618078953294013	1193.8541449495658	nan	nan
78.7201	1.5576673832350325	23.3634	2.33527	0.0623066953294013	1194.6620607734708	nan	nan
79.1501	1.5696773832350326	23.3542	2.34776	0.0627870953294013	1194.1916287747413	nan	nan
79.5501	1.5811573832350325	23.3454	2.36003	0.0632462953294013	1193.7416503411741	nan	nan
79.9601	1.5933473832350324	23.3543	2.3729	0.0637338953294013	1194.1967421660318	nan	nan
80.3701	1.6054673832350326	23.3397	2.3857	0.0642186953294013	1193.4501870376134	nan	nan
80.7801	1.6175473832350324	23.3353	2.39773	0.0647018953294013	1193.2251978208296	nan	nan
81.1901	1.6297373832350326	23.3185	2.40967	0.0651894953294013	1192.3661480840194	nan	nan
81.6201	1.6418773832350324	23.3279	2.42319	0.0656750953294013	1192.84680686533	nan	nan
82.0401	1.6540473832350324	23.3091	2.43526	0.0661618953294013	1191.885489302709	nan	nan
82.4601	1.6663673832350325	23.3144	2.44791	0.0666546953294013	1192.1564990411073	nan	nan
82.8701	1.6788373832350325	23.2921	2.46069	0.0671534953294013	1191.0162127833175	nan	nan
83.2801	1.6903773832350326	23.2902	2.47213	0.0676150953294013	1190.919058348797	nan	nan
83.7001	1.7032773832350325	23.2901	2.48528	0.0681310953294013	1190.9139449575066	nan	nan
84.1001	1.7154673832350325	23.276	2.49712	0.06861869532940129	1190.192956785541	nan	nan
84.5201	1.7275573832350326	23.2668	2.51047	0.0691022953294013	1189.7225247868114	nan	nan
84.9301	1.7400773832350325	23.2467	2.52275	0.0696030953294013	1188.6947331374133	nan	nan
85.3401	1.7525073832350324	23.2491	2.53531	0.07010029532940129	1188.8174545283862	nan	nan
85.7401	1.7645473832350325	23.2327	2.54689	0.0705818953294013	1187.978858356738	nan	nan
86.1601	1.7770273832350325	23.2069	2.5589	0.0710810953294013	1186.6596034037796	nan	nan
86.5701	1.7896573832350324	23.2069	2.57172	0.07158629532940129	1186.6596034037796	nan	nan
86.9901	1.8021073832350325	23.1911	2.58402	0.0720842953294013	1185.8516875798744	nan	nan
87.3801	1.8146173832350325	23.1752	2.59599	0.0725846953294013	1185.0386583646791	nan	nan
87.8001	1.8273473832350324	23.1447	2.60811	0.0730938953294013	1183.4790740210651	nan	nan
88.2101	1.8400873832350324	23.1237	2.62072	0.0736034953294013	1182.405261850052	nan	nan
88.6101	1.8528973832350326	23.1122	2.63291	0.0741158953294013	1181.8172218516404	nan	nan
89.0201	1.8650073832350325	23.0799	2.64488	0.0746002953294013	1180.1655964647964	nan	nan
89.4301	1.8780473832350326	23.0657	2.65775	0.0751218953294013	1179.4394949015402	nan	nan
89.8301	1.8907173832350326	23.0412	2.67	0.07562869532940131	1178.1867140353586	nan	nan
90.2401	1.9029473832350325	23.0117	2.68133	0.0761178953294013	1176.67826360465	nan	nan
90.6601	1.9162473832350324	22.9791	2.69386	0.0766498953294013	1175.0112980439346	nan	nan
91.0601	1.9289973832350324	22.9594	2.70633	0.0771598953294013	1174.0039599596987	nan	nan
91.4701	1.9418173832350325	22.9265	2.71872	0.0776726953294013	1172.3216542251118	nan	nan
91.8801	1.9546873832350324	22.909	2.73164	0.0781874953294013	1171.4268107492678	nan	nan
92.2901	1.9673873832350326	22.875	2.74348	0.0786954953294013	1169.688257710485	nan	nan
92.6901	1.9803873832350325	22.8347	2.75558	0.0792154953294013	1167.6275610203984	nan	nan
93.0901	1.9930273832350325	22.8125	2.76796	0.0797210953294013	1166.492388153899	nan	nan
93.5001	2.0056473832350323	22.7809	2.78029	0.08022589532940129	1164.876556506089	nan	nan
93.9001	2.0184073832350324	22.74	2.79233	0.0807362953294013	1162.7851794682592	nan	nan
94.3001	2.030707383235032	22.7116	2.80408	0.08122829532940129	1161.3329763417466	nan	nan
94.7101	2.0444373832350324	22.6837	2.81701	0.0817774953294013	1159.9063401716865	nan	nan
95.1201	2.0572273832350323	22.6478	2.82956	0.08228909532940129	1158.0706326983834	nan	nan
95.5301	2.0706073832350325	22.6194	2.84226	0.0828242953294013	1156.6184295718706	nan	nan
95.9301	2.0830873832350325	22.5786	2.85422	0.0833234953294013	1154.5321659253316	nan	nan
96.3301	2.0956173832350324	22.5368	2.86572	0.0838246953294013	1152.3947683658866	nan	nan
96.7601	2.109207383235032	22.5199	2.87961	0.0843682953294013	1151.530605237786	nan	nan
97.1801	2.1224973832350322	22.4669	2.89166	0.08489989532940129	1148.8205078538008	nan	nan
97.5801	2.1350073832350325	22.427	2.90297	0.0854002953294013	1146.7802647288763	nan	nan
97.9901	2.148717383235032	22.3953	2.91681	0.08594869532940129	1145.1593196897759	nan	nan
98.3901	2.161947383235032	22.3568	2.92872	0.08647789532940128	1143.1906640429188	nan	nan
98.8001	2.1745573832350322	22.3184	2.94066	0.08698229532940129	1141.2271217873526	nan	nan
99.2101	2.1875073832350322	22.2875	2.95342	0.08750029532940129	1139.6470838785763	nan	nan
99.6301	2.201517383235032	22.2477	2.96626	0.08806069532940128	1137.6119541449423	nan	nan
100.03	2.2140273832350323	22.1923	2.97804	0.08856109532940129	1134.7791353699845	nan	nan
100.44	2.2267573832350323	22.1668	2.98962	0.08907029532940129	1133.4752205908974	nan	nan
100.87	2.2407873832350322	22.1387	3.0028	0.08963149532940129	1132.0383576382565	nan	nan
101.3	2.2543573832350323	22.0873	3.01644	0.0901742953294013	1129.4100745149199	nan	nan
101.7	2.266747383235032	22.0497	3.02779	0.09066989532940128	1127.487439389678	nan	nan
102.11	2.2801173832350323	22.0138	3.04029	0.09120469532940129	1125.6517319163747	nan	nan
102.53	2.2935473832350324	21.9782	3.05285	0.0917418953294013	1123.8313646169436	nan	nan
102.94	2.306927383235032	21.9272	3.06477	0.09227709532940129	1121.2235350587694	nan	nan
103.34	2.3197773832350324	21.8848	3.07684	0.09279109532940129	1119.0554571515813	nan	nan
103.74	2.3325773832350323	21.8565	3.08955	0.09330309532940129	1117.6083674163592	nan	nan
104.15	2.3460273832350325	21.8093	3.10171	0.0938410953294013	1115.1948467272252	nan	nan
104.56	2.358997383235032	21.7638	3.11425	0.09435989532940128	1112.8682536900308	nan	nan
104.98	2.3723173832350324	21.7359	3.12608	0.0948926953294013	1111.4416175199708	nan	nan
105.39	2.3861473832350324	21.6875	3.1392	0.0954458953294013	1108.9667361353506	nan	nan
105.79	2.3988673832350322	21.6507	3.15103	0.09595469532940129	1107.0850081404328	nan	nan
106.21	2.412207383235032	21.6117	3.16391	0.09648829532940129	1105.090785537123	nan	nan
106.62	2.4254573832350323	21.5705	3.17654	0.09701829532940129	1102.9840683254215	nan	nan
107.04	2.4389673832350325	21.5306	3.18857	0.0975586953294013	1100.9438252004968	nan	nan
107.45	2.452127383235032	21.4823	3.20087	0.09808509532940128	1098.4740572071673	nan	nan
107.85	2.465207383235032	21.4399	3.21241	0.09860829532940128	1096.3059792999793	nan	nan
108.25	2.4784773832350324	21.4023	3.22507	0.0991390953294013	1094.3833441747372	nan	nan
108.66	2.4910673832350323	21.3583	3.23706	0.09964269532940129	1092.1334520069006	nan	nan
109.07	2.5048473832350324	21.3286	3.25028	0.1001938953294013	1090.614774793611	nan	nan
109.47	2.5179173832350323	21.2852	3.26148	0.10071669532940129	1088.3955629735176	nan	nan
109.87	2.5303273832350324	21.2478	3.27376	0.1012130953294013	1086.4831546308567	nan	nan
110.3	2.5443773832350325	21.1916	3.28629	0.1017750953294013	1083.6094287255744	nan	nan
110.7	2.557007383235032	21.145	3.29842	0.10228029532940129	1081.2265883841837	nan	nan
111.11	2.5704373832350322	21.104	3.31048	0.10281749532940129	1079.1300979550633	nan	nan
111.51	2.5839973832350323	21.0683	3.3228	0.10335989532940129	1077.3046172643415	nan	nan
111.92	2.596517383235032	21.0143	3.33473	0.10386069532940129	1074.543385967451	nan	nan
112.33	2.6105073832350323	20.9931	3.34722	0.1044202953294013	1073.459347013857	nan	nan
112.74	2.6237573832350325	20.9533	3.3592	0.1049502953294013	1071.424217280223	nan	nan
113.16	2.637057383235032	20.8827	3.37157	0.10548229532940129	1067.8141630291036	nan	nan
113.56	2.6501873832350324	20.8489	3.38413	0.10600749532940129	1066.085836772902	nan	nan
113.97	2.6636773832350324	20.8058	3.39671	0.10654709532940129	1063.8819651266804	nan	nan
114.38	2.6764673832350323	20.7486	3.40807	0.1070586953294013	1060.9571053084926	nan	nan
114.79	2.6900173832350323	20.7045	3.42052	0.1076006953294013	1058.7020997493655	nan	nan
115.2	2.7027173832350324	20.6691	3.43234	0.1081086953294013	1056.891959232515	nan	nan
115.6	2.716307383235032	20.6432	3.44497	0.1086522953294013	1055.567590888266	nan	nan
116.01	2.729847383235032	20.579	3.45763	0.10919389532940128	1052.2847936797407	nan	nan
116.43	2.7437973832350324	20.538	3.4707	0.1097518953294013	1050.1883032506203	nan	nan
116.83	2.7569573832350325	20.4868	3.48236	0.1102782953294013	1047.570246909865	nan	nan
117.24	2.7696973832350325	20.4273	3.49348	0.1107878953294013	1044.5277790919952	nan	nan
117.65	2.7837873832350324	20.3898	3.50691	0.11135149532940129	1042.6102573580436	nan	nan
118.08	2.7977673832350325	20.3467	3.5192	0.1119106953294013	1040.4063857118217	nan	nan
118.48	2.8101673832350325	20.3051	3.53084	0.1124066953294013	1038.2792149349582	nan	nan
118.9	2.8244573832350324	20.242	3.54446	0.11297829532940129	1035.052665030629	nan	nan
119.3	2.8370473832350322	20.2097	3.55603	0.11348189532940128	1033.4010396437852	nan	nan
119.7	2.8499573832350324	20.1642	3.56756	0.1139982953294013	1031.0744466065908	nan	nan
120.12	2.8649373832350324	20.0994	3.58153	0.11459749532940129	1027.7609690503223	nan	nan
120.54	2.8784873832350324	20.0508	3.59345	0.11513949532940129	1025.275860883121	nan	nan
120.96	2.8925073832350323	20.0085	3.60699	0.11570029532940129	1023.1128963672236	nan	nan
121.36	2.9058673832350324	19.9611	3.6189	0.1162346953294013	1020.6891488955087	nan	nan
121.77	2.9185473832350324	19.8992	3.62973	0.1167418953294013	1017.523959686666	nan	nan
122.18	2.932207383235032	19.8615	3.64246	0.11728829532940128	1015.5962111701332	nan	nan
122.59	2.945957383235032	19.8174	3.65532	0.11783829532940128	1013.341205611006	nan	nan
123	2.9596773832350323	19.7521	3.66737	0.1183870953294013	1010.002161098285	nan	nan
123.41	2.9725873832350325	19.7012	3.67875	0.1189034953294013	1007.3994449314015	nan	nan
123.84	2.9870273832350325	19.6575	3.69203	0.1194810953294013	1005.1648929374364	nan	nan
124.24	2.9999673832350324	19.592	3.70425	0.1199986953294013	1001.8156216421343	nan	nan
124.66	3.0131873832350324	19.5494	3.71631	0.1205274953294013	999.6373169523652	nan	nan
125.06	3.0263273832350324	19.5057	3.72861	0.1210530953294013	997.4027649584003	nan	nan
125.48	3.0406473832350325	19.4382	3.741	0.1216258953294013	993.9512258372872	nan	nan
125.88	3.053407383235032	19.395	3.75326	0.12213629532940129	991.7422407997751	nan	nan
126.29	3.066497383235032	19.347	3.76503	0.12265989532940129	989.2878129803171	nan	nan
126.7	3.080057383235032	19.2773	3.77792	0.12320229532940129	985.7237792508123	nan	nan
127.1	3.093257383235032	19.2386	3.78988	0.12373029532940129	983.7448968213744	nan	nan
127.51	3.106967383235032	19.1788	3.80207	0.12427869532940129	980.6870888296328	nan	nan
127.91	3.119907383235032	19.1332	3.814	0.12479629532940129	978.3553824011475	nan	nan
128.32	3.1338873832350322	19.068	3.82663	0.1253554953294013	975.0214512797171	nan	nan
128.73	3.147227383235032	19.0051	3.83862	0.1258890953294013	971.8051281579689	nan	nan
129.14	3.160907383235032	18.9531	3.85134	0.1264362953294013	969.1461646868893	nan	nan
129.55	3.174147383235032	18.9163	3.86381	0.12696589532940128	967.2644366919715	nan	nan
129.97	3.188297383235032	18.8458	3.87651	0.1275318953294013	963.6594958321424	nan	nan
130.38	3.201857383235032	18.7867	3.88861	0.1280742953294013	960.6374815794347	nan	nan
130.79	3.2151173832350324	18.741	3.90126	0.1286046953294013	958.300661759659	nan	nan
131.19	3.2281773832350322	18.6856	3.91275	0.12912709532940128	955.4678429847013	nan	nan
131.59	3.241257383235032	18.6123	3.92521	0.12965029532940128	951.7197271687372	nan	nan
132	3.2551573832350322	18.5658	3.93719	0.13020629532940128	949.342000218637	nan	nan
132.41	3.2686473832350322	18.4964	3.94978	0.13074589532940128	945.793306663004	nan	nan
132.81	3.2818373832350325	18.441	3.96112	0.1312734953294013	942.960487888046	nan	nan
133.23	3.295487383235032	18.3793	3.97435	0.1318194953294013	939.8055254617843	nan	nan
133.62	3.3090673832350324	18.3245	3.98691	0.1323626953294013	937.0033870345698	nan	nan
134.02	3.3225573832350324	18.2685	3.99855	0.1329022953294013	934.1398879118686	nan	nan
134.43	3.3356373832350323	18.2075	4.01056	0.1334254953294013	931.0207192246406	nan	nan
134.83	3.3491473832350325	18.1348	4.02319	0.13396589532940129	927.3032837564198	nan	nan
135.24	3.3631573832350323	18.0915	4.03558	0.1345262953294013	925.089185327617	nan	nan
135.65	3.3767873832350324	18.033	4.048	0.1350714953294013	922.0978514226525	nan	nan
136.05	3.3900573832350323	17.9655	4.05943	0.1356022953294013	918.6463123015396	nan	nan
136.47	3.403997383235032	17.8925	4.07211	0.1361598953294013	914.9135366594471	nan	nan
136.88	3.4181873832350322	17.8244	4.08488	0.1367274953294013	911.431317190591	nan	nan
137.29	3.4312873832350324	17.774	4.09684	0.13725149532940129	908.85416798016	nan	nan
137.7	3.4455973832350324	17.7083	4.10983	0.13782389532940129	905.4946699022769	nan	nan
138.11	3.4588773832350324	17.6388	4.12154	0.1383550953294013	901.940862955353	nan	nan
138.52	3.4731173832350324	17.5648	4.13419	0.1389246953294013	898.1569534003554	nan	nan
138.92	3.486107383235032	17.5127	4.14569	0.13944429532940128	895.492876537985	nan	nan
139.33	3.4999373832350322	17.4479	4.15799	0.13999749532940128	892.1793989817169	nan	nan
139.74	3.5133173832350324	17.3715	4.17007	0.1405326953294013	888.272768035746	nan	nan
140.17	3.528197383235032	17.3036	4.18268	0.1411278953294013	884.8007753494709	nan	nan
140.57	3.5418373832350323	17.2353	4.19516	0.1416734953294013	881.3083290980337	nan	nan
140.98	3.5559673832350325	17.1645	4.20794	0.1422386953294013	877.6880480643331	nan	nan
141.39	3.569347383235032	17.0968	4.21967	0.1427738953294013	874.2262821606392	nan	nan
141.79	3.583107383235032	17.0298	4.23148	0.14332429532940127	870.8003099959791	nan	nan
142.21	3.597057383235032	16.9644	4.24406	0.14388229532940128	867.4561520919674	nan	nan
142.62	3.6117573832350325	16.8836	4.25749	0.1444702953294013	863.324531929213	nan	nan
143.03	3.624777383235032	16.8101	4.26868	0.14499109532940127	859.5661893306676	nan	nan
143.45	3.6390573832350324	16.7331	4.28092	0.1455622953294013	855.6288780369537	nan	nan
143.86	3.6535673832350324	16.653	4.29383	0.1461426953294013	851.533051613233	nan	nan
144.26	3.6672773832350325	16.5848	4.30569	0.1466910953294013	848.0457187530866	nan	nan
144.68	3.681117383235032	16.515	4.31771	0.1472446953294013	844.4765716322911	nan	nan
145.07	3.694407383235032	16.4315	4.32911	0.14777629532940129	840.2068899046922	nan	nan
145.47	3.7084173832350324	16.3662	4.34205	0.1483366953294013	836.8678453919711	nan	nan
145.88	3.7229773832350324	16.2678	4.35456	0.14891909532940129	831.8362683620821	nan	nan
146.28	3.736717383235032	16.1979	4.36608	0.1494686953294013	828.2620078499964	nan	nan
146.69	3.750877383235032	16.1266	4.37834	0.1500350953294013	824.6161598598429	nan	nan