File: original_data/46NTAV.csv
Specimen name:	AWA_4_02_Rz
Specimen ID:	46NTAV
Material:	42CrMoS4
Specimen type:	Round Tensile Specimen
Gauge diameter:	5.004	mm
Gauge length:	25	mm
Parallel length:	30	mm
Original cross-section:	19.666382577842715	mm²
Cross-section after fracture:	13.663761129582781	mm²
Yield stress at 0.2% plastic strain:	1085.8016537577498	MPa
Yield stress at 1% plastic strain:	1154.9496031280007	MPa
Ultimate tensile strength:	1203.7902703404502	MPa
Uniform elongation:	5.085031405728753	%
Elongation after fracture:	10.63843464180778	%
Reduction of area:	30.522244873964947	%
Slope of linear-elastic region:	203052.3321876089	MPa
Crosshead seperation speed:	0.029900807648897538	mm/s
Strain rate:	0.0009966935882965845	s-1
Test temperature:	RT	Cel
Machine type:	INSTRON 8852TT
Standard:	DIN EN ISO 6892-1
Date:	2022-09-13 00:00:00
Heat treatment batch:	Batch 4
Time	Displacement	Force	Machine Displacement	Engineering Strain	Engineering Stress	True Strain	True Stress
s	mm	kN	mm		MPa		MPa
0	0.0008009619332469891	0.132317	0	3.203847732987956e-05	6.728080239274709	3.203796410874585e-05	6.728295796720928
0.430001	0.0008851199332469891	0.14801	0.000549317	3.5404797329879565e-05	7.526040918514248	3.540417059484136e-05	7.526307376467664
0.850001	0.000987777933246989	0.153571	0.000984192	3.951111732987956e-05	7.808807715000013	3.951033678627934e-05	7.809116249717847
1.25	0.0022138119332469892	0.361299	0.0135269	8.855247732987956e-05	18.371400971679478	8.854855679079947e-05	18.373027804747544
1.66	0.003202151933246989	0.569858	0.02565	0.00012808607732987955	28.97624907602657	0.0001280778750086282	28.97996053010645
2.06	0.004239861933246989	0.793317	0.0379944	0.00016959447732987958	40.338735243246866	0.00016958009781229078	40.345576469966595
2.46	0.00527133193324699	1.0268	0.0505219	0.0002108532773298796	52.210923688469904	0.0002108310509019558	52.22193253284204
2.87	0.006320381933246989	1.27702	0.062294	0.0002528152773298796	64.93415832552574	0.00025278332493281787	64.95057467277098
3.29	0.007906491933246988	1.55684	0.0743637	0.0003162596773298795	79.16249944990015	0.0003162096777797085	79.1875353564328
3.68001	0.00984370193324699	1.87085	0.0863571	0.0003937480773298796	95.12934026351179	0.0003936705788983184	95.16679725833822
4.08001	0.01161846193324699	2.16829	0.0981369	0.0004647384773298796	110.25362653337788	0.0004646305198505193	110.30486563589311
4.50001	0.01366696193324699	2.5248	0.111076	0.0005466784773298796	128.381515512903	0.0005465291030883309	128.4516989243209
4.92001	0.01594886193324699	2.84947	0.123993	0.0006379544773298795	144.8903980547179	0.0006377510708770399	144.982831532879
5.32001	0.01815086193324699	3.20462	0.136185	0.0007260344773298796	162.94913349293378	0.0007257710417998884	163.06744018190068
5.74001	0.020479361933246988	3.582	0.148697	0.0008191744773298795	182.1382242424028	0.0008188391370399744	182.28742722704834
6.14001	0.02280636193324699	3.93404	0.160622	0.0009122544773298797	200.03882180306596	0.0009118386261030736	200.2213081138956
6.57001	0.02547726193324699	4.35447	0.173973	0.0010190904773298797	221.416927224125	0.001018571557150613	221.64257110617876
7.00001	0.02803916193324699	4.76236	0.186241	0.0011215664773298797	242.15739631575923	0.001120937991530167	242.42899193370445
7.41001	0.03061426193324699	5.16012	0.198471	0.0012245704773298795	262.38277322102385	0.001223821302452212	262.70407941887026
7.83001	0.033296461933246986	5.57873	0.211227	0.0013318584773298794	283.6683349323897	0.0013309723405466375	284.04614100901944
8.24001	0.03605056193324699	5.99038	0.222961	0.0014420224773298795	304.599993226467	0.0014409837613653196	305.03923326329414
8.65001	0.03851126193324699	6.40128	0.235138	0.0015404504773298797	325.49351537644003	0.0015392652005773897	325.9949220175695
9.07001	0.04107116193324699	6.83621	0.247803	0.0016428464773298795	347.6089195835166	0.0016414984812210538	348.17998767254284
9.47001	0.04365336193324699	7.22936	0.259514	0.0017461344773298795	367.59988632301986	0.0017446117568489668	368.24176515839105
9.89001	0.046282561933246986	7.64449	0.271896	0.0018513024773298794	388.7084963257414	0.0018495909289688581	389.42811332794844
10.3	0.04890676193324699	8.06349	0.284935	0.0019562704773298796	410.01388883204146	0.001954359472129193	410.81598689805884
10.7	0.05140846193324699	8.47483	0.296303	0.0020563384773298796	430.9297841865557	0.0020542271073285636	431.81592168280594
11.11	0.05404706193324699	8.89733	0.309044	0.0021618824773298796	452.41314536534276	0.002159548971978083	453.3912094168218
11.52	0.056666161933246986	9.31219	0.320236	0.0022666464773298794	473.5080263561867	0.0022640815093889787	474.5813016561143
11.94	0.05929886193324699	9.75019	0.333801	0.0023719544773298795	495.7795345131305	0.0023691458337484045	496.9555009997875
12.35	0.061896461933246986	10.1628	0.34568	0.0024758584773298797	516.7600070716614	0.002472798589255897	518.0394317159149
12.76	0.06439076193324698	10.5742	0.357857	0.0025756304773298794	537.678953317704	0.0025723192256405145	539.063815616888
13.16	0.06684926193324699	10.9789	0.370483	0.0026739704773298795	558.2572166764143	0.0026704017785876438	559.7499799925633
13.58	0.06954206193324698	11.4094	0.383171	0.0027816824773298793	580.1473633923144	0.002777820758353969	581.761149147332
14.01	0.07214846193324698	11.8202	0.395416	0.002885938477329879	601.0358007230736	0.0028817821515625254	602.7703530666331
14.41	0.07462956193324698	12.2371	0.407631	0.002985182477329879	622.2344120258815	0.0029807356676127507	624.0918952894529
14.82	0.07703446193324698	12.6117	0.419418	0.0030813784773298793	641.2821448012037	0.003076640760640009	643.25817780009
15.24	0.07954666193324698	13.0129	0.431847	0.0031818664773298794	661.6824394874269	0.003176815052659678	663.7878246602698
15.65	0.08250276193324699	13.4716	0.445717	0.0033001104773298794	685.006505221651	0.0032946770633777308	687.267102366572
16.05	0.08477196193324699	13.8514	0.456848	0.0033908784773298796	704.3186485960966	0.0033851424121150073	706.7069075428032
16.46	0.08726756193324699	14.2422	0.468536	0.0034907024773298797	724.190122084073	0.0034846241164963117	726.7180543372897
16.88	0.08969556193324699	14.6489	0.481995	0.0035878224773298797	744.8700818270615	0.0035814015956713687	747.5425434493311
17.29	0.09239626193324699	15.0639	0.494072	0.0036958504773298793	765.972081564805	0.003689037603037857	768.8029998480777
17.69	0.09481156193324698	15.4635	0.505913	0.003792462477329879	786.2910191436057	0.0037852892219897775	789.2729983299693
18.09	0.09702626193324698	15.8175	0.516975	0.0038810504773298792	804.2912791608616	0.0038735386305574398	807.412774213761
18.5	0.09967796193324699	16.2301	0.529778	0.003987118477329879	825.2712432374711	0.003979190985367069	828.5616974601922
18.91	0.10223696193324698	16.6468	0.542305	0.004089478477329879	846.4596849018511	0.004081139287781399	849.9212635651847
19.32	0.10471196193324699	17.0323	0.5541	0.0041884784773298794	866.06166297149	0.004179731217984292	869.6891436068865
19.74	0.10760596193324698	17.4433	0.566925	0.004304238477329879	886.9602699406769	0.004295001738162059	890.7779584624185
20.16	0.10996396193324698	17.8336	0.57885	0.004398558477329879	906.8063193325837	0.004388913092506949	910.7949599557803
20.57	0.11265596193324698	18.2236	0.591606	0.004506238477329879	926.6371142668487	0.004496115783511822	930.8127620856798
20.98	0.11558896193324698	18.6019	0.603416	0.0046235584773298795	945.8729853530857	0.004612902663395213	950.2462844129924
21.4	0.11879096193324698	18.9655	0.616776	0.0047516384773298795	964.3613880148772	0.004740385077199701	968.9436846922199
21.81	0.12243596193324698	19.3044	0.62883	0.004897438477329879	981.5938403308322	0.004885485037115917	986.4011357735785
22.23	0.126365961933247	19.6309	0.641113	0.005054638477329881	998.1957750642617	0.005041906677335881	1003.2412938368096
22.63	0.131057961933247	19.8954	0.653053	0.005242318477329881	1011.6451218850643	0.00522862536075826	1016.9484878000229
23.04	0.135897961933247	20.1502	0.664818	0.005435918477329879	1024.6012412421176	0.005421197197504776	1030.1708900612807
23.45	0.141908961933247	20.3895	0.67749	0.00567635847732988	1036.769213621014	0.005660308662240776	1042.6542873357862
23.87	0.148235961933247	20.5991	0.689438	0.00592943847732988	1047.4269946933778	0.005911928538976479	1053.6376486179067
24.28	0.154944961933247	20.7979	0.701828	0.00619779847732988	1057.535615290639	0.006178671115352827	1064.0900079168093
24.68	0.161605961933247	20.9542	0.714081	0.00646423847732988	1065.483187721987	0.006443434892543844	1072.3707251410076
25.09	0.169150961933247	21.1213	0.726715	0.00676603847732988	1073.9799206284374	0.0067432515659918155	1081.246510095289
25.49	0.176448961933247	21.2578	0.738556	0.00705795847732988	1080.92069885543	0.007033167668378257	1088.5497922652378
25.9	0.18384896193324698	21.3948	0.750732	0.0073539584773298795	1087.8869011784923	0.007327049966868569	1095.88717627779
26.32	0.191918961933247	21.5048	0.762871	0.00767675847732988	1093.4802023137977	0.007647442107837143	1101.8745857267024
26.73	0.20036096193324698	21.6232	0.776321	0.00801443847732988	1099.500628263072	0.00798249343283104	1108.312508404072
27.15	0.208892961933247	21.7241	0.788284	0.00835571847732988	1104.6312108499114	0.008321002711082147	1113.8611982690454
27.56	0.217342961933247	21.8193	0.801071	0.00869371847732988	1109.4719587415575	0.008656145714492084	1119.1173956093485
27.97	0.226350961933247	21.9111	0.813286	0.009054038477329879	1114.139822779931	0.009013296406483328	1124.2272876045058
28.39	0.235238961933247	21.9825	0.825203	0.00940955847732988	1117.7703836986655	0.009365564343554768	1128.2881094883055
28.79	0.244414961933247	22.0624	0.838226	0.00977659847732988	1121.8331542505828	0.00972911676072883	1132.8008665582472
29.22	0.25368496193324697	22.1349	0.851288	0.010147398477329879	1125.5196481806704	0.010096259291560846	1136.940744544824
29.62	0.26261696193324696	22.175	0.862465	0.010504678477329879	1127.5586606854501	0.010449887714581321	1139.4033018802795
30.04	0.27218196193324695	22.2417	0.875328	0.010887278477329877	1130.9502351011308	0.01082843874547127	1143.2632052546787
30.45	0.281641961933247	22.2999	0.888603	0.011265678477329878	1133.9095998836287	0.011202693327069916	1146.6838608582755
30.85	0.290927961933247	22.3387	0.899742	0.011637118477329879	1135.8825097386275	0.011569927980888649	1149.1009090807827
31.27	0.301166961933247	22.3936	0.912918	0.01204667847732988	1138.6740754870661	0.011974694779148422	1152.3913159649296
31.68	0.310770961933247	22.4273	0.924385	0.01243083847732988	1140.3876595621552	0.012354209988770402	1154.5636343597128
32.09	0.320652961933247	22.4786	0.937653	0.01282611847732988	1142.9961718188931	0.012744560461249268	1157.6563761377768
32.5	0.33049096193324695	22.5133	0.949898	0.013219638477329878	1144.7606040861215	0.013133021584200523	1159.89392541523
32.91	0.33979796193324696	22.5545	0.96106	0.013591918477329878	1146.855549602254	0.013500376904342717	1162.4435167377212
33.31	0.350052961933247	22.5771	0.973434	0.01400211847732988	1148.0047187445987	0.01390499439494488	1164.0792168289943
33.73	0.360318961933247	22.6203	0.986893	0.014412758477329878	1150.2013606450096	0.01430988198502848	1166.7789350562823
34.14	0.36983596193324697	22.6413	0.99855	0.01479343847732988	1151.2691726799317	0.014685082893676496	1168.3004023568187
34.56	0.38012296193324696	22.6772	1.01046	0.015204918477329878	1153.0946227777267	0.015090482242130093	1170.6273325137097
34.96	0.390460961933247	22.7142	1.02296	0.015618438477329879	1154.9760058868749	0.015497725938928168	1173.0149275776112
35.37	0.400616961933247	22.7182	1.03484	0.016024678477329878	1155.1793986554314	0.01589763870118841	1173.69077710252
35.7801	0.41066096193324697	22.7409	1.04652	0.01642643847732988	1156.33365261699	0.016292984008026347	1175.3280962209692
36.1901	0.421413961933247	22.7743	1.0592	0.016856558477329878	1158.0319822344372	0.016716063340377146	1177.5524160615903
36.6001	0.431523961933247	22.8111	1.07205	0.01726095847732988	1159.9031957051575	0.017113680490769962	1179.9242366039464
37.0201	0.441831961933247	22.8257	1.08432	0.017673278477329878	1160.6455793103892	0.017518922093328882	1181.1579918470236
37.4301	0.45251996193324695	22.8587	1.09715	0.01810079847732988	1162.3235696509805	0.017938929412534162	1183.3625543506835
37.8301	0.46256396193324695	22.8708	1.1092	0.01850255847732988	1162.9388327758643	0.01833346868680152	1184.4561765348576
38.2501	0.47294796193324695	22.8858	1.12167	0.01891791847732988	1163.7015556579513	0.01874119994350803	1185.7163668198302
38.6601	0.48276996193324695	22.9096	1.13347	0.019310798477329878	1164.911742630863	0.019126711148995255	1187.407118536683
39.0601	0.49310396193324696	22.9267	1.14537	0.01972415847732988	1165.7812467164424	0.019532157857255473	1188.7753007765766
39.4701	0.503906961933247	22.9461	1.15814	0.02015627847732988	1166.7677016439418	0.019955829753544627	1190.2853963566313
39.8801	0.513607961933247	22.974	1.16988	0.02054431847732988	1168.1863662046237	0.020336130524030917	1192.1859589528062
40.2801	0.5238839619332469	22.9801	1.18192	0.020955358477329877	1168.4965401766724	0.020738814893951966	1192.9828040555942
40.7001	0.534264961933247	23.0069	1.19476	0.02137059847732988	1169.8592717260015	0.021145449304397212	1194.8598644970393
41.1101	0.545138961933247	23.0322	1.20754	0.02180555847732988	1171.1457309871216	0.021571217787540675	1196.6832177096364
41.5101	0.555073961933247	23.0462	1.21963	0.02220295847732988	1171.8576056770694	0.021960061573377043	1197.8763114372605
41.9201	0.5652689619332469	23.0643	1.23189	0.02261075847732988	1172.777957954788	0.022358924317719218	1199.2953571096398
42.3301	0.5758399619332469	23.0744	1.24413	0.023033598477329876	1173.2915246953935	0.022772329516510943	1200.3166505720812
42.7401	0.5857969619332469	23.0982	1.25651	0.023431878477329877	1174.5017116683048	0.023161566480939328	1202.0224930475326
43.1501	0.596577961933247	23.1152	1.26857	0.02386311847732988	1175.3661309346703	0.02358284432025342	1203.4140321714053
43.5701	0.607384961933247	23.1148	1.28106	0.02429539847732988	1175.3457916578147	0.024004960091899362	1203.9012860147943
43.9701	0.617214961933247	23.1317	1.2929	0.02468859847732988	1176.205126104966	0.02438876006828863	1205.2439821903488
44.3801	0.627523961933247	23.1556	1.30551	0.02510095847732988	1177.4203978970916	0.024791103815395312	1206.9747784150677
44.7801	0.637554961933247	23.1642	1.31719	0.02550219847732988	1177.8576923494884	0.02518244233817076	1207.8956529978348
45.1901	0.648013961933247	23.1738	1.32926	0.02592055847732988	1178.345834994024	0.025590315366176942	1208.8892171165048
45.6101	0.6588219619332469	23.1893	1.34181	0.026352878477329877	1179.1339819721807	0.02601162375385097	1210.2075565075836
46.0201	0.6687169619332469	23.205	1.35403	0.02674867847732988	1179.9322985887652	0.02639718676076846	1211.4939282687328
46.4401	0.679362961933247	23.2301	1.36678	0.02717451847732988	1181.2085882114575	0.026811846867566217	1213.3073628173906
46.8501	0.690030961933247	23.2338	1.37899	0.02760123847732988	1181.3967265223723	0.027227191466304146	1214.004739307453
47.2601	0.700841961933247	23.2579	1.39176	0.02803367847732988	1182.6221679529256	0.02764792766105588	1215.7754175694806
47.6701	0.711183961933247	23.2704	1.40356	0.02844735847732988	1183.257770354665	0.028050245988476528	1216.9183283190303
48.0801	0.721847961933247	23.2789	1.41611	0.02887391847732988	1183.689979987848	0.028464921139985992	1217.8677479724493
48.4901	0.731837961933247	23.2858	1.42757	0.029273518477329882	1184.0408325136077	0.028853231518383714	1218.7018737021078
48.9101	0.7422899619332469	23.3062	1.44073	0.029691598477329877	1185.0781356332463	0.029259338452690853	1220.2649998007314
49.3301	0.7533549619332469	23.3235	1.4536	0.030134198477329878	1185.9578093572534	0.029689083538383017	1221.695697370164
49.7401	0.763840961933247	23.337	1.46567	0.03055363847732988	1186.6442599511317	0.030096170917917893	1222.9005596708773
50.1601	0.7741999619332469	23.3491	1.4782	0.030967998477329877	1187.2595230760153	0.030498165248854996	1224.0265741788287
50.5601	0.784268961933247	23.3638	1.49024	0.03137075847732988	1188.006991500461	0.030888750940717878	1225.2756719002014
50.9801	0.795422961933247	23.3765	1.50316	0.031816918477329884	1188.6527635406278	0.031321246745086996	1226.4720316160528
51.4001	0.805946961933247	23.3952	1.51543	0.03223787847732988	1189.6036247336299	0.031729142898287675	1227.9539218239838
51.8101	0.816386961933247	23.3806	1.52728	0.03265547847732988	1188.8612411283984	0.03213361899802119	1227.6840738005985
52.2101	0.826525961933247	23.4045	1.5393	0.03306103847732988	1190.0765129205238	0.03252627694685589	1229.4216783051556
52.6201	0.837094961933247	23.4068	1.55155	0.03348379847732988	1190.1934637624438	0.032935423652349805	1230.0456618521007
53.0501	0.848289961933247	23.4339	1.56445	0.03393159847732988	1191.5714497694146	0.033368621555066764	1232.0033737600402
53.4601	0.8590359619332469	23.4309	1.57761	0.03436143847732988	1191.4189051929973	0.03378426865971617	1232.3577726045141
53.8701	0.8692049619332469	23.4393	1.58907	0.03476819847732988	1191.846030006966	0.034177438810078	1233.2843693326658
54.2801	0.879816961933247	23.4591	1.60136	0.03519267847732988	1192.852824211321	0.034587572171221326	1234.832510124565
54.7001	0.890541961933247	23.473	1.61403	0.03562167847732988	1193.559614082055	0.03500190192965302	1236.0762108984118
55.1001	0.9009529619332469	23.4693	1.62548	0.03603811847732988	1193.37147577114	0.03540393705744913	1236.3783384024464
55.5101	0.911610961933247	23.4891	1.63815	0.03646443847732988	1194.3782699754952	0.03581534306955014	1237.9306029196762
55.9301	0.9221999619332469	23.4866	1.64993	0.036887998477329875	1194.2511494951473	0.036223918088772934	1238.3046840792736
56.3301	0.9323579619332469	23.4904	1.66222	0.03729431847732988	1194.4443726252762	0.03661570621836606	1238.9903614614175
56.7301	0.942950961933247	23.5133	1.67455	0.03771803847732988	1195.6087962252623	0.03702410861121873	1240.7048148051208
57.1501	0.9537819619332469	23.5059	1.68659	0.03815127847732988	1195.2325196034328	0.03744151446885313	1240.832168303984
57.5701	0.964295961933247	23.5264	1.69872	0.03857183847732988	1196.274907542285	0.03784653717247277	1242.417430050489
57.9801	0.975233961933247	23.5178	1.71138	0.03900935847732988	1195.8376130898887	0.03826771927318594	1242.4864712195867
58.3901	0.9858349619332469	23.5419	1.72344	0.03943339847732988	1197.0630545204417	0.03867575553443432	1244.267318951836
58.8001	0.996622961933247	23.5464	1.73598	0.039864918477329876	1197.291871385068	0.039090818637863484	1245.0218142314034
59.2001	1.007170961933247	23.552	1.74794	0.040286838477329875	1197.5766212610472	0.039496481353937296	1245.8231971660175
59.6001	1.017560961933247	23.5594	1.75967	0.040702438477329884	1197.9528978828769	0.03989590677157672	1246.7125020076935
60.0101	1.028220961933247	23.5565	1.77169	0.04112883847732988	1197.8054381256732	0.040305546121972534	1247.0697845176112
60.4301	1.039320961933247	23.5763	1.78458	0.041572838477329885	1198.812232330028	0.040731915401489883	1248.6502596293317
60.8501	1.050050961933247	23.5651	1.79663	0.04200203847732988	1198.24273257807	0.041143899641478354	1248.5713699369949
61.2601	1.060820961933247	23.5721	1.80979	0.04243283847732988	1198.5986699230439	0.041557249092590155	1249.4586136830308
61.6601	1.071620961933247	23.6008	1.82265	0.042864838477329886	1200.0580130374371	0.04197157843362788	1251.4983059297122
62.0901	1.0825709619332469	23.6019	1.8349	0.04330283847732987	1200.1139460487902	0.04239148716030832	1252.082286408932
62.4901	1.092980961933247	23.6009	1.84681	0.04371923847732988	1200.063097856651	0.0427905246310886	1252.5289426196894
62.9101	1.104220961933247	23.5928	1.85944	0.04416883847732988	1199.651227500324	0.043221199064178845	1252.6384287969163
63.3301	1.115340961933247	23.5927	1.87189	0.04461363847732988	1199.6461426811102	0.043647093106886435	1253.1667219914086
63.7501	1.126450961933247	23.6186	1.88497	0.04505803847732988	1200.963110857514	0.04407242308728515	1255.0761529163856
64.1701	1.1378509619332469	23.6198	1.89781	0.04551403847732988	1201.024128688081	0.04450866732134764	1255.6875870933918
64.5801	1.148980961933247	23.6123	1.91033	0.045959238477329876	1200.6427672470375	0.044934395932494486	1255.8233945130255
65.0101	1.160160961933247	23.6174	1.92297	0.04640643847732988	1200.902093026947	0.04536185468096743	1256.631682124299
65.4101	1.170380961933247	23.6224	1.93455	0.04681523847732988	1201.1563339876425	0.04575244876825212	1257.3887542118293
65.8201	1.181730961933247	23.6246	1.94736	0.04726923847732988	1201.268200010349	0.04618605114877621	1258.0512330318709
66.2301	1.1924209619332469	23.6426	1.95921	0.047696838477329875	1202.1834674688535	0.04659426778831209	1259.5238181368318
66.6401	1.203930961933247	23.6421	1.97304	0.04815723847732988	1202.1580433727836	0.04703361135947763	1260.050654954927
67.0501	1.214640961933247	23.6488	1.98464	0.04858563847732988	1202.4987262601162	0.04744224516066487	1260.9228946436397
67.4601	1.225720961933247	23.6404	1.99683	0.04902883847732988	1202.0716014461473	0.047864820435067734	1261.0077758316356
67.8801	1.237250961933247	23.6484	2.00946	0.049490038477329884	1202.4783869832602	0.04830436854920683	1261.9890886232192
68.2801	1.247880961933247	23.6512	2.02142	0.04991523847732988	1202.6207619212498	0.04870943565128698	1262.649864050337
68.6901	1.258790961933247	23.639	2.03378	0.050351638477329874	1202.0004139771524	0.049125001892957404	1262.523104271331
69.0901	1.269790961933247	23.6518	2.04643	0.050791638477329884	1202.6512708365335	0.04954382150536329	1263.735899399164
69.5001	1.281240961933247	23.6517	2.05843	0.05124963847732988	1202.6461860173195	0.04997958840705891	1264.2813682668466
69.9201	1.292690961933247	23.6605	2.07166	0.05170763847732988	1203.093650108144	0.05041516549867208	1265.302781622307
70.3301	1.303470961933247	23.6649	2.08353	0.05213883847732988	1203.317382153556	0.05082508134639311	1266.0569527786238
70.7501	1.314790961933247	23.6636	2.09571	0.05259163847732988	1203.251279503775	0.051255350221143206	1266.5322357928223
71.1501	1.326220961933247	23.6553	2.10763	0.05304883847732988	1202.8292395090202	0.05168961239665581	1266.6379335515437
71.5701	1.337540961933247	23.6624	2.12023	0.05350163847732988	1203.1902616732084	0.05211950953126261	1267.5629120726924
71.9701	1.348790961933247	23.6651	2.1319	0.05395163847732988	1203.327551791984	0.0525465652688773	1268.2490448360757
72.3801	1.3600609619332469	23.6471	2.14359	0.054402438477329874	1202.4122843334794	0.05297419743161231	1267.826444656317
72.8001	1.3721609619332469	23.6651	2.15661	0.05488643847732987	1203.327551791984	0.053433119880578445	1269.3739154314906
73.2201	1.383340961933247	23.6537	2.16926	0.05533363847732988	1202.7478824015977	0.05385696193532776	1269.300298905782
73.6201	1.394550961933247	23.6498	2.18172	0.05578203847732988	1202.549574452255	0.05428176102297398	1269.6302410852475
74.0401	1.406270961933247	23.6481	2.19384	0.05625083847732988	1202.4631325256184	0.054725693513622525	1270.102691968261
74.4401	1.417600961933247	23.6742	2.20563	0.05670403847732988	1203.7902703404502	nan	nan
74.8501	1.429030961933247	23.6637	2.21796	0.05716123847732988	1203.256364322989	nan	nan
75.2801	1.441150961933247	23.6558	2.2304	0.05764603847732988	1202.8546636050899	nan	nan
75.6901	1.452460961933247	23.6614	2.24274	0.05809843847732988	1203.1394134810691	nan	nan
76.1001	1.464440961933247	23.6602	2.25465	0.05857763847732988	1203.0783956505022	nan	nan
76.5101	1.475990961933247	23.6594	2.26678	0.059039638477329875	1203.0377170967909	nan	nan
76.9301	1.487810961933247	23.6417	2.27909	0.05951243847732988	1202.137704095928	nan	nan
77.3301	1.498890961933247	23.6371	2.29076	0.059955638477329876	1201.903802412088	nan	nan
77.7401	1.510890961933247	23.6562	2.30367	0.06043563847732988	1202.8750028819454	nan	nan
78.1501	1.522400961933247	23.6401	2.31617	0.060896038477329884	1202.0563469885053	nan	nan
78.5701	1.534560961933247	23.6499	2.32848	0.06138243847732988	1202.5546592714688	nan	nan
78.9901	1.546220961933247	23.6172	2.34026	0.06184883847732988	1200.8919233885192	nan	nan
79.4001	1.5585409619332469	23.643	2.35343	0.062341638477329875	1202.203806745709	nan	nan
79.8201	1.571020961933247	23.622	2.36552	0.06284083847732988	1201.135994710787	nan	nan
80.2301	1.582180961933247	23.6213	2.37699	0.06328723847732988	1201.1004009762896	nan	nan
80.6401	1.594780961933247	23.6149	2.38944	0.06379123847732987	1200.774972546599	nan	nan
81.0501	1.6065009619332469	23.6235	2.4017	0.06426003847732988	1201.2122669989958	nan	nan
81.4701	1.618250961933247	23.5934	2.4135	0.06473003847732989	1199.6817364156075	nan	nan
81.8701	1.6300209619332469	23.5849	2.42503	0.06520083847732988	1199.249526782425	nan	nan
82.2701	1.641790961933247	23.6042	2.43727	0.06567163847732987	1200.23089689071	nan	nan
82.6801	1.654300961933247	23.5857	2.44984	0.06617203847732987	1199.2902053361363	nan	nan
83.0801	1.665770961933247	23.5704	2.4613	0.06663083847732988	1198.512227996407	nan	nan
83.5101	1.678540961933247	23.5781	2.47427	0.06714163847732987	1198.9037590758787	nan	nan
83.9301	1.690830961933247	23.5679	2.48652	0.06763323847732988	1198.3851075160596	nan	nan
84.3301	1.702850961933247	23.5543	2.49861	0.06811403847732989	1197.6935721029672	nan	nan
84.7501	1.715450961933247	23.5328	2.51072	0.06861803847732988	1196.6003359719757	nan	nan
85.1601	1.727860961933247	23.5313	2.5238	0.06911443847732988	1196.524063683767	nan	nan
85.5601	1.739890961933247	23.516	2.5359	0.06959563847732989	1195.746086344038	nan	nan
85.9801	1.752300961933247	23.4913	2.54819	0.07009203847732988	1194.4901359982011	nan	nan
86.3901	1.764260961933247	23.4783	2.56042	0.07057043847732988	1193.8291095003924	nan	nan
86.8001	1.777100961933247	23.4687	2.57283	0.07108403847732987	1193.3409668558565	nan	nan
87.2001	1.789510961933247	23.4678	2.58543	0.07158043847732988	1193.2952034829314	nan	nan
87.6201	1.8021009619332469	23.4376	2.59714	0.07208403847732987	1191.7595880803294	nan	nan
88.0301	1.815000961933247	23.4265	2.61008	0.07260003847732988	1191.195173147585	nan	nan
88.4401	1.827060961933247	23.3931	2.62176	0.07308243847732988	1189.4968435301378	nan	nan
88.8601	1.839990961933247	23.387	2.63474	0.07359963847732988	1189.1866695580889	nan	nan
89.2701	1.8527709619332469	23.3678	2.64716	0.07411083847732987	1188.2103842690174	nan	nan
89.6701	1.864880961933247	23.346	2.65881	0.07459523847732988	1187.1018936803841	nan	nan
90.0901	1.877600961933247	23.3239	2.67169	0.07510403847732988	1185.978148634109	nan	nan
90.4901	1.890410961933247	23.3041	2.68413	0.07561643847732988	1184.971354429754	nan	nan
90.9001	1.9025609619332469	23.2801	2.69563	0.07610243847732988	1183.7509978184148	nan	nan
91.3201	1.915860961933247	23.2537	2.70815	0.07663443847732988	1182.4086055459413	nan	nan
91.7201	1.928140961933247	23.2151	2.72002	0.07712563847732988	1180.4458653293705	nan	nan
92.1401	1.941140961933247	23.1918	2.73248	0.07764563847732987	1179.2611024525286	nan	nan
92.5401	1.953650961933247	23.1639	2.74442	0.07814603847732987	1177.8424378918467	nan	nan
92.9601	1.966740961933247	23.1431	2.75724	0.07866963847732988	1176.7847954953525	nan	nan
93.3701	1.979780961933247	23.1208	2.77021	0.07919123847732988	1175.6508808106496	nan	nan
93.7901	1.992760961933247	23.0912	2.7828	0.07971043847732988	1174.145774323331	nan	nan
94.2001	2.005140961933247	23.0604	2.79441	0.0802056384773299	1172.5796500054455	nan	nan
94.6001	2.0174909619332473	23.0298	2.80659	0.08069963847732989	1171.0236953259878	nan	nan
95.0201	2.030620961933247	23.0076	2.81847	0.08122483847732989	1169.8948654604987	nan	nan
95.4401	2.0440809619332474	22.9612	2.83121	0.0817632384773299	1167.5355093452426	nan	nan
95.8401	2.056650961933247	22.9374	2.84309	0.08226603847732988	1166.3253223723311	nan	nan
96.2501	2.0698909619332473	22.913	2.85581	0.08279563847732989	1165.0846264841362	nan	nan
96.6601	2.082400961933247	22.8638	2.86774	0.08329603847732989	1162.5828954308904	nan	nan
97.0801	2.0953209619332474	22.8314	2.87996	0.0838128384773299	1160.935414005582	nan	nan
97.4901	2.1083209619332473	22.8078	2.89256	0.08433283847732989	1159.7353966710984	nan	nan
97.9101	2.121650961933247	22.7738	2.90625	0.08486603847732989	1158.0065581383678	nan	nan
98.3201	2.134050961933247	22.7473	2.91817	0.08536203847732989	1156.6590810466803	nan	nan
98.7501	2.147880961933247	22.7115	2.93135	0.08591523847732989	1154.838715768099	nan	nan
99.1801	2.1607309619332473	22.6736	2.94353	0.08642923847732989	1152.9115692860257	nan	nan
99.5901	2.174310961933247	22.6409	2.95621	0.08697243847732988	1151.2488334030757	nan	nan
99.9901	2.187260961933247	22.6075	2.96838	0.08749043847732989	1149.5505037856285	nan	nan
100.41	2.200300961933247	22.561	2.98112	0.08801203847732988	1147.1860628511586	nan	nan
100.83	2.2133309619332473	22.5233	2.99415	0.0885332384773299	1145.269086007513	nan	nan
101.24	2.226030961933247	22.5091	3.00647	0.08904123847732988	1144.547041679137	nan	nan
101.64	2.238330961933247	22.4592	3.01811	0.08953323847732989	1142.009716891394	nan	nan
102.04	2.250800961933247	22.4309	3.02996	0.09003203847732989	1140.5707130538563	nan	nan
102.46	2.264210961933247	22.3873	3.04332	0.09056843847732989	1138.3537318765896	nan	nan
102.87	2.277300961933247	22.3456	3.05576	0.09109203847732988	1136.2333622643876	nan	nan
103.27	2.290050961933247	22.3087	3.06787	0.0916020384773299	1134.3570639744532	nan	nan
103.68	2.3027409619332473	22.2687	3.07971	0.09210963847732989	1132.3231362888876	nan	nan
104.1	2.3162209619332472	22.2417	3.09229	0.0926488384773299	1130.9502351011308	nan	nan
104.51	2.3291009619332472	22.1882	3.10418	0.09316403847732989	1128.2298568216866	nan	nan
104.92	2.3420709619332474	22.1721	3.11682	0.09368283847732989	1127.4112009282464	nan	nan
105.33	2.354920961933247	22.1182	3.12944	0.09419683847732989	1124.6704833719468	nan	nan
105.73	2.367700961933247	22.092	3.14147	0.09470803847732988	1123.3382607379015	nan	nan
106.15	2.380860961933247	22.0386	3.15392	0.09523443847732987	1120.6229672776713	nan	nan
106.56	2.3939909619332473	22.0101	3.16617	0.09575963847732989	1119.1737938017059	nan	nan
106.97	2.4067409619332474	21.9554	3.17793	0.09626963847732989	1116.392397691695	nan	nan
107.39	2.419900961933247	21.9281	3.1905	0.09679603847732988	1115.0042420462962	nan	nan
107.79	2.432740961933247	21.8869	3.20237	0.09730963847732989	1112.9092965301636	nan	nan
108.2	2.4459009619332472	21.8469	3.21556	0.09783603847732988	1110.875368844598	nan	nan
108.6	2.458400961933247	21.7928	3.22637	0.09833603847732988	1108.1244816498704	nan	nan
109.01	2.4714609619332473	21.7596	3.2391	0.09885843847732989	1106.436321670851	nan	nan
109.43	2.484670961933247	21.7201	3.25129	0.09938683847732989	1104.4278180813549	nan	nan
109.84	2.497210961933247	21.6778	3.26343	0.0998884384773299	1102.2769395538694	nan	nan
110.26	2.5105209619332474	21.6308	3.27573	0.1004208384773299	1099.8870745233296	nan	nan
110.66	2.5232009619332474	21.5989	3.28806	0.1009280384773299	1098.2650171940911	nan	nan
111.07	2.536700961933247	21.5463	3.30022	0.10146803847732988	1095.590402287572	nan	nan
111.48	2.549320961933247	21.5074	3.31192	0.10197283847732988	1093.6124076133597	nan	nan
111.9	2.562730961933247	21.462	3.32473	0.10250923847732989	1091.3038996902426	nan	nan
112.29	2.5756709619332474	21.4233	3.33694	0.1030268384773299	1089.336074654458	nan	nan
112.69	2.588440961933247	21.3697	3.3487	0.10353763847732989	1086.6106115558	nan	nan
113.11	2.6015609619332474	21.3343	3.36181	0.10406243847732989	1084.8105855540744	nan	nan
113.52	2.614410961933247	21.2735	3.37313	0.10457643847732989	1081.7190154720145	nan	nan
113.93	2.6276509619332473	21.2274	3.38525	0.1051060384773299	1079.3749138144	nan	nan
114.33	2.6405409619332474	21.1786	3.39753	0.1056216384773299	1076.89352203801	nan	nan
114.74	2.653190961933247	21.1185	3.40969	0.1061276384773299	1073.8375456904478	nan	nan
115.14	2.6660109619332473	21.0721	3.42118	0.10664043847732989	1071.4781895751914	nan	nan
115.56	2.6799909619332474	21.0256	3.43416	0.1071996384773299	1069.1137486407215	nan	nan
115.98	2.693650961933247	20.9659	3.4471	0.10774603847732989	1066.078111570015	nan	nan
116.4	2.707330961933247	20.9011	3.45927	0.10829323847732988	1062.7831487193985	nan	nan
116.81	2.720680961933247	20.83	3.47094	0.10882723847732988	1059.1678422583054	nan	nan
117.22	2.7340909619332474	20.7606	3.48277	0.1093636384773299	1055.6389777238492	nan	nan
117.64	2.747860961933247	20.6903	3.49574	0.10991443847732989	1052.0643498164675	nan	nan
118.05	2.7632809619332472	20.5751	3.5076	0.11053123847732989	1046.2066380820384	nan	nan
118.46	2.783810961933247	20.1376	3.51963	0.11135243847732988	1023.9605540211643	nan	nan