File: original_data/46NT91.csv
Specimen name:	AWA_1_11_Rz
Specimen ID:	46NT91
Material:	42CrMoS4
Specimen type:	Round Tensile Specimen
Gauge diameter:	4.994	mm
Gauge length:	25	mm
Parallel length:	30	mm
Original cross-section:	19.58785846946624	mm²
Cross-section after fracture:	8.701357333591492	mm²
Yield stress at 0.2% plastic strain:	1130.8383894485528	MPa
Yield stress at 1% plastic strain:	1144.0429266258866	MPa
Ultimate tensile strength:	1198.3596898349263	MPa
Uniform elongation:	5.42367647458903	%
Elongation after fracture:	14.687231118163101	%
Reduction of area:	55.57780169202642	%
Slope of linear-elastic region:	202553.6559947184	MPa
Crosshead seperation speed:	0.030032170394200287	mm/s
Strain rate:	0.0010010723464733428	s-1
Test temperature:	RT	Cel
Machine type:	INSTRON 8852TT
Standard:	DIN EN ISO 6892-1
Date:	2022-08-18 00:00:00
Heat treatment batch:	Batch 1
Time	Displacement	Force	Machine Displacement	Engineering Strain	Engineering Stress	True Strain	True Stress
s	mm	kN	mm		MPa		MPa
0	0.0010058891489556074	0.165507	0	4.02355659582243e-05	8.449468851227103	4.0234756529441104e-05	8.449808820388377
0.440001	0.0009881828489556074	0.166671	-0.0001297	3.9527313958224296e-05	8.508893417818417	3.952653277448739e-05	8.50922975151998
0.850001	0.0009773190489556075	0.161921	-0.000518799	3.9092761958224303e-05	8.266396260336686	3.909199785613216e-05	8.266719416597944
1.26	0.0009397985489556075	0.15867	-0.00038147	3.75919419582243e-05	8.100426100552875	3.759123539883875e-05	8.100730611300683
1.67	0.0011056088489556075	0.251844	0.00614548	4.42243539582243e-05	12.857148237648188	4.422337609032198e-05	12.857716836722743
2.08	0.0013585241489556075	0.416763	0.0184402	5.4340965958224295e-05	21.27659849338071	5.4339489541328606e-05	21.277754684295143
2.49	0.0016450361489556073	0.580154	0.0312881	6.580144595822429e-05	29.618041242453845	6.579928113806668e-05	29.61999015239405
2.9	0.0016786001489556075	0.750571	0.043663	6.71440059582243e-05	38.31817557646733	6.71417519004374e-05	38.32074841227655
3.31	0.0015673351489556074	0.909965	0.0552597	6.269340595822429e-05	46.455563349023734	6.26914408087729e-05	46.45847580651579
3.71001	0.0019177321489556075	1.10353	0.067421	7.67092859582243e-05	56.33745014648713	7.670634395132995e-05	56.341771752060566
4.12001	0.0026991491489556075	1.33479	0.0797043	0.0001079659659582243	68.14374333369238	0.00010796013805276051	68.15110053876542
4.53001	0.004248869148955607	1.61712	0.0922775	0.00016995476595822428	82.55726385407489	0.0001699403252830732	82.57129485453136
4.94001	0.005997259148955608	1.92459	0.104328	0.00023989036595822432	98.25423248795018	0.00023986159686519346	98.27780273173865
5.34001	0.007521299148955608	2.23322	0.116604	0.0003008519659582243	114.01042148028418	0.00030080671908033004	114.04472173972624
5.75001	0.009366969148955608	2.55753	0.128483	0.0003746787659582243	130.56710635247362	0.00037460859139743766	130.6160270747565
6.18001	0.011437789148955607	2.90173	0.141132	0.00045751156595822426	148.13921616409712	0.00045740693945237266	148.20699156886417
6.59001	0.013659389148955607	3.28238	0.153549	0.0005463755659582243	167.57217258418567	0.0005462263571756115	167.66372992482022
7.00001	0.015768089148955607	3.65246	0.165844	0.0006307235659582243	186.46550901383594	0.000630524743446811	186.58311720460935
7.40001	0.01806778914895561	4.01243	0.17767	0.0007227115659582243	204.8427093882988	0.0007224505357132956	204.99075158357596
7.81001	0.020561589148955606	4.4118	0.190495	0.0008224635659582242	225.23135986903114	0.0008221255281359975	225.41660445643464
8.21001	0.023006989148955607	4.81262	0.202324	0.0009202795659582243	245.69403579783682	0.000919856368338612	245.92014299845937
8.62001	0.02535388914895561	5.19482	0.214314	0.0010141555659582244	265.20612286931413	0.0010136416576281841	265.47508313494825
9.03001	0.027975089148955606	5.63306	0.22731	0.0011190035659582242	287.5791658787444	0.0011183779481368607	287.900967990858
9.43001	0.03052358914895561	6.04478	0.239094	0.0012209435659582242	308.59830896892925	0.001220198820495777	308.97509008873044
9.83001	0.03285188914895561	6.41984	0.25069	0.0013140755659582243	327.74588452368664	0.001313212924296526	328.1765673823826
10.24	0.035503789148955606	6.85154	0.262783	0.0014201515659582242	349.78504723628936	0.0014191441044422949	350.28179501887075
10.65	0.038179589148955605	7.2633	0.27494	0.0015271835659582242	370.8062324078004	0.0015260186070561053	371.3725215920885
11.06	0.04084708914895561	7.6854	0.287331	0.0016338835659582243	392.3552956021242	0.001632550230350468	392.9963584716252
11.47	0.04338948914895561	8.11475	0.299549	0.0017355795659582244	414.274486036815	0.0017340751881366886	414.9934923694783
11.88	0.046160789148955605	8.52841	0.311993	0.0018464315659582242	435.39267007131866	0.001844729006645115	436.19659284092523
12.29	0.04875378914895561	8.97139	0.324459	0.0019501515659582245	458.007699717899	0.0019482524889841513	458.9008841507248
12.71	0.051765589148955606	9.41958	0.337082	0.002070623565958224	480.888710457212	0.0020684827796479646	481.884449953688
13.11	0.05441228914895561	9.84985	0.349487	0.0021764915659582243	502.8548687624045	0.0021741264393534618	503.9493281431669
13.53	0.05708688914895561	10.2825	0.361698	0.0022834755659582244	524.9425309065036	0.002280872397722242	526.1412243493609
13.95	0.05967758914895561	10.6854	0.373608	0.0023871035659582245	545.5113950642697	0.0023842589602537734	546.8135872606985
14.36	0.06246788914895561	11.1171	0.385887	0.0024987155659582246	567.5505577768724	0.002495598966801987	568.9687051900578
14.76	0.06494668914895561	11.5048	0.397785	0.0025978675659582245	587.343431030697	0.002594498940912897	588.8692714802503
15.18	0.06778768914895561	11.9625	0.410736	0.0027115075659582244	610.709946605305	0.0027078380610816343	612.3658912461314
15.59	0.0706421891489556	12.387	0.422867	0.002825687565958224	632.3815346791986	0.002821702815522967	634.1684473186832
16	0.07321958914895561	12.799	0.435352	0.0029287835659582246	653.4149723386666	0.002924503035165529	655.3286833714031
16.4	0.07610398914895561	13.2336	0.44817	0.003044159565958224	675.602185947416	0.0030395354941250216	677.6588268045502
16.81	0.07861738914895561	13.6414	0.460068	0.003144695565958224	696.4212050676372	0.003139761352549977	698.6112377432527
17.21	0.0813710891489556	14.0607	0.472248	0.003254843565958224	717.8273225691296	0.003249558028598258	720.1637382114628
17.62	0.0838453891489556	14.4449	0.483826	0.0033538155659582243	737.441513706915	0.0033482040696484845	739.914756534569
18.02	0.0865836891489556	14.8677	0.496353	0.003463347565958224	759.0263133244466	0.0034573639892674615	761.6550852591971
18.44	0.0894441891489556	15.2941	0.508812	0.0035777675659582242	780.794900261333	0.0035713825803778848	783.5884029311537
18.87	0.09228008914895561	15.7373	0.521885	0.0036912035659582244	803.4211613552072	0.0036844077919983313	806.3867524109678
19.27	0.09463148914895561	16.1189	0.534012	0.0037852595659582243	822.9026172067921	0.003778113498437443	826.0175172104261
19.68	0.0972691891489556	16.5342	0.546566	0.003890767565958224	844.1045265756684	0.003883218105626423	847.3887410899475
20.08	0.0998795891489556	16.91	0.557423	0.003995183565958224	863.2898806349599	0.003987224012969065	866.7388821787307
20.49	0.10254088914895561	17.334	0.570858	0.004101635565958224	884.9359426922765	0.0040932467894463165	888.5656274284179
20.89	0.10508588914895561	17.7338	0.583046	0.004203435565958225	905.346545547265	0.004194625809546827	909.1521114163357
21.3	0.1077528891489556	18.1417	0.595512	0.0043101155659582245	926.1706698708015	0.0043008536216920055	930.1625724917455
21.72	0.1104478891489556	18.5362	0.607384	0.004417915565958224	946.3106969500736	0.0044081852250080055	950.4914177083622
22.13	0.1130848891489556	18.9487	0.6199	0.004523395565958224	967.3696606261184	0.004513195759175865	971.7454562596371
22.54	0.1158858891489556	19.3636	0.632114	0.004635435565958224	988.5511491817334	0.004624725020456701	993.1335143374192
22.94	0.11859888914895561	19.7518	0.644737	0.004743955565958224	1008.3695484521348	0.004732738470365276	1013.1532087840573
23.34	0.12113588914895561	20.1368	0.656548	0.004845435565958224	1028.0245812164435	0.004833734226547066	1033.005808084949
23.75	0.1237518891489556	20.5454	0.669529	0.004950075565958224	1048.8844419631878	0.004937864223370083	1054.0764992108634
24.16	0.12626888914895562	20.9063	0.681683	0.005050755565958225	1067.309120728484	0.005038043286507663	1072.6998382106015
24.57	0.1292188891489556	21.3048	0.694118	0.005168755565958224	1087.6533559403722	0.005155443400756032	1093.2751702777223
24.97	0.1317558891489556	21.6465	0.705921	0.005270235565958225	1105.0978356691105	0.005256396476709784	1110.9219615865172
25.37	0.13525788914895562	21.9888	0.717903	0.0054103155659582245	1122.5729466177415	0.005395732384791015	1128.646420504751
25.78	0.13983388914895561	22.2622	0.730251	0.005593355565958224	1136.5305724820582	0.005577770839651181	1142.8875920855323
26.19	0.1481148891489556	22.3179	0.742725	0.005924595565958224	1139.3741707287388	0.005907114162496113	1146.1245018886054
26.59	0.1611188891489556	22.2231	0.754261	0.006444755565958225	1134.534437985735	0.0064240769271017555	1141.8462351197147
26.99	0.17277988914895562	22.169	0.765869	0.006911195565958225	1131.772522992101	0.006887422723539596	1139.5944242346773
27.4	0.1850658891489556	22.151	0.778038	0.007402635565958224	1130.853586395328	0.007375370532024391	1139.2248833738695
27.81	0.1971258891489556	22.1548	0.790585	0.007885035565958223	1131.0475841213135	0.007854111126852421	1139.9659345489013
28.21	0.2091158891489556	22.1558	0.802788	0.008364635565958223	1131.0986361544674	0.008329845869341882	1140.5598640350518
28.62	0.22123588914895562	22.1617	0.81525	0.008849435565958224	1131.3998431500763	0.008810508795772914	1141.4120931613681
29.02	0.2331508891489556	22.1313	0.82745	0.009326035565958225	1129.8478613421933	0.009282816596236174	1140.3848626811923
29.44	0.24532488914895562	22.1266	0.839958	0.009812995565958224	1129.6079167863693	0.009765160805261085	1140.6927542650653
29.85	0.2574538891489556	22.1038	0.851933	0.010298155565958225	1128.443930430457	0.010245490819830852	1140.0648215734911
30.25	0.2685668891489556	22.1336	0.863949	0.010742675565958225	1129.9652810184477	0.010685382978683646	1142.1041314332258
30.66	0.2794978891489556	22.182	0.876328	0.011179915565958225	1132.4361994231035	0.011117882233336913	1145.0967405164884
31.07	0.28985888914895563	22.2141	0.88826	0.011594355565958225	1134.0749696873484	0.011527656088693695	1147.2238381243567
31.48	0.3009148891489556	22.2407	0.901192	0.012036595565958224	1135.4329537692463	0.011964731837898921	1149.099701026028
31.89	0.3108868891489556	22.2708	0.912449	0.012435475565958224	1136.9696199671832	0.012358790131761608	1151.108377895522
32.3	0.3221178891489556	22.2887	0.925575	0.012884715565958224	1137.8834513606405	0.012802413820830303	1152.544755978633
32.71	0.3322788891489556	22.3189	0.937363	0.013291155565958224	1139.4252227618927	0.013203603087016298	1154.5695006533977
33.11	0.3426198891489556	22.3311	0.949505	0.013704795565958224	1140.048057566372	0.013611734149646787	1155.672183130687
33.52	0.3540088891489556	22.3669	0.962532	0.014160355565958224	1141.8757203532873	0.014061034249714503	1158.0450865656244
33.92	0.3640698891489556	22.3771	0.974194	0.014562795565958225	1142.3964510914584	0.014457776412443094	1159.0329370639795
34.33	0.3746638891489556	22.3887	0.985828	0.014986555565958223	1142.9886546760454	0.01487536665820062	1160.1181176606078
34.74	0.3855458891489556	22.4099	0.998558	0.015421835565958225	1144.0709577789112	0.015304127698166302	1161.714631965566
35.14	0.39604088914895563	22.4246	1.01054	0.015841635565958224	1144.8214226662758	0.015717466501273814	1162.9572664322568
35.54	0.4062228891489556	22.4435	1.02177	0.016248915565958224	1145.7863060928873	0.01611831478554588	1164.4040910372219
35.9501	0.4170218891489556	22.4745	1.03424	0.016680875565958223	1147.3689191206627	0.016543277820063925	1166.5080372887624
36.3601	0.4279408891489556	22.4894	1.04696	0.017117635565958224	1148.1295944146582	0.016972779566990667	1167.7828583943397
36.7601	0.4385068891489556	22.5102	1.05891	0.017540275565958222	1149.1914767042624	0.01738822041703859	1169.3486118837056
37.1601	0.4488498891489556	22.5203	1.07051	0.017953995565958225	1149.707102239118	0.017794726111075406	1170.3489384548698
37.5701	0.4597398891489556	22.5452	1.08219	0.018389595565958223	1150.978297864654	0.018222551757534337	1172.1443232675801
37.9801	0.4708078891489556	22.5626	1.09475	0.018832315565958224	1151.8666032415344	0.01865718286428816	1173.5589186036675
38.3801	0.4812108891489556	22.5688	1.10662	0.019248435565958222	1152.1831258470895	0.019065527828589484	1174.3608485051413
38.7901	0.4916998891489556	22.5979	1.11874	0.019667995565958225	1153.6687400118722	0.019477079768154847	1176.3590916750102
39.1901	0.5022538891489556	22.6	1.13087	0.020090155565958227	1153.7759492814957	0.019891011199970433	1176.9554875908223
39.6001	0.5133918891489556	22.6322	1.14365	0.020535675565958224	1155.4198247490563	0.020327661565051378	1179.1471514125792
40.0101	0.5235398891489557	22.6421	1.15553	0.020941595565958225	1155.9252398772812	0.020725334378841123	1180.1321587552745
40.4101	0.5340468891489556	22.6648	1.16732	0.021361875565958224	1157.0841210298781	0.0211369088699717	1181.8016080426644
40.8201	0.5453428891489556	22.6859	1.18036	0.021813715565958222	1158.1613189294287	0.021579200770214586	1183.42512052005
41.2201	0.5557098891489556	22.6956	1.19191	0.022228395565958223	1158.6565236510228	0.021984945841150915	1184.4115991838157
41.6301	0.5664108891489557	22.7156	1.20456	0.022656435565958227	1159.6775643141038	0.022403590451091887	1185.9517243272737
42.0301	0.5768218891489556	22.7313	1.21614	0.023072875565958224	1160.4790812346223	0.022810721544620407	1187.2546706728463
42.4401	0.5879168891489556	22.7431	1.22891	0.023516675565958222	1161.0814952258402	0.023244418674277744	1188.3862720547038
42.8501	0.5981028891489556	22.7643	1.24041	0.023924115565958224	1162.163798328706	0.023642417978719767	1189.967539346495
43.2501	0.6087708891489556	22.7804	1.25266	0.024350835565958226	1162.9857360624862	0.02405908079631443	1191.3054104868988
43.6501	0.6190128891489556	22.7941	1.26502	0.02476051556595822	1163.6851489166966	0.0244589419412271	1192.4985931603228
44.0601	0.6299708891489556	22.81	1.27787	0.025198835565958224	1164.496876243846	0.024886579695544274	1193.8408415453866
44.4701	0.6407498891489556	22.8359	1.28978	0.025629995565958224	1165.8191239025357	0.025307053603271012	1195.699062878867
44.8801	0.6517008891489556	22.8453	1.30249	0.026068035565958225	1166.299013014184	0.02573405601786508	1196.7021371659798
45.2801	0.6622898891489556	22.861	1.31497	0.026491595565958224	1167.1005299347025	0.026146769977145854	1198.018885158548
45.6801	0.6726078891489556	22.8841	1.32674	0.026904315565958226	1168.279831900561	0.026548757731499954	1199.7116011673584
46.0901	0.6830238891489556	22.8974	1.33911	0.027320955565958226	1168.95882394151	0.026954399713971816	1200.8958960288508
46.5001	0.6941138891489556	22.9164	1.35134	0.02776455556595822	1169.9288125714368	0.027386109250618164	1202.4113660962919
46.9001	0.7047118891489557	22.926	1.36339	0.028188475565958226	1170.4189120897156	0.027798492218116477	1203.411236995092
47.3001	0.7154378891489556	22.9423	1.37561	0.02861751556595822	1171.2510602301265	0.028215682763138832	1204.7693556779072
47.7101	0.7257138891489556	22.9508	1.38675	0.029028555565958226	1171.685002511936	0.028615207259828697	1205.6973257131538
48.1201	0.7363858891489556	22.961	1.39965	0.029455435565958227	1172.2057332501074	0.02902995909463367	1206.7335636959028
48.5201	0.7469368891489556	22.9895	1.41223	0.029877475565958225	1173.6607161949978	0.029439839404541184	1208.726735565839
48.9301	0.7577428891489556	22.9963	1.42407	0.030309715565958226	1174.0078700204454	0.029859451766177686	1209.5917146329614
49.3301	0.7682088891489556	23.0193	1.43581	0.030728355565958224	1175.1820667829886	0.030265693661095865	1211.293479185834
49.7401	0.7791808891489556	23.043	1.44887	0.031167235565958223	1176.3919999687394	0.030691399025145838	1213.056886549674
50.1501	0.7897768891489556	23.0469	1.46067	0.03159107556595822	1176.5911028980402	0.03110234392710304	1213.7608813399263
50.5801	0.8016758891489556	23.0641	1.47404	0.032067035565958225	1177.4691978682897	0.031563621893518065	1215.2271445141525
50.9901	0.8118668891489557	23.073	1.48599	0.032474675565958226	1177.9235609633608	0.0319585182553589	1216.1762464471442
51.3901	0.8223858891489556	23.0898	1.49832	0.032895435565958225	1178.7812351203488	0.0323659609733039	1217.557757286611
51.8101	0.8333598891489556	23.1074	1.51089	0.03333439556595823	1179.67975090386	0.03279085078951882	1219.0036623616402
52.2301	0.8443048891489556	23.1008	1.52304	0.03377219556595822	1179.3428074850433	0.03321443804759667	1219.1718034187345
52.6601	0.8558918891489556	23.1285	1.53642	0.034235675565958225	1180.7569488034105	0.0336626761942982	1221.1809606248949
53.0601	0.8665238891489556	23.1318	1.54846	0.034660955565958225	1180.9254205128188	0.034073793888232756	1221.8574240399244
53.4701	0.8772838891489556	23.1501	1.56061	0.03509135556595822	1181.859672719538	0.034489689069399025	1223.3327307240063
53.8701	0.8877608891489556	23.1601	1.57237	0.035510435565958225	1182.3701930510783	0.03489447960664007	1224.3566736065281
54.2801	0.8988398891489556	23.1856	1.58537	0.03595359556595822	1183.6720198965068	0.03532235090935235	1226.2292849826067
54.6801	0.9094908891489556	23.1886	1.59759	0.036379635565958225	1183.825175995969	0.035733520309719026	1226.8923044725086
55.0901	0.9202858891489556	23.1967	1.60941	0.03681143556595822	1184.2386974645167	0.036150076229003306	1227.832223970946
55.5001	0.9317488891489556	23.2124	1.62281	0.037269955565958225	1185.040214385035	0.03659221896209968	1229.2066105190386
55.9001	0.9424068891489557	23.2258	1.63472	0.037696275565958226	1185.7243116292993	0.03700313649859021	1230.4217020257336
56.3101	0.9525928891489556	23.2215	1.64646	0.03810371556595822	1185.504787886737	0.03739569840915293	1230.6769251264548
56.7201	0.9638328891489556	23.2397	1.65941	0.03855331556595822	1186.4339348901408	0.03782870203015017	1232.174896780122
57.1201	0.9747048891489556	23.253	1.6707	0.03898819556595822	1187.1129269310895	0.038247350710834814	1233.396317885156
57.5201	0.9853448891489556	23.2478	1.68311	0.039413795565958226	1186.8474563586885	0.03865689612867477	1233.6256193715874
57.9301	0.9960998891489556	23.2731	1.69513	0.039843995565958225	1188.1390727974858	0.0390706976380148	1235.4792807457704
58.3401	1.0077958891489556	23.2618	1.70766	0.04031183556595822	1187.562184822845	0.03952051010002986	1235.4349963417735
58.7401	1.0182758891489554	23.2856	1.71953	0.04073103556595822	1188.7772232119114	0.039923385034982085	1237.1973505705569
59.1601	1.0296358891489554	23.3043	1.73317	0.04118543556595822	1189.7318962318923	0.04035990591707917	1238.731522584916
59.5701	1.0399258891489556	23.3011	1.7444	0.04159703556595822	1189.5685297257994	0.040755146429291234	1239.0510541649483
59.9801	1.0515858891489556	23.3105	1.75701	0.04206343556595822	1190.0484188374473	0.04120282014029257	1240.1059438235866
60.3801	1.0625858891489555	23.3214	1.76934	0.04250343556595822	1190.6048859988264	0.04162497019230358	1241.2096840553925
60.7801	1.0734958891489554	23.332	1.78165	0.04293983556595822	1191.1460375502593	0.042043490333715246	1242.2936525377102
61.1901	1.0851558891489554	23.3509	1.79424	0.04340623556595822	1192.1109209768708	0.042490587787222686	1243.8559684335441
61.5901	1.0951558891489555	23.336	1.80483	0.04380623556595822	1191.3502456828755	0.04287387411808693	1243.538815186822
62.0001	1.1064958891489556	23.3493	1.81785	0.04425983556595822	1192.0292377238243	0.04330834313552497	1244.7882557752953
62.4201	1.1179358891489555	23.3628	1.83025	0.04471743556595822	1192.718440171404	0.04374645226542604	1246.053750168099
62.8301	1.1288358891489556	23.3712	1.84216	0.04515343556595822	1193.147277249898	0.04416370293133852	1247.0219759538998
63.2301	1.1400158891489556	23.379	1.8542	0.045600635565958225	1193.5454831084996	0.04459149117577587	1247.9719157151258
63.6401	1.1514958891489555	23.3799	1.86766	0.04605983556595822	1193.5914299383383	0.04503056818059108	1248.568054934235
64.0401	1.1623758891489555	23.3882	1.87928	0.04649503556595822	1194.015161813517	0.04544651904742701	1249.5309392283295
64.4701	1.1740058891489555	23.3885	1.89177	0.04696023556595822	1194.030477423463	0.04589095176502287	1250.1024299162023
64.8701	1.1853458891489554	23.3983	1.90415	0.04741383556595822	1194.5307873483728	0.0463241122145763	1251.168073678183
65.2801	1.1965558891489554	23.3919	1.91628	0.047862235565958214	1194.2040543361868	0.0467521226453002	1251.3613300986476
65.7001	1.2084358891489555	23.4061	1.92892	0.04833743556595822	1194.9289932069742	0.047205514576121245	1252.6887964220116
66.1101	1.2198558891489555	23.419	1.94131	0.048794235565958216	1195.5875644346615	0.04764115723367354	1253.9253456934168
66.5101	1.2310658891489554	23.425	1.95411	0.04924263556595822	1195.893876633586	0.04806860444682514	1254.7828429762146
66.9201	1.2421858891489554	23.4238	1.96575	0.04968743556595822	1195.832614193801	0.04849243944044982	1255.2504701592268
67.3201	1.2533358891489554	23.4408	1.97775	0.050133435565958215	1196.7004987574198	0.048917237586652056	1256.695206103625
67.7301	1.2648658891489555	23.4272	1.98983	0.05059463556595822	1196.0061911065247	0.04935632345763891	1256.517688480189
68.1401	1.2767558891489554	23.4423	2.00313	0.051070235565958216	1196.777076807151	0.049808917032048816	1257.896764039631
68.5401	1.2874658891489554	23.4334	2.01431	0.05149863556595822	1196.3227137120798	0.050216418552507934	1257.9317011648163
68.9401	1.2988758891489556	23.4492	2.0264	0.05195503556595822	1197.129335835914	0.05065037154460467	1259.3262330563207
69.3501	1.3107058891489556	23.438	2.03873	0.05242823556595822	1196.5575530645885	0.05110009951428306	1259.2909543248854
69.7601	1.3217358891489555	23.4449	2.05085	0.05286943556595822	1196.9098120933515	0.051519232649239424	1260.189758282084
70.1701	1.3338658891489554	23.4554	2.06398	0.053354635565958215	1197.445858441469	0.05197996236478395	1261.3351458285795
70.6001	1.3457658891489555	23.4552	2.07609	0.05383063556595822	1197.435648034838	0.052431749888754896	1261.8943700178884
71.0001	1.3570858891489554	23.4521	2.08831	0.054283435565958216	1197.2773867320607	0.05286132816742957	1262.2697166093094
71.4101	1.3689558891489555	23.4552	2.10063	0.05475823556595822	1197.435648034838	0.053311580065739654	1263.0051113250056
71.8201	1.3805458891489555	23.4558	2.11331	0.05522183556595822	1197.4662792547306	0.05375101550288247	1263.592565223515
72.2201	1.3921158891489556	23.4705	2.12479	0.05568463556595822	1198.216744142095	0.05418950011955711	1264.9390068686764
72.6301	1.4039158891489556	23.4524	2.13767	0.05615663556595822	1197.2927023420068	0.05463650341882147	1264.5286322932081
73.0301	1.4154358891489556	23.4709	2.14899	0.056617435565958225	1198.2371649553568	0.05507270718864508	1266.0782804349533
73.4401	1.4270858891489555	23.4586	2.16148	0.05708343556595822	1197.6092249475619	0.055513639975222726	1265.972873973053
73.8401	1.4382558891489554	23.4639	2.17326	0.05753023556595822	1197.8798007232783	0.055936223081298836	1266.7941078385916
74.2501	1.4507458891489555	23.4727	2.18615	0.05802983556595822	1198.329058615034	0.05640853300632051	1267.867896840374
74.6501	1.4620858891489554	23.4463	2.19737	0.05848343556595822	1196.981284939767	0.056837162501000786	1266.9848627911997
75.0601	1.4739258891489555	23.4502	2.20949	0.05895703556595822	1197.1803878690678	0.05728449503700774	1267.7625945755321
75.4601	1.4853258891489556	23.4608	2.22134	0.05941303556595822	1197.7215394205007	0.05771501472122829	1268.881811840205
75.8701	1.4976958891489556	23.4733	2.23483	0.059907835565958224	1198.3596898349263	nan	nan
76.2801	1.5095658891489554	23.4585	2.24682	0.060382635565958215	1197.6041197442464	nan	nan
76.6801	1.5213058891489555	23.4604	2.25923	0.06085223556595822	1197.7011186072393	nan	nan
77.0901	1.5338158891489555	23.452	2.27234	0.06135263556595822	1197.2722815287452	nan	nan
77.4901	1.5453058891489555	23.4478	2.28442	0.06181223556595822	1197.057862989498	nan	nan
77.9001	1.5571458891489556	23.4569	2.29604	0.06228583556595822	1197.5224364912	nan	nan
78.3101	1.5695058891489555	23.4492	2.3085	0.06278023556595821	1197.129335835914	nan	nan
78.7101	1.5812558891489554	23.442	2.32096	0.06325023556595821	1196.7617611972046	nan	nan
79.1101	1.5933258891489555	23.4464	2.33327	0.06373303556595822	1196.9863901430826	nan	nan
79.5201	1.6052858891489554	23.44	2.34514	0.06421143556595822	1196.6596571308967	nan	nan
79.9301	1.6177258891489554	23.4312	2.35779	0.06470903556595822	1196.210399239141	nan	nan
80.3301	1.6299058891489555	23.4294	2.37048	0.06519623556595822	1196.1185055794638	nan	nan
80.7401	1.6419058891489555	23.4256	2.38261	0.06567623556595822	1195.9245078534782	nan	nan
81.1401	1.6539658891489555	23.4302	2.39487	0.06615863556595822	1196.159347205987	nan	nan
81.5601	1.6667658891489554	23.4141	2.40746	0.06667063556595822	1195.337409472207	nan	nan
81.9701	1.6793358891489556	23.4049	2.41968	0.06717343556595823	1194.8677307671896	nan	nan
82.3701	1.6912658891489556	23.404	2.43178	0.06765063556595823	1194.8217839373508	nan	nan
82.8101	1.7049858891489555	23.3962	2.44555	0.06819943556595823	1194.4235780787492	nan	nan
83.2201	1.7168158891489556	23.3903	2.4572	0.06867263556595822	1194.1223710831403	nan	nan
83.6201	1.7291658891489554	23.3872	2.46964	0.06916663556595821	1193.9641097803628	nan	nan
84.0301	1.7427758891489555	23.3869	2.48319	0.06971103556595822	1193.9487941704167	nan	nan
84.4401	1.7549258891489554	23.3637	2.49467	0.07019703556595822	1192.7643870012428	nan	nan
84.8401	1.7669158891489556	23.3473	2.50629	0.07067663556595823	1191.9271336575162	nan	nan
85.2501	1.7798658891489556	23.3422	2.51888	0.07119463556595823	1191.6667682884304	nan	nan
85.6501	1.7920658891489556	23.316	2.53063	0.07168263556595822	1190.3292050197945	nan	nan
86.0601	1.8050058891489555	23.3247	2.54333	0.07220023556595823	1190.7733577082347	nan	nan
86.4601	1.8178258891489556	23.3015	2.55513	0.07271303556595822	1189.5889505390608	nan	nan
86.8701	1.8307358891489556	23.2876	2.56756	0.07322943556595822	1188.8793272782198	nan	nan
87.2801	1.8433958891489555	23.2743	2.57942	0.07373583556595822	1188.2003352372708	nan	nan
87.6801	1.8559058891489555	23.2485	2.59143	0.07423623556595822	1186.8831927818962	nan	nan
88.0901	1.8694058891489556	23.2513	2.60505	0.07477623556595822	1187.0261384747275	nan	nan
88.4901	1.8815658891489555	23.2004	2.61604	0.07526263556595822	1184.4275899871864	nan	nan
88.9001	1.8946358891489554	23.1922	2.62814	0.07578543556595822	1184.0089633153234	nan	nan
89.3001	1.9070858891489555	23.1744	2.63998	0.07628343556595822	1183.1002371251811	nan	nan
89.7201	1.9207458891489555	23.155	2.65287	0.07682983556595822	1182.1098276819928	nan	nan
90.1301	1.9345358891489555	23.1247	2.66536	0.07738143556595822	1180.5629510774252	nan	nan
90.5301	1.9471858891489555	23.0935	2.67705	0.07788743556595822	1178.9701276430187	nan	nan
90.9401	1.9599858891489554	23.0741	2.68894	0.07839943556595821	1177.9797181998304	nan	nan
91.3401	1.9729458891489555	23.0352	2.701	0.07891783556595822	1175.9937941101377	nan	nan
91.7501	1.9867458891489556	23.0139	2.71335	0.07946983556595823	1174.9063858039565	nan	nan
92.1601	1.9993258891489556	22.9825	2.72477	0.07997303556595822	1173.3033519629194	nan	nan
92.5601	2.0126258891489557	22.9535	2.73798	0.08050503556595823	1171.822843001452	nan	nan
92.9801	2.0258958891489556	22.9184	2.75004	0.08103583556595823	1170.0309166377447	nan	nan
93.3901	2.0396958891489554	22.8867	2.76286	0.08158783556595822	1168.4125671867616	nan	nan
93.8001	2.0527158891489554	22.8489	2.77469	0.08210863556595821	1166.4828003335385	nan	nan
94.2001	2.0658858891489555	22.8279	2.78702	0.08263543556595822	1165.4107076373036	nan	nan
94.6001	2.0786058891489554	22.784	2.79852	0.08314423556595822	1163.1695233818407	nan	nan
95.0101	2.0924158891489557	22.7606	2.81097	0.08369663556595823	1161.9749058060358	nan	nan
95.4201	2.1056658891489555	22.7244	2.82343	0.08422663556595822	1160.1268222058593	nan	nan
95.8301	2.1194658891489553	22.6803	2.83554	0.08477863556595822	1157.875427543766	nan	nan
96.2301	2.1324058891489557	22.6423	2.84703	0.08529623556595822	1155.9354502839121	nan	nan
96.6401	2.1451158891489555	22.6142	2.85918	0.08580463556595821	1154.5008881522833	nan	nan
97.0401	2.1583258891489554	22.5727	2.87143	0.08633303556595821	1152.3822287763903	nan	nan
97.4401	2.1715358891489553	22.5422	2.88361	0.08686143556595821	1150.8251417651918	nan	nan
97.8601	2.1850158891489553	22.4978	2.89543	0.08740063556595822	1148.5584314931523	nan	nan
98.2701	2.1979858891489554	22.457	2.90728	0.08791943556595821	1146.475508540467	nan	nan
98.6801	2.2108458891489553	22.4269	2.91927	0.08843383556595821	1144.93884234253	nan	nan
99.0801	2.2238658891489553	22.391	2.93174	0.08895463556595821	1143.1060743522996	nan	nan
99.4901	2.2374658891489556	22.3476	2.94395	0.08949863556595822	1140.890416113414	nan	nan
99.8901	2.2504958891489557	22.3011	2.95558	0.09001983556595823	1138.5164965717508	nan	nan
100.32	2.2642258891489555	22.2721	2.96906	0.09056903556595822	1137.0359876102832	nan	nan
100.72	2.2772158891489553	22.2412	2.98079	0.09108863556595821	1135.4584797858233	nan	nan
101.14	2.2907358891489555	22.1948	2.99313	0.09162943556595822	1133.0896654474755	nan	nan
101.55	2.3043758891489556	22.1593	3.00642	0.09217503556595823	1131.2773182705068	nan	nan
101.95	2.3176758891489553	22.1322	3.01857	0.09270703556595822	1129.893808172032	nan	nan
102.36	2.3302958891489554	22.0811	3.03035	0.09321183556595822	1127.28504927786	nan	nan
102.77	2.3439358891489555	22.0488	3.0431	0.09375743556595822	1125.6360686069843	nan	nan
103.18	2.3573158891489556	22.0106	3.05548	0.09429263556595822	1123.6858809404996	nan	nan
103.59	2.3710058891489556	21.9561	3.06757	0.09484023556595822	1120.903545133604	nan	nan
104	2.3836658891489555	21.9168	3.07961	0.09534663556595822	1118.8972002306498	nan	nan
104.4	2.3968658891489554	21.8762	3.09183	0.09587463556595821	1116.8244876845956	nan	nan
104.82	2.4107358891489556	21.8325	3.10514	0.09642943556595823	1114.5935138357636	nan	nan
105.23	2.4240558891489554	21.8045	3.11757	0.09696223556595822	1113.1640569074502	nan	nan
105.64	2.4371758891489557	21.754	3.12947	0.09748703556595822	1110.5859292331709	nan	nan
106.05	2.4504558891489556	21.7212	3.1417	0.09801823556595822	1108.911422545718	nan	nan
106.46	2.4643058891489553	21.6842	3.15493	0.09857223556595822	1107.0224973190182	nan	nan
106.87	2.4774758891489554	21.6353	3.16677	0.09909903556595821	1104.5260528977851	nan	nan
107.28	2.4910558891489556	21.5833	3.17896	0.09964223556595822	1101.871347173775	nan	nan
107.68	2.5042258891489553	21.5508	3.19136	0.10016903556595821	1100.212156096268	nan	nan
108.08	2.5168058891489555	21.5108	3.20333	0.10067223556595822	1098.170074770106	nan	nan
108.49	2.5307058891489556	21.4762	3.21598	0.10122823556595822	1096.4036744229759	nan	nan
108.9	2.5428458891489556	21.4166	3.2269	0.10171383556595823	1093.3609732469947	nan	nan
109.3	2.5567058891489554	21.3843	3.24035	0.10226823556595821	1091.711992576119	nan	nan
109.71	2.5698958891489556	21.3456	3.2521	0.10279583556595823	1089.7362788930575	nan	nan
110.11	2.5829258891489557	21.3088	3.26415	0.10331703556595823	1087.8575640729887	nan	nan
110.52	2.5969158891489554	21.2531	3.27676	0.10387663556595822	1085.0139658263079	nan	nan
110.92	2.6096858891489556	21.2129	3.2882	0.10438743556595823	1082.9616740935153	nan	nan
111.33	2.6228758891489554	21.1759	3.30042	0.10491503556595821	1081.0727488668153	nan	nan
111.73	2.6356658891489553	21.1256	3.31195	0.10542663556595822	1078.5048315991667	nan	nan
112.14	2.6493358891489556	21.0685	3.32441	0.10597343556595823	1075.5897605060707	nan	nan
112.55	2.6623358891489555	21.0404	3.33678	0.10649343556595822	1074.1551983744419	nan	nan
112.98	2.6773858891489555	20.9844	3.35063	0.10709543556595821	1071.2962845178151	nan	nan
113.39	2.6903458891489556	20.961	3.36254	0.10761383556595822	1070.1016669420103	nan	nan
113.8	2.7041358891489553	20.897	3.37498	0.10816543556595822	1066.8343368201513	nan	nan
114.2	2.7171058891489555	20.856	3.3869	0.10868423556595821	1064.7412034608353	nan	nan
114.6	2.7298758891489556	20.817	3.39887	0.10919503556595822	1062.7501741678275	nan	nan
115.01	2.7430158891489556	20.7743	3.41101	0.10972063556595822	1060.5702523521495	nan	nan
115.42	2.7571658891489554	20.7306	3.42392	0.11028663556595822	1058.3392785033175	nan	nan
115.83	2.7701758891489554	20.6736	3.43551	0.11080703556595822	1055.429312613537	nan	nan
116.23	2.7835958891489554	20.6409	3.44772	0.11134383556595821	1053.7599111293994	nan	nan
116.63	2.7964158891489554	20.5959	3.45963	0.11185663556595822	1051.4625696374674	nan	nan
117.04	2.8099758891489555	20.5452	3.47266	0.11239903556595822	1048.874231556557	nan	nan
117.45	2.8236358891489557	20.4974	3.4846	0.11294543556595822	1046.4339443717934	nan	nan
117.85	2.8369958891489553	20.4428	3.49642	0.11347983556595821	1043.6465033615823	nan	nan
118.25	2.8499258891489556	20.3931	3.50867	0.11399703556595822	1041.1092173138263	nan	nan
118.66	2.8639858891489554	20.3555	3.52115	0.11455943556595821	1039.189660867234	nan	nan
119.07	2.8765358891489554	20.3067	3.53268	0.11506143556595821	1036.6983216493165	nan	nan
119.47	2.8898358891489555	20.2698	3.5446	0.11559343556595822	1034.814501625932	nan	nan
119.88	2.9041258891489554	20.2256	3.55801	0.11616503556595821	1032.558001760523	nan	nan
120.28	2.9173658891489556	20.1771	3.57041	0.11669463556595822	1030.0819781525518	nan	nan
120.69	2.9304158891489553	20.111	3.58176	0.11721663556595821	1026.7074387610692	nan	nan
121.09	2.9438158891489556	20.0744	3.5941	0.11775263556595822	1024.838934347631	nan	nan
121.5	2.9572858891489555	20.0185	3.60657	0.11829143556595823	1021.9851256943197	nan	nan
121.91	2.9703958891489557	19.9743	3.61835	0.11881583556595823	1019.7286258289107	nan	nan
122.31	2.9838558891489555	19.9258	3.63004	0.11935423556595821	1017.2526022209394	nan	nan
122.72	2.9980258891489555	19.8761	3.64317	0.11992103556595822	1014.7153161731833	nan	nan
123.12	3.0110058891489553	19.8191	3.65472	0.12044023556595822	1011.8053502834023	nan	nan
123.53	3.0239558891489553	19.7653	3.66642	0.12095823556595821	1009.0587508997146	nan	nan
123.94	3.0378458891489557	19.7057	3.67888	0.12151383556595823	1006.0160497237333	nan	nan
124.34	3.0511358891489553	19.6722	3.69091	0.1220454355659582	1004.3058066130727	nan	nan
124.74	3.0646958891489553	19.6083	3.70339	0.12258783556595822	1001.0435816945289	nan	nan
125.15	3.0781058891489557	19.5701	3.71502	0.12312423556595822	999.0933940280443	nan	nan
125.56	3.0921758891489555	19.5198	3.72804	0.12368703556595823	996.5254767603957	nan	nan
125.97	3.1054658891489555	19.4591	3.74081	0.12421863556595822	993.4266183479449	nan	nan
126.37	3.1186958891489556	19.4041	3.75207	0.12474783556595823	990.6187565244722	nan	nan
126.77	3.1319258891489556	19.3513	3.76414	0.12527703556595823	987.9232091739385	nan	nan
127.18	3.1461758891489553	19.3047	3.77749	0.12584703556595822	985.5441844289599	nan	nan
127.59	3.1594658891489553	19.249	3.78897	0.12637863556595821	982.7005861822794	nan	nan
127.99	3.1727558891489553	19.1974	3.80066	0.1269102355659582	980.0663012715304	nan	nan
128.39	3.1861358891489555	19.1443	3.81278	0.12744543556595822	977.3554383110506	nan	nan
128.8	3.1999458891489554	19.0753	3.825	0.12799783556595823	973.8328480234211	nan	nan
129.2	3.2132358891489554	19.0184	3.8375	0.12852943556595822	970.9279873369559	nan	nan
129.61	3.2260958891489553	18.9774	3.84936	0.12904383556595822	968.8348539776397	nan	nan
130.02	3.2405058891489555	18.9054	3.86198	0.12962023556595823	965.1591075905484	nan	nan
130.42	3.2540558891489555	18.8534	3.87388	0.1301622355659582	962.5044018665378	nan	nan
130.83	3.2676358891489556	18.8104	3.88636	0.13070543556595823	960.3091644409137	nan	nan
131.24	3.2818458891489555	18.7339	3.89847	0.13127383556595823	956.4036839046289	nan	nan
131.64	3.2954858891489556	18.6882	3.91087	0.1318194355659582	954.0706059894889	nan	nan
132.05	3.3086558891489557	18.6143	3.92228	0.13234623556595823	950.2978607394048	nan	nan
132.45	3.3224758891489556	18.5702	3.93491	0.13289903556595822	948.0464660773113	nan	nan
132.87	3.3358558891489554	18.4955	3.94699	0.1334342355659582	944.2328792007038	nan	nan
133.29	3.3497458891489553	18.4397	3.95842	0.13398983556595823	941.3841757507078	nan	nan
133.72	3.3643958891489554	18.3738	3.97276	0.1345758355659582	938.0198467658561	nan	nan
134.12	3.3786158891489553	18.3185	3.98467	0.1351446355659582	935.1966693324372	nan	nan
134.53	3.3921558891489556	18.2565	3.99683	0.1356862355659582	932.0314432768862	nan	nan
134.93	3.4053458891489554	18.1966	4.00871	0.13621383556595823	928.9734264909587	nan	nan
135.35	3.4198658891489555	18.1381	4.02122	0.13679463556595822	925.986882551447	nan	nan
135.76	3.4343158891489556	18.0638	4.03381	0.13737263556595822	922.193716488101	nan	nan
136.17	3.4475058891489554	17.9976	4.04505	0.1379002355659582	918.814071893303	nan	nan
136.57	3.4610958891489556	17.9495	4.05731	0.1384438355659582	916.3584690985933	nan	nan
136.97	3.4742158891489554	17.877	4.06962	0.1389686355659582	912.6571966949248	nan	nan
137.38	3.4885258891489555	17.8264	4.08171	0.1395410355659582	910.0739638173299	nan	nan
137.79	3.5024558891489557	17.742	4.09425	0.14009823556595824	905.7651722191283	nan	nan
138.19	3.5160958891489553	17.6712	4.10626	0.14064383556595822	902.1506882718215	nan	nan
138.61	3.5293658891489557	17.6196	4.11792	0.14117463556595822	899.5164033610727	nan	nan
139.02	3.5445658891489553	17.5543	4.13116	0.14178263556595821	896.1827055961136	nan	nan
139.43	3.5578158891489555	17.4723	4.14218	0.14231263556595822	891.9964388774814	nan	nan
139.83	3.5715758891489555	17.4238	4.15488	0.14286303556595822	889.5204152695101	nan	nan
140.23	3.5853058891489553	17.3442	4.16676	0.14341223556595822	885.4566734304478	nan	nan
140.64	3.5998258891489554	17.2774	4.17908	0.14399303556595822	882.0463976157574	nan	nan
141.05	3.6130958891489553	17.1938	4.19039	0.14452383556595821	877.7784476440788	nan	nan
141.46	3.6278258891489554	17.1427	4.20396	0.14511303556595823	875.1696887499071	nan	nan
141.86	3.6411258891489555	17.0626	4.21503	0.14564503556595823	871.0804208942676	nan	nan
142.26	3.6548058891489554	17.0012	4.22717	0.14619223556595823	867.9458260586092	nan	nan
142.67	3.6693758891489554	16.9056	4.23901	0.14677503556595822	863.0652516890821	nan	nan
143.07	3.6828758891489555	16.8473	4.25087	0.1473150355659582	860.0889181562011	nan	nan
143.51	3.6975458891489557	16.7647	4.26379	0.14790183556595823	855.8720202176768	nan	nan
143.92	3.7121158891489556	16.7098	4.27646	0.14848463556595823	853.0692635975196	nan	nan
144.32	3.7259058891489554	16.6089	4.28837	0.1490362355659582	847.9181134522759	nan	nan
144.73	3.7394358891489556	16.5523	4.29993	0.14957743556595823	845.0285683757568	nan	nan
145.13	3.7541558891489557	16.4709	4.31253	0.15016623556595823	840.8729328770173	nan	nan
145.55	3.7687758891489556	16.362	4.32493	0.15075103556595823	835.3133664665413	nan	nan