File: original_data/46NTBH.csv
Specimen name:	AWA_4_13_Rz
Specimen ID:	46NTBH
Material:	42CrMoS4
Specimen type:	Round Tensile Specimen
Gauge diameter:	5.005	mm
Gauge length:	25	mm
Parallel length:	30	mm
Original cross-section:	19.674243628060164	mm²
Cross-section after fracture:	13.070847759022167	mm²
Yield stress at 0.2% plastic strain:	1075.9075047747729	MPa
Yield stress at 1% plastic strain:	1143.675486620504	MPa
Ultimate tensile strength:	1195.7765922165522	MPa
Uniform elongation:	4.794188359048303	%
Elongation after fracture:	11.811540988099626	%
Reduction of area:	33.56365812010165	%
Slope of linear-elastic region:	208673.5486602951	MPa
Crosshead seperation speed:	0.029960657216012175	mm/s
Strain rate:	0.0009986885738670725	s-1
Test temperature:	RT	Cel
Machine type:	INSTRON 8852TT
Standard:	DIN EN ISO 6892-1
Date:	2022-09-13 00:00:00
Heat treatment batch:	Batch 4
Time	Displacement	Force	Machine Displacement	Engineering Strain	Engineering Stress	True Strain	True Stress
s	mm	kN	mm		MPa		MPa
0	0.000996456289763693	0.164678	0	3.985825159054772e-05	8.37023283401502	3.985745727158221e-05	8.37056645686119
0.450001	0.000983884589763693	0.162954	-0.000320435	3.935538359054772e-05	8.282605577151068	3.9354609187664976e-05	8.282931542270685
0.860001	0.001073905589763693	0.195569	0.0015564	4.2956223590547715e-05	9.94035672716139	4.2955300998476934e-05	9.940783727347533
1.28	0.002303716289763693	0.405075	0.0135574	9.214865159054773e-05	20.58910155114001	9.214440616438327e-05	20.59099880908541
1.7	0.003674676289763693	0.656122	0.0269623	0.00014698705159054773	33.34928713926331	0.00014697625005221838	33.35418905265255
2.12	0.005230506289763692	0.925611	0.039917	0.0002092202515905477	47.046840402029886	0.00020919836808607102	47.05668355381535
2.54	0.006777406289763693	1.2017	0.0523376	0.00027109625159054773	61.07985764118978	0.0002710595116416863	61.096416161643994
2.95	0.008450476289763692	1.48762	0.0644608	0.0003380190515905477	75.61256372155009	0.00033796193602126236	75.63812220862758
3.36	0.010219826289763694	1.79329	0.0772705	0.00040879305159054777	91.1491203373298	0.0004087095184754652	91.1863814643823
3.77001	0.012097156289763693	2.09968	0.0894928	0.00048388625159054776	106.72227302326152	0.00048376921639129203	106.77391446391597
4.18001	0.013785456289763694	2.41006	0.101486	0.0005514182515905478	122.49822893128555	0.0005512662764117058	122.56577669050577
4.59001	0.01592695628976369	2.73305	0.112785	0.0006370782515905477	138.9151243457217	0.0006368754033900934	139.00362415025936
5.00001	0.017920156289763692	3.10772	0.126366	0.0007168062515905477	157.95880435106793	0.0007165494686911121	158.07203020952053
5.40001	0.02008015628976369	3.45084	0.137741	0.0008032062515905477	175.39886489350363	0.0008028838540722034	175.53974635830798
5.81001	0.02214415628976369	3.81034	0.149277	0.0008857662515905476	193.6714860318974	0.0008853741921626778	193.84303369811985
6.21001	0.024327556289763692	4.17221	0.161034	0.0009731022515905477	212.0645692345414	0.0009726290945232085	212.27092974434615
6.62001	0.02673825628976369	4.57134	0.173447	0.0010695302515905476	232.3514990675514	0.0010689587115943321	232.6000060248066
7.02001	0.028941956289763694	4.94345	0.185509	0.0011576782515905477	251.2650597123572	0.0011570086588555584	251.5559438073708
7.43001	0.03135965628976369	5.32558	0.197647	0.0012543862515905476	270.68791566677834	0.001253600166457407	271.02746286666246
7.84001	0.03373745628976369	5.73639	0.210037	0.0013494982515905476	291.568515082254	0.001348588497207607	291.9619862835763
8.26001	0.03630655628976369	6.13905	0.223358	0.0014522622515905476	312.0348673147592	0.0014512087386281483	312.48802377374045
8.67001	0.03868875628976369	6.53241	0.235054	0.0015475502515905476	332.02852030780105	0.001546354029683196	332.5423511279386
9.07001	0.04111495628976369	6.9392	0.247276	0.0016445982515905478	352.7047916649281	0.001643247380776281	353.28484934862786
9.49001	0.04369805628976369	7.3364	0.259407	0.0017479222515905477	372.8936236987807	0.0017463964132642198	373.54541276112
9.90001	0.04614495628976369	7.76347	0.272148	0.0018457982515905477	394.600684365189	0.0018440968592939274	395.32903761846666
10.3	0.048439556289763694	8.15116	0.283699	0.0019375822515905479	414.3061433057839	0.0019357075602882015	415.1088955357781
10.71	0.050911056289763695	8.54148	0.295456	0.0020364422515905477	434.145279558184	0.002034371513883847	435.0293913488049
11.12	0.05363145628976369	8.96902	0.309555	0.0021452582515905476	455.8762293259416	0.0021429604707430155	456.8542015686071
11.52	0.055805156289763694	9.34189	0.320915	0.002232206251590548	474.8284191559078	0.0022297185805244526	475.88833412158044
11.92	0.058120756289763695	9.7332	0.33345	0.002324830251590548	494.71787500476694	0.002322132014893566	495.8680100865806
12.34	0.06087845628976369	10.1481	0.345406	0.0024351382515905478	515.806360429856	0.002432178107038636	517.0624202285525
12.75	0.0630709562897637	10.5366	0.357979	0.0025228382515905478	535.552989949372	0.002519661237441999	536.9041035181699
13.15	0.06558035628976369	10.9504	0.369843	0.0026232142515905475	556.5855647117288	0.002619779630272836	558.0456078973102
13.58	0.06828825628976369	11.3693	0.382561	0.0027315302515905477	577.8773616376625	0.002727806402495735	579.455851132685
13.99	0.07058725628976369	11.7618	0.394951	0.0028234902515905476	597.8273026580227	0.0028195116901835065	599.5152622192123
14.4	0.0730783562897637	12.1743	0.407639	0.002923134251590548	618.7938011826053	0.0029188702022355678	620.6026185375141
14.81	0.07556895628976369	12.5524	0.419266	0.003022758251590548	638.0118207999255	0.0030181989034275577	639.9403762958608
15.21	0.0779372562897637	12.945	0.430794	0.003117490251590548	657.966844607807	0.0031126409546660787	660.0180498317417
15.64	0.08049095628976369	13.3916	0.445465	0.0032196382515905474	680.6665736770884	0.003214466314559155	682.8580738142782
16.04	0.08303525628976369	13.7921	0.457878	0.0033214102515905473	701.0231376991376	0.003315906551890203	703.3515231352937
16.46	0.08547795628976369	14.1848	0.469749	0.0034191182515905475	720.98324429454	0.0034132863562937807	723.4483712641984
16.88	0.0880734562897637	14.6008	0.482277	0.0035229382515905476	742.1276403823614	0.0035167472407334308	744.742110234227
17.3	0.09065225628976369	15.0035	0.494957	0.0036260902515905472	762.5960257298751	0.0036195318358243547	765.361267744676
17.72	0.09307805628976369	15.4253	0.507462	0.0037231222515905476	784.0352234939209	0.003716208586906018	786.9542824805418
18.13	0.0955221562897637	15.8225	0.519508	0.0038208862515905478	804.2240555277734	0.0038136052065199716	807.2969041647378
18.54	0.0980597562897637	16.2285	0.532158	0.003922390251590548	824.8601728634837	0.003914717735471732	828.0955963644487
18.95	0.10054695628976369	16.605	0.543587	0.0040218782515905474	843.9968678804663	0.00401381211935681	847.3913205278053
19.38	0.10300245628976369	17.0103	0.556877	0.004120098251590548	864.5974057035287	0.0041116338881634976	868.1596319630975
19.79	0.10558345628976369	17.422	0.56926	0.004223338251590548	885.5232419279424	0.004214444989307388	889.2631061082492
20.21	0.10816545628976369	17.8176	0.581902	0.004326618251590548	905.6307493614571	0.004317285349096966	909.5490678908461
20.62	0.1108864562897637	18.2146	0.594818	0.004435458251590548	925.8094158202675	0.004425650596907672	929.9158048330678
21.02	0.11374245628976369	18.5778	0.606346	0.0045496982515905475	944.2701000969422	0.004539379660313796	948.5662441203824
21.43	0.11671245628976369	18.921	0.618629	0.004668498251590548	961.7142268693949	0.004657634611762362	966.2039880560644
21.84	0.1203534562897637	19.2689	0.630882	0.004814138251590548	979.3972446553396	0.004802587344977704	984.1121983943372
22.27	0.1248204562897637	19.579	0.643906	0.0049928182515905474	995.1589687583047	0.004980395467188344	1000.1276166207552
22.67	0.12954145628976368	19.8407	0.655434	0.0051816582515905475	1008.4606237010518	0.005168279656110956	1013.6861220132564
23.08	0.13500245628976368	20.0883	0.667229	0.005400098251590547	1021.0456056033225	0.0053855700002145715	1026.5593521929352
23.49	0.1410104562897637	20.3111	0.67955	0.005640418251590547	1032.3700562003576	0.005624570656016268	1038.1930551077457
23.9	0.1474894562897637	20.513	0.692169	0.005899578251590548	1042.6322042054805	0.005882243883378751	1048.783294481819
24.31	0.1540674562897637	20.6919	0.704262	0.006162698251590548	1051.725311080748	0.006143786485287901	1058.2067768164989
24.73	0.16123445628976368	20.8541	0.716896	0.006449378251590547	1059.9695924399898	0.006428670000880302	1066.8057372768196
25.14	0.1686904562897637	21.005	0.729103	0.006747618251590548	1067.6395188093463	0.006724954967229623	1074.8435427125837
25.56	0.1763374562897637	21.1389	0.741402	0.007053498251590548	1074.4453713001137	0.007028738692291263	1082.0239698480086
25.96	0.18393245628976368	21.2696	0.753326	0.007357298251590547	1081.0885745902058	0.0073303653543709225	1089.0424656698528
26.38	0.19228645628976368	21.3758	0.766029	0.007691458251590547	1086.4864949376256	0.007662029788776993	1094.8431604543553
26.79	0.2002364562897637	21.4732	0.777763	0.008009458251590548	1091.4371299831873	0.00797755279125685	1100.1789501100236
27.19	0.2085744562897637	21.5724	0.789093	0.008342978251590548	1096.4792552041295	0.008308367977137679	1105.6271577836176
27.62	0.2171674562897637	21.6631	0.801842	0.008686698251590548	1101.0893434857771	0.008649185970379164	1110.65417436068
28.02	0.2259074562897637	21.743	0.815048	0.009036298251590547	1105.1504907151448	0.00899571520566502	1115.1369601621384
28.43	0.2345924562897637	21.8232	0.827072	0.009383698251590548	1109.2268863070758	0.009339944854630194	1119.6355367007327
28.83	0.2433394562897637	21.8891	0.83902	0.009733578251590548	1112.5764432834876	0.00968651214675703	1123.4057931550637
29.24	0.2523714562897637	21.9586	0.851189	0.010094858251590549	1116.10898061066	0.010044245504029907	1127.3759425632518
29.64	0.2613384562897637	22.0119	0.863556	0.010453538251590549	1118.818106359412	0.010399277835240838	1130.5137142308122
30.05	0.27053545628976366	22.0768	0.874962	0.010821418251590546	1122.116835460613	0.010763285713415397	1134.2597310642834
30.45	0.2795474562897637	22.1149	0.886665	0.011181898251590548	1124.053377506156	0.011119842995865947	1136.6224280027866
30.88	0.2898624562897637	22.1729	0.899529	0.011594498251590549	1127.0013942684004	0.011527797138929468	1140.0684099637854
31.29	0.2988484562897637	22.2026	0.911331	0.011953938251590548	1128.5109821621704	0.01188305426773975	1142.0011327591787
31.7	0.3080644562897637	22.2482	0.923195	0.012322578251590548	1130.828733271797	0.012247273287295449	1144.7634588266858
32.09	0.3172454562897637	22.2754	0.934898	0.012689818251590547	1132.2112514775392	0.012609977243735668	1146.5788064811952
32.5	0.3269194562897637	22.3129	0.947281	0.013076778251590548	1134.1172967979558	0.012992015337733661	1148.947897199476
32.9	0.3366644562897637	22.3545	0.959152	0.013466578251590549	1136.231736406738	0.013376709801393992	1151.532889997
33.31	0.3463004562897637	22.3856	0.971008	0.013852018251590548	1137.8124833258034	0.013756955911017622	1153.57348261172
33.71	0.3558304562897637	22.4118	0.982262	0.014233218251590548	1139.1441736563345	0.014132876999173172	1155.357861300013
34.12	0.3657734562897637	22.4484	0.994263	0.014630938251590548	1141.004473889061	0.014524938738565396	1157.6984398913205
34.54	0.37563645628976366	22.4781	1.00744	0.015025458251590547	1142.514061782831	0.014913694200473466	1159.680859120004
34.95	0.3857124562897637	22.4992	1.01948	0.015428498251590548	1143.5865299497852	0.015310689171970055	1161.230352727658
35.36	0.3953354562897637	22.5307	1.03177	0.015813418251590546	1145.1876080189354	0.01568968883860756	1163.2969386410773
35.7701	0.4053834562897637	22.5551	1.04415	0.016215338251590546	1146.4278081740863	0.01608527379669938	1165.0175228646588
36.2001	0.41596545628976367	22.5856	1.05783	0.016638618251590548	1147.9780583680251	0.01650171296564507	1167.0788270424127
36.6101	0.4262214562897637	22.6048	1.07018	0.017048858251590547	1148.9539535720785	0.016905157457785012	1168.5423066641335
37.0201	0.43547645628976367	22.6305	1.08163	0.017419058251590548	1150.260229965004	0.01726908554048691	1170.2966799152523
37.4201	0.4451894562897637	22.662	1.09418	0.017807578251590548	1151.861308034154	0.017650880862689462	1172.3731684119516
37.8301	0.4553304562897637	22.674	1.1059	0.018213218251590547	1152.4712425366872	0.018049344381395986	1173.4614528056898
38.2401	0.4656134562897637	22.693	1.11861	0.018624538251590547	1153.4369721656983	0.01845322535255134	1174.9192031745972
38.6401	0.4752314562897637	22.7237	1.13093	0.019009258251590548	1154.9973879346794	0.018830839824034638	1176.9530315618424
39.0401	0.4850194562897637	22.7356	1.14291	0.019400778251590547	1155.6022396496917	0.019214982364351194	1178.0218224481769
39.4801	0.4956604562897637	22.7607	1.15565	0.01982641825159055	1156.8780193174905	0.019632434629514302	1179.8147667945507
39.9001	0.5061624562897638	22.7822	1.16899	0.02024649825159055	1157.9708186345292	0.02004426305244863	1181.4156727894062
40.3101	0.5156944562897637	22.8018	1.18073	0.02062777825159055	1158.9670449886669	0.02041790684699825	1182.8739601935943
40.7201	0.5258594562897637	22.8291	1.19386	0.02103437825159055	1160.3546459819304	0.020816209772955264	1184.7619845115046
41.1201	0.5359084562897638	22.8445	1.2056	0.021436338251590553	1161.1373952601814	0.021209811504369652	1186.0279292215494
41.5201	0.5454774562897637	22.865	1.21715	0.02181909825159055	1162.179366702009	0.021584468532207784	1187.5370724900513
41.9601	0.5565644562897637	22.8673	1.23007	0.02226257825159055	1162.2962708149946	0.022018384663893036	1188.1719824955453
42.3701	0.5662694562897638	22.888	1.24181	0.02265077825159055	1163.3484078318645	0.022398058456358352	1189.6991546470051
42.7701	0.5759764562897638	22.9118	1.25336	0.02303905825159055	1164.558111261889	0.022777666349729213	1191.3884334246138
43.2001	0.5869204562897637	22.9309	1.26709	0.02347681825159055	1165.5289236784213	0.02320547637720349	1192.8918343865914
43.6001	0.5964804562897638	22.9454	1.27923	0.023859218251590552	1166.265927868982	0.023579034989594367	1194.092121181402
44.0201	0.6067354562897638	22.9556	1.29175	0.02426941825159055	1166.7843721961358	0.023979595772910145	1195.1015501343834
44.4301	0.6163904562897637	22.9606	1.30341	0.02465561825159055	1167.038511572191	0.02435657394213849	1195.8125675984193
44.8301	0.6263204562897637	22.9709	1.31532	0.025052818251590548	1167.5620386868657	0.024744141264298344	1196.8127582395443
45.2401	0.6364284562897637	23.0048	1.32798	0.02545713825159055	1169.285103656522	0.025138501705180474	1199.0517561958316
45.6401	0.6462344562897637	23.0183	1.33967	0.02584937825159055	1169.971279971872	0.025520931148683812	1200.2143101313625
46.0701	0.6568394562897637	23.0282	1.35201	0.02627357825159055	1170.4744759364619	0.025934356674379388	1201.227028671468
46.4701	0.6667854562897637	23.0463	1.36469	0.02667141825159055	1171.3944604777832	0.026321936473797162	1202.6372120707824
46.8801	0.6772684562897637	23.0668	1.37717	0.02709073825159055	1172.4364319196109	0.0267302797714851	1204.198600413374
47.2801	0.6866434562897638	23.0652	1.38864	0.02746573825159055	1172.3551073192732	0.027095322064995087	1204.5547058348197
47.7001	0.6969584562897637	23.0811	1.4017	0.02787833825159055	1173.1632705351296	0.027496812025006406	1205.8691130154502
48.1201	0.7072004562897638	23.102	1.41444	0.028288018251590552	1174.225573127042	0.027895301188225575	1207.4420875711442
48.5401	0.7175244562897638	23.1131	1.42699	0.028700978251590552	1174.7897625418852	0.028296820113460533	1208.5073779667912
48.9701	0.7279114562897637	23.1302	1.43973	0.02911645825159055	1175.658919207995	0.028700626591407104	1209.8899430472247
49.3701	0.7378004562897638	23.1421	1.4519	0.02951201825159055	1176.2637709230073	0.029084921289923914	1210.9776887991718
49.7801	0.7484854562897637	23.164	1.46497	0.02993941825159055	1177.3769013901308	0.029499983280277812	1212.6268808806117
50.1801	0.7580684562897637	23.1685	1.47653	0.03032273825159055	1177.6056268285806	0.029872091269751794	1213.313854014504
50.5901	0.7679744562897638	23.1825	1.48864	0.03071897825159055	1178.3172170815362	0.03025659586440331	1214.5139180465387
50.9901	0.7776524562897638	23.1929	1.50057	0.03110609825159055	1178.8458269837317	0.030632107840623292	1215.5151211013651
51.4201	0.7884904562897638	23.1915	1.51366	0.03153961825159055	1178.774667958436	0.031052461178974092	1215.9527709904905
51.8201	0.7981564562897637	23.2082	1.52583	0.031926258251590546	1179.6234934744618	0.031427209323760426	1217.2844577667709
52.2301	0.8080324562897637	23.2132	1.53821	0.03232129825159055	1179.8776328505173	0.03180995411963354	1218.0128097222596
52.6301	0.8177714562897638	23.2346	1.55029	0.03271085825159055	1180.965349380035	0.03218724606968307	1219.5957395236453
53.0501	0.8284604562897637	23.2471	1.56296	0.03313841825159055	1181.6006978201738	0.032601177532126095	1220.75707595091
53.4801	0.8394494562897638	23.2534	1.57574	0.03357797825159055	1181.9209134340038	0.03302654794808792	1221.6074281603908
53.8801	0.8495404562897637	23.2676	1.58816	0.033981618251590545	1182.6426692620018	0.03341699860867412	1222.8307809769053
54.2901	0.8593724562897638	23.274	1.60028	0.03437489825159055	1182.9679676633527	0.03379728121624348	1223.6323711866714
54.6901	0.8690124562897638	23.2884	1.61206	0.03476049825159055	1183.6998890663926	0.03416999728413882	1224.8458869906929
55.1001	0.8795864562897637	23.2985	1.62443	0.03518345825159055	1184.213250606025	0.03457866535899929	1225.8779680697025
55.5101	0.8893094562897638	23.2982	1.63645	0.03557237825159055	1184.1980022434616	0.0349542963220681	1226.322741504044
55.9101	0.8993144562897637	23.3042	1.64819	0.035972578251590545	1184.5029694947282	0.035340674617863485	1227.1125952541186
56.3101	0.9093434562897638	23.3268	1.66087	0.03637373825159055	1185.6516794744991	0.035727829990318524	1228.7782633212632
56.7201	0.9199354562897637	23.3336	1.6739	0.036797418251590545	1185.997309025935	0.036136556500495125	1229.638948051423
57.1201	0.9297574562897637	23.3237	1.68486	0.03719029825159055	1185.4941130613447	0.03651542085111143	1229.582992701601
57.5301	0.9400334562897638	23.3383	1.69703	0.03760133825159055	1186.236200039427	0.036911643776002534	1230.840268643391
57.9501	0.9505044562897638	23.3456	1.70941	0.03802017825159055	1186.6072435284682	0.037315224103489794	1231.722262442049
58.3601	0.9613184562897638	23.3645	1.72209	0.03845273825159055	1187.5678903699581	0.03773185367069392	1233.2331276143477
58.7601	0.9710764562897638	23.3738	1.73415	0.038843058251590554	1188.0405896094214	0.03810764993933387	1234.1877194368742
59.1701	0.9813294562897638	23.3759	1.74584	0.039253178251590554	1188.1473281473648	0.03850235736252288	1234.7858870082844
59.5701	0.9913294562897638	23.386	1.75764	0.03965317825159055	1188.6606896869969	0.03888717508524987	1235.794863895814
60.0101	1.0022764562897637	23.3972	1.77114	0.040091058251590546	1189.2299618893614	0.039308265331622225	1236.9074495660047
60.4201	1.0126064562897636	23.3963	1.78342	0.04050425825159055	1189.1842168016713	0.03970545934831056	1237.3512414277218
60.8201	1.0226764562897637	23.4012	1.7944	0.04090705825159055	1189.4332733902058	0.04009250442857364	1238.089489591159
61.2301	1.0328664562897638	23.406	1.80672	0.04131465825159055	1189.677247191219	0.040484009331222495	1238.8283560886175
61.6301	1.0432264562897637	23.4209	1.81947	0.041729058251590546	1190.4345825318646	0.04088188864809299	1240.1102965710447
62.0501	1.0539464562897638	23.4153	1.8322	0.04215785825159055	1190.1499464306823	0.04129342729988449	1240.324119170445
62.4901	1.0646964562897638	23.4308	1.8448	0.04258785825159055	1190.9377784964547	0.04170594764008145	1241.657267793526
62.9101	1.0755464562897636	23.4311	1.85687	0.04302185825159054	1190.953026859018	0.04212213289548189	1242.1900391648494
63.3301	1.0862564562897636	23.438	1.86986	0.043450258251590546	1191.3037391979747	0.04253277821648255	1243.0661943222121
63.7401	1.0970264562897638	23.4418	1.88268	0.043881058251590555	1191.4968851237768	0.042945554092272534	1243.7810293464818
64.1501	1.1071064562897637	23.4369	1.89451	0.04428425825159055	1191.2478285352424	0.043331730418279216	1244.0013550157435
64.5501	1.1173964562897638	23.4634	1.90686	0.04469585825159055	1192.5947672283369	0.04372579831971572	1245.8988138959633
64.9601	1.1282164562897639	23.457	1.91945	0.045128658251590556	1192.2694688269858	0.044139995782488124	1246.0749902294842
65.3601	1.1382964562897637	23.4598	1.93092	0.04553185825159055	1192.411786877577	0.044525711207652516	1246.7045113352126
65.7701	1.1488464562897638	23.4643	1.9426	0.045953858251590554	1192.6405123160268	0.04492925209956204	1247.446945364102
66.1701	1.1595264562897638	23.4669	1.95515	0.04638105825159055	1192.7726647915756	0.04533759973317132	1248.0947232381784
66.6001	1.1704764562897638	23.4786	1.96812	0.04681905825159055	1193.3673509315456	0.04575609770948951	1249.239686450356
67.0001	1.1807664562897637	23.4712	1.97971	0.04723065825159055	1192.9912246549834	0.04614921159026961	1249.3369854838093
67.4201	1.1915564562897638	23.4783	1.99187	0.04766225825159055	1193.3521025689822	0.046561261297160816	1250.2299586667039
67.8401	1.2029564562897637	23.4888	2.00493	0.048118258251590544	1193.885795258699	0.0469964213758092	1251.3335002778626
68.2501	1.2140364562897636	23.5009	2.01689	0.04856145825159055	1194.5008125487534	0.047419185046495456	1252.5075138888305
68.6601	1.2248964562897637	23.4929	2.02899	0.04899585825159055	1194.0941895470644	0.047833381123801845	1252.5998591971602
69.0601	1.2357064562897637	23.4948	2.04086	0.04942825825159055	1194.1907625099657	0.04824549991591764	1253.217531920972
69.4701	1.2463664562897638	23.4904	2.05241	0.04985465825159055	1193.9671198590368	0.04865173387563016	1253.491942583245
69.8701	1.2570464562897639	23.4976	2.06428	0.05028185825159055	1194.3330805605567	0.04905856457690606	1254.386367222488
70.2901	1.2688364562897638	23.5024	2.07679	0.050753458251590555	1194.5770543615702	0.04950748611974339	1255.205971018418
70.7001	1.2797964562897637	23.4918	2.08899	0.05119185825159055	1194.0382788843324	0.04992462352376131	1255.1633172039521
71.1001	1.2909264562897638	23.511	2.10217	0.051637058251590554	1195.0141740883855	0.05034805312676699	1256.721190607264
71.5201	1.3017864562897636	23.4936	2.11346	0.05207145825159055	1194.1297690597123	0.05076103810331333	1256.3098474762867
71.9301	1.3133764562897638	23.5102	2.1265	0.052535058251590556	1194.9735117882167	0.05120159552234923	1257.7515148391185
72.3301	1.3238464562897638	23.5049	2.13771	0.05295385825159055	1194.7041240495978	0.05159941286751826	1257.9683168871109
72.7401	1.3351464562897637	23.5099	2.15008	0.05340585825159055	1194.9582634256533	0.05202858933096526	1258.7760350587305
73.1501	1.3473864562897637	23.5182	2.16345	0.05389545825159055	1195.3801347899057	nan	nan
73.5501	1.3577564562897637	23.5144	2.17461	0.05431025825159055	1195.1869888641033	nan	nan
73.9601	1.3690864562897638	23.5029	2.18647	0.05476345825159055	1194.6024682991756	nan	nan
74.3601	1.3802464562897638	23.5123	2.19868	0.055209858251590554	1195.08025032616	nan	nan
74.7801	1.3920764562897638	23.5175	2.21136	0.055683058251590554	1195.3445552772578	nan	nan
75.2201	1.4036064562897637	23.497	2.22433	0.05614425825159055	1194.3025838354301	nan	nan
75.6301	1.4152664562897637	23.508	2.23682	0.05661065825159055	1194.8616904627522	nan	nan
76.0301	1.4267764562897638	23.5102	2.24881	0.057071058251590555	1194.9735117882167	nan	nan
76.4501	1.4380464562897637	23.504	2.26091	0.05752185825159055	1194.6583789619078	nan	nan
76.8601	1.4494564562897638	23.5083	2.27339	0.05797825825159055	1194.8769388253156	nan	nan
77.2601	1.4609564562897637	23.4973	2.28596	0.05843825825159055	1194.3178321979933	nan	nan
77.7001	1.4732164562897638	23.5005	2.29854	0.058928658251590556	1194.4804813986689	nan	nan
78.1201	1.4849064562897638	23.4977	2.31149	0.059396258251590554	1194.3381633480776	nan	nan
78.5501	1.4975264562897637	23.4971	2.32455	0.05990105825159055	1194.307666622951	nan	nan
78.9501	1.5089764562897638	23.5058	2.33654	0.060359058251590554	1194.7498691372878	nan	nan
79.3501	1.5203564562897638	23.4922	2.3484	0.06081425825159055	1194.0586100344167	nan	nan
79.7801	1.5320764562897637	23.4941	2.36108	0.06128305825159055	1194.1551829973178	nan	nan
80.1801	1.5438464562897638	23.4952	2.37308	0.06175385825159055	1194.21109366005	nan	nan
80.6001	1.5557064562897638	23.4875	2.38615	0.06222825825159055	1193.8197190209246	nan	nan
81.0101	1.5678164562897638	23.4806	2.39803	0.06271265825159056	1193.4690066819678	nan	nan
81.4101	1.5794964562897638	23.4713	2.41006	0.06317985825159055	1192.9963074425045	nan	nan
81.8401	1.5916864562897637	23.4825	2.42319	0.06366745825159055	1193.5655796448689	nan	nan
82.2401	1.6029964562897638	23.467	2.43443	0.06411985825159056	1192.7777475790967	nan	nan
82.6601	1.6149764562897637	23.469	2.44643	0.06459905825159055	1192.879403329519	nan	nan
83.0701	1.6271664562897636	23.4576	2.45924	0.06508665825159055	1192.2999655521123	nan	nan
83.4701	1.6391764562897637	23.4585	2.47124	0.06556705825159055	1192.3457106398023	nan	nan
83.9001	1.6512364562897637	23.4551	2.48366	0.06604945825159055	1192.1728958640847	nan	nan
84.3001	1.6629064562897637	23.4577	2.49575	0.06651625825159055	1192.3050483396335	nan	nan
84.7101	1.6755864562897638	23.449	2.50889	0.06702345825159055	1191.8628458252967	nan	nan
85.1201	1.6876564562897638	23.4345	2.52116	0.06750625825159055	1191.1258416347357	nan	nan
85.5201	1.6990964562897637	23.4392	2.53284	0.06796385825159054	1191.364732648228	nan	nan
85.9301	1.7116964562897639	23.4279	2.54521	0.06846785825159056	1190.7903776583425	nan	nan
86.3401	1.7235764562897637	23.4104	2.55688	0.06894305825159056	1189.900889842148	nan	nan
86.7601	1.7355564562897638	23.3993	2.56918	0.06942225825159055	1189.3367004273045	nan	nan
87.1701	1.7480564562897638	23.4059	2.58154	0.06992225825159055	1189.672164403698	nan	nan
87.5901	1.7606164562897637	23.3929	2.59427	0.07042465825159056	1189.0114020259537	nan	nan
88.0101	1.7729664562897638	23.3905	2.6068	0.07091865825159055	1188.889415125447	nan	nan
88.4201	1.7856664562897637	23.3834	2.61975	0.07142665825159054	1188.528537211448	nan	nan
88.8301	1.7981364562897637	23.3685	2.63194	0.07192545825159055	1187.7712018708025	nan	nan
89.2301	1.8102564562897638	23.3583	2.64413	0.07241025825159056	1187.2527575436493	nan	nan
89.6501	1.8229664562897638	23.3518	2.65648	0.07291865825159055	1186.922376354777	nan	nan
90.0701	1.8356064562897638	23.345	2.66909	0.07342425825159055	1186.5767468033414	nan	nan
90.4901	1.8484964562897637	23.3355	2.68228	0.07393985825159055	1186.0938819888358	nan	nan
90.9201	1.8611864562897638	23.3149	2.69483	0.07444745825159055	1185.046827759487	nan	nan
91.3201	1.8729164562897638	23.3007	2.70635	0.07491665825159055	1184.3250719314894	nan	nan
91.7401	1.8854664562897638	23.2808	2.71866	0.07541865825159055	1183.3135972147882	nan	nan
92.1501	1.8986564562897636	23.2766	2.73206	0.07594625825159054	1183.1001201389015	nan	nan
92.5601	1.9111864562897638	23.2671	2.74335	0.07644745825159055	1182.617255324396	nan	nan
92.9601	1.9237364562897636	23.2397	2.75549	0.07694945825159055	1181.2245715436118	nan	nan
93.3601	1.9357464562897637	23.2353	2.76759	0.07742985825159054	1181.0009288926829	nan	nan
93.7901	1.9492664562897637	23.2192	2.78107	0.07797065825159055	1180.182600101784	nan	nan
94.1901	1.9615164562897638	23.1975	2.79245	0.07846065825159056	1179.079635209703	nan	nan
94.6001	1.9737164562897638	23.178	2.80441	0.07894865825159054	1178.0884916430862	nan	nan
95.0001	1.9858364562897637	23.1538	2.81629	0.07943345825159055	1176.8584570629773	nan	nan
95.4201	1.9993564562897637	23.1354	2.82899	0.07997425825159055	1175.923224159093	nan	nan
95.8401	2.0123764562897635	23.1105	2.84162	0.08049505825159053	1174.6576100663365	nan	nan
96.2501	2.0254064562897636	23.0901	2.85418	0.08101625825159055	1173.6207214120298	nan	nan
96.6701	2.0388964562897636	23.0752	2.8679	0.08155585825159055	1172.8633860713842	nan	nan
97.0801	2.0513464562897634	23.0488	2.8794	0.08205385825159053	1171.5215301658109	nan	nan
97.4801	2.0635964562897637	23.0213	2.89095	0.08254385825159055	1170.1237635975053	nan	nan
97.9001	2.0763564562897634	23.0029	2.90344	0.08305425825159053	1169.188530693621	nan	nan
98.3301	2.0902064562897635	22.9799	2.91711	0.08360825825159054	1168.0194895637655	nan	nan
98.7301	2.1026064562897635	22.9502	2.92973	0.08410425825159054	1166.5099016699955	nan	nan
99.1401	2.1152664562897634	22.9272	2.94107	0.08461065825159053	1165.34086054014	nan	nan
99.5401	2.1277964562897633	22.9039	2.95338	0.08511185825159054	1164.1565710477214	nan	nan
99.9601	2.1410864562897634	22.884	2.96645	0.08564345825159053	1163.14509633102	nan	nan
100.37	2.1545864562897634	22.8408	2.97857	0.08618345825159053	1160.9493321219004	nan	nan
100.77	2.1673064562897637	22.8218	2.99142	0.08669225825159055	1159.983602492889	nan	nan
101.18	2.1795064562897637	22.7802	3.00281	0.08718025825159055	1157.869162884107	nan	nan
101.59	2.1929964562897637	22.7573	3.01587	0.08771985825159055	1156.7052045417727	nan	nan
101.99	2.2053964562897637	22.7205	3.02744	0.08821585825159055	1154.8347387340038	nan	nan
102.41	2.2185464562897637	22.7003	3.0402	0.08874185825159055	1153.8080156547394	nan	nan
102.82	2.2309464562897636	22.6629	3.05244	0.08923785825159054	1151.907053121844	nan	nan
103.22	2.2437664562897637	22.6275	3.0638	0.08975065825159055	1150.1077463393708	nan	nan
103.64	2.2569464562897634	22.6079	3.07608	0.09027785825159054	1149.1115199852331	nan	nan
104.07	2.2713764562897634	22.5696	3.08988	0.09085505825159053	1147.1648123646476	nan	nan
104.48	2.2836964562897637	22.5317	3.10183	0.09134785825159054	1145.2384358941465	nan	nan
104.88	2.2966664562897634	22.5225	3.11427	0.09186665825159053	1144.7708194422044	nan	nan
105.28	2.3092164562897635	22.4761	3.1263	0.09236865825159053	1142.4124060324086	nan	nan
105.7	2.3226464562897635	22.4401	3.13947	0.09290585825159053	1140.5826025248089	nan	nan
106.11	2.3356664562897635	22.409	3.15197	0.09342665825159054	1139.0018556057435	nan	nan
106.51	2.3484464562897633	22.3723	3.16367	0.09393785825159054	1137.1364725854955	nan	nan
106.95	2.3619664562897635	22.3377	3.17602	0.09447865825159055	1135.3778281031914	nan	nan
107.36	2.3748264562897634	22.2952	3.18785	0.09499305825159053	1133.2176434067192	nan	nan
107.76	2.3884964562897637	22.2673	3.20099	0.09553985825159055	1131.799545688329	nan	nan
108.18	2.4015964562897634	22.2501	3.21293	0.09606385825159053	1130.9253062346982	nan	nan
108.6	2.4152864562897634	22.2041	3.22649	0.09661145825159054	1128.5872239749872	nan	nan
109.01	2.4277264562897636	22.1587	3.2383	0.09710905825159054	1126.2796384404028	nan	nan
109.43	2.4410864562897636	22.1144	3.24998	0.09764345825159054	1124.0279635685506	nan	nan
109.85	2.4545164562897637	22.1009	3.26406	0.09818065825159054	1123.3417872532007	nan	nan
110.27	2.4677164562897635	22.0511	3.27667	0.09870865825159054	1120.8105590676876	nan	nan
110.68	2.4802064562897637	22.0129	3.2882	0.09920825825159055	1118.8689342346229	nan	nan
111.1	2.4944464562897637	21.9852	3.30167	0.09977785825159055	1117.4610020912753	nan	nan
111.51	2.5075764562897636	21.9377	3.31361	0.10030305825159054	1115.0466780187478	nan	nan
111.92	2.5210864562897637	21.9053	3.3271	0.10084345825159055	1113.3998548619077	nan	nan
112.32	2.5334364562897633	21.8577	3.33833	0.10133745825159053	1110.980448001859	nan	nan
112.72	2.5464664562897634	21.8335	3.35068	0.10185865825159053	1109.7504134217502	nan	nan
113.14	2.5597864562897636	21.7891	3.3632	0.10239145825159054	1107.4936557623769	nan	nan
113.55	2.5724764562897637	21.7496	3.37567	0.10289905825159056	1105.4859546915382	nan	nan
113.97	2.5858264562897637	21.717	3.38815	0.10343305825159055	1103.828965959656	nan	nan
114.38	2.5991964562897634	21.6716	3.40061	0.10396785825159054	1101.5213804250716	nan	nan
114.78	2.6117564562897635	21.6217	3.41237	0.10447025825159054	1098.9850694520371	nan	nan
115.2	2.6255464562897637	21.5998	3.4258	0.10502185825159055	1097.8719389849139	nan	nan
115.62	2.6388364562897637	21.5474	3.43736	0.10555345825159054	1095.2085583238518	nan	nan
116.06	2.6529864562897636	21.506	3.45093	0.10611945825159054	1093.1042842901118	nan	nan
116.47	2.6660864562897637	21.4706	3.46336	0.10664345825159055	1091.3049775076388	nan	nan
116.87	2.6785564562897637	21.4295	3.47498	0.10714225825159054	1089.215951836462	nan	nan
117.3	2.6924364562897636	21.3872	3.48824	0.10769745825159055	1087.0659327150322	nan	nan
117.7	2.7052564562897636	21.3454	3.50024	0.10821025825159054	1084.941327531208	nan	nan
118.12	2.7190864562897636	21.2988	3.51377	0.10876345825159055	1082.5727485463701	nan	nan
118.54	2.7323164562897637	21.2481	3.52563	0.10929265825159055	1079.995775273167	nan	nan
118.96	2.7455964562897637	21.2099	3.53823	0.10982385825159055	1078.0541504401026	nan	nan
119.38	2.7591364562897636	21.1695	3.55101	0.11036545825159054	1076.0007042815737	nan	nan
119.82	2.7739664562897635	21.1196	3.56412	0.11095865825159054	1073.4643933085392	nan	nan
120.24	2.7876164562897636	21.0704	3.5764	0.11150465825159055	1070.9636618481527	nan	nan
120.66	2.8005264562897634	21.0251	3.58933	0.11202105825159053	1068.6611591010894	nan	nan
121.09	2.8144464562897635	20.9889	3.60225	0.11257785825159054	1066.8211900184474	nan	nan
121.49	2.8271364562897636	20.9351	3.6144	0.11308545825159054	1064.0866503320897	nan	nan
121.91	2.8402064562897635	20.8941	3.62663	0.11360825825159054	1062.0027074484344	nan	nan
122.32	2.8536964562897635	20.8405	3.63921	0.11414785825159054	1059.2783333371187	nan	nan
122.72	2.8674864562897637	20.8114	3.65201	0.11469945825159054	1057.7992421684753	nan	nan
123.14	2.8812864562897635	20.7442	3.6644	0.11525145825159054	1054.383608954289	nan	nan
123.58	2.8950964562897634	20.6825	3.6775	0.11580385825159054	1051.2475290537636	nan	nan
124	2.9089364562897635	20.6505	3.69102	0.11635745825159054	1049.621037047008	nan	nan
124.43	2.9225764562897636	20.6074	3.70332	0.11690305825159054	1047.4303556254092	nan	nan
124.83	2.9352264562897634	20.5432	3.71492	0.11740905825159054	1044.167206036856	nan	nan
125.23	2.9477964562897636	20.4888	3.72659	0.11791185825159055	1041.402169625372	nan	nan
125.64	2.9611264562897635	20.4524	3.73971	0.11844505825159053	1039.5520349676874	nan	nan
126.06	2.9749764562897636	20.3961	3.75242	0.11899905825159054	1036.690425593302	nan	nan
126.47	2.9885164562897635	20.3216	3.76366	0.11954065825159053	1032.9037488900742	nan	nan
126.87	3.0019464562897635	20.2674	3.7761	0.12007785825159054	1030.148878053632	nan	nan
127.28	3.0161064562897635	20.2128	3.7898	0.12064425825159054	1027.3736760671059	nan	nan
127.68	3.0291264562897635	20.1361	3.80126	0.12116505825159055	1023.4751780384134	nan	nan
128.12	3.0436964562897635	20.0681	3.81401	0.12174785825159054	1020.0188825240582	nan	nan
128.54	3.0580764562897635	19.9631	3.827	0.12232305825159054	1014.6819556268917	nan	nan
128.96	3.0729264562897636	19.833	3.83952	0.12291705825159055	1008.0692490619264	nan	nan