File: original_data/46NTA3.csv
Specimen name:	AWA_3_02_Rz
Specimen ID:	46NTA3
Material:	42CrMoS4
Specimen type:	Round Tensile Specimen
Gauge diameter:	5.006	mm
Gauge length:	25	mm
Parallel length:	30	mm
Original cross-section:	19.68210624907394	mm²
Cross-section after fracture:	9.886830841888752	mm²
Yield stress at 0.2% plastic strain:	1082.1118886571364	MPa
Yield stress at 1% plastic strain:	1128.687641710045	MPa
Ultimate tensile strength:	1181.5808585574634	MPa
Uniform elongation:	4.756198025739526	%
Elongation after fracture:	13.869693842114053	%
Reduction of area:	49.767414540027005	%
Slope of linear-elastic region:	204815.53653420936	MPa
Crosshead seperation speed:	0.029917171450326047	mm/s
Strain rate:	0.0009972390483442015	s-1
Test temperature:	RT	Cel
Machine type:	INSTRON 8852TT
Standard:	DIN EN ISO 6892-1
Date:	2022-09-06 00:00:00
Heat treatment batch:	Batch 3
Time	Displacement	Force	Machine Displacement	Engineering Strain	Engineering Stress	True Strain	True Stress
s	mm	kN	mm		MPa		MPa
0	0.0011633240049064352	0.192332	0	4.6532960196257406e-05	9.771921641214053	4.653187757158107e-05	9.772376357654824
0.27	0.0010934959049064353	0.192971	2.2889e-05	4.373983619625741e-05	9.804387678736338	4.3738879637579295e-05	9.804816521047412
0.590001	0.0012083345049064352	0.193333	-0.000106811	4.8333380196257404e-05	9.822780019241918	4.833221217597934e-05	9.82325478740317
0.900001	0.001165994674906435	0.190746	-0.000274658	4.66397869962574e-05	9.691340834468607	4.663869939521225e-05	9.691792836540834
1.21	0.0010127900049064352	0.19328	0.000167847	4.051160019625741e-05	9.820087218007677	4.051077962353339e-05	9.820485045454944
1.52	0.001187294804906435	0.192661	-0.000183105	4.74917921962574e-05	9.788637331894542	4.7490664496749306e-05	9.789102211824591
1.82	0.0011977821049064352	0.201079	-0.000129699	4.791128419625741e-05	10.216335460004997	4.7910136487315685e-05	10.216824937756664
2.13	0.0021752440049064353	0.358274	0.0098877	8.700976019625742e-05	18.20303149805713	8.700597506653089e-05	18.204615339462617
2.44	0.002789434004906435	0.518485	0.0194931	0.0001115773601962574	26.342963168608808	0.00011157113590562584	26.345902446898908
2.76	0.003762594004906435	0.676164	0.0282745	0.0001505037601962574	34.354250070762326	0.00015049243564164668	34.3594205145767
3.07	0.004364474004906435	0.86041	0.037796	0.00017457896019625738	43.715341697257784	0.00017456372306303883	43.72297347615592
3.38	0.005448174004906435	1.06019	0.04702	0.0002179269601962574	53.86567812323861	0.00021790321756567747	53.87741690673092
3.77001	0.006583214004906435	1.30956	0.0591888	0.0002633285601962574	66.53556196820226	0.0002632938953163463	66.5530826819372
4.24001	0.008322854004906436	1.61783	0.0722427	0.00033291416019625743	82.1980117131072	0.0003328587565732702	82.22537659514647
4.70001	0.010158124004906436	1.95744	0.0864563	0.0004063249601962574	99.45277071614728	0.00040624243256417563	99.49318085924993
5.13001	0.012167224004906435	2.29384	0.0998611	0.0004866889601962574	116.54443741801907	0.00048657056553691626	116.6011583090827
5.44001	0.013727624004906435	2.54939	0.109146	0.0005491049601962574	129.5283120484095	0.0005489542572328728	129.59943668704113
5.77001	0.015437324004906435	2.82124	0.119247	0.0006174929601962574	143.34035007725566	0.0006173023898648857	143.42886173434044
6.09001	0.017072824004906437	3.10119	0.128334	0.0006829129601962575	157.56392942680685	0.0006826798812496305	157.67153187627184
6.41001	0.018869024004906438	3.37128	0.137978	0.0007547609601962575	171.28654613164798	0.0007544762713818098	171.41582652967503
6.72001	0.020537024004906437	3.6381	0.147636	0.0008214809601962574	184.84302208109338	0.0008211437293854705	184.99486710435815
7.03001	0.022238924004906437	3.90399	0.156929	0.0008895569601962575	198.35224699001338	0.0008891615388860854	198.52869261189394
7.34001	0.024060324004906437	4.18635	0.165977	0.0009624129601962575	212.69827258436692	0.0009619501377702553	212.90297615851344
7.65001	0.026061224004906437	4.46484	0.175842	0.0010424489601962574	226.84767288105027	0.0010419059875937543	227.08415000176808
7.97001	0.027886924004906437	4.76287	0.185425	0.0011154769601962574	241.9898531044714	0.0011148552780436357	242.2597872102107
8.28001	0.029690824004906437	5.02804	0.194298	0.0011876329601962575	255.462496562662	0.0011869282820497118	255.76589224367387
8.59001	0.031620824004906435	5.32593	0.203873	0.0012648329601962574	270.59756372621905	0.001264033732842786	270.93982444376877
8.90001	0.03318382400490644	5.60194	0.212776	0.0013273529601962575	284.62096124816804	0.0013264728060198667	284.9987537236147
9.21001	0.03529022400490644	5.89816	0.222359	0.0014116089601962575	299.6711797690612	0.0014106135768859583	300.0941982915358
9.53001	0.037052124004906435	6.20161	0.231956	0.0014820849601962574	315.0887370243615	0.001480987756247434	315.5557253026325
9.84001	0.038960624004906436	6.4671	0.240242	0.0015584249601962575	328.5776389050985	0.0015572118761880886	329.0897024989306
10.15	0.04100922400490643	6.78881	0.250137	0.0016403689601962573	344.922942396951	0.0016390250245329736	345.4887432853185
10.46	0.04281392400490644	7.07543	0.258972	0.0017125569601962576	359.4854082414531	0.0017110922066029153	360.10104747942603
10.78	0.04482182400490644	7.39363	0.268684	0.0017928729601962576	375.65237716100006	0.0017912676818909851	376.3258741504455
11.09	0.04650462400490644	7.6996	0.278595	0.0018601849601962575	391.197969493853	0.001858456958756174	391.9256700731648
11.4	0.04840442400490644	7.99761	0.287468	0.0019361769601962575	406.3391335658649	0.0019343049855123176	407.12587803430125
11.71	0.050233424004906435	8.294	0.296623	0.0020093369601962576	421.39798937373587	0.00200732094280699	422.2447199287369
12.02	0.05219322400490644	8.59233	0.305626	0.0020877289601962576	436.5554118682942	0.0020855526825493916	437.466821244382
12.35	0.054254724004906434	8.92728	0.315796	0.0021701889601962576	453.5734075930027	0.0021678375015931335	454.5577475947996
12.68	0.055974124004906436	9.21044	0.324806	0.0022389649601962575	467.9600792437222	0.0022364622131620915	469.0078254639195
13.01	0.058056024004906434	9.55453	0.335625	0.0023222409601962573	485.44245616241136	0.0023195487258632014	486.56977051792995
13.32	0.059927624004906435	9.85513	0.344727	0.0023971049601962573	500.7152118419081	0.00239423648720722	501.9154787598601
13.67	0.061819424004906434	10.1679	0.354103	0.0024727769601962575	516.6062956538713	0.002469724677955406	517.8837477992564
13.99	0.06383072400490643	10.4991	0.364098	0.002553228960196257	533.4337629893646	0.002549975008679869	534.7957415213755
14.33	0.06596722400490643	10.8401	0.375092	0.0026386889601962573	550.7591445153405	0.0026352137325029515	552.2124265897003
14.64	0.06759602400490643	11.142	0.383957	0.002703840960196257	566.0979500364317	0.002700192157934752	567.6285888612233
15.02	0.06994992400490643	11.5201	0.395393	0.0027979969601962572	585.3082924263773	0.0027940898530541764	586.945983249364
15.36	0.07186362400490642	11.8408	0.405251	0.002874544960196257	601.6022802720679	0.002870421356265447	603.3316130748666
15.77	0.07437862400490643	12.2476	0.417976	0.002975144960196257	622.2707999341412	0.0029707279750412897	624.1221457684426
16.2	0.07652462400490644	12.6425	0.430733	0.0030609849601962572	642.3347095077713	0.0030563096839369454	644.3008863929867
16.61	0.07893162400490643	13.0343	0.442566	0.003157264960196257	662.2411156129834	0.0031522912652805343	664.3319862825097
17	0.08146392400490643	13.4237	0.453979	0.0032585569601962573	682.025583549098	0.0032532593686809223	684.2480027614038
17.42	0.08379982400490643	13.8272	0.466957	0.0033519929601962574	702.5264382286617	0.0033463875544878182	704.8813019039559
17.86	0.08644432400490643	14.2541	0.48027	0.003457772960196257	724.2161900569288	0.0034518086082363964	726.7203652162441
18.32	0.08931632400490642	14.701	0.493469	0.003572652960196257	746.9220932943442	0.003566286195264212	749.5905867219883
18.78	0.09202502400490643	15.1641	0.50808	0.0036810009601962574	770.4510791731695	0.0036742426559671615	773.2871103353901
19.23	0.09468952400490643	15.5967	0.521957	0.003787580960196257	792.430434153044	0.0037804261360574456	795.4318285777221
19.71	0.09739352400490643	16.0561	0.535965	0.003895740960196257	815.7714320211768	0.003888172212267627	818.9494662030597
20.15	0.10003962400490643	16.4944	0.549736	0.0040015849601962574	838.0403901526582	0.003993599913905141	841.3938799739301
20.62	0.10274332400490643	16.9398	0.563377	0.004109732960196257	860.6700820343877	0.004101311074277054	864.2072062383793
21.07	0.10569832400490643	17.3674	0.576935	0.004227932960196257	882.395399161975	0.004219020364046575	886.1261077540173
21.53	0.10799932400490643	17.793	0.590057	0.004319972960196258	904.0191011486475	0.004310668663589829	907.9244392211104
21.94	0.11035632400490643	18.1828	0.602142	0.004414252960196257	923.8238921129448	0.004404538722508295	927.9018844634044
22.34	0.11268132400490644	18.5519	0.613991	0.004507252960196257	942.5769663687739	0.004497125714874356	946.8253991906523
22.75	0.11536432400490643	18.9669	0.626854	0.004614572960196257	963.6621081085977	0.004603958460124178	968.1089972154415
23.13	0.11751632400490643	19.3124	0.637497	0.004700652960196257	981.2161237016321	0.0046896393915601305	985.8284801781025
23.5	0.12006432400490644	19.6796	0.649635	0.004802572960196257	999.8726635735921	0.004791077397503693	1004.67462499131
23.86	0.12225032400490643	19.977	0.659683	0.004890012960196258	1014.9828350276249	0.004878095681462073	1019.9461142452868
24.28	0.12547532400490644	20.3394	0.672493	0.005019012960196257	1033.3954985613893	0.005006459700443583	1038.5821239616776
24.72	0.13000332400490644	20.6687	0.685341	0.005200132960196257	1050.1264315130136	0.005186658959671217	1055.5872285818978
25.13	0.13566732400490644	20.8801	0.697144	0.005426692960196258	1060.8671519077093	0.005412021516300948	1066.6241522126704
25.59	0.14439632400490643	21.0241	0.711067	0.005775852960196257	1068.1834420535763	0.005759236672940609	1074.3531125493942
26.05	0.15529532400490642	21.1054	0.725258	0.006211812960196256	1072.314097531763	0.006192599177301047	1078.975112140212
26.51	0.16588032400490643	21.1783	0.738945	0.006635212960196257	1076.0179694181084	0.006613296826742284	1083.1575777941955
26.97	0.17635132400490644	21.2668	0.753105	0.0070540529601962575	1080.5144394035888	0.00702928951551357	1088.1364454833986
27.42	0.18652732400490643	21.3593	0.766602	0.0074610929601962575	1085.214139670899	0.007433396683795056	1093.311023248703
27.89	0.19629232400490643	21.4476	0.780746	0.007851692960196256	1089.7004481422882	0.007821028824691292	1098.2564414796896
28.34	0.20650132400490642	21.5227	0.794395	0.008260052960196256	1093.5160966836395	0.008226125423538799	1102.5485975550732
28.81	0.21655432400490643	21.5985	0.808769	0.008662172960196257	1097.3673105243108	0.008624871592489078	1106.8728959689379
29.26	0.22644932400490642	21.6514	0.822128	0.009057972960196257	1100.0550310015076	0.009017195578426316	1110.0192997270472
29.71	0.23692532400490643	21.7289	0.835854	0.009477012960196258	1103.9926177119567	0.009432387793515445	1114.4551700579739
30.18	0.24709632400490644	21.7674	0.848877	0.009883852960196258	1105.9487091745668	0.009835327171385631	1116.879743597567
30.63	0.2577243240049064	21.8281	0.862724	0.010308972960196257	1109.0327287013315	0.010256197893051868	1120.465717113486
31.1	0.26909932400490644	21.8607	0.877838	0.010763972960196258	1110.689055498243	0.010706453791638199	1122.644482458812
31.55	0.2792993240049064	21.9088	0.890404	0.011171972960196256	1113.1328996372442	0.011110027412613495	1125.5687902930963
32.01	0.29012732400490643	21.9537	0.904297	0.011605092960196257	1115.414159550782	0.011538270360307998	1128.358644561488
32.48	0.30135132400490644	21.9857	0.91832	0.012054052960196258	1117.040001805419	0.011981981454907052	1130.5048611458392
32.93	0.3122223240049064	22.0169	0.932213	0.012488892960196256	1118.62519800369	0.012411550022531666	1132.5955883641366
33.39	0.32322932400490645	22.0615	0.946045	0.012929172960196259	1120.8912156460904	0.012846304717715877	1135.3834120427434
33.85	0.3346143240049064	22.085	0.959824	0.013384572960196257	1122.0851935518394	0.01329579089287911	1137.10382469249
34.31	0.3457393240049064	22.115	0.973335	0.013829572960196258	1123.6094206655616	0.013734817039222004	1139.14845912742
34.77	0.35700232400490645	22.1352	0.98671	0.014280092960196257	1124.6357335888013	0.014179092824679489	1140.6956364108078
35.22	0.3683273240049064	22.1716	1.00007	0.014733092960196257	1126.485129153451	0.014625615312231714	1143.0817392795475
35.6901	0.3795683240049064	22.1919	1.01469	0.015182732960196257	1127.5165228337364	0.015068628762949605	1144.63530510813
36.1401	0.3910273240049064	22.2247	1.02849	0.015641092960196258	1129.183011144739	0.015520031786621811	1146.8446675911282
36.6101	0.40216332400490645	22.2386	1.04203	0.016086532960196256	1129.8892363740972	0.015958515765925115	1148.0652368164
37.1501	0.41514732400490645	22.2727	1.05757	0.016605892960196256	1131.621774526695	0.016469522748269166	1150.4133645859126
37.6101	0.4267653240049064	22.3091	1.07178	0.017070612960196255	1133.4711700913444	0.01692654726198715	1152.8202177375147
38.0801	0.43833132400490643	22.321	1.08559	0.01753325296019626	1134.0757801797877	0.017381318842561416	1153.9598177097118
38.5301	0.44971532400490644	22.3409	1.09921	0.017988612960196257	1135.08685083189	0.01782873236851745	1155.5054888677128
38.9901	0.46125432400490646	22.3692	1.11368	0.018450172960196257	1136.5247050758346	0.0182820335048881	1157.4937824580197
39.4501	0.47242732400490645	22.3887	1.12729	0.018897092960196257	1137.5154526997542	0.018720760878119358	1159.011187953081
39.9001	0.48401132400490643	22.4046	1.14102	0.019360452960196256	1138.3232930700267	0.0191754237433786	1160.3617476390048
40.3701	0.49542232400490643	22.4265	1.15501	0.01981689296019626	1139.435978863044	0.019623094475437343	1162.0160596911694
40.8801	0.5078523240049064	22.4484	1.17035	0.020314092960196258	1140.5486646560612	0.020110514168853944	1163.717876255512
41.3501	0.5190743240049065	22.4757	1.18385	0.02076297296019626	1141.9357113295484	0.020550360380182237	1165.6456916261664
41.8001	0.5305923240049065	22.4962	1.19833	0.02122369296019626	1142.9772665239254	0.0210016072129916	1167.2354650891136
42.2701	0.5421293240049064	22.5231	1.2122	0.02168517296019626	1144.3439901692295	0.021453394383283756	1169.1592875220106
42.7201	0.5535323240049065	22.5417	1.22603	0.02214129296019626	1145.2890109797372	0.021899733654428138	1170.647190495933
43.1901	0.5647923240049065	22.5514	1.24023	0.022591692960196263	1145.7818444131742	0.022340280180929102	1171.666996041524
43.6501	0.5759953240049065	22.5705	1.2536	0.02303981296019626	1146.7522690089106	0.02277840406186382	1173.1732267985567
44.1001	0.5873933240049065	22.5976	1.26701	0.02349573296019626	1148.1291541683063	0.023223957043781225	1175.105290178461
44.5601	0.5983363240049064	22.6108	1.28088	0.023933452960196257	1148.7998140983443	0.02365153716198876	1176.2945604097492
45.0201	0.6096983240049065	22.6365	1.29524	0.02438793296019626	1150.1055686590996	0.024095295656707604	1178.1542661647063
45.4801	0.6211263240049065	22.6682	1.30873	0.024845052960196262	1151.7161686425993	0.02454143331965041	1180.330617847639
45.9401	0.6323623240049064	22.67	1.32191	0.025294492960196258	1151.8076222694226	0.024979881529768003	1180.942012062417
46.4101	0.6437983240049064	22.6931	1.33643	0.025751932960196258	1152.981277146989	0.02542593677435293	1182.6727737004398
46.8701	0.6550873240049064	22.705	1.34997	0.026203492960196258	1153.585887235432	0.025866063301065095	1183.8138669105872
47.3401	0.6665193240049064	22.7207	1.36391	0.02666077296019626	1154.3835660916134	0.026311567677710448	1185.1603242561634
47.7901	0.6778243240049064	22.743	1.37809	0.02711297296019626	1155.5165749128134	0.026751927778919944	1186.8460645634832
48.2601	0.6894743240049065	22.7581	1.39185	0.02757897296019626	1156.28376922672	0.027205523763383945	1188.1728880325377
48.7101	0.6999263240049065	22.7726	1.40431	0.02799705296019626	1157.0204789983527	0.027612300258627088	1189.4136426249013
49.2601	0.7138913240049065	22.7992	1.42167	0.02855565296019626	1158.3719603725197	0.028155539449267995	1191.4500280717396
49.7301	0.7251803240049065	22.8057	1.43526	0.02900721296019626	1158.702209580493	0.02859446650683578	1192.3129313312443
50.1801	0.7364663240049065	22.8304	1.44855	0.02945865296019626	1159.9571565707909	0.029033084425851785	1194.127931894906
50.6501	0.7478553240049065	22.8446	1.46188	0.029914212960196262	1160.6786240712859	0.029475510384715128	1195.399411610102
51.1001	0.7591973240049065	22.8685	1.47726	0.03036789296019626	1161.892925005218	0.02991591610005779	1197.177164982986
51.5501	0.7699643240049064	22.8736	1.49017	0.03079857296019626	1162.1520436145508	0.030333815394839418	1197.9446681206548
52.0201	0.7818913240049065	22.8842	1.5044	0.03127565296019626	1162.6906038613993	0.030796533955127246	1199.0545116878495
52.4801	0.7925273240049064	22.9032	1.5172	0.031701092960196256	1163.6559477000899	0.031208986501548262	1200.5451130718156
52.9601	0.8048523240049065	22.9138	1.53197	0.032194092960196256	1164.1945079469385	0.031686723949399136	1201.6746941595322
53.4201	0.8157903240049065	22.9302	1.54588	0.03263161296019626	1165.0277521024402	0.03211050790878461	1203.0444867969345
53.8801	0.8274163240049065	22.942	1.56001	0.03309665296019626	1165.6272814338374	0.03256075106566831	1204.2056430483901
54.3601	0.8395473240049065	22.9645	1.5743	0.03358189296019626	1166.770451769129	0.03303033547188833	1205.9528121895598
54.8101	0.8504793240049064	22.9638	1.58693	0.034019172960196256	1166.734886469809	0.03345331842902359	1206.4262423713203
55.2801	0.8624173240049064	22.9862	1.60201	0.03449669296019626	1167.8729760480549	0.033915021446486567	1208.1607315192953
55.7501	0.8735773240049065	22.998	1.61588	0.03494309296019626	1168.4725053794523	0.03434644255857777	1209.3025487563598
56.2201	0.8854363240049065	23.0093	1.62988	0.03541745296019626	1169.046630925621	0.03480468159258126	1210.4512849847051
56.7001	0.8971173240049065	23.0202	1.64442	0.03588469296019626	1169.6004334436068	0.035255837411490236	1211.571185883843
57.1701	0.9090903240049065	23.0414	1.65845	0.03636361296019626	1170.6775539373036	0.03571806001981225	1213.247619409869
57.6801	0.9219343240049065	23.0461	1.67378	0.03687737296019626	1170.9163495184534	0.03621367052915994	1214.096668444837
58.1801	0.9344883240049064	23.06	1.6888	0.037379532960196256	1171.6225747478115	0.03669785357165279	1215.4172793975074
58.7001	0.9475083240049065	23.0573	1.70346	0.03790033296019626	1171.4853943075766	0.03719976179086263	1215.8850808098407
59.2001	0.9600783240049064	23.0762	1.71883	0.038403132960196255	1172.4456573892217	0.03768408406656169	1217.4712438585445
59.7301	0.9735463240049065	23.0928	1.73466	0.03894185296019626	1173.2890630588145	0.038202746123878376	1218.9791132322573
60.2601	0.9864873240049065	23.1069	1.75066	0.03945949296019626	1174.005449802264	0.03870085974540676	1220.3311095839686
60.8201	1.0006153240049065	23.1092	1.76688	0.04002461296019626	1174.122307214316	0.03924437918111963	1221.1160981285016
61.3501	1.0142433240049065	23.1268	1.78331	0.04056973296019626	1175.0165204543664	0.039768383308634525	1222.686626913019
61.8901	1.0274633240049065	23.1233	1.79872	0.041098532960196256	1174.8386939577654	0.04027643737280189	1223.1228407443025
62.4101	1.0410433240049064	23.1369	1.81458	0.04164173296019626	1175.5296769159863	0.04079805787556443	1224.4807698089078
62.9101	1.0538033240049065	23.1548	1.83039	0.04215213296019626	1176.439132427174	0.04128793359557135	1226.028551156822
63.4501	1.0674533240049064	23.1548	1.84634	0.042698132960196256	1176.439132427174	0.041811712229853054	1226.6708869231275
63.9501	1.0801433240049065	23.1566	1.86111	0.04320573296019626	1176.5305860539972	0.042298407727486324	1227.3634523745495
64.4701	1.0933833240049065	23.1683	1.87665	0.04373533296019626	1177.1250346283487	0.042805944830490064	1228.606989953602
64.9801	1.1062633240049065	23.1788	1.89197	0.04425053296019626	1177.6585141181515	0.04329943477107327	1229.7705310129927
65.5001	1.1194933240049065	23.1887	1.90668	0.04477973296019626	1178.1615090656799	0.043806081342885196	1230.9192668256228
66.0601	1.1338633240049065	23.1991	1.9244	0.04535453296019626	1178.689907798437	0.04435609386969997	1232.1488380715318
66.6101	1.1486233240049064	23.2032	1.94152	0.04594493296019626	1178.8982188373122	0.04492071890337497	1233.0626184686873
67.1701	1.1631733240049065	23.2118	1.95865	0.046526932960196256	1179.335163943246	0.04547699879844757	1234.2060120536355
67.7301	1.1776933240049066	23.2116	1.97558	0.04710773296019626	1179.3250024291547	0.04603182340500681	1234.8803297168702
68.2801	1.1915433240049065	23.2185	1.99158	0.04766173296019626	1179.6755746653105	0.04656075990320305	1235.9009568846745
68.8401	1.2060133240049065	23.2172	2.00797	0.04824053296019626	1179.609524823716	0.04711307574743401	1236.5145169861357
69.4001	1.2204933240049065	23.2292	2.02476	0.04881973296019626	1180.2192156692047	0.0476654680884083	1237.8372026126676
69.9601	1.2355633240049064	23.2384	2.04196	0.049422532960196254	1180.686645317413	0.04824004427188777	1239.0391699612765
70.5101	1.2506133240049064	23.2478	2.05945	0.05002453296019626	1181.1642364797128	0.04881352862047753	1240.2514257588973
71.0701	1.2648733240049066	23.2486	2.07493	0.050594932960196265	1181.2048825360785	0.0493566065298972	1240.9678643802479
71.6301	1.2797833240049066	23.2551	2.09207	0.05119133296019626	1181.5351317440516	0.04992412381334091	1242.0194900773306
72.1801	1.2938733240049065	23.2368	2.10858	0.05175493296019626	1180.605353204681	0.05046013371775676	1241.7075041122382
72.7401	1.3084233240049066	23.2455	2.12484	0.052336932960196265	1181.0473790676606	0.05101334151658867	1242.8597765687405
73.3001	1.3235133240049064	23.2486	2.14149	0.052940532960196254	1181.2048825360785	0.05158675763518553	1243.7384985527244
73.8601	1.3384833240049065	23.2411	2.1582	0.053539332960196265	1180.823825757648	nan	nan
74.4101	1.3536933240049065	23.2457	2.17475	0.05414773296019626	1181.0575405817522	nan	nan
74.9701	1.3684233240049064	23.2498	2.19139	0.05473693296019626	1181.2658516206275	nan	nan
75.5301	1.3838833240049064	23.2531	2.20872	0.055355332960196256	1181.4335166031367	nan	nan
76.0801	1.3987133240049066	23.2507	2.22498	0.055948532960196265	1181.311578434039	nan	nan
76.6401	1.4140433240049064	23.2464	2.24151	0.05656173296019626	1181.0931058810722	nan	nan
77.2001	1.4290333240049065	23.2371	2.25729	0.05716133296019626	1180.6205954758184	nan	nan
77.7601	1.4442733240049064	23.2502	2.27419	0.05777093296019625	1181.2861746488104	nan	nan
78.3101	1.4600133240049065	23.2378	2.29156	0.05840053296019626	1180.6561607751385	nan	nan
78.8101	1.4737533240049066	23.2459	2.30608	0.058950132960196265	1181.0677020958435	nan	nan
79.2701	1.4864233240049065	23.2382	2.31946	0.05945693296019626	1180.6764838033216	nan	nan
79.7301	1.4993333240049065	23.2458	2.3343	0.05997333296019626	1181.0626213387977	nan	nan
80.1901	1.5118833240049065	23.2392	2.34694	0.06047533296019626	1180.727291373779	nan	nan
80.6501	1.5247733240049064	23.2341	2.36111	0.060990932960196254	1180.4681727644463	nan	nan
81.1001	1.5368533240049065	23.2307	2.37334	0.06147413296019626	1180.2954270248908	nan	nan
81.5701	1.5507233240049065	23.2303	2.38818	0.062028932960196265	1180.275103996708	nan	nan
82.0201	1.5631533240049065	23.2249	2.40068	0.06252613296019625	1180.000743116238	nan	nan
82.4901	1.5767833240049065	23.2151	2.41486	0.06307133296019626	1179.5028289257552	nan	nan
82.9401	1.5893133240049064	23.2015	2.42785	0.06357253296019626	1178.8118459675347	nan	nan
83.3901	1.6023933240049064	23.2023	2.44156	0.06409573296019626	1178.8524920239006	nan	nan
83.8601	1.6153633240049066	23.186	2.45562	0.06461453296019626	1178.024328625445	nan	nan
84.3101	1.6286333240049065	23.203	2.46907	0.06514533296019626	1178.8880573232207	nan	nan
84.7801	1.6416733240049064	23.1705	2.4826	0.06566693296019625	1177.236811283355	nan	nan
85.2301	1.6553633240049064	23.1942	2.49636	0.06621453296019625	1178.4409507031955	nan	nan
85.6901	1.6687833240049066	23.1667	2.50973	0.06675133296019627	1177.0437425156167	nan	nan
86.1501	1.6822333240049065	23.1577	2.5229	0.06728933296019626	1176.5864743815	nan	nan
86.6101	1.6959033240049064	23.1505	2.53696	0.06783613296019625	1176.2206598742068	nan	nan
87.0801	1.7091333240049065	23.1324	2.55052	0.06836533296019626	1175.3010428489279	nan	nan
87.5301	1.7225033240049066	23.1318	2.56499	0.06890013296019626	1175.2705583066534	nan	nan
87.9901	1.7364733240049064	23.1193	2.57917	0.06945893296019626	1174.6354636759359	nan	nan
88.4501	1.7497533240049066	23.0968	2.59257	0.06999013296019627	1173.4922933406442	nan	nan
88.9101	1.7631633240049065	23.0803	2.60616	0.07052653296019626	1172.653968428097	nan	nan
89.3701	1.7771533240049064	23.0796	2.61996	0.07108613296019625	1172.6184031287767	nan	nan
89.8201	1.7905433240049065	23.0578	2.63322	0.07162173296019626	1171.510798092805	nan	nan
90.2901	1.8048733240049064	23.0383	2.64754	0.07219493296019626	1170.5200504688858	nan	nan
90.7401	1.8182933240049064	23.0192	2.66113	0.07273173296019625	1169.5496258731494	nan	nan
91.1901	1.8323133240049065	23.0036	2.67457	0.07329253296019626	1168.7570277740137	nan	nan
91.6601	1.8464533240049066	22.9722	2.68803	0.07385813296019626	1167.1616700616512	nan	nan
92.1101	1.8603433240049065	22.9466	2.70244	0.07441373296019627	1165.8609962579415	nan	nan
92.5801	1.8744233240049064	22.9223	2.71621	0.07497693296019625	1164.6263722958265	nan	nan
93.0301	1.8885633240049065	22.9132	2.72972	0.07554253296019625	1164.1640234046642	nan	nan
93.4901	1.9027633240049064	22.871	2.74358	0.07611053296019626	1162.0199439313615	nan	nan
93.9801	1.9175333240049064	22.833	2.75809	0.07670133296019625	1160.08925625398	nan	nan
94.4401	1.9317033240049064	22.8137	2.77144	0.07726813296019626	1159.1086701441523	nan	nan
94.8901	1.9462933240049065	22.7885	2.78584	0.07785173296019626	1157.8283193686254	nan	nan
95.3601	1.9599733240049064	22.7414	2.79879	0.07839893296019626	1155.4352828000815	nan	nan
95.8101	1.9741633240049066	22.725	2.81297	0.07896653296019626	1154.60203864458	nan	nan
96.2901	1.9888633240049065	22.6929	2.82744	0.07955453296019627	1152.9711156328974	nan	nan
96.7801	2.0035433240049065	22.6634	2.84148	0.08014173296019626	1151.4722923044037	nan	nan
97.2301	2.0179733240049065	22.6211	2.85547	0.08071893296019626	1149.3231320740554	nan	nan
97.7101	2.0332133240049064	22.5871	2.86968	0.08132853296019625	1147.5956746785037	nan	nan
98.1701	2.0475933240049065	22.5356	2.88247	0.08190373296019626	1144.979084799947	nan	nan
98.6401	2.0616433240049066	22.5205	2.89684	0.08246573296019627	1144.2118904860404	nan	nan
99.0901	2.0764133240049065	22.4711	2.91109	0.08305653296019626	1141.7019965054444	nan	nan
99.5501	2.0906933240049064	22.441	2.92482	0.08362773296019625	1140.1726886346764	nan	nan
100.04	2.1052933240049065	22.4023	2.93948	0.08421173296019627	1138.2064356579747	nan	nan
100.49	2.1194433240049064	22.371	2.95296	0.08477773296019625	1136.616158702658	nan	nan
101.04	2.1370933240049066	22.3188	2.97014	0.08548373296019626	1133.9640035247812	nan	nan
101.5	2.1514633240049066	22.2846	2.98367	0.08605853296019626	1132.2263846151382	nan	nan
101.96	2.1657633240049066	22.2417	2.99735	0.08663053296019627	1130.0467398425153	nan	nan
102.36	2.1784433240049066	22.214	3.0097	0.08713773296019627	1128.639370140845	nan	nan
102.74	2.1903833240049067	22.1799	3.02171	0.08761533296019626	1126.9068319882474	nan	nan
103.11	2.2016033240049064	22.1378	3.03157	0.08806413296019626	1124.7678332719904	nan	nan
103.48	2.2130333240049063	22.105	3.04276	0.08852133296019625	1123.1013449609875	nan	nan
103.83	2.2237933240049066	22.078	3.05344	0.08895173296019626	1121.7295405586376	nan	nan
104.21	2.2355233240049066	22.0382	3.06566	0.08942093296019626	1119.7073992544329	nan	nan
104.67	2.2499333240049064	22.006	3.07906	0.08999733296019626	1118.0713954857042	nan	nan
105.04	2.2617933240049064	21.9712	3.09029	0.09047173296019625	1116.3032920337866	nan	nan
105.4	2.2733133240049064	21.9379	3.10174	0.09093253296019625	1114.6113999375548	nan	nan
105.78	2.2853833240049064	21.9001	3.1133	0.09141533296019626	1112.6908737742647	nan	nan
106.15	2.2964633240049066	21.8864	3.12373	0.09185853296019626	1111.9948100589982	nan	nan
106.62	2.3118633240049067	21.8374	3.1376	0.09247453296019627	1109.5052391065853	nan	nan
106.99	2.3230233240049065	21.7947	3.1489	0.09292093296019627	1107.335755848054	nan	nan
107.35	2.3337433240049066	21.7706	3.15929	0.09334973296019626	1106.1112934000307	nan	nan
107.8	2.3478333240049065	21.7253	3.17301	0.09391333296019626	1103.80971045831	nan	nan
108.21	2.3605533240049064	21.6907	3.18524	0.09442213296019625	1102.0517685204838	nan	nan
108.63	2.3740233240049067	21.6583	3.19804	0.09496093296019627	1100.4056032376636	nan	nan
109.02	2.3868433240049063	21.6135	3.21019	0.09547373296019625	1098.129424081172	nan	nan
109.42	2.3985833240049064	21.5719	3.22102	0.09594333296019625	1096.0158291501436	nan	nan
109.8	2.4114733240049064	21.5501	3.23363	0.09645893296019625	1094.9082241141725	nan	nan
110.18	2.4229833240049063	21.502	3.24477	0.09691933296019625	1092.464379975171	nan	nan
110.55	2.4342433240049064	21.4761	3.25539	0.09736973296019626	1091.148463900324	nan	nan
110.91	2.4453633240049064	21.4413	3.26589	0.09781453296019625	1089.3803604484065	nan	nan
111.3	2.4585533240049067	21.4241	3.27856	0.09834213296019627	1088.506470236539	nan	nan
111.71	2.4707133240049064	21.3548	3.28918	0.09882853296019625	1084.9855056038407	nan	nan
112.08	2.4825233240049065	21.3294	3.30105	0.09930093296019626	1083.6949933142225	nan	nan
112.58	2.4973733240049065	21.2767	3.31509	0.09989493296019626	1081.0174343511171	nan	nan
112.95	2.5094633240049067	21.2534	3.32687	0.10037853296019626	1079.8336179594594	nan	nan
113.33	2.5218133240049063	21.2316	3.33867	0.10087253296019626	1078.726012923488	nan	nan
113.73	2.5343333240049066	21.1738	3.35021	0.10137333296019627	1075.7893353510499	nan	nan
114.09	2.5455133240049066	21.1329	3.36057	0.10182053296019626	1073.711305719342	nan	nan
114.44	2.5566133240049065	21.1054	3.37091	0.10226453296019626	1072.314097531763	nan	nan
114.81	2.5682833240049066	21.0761	3.38213	0.10273133296019626	1070.8254357173612	nan	nan
115.2	2.5808333240049066	21.0314	3.3937	0.10323333296019627	1068.5543373179153	nan	nan
115.59	2.5925033240049067	20.9749	3.40483	0.10370013296019627	1065.6837095870717	nan	nan
115.95	2.6038033240049065	20.9583	3.41553	0.10415213296019626	1064.8403039174789	nan	nan
116.32	2.6156733240049066	20.9131	3.42724	0.10462693296019626	1062.5438017328038	nan	nan
116.76	2.6296833240049065	20.8663	3.44019	0.10518733296019626	1060.1660074353972	nan	nan
117.13	2.6410233240049066	20.8323	3.45098	0.10564093296019626	1058.4385500398453	nan	nan
117.48	2.6523533240049066	20.7911	3.46146	0.10609413296019626	1056.3452781370002	nan	nan
117.84	2.6638333240049064	20.7663	3.47271	0.10655333296019626	1055.0852503896567	nan	nan
118.24	2.6766733240049065	20.711	3.48442	0.10706693296019626	1052.275591743362	nan	nan
118.65	2.6889533240049066	20.6761	3.49631	0.10755813296019627	1050.5024075343986	nan	nan
119.07	2.7019033240049066	20.6278	3.5083	0.10807613296019626	1048.0484018813056	nan	nan
119.43	2.7132833240049066	20.6114	3.5195	0.10853133296019626	1047.2151577258041	nan	nan
119.83	2.7260033240049064	20.5423	3.53109	0.10904013296019625	1043.7043546071973	nan	nan
120.25	2.7396333240049064	20.5157	3.5435	0.10958533296019626	1042.3528732330303	nan	nan
120.61	2.7516033240049067	20.4659	3.55442	0.11006413296019626	1039.8226562242514	nan	nan
121.02	2.7656233240049066	20.4237	3.56676	0.11062493296019626	1037.6785767509489	nan	nan
121.42	2.7784733240049064	20.3919	3.57935	0.11113893296019625	1036.0628960104034	nan	nan
121.77	2.7892633240049065	20.3445	3.58916	0.11157053296019626	1033.654617170722	nan	nan
122.16	2.8021033240049067	20.2998	3.60042	0.11208413296019627	1031.3835187712762	nan	nan
122.55	2.8144933240049066	20.2445	3.61156	0.11257973296019626	1028.5738601249814	nan	nan
122.95	2.8274233240049065	20.2103	3.62338	0.11309693296019625	1026.836241215338	nan	nan
123.3	2.8395633240049065	20.1797	3.63449	0.11358253296019626	1025.2815295593414	nan	nan
123.66	2.8512633240049063	20.1311	3.64584	0.11405053296019625	1022.8122816351113	nan	nan
124.02	2.8620033240049065	20.0844	3.65607	0.11448013296019627	1020.4395680947504	nan	nan
124.36	2.8738633240049065	20.0403	3.66608	0.11495453296019625	1018.1989542375787	nan	nan
124.73	2.8856233240049063	20.0084	3.67675	0.11542493296019625	1016.5781927399876	nan	nan
125.14	2.8993033240049066	19.9565	3.68966	0.11597213296019626	1013.9412798332481	nan	nan
125.57	2.9128933240049064	19.9057	3.70218	0.11651573296019625	1011.3602552540118	nan	nan
125.98	2.9269833240049064	19.856	3.71525	0.11707933296019625	1008.8351190022787	nan	nan
126.37	2.9392833240049066	19.8051	3.72637	0.11757133296019626	1006.2490136659966	nan	nan
126.76	2.9519433240049064	19.7548	3.73811	0.11807773296019626	1003.693392871989	nan	nan
127.2	2.9657433240049067	19.6955	3.75065	0.11862973296019627	1000.6805039438648	nan	nan
127.6	2.9791033240049063	19.6651	3.76279	0.11916413296019625	999.1359538019595	nan	nan
127.98	2.9918033240049065	19.6264	3.77419	0.11967213296019626	997.169700825258	nan	nan
128.35	3.0036533240049064	19.5813	3.78529	0.12014613296019626	994.8782793976288	nan	nan
128.76	3.0178733240049063	19.5345	3.79852	0.12071493296019625	992.5004851002222	nan	nan
129.15	3.0296333240049065	19.469	3.8093	0.12118533296019626	989.1725892352621	nan	nan
129.58	3.0439033240049063	19.4165	3.82206	0.12175613296019624	986.5051917862481	nan	nan
129.97	3.0565233240049063	19.3688	3.83368	0.12226093296019626	984.0816706754298	nan	nan
130.36	3.0695533240049064	19.314	3.84569	0.12278213296019626	981.297415814364	nan	nan
130.75	3.0823133240049065	19.2851	3.85762	0.12329253296019627	979.8290770281448	nan	nan
131.16	3.0961033240049063	19.2261	3.87014	0.12384413296019625	976.8314303711577	nan	nan
131.58	3.1098633240049063	19.179	3.88238	0.12439453296019626	974.438393802614	nan	nan
131.97	3.1221733240049065	19.1222	3.89381	0.12488693296019626	971.5525238006333	nan	nan
132.36	3.1355833240049065	19.0635	3.90583	0.12542333296019625	968.5701194147834	nan	nan
132.78	3.1492233240049066	19.0189	3.91811	0.12596893296019626	966.304101772383	nan	nan
133.16	3.1617633240049066	18.9499	3.93031	0.12647053296019625	962.7983794108218	nan	nan
133.56	3.1748133240049063	18.9002	3.94225	0.12699253296019625	960.2732431590888	nan	nan
133.94	3.1871133240049065	18.853	3.95295	0.12748453296019627	957.8751258334992	nan	nan
134.37	3.2014933240049066	18.8001	3.96621	0.12805973296019627	955.1874053563024	nan	nan
134.77	3.2143133240049067	18.7327	3.97805	0.12857253296019627	951.7629751074732	nan	nan
135.11	3.2253633240049067	18.6855	3.98783	0.12901453296019627	949.3648577818834	nan	nan
135.48	3.2376933240049066	18.6491	3.99876	0.12950773296019627	947.5154622172339	nan	nan
135.92	3.2525933240049065	18.5858	4.01241	0.13010373296019626	944.29934300728	nan	nan
136.34	3.2661533240049065	18.5137	4.02509	0.13064613296019625	940.6361171773009	nan	nan
136.74	3.2793733240049066	18.4724	4.03657	0.13117493296019625	938.53776451741	nan	nan
137.15	3.2927733240049064	18.4129	4.04898	0.13171093296019626	935.5147140751943	nan	nan
137.56	3.3071333240049063	18.3567	4.0619	0.13228533296019626	932.659328615488	nan	nan
137.99	3.3205433240049067	18.2819	4.07384	0.13282173296019628	928.858922345274	nan	nan
138.43	3.3341333240049065	18.2266	4.08649	0.13336533296019626	926.0492636989794	nan	nan
138.83	3.3483633240049064	18.1666	4.09944	0.13393453296019625	923.0008094715347	nan	nan
139.24	3.3622433240049063	18.0961	4.11204	0.13448973296019626	919.4188757542876	nan	nan
139.65	3.3752033240049064	18.0378	4.12414	0.13500813296019626	916.4567943966207	nan	nan
140.08	3.3899033240049063	17.9941	4.13728	0.13559613296019626	914.236503567632	nan	nan
140.5	3.4037733240049066	17.9264	4.14976	0.13615093296019626	910.7968310476657	nan	nan
140.96	3.4188933240049066	17.8391	4.16372	0.13675573296019627	906.3613301467338	nan	nan
141.42	3.4350633240049064	17.7683	4.17754	0.13740253296019625	902.7641541583495	nan	nan
141.85	3.4487433240049064	17.7105	4.19017	0.13794973296019625	899.8274765859113	nan	nan
142.3	3.4642533240049063	17.6369	4.20469	0.13857013296019624	896.0880394002463	nan	nan
142.75	3.4789733240049063	17.5764	4.21735	0.13915893296019624	893.014181387573	nan	nan
143.17	3.4926933240049065	17.5034	4.23022	0.13970773296019626	889.3052287441822	nan	nan
143.59	3.5077033240049067	17.4255	4.24237	0.14030813296019626	885.3473190055503	nan	nan
144.01	3.5214933240049064	17.3651	4.2556	0.14085973296019627	882.278541749923	nan	nan
144.45	3.5362233240049066	17.2848	4.2683	0.14144893296019626	878.198693842193	nan	nan
144.89	3.5514833240049066	17.2062	4.28142	0.14205933296019627	874.2052188042409	nan	nan
145.34	3.5659433240049063	17.1171	4.29456	0.14263773296019625	869.6782642764861	nan	nan
145.48	3.5712333240049063	17.0586	4.29897	0.14284933296019625	866.7060214047275	nan	nan