File: original_data/46NTAH.csv
Specimen name:	AWA_3_09_Rz
Specimen ID:	46NTAH
Material:	42CrMoS4
Specimen type:	Round Tensile Specimen
Gauge diameter:	4.994	mm
Gauge length:	25	mm
Parallel length:	30	mm
Original cross-section:	19.58785846946624	mm²
Cross-section after fracture:	9.59640336378453	mm²
Yield stress at 0.2% plastic strain:	1090.0500177016443	MPa
Yield stress at 1% plastic strain:	1134.4512277901738	MPa
Ultimate tensile strength:	1187.7459721421997	MPa
Uniform elongation:	4.904524316324483	%
Elongation after fracture:	13.187898072214626	%
Reduction of area:	51.008409731244974	%
Slope of linear-elastic region:	212849.8029269922	MPa
Crosshead seperation speed:	0.030013369031669547	mm/s
Strain rate:	0.001000445634388985	s-1
Test temperature:	RT	Cel
Machine type:	INSTRON 8852TT
Standard:	DIN EN ISO 6892-1
Date:	2022-09-06 00:00:00
Heat treatment batch:	Batch 3
Time	Displacement	Force	Machine Displacement	Engineering Strain	Engineering Stress	True Strain	True Stress
s	mm	kN	mm		MPa		MPa
0	0.0008549209937714926	0.140667	0	3.4196839750859706e-05	7.181336347680538	3.4196255052216166e-05	7.181581926688816
0.450001	0.0008018332937714927	0.141039	-0.000701904	3.20733317508597e-05	7.200327704013844	3.2072817412618726e-05	7.200558642513011
0.880001	0.0008013773937714927	0.145453	-6.1035e-05	3.2055095750859705e-05	7.425671378355815	3.205458199727962e-05	7.425909408962863
1.29	0.0020685709937714927	0.330854	0.0114136	8.274283975085971e-05	16.890769377149557	8.27394167510128e-05	16.892166967373402
1.69	0.0034452709937714925	0.542064	0.0231323	0.0001378108397508597	27.673469299616137	0.0001378013447095114	27.677283003659138
2.13	0.005083490993771493	0.791684	0.0361252	0.0002033396397508597	40.41707781552973	0.00020331896904846446	40.42529620957252
2.55	0.006887890993771493	1.07656	0.0497055	0.0002755156397508597	54.96057681232244	0.00027547769228696906	54.97571931080396
2.96	0.008676320993771492	1.33719	0.0613403	0.00034705283975085965	68.2662682132621	0.00034699263084414994	68.2899602155047
3.36	0.010361770993771493	1.62989	0.0731277	0.00041447083975085973	83.20919831745209	0.00041438497043844283	83.24368610375372
3.78001	0.012590320993771493	1.95966	0.0858612	0.0005036128397508597	100.04462729066265	0.0005034860693650292	100.09501104951431
4.19001	0.014512220993771493	2.27516	0.0978241	0.0005804888397508598	116.15154375076496	0.000580320421277932	116.21896842563211
4.61001	0.016719020993771493	2.61824	0.111176	0.0006687608397508597	133.66647528525593	0.0006685373188696014	133.75586618951422
5.02001	0.018650820993771494	2.95745	0.122856	0.0007460328397508598	150.9838354514407	0.000745754695579699	151.09647435095903
5.42001	0.020682720993771494	3.30875	0.135162	0.0008273088397508598	168.91841469845792	0.0008269668084233245	169.05816239613463
5.84001	0.023064020993771493	3.6942	0.148033	0.0009225608397508598	188.59642087768592	0.0009221355420546643	188.77041255010485
6.25001	0.025331420993771496	4.0798	0.160049	0.00101325683975086	208.282084861887	0.0010127438415426864	208.4931281089709
6.67001	0.027773820993771493	4.47214	0.172729	0.0011109528397508597	228.31183954954636	0.0011103361883162653	228.56548323604267
7.09001	0.030048820993771493	4.85831	0.184982	0.0012019528397508596	248.02660319264533	0.0012012310727317799	248.3247194726865
7.50001	0.03244162099377149	5.28184	0.197639	0.0012976648397508598	269.6486707943795	0.0012968236004185726	269.9985843935549
7.90001	0.03457282099377149	5.66706	0.209793	0.0013829128397508598	289.314935005982	0.0013819574964592952	289.7150323443335
8.31001	0.03719452099377149	6.09839	0.222748	0.0014877808397508595	311.3352084663178	0.0014866751903441218	311.7984070242138
8.72001	0.03971442099377149	6.51123	0.235359	0.0015885768397508595	332.41152983363514	0.00158731638627112	332.939591091195
9.12001	0.041953420993771494	6.90168	0.246864	0.0016781368397508598	352.3447961786333	0.001676730341435706	352.9360789613952
9.54001	0.04432292099377149	7.30023	0.258949	0.0017729168397508596	372.69158399217935	0.0017713470777883096	373.3523351774725
9.96001	0.046961220993771494	7.71931	0.271965	0.0018784488397508598	394.08647004637805	0.0018766867610339238	394.8267413187982
10.37	0.04935302099377149	8.15443	0.28476	0.0019741208397508598	416.3002307123676	0.0019721748238985697	417.1220576734099
10.77	0.05174062099377149	8.55268	0.296524	0.0020696248397508595	436.6317029159674	0.0020674861166568538	437.53536673414504
11.2	0.054320320993771494	8.98102	0.30954	0.0021728128397508597	458.4993307971725	0.0021704556957369368	459.4955640301458
11.6	0.05679012099377149	9.39456	0.321899	0.0022716048397508595	479.6113885876977	0.0022690286461351543	480.70087613921316
12.01	0.05922512099377149	9.80742	0.333549	0.0023690048397508596	500.6887309956782	0.002366203171689879	501.8748650226157
12.41	0.06153042099377149	10.2077	0.345856	0.0024612168397508596	521.1238388265808	0.0024581930061086336	522.4064375942964
12.83	0.06398892099377149	10.6174	0.358284	0.0025595568397508593	542.0398568097944	0.0025562867529364762	543.4272386327095
13.24	0.0664235209937715	11.0219	0.370766	0.00265694083975086	562.690404220607	0.0026534174120838253	564.1854393357165
13.64	0.0685567209937715	11.3956	0.382126	0.00274226883975086	581.768549010275	0.0027385156804383766	583.363914774173
14.08	0.0711937209937715	11.825	0.395012	0.0028477488397508598	603.6902920466234	0.0028437016847238255	605.4094503753681
14.5	0.07373572099377149	12.2731	0.408585	0.0029494288397508596	626.5667081029525	0.0029450878081251205	628.4147220218591
14.91	0.07626942099377149	12.6893	0.420921	0.0030507768397508594	647.8145643016675	0.0030461326632545914	649.7909019708924
15.32	0.0788257209937715	13.089	0.432747	0.00315302883975086	668.2200619533406	0.003148068468379546	670.3269790799795
15.72	0.08100922099377149	13.4827	0.444717	0.0032403688397508595	688.3192474060895	0.0032351301584312413	690.549655647185
16.12	0.08347742099377149	13.8787	0.456589	0.0033390968397508597	708.5358525350928	0.003333534434731585	710.9017223611429
16.53	0.08589992099377149	14.2806	0.468544	0.0034359968397508593	729.0536646597049	0.0034301072897370707	731.5586907474843
16.95	0.08821542099377148	14.6807	0.480751	0.003528616839750859	749.4795831246397	0.003522405877798306	752.1242094027027
17.37	0.09073192099377149	15.0987	0.493736	0.0036292768397508594	770.8193329830318	0.003622706905835353	773.6168497358593
17.79	0.0933039209937715	15.5272	0.507233	0.00373215683975086	792.6951291895417	0.0037252096224502937	795.6535917377836
18.2	0.09561822099377149	15.9199	0.519142	0.0038247288397508595	812.7432626091365	0.003817433161146476	815.8517852049508
18.6	0.09784222099377149	16.2927	0.53006	0.003913688839750859	831.7754605689659	0.0039060502830532843	835.0307709061732
19.04	0.1003857209937715	16.7062	0.543205	0.00401542883975086	852.8854762781649	0.004007388521730472	856.3101772166169
19.45	0.1029509209937715	17.1353	0.555756	0.00411803683975086	874.7919037045671	0.004109580932586516	878.3943289911383
19.85	0.10528792099377149	17.5182	0.568031	0.004211516839750859	894.3397271992523	0.004202673224034732	898.1062540208102
20.28	0.10785692099377149	17.9086	0.579704	0.00431427683975086	914.2704409425927	0.0043049970283024165	918.2148567312202
20.68	0.10996792099377149	18.2701	0.591621	0.0043987168397508596	932.7257509277812	0.004389070761399574	936.8285473952565
21.09	0.11259092099377149	18.6755	0.603928	0.00450363683975086	953.4222451684326	0.0044935258135859486	957.7161127156111
21.49	0.11515492099377149	19.0883	0.616539	0.00460619683975086	974.4965244544237	0.0045956207795950785	978.9852472657138
21.91	0.11734592099377149	19.4567	0.628761	0.00469383683975086	993.3040934683753	0.0046828551384132016	997.9665008153726
22.33	0.1198379209937715	19.8338	0.641411	0.00479351683975086	1012.5558151707669	0.0047820645212432785	1017.4095185219755
22.74	0.12270092099377149	20.1997	0.653	0.004908036839750859	1031.2357541018332	0.0048960316920546865	1036.2970971734333
23.15	0.12592792099377148	20.5574	0.665779	0.0050371168397508595	1049.4970663610366	0.0050244730079196075	1054.783505707273
23.55	0.1298299209937715	20.8287	0.677269	0.00519319683975086	1063.3474829557297	0.005179758697575689	1068.8696557437725
23.97	0.1356349209937715	21.0317	0.690239	0.00542539683975086	1073.7110456860016	0.005410732390708876	1079.536354200072
24.38	0.1434509209937715	21.1318	0.702499	0.005738036839750859	1078.8213542047217	0.005721637011668842	1085.0116708786584
24.78	0.15226992099377148	21.1865	0.714287	0.006090796839750859	1081.6139004182482	0.006072322912685577	1088.2017909447463
25.2	0.1623629209937715	21.2315	0.72657	0.0064945168397508605	1083.9112419101805	0.006473518332995042	1090.9507217235614
25.61	0.17202292099377148	21.3014	0.738655	0.006880916839750859	1087.4797790276486	0.006857351371066642	1094.9626369520483
26.03	0.1810669209937715	21.3756	0.751503	0.00724267683975086	1091.2678398876787	0.007216574613399437	1099.1715401975982
26.44	0.1901419209937715	21.4482	0.763382	0.0076056768397508604	1094.9742174946628	0.00757689950163677	1103.302237540786
26.84	0.19902792099377148	21.5188	0.77552	0.00796111683975086	1098.5784910353386	0.00792959434142004	1107.3244027601081
27.25	0.2084519209937715	21.5873	0.78788	0.008338076839750859	1102.075555306391	0.008303507107515144	1111.2647459697469
27.65	0.21732092099377148	21.6479	0.79995	0.00869283683975086	1105.1693085155264	0.008655271675179349	1114.776364994752
28.07	0.2263739209937715	21.6883	0.811768	0.00905495683975086	1107.2318106549499	0.00901420652820929	1117.2577469120297
28.5	0.2359209209937715	21.762	0.824654	0.00943683683975086	1110.9943454984032	0.009392588056191673	1121.4786178667573
28.9	0.2453099209937715	21.7958	0.836372	0.00981239683975086	1112.71990421901	0.009764567897081428	1123.6383534906963
29.32	0.25493892099377147	21.8402	0.849274	0.010197556839750859	1114.9866144910497	0.010145912557256031	1126.3567538678835
29.74	0.2649119209937715	21.8879	0.861961	0.01059647683975086	1117.4217964724978	0.01054072766313365	1129.2625306590514
30.15	0.2747489209937715	21.9206	0.87413	0.010989956839750861	1119.0911979566351	0.010930006101506233	1131.3899619219237
30.56	0.2842439209937715	21.951	0.885864	0.011369756839750859	1120.6431797645184	0.011305606942341787	1133.3846202225661
30.96	0.2943059209937715	21.9966	0.898499	0.011772236839750861	1122.9711524763431	0.011703483123615209	1136.1910348475026
31.37	0.3045849209937715	22.0308	0.911201	0.01218339683975086	1124.7171320102113	0.012109776620186176	1138.4200071619582
31.77	0.3143079209937715	22.0531	0.92318	0.01257231683975086	1125.855592349547	0.012493941487242064	1140.0102055723708
32.19	0.3241469209937715	22.0816	0.935524	0.01296587683975086	1127.3105752944373	0.012882539447212064	1141.9271453738538
32.61	0.3344989209937715	22.1046	0.947723	0.01337995683975086	1128.4847720569803	0.013291235730819008	1143.5838496014187
33.02	0.3442129209937715	22.1279	0.960083	0.013768516839750859	1129.6742844294697	0.013674591967230573	1145.2282238380703
33.43	0.35463292099377147	22.1566	0.972862	0.014185316839750859	1131.1394777809908	0.014085646695347839	1147.1850496632644
33.83	0.36487192099377147	22.1784	0.984695	0.014594876839750859	1132.252412103749	0.014489396699256248	1148.7774966099141
34.25	0.3752389209937715	22.2107	0.997787	0.01500955683975086	1133.9013927746248	0.014898028055089935	1150.9207501801482
34.67	0.3857039209937715	22.2233	1.0103	0.01542815683975086	1134.5446483923658	0.015310352947511442	1152.0485811694634
35.09	0.3961599209937715	22.2477	1.02251	0.01584639683975086	1135.7903180013243	0.015722153513961418	1153.7885021071202
35.52	0.4066779209937715	22.279	1.03477	0.01626711683975086	1137.3882466390462	0.016136224876785395	1155.8902741392828
35.9301	0.4169369209937715	22.2902	1.04763	0.01667747683975086	1137.9600294103714	0.016539934851813057	1156.938331445425
36.3301	0.4265619209937715	22.3081	1.05975	0.01706247683975086	1138.873860803829	0.01691854766698896	1158.305869677192
36.7301	0.4366269209937715	22.3315	1.07175	0.01746507683975086	1140.068478379634	0.01731431522936658	1159.979861957112
37.1501	0.4471179209937715	22.354	1.08437	0.01788471683975086	1141.2171491256	0.017726666960994508	1161.627494690379
37.5701	0.45736892099377147	22.3829	1.09682	0.018294756839750858	1142.692552883752	0.01812942124748359	1163.5978352813543
38.0101	0.4682989209937715	22.4023	1.10973	0.01873195683975086	1143.6829623269405	0.01855867433854722	1165.106382215607
38.4301	0.4787019209937715	22.4106	1.12201	0.01914807683975086	1144.106694202119	0.0189670595220775	1166.0141370955746
38.8401	0.48914392099377146	22.4418	1.1349	0.01956575683975086	1145.6995176365253	0.01937680805955612	1168.1159958100216
39.2401	0.4987859209937715	22.455	1.14693	0.01995143683975086	1146.3734044741589	0.01975501522132215	1169.2452010482953
39.6801	0.5094019209937715	22.4751	1.15979	0.02037607683975086	1147.3995503405554	0.020171262126080534	1170.7790517441902
40.1001	0.5199059209937715	22.4899	1.17199	0.020796236839750862	1148.155120431235	0.020582947120158103	1172.0324262444958
40.5101	0.5301439209937715	22.5072	1.18465	0.02120575683975086	1149.0383206048002	0.020984043697690975	1173.4045478311011
40.9101	0.5400679209937715	22.5243	1.19608	0.02160271683975086	1149.9113103717343	0.02137268512943663	1174.7525188005218
41.3301	0.5502339209937714	22.5505	1.20918	0.022009356839750856	1151.2488736403704	0.021770647160101894	1176.5871209116826
41.7401	0.5602259209937714	22.5583	1.22134	0.02240903683975086	1151.647079498972	0.02216164345159255	1177.454381329856
42.1501	0.5707719209937715	22.584	1.23409	0.02283087683975086	1152.9591167510312	0.022574152520245444	1179.2821843468419
42.5501	0.5807089209937715	22.6016	1.24577	0.023228356839750858	1153.8576325345425	0.02296268477625971	1180.659849365325
42.9701	0.5909739209937714	22.6148	1.25837	0.02363895683975086	1154.5315193721758	0.02336388323476589	1181.8234401287466
43.3801	0.6007099209937715	22.6252	1.27036	0.02402839683975086	1155.0624605169778	0.023744257521630077	1182.8167596929786
43.7801	0.6110489209937715	22.648	1.28304	0.02444195683975086	1156.2264468728902	0.024148031981803243	1184.486883784336
44.2001	0.6213279209937715	22.6676	1.29521	0.02485311683975086	1157.2270667227094	0.02454930167770761	1185.987766222091
44.6101	0.6308679209937715	22.6694	1.30685	0.02523471683975086	1157.3189603823866	0.024921578414477816	1186.523576640911
45.0201	0.6408419209937715	22.6948	1.31915	0.02563367683975086	1158.6156820244996	0.025310642877377713	1188.3152619989833
45.4201	0.6506099209937715	22.7046	1.33164	0.026024396839750857	1159.1159919494091	0.02569152506211988	1189.2812865072021
45.8301	0.6609509209937715	22.7271	1.34355	0.02643803683975086	1160.2646626953754	0.02609459212811089	1190.9397825915767
46.2301	0.6709829209937714	22.7437	1.35599	0.026839316839750858	1161.1121264457327	0.026485459932102353	1192.2755826938867
46.6601	0.6816429209937714	22.754	1.36967	0.027265716839750858	1161.6379623872192	0.02690062858135173	1193.3108541399743
47.0601	0.6914269209937715	22.7681	1.38121	0.02765707683975086	1162.3577960546916	0.027281528541131726	1194.5052149354597
47.4801	0.7011799209937715	22.7865	1.39324	0.02804719683975086	1163.2971534647259	0.027661077301795706	1195.9243777110728
47.8901	0.7114349209937715	22.7985	1.40633	0.02845739683975086	1163.9097778625744	0.02806000663723286	1197.0316202968759
48.2901	0.7213069209937715	22.8122	1.41824	0.02885227683975086	1164.609190716785	0.028443886623703733	1198.2108174974637
48.7001	0.7311249209937715	22.821	1.42973	0.029244996839750858	1165.0584486085406	0.02882552067938115	1199.1305792562223
49.1001	0.7409949209937715	22.8495	1.44205	0.029639796839750862	1166.513431553431	0.029209029272043455	1201.0886526755153
49.5201	0.7516849209937715	22.8495	1.45564	0.03006739683975086	1166.513431553431	0.029624233925845934	1201.5874538188477
49.9301	0.7618719209937715	22.8771	1.46754	0.03047487683975086	1167.9224676684826	0.030019741468221266	1203.5147610290576
50.3501	0.7723529209937715	22.885	1.47994	0.030894116839750862	1168.3257787303996	0.030426500284392335	1204.4201718453896
50.7601	0.7822719209937715	22.8951	1.49219	0.03129087683975086	1168.8414042652555	0.030811296028820257	1205.4154766913211
51.1601	0.7920919209937715	22.9035	1.50416	0.03168367683975086	1169.2702413437496	0.03119210538397806	1206.3170218088223
51.5801	0.8023599209937715	22.9148	1.51727	0.03209439683975086	1169.8471293183902	0.031590132682223555	1207.392667328578
51.9901	0.8122369209937715	22.9284	1.52907	0.03248947683975086	1170.5414369692855	0.03197285387835324	1208.5717158756677
52.3901	0.8220809209937715	22.9489	1.54105	0.03288323683975086	1171.5880036489432	0.03235415067980975	1210.1136094515423
52.8301	0.8329199209937715	22.9632	1.55395	0.03331679683975086	1172.3180477230462	0.032773819636634845	1211.3759299506082
53.2401	0.8432639209937715	22.9688	1.56654	0.03373055683975086	1172.603939108709	0.03317415880137597	1212.156522927331
53.6401	0.8533389209937715	22.9756	1.57868	0.03413355683975086	1172.9510929341563	0.03356393296732459	1212.9880857350724
54.0501	0.8633099209937715	22.9933	1.59063	0.03453239683975086	1173.8547139209832	0.03394953413626382	1214.3907307343147
54.4601	0.8735559209937714	22.9968	1.60322	0.03494223683975086	1174.0333960370222	0.03434561534324088	1215.056749019125
54.8601	0.8835729209937715	23.0123	1.61528	0.03534291683975086	1174.82470255091	0.03473269246089347	1216.3464343144517
55.2801	0.8940079209937715	23.0289	1.62804	0.03576031683975086	1175.6721663012672	0.0351357626689484	1217.7145754678768
55.6901	0.9039599209937715	23.0378	1.64043	0.03615839683975086	1176.1265293963381	0.03552002485285541	1218.6533791800098
56.0901	0.9136389209937715	23.0386	1.65205	0.03654555683975086	1176.1673710228615	0.03589360449872378	1219.1510625336377
56.5101	0.9241329209937715	23.0528	1.66461	0.036965316839750864	1176.892309893649	0.03629848301762855	1220.396507015134
56.9201	0.9343049209937715	23.0585	1.67766	0.03737219683975086	1177.1833064826271	0.036690781766057924	1221.1772327289648
57.3201	0.9444289209937715	23.0746	1.68923	0.03777715683975086	1178.0052442164072	0.03708107657006574	1222.5069330852195
57.7601	0.9554419209937715	23.0815	1.70217	0.03821767683975086	1178.3575032451702	0.03750547069616385	1223.3915895058897
58.1801	0.9660209209937715	23.0936	1.71496	0.03864083683975086	1178.9752328463342	0.03791297077676007	1224.5318224568566
58.6001	0.9765659209937715	23.0958	1.72841	0.03906263683975086	1179.087547319273	0.03831899599752726	1225.1458159824783
59.0101	0.9864109209937715	23.1078	1.74055	0.03945643683975086	1179.7001717171215	0.03869791963570651	1226.2469370323213
59.4101	0.9963889209937715	23.1095	1.75253	0.03985555683975086	1179.7869601734835	0.03908181585341231	1226.8080264234748
59.8201	1.0066849209937716	23.1194	1.76505	0.04026739683975086	1180.2923753017085	0.039477792451480934	1227.8196767649147
60.2301	1.0166449209937716	23.1357	1.77734	0.04066579683975086	1181.1245234421197	0.039860697588539294	1229.1558933548645
60.6301	1.0267149209937716	23.138	1.78916	0.041068596839750865	1181.241943118374	0.04024768260089232	1229.7538922505064
61.0401	1.0372949209937716	23.1506	1.80172	0.041491796839750864	1181.885198736115	0.040654105393825184	1230.9237392899822
61.4401	1.0474949209937716	23.1496	1.81352	0.04189979683975086	1181.8341467029609	0.041045774445820485	1231.352757348095
61.8701	1.0581249209937715	23.1626	1.82614	0.04232499683975086	1182.4978231339637	0.0414537918604375	1232.547039761121
62.2701	1.0679649209937716	23.1601	1.83817	0.042718596839750864	1182.3701930510783	0.04183133792793314	1232.8793886433657
62.6901	1.0787349209937716	23.1658	1.85071	0.04314939683975086	1182.6611896400564	0.04224440338311145	1233.6923066388072
63.1001	1.0891749209937716	23.1713	1.8635	0.04356699683975086	1182.9419758224037	0.04264464944131059	1234.479205144667
63.5301	1.0997749209937715	23.1853	1.87658	0.04399099683975086	1183.6567042865606	0.04305086570654886	1235.7269426241808
63.9601	1.1110049209937716	23.1886	1.88969	0.04444019683975086	1183.825175995969	0.04348104507591136	1236.4345998410824
64.3601	1.1209049209937716	23.1886	1.90141	0.04483619683975086	1183.825175995969	0.04386012369465244	1236.9033946107768
64.7701	1.1306349209937716	23.1974	1.91347	0.04522539683975087	1184.2744338877244	0.04423255291461005	1237.8337151274682
65.1701	1.1407549209937715	23.2062	1.92531	0.045630196839750864	1184.72369177948	0.044619762826457854	1238.7828670360939
65.5901	1.1505849209937715	23.2125	1.93771	0.04602339683975086	1185.0453195883506	0.04499573330820477	1239.5851306048546
66.0101	1.1588449209937717	23.2187	1.95035	0.04635379683975087	1185.3618421939054	0.04531154634970067	1240.3078642085547
66.4401	1.1571949209937715	23.2142	1.964	0.04628779683975086	1185.1321080447124	0.04524846818072864	1239.9892622901516
66.8401	1.1644949209937716	23.2208	1.97616	0.046579796839750866	1185.469051463529	0.045527511157720135	1240.6879590405122
67.2601	1.1740749209937715	23.2306	1.98842	0.04696299683975086	1185.9693613884388	0.045893589181476346	1241.6660367593654
67.6801	1.1841749209937715	23.2307	2.00146	0.04736699683975086	1185.974466591754	0.046279392761838734	1242.1505154028307
68.1001	1.1945449209937715	23.2295	2.01388	0.04778179683975086	1185.9132041519695	0.04667535509794686	1242.5782679423369
68.5401	1.2058849209937716	23.242	2.02748	0.048235396839750866	1186.551354566395	0.047108175981715364	1243.785130024649
68.9501	1.2159049209937716	23.2318	2.03903	0.048636196839750866	1186.0306238282237	0.04749045976684479	1243.7146427067057
69.3601	1.2270149209937715	23.2397	2.05135	0.04908059683975086	1186.4339348901408	0.04791415853112733	1244.664820525483
69.7601	1.2373249209937716	23.2472	2.06364	0.049492996839750864	1186.816825138796	0.04830718740230975	1245.5559465147537
70.1601	1.2477149209937717	23.2441	2.07593	0.049908596839750866	1186.6585638360184	0.04870310975149735	1245.8830276849478
70.5801	1.2586149209937716	23.2433	2.08799	0.050344596839750864	1186.6177222094955	0.049118297794134666	1246.3575130370361
71.0001	1.2694349209937716	23.252	2.10087	0.05077739683975087	1187.0618748979355	0.04953026816750962	1247.3377867929667
71.4001	1.2796549209937715	23.2379	2.11306	0.05118619683975086	1186.3420412304633	0.049919237801791985	1247.0663784721578
71.8001	1.2901549209937715	23.2495	2.1255	0.05160619683975086	1186.9342448150503	0.05031870662890723	1248.1874070888166
72.2101	1.3005049209937716	23.251	2.13718	0.052020196839750864	1187.0108228647814	0.05071231264810243	1248.759359521122
72.6101	1.3112449209937715	23.25	2.14888	0.05244979683975086	1186.9597708316273	0.05112058647216034	1249.2155696687034
73.0301	1.3226749209937716	23.2463	2.16168	0.052906996839750864	1186.7708783089574	0.05155490716170767	1249.5593614171578
73.4401	1.3337749209937717	23.2499	2.17435	0.05335099683975087	1186.9546656283121	0.05197650794177272	1250.279880243176
73.8501	1.3440249209937716	23.2492	2.18678	0.053760996839750864	1186.918929205104	0.05236566618908371	1250.72887400714
74.2501	1.3548749209937716	23.2563	2.19798	0.05419499683975086	1187.2813986404979	0.05277743949690766	1251.6261102877145
74.6701	1.3663149209937715	23.2654	2.21123	0.05465259683975086	1187.7459721421997	nan	nan
75.0801	1.3773049209937716	23.2434	2.22314	0.05509219683975086	1186.6228274128107	nan	nan
75.4801	1.3878449209937715	23.248	2.23587	0.05551379683975086	1186.8576667653192	nan	nan
75.9001	1.3985149209937715	23.2436	2.24791	0.05594059683975086	1186.6330378194416	nan	nan
76.3101	1.4094649209937715	23.2508	2.25995	0.05637859683975086	1187.0006124581507	nan	nan
76.7301	1.4209149209937717	23.2481	2.2725	0.05683659683975087	1186.8627719686347	nan	nan
77.1401	1.4319249209937717	23.2439	2.28586	0.05727699683975087	1186.6483534293877	nan	nan
77.5401	1.4426849209937715	23.2465	2.29743	0.05770739683975086	1186.781088715588	nan	nan
77.9501	1.4531749209937717	23.2379	2.30912	0.058126996839750866	1186.3420412304633	nan	nan
78.3601	1.4644849209937716	23.2365	2.32222	0.058579396839750865	1186.2705683840477	nan	nan
78.7601	1.4750749209937717	23.2351	2.33448	0.05900299683975087	1186.199095537632	nan	nan
79.1701	1.4854949209937716	23.2355	2.34628	0.05941979683975086	1186.2195163508936	nan	nan
79.6001	1.4969749209937715	23.2218	2.35906	0.05987899683975086	1185.5201034966833	nan	nan
80.0101	1.5074749209937717	23.2263	2.37154	0.06029899683975087	1185.7498376458764	nan	nan
80.4101	1.5167349209937715	23.22	2.38326	0.06066939683975086	1185.4282098370059	nan	nan
80.8301	1.5109649209937717	23.2186	2.39607	0.06043859683975086	1185.3567369905902	nan	nan
81.2401	1.5167149209937716	23.2151	2.40904	0.060668596839750864	1185.178054874551	nan	nan
81.6401	1.5158749209937716	23.2079	2.42101	0.06063499683975086	1184.8104802358419	nan	nan
82.0701	1.5099449209937716	23.2048	2.43347	0.06039779683975086	1184.6522189330644	nan	nan
82.4701	1.5184749209937716	23.1883	2.44503	0.06073899683975086	1183.8098603860228	nan	nan
82.8801	1.5266149209937716	23.1898	2.4583	0.061064596839750865	1183.8864384357537	nan	nan
83.2801	1.5239549209937715	23.1837	2.47021	0.06095819683975086	1183.575021033514	nan	nan
83.7001	1.5343449209937716	23.1738	2.48266	0.06137379683975087	1183.0696059052889	nan	nan
84.1301	1.5463549209937717	23.1743	2.49615	0.061854196839750866	1183.095131921866	nan	nan
84.5301	1.5571849209937716	23.1611	2.50793	0.06228739683975086	1182.4212450842326	nan	nan
84.9501	1.5685549209937717	23.1493	2.5205	0.06274219683975087	1181.8188310930145	nan	nan
85.3701	1.5802549209937715	23.1397	2.53313	0.06321019683975086	1181.328731574736	nan	nan
85.7901	1.5921449209937717	23.1298	2.54515	0.06368579683975087	1180.8233164465107	nan	nan
86.2101	1.6039749209937717	23.1185	2.55882	0.06415899683975086	1180.2464284718699	nan	nan
86.6101	1.6134949209937717	23.1012	2.57019	0.06453979683975086	1179.3632282983049	nan	nan
87.0101	1.6242049209937717	23.0913	2.58215	0.06496819683975087	1178.85781317008	nan	nan
87.4201	1.6361749209937717	23.0759	2.59488	0.06544699683975087	1178.0716118595076	nan	nan
87.8201	1.6478949209937717	23.0671	2.60668	0.06591579683975086	1177.622353967752	nan	nan
88.2401	1.6604649209937716	23.0451	2.61948	0.06641859683975086	1176.499209238363	nan	nan
88.6601	1.6729849209937715	23.0292	2.63217	0.06691939683975086	1175.6874819112136	nan	nan
89.0901	1.6856549209937717	23.0106	2.64496	0.06742619683975087	1174.7379140945482	nan	nan
89.4901	1.6982049209937715	22.9987	2.65726	0.06792819683975086	1174.130394900015	nan	nan
89.9101	1.7104649209937717	22.9735	2.66915	0.06841859683975086	1172.843883664533	nan	nan
90.3201	1.7232049209937716	22.956	2.68204	0.06892819683975086	1171.950473084337	nan	nan
90.7201	1.7355149209937717	22.9362	2.69419	0.06942059683975087	1170.939642827887	nan	nan
91.1601	1.7484649209937717	22.9098	2.70677	0.06993859683975087	1169.5918691526201	nan	nan
91.5701	1.7614049209937717	22.8806	2.71911	0.07045619683975086	1168.101149784522	nan	nan
91.9801	1.7735849209937715	22.8569	2.73117	0.07094339683975086	1166.8912165987708	nan	nan
92.3801	1.7862149209937717	22.8294	2.74297	0.07144859683975087	1165.4872856870347	nan	nan
92.7801	1.7985949209937715	22.8051	2.75543	0.07194379683975086	1164.246721281391	nan	nan
93.2001	1.8113949209937716	22.7797	2.76708	0.07245579683975087	1162.9499996392783	nan	nan
93.6301	1.8251349209937715	22.744	2.7809	0.07300539683975087	1161.1274420556788	nan	nan
94.0301	1.8375349209937717	22.7184	2.79269	0.07350139683975086	1159.8205100069351	nan	nan
94.4401	1.8497949209937716	22.6954	2.80487	0.07399179683975086	1158.6463132443919	nan	nan
94.8401	1.8623149209937715	22.6699	2.81646	0.07449259683975086	1157.3444863989637	nan	nan
95.2601	1.8754749209937716	22.6365	2.83025	0.07501899683975086	1155.6393484916186	nan	nan
95.6801	1.8886349209937716	22.6087	2.84273	0.07554539683975087	1154.220101969936	nan	nan
96.1101	1.9023649209937716	22.5671	2.85527	0.07609459683975087	1152.0963373907275	nan	nan
96.5201	1.9146449209937717	22.5368	2.86721	0.07658579683975086	1150.54946078616	nan	nan
96.9201	1.9276749209937716	22.5146	2.87911	0.07710699683975086	1149.4161056501403	nan	nan
97.3201	1.9402149209937716	22.4729	2.89108	0.07760859683975087	1147.2872358676161	nan	nan
97.7501	1.9538949209937717	22.4325	2.90414	0.07815579683975087	1145.2247337281926	nan	nan
98.1501	1.9659849209937716	22.4018	2.9162	0.07863939683975087	1143.6574363103637	nan	nan
98.5701	1.9791649209937716	22.3702	2.92893	0.07916659683975086	1142.0441920626956	nan	nan
98.9901	1.9924649209937717	22.3427	2.94072	0.07969859683975086	1140.6402611509593	nan	nan
99.4001	2.0051549209937716	22.2963	2.95235	0.08020619683975086	1138.2714468126112	nan	nan
99.8001	2.0176649209937714	22.2673	2.9645	0.08070659683975086	1136.7909378511438	nan	nan
100.21	2.0306849209937714	22.2346	2.97732	0.08122739683975086	1135.1215363670065	nan	nan
100.61	2.0436249209937714	22.1972	2.98943	0.08174499683975085	1133.212190327045	nan	nan
101.04	2.0570549209937714	22.1626	3.00189	0.08228219683975085	1131.4457899799152	nan	nan
101.45	2.0699849209937713	22.1265	3.01451	0.08279939683975085	1129.6028115830538	nan	nan
101.85	2.0825449209937714	22.0991	3.02659	0.08330179683975086	1128.203985874633	nan	nan
102.25	2.0951349209937713	22.0586	3.03839	0.08380539683975086	1126.1363785318938	nan	nan
102.66	2.107384920993771	22.0192	3.05009	0.08429539683975085	1124.1249284256246	nan	nan
103.06	2.119864920993771	21.9945	3.06229	0.08479459683975085	1122.8639432067196	nan	nan
103.47	2.1334249209937712	21.9618	3.07488	0.08533699683975085	1121.194541722582	nan	nan
103.87	2.146024920993771	21.9092	3.08669	0.08584099683975084	1118.509204778679	nan	nan
104.28	2.1588749209937714	21.8735	3.09939	0.08635499683975086	1116.6866471950796	nan	nan
104.69	2.1722449209937715	21.8438	3.11156	0.08688979683975086	1115.1704018104044	nan	nan
105.1	2.1847649209937714	21.8054	3.12333	0.08739059683975085	1113.2100037372888	nan	nan
105.5	2.1971549209937713	21.7595	3.13497	0.08788619683975085	1110.866715415518	nan	nan
105.91	2.210284920993771	21.737	3.14809	0.08841139683975084	1109.718044669552	nan	nan
106.31	2.2227149209937713	21.692	3.15981	0.08890859683975086	1107.4207031776198	nan	nan
106.72	2.2355949209937713	21.6521	3.172	0.08942379683975085	1105.3837270547733	nan	nan
107.12	2.2482049209937713	21.6186	3.18402	0.08992819683975085	1103.6734839441128	nan	nan
107.53	2.261534920993771	21.5832	3.19708	0.09046139683975085	1101.8662419704594	nan	nan
107.93	2.2745249209937715	21.5401	3.2091	0.09098099683975086	1099.6658993415197	nan	nan
108.34	2.2869449209937716	21.4981	3.22106	0.09147779683975087	1097.5217139490499	nan	nan
108.74	2.2996249209937716	21.4675	3.23273	0.09198499683975087	1095.9595217345359	nan	nan
109.16	2.3130949209937715	21.4282	3.24545	0.09252379683975086	1093.953176831582	nan	nan
109.59	2.3268249209937713	21.3858	3.25864	0.09307299683975084	1091.78857062585	nan	nan
109.99	2.3391949209937715	21.34	3.27056	0.09356779683975086	1089.4503875073947	nan	nan
110.4	2.3517349209937715	21.3164	3.28271	0.09406939683975085	1088.2455595249592	nan	nan
110.8	2.364574920993771	21.2771	3.29406	0.09458299683975085	1086.2392146220052	nan	nan
111.21	2.3780949209937714	21.2308	3.30684	0.09512379683975086	1083.8755054869725	nan	nan
111.62	2.3907149209937715	21.1866	3.31861	0.09562859683975086	1081.6190056215637	nan	nan
112.02	2.4033349209937716	21.1412	3.3312	0.09613339683975086	1079.30124331637	nan	nan
112.42	2.4164149209937715	21.1158	3.34314	0.09665659683975086	1078.004521674257	nan	nan
112.83	2.4294549209937712	21.0651	3.35528	0.09717819683975085	1075.416183593347	nan	nan
113.24	2.442124920993771	21.02	3.3676	0.09768499683975085	1073.1137368980992	nan	nan
113.64	2.4547549209937713	20.9814	3.37933	0.09819019683975086	1071.143128418353	nan	nan
114.06	2.4678549209937715	20.9366	3.39146	0.09871419683975086	1068.8559973330514	nan	nan
114.48	2.4812649209937714	20.8903	3.4033	0.09925059683975085	1066.4922881980192	nan	nan
114.9	2.4943549209937714	20.8563	3.41674	0.09977419683975086	1064.7565190707815	nan	nan
115.34	2.5087249209937714	20.8105	3.4295	0.10034899683975086	1062.418335952326	nan	nan
115.76	2.5221349209937713	20.778	3.44272	0.10088539683975085	1060.7591448748194	nan	nan
116.19	2.5360849209937713	20.7243	3.45532	0.10144339683975084	1058.017650694447	nan	nan
116.59	2.5485249209937715	20.6751	3.46708	0.10194099683975086	1055.505890663268	nan	nan
116.99	2.5613449209937715	20.6366	3.47948	0.10245379683975087	1053.5403873868372	nan	nan
117.39	2.5735749209937713	20.5859	3.49091	0.10294299683975085	1050.9520493059267	nan	nan
117.81	2.5870949209937715	20.5568	3.50357	0.10348379683975086	1049.4664351411438	nan	nan
118.21	2.5999749209937715	20.5149	3.51611	0.10399899683975086	1047.3273549519895	nan	nan
118.63	2.6130349209937713	20.4583	3.52843	0.10452139683975085	1044.4378098754703	nan	nan
119.05	2.6262249209937716	20.4189	3.54036	0.10504899683975086	1042.4263597692006	nan	nan
119.48	2.639454920993771	20.381	3.5537	0.10557819683975085	1040.4914877126623	nan	nan
119.88	2.6520749209937713	20.3396	3.5654	0.10608299683975085	1038.3779335400848	nan	nan
120.29	2.6653049209937714	20.2834	3.57824	0.10661219683975086	1035.5088092768272	nan	nan
120.69	2.6778449209937714	20.234	3.59027	0.10711379683975085	1032.986838839017	nan	nan
121.1	2.6903049209937713	20.1985	3.60254	0.10761219683975085	1031.1744916620485	nan	nan
121.5	2.702564920993771	20.1556	3.61391	0.10810259683975085	1028.9843594397396	nan	nan
121.91	2.7157949209937713	20.1064	3.6263	0.10863179683975085	1026.4725994085607	nan	nan
122.32	2.727844920993771	20.0544	3.63803	0.10911379683975085	1023.8178936845501	nan	nan
122.72	2.7403049209937715	20.0085	3.6502	0.10961219683975086	1021.4746053627791	nan	nan
123.13	2.7529149209937716	19.9714	3.66252	0.11011659683975086	1019.5805749327639	nan	nan
123.53	2.7654549209937715	19.9233	3.67447	0.11061819683975087	1017.1249721380544	nan	nan
123.95	2.7783549209937712	19.8704	3.68689	0.11113419683975084	1014.4243195842051	nan	nan
124.37	2.7908649209937715	19.8166	3.69937	0.11163459683975085	1011.6777202005173	nan	nan
124.8	2.8040149209937715	19.7728	3.71265	0.11216059683975085	1009.4416411483699	nan	nan
125.2	2.815424920993771	19.7249	3.72346	0.11261699683975085	1006.9962487602911	nan	nan
125.61	2.8283549209937715	19.6683	3.73565	0.11313419683975086	1004.1067036837718	nan	nan
126.01	2.8396649209937714	19.6298	3.74855	0.11358659683975086	1002.141200407341	nan	nan
126.42	2.8263849209937715	19.576	3.75989	0.11305539683975085	999.3946010236532	nan	nan
126.82	2.8369649209937715	19.5302	3.77273	0.11347859683975087	997.0564179051978	nan	nan
127.24	2.8491349209937713	19.4761	3.78558	0.11396539683975085	994.2945029115637	nan	nan
127.68	2.8623949209937716	19.4259	3.79898	0.11449579683975086	991.7316908472304	nan	nan
128.1	2.8743049209937714	19.3703	3.81097	0.11497219683975085	988.8931978038654	nan	nan
128.52	2.8857749209937715	19.3161	3.8236	0.11543099683975086	986.1261776069159	nan	nan
128.94	2.898194920993771	19.2665	3.83771	0.11592779683975085	983.5939967624752	nan	nan
129.35	2.909784920993771	19.2171	3.84931	0.11639139683975085	981.0720263246651	nan	nan
129.76	2.922394920993771	19.1579	3.8615	0.11689579683975085	978.0497459619456	nan	nan
130.16	2.9350849209937713	19.1102	3.87388	0.11740339683975085	975.6145639804975	nan	nan
130.58	2.9482149209937716	19.0499	3.88638	0.11792859683975086	972.5361263813083	nan	nan
131	2.9615349209937714	18.9993	3.89919	0.11846139683975085	969.9528935037135	nan	nan
131.43	2.9750149209937713	18.9413	3.91147	0.11900059683975085	966.9918755807786	nan	nan
131.84	2.9884349209937713	18.8901	3.92484	0.11953739683975086	964.3780114832913	nan	nan
132.24	3.0012449209937713	18.8274	3.9366	0.12004979683975085	961.1770490045326	nan	nan
132.64	3.013774920993771	18.7732	3.94818	0.12055099683975085	958.4100288075831	nan	nan
133.06	3.0272749209937713	18.7198	3.96072	0.12109099683975084	955.6838502371569	nan	nan
133.47	3.0399949209937716	18.6647	3.97279	0.12159979683975086	952.8708832103689	nan	nan
133.87	3.0530449209937713	18.6125	3.98468	0.12212179683975086	950.2059670797275	nan	nan
134.31	3.0673049209937715	18.556	3.9986	0.12269219683975086	947.3215272065238	nan	nan
134.72	3.0808649209937715	18.4966	4.01124	0.12323459683975085	944.2890364371734	nan	nan
135.12	3.093834920993771	18.4305	4.02245	0.12375339683975085	940.9144970456906	nan	nan
135.54	3.1076349209937715	18.3719	4.03498	0.12430539683975086	937.9228479028635	nan	nan
135.97	3.1212749209937716	18.3127	4.04763	0.12485099683975086	934.9005675401438	nan	nan
136.37	3.1337049209937713	18.2542	4.05981	0.12534819683975085	931.9140236006319	nan	nan
136.79	3.1476149209937714	18.1987	4.07283	0.12590459683975086	929.080635760582	nan	nan
137.2	3.1612649209937715	18.1442	4.08549	0.12645059683975085	926.2982999536866	nan	nan
137.6	3.1742849209937716	18.0837	4.09707	0.12697139683975087	923.2096519478666	nan	nan
138.02	3.1882249209937714	18.0099	4.10926	0.12752899683975086	919.4420119010978	nan	nan
138.44	3.2017549209937712	17.9606	4.12183	0.12807019683975085	916.9251466666032	nan	nan
138.87	3.2153849209937713	17.8988	4.13426	0.12861539683975085	913.7701310176832	nan	nan
139.27	3.2286449209937715	17.8319	4.14648	0.12914579683975086	910.3547499996773	nan	nan
139.69	3.2425749209937713	17.776	4.15922	0.12970299683975084	907.500941346366	nan	nan
140.1	3.2564649209937713	17.7053	4.17122	0.13025859683975086	903.8915626023748	nan	nan
140.51	3.2695949209937716	17.6478	4.18332	0.13078379683975086	900.9560706960169	nan	nan
140.91	3.282754920993771	17.5813	4.196	0.13131019683975084	897.5611104912726	nan	nan
141.33	3.2961649209937716	17.5161	4.20831	0.13184659683975086	894.2325179296288	nan	nan
141.75	3.3100349209937714	17.4368	4.22015	0.13240139683975086	890.1840917005128	nan	nan
142.17	3.3235449209937715	17.3631	4.23302	0.13294179683975085	886.4215568570593	nan	nan
142.59	3.3374049209937713	17.3058	4.24586	0.13349619683975086	883.4962753573325	nan	nan
143.02	3.3521849209937713	17.2359	4.25946	0.13408739683975085	879.9277382398644	nan	nan
143.43	3.3656849209937714	17.1632	4.27106	0.13462739683975086	876.2162554295651	nan	nan
143.83	3.3788449209937714	17.0962	4.2837	0.13515379683975084	872.7957692082438	nan	nan
144.24	3.392504920993771	17.0112	4.29586	0.13570019683975085	868.4563463901495	nan	nan
144.45	3.3994749209937716	16.9809	4.3025	0.13597899683975087	866.9094697855819	nan	nan