File: original_data/46NTB1.csv
Specimen name:	AWA_4_05_Rz
Specimen ID:	46NTB1
Material:	42CrMoS4
Specimen type:	Round Tensile Specimen
Gauge diameter:	5.005	mm
Gauge length:	25	mm
Parallel length:	30	mm
Original cross-section:	19.674243628060164	mm²
Cross-section after fracture:	12.86977306647226	mm²
Yield stress at 0.2% plastic strain:	1071.9857286864112	MPa
Yield stress at 1% plastic strain:	1141.0413345153975	MPa
Ultimate tensile strength:	1193.6774009703333	MPa
Uniform elongation:	4.91729757313988	%
Elongation after fracture:	11.126591655183184	%
Reduction of area:	34.58567805820554	%
Slope of linear-elastic region:	218279.67662951836	MPa
Crosshead seperation speed:	0.029964512255798072	mm/s
Strain rate:	0.000998817075193269	s-1
Test temperature:	RT	Cel
Machine type:	INSTRON 8852TT
Standard:	DIN EN ISO 6892-1
Date:	2022-09-13 00:00:00
Heat treatment batch:	Batch 4
Time	Displacement	Force	Machine Displacement	Engineering Strain	Engineering Stress	True Strain	True Stress
s	mm	kN	mm		MPa		MPa
0	0.001087807293580611	0.179775	0	4.351229174322444e-05	9.137581266077135	4.3511345110957604e-05	9.137978863179011
0.430001	0.001163563893580611	0.173188	-6.1035e-05	4.654255574322444e-05	8.80277805206156	4.6541472672070226e-05	8.803187755849743
0.840001	0.0010812284335806111	0.168598	-0.00012207	4.3249137343224445e-05	8.569478104842569	4.324820212623966e-05	8.569848727378085
1.24	0.002553677293580611	0.347105	0.0101395	0.00010214709174322444	17.64260962515202	0.00010214187508434205	17.644411766415992
1.64	0.003907767293580611	0.546491	0.0215302	0.00015631069174322444	27.77697635199421	0.00015629847649998883	27.78131819038233
2.06	0.0052253172935806105	0.775219	0.0341034	0.00020901269174322443	39.40273459328077	0.00020899085163364784	39.41097026490015
2.47	0.006620707293580611	1.00599	0.0467911	0.00026482829174322446	51.13233418362362	0.00026479323092111007	51.14587547233831
2.88	0.007682067293580611	1.23084	0.0584488	0.0003072826917432244	62.56098192484149	0.00030723549008611405	62.580205831765454
3.29	0.00897375729358061	1.50199	0.0705414	0.0003589502917432244	76.34296028833373	0.00035888588449938793	76.37036361620176
3.71001	0.010445687293580612	1.8136	0.0842438	0.00041782749174322444	92.18143448286743	0.0004177402261439422	92.2199504204227
4.11001	0.011749107293580611	2.08466	0.095932	0.00046996429174322443	105.95883833759065	0.00046985389311300613	106.00863520800391
4.51001	0.013221207293580612	2.38387	0.10775	0.0005288482917432245	121.1670468795066	0.0005287085007686233	121.23112586526439
4.94001	0.01503300729358061	2.72534	0.121422	0.0006013202917432244	138.52324142784403	0.0006011395711402516	138.60653826379263
5.35001	0.01675500729358061	3.05492	0.132706	0.0006702002917432244	155.27509253992136	0.0006699758078214732	155.37915795224205
5.76001	0.01864420729358061	3.38747	0.145493	0.0007457682917432245	172.17790244137566	0.0007454903447516309	172.30630726155533
6.17001	0.02045290729358061	3.72773	0.15728	0.0008181162917432244	189.47259526070766	0.0008177818170236369	189.62760587772934
6.57001	0.02242220729358061	4.09846	0.169838	0.0008968882917432244	208.31601343772212	0.0008964863277659161	208.50284963115706
6.98001	0.02454210729358061	4.47231	0.182007	0.0009816842917432244	227.31801458539528	0.0009812027548378832	227.541169109544
7.40001	0.02666840729358061	4.84757	0.193993	0.0010667362917432244	246.39168303711602	0.0010661677328840712	246.6545179873954
7.81001	0.028859307293580612	5.24115	0.20668	0.0011543722917432245	266.39651816270435	0.0011537065163685102	266.7040389218883
8.21001	0.03110390729358061	5.62919	0.21888	0.0012441562917432244	286.11976685962316	0.001243382970659054	286.4757445677536
8.63001	0.03328070729358062	6.03536	0.231964	0.0013312282917432247	306.76452493411927	0.0013303429929636449	307.17289854861474
9.06001	0.03567300729358062	6.41706	0.243805	0.0014269202917432248	326.16552490219965	0.001425903208399968	326.6309371081497
9.48001	0.03814610729358062	6.84156	0.256714	0.0015258442917432246	347.74195792931545	0.0015246813741456849	348.2725580108215
9.90001	0.040394307293580616	7.2426	0.268692	0.0016157722917432245	368.12596900397864	0.0016144683361017295	368.72077674456636
10.31	0.042810507293580616	7.66549	0.281502	0.0017124202917432247	389.6205691520045	0.0017109557717927546	390.2877633207009
10.73	0.04545560729358061	8.08746	0.293945	0.0018182242917432244	411.0684076548362	0.0018165733228739398	411.81582221920246
11.14	0.047851307293580614	8.50647	0.30619	0.0019140522917432245	432.365795647043	0.0019122228277432297	433.19336638907254
11.54	0.050071307293580614	8.88235	0.317566	0.0020028522917432245	451.47097738139473	0.00200084925716765	452.3752070630986
11.96	0.052459807293580615	9.29595	0.330086	0.0020983922917432248	472.4933865687094	0.0020961937417146243	473.48486304898483
12.4	0.05511310729358061	9.73931	0.343544	0.0022045242917432244	495.02843332230674	0.002202097893448423	496.11973552866937
12.82	0.05758910729358061	10.1363	0.356247	0.0023035642917432243	515.206591502365	0.0023009151550446388	516.3934030094206
13.23	0.06003670729358061	10.5557	0.368462	0.0024014682917432245	536.5238023659042	0.0023985893749288957	537.8122472650515
13.63	0.06241160729358061	10.9469	0.380623	0.0024964642917432245	556.40766714849	0.0024933533013386045	557.7967190211783
14.05	0.06491420729358062	11.3683	0.39418	0.0025965682917432247	577.8265337624513	0.0025932030324546953	579.3268998181468
14.46	0.06728120729358061	11.7575	0.406044	0.0026912482917432244	597.608742794615	0.0026876333673794537	599.2170563027918
14.88	0.06971760729358062	12.1596	0.418678	0.0027887042917432246	618.0466314170019	0.0027848230699752483	619.7701807105319
15.29	0.07233880729358061	12.5862	0.43119	0.0028935522917432244	639.7298029820612	0.0028893740273878235	641.5808946195764
15.69	0.07441300729358061	12.9422	0.442848	0.0029765202917432245	657.8245265572159	0.002972099225975116	659.7825546089199
16.11	0.07705460729358062	13.3894	0.456306	0.0030821842917432246	680.5547523516238	0.0030774440993391787	682.6523475189932
16.52	0.07939010729358062	13.7563	0.467384	0.003175604291743225	699.2034997665799	0.003170572709828949	701.4238934012405
16.92	0.08160360729358061	14.1314	0.479149	0.0032641442917432247	718.2690357582668	0.003258828537216632	720.613569531273
17.36	0.08418810729358062	14.5571	0.493324	0.003367524291743225	739.906462235636	0.0033618668792403474	742.3981152208323
17.77	0.08663500729358062	14.9577	0.505646	0.0034654002917432246	760.2681090452063	0.0034594096281942033	762.9027423720945
18.17	0.08914610729358062	15.3329	0.517845	0.003565844291743225	779.3387278244144	0.003559501742210885	782.1177283783614
18.58	0.09157250729358062	15.7465	0.530083	0.003662900291743225	800.3611370117292	0.003656208209112109	803.2927800539893
18.98	0.09392730729358062	16.1289	0.542618	0.0037570922917432247	819.7977164924573	0.0037500520488836175	822.8777721738797
19.39	0.09645640729358061	16.5259	0.554657	0.0038582562917432246	839.9763829512676	0.0038508323105579025	843.2172271157051
19.81	0.09889490729358061	16.9331	0.566757	0.003955796291743224	860.6734937372311	0.00394799270242892	864.0781427521584
20.22	0.10146780729358061	17.3271	0.579483	0.004058712291743224	880.6996765704082	0.004050497937974089	884.2741831730389
20.63	0.10416380729358062	17.7134	0.591972	0.004166552291743225	900.3344847644596	0.0041578962483184035	904.0857754752903
21.04	0.10659080729358061	18.0867	0.604004	0.004263632291743225	919.3085305807666	0.004254568764815094	923.2281241178258
21.45	0.10924280729358062	18.4468	0.615929	0.004369712291743225	937.611648444287	0.004360192820479188	941.7087415893756
21.85	0.11215180729358061	18.8008	0.628036	0.004486072291743224	955.6047162690196	0.004476039862385482	959.8916281085333
22.29	0.11579280729358062	19.1727	0.641762	0.004631712291743225	974.5076030600311	0.004621018918738058	979.0212419035214
22.71	0.11953080729358062	19.4726	0.653244	0.004781232291743225	989.7508828358426	0.00476983850376076	994.4831117176388
23.13	0.12430480729358061	19.7656	0.666283	0.0049721922917432245	1004.6434502726976	0.00495987176678565	1009.6387306920938
23.54	0.1295918072935806	20.0051	0.678062	0.0051836722917432245	1016.8167263857582	0.005170283311986112	1022.0875710761052
23.95	0.1355848072935806	20.2442	0.691132	0.005423392291743224	1028.9696713487344	0.005408738657496893	1034.5501775327648
24.35	0.1422688072935806	20.4454	0.703484	0.005690752291743224	1039.1962398412095	0.005674621130945929	1045.1100482246568
24.77	0.1486988072935806	20.6156	0.714973	0.005947952291743224	1047.8471442021405	0.005930333054578454	1054.0796890248942
25.18	0.1557758072935806	20.7795	0.727638	0.006231032291743223	1056.177832949241	0.006211699676570226	1062.758911132171
25.59	0.1632748072935806	20.9278	0.740112	0.0065309922917432236	1063.7156068430488	0.006509757766455671	1070.6627252719477
25.99	0.1707258072935806	21.0546	0.751137	0.006829032291743225	1070.1605814198174	0.006805820068813913	1077.4687425876841
26.4	0.1784348072935806	21.1729	0.764145	0.007137392291743224	1076.1735190572913	0.007112041660838118	1083.854591636789
26.8	0.1865358072935806	21.3044	0.775673	0.007461432291743224	1082.8573846475524	0.007433733502251181	1090.9370517047143
27.22	0.1948808072935806	21.3984	0.787666	0.007795232291743223	1087.6352049173963	0.007765006445215575	1096.113573988405
27.64	0.2037368072935806	21.5183	0.80014	0.008149472291743225	1093.7294671552086	0.008116444659607702	1102.642785142453
28.06	0.2130178072935806	21.6062	0.813393	0.008520712291743225	1098.197237386265	0.008484615922347064	1107.5546600856205
28.47	0.2217118072935806	21.6758	0.825516	0.008868472291743224	1101.7348575009582	0.008829378356984894	1111.505562557553
28.87	0.2302298072935806	21.7673	0.837669	0.009209192291743225	1106.3856080827745	0.00916704623688563	1116.574525896426
29.31	0.2402178072935806	21.8346	0.851517	0.009608712291743225	1109.8063240844822	0.00956284221661067	1120.4701337521672
29.72	0.2484408072935806	21.8871	0.862198	0.009937632291743223	1112.4747875330654	0.009888578740350828	1123.5301529054043
30.12	0.2579728072935806	21.9523	0.873962	0.010318912291743223	1115.7887649968297	0.010266035757430325	1127.3024913989445
30.53	0.2676448072935806	22.0051	0.887253	0.010705792291743224	1118.4724768079764	0.01064889105241831	1130.4466108287143
30.93	0.2768648072935806	22.068	0.898933	0.011074592291743224	1121.669550158755	0.011013718020671335	1134.0915831128264
31.35	0.2865308072935806	22.1041	0.911079	0.011461232291743223	1123.5044364538762	0.011396049942816004	1136.381181780878
31.76	0.2960288072935806	22.1503	0.922874	0.011841152291743224	1125.8526842886297	0.011771594406520498	1139.1840773813592
32.18	0.3061588072935806	22.2087	0.935364	0.012246352291743224	1128.8210322009584	0.012171972359050142	1142.6449722356206
32.6	0.3160478072935806	22.2464	0.947571	0.012641912291743225	1130.7372430964172	0.012562670465163078	1145.0319241486495
33.01	0.3258268072935806	22.277	0.960571	0.013033072291743225	1132.292576077877	0.01294887260305684	1147.0498270773041
33.42	0.3359038072935806	22.3119	0.972855	0.013436152291743225	1134.0664689227447	0.01334668768006457	1149.30395870815
33.82	0.3453288072935806	22.3552	0.984337	0.013813152291743225	1136.2673159193857	0.013718620232704924	1151.9627493983105
34.23	0.3552088072935806	22.3837	0.996666	0.014208352291743226	1137.7159103629024	0.014108359694647833	1153.88097882526
34.63	0.3648008072935806	22.4075	1.00817	0.014592032291743225	1138.9256137929267	0.014486593065944022	1155.5448531272866
35.05	0.3752058072935806	22.4503	1.02053	0.015008232291743225	1141.101046851962	0.01489672309311907	1158.226956431468
35.48	0.3862218072935806	22.4757	1.03332	0.015448872291743222	1142.3920748823243	0.015330753446109631	1160.040744154281
35.8801	0.3961378072935806	22.5089	1.04592	0.015845512291743226	1144.0795603393333	0.015721282763820857	1162.2080870754223
36.2801	0.4053768072935806	22.5254	1.0578	0.016215072291743224	1144.9182202803165	0.016085012080631664	1163.4831519902957
36.6901	0.4154018072935806	22.5546	1.06914	0.016616072291743226	1146.4023942364809	0.01647953575395282	1165.4510992945418
37.1101	0.4255638072935806	22.5654	1.08202	0.017022552291743223	1146.951335288761	0.016879292132003006	1166.4753743697986
37.5301	0.4359398072935806	22.597	1.09495	0.017437592291743225	1148.557496145432	0.017287302096575204	1168.5855734868414
37.9401	0.4456798072935806	22.6132	1.10629	0.017827192291743222	1149.3809077238518	0.01767015154958983	1169.8711421823034
38.3401	0.4559248072935806	22.6501	1.11909	0.018236992291743224	1151.2564563191418	0.018072692892477198	1172.2519114388535
38.7501	0.4661028072935806	22.6698	1.13187	0.018644112291743224	1152.2577654608006	0.018472441316187648	1173.7405886290846
39.1701	0.4766668072935806	22.6865	1.1435	0.019066672291743223	1153.106590976826	0.018887181238314	1175.0924964644303
39.5801	0.4870758072935806	22.7048	1.15626	0.019483032291743224	1154.0367410931894	0.01929566772736392	1176.5208761857662
39.9801	0.4972578072935806	22.7272	1.16905	0.019890312291743224	1155.1752854979184	0.019695084544786214	1178.1520826781757
40.3901	0.5069078072935806	22.7419	1.18029	0.020276312291743225	1155.9224552635217	0.02007348501458573	1179.3602999514835
40.8001	0.5169528072935806	22.7667	1.19239	0.020678112291743225	1157.182986568757	0.02046722237623484	1181.1113463071206
41.2001	0.5273008072935806	22.7775	1.20524	0.021092032291743227	1157.7319276210371	0.02087267448529661	1182.150846823602
41.6101	0.5369928072935806	22.8074	1.21778	0.02147971229174322	1159.2516810898494	0.021252274375173984	1184.152073673379
42.0401	0.5475148072935806	22.8169	1.2301	0.021900592291743223	1159.734545904355	0.021664219234393673	1185.1334193608561
42.4601	0.5581138072935806	22.8376	1.24245	0.022324552291743224	1160.7866829212246	0.02207900721134606	1186.7007259236586
42.8801	0.5691028072935806	22.8548	1.25506	0.022764112291743226	1161.6609223748558	0.02250887611080357	1188.105102056727
43.3101	0.5796738072935806	22.8638	1.26817	0.023186952291743227	1162.1183732517559	0.022922219336201075	1189.0643565297025
43.7101	0.5895138072935806	22.8867	1.28009	0.023580552291743224	1163.2823315940902	0.02330682579880166	1190.7131714443055
44.1301	0.6000048072935806	22.9064	1.2927	0.024000192291743227	1164.283640735749	0.023716714402203895	1192.2266719955378
44.5501	0.6103038072935806	22.916	1.30491	0.024412152291743223	1164.7715883377757	0.024118938111354512	1193.2061697373733
44.9701	0.6205838072935806	22.9394	1.31769	0.024823352291743227	1165.9609606177155	0.024520258510692738	1194.9040203015484
45.4101	0.6318858072935806	22.9674	1.33108	0.025275432291743224	1167.3841411236267	0.024961290924084223	1196.8902799410519
45.8201	0.6423698072935806	22.9686	1.34386	0.025694792291743224	1167.4451345738798	0.025370229094729083	1197.4423948187618
46.2201	0.6519418072935806	22.9815	1.35561	0.026077672291743226	1168.1008141641032	0.025743447871229393	1198.5621643995933
46.6301	0.6621788072935806	23.0084	1.36708	0.026487152291743223	1169.4680840072822	0.026142441365152525	1200.443963248716
47.0301	0.6722158072935805	23.0112	1.3789	0.026888632291743222	1169.6104020578732	0.026533485233625472	1201.0596260834052
47.4501	0.6826258072935806	23.03	1.39126	0.027305032291743223	1170.565966111842	0.026938899789110182	1202.5283076161415
47.8801	0.6937978072935806	23.0521	1.40433	0.027751912291743227	1171.6892621540076	0.027373807452590278	1204.2058797904829
48.2801	0.7038248072935805	23.0642	1.41647	0.02815299229174322	1172.304279444062	0.02776398114612454	1205.3081527868283
48.6901	0.7135478072935806	23.063	1.4283	0.028541912291743222	1172.2432859938087	0.02814218017191979	1205.7013510472289
49.0901	0.7235558072935806	23.0899	1.44092	0.028942232291743225	1173.6105558369877	0.02853131561785309	1207.5774651640636
49.5101	0.7337798072935806	23.0949	1.45319	0.029351192291743225	1173.864695213043	0.02892869336827215	1208.3190236067296
49.9201	0.7447218072935806	23.1224	1.46612	0.029788872291743224	1175.2624617813485	0.029353802873078767	1210.2722051646329
50.3301	0.7548398072935806	23.1206	1.4784	0.03019359229174322	1175.1709716059686	0.02974673826176819	1210.6536047957309
50.7301	0.7643248072935807	23.1393	1.48962	0.030572992291743227	1176.1214528724163	0.030114950758151834	1212.0790049852385
51.1501	0.7749348072935806	23.1424	1.50278	0.030997392291743222	1176.2790192855707	0.03052667573166614	1212.7406014909125
51.5701	0.7856088072935806	23.151	1.5152	0.03142435229174322	1176.7161390123863	0.030940713265182912	1213.6936815120914
51.9801	0.7964868072935806	23.1692	1.52762	0.03185947229174322	1177.6412063412286	0.031362487527420595	1215.1602337242718
52.3901	0.8062858072935806	23.1843	1.53999	0.03225143229174322	1178.4087072569162	0.03174227332656645	1216.4140758910135
52.7901	0.8162618072935806	23.1815	1.55196	0.03265047229174322	1178.2663892063251	0.03212877111038993	1216.7373432993984
53.2101	0.8266238072935806	23.2043	1.56446	0.03306495229174323	1179.4252647611384	0.032530065500342896	1218.422904872142
53.6301	0.8372938072935806	23.2206	1.57715	0.033491752291743226	1180.2537591270795	0.03294311974184675	1219.7825256691626
54.0401	0.8479448072935806	23.2225	1.58997	0.03391779229174322	1180.3503320899806	0.0333552683721431	1220.385209485299
54.4401	0.8578808072935806	23.2324	1.60197	0.03431523229174323	1180.8535280545705	0.033739596443659224	1221.3747911722876
54.8601	0.8687908072935806	23.2517	1.615	0.034751632291743224	1181.834506046145	0.03416142911996466	1222.9051842299546
55.2901	0.8799258072935806	23.2583	1.62826	0.03519703229174322	1182.1699700225383	0.03459177796338748	1223.7788446317506
55.7101	0.8897878072935806	23.2712	1.63965	0.035591512291743226	1182.8256496127617	0.0349727729286181	1224.9242032599434
56.1101	0.8999328072935806	23.2753	1.65186	0.03599731229174322	1183.0340439011272	0.03536454952093688	1225.6200898312
56.5301	0.9104118072935806	23.289	1.66457	0.036416472291743225	1183.7303857915194	0.03576906333843204	1226.8376705865908
56.9401	0.9213138072935806	23.2996	1.67788	0.036852552291743224	1184.2691612687572	0.036189732341113216	1227.912502461913
57.3401	0.9310028072935806	23.3145	1.68972	0.037240112291743226	1185.0264966094026	0.0365634475671767	1229.1570164118277
57.7801	0.9424118072935807	23.3111	1.70266	0.03769647229174323	1184.8536818336847	0.03700332607792183	1229.518485820698
58.2001	0.9527268072935806	23.311	1.71451	0.03810907229174323	1184.8485990461638	0.0374008585023922	1230.0020799619847
58.6101	0.9632468072935806	23.3333	1.72731	0.03852987229174323	1185.9820606633716	0.03780612876553272	1231.67779800103
59.0201	0.9739008072935806	23.3441	1.73956	0.03895603229174323	1186.5310017156517	0.03821639388938963	1232.753541733641
59.4201	0.9841808072935806	23.3507	1.75147	0.03936723229174322	1186.8664656920448	0.03861209749563106	1233.5901135462238
59.8401	0.9949968072935806	23.3545	1.76418	0.03979987229174323	1187.059611617847	0.039028264147450795	1234.3044325629235
60.2601	1.0055978072935807	23.3455	1.7762	0.04022391229174323	1186.602160740947	0.03943599026002432	1234.3319419797838
60.6801	1.0162978072935807	23.3532	1.78903	0.040651912291743225	1186.9935353800727	0.039847355513999844	1235.2470924712097
61.0901	1.0262878072935806	23.3705	1.80106	0.041051512291743225	1187.8728576212247	0.04023127187805929	1236.6368348368906
61.5001	1.0371178072935807	23.3741	1.81325	0.04148471229174323	1188.0558379719846	0.04064730306266442	1237.3419925967783
61.9001	1.0473978072935808	23.3741	1.82523	0.041895912291743234	1188.0558379719846	0.041042046107202204	1237.8305211573525
62.3201	1.0579878072935807	23.3823	1.83759	0.04231951229174322	1188.4726265487159	0.04144853000597405	1238.7682084763446
62.7401	1.0688078072935807	23.3887	1.85005	0.04275231229174323	1188.797924950067	0.04186367158633883	1239.6217850893086
63.1501	1.0789978072935806	23.4027	1.86212	0.04315991229174323	1189.5095152030226	0.04225448381744238	1240.848641549379
63.5501	1.0898578072935807	23.4119	1.87481	0.04359431229174323	1189.9771316549645	0.042670824181015046	1241.853366352364
63.9801	1.1011378072935807	23.4034	1.88702	0.04404551229174323	1189.5450947156703	0.04310308265942892	1241.939217806552
64.3801	1.1115678072935806	23.4132	1.89889	0.04446271229174323	1190.0432078927392	0.04350260227887646	1242.9557566600172
64.8001	1.1221278072935807	23.4206	1.91099	0.04488511229174323	1190.4193341693012	0.043906938982210326	1243.8514396577525
65.2201	1.1332878072935808	23.4208	1.92406	0.04533151229174323	1190.4294997443435	0.044334071750686675	1244.393469244458
65.6401	1.1440278072935808	23.435	1.93621	0.04576111229174323	1191.1512555723414	0.044744957429296434	1245.6596619350382
66.0501	1.1543178072935807	23.4352	1.94894	0.046172712291743224	1191.1614211473834	0.04513846892614641	1246.1605747390456
66.4701	1.1653278072935807	23.434	1.96111	0.046613112291743225	1191.1004276971303	0.045559343342751864	1246.62132568412
66.8801	1.1763678072935808	23.4439	1.97382	0.04705471229174323	1191.6036236617201	0.04598118677117301	1247.6741893389212
67.2801	1.1867478072935806	23.4408	1.98484	0.04746991229174322	1191.4460572485657	0.04637764905246132	1248.0038970864985
67.7001	1.1978378072935807	23.4375	1.99808	0.047913512291743225	1191.278325260369	0.046801056054180064	1248.3566539406188
68.1201	1.2085278072935808	23.4459	2.01038	0.04834111229174323	1191.7052794121425	0.047209021766852696	1249.313638142868
68.5601	1.2200178072935808	23.4474	2.02322	0.04880071229174323	1191.7815212249589	0.04764733261638187	1249.9413083568743
68.9701	1.2307878072935807	23.4607	2.03575	0.04923151229174323	1192.4575319652668	0.048058003149471534	1251.1640196075966
69.3701	1.2415778072935808	23.4598	2.04754	0.04966311229174323	1192.411786877577	0.04846926725108784	1251.6306673472764
69.7901	1.2528178072935807	23.4537	2.05964	0.05011271229174323	1192.101736838789	0.04889750344812102	1251.841188199479
70.2001	1.2640478072935808	23.4611	2.07257	0.050561912291743234	1192.477863115351	0.04932517558886085	1252.771824240035
70.6101	1.2755478072935806	23.4769	2.08498	0.05102191229174322	1193.2809435436868	0.049762940670572214	1254.1644191845814
71.0201	1.2868078072935807	23.4658	2.09653	0.051472312291743226	1192.7167541288436	0.050191384184588586	1254.1086433729579
71.4201	1.2980178072935806	23.4723	2.10886	0.05192071229174323	1193.0471353177156	0.050617742931196474	1254.9909923810353
71.8201	1.3088778072935807	23.4759	2.12077	0.05235511229174323	1193.2301156684755	0.05103061656790866	1255.7018123641883
72.2301	1.3199078072935808	23.4684	2.13261	0.05279631229174323	1192.8489066043921	0.05144977882037904	1255.826929994342
72.6301	1.3305578072935806	23.4723	2.14458	0.05322231229174323	1193.0471353177156	0.05185433365274134	1256.5438625323648
73.0501	1.3418178072935807	23.4742	2.15688	0.053672712291743224	1193.1437082806167	0.052281882250659856	1257.182967257866
73.4901	1.3541578072935807	23.478	2.1699	0.05416631229174323	1193.336854206419	0.05275022921953721	1257.9755109206105
73.9101	1.3658678072935808	23.4847	2.1831	0.054634712291743236	1193.6774009703333	nan	nan
74.3201	1.3775378072935807	23.4792	2.19485	0.055101512291743225	1193.3978476566722	nan	nan
74.7201	1.3887478072935806	23.4815	2.20713	0.05554991229174323	1193.5147517696578	nan	nan
75.1401	1.4003878072935807	23.4592	2.21988	0.05601551229174323	1192.3812901524502	nan	nan
75.5801	1.4124378072935808	23.4746	2.2327	0.056497512291743233	1193.1640394307012	nan	nan
75.9901	1.4236778072935807	23.4773	2.24464	0.05694711229174323	1193.3012746937711	nan	nan
76.3901	1.4347878072935807	23.4681	2.25703	0.057391512291743225	1192.833658241829	nan	nan
76.8001	1.4466778072935806	23.4739	2.26934	0.057867112291743225	1193.1284599180535	nan	nan
77.2001	1.4578678072935807	23.4656	2.28126	0.058314712291743225	1192.706588553801	nan	nan
77.6201	1.4698278072935806	23.4718	2.29406	0.05879311229174323	1193.0217213801102	nan	nan
78.0301	1.4812878072935807	23.4668	2.30582	0.059251512291743226	1192.7675820040545	nan	nan
78.4501	1.4937378072935807	23.4808	2.32001	0.05974951229174323	1193.47917225701	nan	nan
78.8701	1.5048578072935808	23.4591	2.33149	0.060194312291743234	1192.3762073649289	nan	nan
79.2801	1.5167978072935806	23.4557	2.34402	0.06067191229174322	1192.2033925892113	nan	nan
79.6801	1.5280778072935808	23.455	2.35538	0.061123112291743234	1192.1678130765636	nan	nan
80.1201	1.5408078072935807	23.4528	2.36913	0.06163231229174323	1192.055991751099	nan	nan
80.5401	1.5529778072935807	23.4398	2.38172	0.06211911229174323	1191.3952293733548	nan	nan
80.9501	1.5647078072935807	23.4353	2.39391	0.06258831229174323	1191.1665039349048	nan	nan
81.3501	1.5756178072935807	23.45	2.4056	0.06302471229174322	1191.9136737005078	nan	nan
81.7701	1.5883678072935807	23.444	2.41879	0.06353471229174323	1191.6087064492413	nan	nan
82.2001	1.6003578072935807	23.4444	2.43083	0.06401431229174323	1191.6290375993258	nan	nan
82.6001	1.6120778072935806	23.4224	2.44199	0.06448311229174322	1190.5108243446814	nan	nan
83.0201	1.6243278072935807	23.4244	2.45492	0.06497311229174323	1190.6124800951034	nan	nan
83.4401	1.6370678072935807	23.4172	2.46863	0.06548271229174323	1190.2465193935836	nan	nan
83.8601	1.6490578072935806	23.4154	2.48077	0.06596231229174322	1190.1550292182037	nan	nan
84.3001	1.6616478072935807	23.4	2.49377	0.06646591229174323	1189.3722799399525	nan	nan
84.7201	1.6739678072935806	23.3978	2.50584	0.06695871229174323	1189.260458614488	nan	nan
85.1401	1.6860778072935807	23.3979	2.51862	0.06744311229174323	1189.2655414020091	nan	nan
85.5501	1.6985678072935808	23.3807	2.53121	0.06794271229174323	1188.391301948378	nan	nan
85.9601	1.7100878072935808	23.3723	2.54316	0.06840351229174323	1187.9643477966047	nan	nan
86.3601	1.7226578072935808	23.3857	2.55546	0.06890631229174322	1188.6454413244337	nan	nan
86.7801	1.7354378072935808	23.3629	2.56805	0.06941751229174323	1187.4865657696205	nan	nan
87.1901	1.7476678072935807	23.3514	2.58039	0.06990671229174322	1186.9020452046927	nan	nan
87.5901	1.7600778072935808	23.3582	2.59361	0.07040311229174323	1187.2476747561282	nan	nan
88.0101	1.7722378072935807	23.3303	2.60551	0.07088951229174323	1185.8295770377383	nan	nan
88.4501	1.7848678072935806	23.3121	2.61781	0.07139471229174323	1184.904509708896	nan	nan
88.8701	1.7977378072935808	23.3136	2.6313	0.07190951229174324	1184.9807515217128	nan	nan
89.3001	1.8107978072935806	23.2913	2.64388	0.07243191229174323	1183.8472899045048	nan	nan
89.7001	1.8228478072935808	23.2899	2.65561	0.07291391229174322	1183.7761308792092	nan	nan
90.1101	1.8356678072935808	23.2727	2.66767	0.07342671229174323	1182.9018914255782	nan	nan
90.5101	1.8481878072935807	23.2493	2.68029	0.07392751229174323	1181.7125191456385	nan	nan
90.9301	1.8611278072935806	23.2295	2.69292	0.07444511229174322	1180.7061272164583	nan	nan
91.3401	1.8732378072935807	23.2261	2.70514	0.07492951229174323	1180.5333124407405	nan	nan
91.7401	1.8853078072935807	23.189	2.71636	0.07541231229174322	1178.6475982704085	nan	nan
92.1601	1.8987378072935808	23.182	2.72976	0.07594951229174324	1178.2918031439308	nan	nan
92.5701	1.9114278072935806	23.1576	2.742	0.07645711229174322	1177.0516029887795	nan	nan
92.9801	1.9240678072935806	23.1434	2.75441	0.07696271229174323	1176.329847160782	nan	nan
93.3801	1.9364178072935807	23.116	2.76653	0.07745671229174322	1174.9371633799974	nan	nan
93.8001	1.9494778072935808	23.092	2.77849	0.07797911229174323	1173.7172943749308	nan	nan
94.2201	1.9630478072935806	23.0775	2.79123	0.07852191229174323	1172.9802901843698	nan	nan
94.6301	1.9764378072935807	23.0555	2.80409	0.07905751229174322	1171.8620769297254	nan	nan
95.0401	1.9884778072935807	23.0207	2.81591	0.07953911229174322	1170.0932668723788	nan	nan
95.4401	2.0009578072935805	23.0096	2.82865	0.08003831229174323	1169.5290774575353	nan	nan
95.8601	2.0145978072935806	22.9856	2.84078	0.08058391229174322	1168.309208452469	nan	nan
96.2701	2.0271578072935803	22.9322	2.85238	0.0810863122917432	1165.5949999161958	nan	nan
96.6701	2.0398378072935803	22.9285	2.86507	0.08159351229174322	1165.4069367779146	nan	nan
97.0901	2.0528278072935806	22.8996	2.877	0.08211311229174323	1163.9380111843134	nan	nan
97.5001	2.0656978072935805	22.8718	2.88954	0.08262791229174322	1162.5249962534447	nan	nan
97.9001	2.0785278072935807	22.8359	2.90131	0.08314111229174323	1160.7002755333658	nan	nan
98.3401	2.0927978072935804	22.8053	2.91481	0.08371191229174321	1159.1449425519058	nan	nan
98.7601	2.1055678072935806	22.7663	2.92737	0.08422271229174322	1157.1626554186728	nan	nan
99.1701	2.1189678072935805	22.7338	2.94012	0.08475871229174321	1155.5107494743115	nan	nan
99.5701	2.1314478072935805	22.7034	2.95179	0.08525791229174322	1153.9655820678938	nan	nan
100.01	2.1452778072935805	22.6781	2.96539	0.08581111229174322	1152.679636825053	nan	nan
100.43	2.1589478072935804	22.647	2.97831	0.08635791229174322	1151.0988899059873	nan	nan
100.84	2.1711178072935806	22.6087	2.98943	0.08684471229174323	1149.1521822854018	nan	nan
101.24	2.1841378072935806	22.585	3.00213	0.08736551229174322	1147.9475616428986	nan	nan
101.65	2.1979278072935804	22.5496	3.0148	0.08791711229174322	1146.1482548604254	nan	nan
102.06	2.2102578072935803	22.5102	3.02698	0.08841031229174322	1144.1456365771076	nan	nan
102.46	2.2231278072935803	22.4678	3.03867	0.08892511229174321	1141.9905346681564	nan	nan
102.88	2.2368278072935803	22.4396	3.05254	0.0894731122917432	1140.5571885872032	nan	nan
103.3	2.2497578072935807	22.4114	3.06447	0.08999031229174323	1139.1238425062502	nan	nan
103.72	2.2630778072935804	22.3618	3.07695	0.09052311229174322	1136.602779895779	nan	nan
104.13	2.2763978072935807	22.3566	3.08949	0.09105591229174323	1136.3384749446811	nan	nan
104.53	2.2890078072935807	22.3082	3.10148	0.09156031229174323	1133.8784057844637	nan	nan
104.96	2.3024278072935807	22.2795	3.11419	0.09209711229174322	1132.4196457659048	nan	nan
105.36	2.3153378072935804	22.2314	3.1262	0.09261351229174322	1129.9748249682505	nan	nan
105.78	2.3286878072935804	22.2038	3.13862	0.09314751229174321	1128.571975612424	nan	nan
106.2	2.3421478072935806	22.1503	3.15115	0.09368591229174322	1125.8526842886297	nan	nan
106.61	2.3557378072935804	22.1255	3.1645	0.09422951229174321	1124.592152983394	nan	nan
107.03	2.3689378072935803	22.0776	3.17635	0.09475751229174321	1122.1574977607818	nan	nan
107.44	2.3815678072935804	22.0469	3.18872	0.09526271229174321	1120.597081991801	nan	nan
107.85	2.3951378072935805	22.0088	3.20158	0.09580551229174322	1118.6605399462576	nan	nan
108.25	2.4081878072935803	21.9732	3.2135	0.09632751229174322	1116.851067588742	nan	nan
108.65	2.4210578072935807	21.9407	3.22546	0.09684231229174323	1115.199161644381	nan	nan
109.07	2.4342578072935805	21.8904	3.23778	0.09737031229174323	1112.6425195212623	nan	nan
109.5	2.4478378072935807	21.8538	3.2501	0.09791351229174322	1110.7822192885355	nan	nan
109.9	2.4609378072935804	21.8211	3.2627	0.09843751229174322	1109.1201477691325	nan	nan
110.31	2.4741678072935804	21.7698	3.27518	0.09896671229174321	1106.5126777708024	nan	nan
110.71	2.4870078072935806	21.7419	3.28743	0.09948031229174323	1105.0945800524125	nan	nan
111.13	2.5004278072935806	21.7028	3.29953	0.10001711229174322	1103.1072101316581	nan	nan
111.56	2.5137478072935804	21.6542	3.31286	0.10054991229174322	1100.6369753963984	nan	nan
111.96	2.5267278072935806	21.6087	3.32439	0.10106911229174323	1098.3243070742926	nan	nan
112.38	2.5400378072935803	21.5826	3.33692	0.10160151229174322	1096.9976995312827	nan	nan
112.8	2.5536578072935803	21.5291	3.34998	0.10214631229174322	1094.2784082074884	nan	nan
113.21	2.5674078072935806	21.4863	3.36229	0.10269631229174322	1092.102975148453	nan	nan
113.61	2.5803378072935805	21.4484	3.37465	0.10321351229174322	1090.176598677952	nan	nan
114.04	2.5940078072935804	21.3957	3.38715	0.10376031229174322	1087.4979696543267	nan	nan
114.44	2.6066478072935806	21.3534	3.39866	0.10426591229174323	1085.3479505328967	nan	nan
114.85	2.6205878072935804	21.3248	3.41241	0.10482351229174322	1083.894273301859	nan	nan
115.25	2.6334478072935803	21.2702	3.42434	0.10533791229174322	1081.1190713153323	nan	nan
115.67	2.6467578072935805	21.2348	3.43697	0.10587031229174322	1079.3197645328592	nan	nan
116.09	2.6598178072935803	21.1785	3.44878	0.10639271229174321	1076.4581551584736	nan	nan
116.53	2.6742178072935805	21.1388	3.46236	0.10696871229174322	1074.4402885125926	nan	nan
116.94	2.6875278072935807	21.0879	3.47398	0.10750111229174322	1071.8531496643473	nan	nan
117.34	2.7011578072935807	21.0587	3.48682	0.10804631229174323	1070.368975708183	nan	nan
117.75	2.7144878072935805	20.9935	3.49933	0.10857951229174322	1067.0549982444184	nan	nan
118.15	2.7272478072935806	20.9429	3.51072	0.10908991229174322	1064.4831077587364	nan	nan
118.58	2.7409178072935805	20.9179	3.52411	0.10963671229174322	1063.2124108784585	nan	nan
118.98	2.7541078072935803	20.843	3.53587	0.11016431229174321	1059.4054030251466	nan	nan
119.4	2.7673178072935807	20.8088	3.54877	0.11069271229174323	1057.6670896929268	nan	nan
119.81	2.7812578072935805	20.766	3.56145	0.11125031229174322	1055.4916566338911	nan	nan
120.21	2.7944678072935805	20.7137	3.57326	0.11177871229174322	1052.8333587603502	nan	nan
120.63	2.8082878072935804	20.6522	3.5855	0.11233151229174322	1049.707444434867	nan	nan
121.07	2.8223578072935807	20.597	3.59927	0.11289431229174322	1046.9017457232137	nan	nan
121.49	2.8361178072935807	20.554	3.61155	0.11344471229174323	1044.716147089136	nan	nan
121.9	2.8504578072935804	20.4855	3.62397	0.11401831229174322	1041.234437637175	nan	nan
122.3	2.8636478072935807	20.42	3.63631	0.11454591229174323	1037.9052118108475	nan	nan
122.72	2.8773278072935806	20.3647	3.64903	0.11509311229174322	1035.094430311673	nan	nan
123.16	2.8913878072935804	20.2847	3.66165	0.11565551229174321	1031.0282002947845	nan	nan
123.36	2.8990278072935807	20.1928	3.66743	0.11596111229174323	1026.3571185628834	nan	nan