File: original_data/46NTBB.csv
Specimen name:	AWA_4_10_Rz
Specimen ID:	46NTBB
Material:	42CrMoS4
Specimen type:	Round Tensile Specimen
Gauge diameter:	5.004	mm
Gauge length:	25	mm
Parallel length:	30	mm
Original cross-section:	19.666382577842715	mm²
Cross-section after fracture:	13.170361436965894	mm²
Yield stress at 0.2% plastic strain:	1077.1065064221755	MPa
Yield stress at 1% plastic strain:	1144.9953222035329	MPa
Ultimate tensile strength:	1196.0613451353008	MPa
Uniform elongation:	5.014295979615404	%
Elongation after fracture:	10.78391715188548	%
Reduction of area:	33.0310931111226	%
Slope of linear-elastic region:	214578.75586566847	MPa
Crosshead seperation speed:	0.02980030634376788	mm/s
Strain rate:	0.0009933435447922628	s-1
Test temperature:	RT	Cel
Machine type:	INSTRON 8852TT
Standard:	DIN EN ISO 6892-1
Date:	2022-09-13 00:00:00
Heat treatment batch:	Batch 4
Time	Displacement	Force	Machine Displacement	Engineering Strain	Engineering Stress	True Strain	True Stress
s	mm	kN	mm		MPa		MPa
0	0.0009039174156163357	0.149325	0	3.615669662465343e-05	7.592906291177219	3.61560429871119e-05	7.593180825586489
0.440001	0.0008664629156163357	0.15035	0.000343323	3.465851662465343e-05	7.64502568811984	3.4657916032142437e-05	7.645290653369747
0.840001	0.0018936264156163359	0.317674	0.0112381	7.574505662465344e-05	16.153148589609458	7.574218811271331e-05	16.154372110764044
1.25	0.003243547415616336	0.522421	0.024292	0.00012974189662465343	26.564163385522146	0.00012973348087266378	26.56760987046203
1.65	0.004540057415616336	0.74147	0.0363464	0.00018160229662465344	37.70240902540882	0.00018158580892359754	37.70925586947611
2.06	0.006226747415616335	0.992742	0.0484085	0.0002490698966246534	50.47913596059504	0.00024903888386740774	50.49170879377044
2.46	0.007869917415616335	1.26245	0.0603333	0.0003147966966246534	64.19330016605846	0.00031474715854050536	64.21350800489617
2.88	0.009558107415616336	1.55312	0.0728302	0.00038232429662465346	78.97334417514256	0.00038225122931366523	79.0035376034064
3.29	0.011383417415616335	1.8675	0.085083	0.0004553366966246534	94.95899881984568	0.0004552330623288339	95.00223713668309
3.69001	0.013194817415616336	2.16043	0.0976334	0.0005277926966246534	109.85395974316422	0.0005276534630482464	109.91193986081197
4.10001	0.015075917415616336	2.48853	0.109489	0.0006030366966246534	126.53725158401636	0.0006028549430617291	126.61355819021156
4.50001	0.017143517415616337	2.8231	0.122086	0.0006857406966246535	143.54953122800876	0.0006855056839056309	143.6479689835532
4.92001	0.019256117415616336	3.17377	0.134026	0.0007702446966246535	161.3804667654413	0.0007699482104131919	161.5047692141062
5.32001	0.021270517415616336	3.53385	0.146545	0.0008508206966246534	179.6898837909032	0.0008504589538667164	179.84276766300658
5.72001	0.023276617415616336	3.90081	0.158493	0.0009310646966246535	198.3491363782823	0.0009306315247432686	198.53381225677015
6.13001	0.025518817415616336	4.27576	0.170197	0.0010207526966246533	217.41466602085322	0.0010202320828392691	217.63659262747973
6.54001	0.027562017415616338	4.65858	0.182739	0.0011024806966246534	236.88037093555914	0.00110187341108752	237.1415269719249
6.96001	0.030019917415616337	5.05982	0.195564	0.0012007966966246534	257.2826995494681	0.0012000763169001752	257.5916437651858
7.36001	0.03212501741561634	5.44252	0.207184	0.0012850006966246535	276.7423026811173	0.0012841757898244966	277.09791673284803
7.78001	0.034384217415616335	5.84935	0.220467	0.0013753686966246534	297.428872689084	0.0013744237434389836	297.83794705005295
8.20001	0.03687251741561634	6.27869	0.233398	0.0014749006966246537	319.26003550210277	0.0014738140988767767	319.73091235086923
8.61001	0.039234517415616336	6.69397	0.245277	0.0015693806966246534	340.3762727336452	0.0015681505056629097	340.9104526856624
9.01001	0.04157381741561634	7.08368	0.257141	0.0016629526966246535	360.1923216921898	0.0016615715217960772	360.79130448485137
9.43001	0.04412781741561634	7.51534	0.269867	0.0017651126966246537	382.1414523109714	0.0017635567159272742	382.8159750403521
9.85001	0.04652801741561634	7.92371	0.281647	0.0018611206966246535	402.90632853483237	0.0018593909573374145	403.6561858416696
10.26	0.048958117415616335	8.35805	0.293961	0.0019583246966246534	424.9917323085469	0.0019564096785597614	425.82400411378796
10.67	0.051511617415616336	8.77642	0.30677	0.0020604646966246535	446.26509045379925	0.0020583448506540825	447.18460391801534
11.07	0.05387341741561634	9.19194	0.318092	0.0021549366966246535	467.3935312514551	0.002152618150823622	468.40073472371387
11.5	0.05633661741561634	9.60454	0.33091	0.0022534646966246535	488.3734953280646	0.0022509294530619747	489.4740277585536
11.92	0.05895481741561634	10.0278	0.343628	0.0023581926966246536	509.89550113287737	0.0023554165238711226	511.0979329796907
12.34	0.06148291741561634	10.4578	0.356041	0.0024593166966246534	531.760223752708	0.0024562975263682715	533.067990549584
12.75	0.06403951741561634	10.8761	0.368935	0.0025615806966246533	553.0300225245105	0.0025583054408209725	554.4466535548631
13.16	0.06633931741561634	11.2843	0.380867	0.0026535726966246537	573.786254555708	0.0026500581885586425	575.3088380944955
13.58	0.06898101741561634	11.7128	0.393021	0.0027592406966246534	595.5747048873299	0.0027554409799640683	597.2180388509352
13.97	0.07144631741561634	12.1127	0.404869	0.0028578526966246535	615.9088969237723	0.0028537767993031325	617.6690738257211
14.4	0.07399031741561633	12.5374	0.417664	0.0029596126966246533	637.5041241252654	0.0029552416652173425	639.3908894251772
14.81	0.07637901741561634	12.9595	0.429848	0.0030551606966246537	658.9671460271968	0.0030505031770861053	660.9803965521061
15.22	0.07893901741561633	13.3549	0.441185	0.003157560696624653	679.0725211990133	0.003152586070885991	681.2167339021092
15.63	0.08122061741561634	13.7722	0.453995	0.0032488246966246538	700.2914717786766	0.003243558668189581	702.5665960070269
16.04	0.08379461741561633	14.1628	0.465973	0.0033517846966246534	720.1527756282252	0.0033461799866606	722.5665726808077
16.46	0.08648181741561634	14.5988	0.478889	0.0034592726966246536	742.3225874008906	0.00345330317566919	744.8904836595743
16.86	0.08876201741561633	14.9809	0.490356	0.0035504806966246533	761.7516816172563	0.003544192619438496	764.4562662584598
17.28	0.09115241741561633	15.3881	0.502754	0.0036460966966246535	782.4570654563145	0.0036394657991054105	785.3099795779254
17.7	0.09382621741561634	15.8242	0.515572	0.0037530486966246535	804.6319620481938	0.0037460235809461816	807.6517849846214
18.12	0.09641001741561633	16.2376	0.528015	0.003856400696624653	825.6526046785148	0.003848983845575876	828.8366519583669
18.53	0.09900071741561633	16.66	0.540184	0.003960028696624654	847.1308810380879	0.003952208421861766	850.4855436367956
18.94	0.10139191741561633	17.0306	0.552032	0.004055676696624653	865.9752210448534	0.004047474609088789	869.4873365686993
19.35	0.10415791741561634	17.4417	0.564209	0.0041663166966246536	886.8789128332544	0.0041576616307187385	890.5739312556758
19.75	0.10642491741561634	17.8138	0.575317	0.004256996696624654	905.7995251282287	0.004247961319491443	909.6555107145036
20.17	0.10930491741561633	18.2132	0.588554	0.004372196696624653	926.1082930686016	0.004362666413398477	930.1574206882727
20.58	0.11207491741561634	18.5806	0.599968	0.004482996696624653	944.789918860522	0.0044729779983019935	949.025408945778
21	0.11525991741561634	18.9424	0.612389	0.004610396696624653	963.186794776463	0.004599801371062767	967.6274679933329
21.41	0.11868991741561634	19.2816	0.624481	0.0047475966966246536	980.4345015500598	0.004736362402660203	985.0892091508757
21.81	0.12284391741561634	19.5869	0.636719	0.004913756696624654	995.9584546101395	0.004901723596572897	1000.8523521360399
22.22	0.1275279174156163	19.8615	0.648697	0.005101116696624652	1009.9213681715476	0.0050881500783096344	1015.0730949250054
22.63	0.1329409174156163	20.1102	0.661247	0.005317636696624653	1022.5673135565519	0.005303547990283581	1028.004955027889
23.04	0.13848891741561634	20.3148	0.673363	0.005539556696624653	1032.9708536682203	0.00552426978159755	1038.6930542780763
23.45	0.14499691741561632	20.5244	0.686798	0.005799876696624653	1043.6286347405842	0.005783122163380129	1049.6815521391463
23.86	0.15123791741561632	20.6924	0.698341	0.0060495166966246525	1052.1711310199596	0.006031291834629742	1058.5362578447712
24.28	0.15852191741561633	20.8579	0.710121	0.006340876696624653	1060.5865068189876	0.006320857917823601	1067.3115550848306
24.69	0.16564991741561633	20.9975	0.722961	0.006625996696624653	1067.6849144416117	0.0066041412700489945	1074.7593911577378
25.09	0.17342991741561634	21.1443	0.735878	0.0069371966966246534	1075.1494290476376	0.006913245055317773	1082.6079521152049
25.52	0.18139491741561634	21.2684	0.747993	0.007255796696624653	1081.459689692105	0.007229600045829727	1089.3065413361057
25.91	0.18907291741561633	21.3712	0.759995	0.007562916696624653	1086.6868838440087	0.00753446122300374	1094.9054062218356
26.33	0.19759391741561633	21.483	0.772285	0.007903756696624653	1092.3717117251645	0.007872685623088103	1101.0055519569155
26.74	0.2057109174156163	21.5739	0.784973	0.008228436696624652	1096.9938123906122	0.008194767680872395	1106.0203565324573
27.15	0.21418891741561633	21.6709	0.797173	0.008567556696624653	1101.926087028109	0.00853106347311613	1111.3669012542118
27.56	0.22268191741561633	21.7411	0.808655	0.008907276696624652	1105.4956301162767	0.008867840911513875	1115.342585580632
27.97	0.23201591741561634	21.8208	0.822273	0.009280636696624654	1109.5482310297664	0.009237836194690012	1119.8455450593362
28.38	0.24061791741561633	21.8893	0.834541	0.009624716696624654	1113.0313321912975	0.00957869417770832	1123.7439434381054
28.79	0.24916491741561633	21.9508	0.846008	0.009966596696624653	1116.1584960078546	0.009917257728659019	1127.2827975870762
29.18	0.25830891741561635	22.0141	0.857712	0.010332356696624655	1119.3771865702622	0.010279342759076689	1130.9429909399703
29.61	0.2683619174156163	22.0718	0.871063	0.010734476696624654	1122.3111272566907	0.010677271218108422	1134.3585498985901
30.02	0.27729091741561634	22.1277	0.882568	0.011091636696624654	1125.1535411972686	0.0110305755911693	1137.6333355041495
30.43	0.28697991741561635	22.1556	0.894783	0.011479196696624654	1126.5722057579505	0.01141381062881989	1139.5043497007962
30.85	0.29701891741561637	22.2143	0.907288	0.011880756696624655	1129.5569946365185	0.011810734571688972	1142.9769864647656
31.28	0.30649891741561636	22.251	0.919937	0.012259956696624654	1131.4231232880247	0.012185412084894511	1145.2943217850957
31.69	0.31622491741561637	22.2937	0.932915	0.012648996696624655	1133.5943410923662	0.012569666403228059	1147.9331721681558
32.1	0.32604691741561637	22.3369	0.945381	0.013041876696624655	1135.7909829927771	0.012957563698009504	1150.6038289461071
32.51	0.33616791741561636	22.3727	0.95752	0.013446716696624655	1137.611348271358	0.013357111967568376	1152.9084857824282
32.91	0.34556491741561635	22.3873	0.969147	0.013822596696624653	1138.3537318765896	0.013727935914662145	1154.0887364104171
33.33	0.35570791741561636	22.4465	0.982216	0.014228316696624655	1141.3639448512267	0.014128044218386877	1157.6036325246787
33.74	0.36586791741561636	22.4645	0.9944	0.014634716696624655	1142.2792123097313	0.01452866269163677	1158.9961449703278
34.15	0.37572091741561636	22.4889	1.00663	0.015028836696624654	1143.5199081979265	0.014917022628725444	1160.7056821575725
34.56	0.3860359174156163	22.5185	1.01894	0.015441436696624653	1145.025014685245	0.015323430948104066	1162.7058459655589
34.96	0.39520891741561637	22.5272	1.03048	0.015808356696624656	1145.4673939568556	0.01568470606570342	1163.5753511048788
35.38	0.40562291741561635	22.5704	1.04373	0.016224916696624653	1147.6640358572663	0.016094699357928816	1166.2847892347625
35.7901	0.41548791741561636	22.5992	1.05625	0.016619516696624655	1149.1284637908736	0.01648292385604998	1168.226423481413
36.2001	0.4259649174156164	22.6252	1.06842	0.017038596696624653	1150.4505167864913	0.016895067867053703	1170.0525791614398
36.6101	0.43602391741561636	22.6468	1.08105	0.017440956696624654	1151.5488377366967	0.017290608834349068	1171.6329511497108
37.0201	0.44629491741561633	22.6786	1.09361	0.017851796696624653	1153.1658102467213	0.01769432471737885	1173.7518918487444
37.4301	0.45621491741561637	22.6948	1.10539	0.018248596696624656	1153.9895509593755	0.01808408939333567	1175.048240866952
37.8501	0.4664389174156163	22.7216	1.11727	0.018657556696624653	1155.3522825087043	0.018485639562757065	1176.9083332241853
38.2501	0.47614091741561637	22.7264	1.12911	0.019045636696624655	1155.5963538309725	0.01886653900478601	1177.6054221539814
38.6601	0.48667191741561633	22.7522	1.14241	0.019466876696624655	1156.908237188162	0.019279820751381134	1179.4296271908133
39.0701	0.49655791741561633	22.769	1.15411	0.01986231669662465	1157.7624868160997	0.019667634554309466	1180.7583319887128
39.4801	0.5068479174156163	22.7984	1.16727	0.020273916696624653	1159.2574236649905	0.020071137025220228	1182.760112102318
39.8901	0.5163939174156164	22.8005	1.17824	0.020655756696624655	1159.3642048684826	0.020445319447508513	1183.3117498070217
40.3001	0.5274549174156163	22.8327	1.19262	0.021098196696624653	1161.001516655363	0.02087871153786297	1185.4965550188374
40.7201	0.5376279174156163	22.8567	1.20502	0.02150511669662465	1162.2218732667025	0.021277144266053608	1187.2155902786726
41.1201	0.5473719174156163	22.8696	1.21656	0.02189487669662465	1162.8778149452974	0.021658626115898923	1188.338881316765
41.5401	0.5579269174156164	22.8976	1.2295	0.022317076696624655	1164.3015643251933	0.022071694834436058	1190.2853716342388
41.9501	0.5679409174156164	22.91	1.24113	0.022717636696624653	1164.9320819077186	0.022463433911038555	1191.3965857207406
42.3601	0.5785109174156163	22.927	1.25378	0.023140436696624654	1165.7965011740841	0.022876756820890076	1192.7735413106495
42.7701	0.5884539174156164	22.9512	1.26611	0.023538156696624655	1167.0270274238512	0.023265406026769436	1194.4966924645498
43.1801	0.5986349174156164	22.9595	1.2784	0.023945396696624655	1167.449067418606	0.023663201657113248	1195.4040984610492
43.5801	0.6087629174156164	22.9806	1.29081	0.024350516696624656	1168.521964272742	0.02405876950708406	1196.9760778741381
44.0001	0.6185769174156164	22.9762	1.30248	0.024743076696624657	1168.2982322273297	0.02444192428934305	1197.2055249918615
44.3901	0.6280639174156164	22.9951	1.31385	0.025122556696624655	1169.2592630587596	0.024812172951648764	1198.634045188007
44.8201	0.6391919174156163	23.0164	1.32761	0.02556767669662465	1170.3423295513232	0.025246290206163563	1200.265263857666
45.2301	0.6491689174156163	23.0296	1.33984	0.025966756696624654	1171.0135256875599	0.025635345343175103	1201.4209489975453
45.6301	0.6593989174156164	23.045	1.35195	0.026375956696624656	1171.7965878465027	0.026034109158547612	1202.7038439047944
46.0301	0.6695189174156163	23.038	1.36311	0.026780756696624653	1171.4406505015286	0.0264284287958209	1202.812717547146
46.4401	0.6800529174156164	23.0838	1.37605	0.027202116696624656	1173.7694977015012	0.026838714598462203	1205.698512552916
46.8401	0.6899989174156164	23.0831	1.38777	0.027599956696624656	1173.7339039670042	0.02722594411328767	1206.1289088898538
47.2501	0.6995669174156164	23.0856	1.39911	0.027982676696624655	1173.8610244473516	0.02759831542855853	1206.7087979812304
47.6701	0.7098199174156163	23.0966	1.41187	0.028392796696624655	1174.4203545608823	0.027997192006055157	1207.7654329243073
48.0601	0.7198699174156163	23.1339	1.42465	0.028794796696624655	1176.3169921276724	0.028388016845178218	1210.1888007667737
48.4801	0.7304319174156163	23.1436	1.43719	0.02921727669662465	1176.8102195914219	0.028798587814509845	1211.19340939664
48.9001	0.7408979174156164	23.154	1.44958	0.029635916696624656	1177.339040789669	0.02920526081782372	1212.2305625261956
49.3101	0.7511499174156163	23.1623	1.46125	0.030045996696624652	1177.761080784424	0.029603458231465082	1213.1480863270858
49.7201	0.7616539174156164	23.1826	1.47385	0.030466156696624655	1178.7932990848485	0.030011279175526418	1214.7066004476987
50.1401	0.7720579174156164	23.1812	1.48597	0.030882316696624654	1178.7221116158537	0.03041505370567061	1215.1237811640885
50.5501	0.7824709174156164	23.2111	1.49868	0.03129883669662466	1180.242472560814	0.03081901434218297	1217.1826889719155
50.9501	0.7922519174156164	23.214	1.50987	0.03169007669662466	1180.3899323180174	0.031198308677843588	1217.7965798050989
51.3501	0.8023839174156163	23.2228	1.52232	0.03209535669662465	1180.8373964088419	0.031591062690593294	1218.7367938472971
51.7701	0.8131979174156163	23.2487	1.53501	0.03252791669662465	1182.1543645852457	0.032010083450364164	1220.6073832790257
52.1801	0.8237219174156164	23.25	1.54743	0.032948876696624656	1182.2204672350265	0.032417698783710036	1221.1733036381793
52.5801	0.8337809174156163	23.2584	1.55939	0.03335123669662465	1182.6475920489954	0.03280714850834353	1222.0903518201146
53.0201	0.8448319174156164	23.2953	1.5723	0.03379327669662466	1184.5238903389295	0.033234830273090855	1224.5528339189152
53.4401	0.8551019174156164	23.2891	1.58434	0.034204076696624654	1184.208631547667	0.03363212285640043	1224.7133944059285
53.8501	0.8652879174156164	23.2824	1.59603	0.034611516696624656	1183.8679486603346	0.034026010070484405	1224.8434139319904
54.2601	0.8760229174156163	23.2995	1.60837	0.03504091669662465	1184.737452745914	0.03444095897613933	1226.2517391349547
54.6701	0.8861199174156164	23.3085	1.62085	0.035444796696624654	1185.1950864751664	0.034831089661427506	1227.2040853611172
55.0901	0.8969259174156163	23.3116	1.6329	0.035877036696624655	1185.3527158707975	0.035248446345749196	1227.8796587565378
55.4901	0.9069559174156163	23.3265	1.64481	0.03627823669662465	1186.110353933671	0.03563567601928252	1229.1403461019938
55.9001	0.9179439174156163	23.344	1.65762	0.03671775669662465	1187.0001972961059	0.03605971929576423	1230.5841817392698
56.3201	0.9280179174156163	23.3418	1.66917	0.03712071669662465	1186.8883312733997	0.036448332015839864	1230.9464767691293
56.7201	0.9391109174156164	23.3581	1.6807	0.03756443669662465	1187.7171568052677	0.03687607885351266	1232.333082755574
57.1301	0.9496889174156163	23.3639	1.69326	0.03798755669662465	1188.0120763196749	0.03728379690365861	1233.1417524251433
57.5501	0.9612759174156164	23.371	1.70658	0.038451036696624655	1188.3730984838626	0.03773021512105446	1234.067276102947
57.9601	0.9722499174156164	23.366	1.71815	0.03888999669662466	1188.118857523167	0.038152832302804786	1234.3247959674404
58.3601	0.9830329174156164	23.3862	1.73062	0.039321316696624656	1189.1459910043775	0.03856792003080739	1235.9047771151822
58.7801	0.9936779174156164	23.3884	1.74241	0.03974711669662465	1189.2578570270837	0.038977526563343	1236.5274278527168
59.1901	1.0044139174156161	23.4041	1.75433	0.04017655669662465	1190.056173643668	0.03939046479910208	1237.8685329762309
59.5901	1.0149739174156163	23.4058	1.7656	0.04059895669662465	1190.1426155703048	0.03979646727566297	1238.4611640826513
60.0001	1.0262839174156162	23.4188	1.77964	0.04105135669662465	1190.8036420681135	0.04023112241847121	1239.6877471342914
60.4101	1.0367639174156162	23.4186	1.79102	0.04147055669662465	1190.7934724296858	0.040633711224827576	1240.1763406420516
60.8101	1.0472239174156162	23.4324	1.80254	0.041888956696624645	1191.495177481206	0.04103537018280897	1241.4056673749533
61.2401	1.0594739174156163	23.4391	1.81657	0.04237895669662465	1191.835860368538	0.041505559265391435	1242.3446206845806
61.6501	1.0698839174156163	23.4262	1.82829	0.042795356696624653	1191.1799186899432	0.04190495034062243	1242.1568882001357
62.0601	1.0813439174156163	23.4453	1.8411	0.04325375669662465	1192.1511191598008	0.04234444143834913	1243.7161336135478
62.4701	1.0920639174156161	23.4603	1.8534	0.043682556696624644	1192.9138420418878	0.042755378756639366	1245.0233685810708
62.8801	1.1031139174156162	23.4436	1.86555	0.04412455669662465	1192.0646772331643	0.04317878952458626	1244.6640026697826
63.2901	1.1138939174156162	23.4558	1.87776	0.04455575669662465	1192.6850251772617	0.04359168182156526	1245.8260089747673
63.7101	1.1253739174156163	23.4592	1.89034	0.045014956696624656	1192.857909030535	0.04403119794269863	1246.554356150771
64.1201	1.1363739174156162	23.4628	1.90286	0.04545495669662465	1193.040962522236	0.044452155932745305	1247.2705878109837
64.5401	1.1481739174156163	23.4679	1.91581	0.04592695669662465	1193.3002883021454	0.044903532130455656	1248.104938969068
64.9501	1.1591239174156163	23.4914	1.92768	0.04636495669662465	1194.495220817415	0.045322211764587374	1249.8779400049395
65.3701	1.1705339174156162	23.4825	1.94012	0.04682135669662465	1194.0426719073769	0.045758293353992424	1249.949369759743
65.7701	1.1815439174156162	23.476	1.95206	0.04726175669662465	1193.7121586584724	0.046178907038020654	1250.1290922667918
66.1801	1.1926739174156162	23.4788	1.96469	0.04770695669662465	1193.854533596462	0.04660392532479076	1250.8097001328174
66.5901	1.2036739174156161	23.4913	1.97704	0.048146956696624645	1194.4901359982011	0.047023801923681975	1252.0012008506517
67.0001	1.2152939174156163	23.508	1.98919	0.04861175669662465	1195.339300806925	0.04746715289644247	1253.4468440676646
67.4101	1.2262039174156163	23.4924	2.00082	0.04904815669662465	1194.5460690095545	0.0478832356022324	1253.136351783672
67.8201	1.2378339174156163	23.4986	2.0143	0.049513356696624655	1194.861327800817	0.04832658692136323	1254.0229229272213
68.2301	1.2487739174156163	23.4975	2.02589	0.04995095669662465	1194.805394789464	0.04874345517060727	1254.4870673254861
68.6501	1.2602539174156162	23.5052	2.03866	0.05041015669662465	1195.196925868935	0.04918071332053979	1255.4469901853122
69.0601	1.2721539174156162	23.505	2.05077	0.05088615669662465	1195.1867562305074	0.04963376699517661	1256.0052167897834
69.4801	1.2834739174156162	23.5148	2.06304	0.05133895669662465	1195.685068513471	0.050064548650402434	1257.0702924686848
69.8801	1.2952939174156162	23.5072	2.07569	0.05181175669662465	1195.2986222532136	0.05051415980280715	1257.2291436492078
70.3001	1.3064539174156162	23.5146	2.08736	0.05225815669662465	1195.6748988750433	0.05093848031027339	1258.1586650986762
70.7101	1.3179239174156163	23.5026	2.09978	0.052716956696624656	1195.0647205693735	0.051374399960198	1258.064895693293
71.1301	1.3295139174156163	23.5124	2.11178	0.05318055669662465	1195.563032852337	0.05181468730043251	1259.1437405053293
71.5401	1.3410539174156162	23.5096	2.12465	0.05364215669662465	1195.4206579143474	0.05225288269718035	1259.5456001645712
71.9501	1.3525439174156162	23.5087	2.13618	0.05410175669662465	1195.3748945414222	0.05268898881459212	1260.0467762471555
72.3501	1.3636339174156162	23.5068	2.14836	0.05454535669662465	1195.278282976358	0.05310973252626068	1260.4751632730326
72.7601	1.3756939174156162	23.5097	2.16089	0.05502775669662465	1195.4257427335613	0.053567076246983696	1261.2073396535854
73.1701	1.3874939174156162	23.5188	2.17303	0.05549975669662465	1195.8884612820275	0.05401435779614504	1262.2599799194809
73.5701	1.3989339174156163	23.5122	2.18488	0.055957356696624654	1195.5528632139094	nan	nan
73.9901	1.4108339174156161	23.497	2.19762	0.056433356696624644	1194.7799706933943	nan	nan
74.4001	1.4225239174156163	23.5091	2.21034	0.056900956696624656	1195.3952338182778	nan	nan
74.8101	1.4338339174156163	23.4908	2.22152	0.05735335669662465	1194.4647119021317	nan	nan
75.2201	1.4456539174156162	23.5013	2.23439	0.05782615669662465	1194.9986179195926	nan	nan
75.6401	1.4580039174156163	23.5011	2.24728	0.05832015669662465	1194.988448281165	nan	nan
76.0601	1.4699939174156162	23.4988	2.25941	0.05879975669662465	1194.8714974392449	nan	nan
76.4701	1.4822939174156162	23.502	2.27205	0.05929175669662465	1195.03421165409	nan	nan
76.8701	1.4941139174156162	23.4896	2.28484	0.05976455669662464	1194.4036940715646	nan	nan
77.3001	1.5063739174156163	23.4996	2.29764	0.06025495669662465	1194.9121759929562	nan	nan
77.7101	1.5185139174156161	23.4891	2.31034	0.06074055669662465	1194.3782699754952	nan	nan
78.1201	1.5300539174156162	23.4824	2.32178	0.06120215669662465	1194.0375870881628	nan	nan
78.5301	1.5423639174156163	23.4789	2.33457	0.06169455669662465	1193.8596184156759	nan	nan
78.9301	1.5537139174156163	23.4691	2.34605	0.06214855669662465	1193.3613061327123	nan	nan
79.3401	1.5658139174156163	23.4712	2.35824	0.06263255669662465	1193.4680873362045	nan	nan
79.7501	1.5778239174156163	23.4611	2.37043	0.06311295669662466	1192.9545205955992	nan	nan
80.1501	1.5898939174156161	23.4522	2.38305	0.06359575669662465	1192.5019716855609	nan	nan
80.5601	1.6021139174156163	23.4663	2.39555	0.06408455669662465	1193.2189311947227	nan	nan
80.9601	1.6140239174156163	23.4466	2.40715	0.06456095669662465	1192.2172218095816	nan	nan
81.3701	1.6265739174156162	23.4364	2.42015	0.06506295669662465	1191.6985702497623	nan	nan
81.7701	1.6383839174156163	23.4208	2.432	0.06553535669662465	1190.9053384523918	nan	nan
82.1801	1.6501339174156162	23.429	2.44362	0.06600535669662465	1191.3222936279328	nan	nan
82.5801	1.6624139174156163	23.417	2.45557	0.06649655669662465	1190.7121153222631	nan	nan
83.0001	1.6749739174156162	23.4051	2.46789	0.06699895669662465	1190.1070218358075	nan	nan
83.4201	1.6874839174156162	23.3941	2.48043	0.06749935669662464	1189.5476917222768	nan	nan
83.8301	1.7001039174156163	23.394	2.49287	0.06800415669662466	1189.5426069030627	nan	nan
84.2501	1.7126339174156162	23.3745	2.50487	0.06850535669662465	1188.5510671563495	nan	nan
84.6401	1.7248439174156163	23.3629	2.51707	0.06899375669662465	1187.9612281275356	nan	nan
85.0701	1.7386039174156163	23.3522	2.53098	0.06954415669662466	1187.417152471647	nan	nan
85.4701	1.7503939174156162	23.3234	2.54221	0.07001575669662465	1185.9527245380393	nan	nan
85.8701	1.7625639174156162	23.3212	2.55434	0.07050255669662465	1185.8408585153334	nan	nan
86.2901	1.7754039174156162	23.2889	2.56796	0.07101615669662464	1184.1984619092393	nan	nan
86.6901	1.7876939174156163	23.2798	2.5797	0.07150775669662465	1183.735743360773	nan	nan
87.0901	1.8001139174156162	23.2658	2.59161	0.07200455669662464	1183.0238686708249	nan	nan
87.5001	1.8127139174156162	23.2528	2.60332	0.07250855669662465	1182.3628421730161	nan	nan
87.9001	1.8253439174156163	23.2396	2.61671	0.07301375669662465	1181.6916460367795	nan	nan
88.3101	1.8379139174156163	23.2106	2.62836	0.07351655669662466	1180.2170484647443	nan	nan
88.7301	1.8507839174156162	23.1748	2.64066	0.07403135669662465	1178.3966831861633	nan	nan
89.1401	1.8637439174156163	23.173	2.65395	0.07454975669662466	1178.3051564403127	nan	nan
89.5701	1.8766739174156162	23.1413	2.66637	0.07506695669662465	1176.693268749502	nan	nan
89.9801	1.8899239174156162	23.1181	2.67879	0.07559695669662464	1175.5135906918738	nan	nan
90.3901	1.9020839174156163	23.0917	2.69095	0.07608335669662465	1174.1711984194005	nan	nan
90.8001	1.9151239174156163	23.0662	2.7037	0.07660495669662465	1172.8745695198522	nan	nan
91.2101	1.9282739174156163	23.0386	2.71586	0.07713095669662465	1171.471159416812	nan	nan
91.6201	1.9407739174156162	23.0102	2.72707	0.07763095669662465	1170.0270707600605	nan	nan
92.0401	1.9544239174156162	22.9888	2.7407	0.07817695669662465	1168.938919448283	nan	nan
92.4501	1.9670139174156163	22.9519	2.75257	0.07868055669662465	1167.0626211583485	nan	nan
92.8501	1.9803239174156162	22.9194	2.76525	0.07921295669662465	1165.4100549138263	nan	nan
93.2601	1.9928839174156163	22.9061	2.77715	0.07971535669662465	1164.7337739583759	nan	nan
93.6801	2.0058139174156167	22.8709	2.78972	0.08023255669662467	1162.9439175950781	nan	nan
94.1001	2.0188439174156163	22.8415	2.80201	0.08075375669662466	1161.4489807461875	nan	nan
94.5001	2.0313539174156166	22.8145	2.81413	0.08125415669662467	1160.0760795584306	nan	nan
94.9101	2.0447639174156165	22.7809	2.82686	0.08179055669662466	1158.3675803025553	nan	nan
95.3101	2.0574639174156166	22.7438	2.8385	0.08229855669662467	1156.4811123741933	nan	nan
95.7201	2.0704839174156167	22.728	2.85101	0.08281935669662467	1155.677710938395	nan	nan
96.1201	2.0832139174156166	22.6997	2.86317	0.08332855669662466	1154.2387071008573	nan	nan
96.5501	2.0972039174156163	22.6447	2.87577	0.08388815669662465	1151.4420565332045	nan	nan
96.9801	2.1105839174156165	22.6163	2.88852	0.08442335669662465	1149.997967876453	nan	nan
97.3901	2.1237239174156164	22.5677	2.90096	0.08494895669662465	1147.5267457384905	nan	nan
97.8001	2.1362339174156166	22.5534	2.91338	0.08544935669662466	1146.799616590901	nan	nan
98.2201	2.1493939174156163	22.5135	2.92638	0.08597575669662465	1144.7707737245494	nan	nan
98.6201	2.1622239174156164	22.4774	2.93829	0.08648895669662465	1142.9351539883262	nan	nan
99.0401	2.1758639174156165	22.4607	2.95136	0.08703455669662466	1142.0859891796026	nan	nan
99.4501	2.1890239174156165	22.415	2.96334	0.08756095669662466	1139.7622267988438	nan	nan
99.8501	2.2019339174156163	22.3888	2.97536	0.08807735669662466	1138.4300041647984	nan	nan
100.27	2.2154539174156165	22.3362	2.98808	0.08861815669662466	1135.7553892582796	nan	nan
100.68	2.2282539174156164	22.3039	2.99994	0.08913015669662466	1134.1129926521853	nan	nan
101.09	2.2412839174156165	22.2644	3.01195	0.08965135669662466	1132.1044890626893	nan	nan
101.51	2.2545639174156165	22.2222	3.02551	0.09018255669662466	1129.9586953544176	nan	nan
101.91	2.2671339174156167	22.1957	3.03722	0.09068535669662467	1128.61121826273	nan	nan
102.32	2.2798039174156166	22.1606	3.04939	0.09119215669662467	1126.8264467186464	nan	nan
102.72	2.2928339174156163	22.1271	3.0616	0.09171335669662466	1125.1230322819852	nan	nan
103.14	2.3062439174156166	22.0877	3.07431	0.09224975669662466	1123.1196135117032	nan	nan
103.55	2.3198739174156167	22.0425	3.08675	0.09279495669662467	1120.821275227014	nan	nan
103.96	2.3327439174156166	22.0053	3.09904	0.09330975669662467	1118.9297224794377	nan	nan
104.37	2.3459839174156163	21.9641	3.11131	0.09383935669662465	1116.834776963305	nan	nan
104.79	2.3595639174156164	21.9269	3.12374	0.09438255669662465	1114.9432242157293	nan	nan
105.19	2.3725439174156167	21.8867	3.13619	0.09490175669662466	1112.8991268917357	nan	nan
105.6	2.3851339174156165	21.844	3.14754	0.09540535669662466	1110.7279090873944	nan	nan
106.01	2.3985339174156164	21.8166	3.16054	0.09594135669662465	1109.3346686227821	nan	nan
106.43	2.4120939174156164	21.7805	3.17364	0.09648375669662465	1107.499048886559	nan	nan
106.84	2.4250039174156166	21.7328	3.18512	0.09700015669662466	1105.0735901215219	nan	nan
107.26	2.4388139174156165	21.6989	3.19827	0.09755255669662466	1103.3498364080049	nan	nan
107.66	2.4519639174156165	21.6278	3.21009	0.09807855669662466	1099.734529946912	nan	nan
108.07	2.4649439174156162	21.6139	3.22239	0.09859775669662466	1099.0277400761781	nan	nan
108.49	2.4782539174156164	21.5762	3.23524	0.09913015669662466	1097.1107632325325	nan	nan
108.9	2.4911439174156165	21.521	3.24703	0.09964575669662466	1094.3039430264519	nan	nan
109.31	2.5046839174156164	21.4837	3.26003	0.10018735669662465	1092.4073054596618	nan	nan
109.73	2.5185839174156164	21.4192	3.27217	0.10074335669662465	1089.1275970666875	nan	nan
110.13	2.5312839174156165	21.3902	3.2844	0.10125135669662466	1087.6529994946522	nan	nan
110.55	2.5447839174156166	21.3498	3.29686	0.10179135669662466	1085.598732532231	nan	nan
110.97	2.5580339174156164	21.3099	3.30984	0.10232135669662465	1083.5698896658791	nan	nan
111.37	2.5715039174156167	21.2573	3.32153	0.10286015669662467	1080.8952747593603	nan	nan
111.79	2.5851439174156163	21.2217	3.33484	0.10340575669662465	1079.085079119207	nan	nan
112.21	2.5985939174156165	21.1668	3.34721	0.10394375669662466	1076.293513370768	nan	nan
112.62	2.6114739174156165	21.1228	3.35936	0.10445895669662467	1074.056192916646	nan	nan
113.03	2.6247239174156163	21.0722	3.37167	0.10498895669662466	1071.4832743944053	nan	nan
113.45	2.6380439174156165	21.0264	3.38461	0.10552175669662466	1069.1544271944326	nan	nan
113.86	2.6514939174156162	20.9872	3.39706	0.10605975669662465	1067.1611780625785	nan	nan
114.27	2.6652539174156167	20.9336	3.40986	0.10661015669662467	1064.4357149639204	nan	nan
114.68	2.6782239174156164	20.8691	3.42137	0.10712895669662466	1061.156006570946	nan	nan
115.1	2.6916939174156163	20.8179	3.43406	0.10766775669662465	1058.552579133422	nan	nan
115.51	2.7053239174156163	20.7812	3.44655	0.10821295669662465	1056.6864504819152	nan	nan
115.92	2.7184439174156165	20.7236	3.4584	0.10873775669662467	1053.757594614701	nan	nan
116.33	2.7329639174156166	20.6586	3.47133	0.10931855669662466	1050.4524621256567	nan	nan
116.75	2.7464539174156166	20.5931	3.48368	0.10985815669662466	1047.121905540543	nan	nan
117.16	2.7600539174156165	20.5364	3.49665	0.11040215669662466	1044.2388130462539	nan	nan
117.58	2.7738339174156166	20.4696	3.50914	0.11095335669662466	1040.8421538113591	nan	nan
117.99	2.7878539174156165	20.4014	3.52177	0.11151415669662466	1037.3743071074696	nan	nan
118.39	2.8012439174156163	20.325	3.53362	0.11204975669662465	1033.4895052280394	nan	nan
118.81	2.8160739174156166	20.2179	3.5462	0.11264295669662466	1028.0436638499375	nan	nan