File: original_data/46NTAB.csv
Specimen name:	AWA_3_06_Rz
Specimen ID:	46NTAB
Material:	42CrMoS4
Specimen type:	Round Tensile Specimen
Gauge diameter:	5.012	mm
Gauge length:	25	mm
Parallel length:	30	mm
Original cross-section:	19.729314961879428	mm²
Cross-section after fracture:	10.09411391057077	mm²
Yield stress at 0.2% plastic strain:	1084.3977857605105	MPa
Yield stress at 1% plastic strain:	1128.8671492870556	MPa
Ultimate tensile strength:	1181.8200502679215	MPa
Uniform elongation:	5.04855508833242	%
Elongation after fracture:	13.297709591890749	%
Reduction of area:	48.8369772084109	%
Slope of linear-elastic region:	210160.10139532542	MPa
Crosshead seperation speed:	0.02995096653413265	mm/s
Strain rate:	0.000998365551137755	s-1
Test temperature:	RT	Cel
Machine type:	INSTRON 8852TT
Standard:	DIN EN ISO 6892-1
Date:	2022-09-06 00:00:00
Heat treatment batch:	Batch 3
Time	Displacement	Force	Machine Displacement	Engineering Strain	Engineering Stress	True Strain	True Stress
s	mm	kN	mm		MPa		MPa
0	0.0009959798420759829	0.16506	0	3.9839193683039316e-05	8.366230673438256	3.983840012351085e-05	8.366563977322453
0.420001	0.0010585125420759828	0.162987	-0.000106811	4.234050168303931e-05	8.261158601549019	4.233960534920635e-05	8.26150838314869
0.840001	0.0011692468420759828	0.178726	0.000869751	4.676987368303931e-05	9.058905509153798	4.6768780006575324e-05	9.059329193020167
1.25	0.002772359842075983	0.447833	0.0139465	0.00011089439368303932	22.698862117883646	0.00011088824535421173	22.7013792944355
1.65	0.004530899842075983	0.719887	0.0254593	0.00018123599368303933	36.48819035992637	0.00018121957242437555	36.49480333336395
2.07	0.006444979842075983	1.0322	0.0383835	0.0002577991936830393	52.318086157294125	0.00025776596918087365	52.33157371772051
2.49	0.008445699842075983	1.35597	0.0506668	0.0003378279936830393	68.72869142288907	0.00033777094265491863	68.75190989882093
2.9	0.010475799842075983	1.68607	0.0626068	0.00041903199368303933	85.46013904982455	0.0004189442242950502	85.49594958227102
3.31	0.012676979842075983	2.03991	0.0749817	0.0005070791936830393	103.39487224677956	0.0005069506724737655	103.44730163522941
3.72001	0.014879879842075982	2.39043	0.0870972	0.0005951951936830393	121.1613279335212	0.000595018135276551	121.2334425735675
4.12001	0.016864579842075983	2.7143	0.0987015	0.0006745831936830393	137.5770017988214	0.0006743557647144575	137.6698089320722
4.53001	0.019257479842075983	3.11923	0.112236	0.0007702991936830393	158.10128258517395	0.0007700026655263674	158.22306787566959
4.94001	0.021327179842075984	3.45004	0.122726	0.0008530871936830393	174.8687172700165	0.0008527235216175444	175.0178955332953
5.36001	0.023677579842075983	3.84507	0.135902	0.0009471031936830393	194.89120668555216	0.0009466549744374819	195.07578876982478
5.77001	0.026313379842075983	4.26954	0.148705	0.0010525351936830393	216.40589185430494	0.0010519816668862502	216.63366667160196
6.19001	0.028775279842075983	4.68992	0.161095	0.0011510111936830394	237.7132712951142	0.0011503492881574273	237.98688193126188
6.60001	0.03128347984207598	5.08531	0.173195	0.0012513391936830392	257.7540076695886	0.0012505569213182494	258.0765453617144
7.01001	0.033938879842075984	5.52971	0.185966	0.0013575551936830393	280.27886475959207	0.0013566345487544748	280.65935878812604
7.43001	0.03640627984207598	5.96912	0.198875	0.0014562511936830392	302.5507987243049	0.0014551918881987496	302.99138868609697
7.84001	0.038938279842075985	6.3832	0.210899	0.0015575311936830395	323.53885638368524	0.0015563194999774178	324.0427782448714
8.24001	0.04135867984207599	6.77266	0.222244	0.0016543471936830395	343.27902479564	0.0016529802687356477	343.8469274869609
8.66001	0.043819879842075984	7.20242	0.234558	0.0017527951936830394	365.06183888879906	0.0017512608408634547	365.70171752540045
9.08001	0.046388379842075986	7.61685	0.247757	0.0018555351936830394	386.06763664714765	0.0018538158148390066	386.78399873408847
9.49001	0.04906257984207599	8.06034	0.260857	0.0019625031936830396	408.5463694798335	0.0019605800000616997	409.3481430347053
9.89001	0.051320179842075986	8.4443	0.271446	0.0020528071936830395	428.0077649080011	0.0020507030640852498	428.8863823267564
10.31	0.05399277984207598	8.90979	0.284874	0.002159711193683039	451.60158967583567	0.002157382369918078	452.57691868414366
10.72	0.056581079842075985	9.33426	0.297173	0.0022632431936830395	473.11627484458853	0.0022606859165727133	474.18705203345127
11.12	0.05908807984207598	9.73456	0.307999	0.0023635231936830394	493.4058794645893	0.002360734466023351	494.5720557046034
11.54	0.06158837984207598	10.1754	0.321075	0.002463535193683039	515.7502944050868	0.0024605056654040136	517.0208634065061
11.96	0.06391667984207598	10.5798	0.333458	0.002556667193683039	536.2477116130018	0.0025534044800454097	537.6187185449703
12.36	0.06658707984207599	11.0049	0.345573	0.0026634831936830396	557.7943289598974	0.002659942408143304	559.2800047806138
12.77	0.069139379842076	11.4235	0.358406	0.00276557519368304	579.0114873259538	0.002761758026762271	580.61278713216
13.17	0.071423579842076	11.8188	0.369621	0.00285694319368304	599.0476619606934	0.0028528698877686616	600.7591071012238
13.59	0.07384647984207598	12.2344	0.382111	0.0029538591936830393	620.1127623355933	0.0029495051237141603	621.9444881197385
14	0.07659067984207599	12.6782	0.395477	0.0030636271936830394	642.6072078273653	0.0030589438507984306	644.575916744122
14.42	0.07888757984207599	13.0653	0.40612	0.0031555031936830397	662.2277572862769	0.0031505350420821306	664.3174190893392
14.82	0.08154357984207598	13.5029	0.41935	0.0032617431936830393	684.4079495963251	0.003256435248323493	686.6403125676235
15.23	0.08395817984207599	13.8976	0.430527	0.0033583271936830396	704.4137126328336	0.003352700606674018	706.7793643595717
15.64	0.08653067984207599	14.3455	0.444252	0.0034612271936830395	727.1159707125197	0.003455250933000413	729.6326842833112
16.04	0.08888287984207599	14.7384	0.456245	0.0035553151936830395	747.0304989543341	0.0035490100008325086	749.6864278374112
16.46	0.09131997984207599	15.136	0.468391	0.0036527991936830396	767.183251382294	0.003646143924691989	769.9856177443503
16.87	0.09351727984207599	15.5174	0.48098	0.0037406911936830396	786.514890658008	0.003733712207120999	789.456999983193
17.28	0.09615567984207599	15.9302	0.49276	0.0038462271936830395	807.4380702411614	0.003838849373667143	810.5436605041378
17.7	0.09846257984207599	16.3532	0.505783	0.0039385031936830395	828.8782469942475	0.0039307675944488234	832.1427866172087
18.1	0.10105397984207598	16.7619	0.518219	0.004042159193683039	849.593613989487	0.004034011616698418	853.027806627169
18.51	0.10316897984207599	17.1275	0.529343	0.004126759193683039	868.124414511776	0.004118267477124828	871.7069549206232
18.93	0.10583897984207599	17.5551	0.542084	0.00423355919368304	889.7977468513021	0.0042246228946490995	893.5647582830029
19.33	0.10839097984207599	17.9635	0.554306	0.00433563919368304	910.4979080474259	0.004326267388819228	914.4454984633228
19.74	0.11082397984207598	18.3645	0.567436	0.004432959193683039	930.8229928653633	0.00442316257142447	934.9492932092775
20.17	0.11341197984207599	18.7745	0.580307	0.00453647919368304	951.6042516567705	0.004526220386156219	955.9211845450318
20.57	0.115650979842076	19.1474	0.592377	0.004626039193683039	970.5050599575408	0.004615371959749316	974.994654402572
20.97	0.11795197984207599	19.5147	0.603546	0.004718079193683039	989.1220266748186	0.004706983943204097	993.7887827288865
21.37	0.12036397984207599	19.8815	0.615883	0.00481455919368304	1007.7136503935702	0.0048030062702180245	1012.5653474136725
21.79	0.12317997984207599	20.2829	0.629227	0.004927199193683039	1028.0590096103285	0.004915100273985279	1033.1244611335392
22.2	0.12657097984207596	20.6445	0.641861	0.005062839193683039	1046.3870661444087	0.005050066117213863	1051.6847555946476
22.61	0.13022197984207598	20.9141	0.653053	0.005208879193683039	1060.0520109496854	0.00519535990901433	1065.5736938137431
23.03	0.13669897984207596	21.112	0.666557	0.005467959193683039	1070.082769766318	0.005453064177037413	1075.9339386852637
23.44	0.14555197984207596	21.1745	0.679283	0.005822079193683038	1073.2506445820813	0.005805196387609079	1079.4991948295094
23.85	0.15508397984207598	21.2205	0.691002	0.006203359193683039	1075.5822004464833	0.006184197564522246	1082.2544231781847
24.27	0.16471197984207597	21.2772	0.70388	0.006588479193683039	1078.4560964793438	0.006566870027073825	1085.5614820322985
24.69	0.17377997984207597	21.3474	0.71624	0.006951199193683038	1082.014253472409	0.0069271509868352255	1089.5355500787
25.1	0.18299897984207597	21.42	0.729134	0.007319959193683039	1085.6940568583998	0.0072932983176791834	1093.6412930514275
25.51	0.19172497984207598	21.4951	0.741005	0.007668999193683039	1089.500575237021	0.007639741906899197	1097.855954270031
25.94	0.20104797984207598	21.5545	0.754074	0.00804191919368304	1092.5113234619223	0.00800975528615206	1101.297211243387
26.36	0.21042097984207597	21.6212	0.766228	0.008416839193683039	1095.892079465305	0.008381615114934269	1105.1160268717952
26.78	0.21985497984207597	21.6964	0.778984	0.00879419919368304	1099.7036664436314	0.008755755447523085	1109.3746795403604
27.18	0.22893097984207597	21.7385	0.790871	0.00915723919368304	1101.8375469195296	0.009115565893909936	1111.9273368892525
27.59	0.23808697984207597	21.7879	0.802521	0.009523479193683038	1104.3414351739088	0.009478416740685787	1114.8586078545097
28	0.24763797984207597	21.8366	0.815643	0.009905519193683038	1106.8098432303518	0.009856781124739564	1117.7733693762273
28.41	0.256431979842076	21.8837	0.826775	0.01025727919368304	1109.197153691511	0.01020503028944637	1120.5744985777633
28.82	0.266175979842076	21.9198	0.839317	0.01064703919368304	1111.0269181850956	0.010590758600565638	1122.8560653282493
29.22	0.275641979842076	21.9602	0.851624	0.01102567919368304	1113.0746324660051	0.010965339511692937	1125.347036282202
29.63	0.285218979842076	21.9973	0.863678	0.01140875919368304	1114.9550829566422	0.011344170090633076	1127.6753370098675
30.05	0.295211979842076	22.0293	0.875999	0.011808479193683039	1116.577034862313	0.011739303146655453	1129.7621115466288
30.45	0.305188979842076	22.0576	0.88855	0.01220755919368304	1118.0114485788908	0.012133647853024116	1131.659639516633
30.86	0.315590979842076	22.0861	0.900848	0.01262363919368304	1119.4559994948786	0.012544625327282654	1133.5876081257059
31.26	0.325220979842076	22.1088	0.911987	0.01300883919368304	1120.6065716279638	0.012924950987295595	1135.1843623176565
31.67	0.334978979842076	22.1438	0.924171	0.013399159193683039	1122.3805815247913	0.01331018437083699	1137.4195376125406
32.09	0.344994979842076	22.1619	0.936798	0.01379979919368304	1123.2979980714363	0.013705448983181611	1138.7992848794884
32.48	0.354571979842076	22.1877	0.948471	0.01418287919368304	1124.6056967953837	0.014083243141523209	1140.5558435335604
32.88	0.364368979842076	22.2149	0.960281	0.01457475919368304	1125.9843559152039	0.014469568247547627	1142.3953067585223
33.29	0.374185979842076	22.2536	0.972923	0.014967439193683041	1127.9459040011243	0.014856532367054066	1144.828365733025
33.71	0.384472979842076	22.271	0.9851	0.01537891919368304	1128.827840349833	0.015261862230043863	1146.1879924901527
34.13	0.394925979842076	22.2943	0.996834	0.01579703919368304	1130.0088240811494	0.01567356462754352	1147.859617764367
34.54	0.405689979842076	22.3102	1.01011	0.01622759919368304	1130.8147314342796	0.01609733902309935	1149.1651396583075
34.94	0.415381979842076	22.3273	1.022	0.01661527919368304	1131.6814619838724	0.016478755618372542	1150.48466543305
35.37	0.425812979842076	22.3449	1.03432	0.01703251919368304	1132.5735355319912	0.016889092163555323	1151.8641160141974
35.8001	0.436136979842076	22.3656	1.04646	0.01744547919368304	1133.6227356709724	0.017295053796955964	1153.3993275196065
36.2101	0.446186979842076	22.3829	1.05894	0.01784747919368304	1134.4996034199753	0.017690082928827126	1154.747561487255
36.6201	0.456417979842076	22.4234	1.0721	0.01825671919368304	1136.5523863005901	0.0180920662908131	1157.3021040661904
37.0301	0.466351979842076	22.4402	1.08356	0.01865407919368304	1137.4039110510673	0.018482225747334477	1158.6211336830188
37.4501	0.476662979842076	22.4568	1.09596	0.01906651919368304	1138.2452986021342	0.018887031004697404	1159.947674435051
37.8501	0.486467979842076	22.4665	1.10739	0.01945871919368304	1138.7369527735405	0.019271818985197933	1160.895315373031
38.2601	0.497143979842076	22.4957	1.12001	0.019885759193683038	1140.2169838874652	0.019690620233115918	1162.8910642575988
38.6801	0.507021979842076	22.5122	1.13203	0.02028087919368304	1141.0533028388265	0.020077961146848813	1164.1948670272538
39.0801	0.517410979842076	22.5409	1.14463	0.02069643919368304	1142.5079909542253	0.020485177828777314	1166.1538381173063
39.4801	0.527016979842076	22.548	1.15607	0.02108067919368304	1142.8678615332958	0.020861555838968242	1166.9602922830497
39.9001	0.537128979842076	22.5597	1.16795	0.02148515919368304	1143.4608876988068	0.021257606725246146	1168.028326902766
40.3101	0.546684979842076	22.5774	1.17975	0.021867399193683038	1144.3580298466309	0.021631736977893556	1169.3821637057838
40.7201	0.557028979842076	22.5978	1.19281	0.02228115919368304	1145.392024186496	0.022036560789698234	1170.9126862165701
41.1401	0.567474979842076	22.6137	1.20595	0.02269899919368304	1146.1979315396263	0.022445210237078825	1172.2154774634455
41.5401	0.577159979842076	22.6356	1.21795	0.02308639919368304	1147.3079548750695	0.02282394009304114	1173.7951643194033
41.9501	0.586887979842076	22.6599	1.2298	0.02347551919368304	1148.5396246034386	0.02320420711667045	1175.5021886055222
42.3601	0.597226979842076	22.6594	1.24145	0.02388907919368304	1148.5142816049124	0.023608199650243054	1175.951230233248
42.7701	0.607147979842076	22.6843	1.25423	0.02428591919368304	1149.7763629315125	0.023995705605816514	1177.6997387724741
43.1801	0.617679979842076	22.6992	1.26683	0.02470719919368304	1150.5315842875905	0.024406912458739344	1178.9579973192078
43.5901	0.627344979842076	22.7155	1.27852	0.025093799193683042	1151.3577660395415	0.024784119811929253	1180.2497066206251
44.0101	0.637717979842076	22.731	1.29153	0.02550871919368304	1152.1433989938507	0.02518880087707191	1181.5331014296405
44.4201	0.647699979842076	22.7508	1.30456	0.02590799919368304	1153.1469817354848	0.025578073326168235	1183.0227128084857
44.8301	0.657092979842076	22.7514	1.31571	0.026283719193683042	1153.177393333716	0.025944237949903547	1183.487184120603
45.2501	0.667473979842076	22.7777	1.32818	0.02669895919368304	1154.5104350561892	0.026348761582795147	1185.3346620504356
45.6501	0.677509979842076	22.806	1.34145	0.02710039919368304	1155.9448487727668	0.026739685850516892	1187.2714156203904
46.0501	0.687353979842076	22.8071	1.35306	0.027494159193683042	1156.000603369524	0.027122982889062338	1187.7838679865592
46.4701	0.697845979842076	22.8314	1.36532	0.027913839193683038	1157.2322730978929	0.02753134950645565	1189.5350686788877
46.8801	0.708465979842076	22.8559	1.3783	0.02833863919368304	1158.474080025672	0.027944528345638403	1191.3036589947535
47.2801	0.718202979842076	22.8441	1.39038	0.02872811919368304	1157.8759852604562	0.0283232034693951	1191.1395845765217
47.7001	0.728474979842076	22.8779	1.40331	0.02913899919368304	1159.589171960821	0.028722529550062485	1193.378439907591
48.1301	0.738804979842076	22.8868	1.41557	0.029552199193683043	1160.0402773345854	0.02912394964247101	1194.3220186830724
48.5201	0.748110979842076	22.8901	1.42719	0.02992443919368304	1160.2075411248577	0.029485439544434573	1194.926101141301
48.9301	0.757882979842076	22.9038	1.43914	0.03031531919368304	1160.9019392844732	0.029864890531242107	1196.0950521264479
49.3401	0.768176979842076	22.913	1.45177	0.03072707919368304	1161.3682504573535	0.030264455339613205	1197.0537046621857
49.7601	0.778683979842076	22.9439	1.46423	0.03114735919368304	1162.9344477662669	0.0306721232344141	1199.1567847295503
50.1701	0.788705979842076	22.9467	1.47596	0.03154823919368304	1163.0763685580132	0.031060818498378943	1199.7693800338016
50.5801	0.799504979842076	22.9627	1.48887	0.03198019919368304	1163.8873445108486	0.0314794800474749	1201.1086936273123
51.0001	0.809512979842076	22.9664	1.50074	0.03238051919368304	1164.0748826999418	0.031867319247719635	1201.7682317820916
51.4201	0.820139979842076	22.982	1.51364	0.03280559919368304	1164.8655842539563	0.03227898190825995	1203.079697725507
51.8301	0.829816979842076	23.002	1.52567	0.033192679193683045	1165.8793041950005	0.03265369664890456	1204.5779619176994
52.2401	0.840026979842076	23.0091	1.53822	0.03360107919368304	1166.2391747740712	0.033048898157190615	1205.4260696444303
52.6501	0.849598979842076	23.0132	1.54965	0.03398395919368304	1166.4469873619853	0.03341926261356659	1206.0874741820894
53.0601	0.859996979842076	23.0319	1.56275	0.03439987919368304	1167.3948155068617	0.03382143168672102	1207.5530561316298
53.4801	0.871090979842076	23.0478	1.57607	0.03484363919368304	1168.2007228599919	0.03425034206180229	1208.905087353125
53.8701	0.880277979842076	23.0539	1.58731	0.03521111919368304	1168.5099074420102	0.03460538581354006	1209.6544490719505
54.2801	0.890723979842076	23.0684	1.5993	0.03562895919368304	1169.2448543992675	0.0350089321907146	1210.903831604083
54.7001	0.901221979842076	23.07	1.61295	0.03604887919368304	1169.325951994551	0.035414323413200874	1211.478841976041
55.1101	0.911806979842076	23.0789	1.62467	0.03647227919368304	1169.7770573683158	0.03582290790863711	1212.441492799018
55.5201	0.921769979842076	23.0993	1.63725	0.03687079919368304	1170.8110517081807	0.036207330543812005	1213.9797908894577
55.9301	0.932229979842076	23.1118	1.64983	0.03728919919368304	1171.4446266713335	0.03661077097849437	1215.1268586996505
56.3301	0.942216979842076	23.114	1.66179	0.03768867919368304	1171.5561358648483	0.03699581605207948	1215.7105392268495
56.7401	0.951769979842076	23.1209	1.67329	0.03807079919368304	1171.9058692445085	0.03736398973337066	1216.5212622664149
57.1401	0.962026979842076	23.1346	1.68553	0.038481079193683036	1172.6002674041238	0.037759144807133785	1217.7231911566357
57.5501	0.972849979842076	23.149	1.69865	0.03891399919368304	1173.3301457616758	0.03817593601913886	1218.9891141077696
57.9601	0.983100979842076	23.1568	1.71082	0.03932403919368304	1173.725496538683	0.03857053952244001	1219.8811239671954
58.3801	0.993712979842076	23.172	1.72355	0.03974851919368304	1174.4959236938766	0.03897887544528753	1221.180397459725
58.7901	1.004455979842076	23.1606	1.73582	0.04017823919368304	1173.9181033274813	0.03939208230882868	1221.0840656767678
59.1901	1.014445979842076	23.1741	1.7477	0.04057783919368304	1174.6023642876862	0.03977617346594524	1222.2651901422719
59.6001	1.024635979842076	23.1907	1.75965	0.04098543919368305	1175.443751838753	0.04016780220905537	1223.619830255335
60.0001	1.034205979842076	23.1869	1.77178	0.041368239193683036	1175.2511450499546	0.04053546309998378	1223.869215531031
60.4001	1.044495979842076	23.1934	1.78386	0.04177983919368304	1175.5806040307941	0.04093063424468223	1224.6961726264135
60.8101	1.055195979842076	23.2022	1.79656	0.04220783919368304	1176.0266408048535	0.04134138523947587	1225.664184147432
61.2101	1.065175979842076	23.2035	1.80824	0.042607039193683034	1176.0925326010213	0.04172434490559985	1226.2023532329508
61.6401	1.075915979842076	23.2235	1.82115	0.04303663919368304	1177.1062525420657	0.04213630406288765	1227.7649496253468
62.0601	1.087005979842076	23.2211	1.83317	0.04348023919368304	1176.9846061491403	0.042561510310944975	1228.1601783517876
62.4701	1.097785979842076	23.227	1.84617	0.04391143919368304	1177.2836535317483	0.04297465750377711	1228.9798730975247
62.8801	1.1084559798420761	23.2275	1.85786	0.04433823919368304	1177.3089965302745	0.04338342089099084	1229.508804423309
63.3001	1.119355979842076	23.2442	1.87067	0.04477423919368304	1178.1554526810464	0.04380082302787013	1230.9064667267294
63.7101	1.129835979842076	23.2433	1.88348	0.045193439193683044	1178.1098352836996	0.04420197756241793	1231.3526704880733
64.1301	1.140425979842076	23.2485	1.89561	0.04561703919368304	1178.3734024683708	0.04460717928698796	1232.1273081535642
64.5401	1.150595979842076	23.2518	1.9072	0.04602383919368304	1178.5406662586431	0.04499615619916512	1232.781632365747
64.9401	1.161115979842076	23.264	1.91894	0.046444639193683045	1179.1590354226803	0.045398360590790526	1233.924651374858
65.3501	1.172195979842076	23.2657	1.93215	0.04688783919368304	1179.245201617669	0.045821800260501956	1234.5374610010406
65.7601	1.182315979842076	23.2539	1.94342	0.04729263919368304	1178.647106852453	0.046208395407595707	1234.3884392135042
66.1801	1.193755979842076	23.2692	1.95641	0.04775023919368304	1179.4226026073518	0.0466452361157241	1235.740313992289
66.6001	1.204655979842076	23.2719	1.96823	0.04818623919368304	1179.5594547993926	0.04706127926472694	1236.3979888315266
67.0001	1.215345979842076	23.2815	1.98083	0.04861383919368304	1180.046040371094	0.047469138850707415	1237.4126088188368
67.4101	1.226135979842076	23.2875	1.99356	0.04904543919368304	1180.3501563534073	0.04788064515255285	1238.2409481740926
67.8201	1.236605979842076	23.2886	2.00504	0.04946423919368304	1180.4059109501645	0.04827978556145667	1238.7937912750408
68.2301	1.247655979842076	23.2835	2.01723	0.04990623919368305	1180.1474123651983	0.048700864176290194	1239.0441314105021
68.6501	1.258555979842076	23.2927	2.03001	0.05034223919368304	1180.6137235380788	0.0491160531510708	1240.0484620037776
69.0601	1.269215979842076	23.2943	2.04202	0.05076863919368304	1180.6948211333622	0.04952193368811418	1240.637090505332
69.4701	1.279895979842076	23.2967	2.05353	0.051195839193683035	1180.8164675262876	0.0499284105912917	1241.2693575150163
69.8801	1.291215979842076	23.2905	2.06611	0.05164863919368304	1180.502214344564	0.050359065365481494	1241.4735472805903
70.2901	1.302285979842076	23.2931	2.07892	0.052091439193683045	1180.6339979368995	0.05078002992387751	1242.1349220504244
70.7101	1.313565979842076	23.2915	2.09086	0.052542639193683044	1180.5529003416161	0.051208798051834516	1242.5822654333217
71.1201	1.324705979842076	23.3048	2.1031	0.052988239193683034	1181.2270241024105	0.05163206423256518	1243.8181641975916
71.5301	1.335405979842076	23.2976	2.11548	0.053416239193683046	1180.8620849236345	0.052038443928660104	1243.9392965066666
71.9501	1.346945979842076	23.3024	2.12846	0.05387783919368304	1181.105377709485	0.052476541308724	1244.740783320511
72.3501	1.357415979842076	23.2937	2.13969	0.054296639193683036	1180.664409535131	0.05287385188221085	1244.7705189884828
72.7601	1.368395979842076	23.3123	2.15207	0.054735839193683036	1181.6071690803021	0.05329034618549888	1246.2834290771846
73.1801	1.379915979842076	23.3086	2.16492	0.055196639193683034	1181.419630891209	0.053727137421281504	1246.6300239938453
73.5901	1.391585979842076	23.3093	2.17658	0.05566343919368304	1181.4551110891455	0.0541694215995544	1247.2189658253221
74.0001	1.403135979842076	23.3165	2.18848	0.05612543919368304	1181.8200502679215	nan	nan
74.4101	1.414605979842076	23.302	2.20046	0.05658423919368304	1181.0851033106644	nan	nan
74.8201	1.426495979842076	23.3024	2.21307	0.05705983919368304	1181.105377709485	nan	nan
75.2201	1.437435979842076	23.2968	2.22433	0.05749743919368304	1180.821536125993	nan	nan
75.6401	1.449515979842076	23.2889	2.23734	0.05798063919368304	1180.4211167492804	nan	nan
76.0501	1.461345979842076	23.3039	2.24995	0.05845383919368304	1181.1814067050634	nan	nan
76.4601	1.472775979842076	23.2968	2.26154	0.05891103919368304	1180.821536125993	nan	nan
76.8901	1.485195979842076	23.3016	2.27525	0.05940783919368304	1181.0648289118435	nan	nan
77.3101	1.497165979842076	23.2906	2.28714	0.05988663919368304	1180.5072829442693	nan	nan
77.7301	1.509465979842076	23.2881	2.30006	0.06037863919368304	1180.3805679516386	nan	nan
78.1501	1.522095979842076	23.2871	2.312	0.06088383919368304	1180.3298819545862	nan	nan
78.5501	1.533525979842076	23.2757	2.32421	0.061341039193683035	1179.7520615881913	nan	nan
78.9501	1.545175979842076	23.2712	2.33588	0.06180703919368304	1179.5239746014563	nan	nan
79.3601	1.556955979842076	23.2703	2.34866	0.06227823919368304	1179.4783572041092	nan	nan
79.7601	1.568235979842076	23.2573	2.36015	0.06272943919368304	1178.8194392424305	nan	nan
80.1801	1.580785979842076	23.2561	2.37278	0.06323143919368304	1178.7586160459678	nan	nan
80.5901	1.593215979842076	23.2435	2.38538	0.06372863919368305	1178.11997248311	nan	nan
81.0001	1.605005979842076	23.2481	2.39764	0.06420023919368303	1178.3531280695502	nan	nan
81.4101	1.617865979842076	23.2342	2.41022	0.06471463919368305	1177.6485927105243	nan	nan
81.8301	1.630365979842076	23.2233	2.42341	0.06521463919368303	1177.0961153426551	nan	nan
82.2401	1.642315979842076	23.2133	2.43565	0.06569263919368304	1176.589255372133	nan	nan
82.6601	1.655015979842076	23.2093	2.44752	0.06620063919368305	1176.3865113839242	nan	nan
83.0901	1.668165979842076	23.1859	2.46097	0.06672663919368305	1175.2004590529025	nan	nan
83.5001	1.680385979842076	23.1807	2.47283	0.06721543919368304	1174.936891868231	nan	nan
83.9101	1.692215979842076	23.163	2.48488	0.06768863919368304	1174.0397497204067	nan	nan
84.3001	1.704465979842076	23.1642	2.49677	0.06817863919368304	1174.1005729168694	nan	nan
84.7301	1.717815979842076	23.133	2.50956	0.06871263919368303	1172.5191698088404	nan	nan
85.1401	1.730155979842076	23.1221	2.52162	0.06920623919368304	1171.9666924409712	nan	nan
85.5601	1.743415979842076	23.1077	2.53457	0.06973663919368304	1171.2368140834194	nan	nan
85.9601	1.755915979842076	23.0774	2.54656	0.07023663919368305	1169.7010283727375	nan	nan
86.3701	1.768245979842076	23.0637	2.55849	0.07072983919368304	1169.006630213122	nan	nan
86.7801	1.780955979842076	23.0477	2.57148	0.07123823919368304	1168.1956542602866	nan	nan
87.1801	1.793645979842076	23.0296	2.5834	0.07174583919368305	1167.2782377136414	nan	nan
87.5901	1.806715979842076	23.0041	2.59566	0.07226863919368304	1165.9857447888103	nan	nan
88.0001	1.819085979842076	22.9739	2.60744	0.07276343919368304	1164.4550276778334	nan	nan
88.4201	1.832185979842076	22.9448	2.61992	0.07328743919368304	1162.980065163614	nan	nan
88.8301	1.845645979842076	22.9289	2.63248	0.07382583919368303	1162.1741578104836	nan	nan
89.2401	1.858195979842076	22.8939	2.64401	0.07432783919368303	1160.4001479136562	nan	nan
89.6501	1.871565979842076	22.8649	2.6571	0.07486263919368304	1158.930253999142	nan	nan
90.0601	1.884255979842076	22.8243	2.66921	0.07537023919368303	1156.8724025188221	nan	nan
90.4801	1.897175979842076	22.7904	2.68045	0.07588703919368305	1155.1541472187523	nan	nan
90.8901	1.910525979842076	22.7847	2.69396	0.07642103919368304	1154.8652370355546	nan	nan
91.3001	1.923045979842076	22.7459	2.7063	0.07692183919368305	1152.8986203499287	nan	nan
91.7001	1.936195979842076	22.7194	2.71802	0.07744783919368305	1151.5554414280452	nan	nan
92.1001	1.948755979842076	22.6906	2.73036	0.07795023919368303	1150.0956847129414	nan	nan
92.5101	1.962065979842076	22.6694	2.74317	0.07848263919368305	1149.0211415754343	nan	nan
92.9401	1.975115979842076	22.6216	2.75525	0.07900463919368304	1146.5983509163389	nan	nan
93.3501	1.989065979842076	22.5932	2.76798	0.07956263919368305	1145.158868600056	nan	nan
93.7601	2.001775979842076	22.5516	2.78001	0.08007103919368302	1143.050331122684	nan	nan
94.1601	2.014565979842076	22.5125	2.79205	0.08058263919368304	1141.0685086379424	nan	nan
94.5701	2.027775979842076	22.4883	2.80475	0.08111103919368304	1139.8419075092786	nan	nan
94.9801	2.040555979842076	22.4414	2.81661	0.08162223919368303	1137.46473424753	nan	nan
95.4101	2.054155979842076	22.414	2.82967	0.08216623919368304	1136.0759379282993	nan	nan
95.8001	2.066905979842076	22.3906	2.84233	0.08267623919368304	1134.8898855972775	nan	nan
96.2101	2.079755979842076	22.3413	2.85385	0.08319023919368304	1132.3910659426033	nan	nan
96.6201	2.093045979842076	22.3253	2.86646	0.08372183919368303	1131.5800899897679	nan	nan
97.0401	2.106815979842076	22.2954	2.87937	0.08427263919368304	1130.0645786779069	nan	nan
97.4501	2.119495979842076	22.2369	2.89097	0.08477983919368304	1127.0994478503524	nan	nan
97.8601	2.133455979842076	22.208	2.90396	0.08533823919368304	1125.6346225355435	nan	nan
98.2701	2.145515979842076	22.1617	2.91526	0.08582063919368305	1123.287860872026	nan	nan
98.6801	2.159505979842076	22.1252	2.92797	0.08638023919368304	1121.4378219796204	nan	nan
99.0801	2.171605979842076	22.0795	2.93967	0.08686423919368304	1119.121471914334	nan	nan
99.4901	2.184235979842076	22.0583	2.95209	0.08736943919368305	1118.0469287768271	nan	nan
99.9001	2.197825979842076	22.0249	2.96425	0.08791303919368304	1116.354016475283	nan	nan
100.32	2.211715979842076	21.9788	2.97695	0.08846863919368303	1114.0173920111763	nan	nan
100.75	2.225385979842076	21.9357	2.98973	0.08901543919368304	1111.832825538226	nan	nan
101.15	2.237895979842076	21.896	3.00132	0.08951583919368304	1109.820591455253	nan	nan
101.57	2.251455979842076	21.8751	3.01459	0.09005823919368304	1108.7612541168617	nan	nan
101.98	2.264845979842076	21.8236	3.02702	0.09059383919368305	1106.1509252686728	nan	nan
102.39	2.277625979842076	21.7973	3.03912	0.09110503919368304	1104.8178835461995	nan	nan
102.81	2.291065979842076	21.7627	3.05225	0.09164263919368304	1103.064148048193	nan	nan
103.21	2.303545979842076	21.7098	3.06374	0.09214183919368304	1100.382858804131	nan	nan
103.62	2.317115979842076	21.6789	3.0767	0.09268463919368304	1098.8166614952174	nan	nan
104.03	2.330355979842076	21.6371	3.08894	0.09321423919368303	1096.697986818435	nan	nan
104.43	2.343115979842076	21.5942	3.10091	0.09372463919368304	1094.5235575448953	nan	nan
104.84	2.356215979842076	21.5498	3.11308	0.09424863919368304	1092.273099275777	nan	nan
105.26	2.369805979842076	21.5174	3.12589	0.09479223919368303	1090.630872971285	nan	nan
105.67	2.382605979842076	21.4866	3.13728	0.09530423919368303	1089.069744262077	nan	nan
106.08	2.396315979842076	21.4246	3.14998	0.09585263919368303	1085.92721244484	nan	nan
106.49	2.409055979842076	21.3867	3.16357	0.09636223919368303	1084.006213156561	nan	nan
106.89	2.422055979842076	21.3523	3.17509	0.09688223919368305	1082.2626148579648	nan	nan
107.31	2.435355979842076	21.3068	3.18755	0.09741423919368303	1079.9564019920892	nan	nan
107.72	2.448965979842076	21.2647	3.2	0.09795863919368304	1077.822521516191	nan	nan
108.13	2.461615979842076	21.2317	3.21214	0.09846463919368303	1076.149883613468	nan	nan
108.53	2.474905979842076	21.1813	3.22444	0.09899623919368304	1073.5953093620365	nan	nan
108.95	2.488385979842076	21.1499	3.2371	0.09953543919368305	1072.003769054597	nan	nan
109.36	2.501455979842076	21.1003	3.24902	0.10005823919368304	1069.4897436008073	nan	nan
109.78	2.515155979842076	21.056	3.26162	0.10060623919368304	1067.2443539313942	nan	nan
110.19	2.527605979842076	21.0125	3.27374	0.10110423919368303	1065.039513059623	nan	nan
110.59	2.540745979842076	20.9793	3.28579	0.10162983919368304	1063.3567379574895	nan	nan
111	2.554155979842076	20.9234	3.29875	0.10216623919368305	1060.523390722271	nan	nan
111.41	2.567005979842076	20.8999	3.31042	0.10268023919368303	1059.3322697915437	nan	nan
111.81	2.580095979842076	20.8418	3.32255	0.10320383919368303	1056.38741336281	nan	nan
112.24	2.594245979842076	20.8048	3.3361	0.10376983919368303	1054.5120314718783	nan	nan
112.66	2.607955979842076	20.7575	3.34866	0.10431823919368303	1052.1145838113086	nan	nan
113.09	2.621315979842076	20.7153	3.36104	0.10485263919368304	1049.9756347357052	nan	nan
113.51	2.634975979842076	20.6658	3.37354	0.10539903919368304	1047.4666778816206	nan	nan
113.91	2.647745979842076	20.6297	3.38586	0.10590983919368303	1045.636913388036	nan	nan
114.32	2.661395979842076	20.583	3.39913	0.10645583919368304	1043.2698773256975	nan	nan
114.72	2.673985979842076	20.529	3.41097	0.10695943919368305	1040.532833484878	nan	nan
115.13	2.686865979842076	20.4922	3.42261	0.10747463919368304	1038.6675887933566	nan	nan
115.54	2.700475979842076	20.4504	3.43491	0.10801903919368304	1036.548914116574	nan	nan
115.97	2.714335979842076	20.3986	3.44822	0.10857343919368305	1033.9233794692693	nan	nan
116.38	2.727785979842076	20.353	3.46057	0.10911143919368303	1031.6120980036885	nan	nan
116.78	2.740775979842076	20.3091	3.47265	0.10963103919368304	1029.3869827330966	nan	nan
117.19	2.753545979842076	20.2626	3.48444	0.11014183919368303	1027.0300838701685	nan	nan
117.6	2.766935979842076	20.2067	3.49709	0.11067743919368304	1024.19673663495	nan	nan
118.02	2.780555979842076	20.1554	3.50918	0.11122223919368304	1021.5965449861714	nan	nan
118.42	2.793505979842076	20.1178	3.52144	0.11174023919368305	1019.690751497008	nan	nan
118.83	2.806515979842076	20.0868	3.53403	0.11226063919368304	1018.1194855883895	nan	nan
119.23	2.819655979842076	20.0219	3.54591	0.11278623919368304	1014.8299643797008	nan	nan
119.64	2.833355979842076	19.9679	3.55844	0.11333423919368305	1012.0929205388815	nan	nan
120.05	2.846345979842076	19.9336	3.57035	0.11385383919368303	1010.3543908399904	nan	nan
120.47	2.860075979842076	19.882	3.58354	0.11440303919368304	1007.7389933920963	nan	nan
120.87	2.872915979842076	19.8298	3.59531	0.11491663919368303	1005.0931843459707	nan	nan
121.28	2.886625979842076	19.7852	3.60768	0.11546503919368303	1002.8325888774422	nan	nan
121.68	2.899735979842076	19.7269	3.62034	0.11598943919368304	999.8775952492982	nan	nan
122.09	2.912885979842076	19.6833	3.63222	0.11651543919368304	997.6676857778216	nan	nan
122.49	2.925545979842076	19.63	3.64375	0.11702183919368304	994.9661221349387	nan	nan
122.9	2.938985979842076	19.5798	3.65604	0.11755943919368304	992.4216850829175	nan	nan
123.3	2.952035979842076	19.5392	3.66869	0.11808143919368304	990.3638336025978	nan	nan
123.71	2.965205979842076	19.4946	3.68128	0.11860823919368305	988.103238134069	nan	nan
124.11	2.978305979842076	19.4327	3.69271	0.11913223919368304	984.9657749165372	nan	nan
124.52	2.992095979842076	19.3731	3.70481	0.11968383919368303	981.9448894922253	nan	nan
124.93	3.005315979842076	19.3341	3.71697	0.12021263919368304	979.9681356071889	nan	nan
125.35	3.018635979842076	19.2726	3.72941	0.12074543919368304	976.8509467884779	nan	nan
125.77	3.032435979842076	19.218	3.74213	0.12129743919368303	974.0834913494269	nan	nan
126.17	3.045215979842076	19.1751	3.75406	0.12180863919368305	971.9090620758872	nan	nan
126.6	3.059605979842076	19.1128	3.76703	0.12238423919368303	968.7513244595341	nan	nan
127.03	3.073745979842076	19.0563	3.78059	0.12294983919368305	965.8875656260841	nan	nan
127.44	3.087475979842076	19.0014	3.79251	0.12349903919368303	963.1049043879177	nan	nan
127.85	3.100595979842076	18.9488	3.80525	0.12402383919368304	960.4388209429712	nan	nan
128.26	3.114405979842076	18.9001	3.81741	0.12457623919368305	957.9704128865284	nan	nan
128.68	3.128115979842076	18.8274	3.83027	0.12512463919368305	954.2855409008326	nan	nan
129.1	3.141815979842076	18.7738	3.84252	0.12567263919368304	951.5687714588341	nan	nan
129.51	3.154725979842076	18.7108	3.85468	0.12618903919368304	948.3755536445445	nan	nan
129.93	3.168665979842076	18.6672	3.86726	0.12674663919368304	946.1656441730681	nan	nan
130.34	3.182935979842076	18.6053	3.88044	0.12731743919368305	943.0281809555361	nan	nan
130.76	3.196405979842076	18.5397	3.89291	0.12785623919368302	939.7031795489111	nan	nan
131.17	3.209505979842076	18.499	3.90465	0.12838023919368305	937.6402594688859	nan	nan
131.59	3.223205979842076	18.4167	3.91783	0.12892823919368304	933.4688019114886	nan	nan
132	3.237395979842076	18.3637	3.93082	0.12949583919368304	930.7824440677216	nan	nan
132.41	3.250155979842076	18.3127	3.94222	0.13000623919368304	928.1974582180587	nan	nan
132.85	3.264505979842076	18.2467	3.9557	0.13058023919368306	924.8521824126126	nan	nan
133.26	3.278705979842076	18.1922	3.96873	0.13114823919368304	922.089795573267	nan	nan
133.66	3.292175979842076	18.1258	3.9806	0.13168703919368305	918.7242453690002	nan	nan
134.07	3.304915979842076	18.0682	3.99258	0.13219663919368305	915.8047319387927	nan	nan
134.47	3.318185979842076	17.9941	4.00431	0.13272743919368304	912.0488995572235	nan	nan
134.9	3.332695979842076	17.9222	4.01687	0.13330783919368305	908.4045763691696	nan	nan
135.31	3.346805979842076	17.8657	4.02974	0.13387223919368305	905.5408175357195	nan	nan
135.72	3.360025979842076	17.8075	4.04214	0.13440103919368304	902.5908925072807	nan	nan
136.14	3.374135979842076	17.7332	4.05476	0.13496543919368303	898.8249229263014	nan	nan
136.55	3.388075979842076	17.6567	4.06706	0.13552303919368305	894.9474441518071	nan	nan
136.95	3.402045979842076	17.5843	4.07955	0.13608183919368305	891.2777779652267	nan	nan
137.37	3.415925979842076	17.4934	4.09152	0.13663703919368303	886.6704208331807	nan	nan
137.78	3.429795979842076	17.4074	4.10349	0.13719183919368302	882.3114250866902	nan	nan